

BranchFrequency: 10

BranchFrequencyGroup: CanOverride:0

CanOverride: true

SmoothRadius: -1

OverrideChildSettings: false

ReplaceAbove:
ReplaceBelow:

MustBeInside: VillageGeneratorStructurePlaceHolder, VillageGeneratorStructuresDelay, VillageGeneratorStructuresDelay2, VillageGeneratorStructuresDelay3, VillageGeneratorStructuresDelay4, VillageGeneratorStructuresDelay5, VillageGeneratorStructuresDelay6, VillageGeneratorStructuresDelay7, VillageGeneratorStructuresDelay8, VillageGeneratorStructuresDelay9, VillageGeneratorStructuresDelay10

Block(-8,0,-7,98)
Block(-8,0,-6,98)
Block(-8,0,-5,98)
Block(-8,0,-4,98)
Block(-8,0,-3,98)
Block(-8,0,-2,98)
Block(-8,0,-1,98)
Block(-8,1,-6,156:2)
Block(-8,1,-5,155)
Block(-8,1,-4,156)
Block(-8,1,-3,155)
Block(-8,1,-2,156:3)
Block(-7,0,-7,98)
Block(-7,0,-6,155:1)
Block(-7,0,-5,155:1)
Block(-7,0,-4,155:1)
Block(-7,0,-3,155:1)
Block(-7,0,-2,155:1)
Block(-7,0,-1,98)
Block(-7,1,-7,156)
Block(-7,1,-6,156)
Block(-7,1,-5,9)
Block(-7,1,-4,9)
Block(-7,1,-3,9)
Block(-7,1,-2,156)
Block(-7,1,-1,156)
Block(-7,2,-4,9:9)
Block(-7,3,-4,9:1)
Block(-6,0,-7,98)
Block(-6,0,-6,155:1)
Block(-6,0,-5,155:1)
Block(-6,0,-4,155:1)
Block(-6,0,-3,155:1)
Block(-6,0,-2,155:1)
Block(-6,0,-1,98)
Block(-6,1,-7,155)
Block(-6,1,-6,9)
Block(-6,1,-5,9)
Block(-6,1,-4,155:2)
Block(-6,1,-3,9)
Block(-6,1,-2,9)
Block(-6,1,-1,155)
Block(-6,2,-5,9:9)
Block(-6,2,-4,155:2)
Block(-6,2,-3,9:9)
Block(-6,3,-5,9:1)
Block(-6,3,-4,9:9)
Block(-6,3,-3,9:1)
Block(-6,4,-4,9:9)
Block(-6,5,-4,9:1)
Block(-5,0,-7,98)
Block(-5,0,-6,155:1)
Block(-5,0,-5,155:1)
Block(-5,0,-4,155:1)
Block(-5,0,-3,155:1)
Block(-5,0,-2,155:1)
Block(-5,0,-1,98)
Block(-5,1,-7,156:2)
Block(-5,1,-6,9)
Block(-5,1,-5,155:2)
Block(-5,1,-4,155:2)
Block(-5,1,-3,155:2)
Block(-5,1,-2,9)
Block(-5,1,-1,156:3)
Block(-5,2,-6,9:9)
Block(-5,2,-5,155:2)
Block(-5,2,-4,155:2)
Block(-5,2,-3,155:2)
Block(-5,2,-2,9:9)
Block(-5,3,-6,9:1)
Block(-5,3,-5,9:9)
Block(-5,3,-4,155:2)
Block(-5,3,-3,9:9)
Block(-5,3,-2,9:1)
Block(-5,4,-5,9:9)
Block(-5,4,-4,89)
Block(-5,4,-3,9:9)
Block(-5,5,-5,9:1)
Block(-5,5,-4,9)
Block(-5,5,-3,9:1)
Block(-4,0,-7,98)
Block(-4,0,-6,155:1)
Block(-4,0,-5,155:1)
Block(-4,0,-4,155:1)
Block(-4,0,-3,155:1)
Block(-4,0,-2,155:1)
Block(-4,0,-1,98)
Block(-4,1,-7,155)
Block(-4,1,-6,9)
Block(-4,1,-5,9)
Block(-4,1,-4,155:2)
Block(-4,1,-3,9)
Block(-4,1,-2,9)
Block(-4,1,-1,155)
Block(-4,2,-5,9:9)
Block(-4,2,-4,155:2)
Block(-4,2,-3,9:9)
Block(-4,3,-5,9:1)
Block(-4,3,-4,9:9)
Block(-4,3,-3,9:1)
Block(-4,4,-4,9:9)
Block(-4,5,-4,9:1)
Block(-3,0,-7,98)
Block(-3,0,-6,155:1)
Block(-3,0,-5,155:1)
Block(-3,0,-4,155:1)
Block(-3,0,-3,155:1)
Block(-3,0,-2,155:1)
Block(-3,0,-1,98)
Block(-3,1,-7,156:1)
Block(-3,1,-6,156:1)
Block(-3,1,-5,9)
Block(-3,1,-4,9)
Block(-3,1,-3,9)
Block(-3,1,-2,156:1)
Block(-3,1,-1,156:1)
Block(-3,2,-4,9:9)
Block(-3,3,-4,9:1)
Block(-2,0,-7,98)
Block(-2,0,-6,98)
Block(-2,0,-5,98)
Block(-2,0,-4,98)
Block(-2,0,-3,98)
Block(-2,0,-2,98:2)
Block(-2,0,-1,98)
Block(-2,1,-6,156:2)
Block(-2,1,-5,155)
Block(-2,1,-4,156:1)
Block(-2,1,-3,155)
Block(-2,1,-2,156:3)
