

BranchFrequencyGroup: CanOverride:0

CanOverride: true

SmoothRadius: -1

OverrideChildSettings: false

ReplaceAbove:
ReplaceBelow:

MustBeInside: VillageGeneratorStructurePlaceHolder, VillageGeneratorStructuresDelay, VillageGeneratorStructuresDelay2, VillageGeneratorStructuresDelay3, VillageGeneratorStructuresDelay4, VillageGeneratorStructuresDelay5, VillageGeneratorStructuresDelay6, VillageGeneratorStructuresDelay7, VillageGeneratorStructuresDelay8, VillageGeneratorStructuresDelay9, VillageGeneratorStructuresDelay10

Block(-8,0,-7,3)
Block(-8,0,-6,3)
Block(-8,0,-5,3)
Block(-8,0,-4,3)
Block(-8,0,-3,3)
Block(-8,0,-2,3)
Block(-8,0,-1,3)
Block(-8,0,0,3)
Block(-8,0,1,3)
Block(-8,0,2,3)
Block(-8,0,3,3)
Block(-8,0,4,3)
Block(-8,0,5,3)
Block(-8,0,6,3)
Block(-8,0,7,3)
Block(-8,0,8,3)
Block(-8,1,-7,2)
Block(-8,1,-6,2)
Block(-8,1,-5,2)
Block(-8,1,-4,2)
Block(-8,1,-3,2)
Block(-8,1,-2,2)
Block(-8,1,-1,2)
Block(-8,1,0,2)
Block(-8,1,1,2)
Block(-8,1,2,2)
Block(-8,1,3,2)
Block(-8,1,4,13)
Block(-8,1,5,3:2)
Block(-8,1,6,3)
Block(-8,1,7,5:2)
Block(-8,1,8,5:2)
Block(-8,2,1,38:3)
Block(-8,2,6,17)
Block(-8,2,7,170)
Block(-8,3,5,175:10)
Block(-8,3,6,17)
Block(-8,4,6,17)
Block(-8,5,4,134:6)
Block(-8,5,5,134:4)
Block(-8,5,6,17:4)
Block(-8,5,7,17:8)
Block(-8,5,8,50:3)
Block(-8,6,3,134:6)
Block(-8,6,4,5:1)
Block(-8,6,5,5:1)
Block(-8,6,6,5)
Block(-8,6,7,5:2)
Block(-8,6,8,5:2)
Block(-8,7,-1,18)
Block(-8,7,0,18)
Block(-8,7,1,18)
Block(-8,7,2,18)
Block(-8,7,3,85)
Block(-8,7,6,17)
Block(-8,7,7,17)
Block(-8,7,8,58)
Block(-8,8,-1,18)
Block(-8,8,0,18)
Block(-8,8,1,18)
Block(-8,8,2,18)
Block(-8,8,3,18)
Block(-8,8,6,17)
Block(-8,8,7,17)
Block(-8,8,8,58)
Block(-8,9,0,18)
Block(-8,9,1,18)
Block(-8,9,2,18)
Block(-8,9,6,17)
Block(-8,9,7,17)
Block(-8,9,8,58)
Block(-8,10,1,18)
Block(-8,10,6,17)
Block(-8,10,7,17)
Block(-8,10,8,85)
Block(-8,11,5,17:8)
Block(-8,11,6,17:4)
Block(-8,11,7,17:4)
Block(-8,11,8,5:2)
Block(-8,12,6,85)
Block(-8,12,8,17)
Block(-8,13,8,17)
Block(-8,14,8,17)
Block(-8,15,8,17)
Block(-8,16,8,17)
Block(-8,17,8,17)
Block(-8,18,8,17)
Block(-8,19,7,85)
Block(-8,19,8,17:4)
Block(-8,20,7,134:2)
Block(-8,20,8,5:1)
Block(-8,21,8,134:2)
Block(-7,0,-7,3)
Block(-7,0,-6,3)
Block(-7,0,-5,3)
Block(-7,0,-4,3)
Block(-7,0,-3,3)
Block(-7,0,-2,3)
Block(-7,0,-1,3)
Block(-7,0,0,3)
Block(-7,0,1,3)
Block(-7,0,2,3)
Block(-7,0,3,3)
Block(-7,0,4,3)
Block(-7,0,5,3)
Block(-7,0,6,3)
Block(-7,0,7,3)
Block(-7,0,8,3)
Block(-7,1,-7,2)
Block(-7,1,-6,2)
Block(-7,1,-5,2)
Block(-7,1,-4,2)
Block(-7,1,-3,2)
Block(-7,1,-2,2)
Block(-7,1,-1,2)
Block(-7,1,0,2)
Block(-7,1,1,3)
Block(-7,1,2,2)
Block(-7,1,3,2)
Block(-7,1,4,13)
Block(-7,1,5,3)
Block(-7,1,6,5:2)
Block(-7,1,7,5:2)
Block(-7,1,8,5:2)
Block(-7,2,1,17)
Block(-7,2,2,31:1)
Block(-7,2,5,17)
Block(-7,2,6,170)
Block(-7,3,1,17)
Block(-7,3,5,45)
Block(-7,3,6,170)
Block(-7,4,1,17)
Block(-7,4,5,45)
Block(-7,4,6,170)
Block(-7,5,1,17)
Block(-7,5,4,134:6)
Block(-7,5,5,17:4)
Block(-7,5,6,17:8)
Block(-7,5,7,50:3)
Block(-7,6,1,17)
Block(-7,6,3,134:6)
Block(-7,6,4,5:1)
Block(-7,6,5,5:1)
Block(-7,6,6,45)
Block(-7,6,7,5:2)
Block(-7,6,8,5:2)
Block(-7,7,-1,18)
Block(-7,7,0,18)
Block(-7,7,1,17)
Block(-7,7,2,18)
Block(-7,7,3,85)
Block(-7,7,6,45)
Block(-7,7,7,58)
Block(-7,8,-1,18)
Block(-7,8,0,18)
Block(-7,8,1,17)
Block(-7,8,2,18)
Block(-7,8,3,18)
Block(-7,8,5,96:12)
Block(-7,8,6,45)
Block(-7,8,7,50:5)
Block(-7,9,0,18)
Block(-7,9,1,17)
Block(-7,9,2,18)
Block(-7,9,5,96:12)
Block(-7,9,6,45)
Block(-7,10,0,18)
Block(-7,10,1,18)
Block(-7,10,2,18)
Block(-7,10,6,45)
Block(-7,10,7,85)
Block(-7,11,5,85)
Block(-7,11,6,17:4)
Block(-7,11,7,17:4)
Block(-7,11,8,5:2)
Block(-7,12,6,85)
Block(-7,12,8,45)
Block(-7,13,8,45)
Block(-7,14,8,45)
Block(-7,15,8,45)
Block(-7,16,8,45)
Block(-7,17,8,45)
Block(-7,18,8,45)
Block(-7,19,7,85)
Block(-7,19,8,17:4)
Block(-7,20,7,134:2)
Block(-7,20,8,5:1)
Block(-7,21,8,5:1)
Block(-7,22,8,5:1)
Block(-7,23,8,5:1)
Block(-7,24,8,5:1)
Block(-6,0,-7,3)
Block(-6,0,-6,3)
Block(-6,0,-5,3)
Block(-6,0,-4,3)
Block(-6,0,-3,3)
Block(-6,0,-2,3)
Block(-6,0,-1,3)
Block(-6,0,0,3)
Block(-6,0,1,3)
Block(-6,0,2,3)
Block(-6,0,3,3)
Block(-6,0,4,3)
Block(-6,0,5,3)
Block(-6,0,6,3)
Block(-6,0,7,3)
Block(-6,0,8,3)
Block(-6,1,-7,2)
Block(-6,1,-6,2)
Block(-6,1,-5,2)
Block(-6,1,-4,2)
Block(-6,1,-3,2)
Block(-6,1,-2,2)
Block(-6,1,-1,2)
Block(-6,1,0,2)
Block(-6,1,1,2)
Block(-6,1,2,2)
Block(-6,1,3,2)
Block(-6,1,4,13)
Block(-6,1,5,3)
Block(-6,1,6,5:2)
Block(-6,1,7,5:2)
Block(-6,1,8,5:2)
Block(-6,2,-2,31:1)
Block(-6,2,5,17)
Block(-6,2,6,170:8)
Block(-6,2,7,170)
Block(-6,3,5,45)
Block(-6,3,6,170)
Block(-6,4,5,45)
Block(-6,5,4,134:6)
Block(-6,5,5,17:4)
Block(-6,6,3,134:6)
Block(-6,6,4,5:1)
Block(-6,6,5,5:1)
Block(-6,6,6,45)
Block(-6,6,7,5:2)
Block(-6,6,8,5:2)
Block(-6,7,-1,18)
Block(-6,7,0,18)
Block(-6,7,1,18)
Block(-6,7,2,18)
Block(-6,7,3,85)
Block(-6,7,6,45)
Block(-6,7,7,135:1)
Block(-6,7,8,135:1)
Block(-6,8,-1,18)
Block(-6,8,0,18)
Block(-6,8,1,18)
Block(-6,8,2,18)
Block(-6,8,3,18)
Block(-6,8,6,102)
Block(-6,9,1,18)
Block(-6,9,2,18)
Block(-6,9,6,102)
Block(-6,10,1,18)
Block(-6,10,6,45)
Block(-6,10,7,85)
Block(-6,11,5,85)
Block(-6,11,6,17:4)
Block(-6,11,7,17:4)
Block(-6,11,8,5:2)
Block(-6,12,6,85)
Block(-6,12,8,45)
Block(-6,13,8,102)
Block(-6,14,8,102)
Block(-6,15,8,45)
Block(-6,16,8,102)
Block(-6,17,8,102)
Block(-6,18,8,45)
Block(-6,19,7,85)
Block(-6,19,8,17:4)
Block(-6,20,7,134:2)
Block(-6,20,8,5:1)
Block(-6,21,8,102)
Block(-6,22,8,5:1)
Block(-6,23,8,5:1)
Block(-6,24,8,5:1)
Block(-5,0,-7,3)
Block(-5,0,-6,3)
Block(-5,0,-5,3)
Block(-5,0,-4,3)
Block(-5,0,-3,3)
Block(-5,0,-2,3)
Block(-5,0,-1,3)
Block(-5,0,0,3)
Block(-5,0,1,3)
Block(-5,0,2,3)
Block(-5,0,3,3)
Block(-5,0,4,3)
Block(-5,0,5,3)
Block(-5,0,6,3)
Block(-5,0,7,3)
Block(-5,0,8,3)
Block(-5,1,-7,2)
Block(-5,1,-6,2)
Block(-5,1,-5,2)
Block(-5,1,-4,2)
Block(-5,1,-3,2)
Block(-5,1,-2,2)
Block(-5,1,-1,2)
Block(-5,1,0,2)
Block(-5,1,1,2)
Block(-5,1,2,2)
Block(-5,1,3,2)
Block(-5,1,4,13)
Block(-5,1,5,3)
Block(-5,1,6,5:2)
Block(-5,1,7,5:2)
Block(-5,1,8,5:2)
Block(-5,2,5,17)
Block(-5,2,6,35)
Block(-5,3,-4,18)
Block(-5,3,5,45)
Block(-5,4,5,45)
Block(-5,5,4,134:6)
Block(-5,5,5,17:4)
Block(-5,6,3,134:6)
Block(-5,6,4,5:1)
Block(-5,6,5,5:1)
Block(-5,6,6,45)
Block(-5,6,7,5:2)
Block(-5,6,8,5:2)
Block(-5,7,-1,18)
Block(-5,7,0,18)
Block(-5,7,1,18)
Block(-5,7,2,18)
Block(-5,7,3,85)
Block(-5,7,6,45)
Block(-5,7,7,85)
Block(-5,7,8,85)
Block(-5,8,0,18)
Block(-5,8,1,18)
Block(-5,8,2,18)
Block(-5,8,6,45)
Block(-5,8,7,72)
Block(-5,8,8,72)
Block(-5,9,6,45)
Block(-5,10,6,45)
Block(-5,10,7,85)
Block(-5,11,5,85)
Block(-5,11,6,17:4)
Block(-5,11,7,17:4)
Block(-5,11,8,5:2)
Block(-5,12,6,85)
Block(-5,12,8,45)
Block(-5,13,8,45)
Block(-5,14,8,45)
Block(-5,15,8,45)
Block(-5,16,8,45)
Block(-5,17,8,45)
Block(-5,18,8,45)
Block(-5,19,7,85)
Block(-5,19,8,17:4)
Block(-5,20,7,134:2)
Block(-5,20,8,5:1)
Block(-5,21,8,102)
Block(-5,22,8,102)
Block(-5,23,8,5:1)
Block(-5,24,8,5:1)
Block(-4,0,-7,3)
Block(-4,0,-6,3)
Block(-4,0,-5,3)
Block(-4,0,-4,3)
Block(-4,0,-3,3)
Block(-4,0,-2,3)
Block(-4,0,-1,3)
Block(-4,0,0,3)
Block(-4,0,1,3)
Block(-4,0,2,3)
Block(-4,0,3,3)
Block(-4,0,4,3)
Block(-4,0,5,3)
Block(-4,0,6,3)
Block(-4,0,7,3)
Block(-4,0,8,3)
Block(-4,1,-7,2)
Block(-4,1,-6,2)
Block(-4,1,-5,2)
Block(-4,1,-4,2)
Block(-4,1,-3,2)
Block(-4,1,-2,2)
Block(-4,1,-1,2)
Block(-4,1,0,2)
Block(-4,1,1,2)
Block(-4,1,2,2)
Block(-4,1,3,2)
Block(-4,1,4,13)
Block(-4,1,5,3)
Block(-4,1,6,5:2)
Block(-4,1,7,5:2)
Block(-4,1,8,5:2)
Block(-4,2,5,17)
Block(-4,2,6,35)
Block(-4,3,-5,18)
Block(-4,3,-4,18)
Block(-4,3,-3,18)
Block(-4,3,5,45)
Block(-4,3,6,35)
Block(-4,4,-4,18)
Block(-4,4,5,45)
Block(-4,5,4,134:6)
Block(-4,5,5,17:4)
Block(-4,6,3,134:6)
Block(-4,6,4,5:1)
Block(-4,6,5,5:1)
Block(-4,6,6,45)
Block(-4,6,7,5:2)
Block(-4,6,8,5:2)
Block(-4,7,3,85)
Block(-4,7,6,45)
Block(-4,7,7,135)
Block(-4,7,8,135)
Block(-4,8,6,102)
Block(-4,9,6,102)
Block(-4,10,6,45)
Block(-4,10,7,85)
Block(-4,11,5,85)
Block(-4,11,6,17:4)
Block(-4,11,7,17:4)
Block(-4,11,8,5:2)
Block(-4,12,6,85)
Block(-4,12,8,45)
Block(-4,13,8,102)
Block(-4,14,8,102)
Block(-4,15,8,45)
Block(-4,16,8,102)
Block(-4,17,8,102)
Block(-4,18,8,45)
Block(-4,19,7,85)
Block(-4,19,8,17:4)
Block(-4,20,7,134:2)
Block(-4,20,8,5:1)
Block(-4,21,8,102)
Block(-4,22,8,5:1)
Block(-4,23,8,5:1)
Block(-4,24,8,5:1)
Block(-3,0,-7,3)
Block(-3,0,-6,3)
Block(-3,0,-5,3)
Block(-3,0,-4,3)
Block(-3,0,-3,3)
Block(-3,0,-2,3)
Block(-3,0,-1,3)
Block(-3,0,0,3)
Block(-3,0,1,3)
Block(-3,0,2,3)
Block(-3,0,3,3)
Block(-3,0,4,3)
Block(-3,0,5,3)
Block(-3,0,6,3)
Block(-3,0,7,3)
Block(-3,0,8,3)
Block(-3,1,-7,2)
Block(-3,1,-6,2)
Block(-3,1,-5,2)
Block(-3,1,-4,2)
Block(-3,1,-3,2)
Block(-3,1,-2,2)
Block(-3,1,-1,2)
Block(-3,1,0,2)
Block(-3,1,1,2)
Block(-3,1,2,2)
Block(-3,1,3,2)
Block(-3,1,4,13)
Block(-3,1,5,3)
Block(-3,1,6,5:2)
Block(-3,1,7,5:2)
Block(-3,1,8,5:2)
Block(-3,2,-5,18)
Block(-3,2,2,31:1)
Block(-3,2,5,17)
Block(-3,2,6,35)
Block(-3,3,-5,18)
Block(-3,3,-4,18)
Block(-3,3,-3,18)
Block(-3,3,5,45)
Block(-3,3,6,35)
Block(-3,4,-3,18)
Block(-3,4,5,45)
Block(-3,5,4,134:6)
Block(-3,5,5,17:4)
Block(-3,5,6,17:8)
Block(-3,5,7,50:3)
Block(-3,6,3,134:6)
Block(-3,6,4,5:1)
Block(-3,6,5,5:1)
Block(-3,6,6,45)
Block(-3,6,7,5:2)
Block(-3,6,8,5:2)
Block(-3,7,3,85)
Block(-3,7,6,45)
Block(-3,7,7,58)
Block(-3,8,5,96:4)
Block(-3,8,6,45)
Block(-3,8,7,50:5)
Block(-3,9,5,96:4)
Block(-3,9,6,45)
Block(-3,10,6,45)
Block(-3,10,7,85)
Block(-3,11,5,85)
Block(-3,11,6,17:4)
Block(-3,11,7,17:4)
Block(-3,11,8,5:2)
Block(-3,12,6,85)
Block(-3,12,8,45)
Block(-3,13,8,45)
Block(-3,14,8,45)
Block(-3,15,8,45)
Block(-3,16,8,45)
Block(-3,17,8,45)
Block(-3,18,8,45)
Block(-3,19,7,85)
Block(-3,19,8,17:4)
Block(-3,20,7,134:2)
Block(-3,20,8,5:1)
Block(-3,21,8,5:1)
Block(-3,22,8,5:1)
Block(-3,23,8,5:1)
Block(-3,24,8,5:1)
Block(-2,0,-7,3)
Block(-2,0,-6,3)
Block(-2,0,-5,3)
Block(-2,0,-4,3)
Block(-2,0,-3,3)
Block(-2,0,-2,3)
Block(-2,0,-1,3)
Block(-2,0,0,3)
Block(-2,0,1,3)
Block(-2,0,2,3)
Block(-2,0,3,3)
Block(-2,0,4,3)
Block(-2,0,5,3)
Block(-2,0,7,3)
Block(-2,0,8,3)
Block(-2,1,-7,2)
Block(-2,1,-6,2)
Block(-2,1,-5,2)
Block(-2,1,-4,2)
Block(-2,1,-3,2)
Block(-2,1,-2,2)
Block(-2,1,-1,2)
Block(-2,1,0,2)
Block(-2,1,1,2)
Block(-2,1,2,2)
Block(-2,1,3,2)
Block(-2,1,4,13)
Block(-2,1,5,3:2)
Block(-2,1,6,3)
Block(-2,1,7,5:2)
Block(-2,1,8,5:2)
Block(-2,2,-6,18)
Block(-2,2,-5,18)
Block(-2,2,-4,18)
Block(-2,2,-3,18)
Block(-2,2,2,37)
Block(-2,2,3,31:1)
Block(-2,2,5,175:2)
Block(-2,2,6,17)
Block(-2,3,-7,18)
Block(-2,3,-6,18)
Block(-2,3,-5,18:8)
Block(-2,3,-4,18)
Block(-2,3,-3,18)
Block(-2,3,5,175:8)
Block(-2,3,6,17)
Block(-2,4,-7,18)
Block(-2,4,-6,18)
Block(-2,4,-5,18)
Block(-2,4,-4,18)
Block(-2,4,6,17)
Block(-2,5,-4,18)
Block(-2,5,4,134:5)
Block(-2,5,5,134:6)
Block(-2,5,6,17:4)
Block(-2,5,7,17:8)
Block(-2,5,8,50:3)
Block(-2,6,3,134:6)
Block(-2,6,4,5:1)
Block(-2,6,5,5:1)
Block(-2,6,6,5)
Block(-2,6,7,5:2)
Block(-2,6,8,5:2)
Block(-2,7,3,85)
Block(-2,7,6,17)
Block(-2,7,7,17)
Block(-2,8,6,17)
Block(-2,8,7,17)
Block(-2,9,6,17)
Block(-2,9,7,17)
Block(-2,10,6,17)
Block(-2,10,7,17)
Block(-2,10,8,85)
Block(-2,11,5,17:8)
Block(-2,11,6,17:4)
Block(-2,11,7,17:4)
Block(-2,11,8,5:2)
Block(-2,12,6,85)
Block(-2,12,8,17)
Block(-2,13,8,17)
Block(-2,14,8,17)
Block(-2,15,8,17)
Block(-2,16,8,17)
Block(-2,17,8,17)
Block(-2,18,8,17)
Block(-2,19,7,85)
Block(-2,19,8,17:4)
Block(-2,20,7,134:2)
Block(-2,20,8,5:1)
Block(-2,21,8,134:2)
Block(-1,0,-7,3)
Block(-1,0,-6,3)
Block(-1,0,-5,3)
Block(-1,0,-4,3)
Block(-1,0,-3,3)
Block(-1,0,-2,3)
Block(-1,0,-1,3)
Block(-1,0,0,3)
Block(-1,0,1,3)
Block(-1,0,2,3)
Block(-1,0,3,3)
Block(-1,0,4,3)
Block(-1,0,5,3)
Block(-1,0,6,3)
Block(-1,0,7,3)
Block(-1,0,8,3)
Block(-1,1,-7,2)
Block(-1,1,-6,2)
Block(-1,1,-5,2)
Block(-1,1,-4,2)
Block(-1,1,-3,2)
Block(-1,1,-2,2)
Block(-1,1,-1,2)
Block(-1,1,0,2)
Block(-1,1,1,2)
Block(-1,1,2,2)
Block(-1,1,3,2)
Block(-1,1,4,5)
Block(-1,1,5,3:2)
Block(-1,1,6,3)
Block(-1,1,7,5:2)
Block(-1,1,8,5:2)
Block(-1,2,-6,18)
Block(-1,2,-5,18)
Block(-1,2,-4,17)
Block(-1,2,-3,18)
Block(-1,2,3,31:1)
Block(-1,2,4,85)
Block(-1,2,5,38:5)
Block(-1,2,6,17)
Block(-1,2,7,170)
Block(-1,2,8,170)
Block(-1,3,-7,18)
Block(-1,3,-6,18)
Block(-1,3,-5,18)
Block(-1,3,-4,17)
Block(-1,3,-3,18)
Block(-1,3,4,85)
Block(-1,3,6,45)
Block(-1,3,7,170)
Block(-1,4,-7,18)
Block(-1,4,-6,18)
Block(-1,4,-5,18)
Block(-1,4,-4,17)
Block(-1,4,-3,18)
Block(-1,4,4,85)
Block(-1,4,6,45)
Block(-1,5,-5,18)
Block(-1,5,-4,18)
Block(-1,5,-3,18)
Block(-1,5,4,85)
Block(-1,5,5,134:6)
Block(-1,5,6,17:4)
Block(-1,5,7,85)
Block(-1,6,-7,18)
Block(-1,6,3,134:6)
Block(-1,6,4,5:1)
Block(-1,6,5,5:1)
Block(-1,6,6,5:1)
Block(-1,6,7,5:2)
Block(-1,6,8,5:2)
Block(-1,7,3,85)
Block(-1,7,7,45)
Block(-1,7,8,17)
Block(-1,8,7,45)
Block(-1,8,8,17)
Block(-1,9,7,45)
Block(-1,9,8,17)
Block(-1,10,7,45)
Block(-1,10,8,17)
Block(-1,11,6,85)
Block(-1,11,7,17:4)
Block(-1,11,8,5)
Block(-1,12,7,85)
Block(-1,19,7,17:8)
Block(-1,19,8,17:8)
Block(-1,20,7,134:2)
Block(-1,20,8,5:1)
Block(-1,21,8,134:1)
Block(0,0,-7,3)
Block(0,0,-6,3)
Block(0,0,-5,3)
Block(0,0,-4,3)
Block(0,0,-3,3)
Block(0,0,-2,3)
Block(0,0,-1,3)
Block(0,0,0,3)
Block(0,0,1,3)
Block(0,0,2,3)
Block(0,0,3,3)
Block(0,0,4,3)
Block(0,0,5,3)
Block(0,0,6,3)
Block(0,0,7,3)
Block(0,0,8,3)
Block(0,1,-7,2)
Block(0,1,-6,2)
Block(0,1,-5,2)
Block(0,1,-4,2)
Block(0,1,-3,2)
Block(0,1,-2,2)
Block(0,1,-1,2)
Block(0,1,0,2)
Block(0,1,1,2)
Block(0,1,2,2)
Block(0,1,3,2)
Block(0,1,4,13)
Block(0,1,5,13)
Block(0,1,6,13)
Block(0,1,7,3)
Block(0,1,8,5:2)
Block(0,2,-7,17)
Block(0,2,-6,18)
Block(0,2,-5,18)
Block(0,2,-4,18)
Block(0,2,-3,18)
Block(0,2,7,17)
Block(0,2,8,170)
Block(0,3,-7,17)
Block(0,3,-6,18)
Block(0,3,-5,18)
Block(0,3,-4,18)
Block(0,3,-3,18)
Block(0,3,7,17)
Block(0,3,8,170:4)
Block(0,4,-7,17)
Block(0,4,-6,18)
Block(0,4,-5,18)
Block(0,4,-4,18)
Block(0,4,7,17)
Block(0,4,8,170)
Block(0,5,-7,17)
Block(0,5,-6,18)
Block(0,5,-4,18)
Block(0,5,5,134:5)
Block(0,5,6,134:6)
Block(0,5,7,17:8)
Block(0,5,8,17:8)
Block(0,6,-7,18)
Block(0,6,-6,18)
Block(0,6,3,134:5)
Block(0,6,4,134:6)
Block(0,6,5,5:1)
Block(0,6,6,5:1)
Block(0,6,7,5)
Block(0,6,8,45)
Block(0,7,3,85)
Block(0,7,4,85)
Block(0,7,7,17)
Block(0,7,8,45)
Block(0,8,3,50:5)
Block(0,8,7,17)
Block(0,8,8,45)
Block(0,9,7,17)
Block(0,9,8,45)
Block(0,10,7,17)
Block(0,10,8,45)
Block(0,11,6,17:8)
Block(0,11,7,17:4)
Block(0,11,8,17:8)
Block(0,12,7,85)
Block(0,12,8,85)
Block(0,19,8,17:4)
Block(0,20,7,134:2)
Block(0,20,8,134:1)
Block(1,0,-7,3)
Block(1,0,-6,3)
Block(1,0,-5,3)
Block(1,0,-4,3)
Block(1,0,-3,3)
Block(1,0,-2,3)
Block(1,0,-1,3)
Block(1,0,0,3)
Block(1,0,1,3)
Block(1,0,2,3)
Block(1,0,3,3)
Block(1,0,4,3)
Block(1,0,5,3)
Block(1,0,6,3)
Block(1,0,7,3)
Block(1,1,-7,2)
Block(1,1,-6,2)
Block(1,1,-5,2)
Block(1,1,-4,2)
Block(1,1,-3,2)
Block(1,1,-2,2)
Block(1,1,-1,2)
Block(1,1,0,2)
Block(1,1,1,2)
Block(1,1,2,2)
Block(1,1,3,2)
Block(1,1,4,60)
Block(1,1,5,60)
Block(1,1,6,13)
Block(1,1,7,3:2)
Block(1,1,8,3)
Block(1,2,-6,18)
Block(1,2,-5,18)
Block(1,2,-4,18)
Block(1,2,-3,18)
Block(1,2,4,59:7)
Block(1,2,5,59:7)
Block(1,2,7,31:1)
Block(1,2,8,17)
Block(1,3,-7,18)
Block(1,3,-6,18)
Block(1,3,-5,18)
Block(1,3,-4,18)
Block(1,3,-3,18)
Block(1,3,8,45)
Block(1,4,-7,18)
Block(1,4,-6,18)
Block(1,4,-5,18)
Block(1,4,8,45)
Block(1,5,-7,18)
Block(1,5,-6,18)
Block(1,5,6,134:5)
Block(1,5,7,134:6)
Block(1,5,8,17:8)
Block(1,6,-7,18)
Block(1,6,4,134:5)
Block(1,6,5,134:6)
Block(1,6,6,5:1)
Block(1,6,7,5:1)
Block(1,6,8,5:1)
Block(1,7,4,85)
Block(1,7,5,85)
Block(1,11,7,17:4)
Block(1,11,8,85)
Block(2,0,-7,3)
Block(2,0,-6,3)
Block(2,0,-5,3)
Block(2,0,-4,3)
Block(2,0,-3,3)
Block(2,0,-2,3)
Block(2,0,-1,3)
Block(2,0,0,3)
Block(2,0,1,3)
Block(2,0,2,3)
Block(2,0,3,3)
Block(2,0,4,3)
Block(2,0,5,3)
Block(2,0,6,3)
Block(2,0,7,3)
Block(2,0,8,3)
Block(2,1,-7,2)
Block(2,1,-6,2)
Block(2,1,-5,2)
Block(2,1,-4,2)
Block(2,1,-3,2)
Block(2,1,-2,2)
Block(2,1,-1,2)
Block(2,1,0,2)
Block(2,1,1,2)
Block(2,1,2,2)
Block(2,1,3,2)
Block(2,1,4,60:7)
Block(2,1,5,60)
Block(2,1,6,13)
Block(2,1,7,3:2)
Block(2,1,8,3:2)
Block(2,2,4,59:7)
Block(2,2,5,59:7)
Block(2,2,8,38:5)
Block(2,3,-7,18)
Block(2,3,-6,18)
Block(2,4,-7,18)
Block(2,4,-6,18)
Block(2,4,-5,18)
Block(2,5,7,134:5)
Block(2,5,8,134:5)
Block(2,6,5,134:5)
Block(2,6,6,134:6)
Block(2,6,7,5:1)
Block(2,6,8,5:1)
Block(2,7,5,85)
Block(2,7,6,85)
Block(2,8,5,50:5)
Block(3,0,-7,3)
Block(3,0,-6,3)
Block(3,0,-5,3)
Block(3,0,-4,3)
Block(3,0,-3,3)
Block(3,0,-2,3)
Block(3,0,-1,3)
Block(3,0,0,3)
Block(3,0,1,3)
Block(3,0,2,3)
Block(3,0,3,3)
Block(3,0,4,3)
Block(3,0,5,3)
Block(3,0,6,3)
Block(3,0,7,3)
Block(3,0,8,3)
Block(3,1,-7,2)
Block(3,1,-6,2)
Block(3,1,-5,2)
Block(3,1,-4,2)
Block(3,1,-3,2)
Block(3,1,-2,2)
Block(3,1,-1,2)
Block(3,1,0,2)
Block(3,1,1,2)
Block(3,1,2,2)
Block(3,1,3,2)
Block(3,1,4,60:7)
Block(3,1,5,60:7)
Block(3,1,6,13)
Block(3,1,7,13)
Block(3,1,8,126:8)
Block(3,2,4,59:7)
Block(3,2,5,59:7)
Block(3,2,8,85)
Block(3,3,8,85)
Block(3,4,8,85)
Block(3,5,8,85)
Block(3,6,6,134:5)
Block(3,6,7,134:5)
Block(3,6,8,5:1)
Block(3,7,6,85)
Block(3,7,7,85)
Block(4,0,-7,3)
Block(4,0,-6,3)
Block(4,0,-5,3)
Block(4,0,-4,3)
Block(4,0,-3,3)
Block(4,0,-2,3)
Block(4,0,-1,3)
Block(4,0,0,3)
Block(4,0,1,3)
Block(4,0,2,3)
Block(4,0,3,3)
Block(4,0,4,3)
Block(4,0,5,3)
Block(4,0,6,3)
Block(4,0,7,3)
Block(4,0,8,3)
Block(4,1,-7,2)
Block(4,1,-6,2)
Block(4,1,-5,2)
Block(4,1,-4,2)
Block(4,1,-3,2)
Block(4,1,-2,2)
Block(4,1,-1,2)
Block(4,1,0,2)
Block(4,1,1,2)
Block(4,1,2,2)
Block(4,1,3,2)
Block(4,1,4,2)
Block(4,1,5,2)
Block(4,1,6,2)
Block(4,1,7,2)
Block(4,1,8,2)
Block(4,2,5,37)
Block(4,2,6,85)
Block(4,6,7,134:6)
Block(4,6,8,134:5)
Block(4,7,7,85)
Block(4,7,8,85)
Block(4,8,7,50:5)
Block(5,0,-7,3)
Block(5,0,-6,3)
Block(5,0,-5,3)
Block(5,0,-4,3)
Block(5,0,-3,3)
Block(5,0,-2,3)
Block(5,0,-1,3)
Block(5,0,0,3)
Block(5,0,1,3)
Block(5,0,2,3)
Block(5,0,3,3)
Block(5,0,4,3)
Block(5,0,5,3)
Block(5,0,6,3)
Block(5,0,7,3)
Block(5,0,8,3)
Block(5,1,-7,2)
Block(5,1,-6,2)
Block(5,1,-5,2)
Block(5,1,-4,2)
Block(5,1,-3,2)
Block(5,1,-2,2)
Block(5,1,-1,2)
Block(5,1,0,2)
Block(5,1,1,2)
Block(5,1,2,2)
Block(5,1,3,2)
Block(5,1,4,2)
Block(5,1,5,2)
Block(5,1,6,2)
Block(5,1,7,2)
Block(5,1,8,2)
Block(5,2,6,85)
Block(5,2,7,85)
Block(5,3,6,50:5)
Block(6,0,-7,3)
Block(6,0,-6,3)
Block(6,0,-5,3)
Block(6,0,-4,3)
Block(6,0,-3,3)
Block(6,0,-2,3)
Block(6,0,-1,3)
Block(6,0,0,3)
Block(6,0,1,3)
Block(6,0,2,3)
Block(6,0,3,3)
Block(6,0,4,3)
Block(6,0,5,3)
Block(6,0,6,3)
Block(6,0,7,3)
Block(6,0,8,3)
Block(6,1,-7,2)
Block(6,1,-6,2)
Block(6,1,-5,2)
Block(6,1,-4,2)
Block(6,1,-3,2)
Block(6,1,-2,2)
Block(6,1,-1,2)
Block(6,1,0,2)
Block(6,1,1,2)
Block(6,1,2,2)
Block(6,1,3,2)
Block(6,1,4,2)
Block(6,1,5,2)
Block(6,1,6,2)
Block(6,1,7,2)
Block(6,1,8,2)
Block(6,2,7,85)
Block(6,2,8,37)
Block(7,0,-7,3)
Block(7,0,-6,3)
Block(7,0,-5,3)
Block(7,0,-4,3)
Block(7,0,-3,3)
Block(7,0,-2,3)
Block(7,0,-1,3)
Block(7,0,0,3)
Block(7,0,1,3)
Block(7,0,2,3)
Block(7,0,3,3)
Block(7,0,4,3)
Block(7,0,5,3)
Block(7,0,6,3)
Block(7,0,7,3)
Block(7,0,8,3)
Block(7,1,-7,2)
Block(7,1,-6,2)
Block(7,1,-5,2)
Block(7,1,-4,2)
Block(7,1,-3,2)
Block(7,1,-2,2)
Block(7,1,-1,2)
Block(7,1,0,2)
Block(7,1,1,2)
Block(7,1,2,2)
Block(7,1,3,2)
Block(7,1,4,2)
Block(7,1,5,2)
Block(7,1,6,2)
Block(7,1,7,2)
Block(7,1,8,2)
Block(7,2,7,85)
Block(7,2,8,85)
Block(7,3,7,50:5)

Branch(16,0,0,true,monsterley-s-grainC2R0,NORTH,100,0)
