

BranchFrequencyGroup: CanOverride:0

CanOverride: true

SmoothRadius: -1

OverrideChildSettings: false

ReplaceAbove:
ReplaceBelow:

MustBeInside: VillageGeneratorStructurePlaceHolder, VillageGeneratorStructuresDelay, VillageGeneratorStructuresDelay2, VillageGeneratorStructuresDelay3, VillageGeneratorStructuresDelay4, VillageGeneratorStructuresDelay5, VillageGeneratorStructuresDelay6, VillageGeneratorStructuresDelay7, VillageGeneratorStructuresDelay8, VillageGeneratorStructuresDelay9, VillageGeneratorStructuresDelay10

Block(-8,0,-7,3)
Block(-8,0,-6,3)
Block(-8,0,-5,3)
Block(-8,0,-4,3)
Block(-8,0,-3,3)
Block(-8,0,-2,3)
Block(-8,0,-1,3)
Block(-8,0,0,3)
Block(-8,0,1,3)
Block(-8,0,2,3)
Block(-8,0,3,3)
Block(-8,0,4,3)
Block(-8,0,5,3)
Block(-8,0,6,3)
Block(-8,0,7,3)
Block(-8,0,8,3)
Block(-8,1,-7,5:2)
Block(-8,1,-6,5:2)
Block(-8,1,-5,5:2)
Block(-8,1,-4,5:2)
Block(-8,1,-3,5:2)
Block(-8,1,-2,3)
Block(-8,1,-1,2)
Block(-8,1,0,3)
Block(-8,1,1,3)
Block(-8,1,2,3)
Block(-8,1,3,3)
Block(-8,1,4,3)
Block(-8,1,5,3)
Block(-8,1,6,3)
Block(-8,1,7,3)
Block(-8,1,8,3)
Block(-8,2,-2,108:2)
Block(-8,2,0,45)
Block(-8,2,1,45)
Block(-8,2,2,17)
Block(-8,2,3,2)
Block(-8,2,4,13)
Block(-8,2,5,13)
Block(-8,2,6,3)
Block(-8,2,7,3)
Block(-8,2,8,3)
Block(-8,3,-1,108:2)
Block(-8,3,0,45)
Block(-8,3,1,45)
Block(-8,3,2,17)
Block(-8,3,3,37)
Block(-8,3,6,2)
Block(-8,3,7,2)
Block(-8,3,8,2)
Block(-8,4,0,108)
Block(-8,4,1,45)
Block(-8,4,2,17)
Block(-8,4,6,175:2)
Block(-8,5,1,45)
Block(-8,5,2,17:4)
Block(-8,5,3,134:7)
Block(-8,5,4,134:4)
Block(-8,5,6,175:8)
Block(-8,6,-7,5:2)
Block(-8,6,-6,5:2)
Block(-8,6,-5,5:2)
Block(-8,6,-4,5:2)
Block(-8,6,-3,5:2)
Block(-8,6,-2,5:2)
Block(-8,6,-1,5:2)
Block(-8,6,1,45)
Block(-8,6,2,5)
Block(-8,6,3,5:1)
Block(-8,6,4,5:1)
Block(-8,6,5,134:7)
Block(-8,7,1,17)
Block(-8,7,2,17)
Block(-8,7,5,85)
Block(-8,8,1,17)
Block(-8,8,2,17)
Block(-8,9,1,17)
Block(-8,9,2,17)
Block(-8,10,-6,126:10)
Block(-8,10,-5,126:10)
Block(-8,10,-4,126:10)
Block(-8,10,-3,126:10)
Block(-8,10,-2,126:10)
Block(-8,10,0,85)
Block(-8,10,1,17)
Block(-8,10,2,17)
Block(-8,11,-7,5:2)
Block(-8,11,-6,5:2)
Block(-8,11,-5,5:2)
Block(-8,11,-4,5:2)
Block(-8,11,-3,5:2)
Block(-8,11,-2,5:2)
Block(-8,11,-1,5:2)
Block(-8,11,0,5:2)
Block(-8,11,1,17:4)
Block(-8,11,2,17:4)
Block(-8,11,3,17:8)
Block(-8,12,-7,85)
Block(-8,12,-6,170)
Block(-8,12,-4,85)
Block(-8,12,-2,85)
Block(-8,12,-1,65:2)
Block(-8,12,0,17)
Block(-8,12,2,85)
Block(-8,13,-7,85)
Block(-8,13,-4,85)
Block(-8,13,-2,85)
Block(-8,13,-1,65:2)
Block(-8,13,0,17)
Block(-8,14,-7,85)
Block(-8,14,-4,85)
Block(-8,14,-2,85)
Block(-8,14,-1,65:2)
Block(-8,14,0,17)
Block(-8,15,-7,85)
Block(-8,15,-6,85)
Block(-8,15,-5,85)
Block(-8,15,-4,85)
Block(-8,15,-3,85)
Block(-8,15,-2,85)
Block(-8,15,-1,65:2)
Block(-8,15,0,17)
Block(-8,16,-2,85)
Block(-8,16,-1,65:2)
Block(-8,16,0,17)
Block(-8,17,-2,85)
Block(-8,17,-1,65:2)
Block(-8,17,0,17)
Block(-8,18,-7,85)
Block(-8,18,-6,85)
Block(-8,18,-5,85)
Block(-8,18,-4,85)
Block(-8,18,-3,85)
Block(-8,18,-2,85)
Block(-8,18,-1,65:2)
Block(-8,18,0,17)
Block(-8,19,-7,5:2)
Block(-8,19,-6,5:2)
Block(-8,19,-5,5:2)
Block(-8,19,-4,5:2)
Block(-8,19,-3,5:2)
Block(-8,19,-2,5:2)
Block(-8,19,-1,65:2)
Block(-8,19,0,17:4)
Block(-8,19,1,85)
Block(-8,20,-7,170)
Block(-8,20,0,5:1)
Block(-8,20,1,134:3)
Block(-8,21,-7,170)
Block(-8,21,0,134:3)
Block(-8,22,-7,5:1)
Block(-8,22,-1,5:1)
Block(-8,23,-7,5:1)
Block(-8,23,-6,50:3)
Block(-8,23,-2,50:4)
Block(-8,23,-1,5:1)
Block(-8,24,-7,5:1)
Block(-8,24,-1,5:1)
Block(-8,25,-6,5:1)
Block(-8,25,-5,5:1)
Block(-8,25,-4,5:1)
Block(-8,25,-3,5:1)
Block(-8,25,-2,5:1)
Block(-8,26,-5,5:1)
Block(-8,26,-4,17:5)
Block(-8,26,-3,5:1)
Block(-8,27,-5,5:1)
Block(-8,27,-4,5:1)
Block(-8,27,-3,5:1)
Block(-7,0,-7,3)
Block(-7,0,-6,3)
Block(-7,0,-5,3)
Block(-7,0,-4,3)
Block(-7,0,-3,3)
Block(-7,0,-2,3)
Block(-7,0,-1,3)
Block(-7,0,0,3)
Block(-7,0,1,3)
Block(-7,0,2,3)
Block(-7,0,3,3)
Block(-7,0,4,3)
Block(-7,0,5,3)
Block(-7,0,6,3)
Block(-7,0,7,3)
Block(-7,0,8,3)
Block(-7,1,-7,5:2)
Block(-7,1,-6,5:2)
Block(-7,1,-5,5:2)
Block(-7,1,-4,5:2)
Block(-7,1,-3,5:2)
Block(-7,1,-2,3)
Block(-7,1,-1,3)
Block(-7,1,0,3)
Block(-7,1,1,3)
Block(-7,1,2,3)
Block(-7,1,3,3)
Block(-7,1,4,3)
Block(-7,1,5,3)
Block(-7,1,6,3)
Block(-7,1,7,3)
Block(-7,1,8,3)
Block(-7,2,-3,85)
Block(-7,2,-2,17)
Block(-7,2,-1,17)
Block(-7,2,0,35)
Block(-7,2,1,35)
Block(-7,2,2,17)
Block(-7,2,3,98)
Block(-7,2,4,13)
Block(-7,2,5,13)
Block(-7,2,6,3)
Block(-7,2,7,3)
Block(-7,2,8,3)
Block(-7,3,-3,50:5)
Block(-7,3,-2,17)
Block(-7,3,-1,17)
Block(-7,3,0,35)
Block(-7,3,1,35)
Block(-7,3,2,17)
Block(-7,3,3,45)
Block(-7,3,6,2)
Block(-7,3,7,2)
Block(-7,3,8,2)
Block(-7,4,-2,17)
Block(-7,4,-1,17)
Block(-7,4,1,35)
Block(-7,4,2,17)
Block(-7,4,3,45)
Block(-7,4,6,85)
Block(-7,4,7,85)
Block(-7,5,-4,50:4)
Block(-7,5,-3,17:8)
Block(-7,5,-2,17)
Block(-7,5,-1,50:5)
Block(-7,5,0,108)
Block(-7,5,1,45)
Block(-7,5,2,17)
Block(-7,5,3,17:4)
Block(-7,5,4,134:7)
Block(-7,6,-7,5:2)
Block(-7,6,-6,5:2)
Block(-7,6,-5,5:2)
Block(-7,6,-4,85)
Block(-7,6,-3,5:2)
Block(-7,6,-2,5:2)
Block(-7,6,-1,5:2)
Block(-7,6,1,108:1)
Block(-7,6,2,45)
Block(-7,6,3,5:1)
Block(-7,6,4,5:1)
Block(-7,6,5,134:7)
Block(-7,7,2,45)
Block(-7,7,5,85)
Block(-7,8,2,45)
Block(-7,9,2,45)
Block(-7,10,-7,126:10)
Block(-7,10,-6,126:10)
Block(-7,10,-5,126:10)
Block(-7,10,-4,126:10)
Block(-7,10,-3,126:10)
Block(-7,10,-2,126:10)
Block(-7,10,-1,126:10)
Block(-7,10,1,85)
Block(-7,10,2,45)
Block(-7,11,-7,5:2)
Block(-7,11,-6,5:2)
Block(-7,11,-5,5:2)
Block(-7,11,-4,5:2)
Block(-7,11,-3,5:2)
Block(-7,11,-2,5:2)
Block(-7,11,-1,5:2)
Block(-7,11,0,5:2)
Block(-7,11,1,17:4)
Block(-7,11,2,17:4)
Block(-7,11,3,85)
Block(-7,12,-7,170)
Block(-7,12,-1,85)
Block(-7,12,0,45)
Block(-7,12,2,85)
Block(-7,13,-7,170:4)
Block(-7,13,-1,85)
Block(-7,13,0,45)
Block(-7,14,-7,170)
Block(-7,14,-2,85)
Block(-7,14,-1,85)
Block(-7,14,0,45)
Block(-7,15,-7,85)
Block(-7,15,-2,85)
Block(-7,15,-1,85)
Block(-7,15,0,45)
Block(-7,16,-2,85)
Block(-7,16,-1,85)
Block(-7,16,0,45)
Block(-7,17,-2,85)
Block(-7,17,-1,85)
Block(-7,17,0,45)
Block(-7,18,-7,85)
Block(-7,18,-2,85)
Block(-7,18,-1,85)
Block(-7,18,0,45)
Block(-7,19,-7,5:2)
Block(-7,19,-6,5:2)
Block(-7,19,-5,5:2)
Block(-7,19,-4,85)
Block(-7,19,-3,5:2)
Block(-7,19,-2,5:2)
Block(-7,19,-1,5:2)
Block(-7,19,0,17:4)
Block(-7,19,1,85)
Block(-7,20,-7,170)
Block(-7,20,0,5:1)
Block(-7,20,1,134:3)
Block(-7,21,-7,170:8)
Block(-7,21,0,5:1)
Block(-7,22,-7,170:4)
Block(-7,22,0,5:1)
Block(-7,23,-7,50:1)
Block(-7,23,-1,50:1)
Block(-7,23,0,5:1)
Block(-7,24,-7,5:1)
Block(-7,24,-1,5:1)
Block(-7,24,0,5:1)
Block(-7,25,-6,5:1)
Block(-7,25,-2,5:1)
Block(-7,26,-5,5:1)
Block(-7,26,-4,17:5)
Block(-7,26,-3,5:1)
Block(-7,27,-5,5:1)
Block(-7,27,-4,5:1)
Block(-7,27,-3,5:1)
Block(-6,0,-7,3)
Block(-6,0,-6,35)
Block(-6,0,-5,60)
Block(-6,0,-4,60)
Block(-6,0,-3,35)
Block(-6,0,-2,3)
Block(-6,0,-1,3)
Block(-6,0,0,3)
Block(-6,0,1,3)
Block(-6,0,2,3)
Block(-6,0,3,3)
Block(-6,0,4,3)
Block(-6,0,5,3)
Block(-6,0,6,3)
Block(-6,0,7,3)
Block(-6,0,8,3)
Block(-6,1,-7,5:2)
Block(-6,1,-5,59:7)
Block(-6,1,-4,59:7)
Block(-6,1,-2,5:2)
Block(-6,1,-1,5:2)
Block(-6,1,0,5:2)
Block(-6,1,1,5:2)
Block(-6,1,2,5:2)
Block(-6,1,3,3)
Block(-6,1,4,3)
Block(-6,1,5,3)
Block(-6,1,6,3)
Block(-6,1,7,3)
Block(-6,1,8,3)
Block(-6,2,-2,85)
Block(-6,2,-1,170)
Block(-6,2,2,170)
Block(-6,2,3,17)
Block(-6,2,4,13)
Block(-6,2,5,13)
Block(-6,2,6,3)
Block(-6,2,7,3)
Block(-6,2,8,3)
Block(-6,3,-4,143:2)
Block(-6,3,-2,50:5)
Block(-6,3,2,170)
Block(-6,3,3,45)
Block(-6,3,6,17)
Block(-6,3,7,2)
Block(-6,3,8,2)
Block(-6,4,2,170)
Block(-6,4,3,45)
Block(-6,4,6,17)
Block(-6,4,7,85)
Block(-6,4,8,31:1)
Block(-6,5,-3,50:4)
Block(-6,5,-2,17:8)
Block(-6,5,-1,17:8)
Block(-6,5,0,17:8)
Block(-6,5,1,17:8)
Block(-6,5,2,17:8)
Block(-6,5,3,17:4)
Block(-6,5,4,17:8)
Block(-6,5,5,17:8)
Block(-6,5,6,17)
Block(-6,6,-7,5:2)
Block(-6,6,-6,5:2)
Block(-6,6,-5,85)
Block(-6,6,-3,85)
Block(-6,6,-2,5:2)
Block(-6,6,-1,5:2)
Block(-6,6,0,108)
Block(-6,6,1,108:2)
Block(-6,6,2,45)
Block(-6,6,3,5:1)
Block(-6,6,4,5:1)
Block(-6,6,5,5:1)
Block(-6,6,6,17)
Block(-6,7,2,45)
Block(-6,7,5,85)
Block(-6,7,6,85)
Block(-6,8,2,45)
Block(-6,8,5,50:5)
Block(-6,9,2,45)
Block(-6,10,-7,126:10)
Block(-6,10,-6,126:10)
Block(-6,10,-2,126:10)
Block(-6,10,-1,126:10)
Block(-6,10,1,85)
Block(-6,10,2,45)
Block(-6,11,-7,5:2)
Block(-6,11,-6,5:2)
Block(-6,11,-5,85)
Block(-6,11,-3,85)
Block(-6,11,-2,5:2)
Block(-6,11,-1,5:2)
Block(-6,11,0,5:2)
Block(-6,11,1,17:4)
Block(-6,11,2,17:4)
Block(-6,11,3,85)
Block(-6,12,-5,85)
Block(-6,12,-3,85)
Block(-6,12,0,45)
Block(-6,12,2,85)
Block(-6,13,-5,50:5)
Block(-6,13,-3,50:5)
Block(-6,13,0,102)
Block(-6,14,0,102)
Block(-6,15,-7,85)
Block(-6,15,-1,85)
Block(-6,15,0,45)
Block(-6,16,0,102)
Block(-6,17,0,102)
Block(-6,18,-7,85)
Block(-6,18,-1,85)
Block(-6,18,0,45)
Block(-6,19,-7,5:2)
Block(-6,19,-6,5:2)
Block(-6,19,-5,85)
Block(-6,19,-3,85)
Block(-6,19,-2,5:2)
Block(-6,19,-1,5:2)
Block(-6,19,0,17:4)
Block(-6,19,1,85)
Block(-6,20,0,5:1)
Block(-6,20,1,134:3)
Block(-6,21,0,102)
Block(-6,22,0,5:1)
Block(-6,23,0,5:1)
Block(-6,24,-7,5:1)
Block(-6,24,-1,5:1)
Block(-6,24,0,5:1)
Block(-6,25,-6,5:1)
Block(-6,25,-2,5:1)
Block(-6,26,-5,5:1)
Block(-6,26,-4,17:5)
Block(-6,26,-3,5:1)
Block(-6,27,-5,5:1)
Block(-6,27,-4,3)
Block(-6,27,-3,5:1)
Block(-6,28,-5,134:2)
Block(-6,28,-4,134)
Block(-6,28,-3,134)
Block(-5,0,-7,3)
Block(-5,0,-6,35)
Block(-5,0,-5,60)
Block(-5,0,-4,60)
Block(-5,0,-3,35)
Block(-5,0,-2,3)
Block(-5,0,-1,3)
Block(-5,0,0,3)
Block(-5,0,1,3)
Block(-5,0,2,3)
Block(-5,0,3,3)
Block(-5,0,4,3)
Block(-5,0,5,3)
Block(-5,0,6,3)
Block(-5,0,7,3)
Block(-5,0,8,3)
Block(-5,1,-7,5:2)
Block(-5,1,-5,59:7)
Block(-5,1,-4,59:7)
Block(-5,1,-2,5:2)
Block(-5,1,-1,5:2)
Block(-5,1,0,5:2)
Block(-5,1,1,5:2)
Block(-5,1,2,5:2)
Block(-5,1,3,3)
Block(-5,1,4,3)
Block(-5,1,5,3)
Block(-5,1,6,3)
Block(-5,1,7,3)
Block(-5,1,8,3)
Block(-5,2,-4,33)
Block(-5,2,-2,85)
Block(-5,2,2,35)
Block(-5,2,3,17)
Block(-5,2,4,13)
Block(-5,2,5,13)
Block(-5,2,6,3)
Block(-5,2,7,3)
Block(-5,2,8,3)
Block(-5,3,-4,17:1)
Block(-5,3,2,170)
Block(-5,3,3,45)
Block(-5,3,6,17)
Block(-5,3,7,3)
Block(-5,3,8,2)
Block(-5,4,-4,17:1)
Block(-5,4,2,170)
Block(-5,4,3,45)
Block(-5,4,6,50:5)
Block(-5,4,7,134:3)
Block(-5,5,-4,17:1)
Block(-5,5,2,170:8)
Block(-5,5,3,17:4)
Block(-5,5,4,17:8)
Block(-5,5,5,17:8)
Block(-5,5,6,134:3)
Block(-5,6,-7,5:2)
Block(-5,6,-6,85)
Block(-5,6,-4,17:1)
Block(-5,6,-2,85)
Block(-5,6,-1,5:2)
Block(-5,6,0,5:2)
Block(-5,6,1,5:2)
Block(-5,6,2,45)
Block(-5,6,3,5:1)
Block(-5,6,4,5:1)
Block(-5,6,5,134:3)
Block(-5,7,-4,17:1)
Block(-5,7,2,193:3)
Block(-5,7,3,72)
Block(-5,8,-4,17:1)
Block(-5,8,2,193:8)
Block(-5,9,-4,17:1)
Block(-5,9,2,45)
Block(-5,10,-7,126:10)
Block(-5,10,-6,126:10)
Block(-5,10,-4,17:1)
Block(-5,10,-2,126:10)
Block(-5,10,-1,126:10)
Block(-5,10,1,85)
Block(-5,10,2,45)
Block(-5,11,-7,5:2)
Block(-5,11,-6,5:2)
Block(-5,11,-4,17:1)
Block(-5,11,-2,5:2)
Block(-5,11,-1,5:2)
Block(-5,11,0,5:2)
Block(-5,11,1,17:4)
Block(-5,11,2,17:4)
Block(-5,11,3,85)
Block(-5,12,-4,17:1)
Block(-5,12,-1,85)
Block(-5,12,0,45)
Block(-5,12,2,85)
Block(-5,13,-4,17:1)
Block(-5,13,-1,85)
Block(-5,13,0,45)
Block(-5,14,-4,17:1)
Block(-5,14,-1,85)
Block(-5,14,0,45)
Block(-5,15,-7,85)
Block(-5,15,-4,17:1)
Block(-5,15,-1,85)
Block(-5,15,0,45)
Block(-5,16,-4,17:1)
Block(-5,16,0,45)
Block(-5,17,-4,17:1)
Block(-5,17,0,45)
Block(-5,18,-7,85)
Block(-5,18,-4,17:1)
Block(-5,18,-1,85)
Block(-5,18,0,45)
Block(-5,19,-7,5:2)
Block(-5,19,-6,85)
Block(-5,19,-4,17:1)
Block(-5,19,-2,85)
Block(-5,19,-1,5:2)
Block(-5,19,0,17:4)
Block(-5,19,1,85)
Block(-5,20,-4,17:1)
Block(-5,20,0,5:1)
Block(-5,20,1,134:3)
Block(-5,21,-4,17:1)
Block(-5,21,0,102)
Block(-5,22,-4,17:1)
Block(-5,22,0,102)
Block(-5,23,-4,17:1)
Block(-5,23,0,5:1)
Block(-5,24,-7,5:1)
Block(-5,24,-4,17:1)
Block(-5,24,-1,5:1)
Block(-5,24,0,5:1)
Block(-5,25,-6,5:1)
Block(-5,25,-4,17:1)
Block(-5,25,-2,5:1)
Block(-5,26,-5,5:1)
Block(-5,26,-4,17:1)
Block(-5,26,-3,5:1)
Block(-5,27,-5,5:1)
Block(-5,27,-4,3)
Block(-5,27,-3,5:1)
Block(-5,28,-5,134:2)
Block(-5,28,-4,3)
Block(-5,28,-3,134:3)
Block(-5,29,-4,5:1)
Block(-4,0,-7,3)
Block(-4,0,-6,35)
Block(-4,0,-5,60)
Block(-4,0,-4,60)
Block(-4,0,-3,35)
Block(-4,0,-2,3)
Block(-4,0,-1,3)
Block(-4,0,0,3)
Block(-4,0,1,3)
Block(-4,0,2,3)
Block(-4,0,3,3)
Block(-4,0,4,3)
Block(-4,0,5,3)
Block(-4,0,6,3)
Block(-4,0,7,3)
Block(-4,0,8,3)
Block(-4,1,-7,5:2)
Block(-4,1,-5,59:7)
Block(-4,1,-4,59:7)
Block(-4,1,-2,5:2)
Block(-4,1,-1,5:2)
Block(-4,1,0,5:2)
Block(-4,1,1,5:2)
Block(-4,1,2,5:2)
Block(-4,1,3,3)
Block(-4,1,4,3)
Block(-4,1,5,3)
Block(-4,1,6,3)
Block(-4,1,7,3)
Block(-4,1,8,3)
Block(-4,2,-2,85)
Block(-4,2,2,35)
Block(-4,2,3,17)
Block(-4,2,4,13)
Block(-4,2,5,13)
Block(-4,2,6,3)
Block(-4,2,7,3)
Block(-4,2,8,3)
Block(-4,3,2,170:4)
Block(-4,3,3,45)
Block(-4,3,6,17)
Block(-4,3,7,2)
Block(-4,3,8,2)
Block(-4,4,3,45)
Block(-4,4,6,17)
Block(-4,4,7,85)
Block(-4,5,3,17:4)
Block(-4,5,4,17:8)
Block(-4,5,5,17:8)
Block(-4,5,6,17)
Block(-4,6,-7,5:2)
Block(-4,6,-6,5:2)
Block(-4,6,-5,85)
Block(-4,6,-3,85)
Block(-4,6,-2,5:2)
Block(-4,6,-1,5:2)
Block(-4,6,0,5:2)
Block(-4,6,1,5:2)
Block(-4,6,2,45)
Block(-4,6,3,5:1)
Block(-4,6,4,5:1)
Block(-4,6,5,5:1)
Block(-4,6,6,17)
Block(-4,7,2,45)
Block(-4,7,5,85)
Block(-4,7,6,85)
Block(-4,8,2,45)
Block(-4,8,5,50:5)
Block(-4,9,2,45)
Block(-4,10,-7,126:10)
Block(-4,10,-6,126:10)
Block(-4,10,-2,126:10)
Block(-4,10,-1,126:10)
Block(-4,10,1,85)
Block(-4,10,2,45)
Block(-4,11,-7,5:2)
Block(-4,11,-6,5:2)
Block(-4,11,-5,85)
Block(-4,11,-3,85)
Block(-4,11,-2,5:2)
Block(-4,11,-1,5:2)
Block(-4,11,0,5:2)
Block(-4,11,1,17:4)
Block(-4,11,2,17:4)
Block(-4,11,3,85)
Block(-4,12,-5,85)
Block(-4,12,-3,85)
Block(-4,12,-1,170:8)
Block(-4,12,0,45)
Block(-4,12,2,85)
Block(-4,13,-5,50:5)
Block(-4,13,-3,50:5)
Block(-4,13,0,102)
Block(-4,14,0,102)
Block(-4,15,-7,85)
Block(-4,15,-1,85)
Block(-4,15,0,45)
Block(-4,16,0,102)
Block(-4,17,0,102)
Block(-4,18,-7,85)
Block(-4,18,-1,85)
Block(-4,18,0,45)
Block(-4,19,-7,5:2)
Block(-4,19,-6,5:2)
Block(-4,19,-5,85)
Block(-4,19,-3,85)
Block(-4,19,-2,5:2)
Block(-4,19,-1,5:2)
Block(-4,19,0,17:4)
Block(-4,19,1,85)
Block(-4,20,0,5:1)
Block(-4,20,1,134:3)
Block(-4,21,0,102)
Block(-4,22,0,5:1)
Block(-4,23,0,5:1)
Block(-4,24,-7,5:1)
Block(-4,24,-1,5:1)
Block(-4,24,0,5:1)
Block(-4,25,-6,5:1)
Block(-4,25,-2,5:1)
Block(-4,26,-5,5:1)
Block(-4,26,-4,5:1)
Block(-4,26,-3,5:1)
Block(-4,27,-5,5:1)
Block(-4,27,-4,50:5)
Block(-4,27,-3,5:1)
Block(-4,28,-5,134:1)
Block(-4,28,-4,134:1)
Block(-4,28,-3,134:3)
Block(-3,0,-7,3)
Block(-3,0,-6,35)
Block(-3,0,-5,35)
Block(-3,0,-4,35)
Block(-3,0,-3,35)
Block(-3,0,-2,3)
Block(-3,0,-1,3)
Block(-3,0,0,3)
Block(-3,0,1,3)
Block(-3,0,2,3)
Block(-3,0,3,3)
Block(-3,0,4,3)
Block(-3,0,5,3)
Block(-3,0,6,3)
Block(-3,0,7,1)
Block(-3,0,8,1)
Block(-3,1,-7,5:2)
Block(-3,1,-2,5:2)
Block(-3,1,-1,5:2)
Block(-3,1,0,5:2)
Block(-3,1,1,5:2)
Block(-3,1,2,5:2)
Block(-3,1,3,3)
Block(-3,1,4,3)
Block(-3,1,5,3)
Block(-3,1,6,3)
Block(-3,1,7,3)
Block(-3,1,8,3)
Block(-3,2,-2,85)
Block(-3,2,2,35)
Block(-3,2,3,17)
Block(-3,2,4,13)
Block(-3,2,5,13)
Block(-3,2,6,3)
Block(-3,2,7,3)
Block(-3,2,8,3)
Block(-3,3,2,35)
Block(-3,3,3,45)
Block(-3,3,6,2)
Block(-3,3,7,2)
Block(-3,3,8,2)
Block(-3,4,2,170:8)
Block(-3,4,3,45)
Block(-3,4,6,85)
Block(-3,4,7,85)
Block(-3,5,1,50:4)
Block(-3,5,2,17:8)
Block(-3,5,3,17:4)
Block(-3,5,4,134:7)
Block(-3,6,-7,5:2)
Block(-3,6,-6,5:2)
Block(-3,6,-5,5:2)
Block(-3,6,-4,85)
Block(-3,6,-3,5:2)
Block(-3,6,-2,5:2)
Block(-3,6,-1,5:2)
Block(-3,6,0,5:2)
Block(-3,6,1,5:2)
Block(-3,6,2,45)
Block(-3,6,3,5:1)
Block(-3,6,4,5:1)
Block(-3,6,5,134:7)
Block(-3,7,-5,85)
Block(-3,7,-4,85)
Block(-3,7,-3,85)
Block(-3,7,-2,85)
Block(-3,7,2,45)
Block(-3,7,5,85)
Block(-3,8,-5,85)
Block(-3,8,-4,85)
Block(-3,8,-3,85)
Block(-3,8,-2,85)
Block(-3,8,2,45)
Block(-3,9,-5,85)
Block(-3,9,-4,85)
Block(-3,9,-3,85)
Block(-3,9,-2,50:5)
Block(-3,9,2,45)
Block(-3,10,-7,126:10)
Block(-3,10,-6,126:10)
Block(-3,10,-5,85)
Block(-3,10,-4,85)
Block(-3,10,-3,50:5)
Block(-3,10,-2,126:10)
Block(-3,10,-1,126:10)
Block(-3,10,1,85)
Block(-3,10,2,45)
Block(-3,11,-7,44:4)
Block(-3,11,-6,44:4)
Block(-3,11,-5,5:2)
Block(-3,11,-4,5:2)
Block(-3,11,-3,5:2)
Block(-3,11,-2,5:2)
Block(-3,11,-1,5:2)
Block(-3,11,0,5:2)
Block(-3,11,1,17:4)
Block(-3,11,2,17:4)
Block(-3,11,3,85)
Block(-3,12,-1,170)
Block(-3,12,0,45)
Block(-3,12,2,85)
Block(-3,13,0,45)
Block(-3,14,0,45)
Block(-3,15,-7,85)
Block(-3,15,-1,85)
Block(-3,15,0,45)
Block(-3,16,0,45)
Block(-3,17,0,45)
Block(-3,18,-7,85)
Block(-3,18,-1,85)
Block(-3,18,0,45)
Block(-3,19,-7,5:2)
Block(-3,19,-6,5:2)
Block(-3,19,-5,5:2)
Block(-3,19,-4,85)
Block(-3,19,-3,5:2)
Block(-3,19,-2,5:2)
Block(-3,19,-1,5:2)
Block(-3,19,0,17:4)
Block(-3,19,1,85)
Block(-3,20,-7,170)
Block(-3,20,-1,170)
Block(-3,20,0,5:1)
Block(-3,20,1,134:3)
Block(-3,21,0,5:1)
Block(-3,22,0,5:1)
Block(-3,23,-7,50:2)
Block(-3,23,-1,50:2)
Block(-3,23,0,5:1)
Block(-3,24,-7,5:1)
Block(-3,24,-1,5:1)
Block(-3,24,0,5:1)
Block(-3,25,-6,5:1)
Block(-3,25,-2,5:1)
Block(-3,26,-5,5:1)
Block(-3,26,-4,5:1)
Block(-3,26,-3,5:1)
Block(-2,0,-7,3)
Block(-2,0,-6,3)
Block(-2,0,-5,3)
Block(-2,0,-4,3)
Block(-2,0,-3,3)
Block(-2,0,-2,3)
Block(-2,0,-1,3)
Block(-2,0,0,3)
Block(-2,0,1,3)
Block(-2,0,2,3)
Block(-2,0,3,3)
Block(-2,0,4,3)
Block(-2,0,5,3)
Block(-2,0,6,3)
Block(-2,0,7,1)
Block(-2,0,8,1)
Block(-2,1,-7,5:2)
Block(-2,1,-6,5:2)
Block(-2,1,-5,5:2)
Block(-2,1,-4,5:2)
Block(-2,1,-3,5:2)
Block(-2,1,-2,5:2)
Block(-2,1,-1,5:2)
Block(-2,1,0,5:2)
Block(-2,1,1,5:2)
Block(-2,1,2,3)
Block(-2,1,3,3)
Block(-2,1,4,3)
Block(-2,1,5,3)
Block(-2,1,6,3)
Block(-2,1,7,3)
Block(-2,1,8,1)
Block(-2,2,-6,85)
Block(-2,2,-5,85)
Block(-2,2,-4,85)
Block(-2,2,-3,85)
Block(-2,2,-2,85)
Block(-2,2,2,17)
Block(-2,2,3,3:2)
Block(-2,2,4,13)
Block(-2,2,5,13)
Block(-2,2,6,3)
Block(-2,2,7,3)
Block(-2,2,8,3)
Block(-2,3,-6,50:5)
Block(-2,3,-2,50:5)
Block(-2,3,2,17)
Block(-2,3,3,38:3)
Block(-2,3,6,2)
Block(-2,3,7,2)
Block(-2,3,8,3)
Block(-2,4,2,17)
Block(-2,4,8,2)
Block(-2,5,0,50:4)
Block(-2,5,1,17:8)
Block(-2,5,2,17:4)
Block(-2,5,3,134:7)
Block(-2,5,4,134:5)
Block(-2,6,-7,5:2)
Block(-2,6,-6,5:2)
Block(-2,6,-5,5:2)
Block(-2,6,-4,5:2)
Block(-2,6,-3,5:2)
Block(-2,6,-2,5:2)
Block(-2,6,-1,5:2)
Block(-2,6,0,5:2)
Block(-2,6,1,5:2)
Block(-2,6,2,5)
Block(-2,6,3,5:1)
Block(-2,6,4,5:1)
Block(-2,6,5,134:7)
Block(-2,7,-5,85)
Block(-2,7,-2,108:3)
Block(-2,7,1,17)
Block(-2,7,2,17)
Block(-2,7,5,85)
Block(-2,8,-5,85)
Block(-2,8,-3,108:3)
Block(-2,8,1,17)
Block(-2,8,2,17)
Block(-2,9,-5,85)
Block(-2,9,-4,108:3)
Block(-2,9,1,17)
Block(-2,9,2,17)
Block(-2,10,-7,126:10)
Block(-2,10,-6,126:10)
Block(-2,10,-5,108:3)
Block(-2,10,0,85)
Block(-2,10,1,17)
Block(-2,10,2,17)
Block(-2,11,-7,44:4)
Block(-2,11,-6,44:4)
Block(-2,11,-2,5:2)
Block(-2,11,-1,5:2)
Block(-2,11,0,5:2)
Block(-2,11,1,17:4)
Block(-2,11,2,17:4)
Block(-2,11,3,17:8)
Block(-2,12,-2,170)
Block(-2,12,-1,85)
Block(-2,12,0,17)
Block(-2,12,2,85)
Block(-2,13,-2,170:4)
Block(-2,13,-1,85)
Block(-2,13,0,17)
Block(-2,14,-2,170:4)
Block(-2,14,-1,85)
Block(-2,14,0,17)
Block(-2,15,-7,85)
Block(-2,15,-6,85)
Block(-2,15,-5,85)
Block(-2,15,-4,85)
Block(-2,15,-3,85)
Block(-2,15,-2,85)
Block(-2,15,-1,85)
Block(-2,15,0,17)
Block(-2,16,0,17)
Block(-2,17,0,17)
Block(-2,18,-7,85)
Block(-2,18,-6,85)
Block(-2,18,-5,85)
Block(-2,18,-4,85)
Block(-2,18,-3,85)
Block(-2,18,-2,85)
Block(-2,18,-1,85)
Block(-2,18,0,17)
Block(-2,19,-7,5:2)
Block(-2,19,-6,5:2)
Block(-2,19,-5,5:2)
Block(-2,19,-4,5:2)
Block(-2,19,-3,5:2)
Block(-2,19,-2,5:2)
Block(-2,19,-1,5:2)
Block(-2,19,0,17:4)
Block(-2,19,1,85)
Block(-2,20,-7,170:8)
Block(-2,20,-6,170:4)
Block(-2,20,-1,170)
Block(-2,20,0,5:1)
Block(-2,20,1,134:3)
Block(-2,21,-7,170)
Block(-2,21,-6,170)
Block(-2,21,0,134:3)
Block(-2,22,-7,5:1)
Block(-2,22,-6,170:4)
Block(-2,22,-1,5:1)
Block(-2,23,-7,5:1)
Block(-2,23,-6,50:3)
Block(-2,23,-2,50:4)
Block(-2,23,-1,5:1)
Block(-2,24,-7,5:1)
Block(-2,24,-1,5:1)
Block(-2,25,-6,5:1)
Block(-2,25,-5,5:1)
Block(-2,25,-4,5:1)
Block(-2,25,-3,5:1)
Block(-2,25,-2,5:1)
Block(-1,0,-7,3)
Block(-1,0,-6,3)
Block(-1,0,-5,3)
Block(-1,0,-4,3)
Block(-1,0,-3,3)
Block(-1,0,-2,3)
Block(-1,0,-1,3)
Block(-1,0,0,3)
Block(-1,0,1,3)
Block(-1,0,2,3)
Block(-1,0,3,3)
Block(-1,0,4,3)
Block(-1,0,5,3)
Block(-1,0,6,1)
Block(-1,0,7,1)
Block(-1,0,8,1)
Block(-1,1,-7,5:2)
Block(-1,1,-6,5:2)
Block(-1,1,-5,5:2)
Block(-1,1,-4,5:2)
Block(-1,1,-3,5:2)
Block(-1,1,-2,5:2)
Block(-1,1,-1,5:2)
Block(-1,1,0,5:2)
Block(-1,1,1,5:2)
Block(-1,1,2,3)
Block(-1,1,3,3)
Block(-1,1,4,3)
Block(-1,1,5,3)
Block(-1,1,6,3)
Block(-1,1,7,3)
Block(-1,1,8,1)
Block(-1,2,2,17)
Block(-1,2,3,3:2)
Block(-1,2,4,5)
Block(-1,2,5,13)
Block(-1,2,6,3)
Block(-1,2,7,3)
Block(-1,2,8,3)
Block(-1,3,2,45)
Block(-1,3,3,38:5)
Block(-1,3,4,85)
Block(-1,3,6,2)
Block(-1,3,7,2)
Block(-1,3,8,3)
Block(-1,4,2,45)
Block(-1,4,4,85)
Block(-1,4,8,2)
Block(-1,5,1,85)
Block(-1,5,2,17:4)
Block(-1,5,3,134:7)
Block(-1,5,4,85)
Block(-1,6,-7,5:2)
Block(-1,6,-6,5:2)
Block(-1,6,-5,5:2)
Block(-1,6,-4,5:2)
Block(-1,6,-3,5:2)
Block(-1,6,-2,5:2)
Block(-1,6,-1,5:2)
Block(-1,6,0,5:2)
Block(-1,6,1,5:2)
Block(-1,6,2,5:1)
Block(-1,6,3,5:1)
Block(-1,6,4,5:1)
Block(-1,6,5,134:7)
Block(-1,7,-5,85)
Block(-1,7,-4,85)
Block(-1,7,-3,85)
Block(-1,7,-2,85)
Block(-1,7,0,17)
Block(-1,7,1,45)
Block(-1,7,5,85)
Block(-1,8,-5,85)
Block(-1,8,-4,85)
Block(-1,8,-3,85)
Block(-1,8,-2,85)
Block(-1,8,0,17)
Block(-1,8,1,45)
Block(-1,9,-5,85)
Block(-1,9,-4,85)
Block(-1,9,-2,50:5)
Block(-1,9,0,17)
Block(-1,9,1,45)
Block(-1,10,-7,85)
Block(-1,10,-5,85)
Block(-1,10,-4,50:5)
Block(-1,10,-1,85)
Block(-1,10,0,17)
Block(-1,10,1,45)
Block(-1,11,-7,5:2)
Block(-1,11,-6,5:2)
Block(-1,11,-5,5:2)
Block(-1,11,-4,5:2)
Block(-1,11,-3,5:2)
Block(-1,11,-2,5:2)
Block(-1,11,-1,5:2)
Block(-1,11,0,5)
Block(-1,11,1,17:4)
Block(-1,11,2,85)
Block(-1,12,-7,17)
Block(-1,12,-6,45)
Block(-1,12,-5,45)
Block(-1,12,-4,45)
Block(-1,12,-3,45)
Block(-1,12,-2,45)
Block(-1,12,-1,17)
Block(-1,12,1,85)
Block(-1,13,-7,17)
Block(-1,13,-6,45)
Block(-1,13,-5,102)
Block(-1,13,-4,45)
Block(-1,13,-3,102)
Block(-1,13,-2,45)
Block(-1,13,-1,17)
Block(-1,14,-7,17)
Block(-1,14,-6,45)
Block(-1,14,-5,102)
Block(-1,14,-4,45)
Block(-1,14,-3,102)
Block(-1,14,-2,45)
Block(-1,14,-1,17)
Block(-1,15,-7,17)
Block(-1,15,-6,45)
Block(-1,15,-5,45)
Block(-1,15,-4,45)
Block(-1,15,-3,45)
Block(-1,15,-2,45)
Block(-1,15,-1,17)
Block(-1,16,-7,17)
Block(-1,16,-6,45)
Block(-1,16,-5,102)
Block(-1,16,-4,45)
Block(-1,16,-3,102)
Block(-1,16,-2,45)
Block(-1,16,-1,17)
Block(-1,17,-7,17)
Block(-1,17,-6,45)
Block(-1,17,-5,102)
Block(-1,17,-4,45)
Block(-1,17,-3,102)
Block(-1,17,-2,45)
Block(-1,17,-1,17)
Block(-1,18,-7,17)
Block(-1,18,-6,45)
Block(-1,18,-5,45)
Block(-1,18,-4,45)
Block(-1,18,-3,45)
Block(-1,18,-2,45)
Block(-1,18,-1,17)
Block(-1,19,-7,17:8)
Block(-1,19,-6,17:8)
Block(-1,19,-5,17:8)
Block(-1,19,-4,17:8)
Block(-1,19,-3,17:8)
Block(-1,19,-2,17:8)
Block(-1,19,-1,17:8)
Block(-1,19,0,17:8)
Block(-1,19,1,17:8)
Block(-1,20,-7,5:1)
Block(-1,20,-6,5:1)
Block(-1,20,-5,5:1)
Block(-1,20,-4,5:1)
Block(-1,20,-3,5:1)
Block(-1,20,-2,5:1)
Block(-1,20,-1,5:1)
Block(-1,20,0,5:1)
Block(-1,20,1,134:3)
Block(-1,21,-7,134:1)
Block(-1,21,-6,5:1)
Block(-1,21,-5,102)
Block(-1,21,-4,102)
Block(-1,21,-3,102)
Block(-1,21,-2,5:1)
Block(-1,21,-1,134:1)
Block(-1,21,0,134:3)
Block(-1,22,-6,5:1)
Block(-1,22,-5,5:1)
Block(-1,22,-4,102)
Block(-1,22,-3,5:1)
Block(-1,22,-2,5:1)
Block(-1,23,-6,5:1)
Block(-1,23,-5,5:1)
Block(-1,23,-4,5:1)
Block(-1,23,-3,5:1)
Block(-1,23,-2,5:1)
Block(-1,24,-6,5:1)
Block(-1,24,-5,5:1)
Block(-1,24,-4,5:1)
Block(-1,24,-3,5:1)
Block(-1,24,-2,5:1)
Block(0,0,-7,3)
Block(0,0,-6,3)
Block(0,0,-5,3)
Block(0,0,-4,3)
Block(0,0,-3,3)
Block(0,0,-2,3)
Block(0,0,-1,3)
Block(0,0,0,3)
Block(0,0,1,3)
Block(0,0,2,3)
Block(0,0,3,3)
Block(0,0,4,3)
Block(0,0,5,1)
Block(0,0,6,1)
Block(0,0,7,1)
Block(0,0,8,1)
Block(0,1,-7,5:2)
Block(0,1,-6,5:2)
Block(0,1,-5,5:2)
Block(0,1,-4,5:2)
Block(0,1,-3,5:2)
Block(0,1,-2,5:2)
Block(0,1,-1,5:2)
Block(0,1,0,5:2)
Block(0,1,1,3)
Block(0,1,2,3)
Block(0,1,3,3)
Block(0,1,4,3)
Block(0,1,5,3)
Block(0,1,6,3)
Block(0,1,7,1)
Block(0,1,8,1)
Block(0,2,-7,35)
Block(0,2,-1,58)
Block(0,2,0,54:4,1-Chest.nbt)
Block(0,2,1,17)
Block(0,2,2,3:2)
Block(0,2,3,3:2)
Block(0,2,4,13)
Block(0,2,5,2)
Block(0,2,6,3)
Block(0,2,7,3)
Block(0,2,8,3)
Block(0,3,1,17)
Block(0,3,2,175:5)
Block(0,3,3,37)
Block(0,3,6,2)
Block(0,3,7,3)
Block(0,3,8,3)
Block(0,4,1,17)
Block(0,4,2,175:8)
Block(0,4,7,2)
Block(0,4,8,2)
Block(0,5,-7,50:3)
Block(0,5,-1,50:4)
Block(0,5,0,17:8)
Block(0,5,1,17:8)
Block(0,5,2,134:7)
Block(0,5,3,134:5)
Block(0,6,-7,5:2)
Block(0,6,-6,5:2)
Block(0,6,-5,5:2)
Block(0,6,-4,5:2)
Block(0,6,-3,5:2)
Block(0,6,-2,5:2)
Block(0,6,-1,5:2)
Block(0,6,0,45)
Block(0,6,1,5)
Block(0,6,2,5:1)
Block(0,6,3,5:1)
Block(0,6,4,134:7)
Block(0,6,5,134:5)
Block(0,7,-7,17)
Block(0,7,-3,170)
Block(0,7,-2,170)
Block(0,7,-1,17)
Block(0,7,0,45)
Block(0,7,1,17)
Block(0,7,4,85)
Block(0,7,5,85)
Block(0,8,-7,17)
Block(0,8,-2,170)
Block(0,8,-1,17)
Block(0,8,0,45)
Block(0,8,1,17)
Block(0,8,5,50:5)
Block(0,9,-7,17)
Block(0,9,-2,170:4)
Block(0,9,-1,17)
Block(0,9,0,45)
Block(0,9,1,17)
Block(0,10,-7,17)
Block(0,10,-6,85)
Block(0,10,-5,85)
Block(0,10,-4,85)
Block(0,10,-3,85)
Block(0,10,-2,85)
Block(0,10,-1,17)
Block(0,10,0,45)
Block(0,10,1,17)
Block(0,11,-7,17:8)
Block(0,11,-6,17:8)
Block(0,11,-5,17:8)
Block(0,11,-4,17:8)
Block(0,11,-3,17:8)
Block(0,11,-2,17:8)
Block(0,11,-1,17:8)
Block(0,11,0,17:8)
Block(0,11,1,17:8)
Block(0,11,2,17:8)
Block(0,12,0,85)
Block(0,12,1,85)
Block(0,19,-7,85)
Block(0,19,-6,85)
Block(0,19,-5,85)
Block(0,19,-4,85)
Block(0,19,-3,85)
Block(0,19,-2,85)
Block(0,19,-1,85)
Block(0,19,0,17:4)
Block(0,20,-7,134:1)
Block(0,20,-6,134:1)
Block(0,20,-5,134:1)
Block(0,20,-4,134:1)
Block(0,20,-3,134:1)
Block(0,20,-2,134:1)
Block(0,20,-1,134:1)
Block(0,20,0,134:1)
Block(0,20,1,134:1)
Block(1,0,-7,3)
Block(1,0,-6,3)
Block(1,0,-5,3)
Block(1,0,-4,3)
Block(1,0,-3,3)
Block(1,0,-2,3)
Block(1,0,-1,3)
Block(1,0,0,3)
Block(1,0,1,3)
Block(1,0,2,3)
Block(1,0,3,3)
Block(1,0,4,1)
Block(1,0,5,1)
Block(1,0,6,1)
Block(1,0,7,1)
Block(1,0,8,1)
Block(1,1,-7,3)
Block(1,1,-6,5:2)
Block(1,1,-5,5:2)
Block(1,1,-4,5:2)
Block(1,1,-3,5:2)
Block(1,1,-2,5:2)
Block(1,1,-1,3)
Block(1,1,0,3)
Block(1,1,1,3)
Block(1,1,2,3)
Block(1,1,3,3)
Block(1,1,4,3)
Block(1,1,5,3)
Block(1,1,6,3)
Block(1,1,7,1)
Block(1,1,8,1)
Block(1,2,-7,17)
Block(1,2,-6,35)
Block(1,2,-5,35)
Block(1,2,-4,35)
Block(1,2,-3,170)
Block(1,2,-2,170)
Block(1,2,-1,17)
Block(1,2,0,17)
Block(1,2,1,13)
Block(1,2,2,13)
Block(1,2,3,13)
Block(1,2,4,13)
Block(1,2,5,2)
Block(1,2,6,3)
Block(1,2,7,3)
Block(1,2,8,3)
Block(1,3,-7,17)
Block(1,3,-6,35)
Block(1,3,-5,35)
Block(1,3,-4,35)
Block(1,3,-2,170:4)
Block(1,3,-1,17)
Block(1,3,0,45)
Block(1,3,6,2)
Block(1,3,7,3)
Block(1,3,8,3)
Block(1,4,-7,17)
Block(1,4,-6,35)
Block(1,4,-2,170:4)
Block(1,4,-1,17)
Block(1,4,0,45)
Block(1,4,7,2)
Block(1,4,8,2)
Block(1,5,-7,17:8)
Block(1,5,-6,17:8)
Block(1,5,-5,50:3)
Block(1,5,-3,50:4)
Block(1,5,-2,17:8)
Block(1,5,-1,17:8)
Block(1,5,0,17:8)
Block(1,5,1,134:5)
Block(1,5,2,134:5)
Block(1,6,-7,5)
Block(1,6,-6,45)
Block(1,6,-5,45)
Block(1,6,-4,45)
Block(1,6,-3,45)
Block(1,6,-2,45)
Block(1,6,-1,5)
Block(1,6,0,5:1)
Block(1,6,1,5:1)
Block(1,6,2,5:1)
Block(1,6,3,134:5)
Block(1,6,4,134:7)
Block(1,7,-7,17)
Block(1,7,-6,45)
Block(1,7,-5,45)
Block(1,7,-4,45)
Block(1,7,-3,45)
Block(1,7,-2,45)
Block(1,7,-1,17)
Block(1,7,3,85)
Block(1,7,4,85)
Block(1,8,-7,17)
Block(1,8,-6,45)
Block(1,8,-5,102)
Block(1,8,-4,102)
Block(1,8,-3,45)
Block(1,8,-2,45)
Block(1,8,-1,17)
Block(1,9,-7,17)
Block(1,9,-6,45)
Block(1,9,-5,45)
Block(1,9,-4,45)
Block(1,9,-3,45)
Block(1,9,-2,45)
Block(1,9,-1,17)
Block(1,10,-7,17)
Block(1,10,-6,45)
Block(1,10,-5,45)
Block(1,10,-4,45)
Block(1,10,-3,45)
Block(1,10,-2,45)
Block(1,10,-1,17)
Block(1,11,-7,17:8)
Block(1,11,-6,17:8)
Block(1,11,-5,17:8)
Block(1,11,-4,17:8)
Block(1,11,-3,17:8)
Block(1,11,-2,17:8)
Block(1,11,-1,17:8)
Block(1,11,0,85)
Block(1,11,1,17:4)
Block(1,12,-7,85)
Block(1,12,-6,85)
Block(1,12,-5,85)
Block(1,12,-4,85)
Block(1,12,-3,85)
Block(1,12,-2,85)
Block(1,12,-1,85)
Block(2,0,-7,3)
Block(2,0,-6,3)
Block(2,0,-5,3)
Block(2,0,-4,3)
Block(2,0,-3,3)
Block(2,0,-2,3)
Block(2,0,-1,3)
Block(2,0,0,3)
Block(2,0,1,3)
Block(2,0,2,3)
Block(2,0,3,1)
Block(2,0,4,1)
Block(2,0,5,1)
Block(2,0,6,1)
Block(2,0,7,1)
Block(2,0,8,1)
Block(2,1,-7,3:2)
Block(2,1,-6,3)
Block(2,1,-5,3)
Block(2,1,-4,3)
Block(2,1,-3,3)
Block(2,1,-2,3)
Block(2,1,-1,3)
Block(2,1,0,3)
Block(2,1,1,3)
Block(2,1,2,3)
Block(2,1,3,3)
Block(2,1,4,3)
Block(2,1,5,3)
Block(2,1,6,13)
Block(2,1,7,1)
Block(2,1,8,1)
Block(2,2,-7,85)
Block(2,2,-6,17)
Block(2,2,-5,17)
Block(2,2,-4,17)
Block(2,2,-3,17)
Block(2,2,-2,17)
Block(2,2,-1,3:2)
Block(2,2,0,3:2)
Block(2,2,1,13)
Block(2,2,2,13)
Block(2,2,3,2)
Block(2,2,4,2)
Block(2,2,5,3)
Block(2,2,6,3)
Block(2,2,7,3)
Block(2,2,8,1)
Block(2,3,-7,50:5)
Block(2,3,-6,45)
Block(2,3,-5,45)
Block(2,3,-4,45)
Block(2,3,-3,45)
Block(2,3,-2,45)
Block(2,3,-1,175:2)
Block(2,3,0,38:3)
Block(2,3,5,2)
Block(2,3,6,3)
Block(2,3,7,3)
Block(2,3,8,3)
Block(2,4,-6,45)
Block(2,4,-5,45)
Block(2,4,-4,45)
Block(2,4,-3,45)
Block(2,4,-2,45)
Block(2,4,-1,175:8)
Block(2,4,6,2)
Block(2,4,7,2)
Block(2,4,8,3)
Block(2,5,-7,134:5)
Block(2,5,-6,17:8)
Block(2,5,-5,17:8)
Block(2,5,-4,17:8)
Block(2,5,-3,17:8)
Block(2,5,-2,17:8)
Block(2,5,-1,134:5)
Block(2,5,0,134:5)
Block(2,5,1,134:7)
Block(2,5,8,2)
Block(2,6,-7,5:1)
Block(2,6,-6,5:1)
Block(2,6,-5,5:1)
Block(2,6,-4,5:1)
Block(2,6,-3,5:1)
Block(2,6,-2,5:1)
Block(2,6,-1,5:1)
Block(2,6,0,5:1)
Block(2,6,1,5:1)
Block(2,6,2,134:5)
Block(2,6,3,134:7)
Block(2,7,2,85)
Block(2,7,3,85)
Block(2,8,-6,96:15)
Block(2,8,-3,96:7)
Block(2,8,3,50:5)
Block(2,11,-7,17:4)
Block(2,11,-6,85)
Block(2,11,-5,85)
Block(2,11,-4,85)
Block(2,11,-3,85)
Block(2,11,-2,85)
Block(2,11,-1,17:4)
Block(3,0,-7,3)
Block(3,0,-6,3)
Block(3,0,-5,3)
Block(3,0,-4,3)
Block(3,0,-3,3)
Block(3,0,-2,3)
Block(3,0,-1,3)
Block(3,0,0,3)
Block(3,0,1,3)
Block(3,0,2,1)
Block(3,0,3,1)
Block(3,0,4,1)
Block(3,0,5,1)
Block(3,0,6,13)
Block(3,0,7,1)
Block(3,0,8,1)
Block(3,1,-7,13)
Block(3,1,-6,13)
Block(3,1,-5,13)
Block(3,1,-4,13)
Block(3,1,-3,13)
Block(3,1,-2,13)
Block(3,1,-1,3)
Block(3,1,0,3)
Block(3,1,1,3)
Block(3,1,2,3)
Block(3,1,3,3)
Block(3,1,4,3)
Block(3,1,5,13)
Block(3,1,6,13)
Block(3,1,7,13)
Block(3,1,8,1)
Block(3,2,-1,13)
Block(3,2,0,126:8)
Block(3,2,1,13)
Block(3,2,2,3)
Block(3,2,3,3)
Block(3,2,4,3)
Block(3,2,5,3)
Block(3,2,6,3)
Block(3,2,7,3)
Block(3,2,8,1)
Block(3,3,0,85)
Block(3,3,2,2)
Block(3,3,3,2)
Block(3,3,4,2)
Block(3,3,5,3)
Block(3,3,6,3)
Block(3,3,7,3)
Block(3,3,8,3)
Block(3,4,0,85)
Block(3,4,5,2)
Block(3,4,6,2)
Block(3,4,7,2)
Block(3,4,8,3)
Block(3,5,-7,134:6)
Block(3,5,-6,134:5)
Block(3,5,-5,134:5)
Block(3,5,-4,134:5)
Block(3,5,-3,134:5)
Block(3,5,-2,134:5)
Block(3,5,-1,134:7)
Block(3,5,0,85)
Block(3,5,5,37)
Block(3,5,8,2)
Block(3,6,-7,5:1)
Block(3,6,-6,5:1)
Block(3,6,-5,5:1)
Block(3,6,-4,5:1)
Block(3,6,-3,5:1)
Block(3,6,-2,5:1)
Block(3,6,-1,5:1)
Block(3,6,0,5:1)
Block(3,6,1,134:5)
Block(3,6,2,134:7)
Block(3,7,1,85)
Block(3,7,2,85)
Block(4,0,-7,3)
Block(4,0,-6,3)
Block(4,0,-5,3)
Block(4,0,-4,3)
Block(4,0,-3,3)
Block(4,0,-2,3)
Block(4,0,-1,3)
Block(4,0,0,3)
Block(4,0,1,3)
Block(4,0,2,1)
Block(4,0,3,1)
Block(4,0,4,1)
Block(4,0,5,13)
Block(4,0,6,13)
Block(4,0,7,13)
Block(4,0,8,1)
Block(4,1,-7,60)
Block(4,1,-6,60)
Block(4,1,-5,60)
Block(4,1,-4,60)
Block(4,1,-3,60)
Block(4,1,-2,2)
Block(4,1,-1,2)
Block(4,1,0,3)
Block(4,1,1,3)
Block(4,1,2,3)
Block(4,1,3,3)
Block(4,1,4,13)
Block(4,1,5,13)
Block(4,1,6,13)
Block(4,1,7,13)
Block(4,1,8,13)
Block(4,2,-7,59:7)
Block(4,2,-6,59:7)
Block(4,2,-5,59:7)
Block(4,2,-4,59:7)
Block(4,2,-3,59:7)
Block(4,2,-1,31:1)
Block(4,2,0,2)
Block(4,2,1,2)
Block(4,2,2,3)
Block(4,2,3,3)
Block(4,2,4,3)
Block(4,2,5,3)
Block(4,2,6,3)
Block(4,2,7,13)
Block(4,2,8,13)
Block(4,3,1,37)
Block(4,3,2,2)
Block(4,3,3,2)
Block(4,3,4,3)
Block(4,3,5,3)
Block(4,3,6,3)
Block(4,3,7,3)
Block(4,3,8,3)
Block(4,4,4,2)
Block(4,4,5,2)
Block(4,4,6,2)
Block(4,4,7,3)
Block(4,4,8,3)
Block(4,5,7,2)
Block(4,5,8,2)
Block(4,6,-7,134:5)
Block(4,6,-6,134:5)
Block(4,6,-5,134:5)
Block(4,6,-4,134:5)
Block(4,6,-3,134:5)
Block(4,6,-2,134:5)
Block(4,6,-1,134:5)
Block(4,6,0,134:5)
Block(4,6,1,134:7)
Block(4,7,-7,85)
Block(4,7,-6,85)
Block(4,7,-5,85)
Block(4,7,-4,85)
Block(4,7,-3,85)
Block(4,7,-2,85)
Block(4,7,-1,85)
Block(4,7,0,85)
Block(4,7,1,85)
Block(4,8,1,50:5)
Block(5,0,-7,3)
Block(5,0,-6,3)
Block(5,0,-5,3)
Block(5,0,-4,3)
Block(5,0,-3,3)
Block(5,0,-2,3)
Block(5,0,-1,3)
Block(5,0,0,3)
Block(5,0,1,3)
Block(5,0,2,1)
Block(5,0,3,1)
Block(5,0,4,1)
Block(5,0,5,1)
Block(5,0,6,13)
Block(5,0,7,13)
Block(5,0,8,1)
Block(5,1,-7,60)
Block(5,1,-6,60)
Block(5,1,-5,60:7)
Block(5,1,-4,60)
Block(5,1,-3,60:7)
Block(5,1,-2,2)
Block(5,1,-1,2)
Block(5,1,0,3)
Block(5,1,1,3)
Block(5,1,2,3)
Block(5,1,3,3)
Block(5,1,4,1)
Block(5,1,5,13)
Block(5,1,6,13)
Block(5,1,7,13)
Block(5,1,8,13)
Block(5,2,-7,59:7)
Block(5,2,-6,59:7)
Block(5,2,-5,59:7)
Block(5,2,-4,59:7)
Block(5,2,-3,59:7)
Block(5,2,-2,31:1)
Block(5,2,0,2)
Block(5,2,1,2)
Block(5,2,2,3)
Block(5,2,3,3)
Block(5,2,4,3)
Block(5,2,5,3)
Block(5,2,6,13)
Block(5,2,7,13)
Block(5,2,8,13)
Block(5,3,2,2)
Block(5,3,3,2)
Block(5,3,4,3)
Block(5,3,5,3)
Block(5,3,6,3)
Block(5,3,7,3)
Block(5,3,8,3)
Block(5,4,0,18)
Block(5,4,2,31:1)
Block(5,4,4,2)
Block(5,4,5,2)
Block(5,4,6,3)
Block(5,4,7,3)
Block(5,4,8,3)
Block(5,5,0,18)
Block(5,5,6,2)
Block(5,5,7,2)
Block(5,5,8,2)
Block(6,0,-7,3)
Block(6,0,-6,3)
Block(6,0,-5,3)
Block(6,0,-4,3)
Block(6,0,-3,3)
Block(6,0,-2,3)
Block(6,0,-1,3)
Block(6,0,0,3)
Block(6,0,1,1)
Block(6,0,2,1)
Block(6,0,3,1)
Block(6,0,4,1)
Block(6,0,5,1)
Block(6,0,6,1)
Block(6,0,7,13)
Block(6,0,8,1)
Block(6,1,-7,13)
Block(6,1,-6,13)
Block(6,1,-5,13)
Block(6,1,-4,13)
Block(6,1,-3,13)
Block(6,1,-2,2)
Block(6,1,-1,2)
Block(6,1,0,3)
Block(6,1,1,3)
Block(6,1,2,3)
Block(6,1,3,1)
Block(6,1,4,1)
Block(6,1,5,1)
Block(6,1,6,13)
Block(6,1,7,13)
Block(6,1,8,13)
Block(6,2,0,2)
Block(6,2,1,3)
Block(6,2,2,3)
Block(6,2,3,3)
Block(6,2,4,3)
Block(6,2,5,3)
Block(6,2,6,13)
Block(6,2,7,13)
Block(6,2,8,13)
Block(6,3,1,2)
Block(6,3,2,2)
Block(6,3,3,3)
Block(6,3,4,3)
Block(6,3,5,3)
Block(6,3,6,3)
Block(6,3,7,3)
Block(6,3,8,3)
Block(6,4,-1,18)
Block(6,4,0,18)
Block(6,4,3,2)
Block(6,4,4,2)
Block(6,4,5,2)
Block(6,4,6,3)
Block(6,4,7,3)
Block(6,4,8,3)
Block(6,5,-1,18)
Block(6,5,0,18)
Block(6,5,1,18)
Block(6,5,2,18)
Block(6,5,6,2)
Block(6,5,7,2)
Block(6,5,8,2)
Block(6,6,0,18)
Block(7,0,-7,3)
Block(7,0,-6,3)
Block(7,0,-5,3)
Block(7,0,-4,3)
Block(7,0,-3,3)
Block(7,0,-2,3)
Block(7,0,-1,3)
Block(7,0,0,3)
Block(7,0,1,1)
Block(7,0,2,1)
Block(7,0,3,1)
Block(7,0,4,1)
Block(7,0,5,1)
Block(7,0,6,1)
Block(7,0,7,1)
Block(7,0,8,1)
Block(7,1,-7,60)
Block(7,1,-6,60:7)
Block(7,1,-5,60)
Block(7,1,-4,60:7)
Block(7,1,-3,60:7)
Block(7,1,-2,2)
Block(7,1,-1,2)
Block(7,1,0,3)
Block(7,1,1,3)
Block(7,1,2,3)
Block(7,1,3,1)
Block(7,1,4,1)
Block(7,1,5,1)
Block(7,1,6,1)
Block(7,1,7,13)
Block(7,1,8,13)
Block(7,2,-7,59:7)
Block(7,2,-6,59:7)
Block(7,2,-5,59:7)
Block(7,2,-4,59:7)
Block(7,2,-3,59:7)
Block(7,2,0,2)
Block(7,2,1,3)
Block(7,2,2,3)
Block(7,2,3,3)
Block(7,2,4,3)
Block(7,2,5,1)
Block(7,2,6,13)
Block(7,2,7,13)
Block(7,2,8,13)
Block(7,3,1,2)
Block(7,3,2,2)
Block(7,3,3,3)
Block(7,3,4,3)
Block(7,3,5,3)
Block(7,3,6,3)
Block(7,3,7,3)
Block(7,3,8,3)
Block(7,4,-2,18)
Block(7,4,-1,18)
Block(7,4,0,18)
Block(7,4,2,37)
Block(7,4,3,2)
Block(7,4,4,2)
Block(7,4,5,3)
Block(7,4,6,3)
Block(7,4,7,3)
Block(7,4,8,3)
Block(7,5,-2,18)
Block(7,5,-1,18)
Block(7,5,0,18)
Block(7,5,1,18)
Block(7,5,2,18)
Block(7,5,3,18)
Block(7,5,5,2)
Block(7,5,6,2)
Block(7,5,7,2)
Block(7,5,8,2)
Block(7,6,1,18)
Block(7,6,2,18)
Block(7,6,3,18)
Block(7,8,1,18)

Branch(16,0,0,true,monsterley-s-grainC2R1,NORTH,100,0)
