

BranchFrequency: 10

BranchFrequencyGroup: CanOverride:0

CanOverride: true

SmoothRadius: -1

OverrideChildSettings: false

ReplaceAbove:
ReplaceBelow:

MustBeInside: VillageGeneratorStructurePlaceHolder, VillageGeneratorStructuresDelay, VillageGeneratorStructuresDelay2, VillageGeneratorStructuresDelay3, VillageGeneratorStructuresDelay4, VillageGeneratorStructuresDelay5, VillageGeneratorStructuresDelay6, VillageGeneratorStructuresDelay7, VillageGeneratorStructuresDelay8, VillageGeneratorStructuresDelay9, VillageGeneratorStructuresDelay10

Block(-8,0,-7,3)
Block(-8,0,-6,3)
Block(-8,0,-5,3)
Block(-8,0,-4,3)
Block(-8,0,-3,3)
Block(-8,0,-2,3)
Block(-8,0,-1,3)
Block(-8,0,0,3)
Block(-8,0,1,3)
Block(-8,0,2,3)
Block(-8,0,3,3)
Block(-8,0,4,2)
Block(-8,0,5,2)
Block(-8,0,6,3)
Block(-8,0,7,3)
Block(-8,0,8,3)
Block(-8,1,-7,2)
Block(-8,1,-6,2)
Block(-8,1,-5,2)
Block(-8,1,-4,2)
Block(-8,1,-3,2)
Block(-8,1,-2,2)
Block(-8,1,-1,2)
Block(-8,1,0,2)
Block(-8,1,1,2)
Block(-8,1,2,2)
Block(-8,1,3,2)
Block(-8,1,4,13)
Block(-8,1,5,13)
Block(-8,1,6,2)
Block(-8,1,7,2)
Block(-8,1,8,2)
Block(-7,0,-7,3)
Block(-7,0,-6,3)
Block(-7,0,-5,3)
Block(-7,0,-4,3)
Block(-7,0,-3,3)
Block(-7,0,-2,3)
Block(-7,0,-1,3)
Block(-7,0,0,3)
Block(-7,0,1,3)
Block(-7,0,2,3)
Block(-7,0,3,3)
Block(-7,0,4,3)
Block(-7,0,5,2)
Block(-7,0,6,2)
Block(-7,0,7,3)
Block(-7,0,8,3)
Block(-7,1,-7,2)
Block(-7,1,-6,2)
Block(-7,1,-5,2)
Block(-7,1,-4,2)
Block(-7,1,-3,2)
Block(-7,1,-2,2)
Block(-7,1,-1,2)
Block(-7,1,0,2)
Block(-7,1,1,2)
Block(-7,1,2,2)
Block(-7,1,3,2)
Block(-7,1,4,2)
Block(-7,1,5,13)
Block(-7,1,6,13)
Block(-7,1,7,2)
Block(-7,1,8,2)
Block(-7,2,3,31:1)
Block(-7,2,7,31:1)
Block(-7,2,8,31:1)
Block(-6,0,-7,3)
Block(-6,0,-6,3)
Block(-6,0,-5,3)
Block(-6,0,-4,3)
Block(-6,0,-3,3)
Block(-6,0,-2,3)
Block(-6,0,-1,3)
Block(-6,0,0,3)
Block(-6,0,1,3)
Block(-6,0,2,3)
Block(-6,0,3,3)
Block(-6,0,4,3)
Block(-6,0,5,2)
Block(-6,0,6,2)
Block(-6,0,7,3)
Block(-6,0,8,3)
Block(-6,1,-7,2)
Block(-6,1,-6,2)
Block(-6,1,-5,2)
Block(-6,1,-4,2)
Block(-6,1,-3,2)
Block(-6,1,-2,2)
Block(-6,1,-1,2)
Block(-6,1,0,2)
Block(-6,1,1,2)
Block(-6,1,2,2)
Block(-6,1,3,2)
Block(-6,1,4,2)
Block(-6,1,5,13)
Block(-6,1,6,13)
Block(-6,1,7,13)
Block(-6,1,8,13)
Block(-6,2,3,31:1)
Block(-6,2,4,31:1)
Block(-5,0,-7,3)
Block(-5,0,-6,3)
Block(-5,0,-5,3)
Block(-5,0,-4,3)
Block(-5,0,-3,3)
Block(-5,0,-2,3)
Block(-5,0,-1,3)
Block(-5,0,0,3)
Block(-5,0,1,3)
Block(-5,0,2,3)
Block(-5,0,3,3)
Block(-5,0,4,3)
Block(-5,0,5,3)
Block(-5,0,6,3)
Block(-5,0,7,3)
Block(-5,0,8,3)
Block(-5,1,-7,2)
Block(-5,1,-6,2)
Block(-5,1,-5,2)
Block(-5,1,-4,2)
Block(-5,1,-3,2)
Block(-5,1,-2,2)
Block(-5,1,-1,2)
Block(-5,1,0,2)
Block(-5,1,1,2)
Block(-5,1,2,2)
Block(-5,1,3,2)
Block(-5,1,4,2)
Block(-5,1,5,2)
Block(-5,1,6,2)
Block(-5,1,7,13)
Block(-5,1,8,13)
Block(-5,2,3,31:1)
Block(-5,2,4,31:1)
Block(-5,2,5,31:1)
Block(-5,2,6,31:1)
Block(-4,0,-7,3)
Block(-4,0,-6,3)
Block(-4,0,-5,3)
Block(-4,0,-4,3)
Block(-4,0,-3,3)
Block(-4,0,-2,3)
Block(-4,0,-1,3)
Block(-4,0,0,3)
Block(-4,0,1,3)
Block(-4,0,2,3)
Block(-4,0,3,3)
Block(-4,0,4,3)
Block(-4,0,5,3)
Block(-4,0,6,3)
Block(-4,0,7,3)
Block(-4,0,8,3)
Block(-4,1,-7,2)
Block(-4,1,-6,2)
Block(-4,1,-5,2)
Block(-4,1,-4,2)
Block(-4,1,-3,2)
Block(-4,1,-2,2)
Block(-4,1,-1,2)
Block(-4,1,0,2)
Block(-4,1,1,2)
Block(-4,1,2,2)
Block(-4,1,3,2)
Block(-4,1,4,2)
Block(-4,1,5,2)
Block(-4,1,6,2)
Block(-4,1,7,2)
Block(-4,1,8,13)
Block(-4,2,4,31:1)
Block(-4,2,5,31:1)
Block(-3,0,-7,3)
Block(-3,0,-6,3)
Block(-3,0,-5,3)
Block(-3,0,-4,3)
Block(-3,0,-3,3)
Block(-3,0,-2,3)
Block(-3,0,-1,3)
Block(-3,0,0,3)
Block(-3,0,1,3)
Block(-3,0,2,3)
Block(-3,0,3,3)
Block(-3,0,4,2)
Block(-3,0,5,2)
Block(-3,0,6,3)
Block(-3,0,7,3)
Block(-3,0,8,3)
Block(-3,1,-7,2)
Block(-3,1,-6,2)
Block(-3,1,-5,2)
Block(-3,1,-4,2)
Block(-3,1,-3,2)
Block(-3,1,-2,2)
Block(-3,1,-1,2)
Block(-3,1,0,2)
Block(-3,1,1,2)
Block(-3,1,2,2)
Block(-3,1,3,2)
Block(-3,1,4,9)
Block(-3,1,5,9)
Block(-3,1,6,2)
Block(-3,1,7,2)
Block(-3,1,8,13)
Block(-3,2,2,31:1)
Block(-3,2,7,31:1)
Block(-2,0,-7,3)
Block(-2,0,-6,3)
Block(-2,0,-5,3)
Block(-2,0,-4,3)
Block(-2,0,-3,3)
Block(-2,0,-2,3)
Block(-2,0,-1,3)
Block(-2,0,0,3)
Block(-2,0,1,3)
Block(-2,0,2,3)
Block(-2,0,3,2)
Block(-2,0,4,2)
Block(-2,0,5,2)
Block(-2,0,6,2)
Block(-2,0,7,3)
Block(-2,0,8,3)
Block(-2,1,-7,2)
Block(-2,1,-6,2)
Block(-2,1,-5,2)
Block(-2,1,-4,2)
Block(-2,1,-3,2)
Block(-2,1,-2,2)
Block(-2,1,-1,2)
Block(-2,1,0,2)
Block(-2,1,1,2)
Block(-2,1,2,2)
Block(-2,1,3,9)
Block(-2,1,4,9)
Block(-2,1,5,9)
Block(-2,1,6,9)
Block(-2,1,7,2)
Block(-2,1,8,2)
Block(-1,0,-7,3)
Block(-1,0,-6,3)
Block(-1,0,-5,3)
Block(-1,0,-4,3)
Block(-1,0,-3,3)
Block(-1,0,-2,3)
Block(-1,0,-1,3)
Block(-1,0,0,3)
Block(-1,0,1,3)
Block(-1,0,2,2)
Block(-1,0,3,2)
Block(-1,0,4,2)
Block(-1,0,5,2)
Block(-1,0,6,2)
Block(-1,0,7,3)
Block(-1,0,8,3)
Block(-1,1,-7,2)
Block(-1,1,-6,2)
Block(-1,1,-5,2)
Block(-1,1,-4,2)
Block(-1,1,-3,2)
Block(-1,1,-2,2)
Block(-1,1,-1,2)
Block(-1,1,0,2)
Block(-1,1,1,2)
Block(-1,1,2,9)
Block(-1,1,3,9)
Block(-1,1,4,9)
Block(-1,1,5,9)
Block(-1,1,6,9)
Block(-1,1,7,2)
Block(-1,1,8,2)
Block(0,0,-7,3)
Block(0,0,-6,3)
Block(0,0,-5,3)
Block(0,0,-4,3)
Block(0,0,-3,3)
Block(0,0,-2,3)
Block(0,0,-1,3)
Block(0,0,0,3)
Block(0,0,1,3)
Block(0,0,2,3)
Block(0,0,3,2)
Block(0,0,4,2)
Block(0,0,5,2)
Block(0,0,6,2)
Block(0,0,7,3)
Block(0,0,8,3)
Block(0,1,-7,2)
Block(0,1,-6,2)
Block(0,1,-5,2)
Block(0,1,-4,2)
Block(0,1,-3,2)
Block(0,1,-2,2)
Block(0,1,-1,2)
Block(0,1,0,2)
Block(0,1,1,2)
Block(0,1,2,2)
Block(0,1,3,9)
Block(0,1,4,9)
Block(0,1,5,9)
Block(0,1,6,9)
Block(0,1,7,2)
Block(0,1,8,2)
Block(1,0,-7,3)
Block(1,0,-6,3)
Block(1,0,-5,3)
Block(1,0,-4,3)
Block(1,0,-3,3)
Block(1,0,-2,3)
Block(1,0,-1,3)
Block(1,0,0,3)
Block(1,0,1,3)
Block(1,0,2,3)
Block(1,0,3,2)
Block(1,0,4,2)
Block(1,0,5,2)
Block(1,0,6,3)
Block(1,0,7,3)
Block(1,0,8,3)
Block(1,1,-7,2)
Block(1,1,-6,2)
Block(1,1,-5,2)
Block(1,1,-4,2)
Block(1,1,-3,2)
Block(1,1,-2,2)
Block(1,1,-1,2)
Block(1,1,0,2)
Block(1,1,1,2)
Block(1,1,2,2)
Block(1,1,3,9)
Block(1,1,4,9)
Block(1,1,5,9)
Block(1,1,6,2)
Block(1,1,7,2)
Block(1,1,8,2)
Block(1,2,2,38:3)
Block(1,2,8,31:1)
Block(2,0,-7,3)
Block(2,0,-6,3)
Block(2,0,-5,3)
Block(2,0,-4,3)
Block(2,0,-3,3)
Block(2,0,-2,3)
Block(2,0,-1,3)
Block(2,0,0,3)
Block(2,0,1,3)
Block(2,0,2,3)
Block(2,0,3,3)
Block(2,0,4,3)
Block(2,0,5,3)
Block(2,0,6,3)
Block(2,0,7,3)
Block(2,0,8,3)
Block(2,1,-7,2)
Block(2,1,-6,2)
Block(2,1,-5,2)
Block(2,1,-4,2)
Block(2,1,-3,2)
Block(2,1,-2,2)
Block(2,1,-1,2)
Block(2,1,0,2)
Block(2,1,1,2)
Block(2,1,2,2)
Block(2,1,3,2)
Block(2,1,4,2)
Block(2,1,5,2)
Block(2,1,6,2)
Block(2,1,7,2)
Block(2,1,8,2)
Block(2,2,6,31:1)
Block(2,2,7,31:1)
Block(2,7,7,85)
Block(2,7,8,85)
Block(2,8,6,85)
Block(2,8,7,85)
Block(2,8,8,85)
Block(2,9,6,85)
Block(2,9,7,85)
Block(2,9,8,85)
Block(2,10,6,85)
Block(2,10,7,85)
Block(2,10,8,85)
Block(2,11,6,85)
Block(2,11,7,85)
Block(2,11,8,85)
Block(2,12,6,85)
Block(2,12,7,85)
Block(2,12,8,85)
Block(2,13,6,85)
Block(2,13,7,85)
Block(2,13,8,85)
Block(2,14,6,85)
Block(2,14,7,85)
Block(2,14,8,85)
Block(2,15,7,85)
Block(2,15,8,85)
Block(2,16,7,85)
Block(2,16,8,85)
Block(2,17,7,85)
Block(2,17,8,85)
Block(2,18,7,85)
Block(2,18,8,85)
Block(2,19,8,85)
Block(2,20,8,85)
Block(2,21,8,85)
Block(2,22,8,85)
Block(2,26,7,5:1)
Block(2,26,8,5:1)
Block(2,27,4,5:1)
Block(2,27,5,5:1)
Block(2,27,6,5:1)
Block(2,27,7,5:1)
Block(2,27,8,5:1)
Block(2,28,-1,5:1)
Block(2,28,0,5:1)
Block(2,28,1,5:1)
Block(2,28,2,5:1)
Block(2,28,3,5:1)
Block(2,28,4,5:1)
Block(2,28,5,85)
Block(2,28,6,85)
Block(2,28,7,85)
Block(2,28,8,85)
Block(2,29,-7,85)
Block(2,29,-6,5:1)
Block(2,29,-5,5:1)
Block(2,29,-4,5:1)
Block(2,29,-3,5:1)
Block(2,29,-2,5:1)
Block(2,29,-1,5:1)
Block(2,29,0,5:1)
Block(2,29,1,85)
Block(2,29,2,85)
Block(2,29,3,85)
Block(2,29,4,85)
Block(2,29,5,85)
Block(2,29,6,85)
Block(2,29,7,85)
Block(2,29,8,85)
Block(2,30,-7,85)
Block(2,30,-6,85)
Block(2,30,-5,85)
Block(2,30,-4,85)
Block(2,30,-3,85)
Block(2,30,-2,85)
Block(2,30,-1,85)
Block(2,30,0,85)
Block(2,30,1,85)
Block(2,30,2,85)
Block(2,30,3,85)
Block(2,30,4,85)
Block(2,30,5,85)
Block(2,30,6,85)
Block(2,30,7,85)
Block(2,30,8,85)
Block(2,31,-7,85)
Block(2,31,-6,85)
Block(2,31,-5,85)
Block(2,31,-4,85)
Block(2,31,-3,85)
Block(2,31,-2,85)
Block(2,31,-1,85)
Block(2,31,0,85)
Block(2,31,1,85)
Block(2,31,2,85)
Block(2,31,3,85)
Block(2,31,4,85)
Block(2,32,-6,85)
Block(2,32,-5,85)
Block(2,32,-4,85)
Block(2,32,-3,85)
Block(2,32,-2,85)
Block(2,32,-1,85)
Block(2,32,0,85)
Block(3,0,-7,3)
Block(3,0,-6,3)
Block(3,0,-5,3)
Block(3,0,-4,3)
Block(3,0,-3,3)
Block(3,0,-2,3)
Block(3,0,-1,3)
Block(3,0,0,3)
Block(3,0,1,3)
Block(3,0,2,3)
Block(3,0,3,3)
Block(3,0,4,3)
Block(3,0,5,3)
Block(3,0,6,3)
Block(3,0,7,3)
Block(3,0,8,3)
Block(3,1,-7,2)
Block(3,1,-6,2)
Block(3,1,-5,2)
Block(3,1,-4,2)
Block(3,1,-3,2)
Block(3,1,-2,2)
Block(3,1,-1,2)
Block(3,1,0,2)
Block(3,1,1,2)
Block(3,1,2,2)
Block(3,1,3,2)
Block(3,1,4,2)
Block(3,1,5,13)
Block(3,1,6,13)
Block(3,1,7,13)
Block(3,1,8,5)
Block(3,2,4,31:1)
Block(3,2,8,85)
Block(3,3,8,85)
Block(3,4,8,85)
Block(3,5,8,85)
Block(3,6,6,134:6)
Block(3,6,7,134:4)
Block(3,6,8,5:1)
Block(4,0,-7,3)
Block(4,0,-6,3)
Block(4,0,-5,3)
Block(4,0,-4,3)
Block(4,0,-3,3)
Block(4,0,-2,3)
Block(4,0,-1,3)
Block(4,0,0,3)
Block(4,0,1,3)
Block(4,0,2,3)
Block(4,0,3,3)
Block(4,0,4,3)
Block(4,0,5,3)
Block(4,0,6,3)
Block(4,0,7,3)
Block(4,0,8,3)
Block(4,1,-7,2)
Block(4,1,-6,2)
Block(4,1,-5,2)
Block(4,1,-4,2)
Block(4,1,-3,2)
Block(4,1,-2,2)
Block(4,1,-1,2)
Block(4,1,0,2)
Block(4,1,1,2)
Block(4,1,2,2)
Block(4,1,3,2)
Block(4,1,4,13)
Block(4,1,5,13)
Block(4,1,6,3:2)
Block(4,1,7,3:2)
Block(4,1,8,3:2)
Block(4,2,6,38:5)
Block(4,2,8,37)
Block(4,5,7,134:6)
Block(4,5,8,134:4)
Block(4,6,4,134:6)
Block(4,6,5,134:4)
Block(4,6,6,134:4)
Block(4,6,7,5:1)
Block(4,6,8,5:1)
Block(4,7,5,85)
Block(4,7,6,85)
Block(4,7,7,85)
Block(4,7,8,85)
Block(4,8,5,50:5)
Block(5,0,-7,3)
Block(5,0,-6,3)
Block(5,0,-5,3)
Block(5,0,-4,3)
Block(5,0,-3,3)
Block(5,0,-2,3)
Block(5,0,-1,3)
Block(5,0,0,3)
Block(5,0,1,3)
Block(5,0,2,3)
Block(5,0,3,3)
Block(5,0,4,3)
Block(5,0,5,3)
Block(5,0,6,3)
Block(5,0,7,3)
Block(5,0,8,3)
Block(5,1,-7,2)
Block(5,1,-6,2)
Block(5,1,-5,2)
Block(5,1,-4,2)
Block(5,1,-3,2)
Block(5,1,-2,2)
Block(5,1,-1,2)
Block(5,1,0,2)
Block(5,1,1,2)
Block(5,1,2,2)
Block(5,1,3,2)
Block(5,1,4,13)
Block(5,1,5,5)
Block(5,1,6,3:2)
Block(5,1,7,3:2)
Block(5,1,8,3)
Block(5,2,5,85)
Block(5,2,6,31:1)
Block(5,2,7,175:2)
Block(5,2,8,17)
Block(5,3,5,85)
Block(5,3,7,175:8)
Block(5,3,8,45)
Block(5,4,5,85)
Block(5,4,8,45)
Block(5,5,5,85)
Block(5,5,6,134:6)
Block(5,5,7,134:4)
Block(5,5,8,17:8)
Block(5,6,4,134:6)
Block(5,6,5,5:1)
Block(5,6,6,5:1)
Block(5,6,7,5:1)
Block(5,6,8,5:1)
Block(5,7,4,85)
Block(5,7,5,85)
Block(5,11,7,17:4)
Block(5,11,8,85)
Block(6,0,-7,3)
Block(6,0,-6,3)
Block(6,0,-5,3)
Block(6,0,-4,3)
Block(6,0,-3,3)
Block(6,0,-2,3)
Block(6,0,-1,3)
Block(6,0,0,3)
Block(6,0,1,3)
Block(6,0,2,3)
Block(6,0,3,3)
Block(6,0,4,3)
Block(6,0,5,3)
Block(6,0,6,3)
Block(6,0,7,3)
Block(6,0,8,3)
Block(6,1,-7,2)
Block(6,1,-6,2)
Block(6,1,-5,2)
Block(6,1,-4,2)
Block(6,1,-3,2)
Block(6,1,-2,2)
Block(6,1,-1,2)
Block(6,1,0,2)
Block(6,1,1,2)
Block(6,1,2,2)
Block(6,1,3,2)
Block(6,1,4,13)
Block(6,1,5,3:2)
Block(6,1,6,3:2)
Block(6,1,7,3)
Block(6,1,8,5:2)
Block(6,2,1,31:1)
Block(6,2,5,31:1)
Block(6,2,6,37)
Block(6,2,7,17)
Block(6,2,8,85)
Block(6,3,7,17)
Block(6,3,8,85)
Block(6,4,7,17)
Block(6,4,8,50:5)
Block(6,5,5,134:6)
Block(6,5,6,134:4)
Block(6,5,7,17:8)
Block(6,5,8,17:8)
Block(6,6,3,134:6)
Block(6,6,4,134:4)
Block(6,6,5,5:1)
Block(6,6,6,5:1)
Block(6,6,7,5)
Block(6,6,8,45)
Block(6,7,3,85)
Block(6,7,4,85)
Block(6,7,7,17)
Block(6,7,8,45)
Block(6,8,3,50:5)
Block(6,8,7,17)
Block(6,8,8,45)
Block(6,9,7,17)
Block(6,9,8,45)
Block(6,10,7,17)
Block(6,10,8,45)
Block(6,11,6,17:8)
Block(6,11,7,17:8)
Block(6,11,8,17:8)
Block(6,12,7,85)
Block(6,12,8,85)
Block(6,19,8,17:4)
Block(6,20,7,134:2)
Block(6,20,8,134)
Block(7,0,-7,3)
Block(7,0,-6,3)
Block(7,0,-5,3)
Block(7,0,-4,3)
Block(7,0,-3,3)
Block(7,0,-2,3)
Block(7,0,-1,3)
Block(7,0,0,3)
Block(7,0,1,3)
Block(7,0,2,3)
Block(7,0,3,3)
Block(7,0,4,3)
Block(7,0,5,3)
Block(7,0,6,3)
Block(7,0,7,3)
Block(7,0,8,3)
Block(7,1,-7,2)
Block(7,1,-6,2)
Block(7,1,-5,2)
Block(7,1,-4,2)
Block(7,1,-3,2)
Block(7,1,-2,2)
Block(7,1,-1,2)
Block(7,1,0,2)
Block(7,1,1,2)
Block(7,1,2,2)
Block(7,1,3,2)
Block(7,1,4,5)
Block(7,1,5,3:2)
Block(7,1,6,3)
Block(7,1,7,5:2)
Block(7,1,8,5:2)
Block(7,2,4,85)
Block(7,2,5,37)
Block(7,2,6,17)
Block(7,2,7,170)
Block(7,3,4,85)
Block(7,3,6,45)
Block(7,4,4,85)
Block(7,4,6,45)
Block(7,5,4,85)
Block(7,5,5,134:6)
Block(7,5,6,17:4)
Block(7,5,7,85)
Block(7,6,3,134:6)
Block(7,6,4,5:1)
Block(7,6,5,5:1)
Block(7,6,6,5:1)
Block(7,6,7,5:2)
Block(7,6,8,5:2)
Block(7,7,-1,18)
Block(7,7,0,18)
Block(7,7,1,18)
Block(7,7,2,18)
Block(7,7,3,85)
Block(7,7,7,45)
Block(7,7,8,17)
Block(7,8,-1,18)
Block(7,8,0,18)
Block(7,8,1,18)
Block(7,8,2,18)
Block(7,8,7,45)
Block(7,8,8,17)
Block(7,9,7,45)
Block(7,9,8,17)
Block(7,10,7,45)
Block(7,10,8,17)
Block(7,11,6,85)
Block(7,11,7,17:4)
Block(7,11,8,5)
Block(7,12,7,85)
Block(7,19,7,17:8)
Block(7,19,8,17:4)
Block(7,20,7,134:2)
Block(7,20,8,5:1)
Block(7,21,8,134:2)

Branch(16,0,0,true,monsterley-s-grainC1R0,NORTH,100,0)
Branch(0,0,16,true,monsterley-s-grainC0R1,NORTH,100,0)
