

BranchFrequencyGroup: CanOverride:0

CanOverride: true

SmoothRadius: -1

OverrideChildSettings: false

ReplaceAbove:
ReplaceBelow:

MustBeInside: VillageGeneratorStructurePlaceHolder, VillageGeneratorStructuresDelay, VillageGeneratorStructuresDelay2, VillageGeneratorStructuresDelay3, VillageGeneratorStructuresDelay4, VillageGeneratorStructuresDelay5, VillageGeneratorStructuresDelay6, VillageGeneratorStructuresDelay7, VillageGeneratorStructuresDelay8, VillageGeneratorStructuresDelay9, VillageGeneratorStructuresDelay10

Block(-8,0,-7,3)
Block(-8,0,-6,3)
Block(-8,0,-5,3)
Block(-8,0,-4,3)
Block(-8,0,-3,3)
Block(-8,0,-2,3)
Block(-8,0,-1,3)
Block(-8,0,0,3)
Block(-8,0,1,3)
Block(-8,0,2,3)
Block(-8,0,3,3)
Block(-8,0,4,3)
Block(-8,0,5,3)
Block(-8,0,6,3)
Block(-8,0,7,3)
Block(-8,0,8,3)
Block(-8,1,-7,2)
Block(-8,1,-6,2)
Block(-8,1,-5,2)
Block(-8,1,-4,2)
Block(-8,1,-3,2)
Block(-8,1,-2,2)
Block(-8,1,-1,2)
Block(-8,1,0,2)
Block(-8,1,1,2)
Block(-8,1,2,2)
Block(-8,1,3,3)
Block(-8,1,4,3)
Block(-8,1,5,3)
Block(-8,1,6,3)
Block(-8,1,7,3)
Block(-8,1,8,3)
Block(-8,2,-7,31:1)
Block(-8,2,3,2)
Block(-8,2,4,3)
Block(-8,2,5,3)
Block(-8,2,6,3)
Block(-8,2,7,3)
Block(-8,2,8,3)
Block(-8,3,4,2)
Block(-8,3,5,2)
Block(-8,3,6,2)
Block(-8,3,7,2)
Block(-8,3,8,2)
Block(-8,4,8,31:1)
Block(-7,0,-7,3)
Block(-7,0,-6,3)
Block(-7,0,-5,3)
Block(-7,0,-4,3)
Block(-7,0,-3,3)
Block(-7,0,-2,3)
Block(-7,0,-1,3)
Block(-7,0,0,3)
Block(-7,0,1,3)
Block(-7,0,2,3)
Block(-7,0,3,3)
Block(-7,0,4,3)
Block(-7,0,5,3)
Block(-7,0,6,3)
Block(-7,0,7,3)
Block(-7,0,8,3)
Block(-7,1,-7,2)
Block(-7,1,-6,2)
Block(-7,1,-5,2)
Block(-7,1,-4,2)
Block(-7,1,-3,2)
Block(-7,1,-2,2)
Block(-7,1,-1,2)
Block(-7,1,0,2)
Block(-7,1,1,2)
Block(-7,1,2,2)
Block(-7,1,3,3)
Block(-7,1,4,3)
Block(-7,1,5,3)
Block(-7,1,6,3)
Block(-7,1,7,3)
Block(-7,1,8,3)
Block(-7,2,-6,31:1)
Block(-7,2,-5,31:1)
Block(-7,2,3,2)
Block(-7,2,4,2)
Block(-7,2,5,3)
Block(-7,2,6,3)
Block(-7,2,7,3)
Block(-7,2,8,3)
Block(-7,3,5,2)
Block(-7,3,6,2)
Block(-7,3,7,2)
Block(-7,3,8,2)
Block(-6,0,-7,3)
Block(-6,0,-6,3)
Block(-6,0,-5,3)
Block(-6,0,-4,3)
Block(-6,0,-3,3)
Block(-6,0,-2,3)
Block(-6,0,-1,3)
Block(-6,0,0,3)
Block(-6,0,1,3)
Block(-6,0,2,3)
Block(-6,0,3,3)
Block(-6,0,4,3)
Block(-6,0,5,3)
Block(-6,0,6,3)
Block(-6,0,7,3)
Block(-6,0,8,3)
Block(-6,1,-7,2)
Block(-6,1,-6,2)
Block(-6,1,-5,2)
Block(-6,1,-4,60:7)
Block(-6,1,-3,60)
Block(-6,1,-2,2)
Block(-6,1,-1,60)
Block(-6,1,0,60)
Block(-6,1,1,2)
Block(-6,1,2,2)
Block(-6,1,3,2)
Block(-6,1,4,3)
Block(-6,1,5,3)
Block(-6,1,6,3)
Block(-6,1,7,3)
Block(-6,1,8,3)
Block(-6,2,-6,31:1)
Block(-6,2,-4,59:7)
Block(-6,2,-3,59:7)
Block(-6,2,-1,59:7)
Block(-6,2,0,59:7)
Block(-6,2,4,2)
Block(-6,2,5,3)
Block(-6,2,6,3)
Block(-6,2,7,3)
Block(-6,2,8,3)
Block(-6,3,4,38:8)
Block(-6,3,5,2)
Block(-6,3,6,2)
Block(-6,3,7,2)
Block(-6,3,8,2)
Block(-6,4,7,31:1)
Block(-6,4,8,31:1)
Block(-5,0,-7,3)
Block(-5,0,-6,3)
Block(-5,0,-5,3)
Block(-5,0,-4,3)
Block(-5,0,-3,3)
Block(-5,0,-2,3)
Block(-5,0,-1,3)
Block(-5,0,0,3)
Block(-5,0,1,3)
Block(-5,0,2,3)
Block(-5,0,3,3)
Block(-5,0,4,3)
Block(-5,0,5,3)
Block(-5,0,6,3)
Block(-5,0,7,3)
Block(-5,0,8,3)
Block(-5,1,-7,2)
Block(-5,1,-6,2)
Block(-5,1,-5,2)
Block(-5,1,-4,60:7)
Block(-5,1,-3,60)
Block(-5,1,-2,2)
Block(-5,1,-1,60:7)
Block(-5,1,0,60:7)
Block(-5,1,1,2)
Block(-5,1,2,2)
Block(-5,1,3,2)
Block(-5,1,4,3)
Block(-5,1,5,3)
Block(-5,1,6,3)
Block(-5,1,7,3)
Block(-5,1,8,3)
Block(-5,2,-7,31:1)
Block(-5,2,-4,59:7)
Block(-5,2,-3,59:7)
Block(-5,2,-1,59:7)
Block(-5,2,0,59:7)
Block(-5,2,4,2)
Block(-5,2,5,2)
Block(-5,2,6,3)
Block(-5,2,7,3)
Block(-5,2,8,3)
Block(-5,3,4,31:1)
Block(-5,3,6,2)
Block(-5,3,7,2)
Block(-5,3,8,2)
Block(-5,4,7,31:1)
Block(-4,0,-7,3)
Block(-4,0,-6,3)
Block(-4,0,-5,3)
Block(-4,0,-4,3)
Block(-4,0,-3,3)
Block(-4,0,-2,3)
Block(-4,0,-1,3)
Block(-4,0,0,3)
Block(-4,0,1,3)
Block(-4,0,2,3)
Block(-4,0,3,3)
Block(-4,0,4,3)
Block(-4,0,5,3)
Block(-4,0,6,3)
Block(-4,0,7,3)
Block(-4,0,8,3)
Block(-4,1,-7,13)
Block(-4,1,-6,2)
Block(-4,1,-5,2)
Block(-4,1,-4,60:7)
Block(-4,1,-3,60)
Block(-4,1,-2,2)
Block(-4,1,-1,60:7)
Block(-4,1,0,60:7)
Block(-4,1,1,2)
Block(-4,1,2,2)
Block(-4,1,3,2)
Block(-4,1,4,3)
Block(-4,1,5,3)
Block(-4,1,6,3)
Block(-4,1,7,3)
Block(-4,1,8,3)
Block(-4,2,-5,31:1)
Block(-4,2,-4,59:7)
Block(-4,2,-3,59:7)
Block(-4,2,-1,59:7)
Block(-4,2,0,59:7)
Block(-4,2,4,2)
Block(-4,2,5,2)
Block(-4,2,6,3)
Block(-4,2,7,3)
Block(-4,2,8,3)
Block(-4,3,4,38:8)
Block(-4,3,5,31:1)
Block(-4,3,6,2)
Block(-4,3,7,2)
Block(-4,3,8,2)
Block(-4,4,7,31:1)
Block(-4,4,8,31:1)
Block(-3,0,-7,3)
Block(-3,0,-6,3)
Block(-3,0,-5,3)
Block(-3,0,-4,3)
Block(-3,0,-3,3)
Block(-3,0,-2,3)
Block(-3,0,-1,3)
Block(-3,0,0,3)
Block(-3,0,1,3)
Block(-3,0,2,3)
Block(-3,0,3,3)
Block(-3,0,4,3)
Block(-3,0,5,3)
Block(-3,0,6,3)
Block(-3,0,7,3)
Block(-3,0,8,3)
Block(-3,1,-7,13)
Block(-3,1,-6,2)
Block(-3,1,-5,2)
Block(-3,1,-4,60)
Block(-3,1,-3,60:7)
Block(-3,1,-2,2)
Block(-3,1,-1,60:7)
Block(-3,1,0,60:7)
Block(-3,1,1,2)
Block(-3,1,2,2)
Block(-3,1,3,2)
Block(-3,1,4,3)
Block(-3,1,5,3)
Block(-3,1,6,3)
Block(-3,1,7,3)
Block(-3,1,8,3)
Block(-3,2,-6,31:1)
Block(-3,2,-4,59:7)
Block(-3,2,-3,59:7)
Block(-3,2,-1,59:7)
Block(-3,2,0,59:7)
Block(-3,2,4,2)
Block(-3,2,5,2)
Block(-3,2,6,3)
Block(-3,2,7,3)
Block(-3,2,8,3)
Block(-3,3,5,31:1)
Block(-3,3,6,2)
Block(-3,3,7,2)
Block(-3,3,8,2)
Block(-3,4,6,38:8)
Block(-3,4,8,31:1)
Block(-3,6,5,18:2)
Block(-3,6,6,18:2)
Block(-3,6,7,18:2)
Block(-3,7,5,18:2)
Block(-3,7,6,18:2)
Block(-3,7,7,18:2)
Block(-2,0,-7,3)
Block(-2,0,-6,3)
Block(-2,0,-5,3)
Block(-2,0,-4,3)
Block(-2,0,-3,3)
Block(-2,0,-2,3)
Block(-2,0,-1,3)
Block(-2,0,0,3)
Block(-2,0,1,3)
Block(-2,0,2,3)
Block(-2,0,3,3)
Block(-2,0,4,3)
Block(-2,0,5,3)
Block(-2,0,6,3)
Block(-2,0,7,3)
Block(-2,0,8,3)
Block(-2,1,-7,13)
Block(-2,1,-6,13)
Block(-2,1,-5,2)
Block(-2,1,-4,60:7)
Block(-2,1,-3,60:7)
Block(-2,1,-2,2)
Block(-2,1,-1,60:7)
Block(-2,1,0,60)
Block(-2,1,1,2)
Block(-2,1,2,2)
Block(-2,1,3,2)
Block(-2,1,4,3)
Block(-2,1,5,3)
Block(-2,1,6,3)
Block(-2,1,7,3)
Block(-2,1,8,3)
Block(-2,2,-5,31:1)
Block(-2,2,-4,59:7)
Block(-2,2,-3,59:7)
Block(-2,2,-1,59:7)
Block(-2,2,0,59:7)
Block(-2,2,4,2)
Block(-2,2,5,2)
Block(-2,2,6,3)
Block(-2,2,7,3)
Block(-2,2,8,3)
Block(-2,3,6,2)
Block(-2,3,7,2)
Block(-2,3,8,2)
Block(-2,4,6,31:1)
Block(-2,4,8,31:1)
Block(-2,6,4,18:2)
Block(-2,6,5,18:2)
Block(-2,6,6,18:2)
Block(-2,6,7,18:2)
Block(-2,6,8,18:2)
Block(-2,7,4,18:2)
Block(-2,7,5,18:2)
Block(-2,7,6,18:2)
Block(-2,7,7,18:2)
Block(-2,7,8,18:2)
Block(-2,8,6,18:2)
Block(-2,8,7,18:2)
Block(-2,9,6,18:2)
Block(-1,0,-7,3)
Block(-1,0,-6,3)
Block(-1,0,-5,3)
Block(-1,0,-4,3)
Block(-1,0,-3,3)
Block(-1,0,-2,3)
Block(-1,0,-1,3)
Block(-1,0,0,3)
Block(-1,0,1,3)
Block(-1,0,2,3)
Block(-1,0,3,3)
Block(-1,0,4,3)
Block(-1,0,5,3)
Block(-1,0,6,3)
Block(-1,0,7,3)
Block(-1,0,8,3)
Block(-1,1,-7,13)
Block(-1,1,-6,13)
Block(-1,1,-5,2)
Block(-1,1,-4,2)
Block(-1,1,-3,2)
Block(-1,1,-2,2)
Block(-1,1,-1,2)
Block(-1,1,0,2)
Block(-1,1,1,2)
Block(-1,1,2,2)
Block(-1,1,3,2)
Block(-1,1,4,3)
Block(-1,1,5,3)
Block(-1,1,6,3)
Block(-1,1,7,3)
Block(-1,1,8,3)
Block(-1,2,-1,31:1)
Block(-1,2,0,31:1)
Block(-1,2,4,2)
Block(-1,2,5,3)
Block(-1,2,6,3)
Block(-1,2,7,3)
Block(-1,2,8,3)
Block(-1,3,5,2)
Block(-1,3,6,3)
Block(-1,3,7,2)
Block(-1,3,8,2)
Block(-1,4,6,17:2)
Block(-1,4,8,31:1)
Block(-1,5,6,17:2)
Block(-1,6,4,18:2)
Block(-1,6,5,18:2)
Block(-1,6,6,17:2)
Block(-1,6,7,18:2)
Block(-1,6,8,18:2)
Block(-1,7,4,18:2)
Block(-1,7,5,18:2)
Block(-1,7,6,17:2)
Block(-1,7,7,18:2)
Block(-1,7,8,18:2)
Block(-1,8,5,18:2)
Block(-1,8,6,17:2)
Block(-1,8,7,18:2)
Block(-1,9,5,18:2)
Block(-1,9,6,18:2)
Block(-1,9,7,18:2)
Block(0,0,-7,3)
Block(0,0,-6,3)
Block(0,0,-5,3)
Block(0,0,-4,3)
Block(0,0,-3,3)
Block(0,0,-2,3)
Block(0,0,-1,3)
Block(0,0,0,3)
Block(0,0,1,3)
Block(0,0,2,3)
Block(0,0,3,3)
Block(0,0,4,3)
Block(0,0,5,3)
Block(0,0,6,3)
Block(0,0,7,3)
Block(0,0,8,3)
Block(0,1,-7,2)
Block(0,1,-6,13)
Block(0,1,-5,13)
Block(0,1,-4,2)
Block(0,1,-3,2)
Block(0,1,-2,2)
Block(0,1,-1,2)
Block(0,1,0,2)
Block(0,1,1,2)
Block(0,1,2,2)
Block(0,1,3,2)
Block(0,1,4,2)
Block(0,1,5,3)
Block(0,1,6,3)
Block(0,1,7,3)
Block(0,1,8,3)
Block(0,2,-3,31:1)
Block(0,2,5,2)
Block(0,2,6,3)
Block(0,2,7,3)
Block(0,2,8,3)
Block(0,3,6,2)
Block(0,3,7,2)
Block(0,3,8,2)
Block(0,6,4,18:2)
Block(0,6,5,18:2)
Block(0,6,6,18:2)
Block(0,6,7,18:2)
Block(0,6,8,18:2)
Block(0,7,4,18:2)
Block(0,7,5,18:2)
Block(0,7,6,18:2)
Block(0,7,7,18:2)
Block(0,7,8,18:2)
Block(0,8,6,18:2)
Block(0,9,6,18:2)
Block(1,0,-7,3)
Block(1,0,-6,3)
Block(1,0,-5,3)
Block(1,0,-4,3)
Block(1,0,-3,3)
Block(1,0,-2,3)
Block(1,0,-1,3)
Block(1,0,0,3)
Block(1,0,1,3)
Block(1,0,2,3)
Block(1,0,3,3)
Block(1,0,4,3)
Block(1,0,5,3)
Block(1,0,6,3)
Block(1,0,7,3)
Block(1,0,8,3)
Block(1,1,-7,2)
Block(1,1,-6,2)
Block(1,1,-5,13)
Block(1,1,-4,13)
Block(1,1,-3,13)
Block(1,1,-2,2)
Block(1,1,-1,2)
Block(1,1,0,2)
Block(1,1,1,2)
Block(1,1,2,2)
Block(1,1,3,2)
Block(1,1,4,2)
Block(1,1,5,3)
Block(1,1,6,3)
Block(1,1,7,3)
Block(1,1,8,3)
Block(1,2,-6,31:1)
Block(1,2,0,31:1)
Block(1,2,3,31:1)
Block(1,2,4,31:1)
Block(1,2,5,2)
Block(1,2,6,3)
Block(1,2,7,3)
Block(1,2,8,3)
Block(1,3,6,2)
Block(1,3,7,2)
Block(1,3,8,2)
Block(1,6,4,18:2)
Block(1,6,5,18:2)
Block(1,6,6,18:2)
Block(1,6,7,18:2)
Block(1,6,8,18:2)
Block(1,7,4,18:2)
Block(1,7,5,18:2)
Block(1,7,6,18:2)
Block(1,7,7,18:2)
Block(1,7,8,18:2)
Block(1,26,-4,17:5)
Block(2,0,-7,3)
Block(2,0,-6,3)
Block(2,0,-5,3)
Block(2,0,-4,3)
Block(2,0,-3,3)
Block(2,0,-2,3)
Block(2,0,-1,3)
Block(2,0,0,3)
Block(2,0,1,3)
Block(2,0,2,3)
Block(2,0,3,3)
Block(2,0,4,3)
Block(2,0,5,3)
Block(2,0,6,3)
Block(2,0,7,3)
Block(2,0,8,3)
Block(2,1,-7,2)
Block(2,1,-6,2)
Block(2,1,-5,13)
Block(2,1,-4,13)
Block(2,1,-3,13)
Block(2,1,-2,2)
Block(2,1,-1,2)
Block(2,1,0,2)
Block(2,1,1,2)
Block(2,1,2,2)
Block(2,1,3,2)
Block(2,1,4,2)
Block(2,1,5,3)
Block(2,1,6,3)
Block(2,1,7,3)
Block(2,1,8,3)
Block(2,2,-2,31:1)
Block(2,2,-1,31:1)
Block(2,2,2,31:1)
Block(2,2,3,38:8)
Block(2,2,5,2)
Block(2,2,6,3)
Block(2,2,7,3)
Block(2,2,8,3)
Block(2,3,6,2)
Block(2,3,7,2)
Block(2,3,8,2)
Block(2,7,-7,85)
Block(2,8,-7,5:1)
Block(2,9,-7,5:1)
Block(2,10,-7,5:1)
Block(2,11,-7,5:1)
Block(2,12,-7,5:1)
Block(2,13,-7,5:1)
Block(2,13,-6,5:1)
Block(2,14,-7,5:1)
Block(2,14,-6,5:1)
Block(2,15,-7,85)
Block(2,15,-6,5:1)
Block(2,16,-7,85)
Block(2,16,-6,5:1)
Block(2,17,-7,85)
Block(2,17,-6,5:1)
Block(2,18,-7,85)
Block(2,18,-6,5:1)
Block(2,18,-5,5:1)
Block(2,19,-7,85)
Block(2,19,-6,85)
Block(2,19,-5,5:1)
Block(2,20,-7,85)
Block(2,20,-6,85)
Block(2,20,-5,5:1)
Block(2,20,8,85)
Block(2,21,-7,85)
Block(2,21,-6,85)
Block(2,21,-5,5:1)
Block(2,21,-4,5:1)
Block(2,21,4,85)
Block(2,21,5,85)
Block(2,21,6,85)
Block(2,21,7,85)
Block(2,21,8,85)
Block(2,22,-7,85)
Block(2,22,-6,85)
Block(2,22,-5,5:1)
Block(2,22,-4,5:1)
Block(2,22,0,85)
Block(2,22,1,85)
Block(2,22,2,85)
Block(2,22,3,85)
Block(2,22,4,85)
Block(2,22,5,85)
Block(2,22,6,85)
Block(2,22,7,85)
Block(2,22,8,85)
Block(2,23,-7,85)
Block(2,23,-6,85)
Block(2,23,-5,85)
Block(2,23,-4,5:1)
Block(2,23,-3,85)
Block(2,23,-2,85)
Block(2,23,-1,85)
Block(2,23,0,85)
Block(2,23,1,85)
Block(2,23,2,85)
Block(2,23,3,85)
Block(2,23,4,85)
Block(2,23,5,85)
Block(2,23,6,85)
Block(2,23,7,85)
Block(2,23,8,5:1)
Block(2,24,-7,85)
Block(2,24,-6,85)
Block(2,24,-5,85)
Block(2,24,-4,5:1)
Block(2,24,-3,85)
Block(2,24,-2,85)
Block(2,24,-1,85)
Block(2,24,0,85)
Block(2,24,1,85)
Block(2,24,2,85)
Block(2,24,3,85)
Block(2,24,4,5:1)
Block(2,24,5,5:1)
Block(2,24,6,5:1)
Block(2,24,7,5:1)
Block(2,24,8,5:1)
Block(2,25,-7,85)
Block(2,25,-6,85)
Block(2,25,-5,85)
Block(2,25,-4,5:1)
Block(2,25,-3,85)
Block(2,25,-2,85)
Block(2,25,-1,85)
Block(2,25,0,5:1)
Block(2,25,1,5:1)
Block(2,25,2,5:1)
Block(2,25,3,5:1)
Block(2,25,4,5:1)
Block(2,26,-7,5:1)
Block(2,26,-6,5:1)
Block(2,26,-5,5:1)
Block(2,26,-4,17:5)
Block(2,26,-3,5:1)
Block(2,26,-2,5:1)
Block(2,26,-1,5:1)
Block(2,26,0,5:1)
Block(2,26,1,5:1)
Block(2,27,-7,85)
Block(2,27,-6,85)
Block(2,27,-5,85)
Block(2,27,-4,5:1)
Block(2,27,-3,85)
Block(2,27,-2,85)
Block(2,27,-1,85)
Block(2,28,-7,85)
Block(2,28,-6,85)
Block(2,28,-5,85)
Block(2,28,-4,5:1)
Block(2,28,-3,85)
Block(2,28,-2,85)
Block(2,28,-1,85)
Block(2,29,-7,85)
Block(2,29,-6,85)
Block(2,29,-5,85)
Block(2,29,-4,5:1)
Block(2,29,-3,85)
Block(2,29,-2,85)
Block(2,29,-1,85)
Block(2,30,-4,5:1)
Block(2,30,-3,5:1)
Block(2,30,-2,85)
Block(2,30,-1,85)
Block(2,30,0,85)
Block(2,31,-4,5:1)
Block(2,31,-3,5:1)
Block(2,31,-2,85)
Block(2,31,-1,85)
Block(2,31,0,85)
Block(2,32,-3,5:1)
Block(2,32,-2,85)
Block(2,32,-1,85)
Block(2,32,0,85)
Block(2,33,-3,5:1)
Block(2,33,-2,85)
Block(2,33,-1,85)
Block(2,33,0,85)
Block(2,34,-3,5:1)
Block(2,34,-2,5:1)
Block(2,34,-1,85)
Block(2,34,0,85)
Block(2,34,1,85)
Block(2,35,-2,5:1)
Block(2,35,-1,85)
Block(2,35,0,85)
Block(2,35,1,85)
Block(2,36,-2,5:1)
Block(2,36,-1,85)
Block(2,36,0,85)
Block(2,36,1,85)
Block(2,37,-2,5:1)
Block(2,37,-1,85)
Block(2,37,0,85)
Block(2,37,1,85)
Block(2,38,-2,5:1)
Block(2,38,-1,5:1)
Block(2,38,0,85)
Block(2,38,1,85)
Block(2,38,2,85)
Block(2,39,-2,5:1)
Block(2,39,-1,5:1)
Block(2,39,0,85)
Block(2,39,1,85)
Block(2,39,2,85)
Block(2,40,-1,5:1)
Block(2,40,0,85)
Block(2,40,1,85)
Block(2,40,2,85)
Block(2,41,-1,5:1)
Block(2,41,0,85)
Block(2,41,1,85)
Block(2,41,2,85)
Block(2,42,-1,5:1)
Block(2,42,0,85)
Block(2,42,1,85)
Block(2,42,2,85)
Block(2,43,-1,5:1)
Block(2,43,0,85)
Block(2,43,1,85)
Block(2,43,2,85)
Block(2,44,-1,5:1)
Block(2,44,0,85)
Block(2,44,1,85)
Block(2,44,2,85)
Block(2,45,-1,85)
Block(2,45,0,85)
Block(2,45,1,85)
Block(3,0,-7,3)
Block(3,0,-6,3)
Block(3,0,-5,3)
Block(3,0,-4,3)
Block(3,0,-3,3)
Block(3,0,-2,3)
Block(3,0,-1,3)
Block(3,0,0,3)
Block(3,0,1,3)
Block(3,0,2,3)
Block(3,0,3,3)
Block(3,0,4,3)
Block(3,0,5,3)
Block(3,0,6,3)
Block(3,0,7,3)
Block(3,0,8,3)
Block(3,1,-7,13)
Block(3,1,-6,13)
Block(3,1,-5,13)
Block(3,1,-4,13)
Block(3,1,-3,13)
Block(3,1,-2,13)
Block(3,1,-1,13)
Block(3,1,0,5)
Block(3,1,1,13)
Block(3,1,2,13)
Block(3,1,3,13)
Block(3,1,4,2)
Block(3,1,5,3)
Block(3,1,6,3)
Block(3,1,7,3)
Block(3,1,8,3)
Block(3,2,-7,85)
Block(3,2,-6,85)
Block(3,2,-2,85)
Block(3,2,-1,85)
Block(3,2,0,85)
Block(3,2,5,2)
Block(3,2,6,3)
Block(3,2,7,3)
Block(3,2,8,3)
Block(3,3,-6,50:5)
Block(3,3,-2,50:5)
Block(3,3,0,85)
Block(3,3,6,2)
Block(3,3,7,2)
Block(3,3,8,2)
Block(3,4,0,85)
Block(3,5,0,85)
Block(3,6,-7,134:7)
Block(3,6,-6,134:4)
Block(3,6,-5,134:4)
Block(3,6,-4,134:4)
Block(3,6,-3,134:4)
Block(3,6,-2,134:4)
Block(3,6,-1,134:6)
Block(3,6,0,5:1)
Block(3,6,1,134:4)
Block(3,6,2,134:4)
Block(3,6,3,134:4)
Block(3,7,-6,85)
Block(3,7,-5,85)
Block(3,7,-4,85)
Block(3,7,-3,85)
Block(3,7,-2,85)
Block(3,8,-6,50:5)
Block(3,8,-2,50:5)
Block(3,26,-4,17:5)
Block(4,0,-7,3)
Block(4,0,-6,3)
Block(4,0,-5,3)
Block(4,0,-4,3)
Block(4,0,-3,3)
Block(4,0,-2,3)
Block(4,0,-1,3)
Block(4,0,0,3)
Block(4,0,1,3)
Block(4,0,2,3)
Block(4,0,3,3)
Block(4,0,4,3)
Block(4,0,5,3)
Block(4,0,6,3)
Block(4,0,7,3)
Block(4,0,8,3)
Block(4,1,-7,3:2)
Block(4,1,-6,3)
Block(4,1,-5,13)
Block(4,1,-4,13)
Block(4,1,-3,13)
Block(4,1,-2,3)
Block(4,1,-1,3:2)
Block(4,1,0,3:2)
Block(4,1,1,3:2)
Block(4,1,2,5)
Block(4,1,3,13)
Block(4,1,4,2)
Block(4,1,5,3)
Block(4,1,6,3)
Block(4,1,7,3)
Block(4,1,8,3)
Block(4,2,-7,38:3)
Block(4,2,-6,17)
Block(4,2,-5,85)
Block(4,2,-4,72)
Block(4,2,-3,85)
Block(4,2,-2,17)
Block(4,2,-1,37)
Block(4,2,0,38:5)
Block(4,2,1,31:1)
Block(4,2,2,85)
Block(4,2,5,2)
Block(4,2,6,2)
Block(4,2,7,3)
Block(4,2,8,3)
Block(4,3,-6,45)
Block(4,3,-5,85)
Block(4,3,-3,85)
Block(4,3,-2,45)
Block(4,3,2,85)
Block(4,3,7,2)
Block(4,3,8,2)
Block(4,4,-6,45)
Block(4,4,-5,50:5)
Block(4,4,-3,50:5)
Block(4,4,-2,45)
Block(4,4,2,85)
Block(4,5,-7,134:6)
Block(4,5,-6,17:8)
Block(4,5,-5,17:8)
Block(4,5,-4,17:8)
Block(4,5,-3,17:8)
Block(4,5,-2,17:8)
Block(4,5,-1,134:7)
Block(4,5,0,134:4)
Block(4,5,1,134:7)
Block(4,5,2,85)
Block(4,6,-7,5:1)
Block(4,6,-6,5:1)
Block(4,6,-5,5:1)
Block(4,6,-4,5:1)
Block(4,6,-3,5:1)
Block(4,6,-2,5:1)
Block(4,6,-1,5:1)
Block(4,6,0,5:1)
Block(4,6,1,5:1)
Block(4,6,2,5:1)
Block(4,6,3,134:7)
Block(4,7,-7,85)
Block(4,7,-6,85)
Block(4,7,-2,85)
Block(4,7,-1,85)
Block(4,7,0,85)
Block(4,7,1,85)
Block(4,7,2,85)
Block(4,7,3,85)
Block(4,8,-7,50:5)
Block(4,8,-1,50:5)
Block(4,8,3,50:5)
Block(4,11,-7,17:4)
Block(4,11,-6,85)
Block(4,11,-5,85)
Block(4,11,-4,85)
Block(4,11,-3,85)
Block(4,11,-2,85)
Block(4,11,-1,17:4)
Block(4,26,-4,17:5)
Block(5,0,-7,3)
Block(5,0,-6,3)
Block(5,0,-5,3)
Block(5,0,-4,3)
Block(5,0,-3,3)
Block(5,0,-2,3)
Block(5,0,-1,3)
Block(5,0,0,3)
Block(5,0,1,3)
Block(5,0,2,3)
Block(5,0,3,3)
Block(5,0,4,3)
Block(5,0,5,3)
Block(5,0,6,3)
Block(5,0,7,3)
Block(5,0,8,3)
Block(5,1,-7,3)
Block(5,1,-6,3)
Block(5,1,-5,3)
Block(5,1,-4,5:2)
Block(5,1,-3,3)
Block(5,1,-2,3)
Block(5,1,-1,3)
Block(5,1,0,3)
Block(5,1,1,3:2)
Block(5,1,2,3:2)
Block(5,1,3,13)
Block(5,1,4,2)
Block(5,1,5,3)
Block(5,1,6,3)
Block(5,1,7,3)
Block(5,1,8,3)
Block(5,2,-7,17)
Block(5,2,-6,17)
Block(5,2,-5,17)
Block(5,2,-4,193)
Block(5,2,-3,17)
Block(5,2,-2,17)
Block(5,2,-1,17)
Block(5,2,0,17)
Block(5,2,1,175:2)
Block(5,2,2,38:5)
Block(5,2,5,2)
Block(5,2,6,2)
Block(5,2,7,3)
Block(5,2,8,3)
Block(5,3,-7,17)
Block(5,3,-6,45)
Block(5,3,-5,45)
Block(5,3,-4,193:8)
Block(5,3,-3,45)
Block(5,3,-2,45)
Block(5,3,-1,17)
Block(5,3,0,45)
Block(5,3,1,175:8)
Block(5,3,7,2)
Block(5,3,8,2)
Block(5,4,-7,17)
Block(5,4,-6,45)
Block(5,4,-5,45)
Block(5,4,-4,45)
Block(5,4,-3,45)
Block(5,4,-2,45)
Block(5,4,-1,17)
Block(5,4,0,45)
Block(5,5,-7,17:8)
Block(5,5,-6,17:8)
Block(5,5,-5,17:8)
Block(5,5,-4,17:8)
Block(5,5,-3,17:8)
Block(5,5,-2,17:8)
Block(5,5,-1,17:8)
Block(5,5,0,17:8)
Block(5,5,1,134:7)
Block(5,5,2,134:4)
Block(5,6,-7,17)
Block(5,6,-6,45)
Block(5,6,-5,45)
Block(5,6,-4,45)
Block(5,6,-3,45)
Block(5,6,-2,45)
Block(5,6,-1,17)
Block(5,6,0,5:1)
Block(5,6,1,5:1)
Block(5,6,2,5:1)
Block(5,6,3,134:4)
Block(5,6,4,134:7)
Block(5,7,-7,17)
Block(5,7,-6,45)
Block(5,7,-5,45)
Block(5,7,-4,45)
Block(5,7,-3,193:2)
Block(5,7,-2,45)
Block(5,7,-1,17)
Block(5,7,3,85)
Block(5,7,4,85)
Block(5,8,-7,17)
Block(5,8,-6,45)
Block(5,8,-5,102)
Block(5,8,-4,45)
Block(5,8,-3,193:8)
Block(5,8,-2,45)
Block(5,8,-1,17)
Block(5,9,-7,17)
Block(5,9,-6,45)
Block(5,9,-5,102)
Block(5,9,-4,45)
Block(5,9,-3,45)
Block(5,9,-2,45)
Block(5,9,-1,17)
Block(5,10,-7,17)
Block(5,10,-6,45)
Block(5,10,-5,45)
Block(5,10,-4,45)
Block(5,10,-3,45)
Block(5,10,-2,45)
Block(5,10,-1,17)
Block(5,11,-7,17:8)
Block(5,11,-6,17:8)
Block(5,11,-5,17:8)
Block(5,11,-4,17:8)
Block(5,11,-3,17:8)
Block(5,11,-2,17:8)
Block(5,11,-1,17:8)
Block(5,11,0,85)
Block(5,11,1,17:4)
Block(5,12,-7,85)
Block(5,12,-6,85)
Block(5,12,-5,85)
Block(5,12,-4,85)
Block(5,12,-3,85)
Block(5,12,-2,85)
Block(5,12,-1,85)
Block(5,26,-4,17:5)
Block(6,0,-7,3)
Block(6,0,-6,3)
Block(6,0,-5,3)
Block(6,0,-4,3)
Block(6,0,-3,3)
Block(6,0,-2,3)
Block(6,0,-1,3)
Block(6,0,0,3)
Block(6,0,1,3)
Block(6,0,2,3)
Block(6,0,3,3)
Block(6,0,4,3)
Block(6,0,5,3)
Block(6,0,6,3)
Block(6,0,7,3)
Block(6,0,8,3)
Block(6,1,-7,5:2)
Block(6,1,-6,5:2)
Block(6,1,-5,5:2)
Block(6,1,-4,5:2)
Block(6,1,-3,5:2)
Block(6,1,-2,2)
Block(6,1,-1,2)
Block(6,1,0,2)
Block(6,1,1,3)
Block(6,1,2,3:2)
Block(6,1,3,13)
Block(6,1,4,3)
Block(6,1,5,3)
Block(6,1,6,3)
Block(6,1,7,3)
Block(6,1,8,3)
Block(6,2,-5,85)
Block(6,2,-4,72)
Block(6,2,-2,108:2)
Block(6,2,1,17)
Block(6,2,2,38:3)
Block(6,2,4,2)
Block(6,2,5,2)
Block(6,2,6,2)
Block(6,2,7,3)
Block(6,2,8,3)
Block(6,3,-5,50:5)
Block(6,3,-1,108:2)
Block(6,3,0,45)
Block(6,3,1,17)
Block(6,3,4,31:1)
Block(6,3,7,2)
Block(6,3,8,2)
Block(6,4,1,17)
Block(6,5,-7,50:3)
Block(6,5,1,17:4)
Block(6,5,2,134:7)
Block(6,5,3,134:4)
Block(6,6,-7,5:2)
Block(6,6,-6,5:2)
Block(6,6,-5,5:2)
Block(6,6,-4,5:2)
Block(6,6,-3,5:2)
Block(6,6,-2,5:2)
Block(6,6,-1,5:2)
Block(6,6,1,5)
Block(6,6,2,5:1)
Block(6,6,3,5:1)
Block(6,6,4,134:7)
Block(6,6,5,134:4)
Block(6,7,-7,17)
Block(6,7,-6,85)
Block(6,7,-5,85)
Block(6,7,-4,85)
Block(6,7,-3,72)
Block(6,7,-2,85)
Block(6,7,-1,17)
Block(6,7,0,45)
Block(6,7,1,17)
Block(6,7,4,85)
Block(6,7,5,85)
Block(6,8,-7,17)
Block(6,8,-6,50:5)
Block(6,8,-4,50:5)
Block(6,8,-2,50:5)
Block(6,8,-1,17)
Block(6,8,0,45)
Block(6,8,1,17)
Block(6,8,5,50:5)
Block(6,9,-7,17)
Block(6,9,-1,17)
Block(6,9,0,45)
Block(6,9,1,17)
Block(6,10,-7,17)
Block(6,10,-6,85)
Block(6,10,-5,85)
Block(6,10,-4,85)
Block(6,10,-3,85)
Block(6,10,-2,85)
Block(6,10,-1,17)
Block(6,10,0,45)
Block(6,10,1,17)
Block(6,11,-7,17:8)
Block(6,11,-6,17:8)
Block(6,11,-5,17:8)
Block(6,11,-4,17:8)
Block(6,11,-3,17:8)
Block(6,11,-2,17:8)
Block(6,11,-1,17:8)
Block(6,11,0,17:8)
Block(6,11,1,17:8)
Block(6,11,2,17:8)
Block(6,12,0,85)
Block(6,12,1,85)
Block(6,19,-7,85)
Block(6,19,-6,85)
Block(6,19,-5,85)
Block(6,19,-4,85)
Block(6,19,-3,85)
Block(6,19,-2,85)
Block(6,19,-1,85)
Block(6,19,0,17:4)
Block(6,20,-7,134)
Block(6,20,-6,134)
Block(6,20,-5,134)
Block(6,20,-4,134)
Block(6,20,-3,134)
Block(6,20,-2,134)
Block(6,20,-1,134)
Block(6,20,0,134)
Block(6,20,1,134:3)
Block(6,26,-4,17:5)
Block(7,0,-7,3)
Block(7,0,-6,3)
Block(7,0,-5,3)
Block(7,0,-4,3)
Block(7,0,-3,3)
Block(7,0,-2,3)
Block(7,0,-1,3)
Block(7,0,0,3)
Block(7,0,1,3)
Block(7,0,2,3)
Block(7,0,3,3)
Block(7,0,4,3)
Block(7,0,5,3)
Block(7,0,6,3)
Block(7,0,7,3)
Block(7,0,8,3)
Block(7,1,-7,5:2)
Block(7,1,-6,5:2)
Block(7,1,-5,5:2)
Block(7,1,-4,5:2)
Block(7,1,-3,5:2)
Block(7,1,-2,2)
Block(7,1,-1,3)
Block(7,1,0,2)
Block(7,1,1,2)
Block(7,1,2,3)
Block(7,1,3,3)
Block(7,1,4,3)
Block(7,1,5,3)
Block(7,1,6,3)
Block(7,1,7,3)
Block(7,1,8,3)
Block(7,2,-2,108:2)
Block(7,2,-1,2)
Block(7,2,2,17)
Block(7,2,3,2)
Block(7,2,4,5)
Block(7,2,5,2)
Block(7,2,6,2)
Block(7,2,7,3)
Block(7,2,8,3)
Block(7,3,-1,108:2)
Block(7,3,0,44:12)
Block(7,3,2,45)
Block(7,3,3,38:3)
Block(7,3,4,85)
Block(7,3,7,2)
Block(7,3,8,2)
Block(7,4,1,45)
Block(7,4,2,45)
Block(7,4,4,85)
Block(7,5,1,45)
Block(7,5,2,17:4)
Block(7,5,3,134:7)
Block(7,5,4,85)
Block(7,6,-7,5:2)
Block(7,6,-6,5:2)
Block(7,6,-5,5:2)
Block(7,6,-4,5:2)
Block(7,6,-3,5:2)
Block(7,6,-2,5:2)
Block(7,6,-1,5:2)
Block(7,6,1,45)
Block(7,6,2,5:1)
Block(7,6,3,5:1)
Block(7,6,4,5:1)
Block(7,6,5,134:7)
Block(7,7,-7,58)
Block(7,7,0,17)
Block(7,7,1,45)
Block(7,7,5,85)
Block(7,8,-7,58)
Block(7,8,0,17)
Block(7,8,1,45)
Block(7,9,-7,58)
Block(7,9,0,17)
Block(7,9,1,45)
Block(7,10,-7,85)
Block(7,10,-1,85)
Block(7,10,0,17)
Block(7,10,1,45)
Block(7,11,-7,5:2)
Block(7,11,-6,5:2)
Block(7,11,-5,5:2)
Block(7,11,-4,5:2)
Block(7,11,-3,5:2)
Block(7,11,-2,5:2)
Block(7,11,-1,5:2)
Block(7,11,0,17:4)
Block(7,11,1,17:4)
Block(7,11,2,85)
Block(7,12,-7,17)
Block(7,12,-6,45)
Block(7,12,-5,45)
Block(7,12,-4,45)
Block(7,12,-3,45)
Block(7,12,-2,45)
Block(7,12,-1,17)
Block(7,12,1,85)
Block(7,13,-7,17)
Block(7,13,-6,45)
Block(7,13,-5,102)
Block(7,13,-4,45)
Block(7,13,-3,102)
Block(7,13,-2,45)
Block(7,13,-1,17)
Block(7,14,-7,17)
Block(7,14,-6,45)
Block(7,14,-5,102)
Block(7,14,-4,45)
Block(7,14,-3,102)
Block(7,14,-2,45)
Block(7,14,-1,17)
Block(7,15,-7,17)
Block(7,15,-6,45)
Block(7,15,-5,45)
Block(7,15,-4,45)
Block(7,15,-3,45)
Block(7,15,-2,45)
Block(7,15,-1,17)
Block(7,16,-7,17)
Block(7,16,-6,45)
Block(7,16,-5,102)
Block(7,16,-4,45)
Block(7,16,-3,102)
Block(7,16,-2,45)
Block(7,16,-1,17)
Block(7,17,-7,17)
Block(7,17,-6,45)
Block(7,17,-5,102)
Block(7,17,-4,45)
Block(7,17,-3,102)
Block(7,17,-2,45)
Block(7,17,-1,17)
Block(7,18,-7,17)
Block(7,18,-6,45)
Block(7,18,-5,45)
Block(7,18,-4,45)
Block(7,18,-3,45)
Block(7,18,-2,45)
Block(7,18,-1,17)
Block(7,19,-7,17:8)
Block(7,19,-6,17:8)
Block(7,19,-5,17:8)
Block(7,19,-4,17:8)
Block(7,19,-3,17:8)
Block(7,19,-2,17:8)
Block(7,19,-1,17:8)
Block(7,19,0,17:4)
Block(7,19,1,17:8)
Block(7,20,-7,5:1)
Block(7,20,-6,5:1)
Block(7,20,-5,5:1)
Block(7,20,-4,5:1)
Block(7,20,-3,5:1)
Block(7,20,-2,5:1)
Block(7,20,-1,5:1)
Block(7,20,0,5:1)
Block(7,20,1,134:3)
Block(7,21,-7,134)
Block(7,21,-6,5:1)
Block(7,21,-5,102)
Block(7,21,-4,102)
Block(7,21,-3,102)
Block(7,21,-2,5:1)
Block(7,21,-1,134)
Block(7,21,0,134)
Block(7,22,-6,5:1)
Block(7,22,-5,5:1)
Block(7,22,-4,102)
Block(7,22,-3,5:1)
Block(7,22,-2,5:1)
Block(7,23,-6,5:1)
Block(7,23,-5,5:1)
Block(7,23,-4,5:1)
Block(7,23,-3,5:1)
Block(7,23,-2,5:1)
Block(7,24,-6,5:1)
Block(7,24,-5,5:1)
Block(7,24,-4,5:1)
Block(7,24,-3,5:1)
Block(7,24,-2,5:1)
Block(7,25,-6,5:1)
Block(7,25,-5,5:1)
Block(7,25,-4,5:1)
Block(7,25,-3,5:1)
Block(7,25,-2,5:1)
Block(7,26,-4,17:5)

Branch(16,0,0,true,monsterley-s-grainC1R1,NORTH,100,0)
Branch(0,0,16,true,monsterley-s-grainC0R2,NORTH,100,0)
