

BranchFrequencyGroup: CanOverride:0

CanOverride: true

SmoothRadius: -1

OverrideChildSettings: false

ReplaceAbove:
ReplaceBelow:

MustBeInside: VillageGeneratorStructurePlaceHolder, VillageGeneratorStructuresDelay, VillageGeneratorStructuresDelay2, VillageGeneratorStructuresDelay3, VillageGeneratorStructuresDelay4, VillageGeneratorStructuresDelay5, VillageGeneratorStructuresDelay6, VillageGeneratorStructuresDelay7, VillageGeneratorStructuresDelay8, VillageGeneratorStructuresDelay9, VillageGeneratorStructuresDelay10

Block(-8,0,-7,1)
Block(-8,0,-6,1)
Block(-8,0,-5,1)
Block(-8,0,-4,1)
Block(-8,0,-3,1)
Block(-8,0,-2,1)
Block(-8,0,-1,1)
Block(-8,0,0,1)
Block(-8,0,1,1)
Block(-8,0,2,1)
Block(-8,0,3,1)
Block(-8,1,-7,1)
Block(-8,1,-6,1)
Block(-8,1,-5,1)
Block(-8,1,-4,1)
Block(-8,1,-3,1)
Block(-8,1,-2,1)
Block(-8,1,-1,1)
Block(-8,1,0,1)
Block(-8,1,1,1)
Block(-8,1,2,1)
Block(-8,1,3,1)
Block(-8,2,-7,1)
Block(-8,2,-6,1)
Block(-8,2,-5,1)
Block(-8,2,-4,1)
Block(-8,2,-3,1)
Block(-8,2,-2,1)
Block(-8,2,-1,1)
Block(-8,2,0,1)
Block(-8,2,1,1)
Block(-8,2,2,1)
Block(-8,2,3,1)
Block(-8,3,-7,3)
Block(-8,3,-6,1)
Block(-8,3,-5,1)
Block(-8,3,-4,1)
Block(-8,3,-3,1)
Block(-8,3,-2,1)
Block(-8,3,-1,1)
Block(-8,3,0,1)
Block(-8,3,1,1)
Block(-8,3,2,1)
Block(-8,3,3,1)
Block(-8,4,-7,3)
Block(-8,4,-6,3)
Block(-8,4,-5,3)
Block(-8,4,-4,1)
Block(-8,4,-3,1)
Block(-8,4,-2,1)
Block(-8,4,-1,1)
Block(-8,4,0,1)
Block(-8,4,1,1)
Block(-8,4,2,1)
Block(-8,4,3,1)
Block(-8,5,-7,2)
Block(-8,5,-6,3)
Block(-8,5,-5,3)
Block(-8,5,-4,3)
Block(-8,5,-3,1)
Block(-8,5,-2,1)
Block(-8,5,-1,1)
Block(-8,5,0,1)
Block(-8,5,1,1)
Block(-8,5,2,1)
Block(-8,5,3,1)
Block(-8,6,-6,2)
Block(-8,6,-5,2)
Block(-8,6,-4,3)
Block(-8,6,-3,3)
Block(-8,6,-2,1)
Block(-8,6,-1,1)
Block(-8,6,0,1)
Block(-8,6,1,1)
Block(-8,6,2,1)
Block(-8,6,3,1)
Block(-8,7,-4,2)
Block(-8,7,-3,3)
Block(-8,7,-2,1)
Block(-8,7,-1,16)
Block(-8,7,0,16)
Block(-8,7,1,1)
Block(-8,7,2,3)
Block(-8,7,3,3)
Block(-8,8,-3,2)
Block(-8,8,-2,3)
Block(-8,8,-1,3)
Block(-8,8,0,3)
Block(-8,8,1,3)
Block(-8,8,2,3)
Block(-8,8,3,3)
Block(-8,9,-2,3)
Block(-8,9,-1,3)
Block(-8,9,0,3)
Block(-8,9,1,3)
Block(-8,9,2,3)
Block(-8,9,3,3)
Block(-8,10,-2,2)
Block(-8,10,-1,2)
Block(-8,10,0,2)
Block(-8,10,1,2)
Block(-8,10,2,2)
Block(-8,10,3,2)
Block(-7,0,-7,1)
Block(-7,0,-6,1)
Block(-7,0,-5,1)
Block(-7,0,-4,1)
Block(-7,0,-3,1)
Block(-7,0,-2,1)
Block(-7,0,-1,1)
Block(-7,0,0,1)
Block(-7,0,1,1)
Block(-7,0,2,1)
Block(-7,0,3,1)
Block(-7,1,-7,1)
Block(-7,1,-6,1)
Block(-7,1,-5,1)
Block(-7,1,-4,1)
Block(-7,1,-3,1)
Block(-7,1,-2,1)
Block(-7,1,-1,1)
Block(-7,1,0,1)
Block(-7,1,1,1)
Block(-7,1,2,1)
Block(-7,1,3,1)
Block(-7,2,-7,1)
Block(-7,2,-6,1)
Block(-7,2,-5,1)
Block(-7,2,-4,1)
Block(-7,2,-3,1)
Block(-7,2,-2,1)
Block(-7,2,-1,1)
Block(-7,2,0,1)
Block(-7,2,1,1)
Block(-7,2,2,1)
Block(-7,2,3,1)
Block(-7,3,-7,1)
Block(-7,3,-6,1)
Block(-7,3,-5,1)
Block(-7,3,-4,1)
Block(-7,3,-3,1)
Block(-7,3,-2,1)
Block(-7,3,-1,1)
Block(-7,3,0,1)
Block(-7,3,1,1)
Block(-7,3,2,1)
Block(-7,3,3,1)
Block(-7,4,-7,3)
Block(-7,4,-6,3)
Block(-7,4,-5,3)
Block(-7,4,-4,1)
Block(-7,4,-3,1)
Block(-7,4,-2,1)
Block(-7,4,-1,1)
Block(-7,4,0,1)
Block(-7,4,1,1)
Block(-7,4,2,1)
Block(-7,4,3,1)
Block(-7,5,-7,3)
Block(-7,5,-6,3)
Block(-7,5,-5,3)
Block(-7,5,-4,3)
Block(-7,5,-3,1)
Block(-7,5,-2,1)
Block(-7,5,-1,1)
Block(-7,5,0,1)
Block(-7,5,1,1)
Block(-7,5,2,1)
Block(-7,5,3,1)
Block(-7,6,-7,2)
Block(-7,6,-6,2)
Block(-7,6,-5,2)
Block(-7,6,-4,3)
Block(-7,6,-3,1)
Block(-7,6,-2,1)
Block(-7,6,-1,1)
Block(-7,6,0,1)
Block(-7,6,1,1)
Block(-7,6,2,1)
Block(-7,6,3,1)
Block(-7,7,-4,2)
Block(-7,7,-3,3)
Block(-7,7,-2,1)
Block(-7,7,-1,16)
Block(-7,7,0,16)
Block(-7,7,1,1)
Block(-7,7,2,1)
Block(-7,7,3,1)
Block(-7,8,-3,3)
Block(-7,8,-2,3)
Block(-7,8,-1,3)
Block(-7,8,0,3)
Block(-7,8,1,3)
Block(-7,8,2,3)
Block(-7,8,3,3)
Block(-7,9,-3,2)
Block(-7,9,-2,3)
Block(-7,9,-1,3)
Block(-7,9,0,3)
Block(-7,9,1,3)
Block(-7,9,2,3)
Block(-7,9,3,3)
Block(-7,10,-2,2)
Block(-7,10,-1,2)
Block(-7,10,0,2)
Block(-7,10,1,2)
Block(-7,10,2,2)
Block(-7,10,3,2)
Block(-6,0,-7,1)
Block(-6,0,-6,1)
Block(-6,0,-5,1)
Block(-6,0,-4,1)
Block(-6,0,-3,1)
Block(-6,0,-2,1)
Block(-6,0,-1,1)
Block(-6,0,0,1)
Block(-6,0,1,1)
Block(-6,0,2,1)
Block(-6,0,3,1)
Block(-6,1,-7,1)
Block(-6,1,-6,1)
Block(-6,1,-5,1)
Block(-6,1,-4,1)
Block(-6,1,-3,1)
Block(-6,1,-2,1)
Block(-6,1,-1,1)
Block(-6,1,0,1)
Block(-6,1,1,1)
Block(-6,1,2,1)
Block(-6,1,3,1)
Block(-6,2,-7,1)
Block(-6,2,-6,1)
Block(-6,2,-5,1)
Block(-6,2,-4,1)
Block(-6,2,-3,1)
Block(-6,2,-2,1)
Block(-6,2,-1,1)
Block(-6,2,0,1)
Block(-6,2,1,1)
Block(-6,2,2,1)
Block(-6,2,3,1)
Block(-6,3,-7,1)
Block(-6,3,-6,1)
Block(-6,3,-5,1)
Block(-6,3,-4,1)
Block(-6,3,-3,1)
Block(-6,3,-2,1)
Block(-6,3,-1,1)
Block(-6,3,0,1)
Block(-6,3,1,1)
Block(-6,3,2,1)
Block(-6,3,3,1)
Block(-6,4,-7,3)
Block(-6,4,-6,3)
Block(-6,4,-5,1)
Block(-6,4,-4,1)
Block(-6,4,-3,1)
Block(-6,4,-2,1)
Block(-6,4,-1,1)
Block(-6,4,0,1)
Block(-6,4,1,1)
Block(-6,4,2,1)
Block(-6,4,3,1)
Block(-6,5,-7,3)
Block(-6,5,-6,3)
Block(-6,5,-5,3)
Block(-6,5,-4,1)
Block(-6,5,-3,1)
Block(-6,5,-2,1)
Block(-6,5,-1,1)
Block(-6,5,0,1)
Block(-6,5,1,1)
Block(-6,5,2,1)
Block(-6,5,3,1)
Block(-6,6,-7,2)
Block(-6,6,-6,2)
Block(-6,6,-5,3)
Block(-6,6,-4,3)
Block(-6,6,-3,1)
Block(-6,6,-2,1)
Block(-6,6,-1,1)
Block(-6,6,0,1)
Block(-6,6,1,1)
Block(-6,6,2,1)
Block(-6,6,3,1)
Block(-6,7,-5,2)
Block(-6,7,-4,3)
Block(-6,7,-3,3)
Block(-6,7,-2,1)
Block(-6,7,-1,16)
Block(-6,7,0,16)
Block(-6,7,1,1)
Block(-6,7,2,1)
Block(-6,7,3,1)
Block(-6,8,-4,2)
Block(-6,8,-3,3)
Block(-6,8,-2,3)
Block(-6,8,-1,3)
Block(-6,8,0,3)
Block(-6,8,1,3)
Block(-6,8,2,3)
Block(-6,8,3,3)
Block(-6,9,-3,2)
Block(-6,9,-2,3)
Block(-6,9,-1,3)
Block(-6,9,0,3)
Block(-6,9,1,3)
Block(-6,9,2,3)
Block(-6,9,3,3)
Block(-6,10,-2,2)
Block(-6,10,-1,2)
Block(-6,10,0,2)
Block(-6,10,1,2)
Block(-6,10,2,2)
Block(-6,10,3,2)
Block(-6,14,-3,18)
Block(-6,14,-2,18)
Block(-6,14,-1,18)
Block(-6,15,-4,18)
Block(-6,15,-3,18)
Block(-6,15,-2,18)
Block(-6,15,-1,18)
Block(-6,15,0,18)
Block(-5,0,-7,1)
Block(-5,0,-6,1)
Block(-5,0,-5,1)
Block(-5,0,-4,1)
Block(-5,0,-3,1)
Block(-5,0,-2,1)
Block(-5,0,-1,1)
Block(-5,0,0,1)
Block(-5,0,1,1)
Block(-5,0,2,1)
Block(-5,0,3,1)
Block(-5,1,-7,1)
Block(-5,1,-6,1)
Block(-5,1,-5,1)
Block(-5,1,-4,1)
Block(-5,1,-3,1)
Block(-5,1,-2,1)
Block(-5,1,-1,1)
Block(-5,1,0,1)
Block(-5,1,1,1)
Block(-5,1,2,1)
Block(-5,1,3,1)
Block(-5,2,-7,1)
Block(-5,2,-6,1)
Block(-5,2,-5,1)
Block(-5,2,-4,1)
Block(-5,2,-3,1)
Block(-5,2,-2,1)
Block(-5,2,-1,1)
Block(-5,2,0,1)
Block(-5,2,1,1)
Block(-5,2,2,1)
Block(-5,2,3,1)
Block(-5,3,-7,1)
Block(-5,3,-6,1)
Block(-5,3,-5,1)
Block(-5,3,-4,1)
Block(-5,3,-3,1)
Block(-5,3,-2,1)
Block(-5,3,-1,1)
Block(-5,3,0,1)
Block(-5,3,1,1)
Block(-5,3,2,1)
Block(-5,3,3,1)
Block(-5,4,-7,3)
Block(-5,4,-6,3)
Block(-5,4,-5,1)
Block(-5,4,-4,1)
Block(-5,4,-3,1)
Block(-5,4,-2,1)
Block(-5,4,-1,1)
Block(-5,4,0,1)
Block(-5,4,1,1)
Block(-5,4,2,1)
Block(-5,4,3,1)
Block(-5,5,-7,3)
Block(-5,5,-6,3)
Block(-5,5,-5,3)
Block(-5,5,-4,1)
Block(-5,5,-3,1)
Block(-5,5,-2,1)
Block(-5,5,-1,1)
Block(-5,5,0,1)
Block(-5,5,1,1)
Block(-5,5,2,1)
Block(-5,5,3,1)
Block(-5,6,-7,2)
Block(-5,6,-6,2)
Block(-5,6,-5,3)
Block(-5,6,-4,3)
Block(-5,6,-3,1)
Block(-5,6,-2,1)
Block(-5,6,-1,1)
Block(-5,6,0,1)
Block(-5,6,1,1)
Block(-5,6,2,1)
Block(-5,6,3,1)
Block(-5,7,-5,2)
Block(-5,7,-4,3)
Block(-5,7,-3,1)
Block(-5,7,-2,1)
Block(-5,7,-1,1)
Block(-5,7,0,16)
Block(-5,7,1,1)
Block(-5,7,2,1)
Block(-5,7,3,1)
Block(-5,8,-4,2)
Block(-5,8,-3,3)
Block(-5,8,-2,1)
Block(-5,8,-1,1)
Block(-5,8,0,3)
Block(-5,8,1,3)
Block(-5,8,2,3)
Block(-5,8,3,3)
Block(-5,9,-3,3)
Block(-5,9,-2,3)
Block(-5,9,-1,3)
Block(-5,9,0,3)
Block(-5,9,1,3)
Block(-5,9,2,3)
Block(-5,9,3,3)
Block(-5,10,-3,2)
Block(-5,10,-2,3)
Block(-5,10,-1,3)
Block(-5,10,0,3)
Block(-5,10,1,2)
Block(-5,10,2,2)
Block(-5,10,3,2)
Block(-5,11,-2,2)
Block(-5,11,-1,2)
Block(-5,11,0,2)
Block(-5,11,1,37)
Block(-5,14,-4,18)
Block(-5,14,-3,18)
Block(-5,14,-2,18)
Block(-5,14,-1,18)
Block(-5,14,0,18)
Block(-5,15,-4,18)
Block(-5,15,-3,18)
Block(-5,15,-2,18)
Block(-5,15,-1,18)
Block(-5,15,0,18)
Block(-5,16,-2,18)
Block(-5,17,-2,18)
Block(-4,0,-7,1)
Block(-4,0,-6,1)
Block(-4,0,-5,1)
Block(-4,0,-4,1)
Block(-4,0,-3,1)
Block(-4,0,-2,1)
Block(-4,0,-1,1)
Block(-4,0,0,1)
Block(-4,0,1,1)
Block(-4,0,2,1)
Block(-4,0,3,1)
Block(-4,1,-7,1)
Block(-4,1,-6,1)
Block(-4,1,-5,1)
Block(-4,1,-4,1)
Block(-4,1,-3,1)
Block(-4,1,-2,1)
Block(-4,1,-1,1)
Block(-4,1,0,1)
Block(-4,1,1,1)
Block(-4,1,2,1)
Block(-4,1,3,1)
Block(-4,2,-7,1)
Block(-4,2,-6,1)
Block(-4,2,-5,1)
Block(-4,2,-4,1)
Block(-4,2,-3,1)
Block(-4,2,-2,1)
Block(-4,2,-1,1)
Block(-4,2,0,1)
Block(-4,2,1,1)
Block(-4,2,2,1)
Block(-4,2,3,1)
Block(-4,3,-7,3)
Block(-4,3,-6,1)
Block(-4,3,-5,1)
Block(-4,3,-4,1)
Block(-4,3,-3,1)
Block(-4,3,-2,1)
Block(-4,3,-1,1)
Block(-4,3,0,1)
Block(-4,3,1,1)
Block(-4,3,2,1)
Block(-4,3,3,1)
Block(-4,4,-7,3)
Block(-4,4,-6,3)
Block(-4,4,-5,3)
Block(-4,4,-4,1)
Block(-4,4,-3,1)
Block(-4,4,-2,1)
Block(-4,4,-1,1)
Block(-4,4,0,1)
Block(-4,4,1,1)
Block(-4,4,2,1)
Block(-4,4,3,1)
Block(-4,5,-7,2)
Block(-4,5,-6,3)
Block(-4,5,-5,3)
Block(-4,5,-4,1)
Block(-4,5,-3,1)
Block(-4,5,-2,1)
Block(-4,5,-1,1)
Block(-4,5,0,1)
Block(-4,5,1,1)
Block(-4,5,2,1)
Block(-4,5,3,1)
Block(-4,6,-6,2)
Block(-4,6,-5,2)
Block(-4,6,-4,3)
Block(-4,6,-3,1)
Block(-4,6,-2,1)
Block(-4,6,-1,1)
Block(-4,6,0,1)
Block(-4,6,1,1)
Block(-4,6,2,1)
Block(-4,6,3,1)
Block(-4,7,-4,3)
Block(-4,7,-3,3)
Block(-4,7,-2,1)
Block(-4,7,-1,1)
Block(-4,7,0,1)
Block(-4,7,1,1)
Block(-4,7,2,1)
Block(-4,7,3,1)
Block(-4,8,-4,2)
Block(-4,8,-3,3)
Block(-4,8,-2,3)
Block(-4,8,-1,3)
Block(-4,8,0,3)
Block(-4,8,1,1)
Block(-4,8,2,1)
Block(-4,8,3,1)
Block(-4,9,-3,2)
Block(-4,9,-2,3)
Block(-4,9,-1,3)
Block(-4,9,0,3)
Block(-4,9,1,3)
Block(-4,9,2,3)
Block(-4,9,3,3)
Block(-4,10,-2,3)
Block(-4,10,-1,2)
Block(-4,10,0,3)
Block(-4,10,1,3)
Block(-4,10,2,3)
Block(-4,10,3,3)
Block(-4,11,-2,17)
Block(-4,11,0,2)
Block(-4,11,1,2)
Block(-4,11,2,2)
Block(-4,11,3,2)
Block(-4,12,-2,17)
Block(-4,13,-2,17)
Block(-4,14,-4,18)
Block(-4,14,-3,18)
Block(-4,14,-2,17)
Block(-4,14,-1,18)
Block(-4,14,0,18)
Block(-4,15,-4,18)
Block(-4,15,-3,18)
Block(-4,15,-2,17)
Block(-4,15,-1,18)
Block(-4,15,0,18)
Block(-4,16,-3,18)
Block(-4,16,-2,17)
Block(-4,16,-1,18)
Block(-4,17,-3,18)
Block(-4,17,-2,18)
Block(-4,17,-1,18)
Block(-3,0,-7,1)
Block(-3,0,-6,1)
Block(-3,0,-5,1)
Block(-3,0,-4,1)
Block(-3,0,-3,1)
Block(-3,0,-2,1)
Block(-3,0,-1,1)
Block(-3,0,0,1)
Block(-3,0,1,1)
Block(-3,0,2,1)
Block(-3,0,3,1)
Block(-3,1,-7,1)
Block(-3,1,-6,1)
Block(-3,1,-5,1)
Block(-3,1,-4,1)
Block(-3,1,-3,1)
Block(-3,1,-2,1)
Block(-3,1,-1,1)
Block(-3,1,0,1)
Block(-3,1,1,1)
Block(-3,1,2,1)
Block(-3,1,3,1)
Block(-3,2,-7,1)
Block(-3,2,-6,1)
Block(-3,2,-5,1)
Block(-3,2,-4,1)
Block(-3,2,-3,1)
Block(-3,2,-2,1)
Block(-3,2,-1,1)
Block(-3,2,0,1)
Block(-3,2,1,1)
Block(-3,2,2,1)
Block(-3,2,3,1)
Block(-3,3,-7,3)
Block(-3,3,-6,3)
Block(-3,3,-5,1)
Block(-3,3,-4,1)
Block(-3,3,-3,1)
Block(-3,3,-2,1)
Block(-3,3,-1,1)
Block(-3,3,0,1)
Block(-3,3,1,1)
Block(-3,3,2,1)
Block(-3,3,3,1)
Block(-3,4,-7,3)
Block(-3,4,-6,3)
Block(-3,4,-5,3)
Block(-3,4,-4,1)
Block(-3,4,-3,1)
Block(-3,4,-2,1)
Block(-3,4,-1,1)
Block(-3,4,0,1)
Block(-3,4,1,1)
Block(-3,4,2,1)
Block(-3,4,3,1)
Block(-3,5,-7,2)
Block(-3,5,-6,2)
Block(-3,5,-5,3)
Block(-3,5,-4,3)
Block(-3,5,-3,1)
Block(-3,5,-2,1)
Block(-3,5,-1,1)
Block(-3,5,0,1)
Block(-3,5,1,1)
Block(-3,5,2,1)
Block(-3,5,3,1)
Block(-3,6,-5,2)
Block(-3,6,-4,3)
Block(-3,6,-3,3)
Block(-3,6,-2,1)
Block(-3,6,-1,1)
Block(-3,6,0,1)
Block(-3,6,1,1)
Block(-3,6,2,1)
Block(-3,6,3,1)
Block(-3,7,-4,2)
Block(-3,7,-3,3)
Block(-3,7,-2,1)
Block(-3,7,-1,1)
Block(-3,7,0,1)
Block(-3,7,1,1)
Block(-3,7,2,1)
Block(-3,7,3,1)
Block(-3,8,-3,2)
Block(-3,8,-2,3)
Block(-3,8,-1,3)
Block(-3,8,0,3)
Block(-3,8,1,1)
Block(-3,8,2,1)
Block(-3,8,3,1)
Block(-3,9,-2,3)
Block(-3,9,-1,3)
Block(-3,9,0,3)
Block(-3,9,1,3)
Block(-3,9,2,3)
Block(-3,9,3,3)
Block(-3,10,-2,2)
Block(-3,10,-1,2)
Block(-3,10,0,2)
Block(-3,10,1,3)
Block(-3,10,2,3)
Block(-3,10,3,3)
Block(-3,11,1,2)
Block(-3,11,2,2)
Block(-3,11,3,2)
Block(-3,13,-2,18)
Block(-3,13,-1,18)
Block(-3,13,0,18)
Block(-3,14,-4,18)
Block(-3,14,-3,18)
Block(-3,14,-2,18)
Block(-3,14,-1,18)
Block(-3,14,0,18)
Block(-3,14,1,18)
Block(-3,15,-4,18)
Block(-3,15,-3,18)
Block(-3,15,-2,18)
Block(-3,15,-1,18)
Block(-3,15,0,18)
Block(-3,16,-2,18)
Block(-3,17,-2,18)
Block(-2,0,-7,1)
Block(-2,0,-6,1)
Block(-2,0,-5,1)
Block(-2,0,-4,1)
Block(-2,0,-3,1)
Block(-2,0,-2,1)
Block(-2,0,-1,1)
Block(-2,0,0,1)
Block(-2,0,1,1)
Block(-2,0,2,1)
Block(-2,0,3,1)
Block(-2,1,-7,1)
Block(-2,1,-6,1)
Block(-2,1,-5,1)
Block(-2,1,-4,1)
Block(-2,1,-3,1)
Block(-2,1,-2,1)
Block(-2,1,-1,1)
Block(-2,1,0,1)
Block(-2,1,1,1)
Block(-2,1,2,1)
Block(-2,1,3,1)
Block(-2,2,-7,1)
Block(-2,2,-6,1)
Block(-2,2,-5,1)
Block(-2,2,-4,1)
Block(-2,2,-3,1)
Block(-2,2,-2,1)
Block(-2,2,-1,1)
Block(-2,2,0,1)
Block(-2,2,1,1)
Block(-2,2,2,1)
Block(-2,2,3,1)
Block(-2,3,-7,3)
Block(-2,3,-6,3)
Block(-2,3,-5,1)
Block(-2,3,-4,1)
Block(-2,3,-3,1)
Block(-2,3,-2,1)
Block(-2,3,-1,1)
Block(-2,3,0,1)
Block(-2,3,1,1)
Block(-2,3,2,1)
Block(-2,3,3,1)
Block(-2,4,-7,3)
Block(-2,4,-6,3)
Block(-2,4,-5,3)
Block(-2,4,-4,1)
Block(-2,4,-3,1)
Block(-2,4,-2,1)
Block(-2,4,-1,1)
Block(-2,4,0,1)
Block(-2,4,1,1)
Block(-2,4,2,1)
Block(-2,4,3,1)
Block(-2,5,-7,2)
Block(-2,5,-6,2)
Block(-2,5,-5,3)
Block(-2,5,-4,3)
Block(-2,5,-3,1)
Block(-2,5,-2,1)
Block(-2,5,-1,1)
Block(-2,5,0,1)
Block(-2,5,1,1)
Block(-2,5,2,1)
Block(-2,5,3,1)
Block(-2,6,-5,2)
Block(-2,6,-4,3)
Block(-2,6,-3,3)
Block(-2,6,-2,1)
Block(-2,6,-1,1)
Block(-2,6,0,1)
Block(-2,6,1,1)
Block(-2,6,2,1)
Block(-2,6,3,1)
Block(-2,7,-4,2)
Block(-2,7,-3,3)
Block(-2,7,-2,1)
Block(-2,7,-1,1)
Block(-2,7,0,1)
Block(-2,7,1,1)
Block(-2,7,2,1)
Block(-2,7,3,1)
Block(-2,8,-3,2)
Block(-2,8,-2,3)
Block(-2,8,-1,3)
Block(-2,8,0,3)
Block(-2,8,1,1)
Block(-2,8,2,1)
Block(-2,8,3,1)
Block(-2,9,-2,3)
Block(-2,9,-1,3)
Block(-2,9,0,3)
Block(-2,9,1,3)
Block(-2,9,2,3)
Block(-2,9,3,3)
Block(-2,10,-2,2)
Block(-2,10,-1,2)
Block(-2,10,0,2)
Block(-2,10,1,3)
Block(-2,10,2,3)
Block(-2,10,3,3)
Block(-2,11,-1,37)
Block(-2,11,1,2)
Block(-2,11,2,2)
Block(-2,11,3,2)
Block(-2,13,-3,18)
Block(-2,13,-2,18)
Block(-2,13,-1,18)
Block(-2,13,0,18)
Block(-2,13,1,18)
Block(-2,14,-4,18)
Block(-2,14,-3,18)
Block(-2,14,-2,18)
Block(-2,14,-1,18)
Block(-2,14,0,18)
Block(-2,14,1,18)
Block(-2,15,-3,18)
Block(-2,15,-2,18)
Block(-2,15,-1,18)
Block(-2,16,-1,18)
