#######################################################################
# +-----------------------------------------------------------------+ #
# |                            BO3 object                           | #
# +-----------------------------------------------------------------+ #
#######################################################################

# This BO3 is made for use with MCW and OTG+.
# The descriptions in this file are only accurate for MCW and OTG+.
# For TerrainControl and OTG these descriptions are only accurate if the BO3 is used as a CustomObject.
# MCW and OTG+ completely reimplemented CustomStructure, check the MCW/OTG+ documentation for more information.

# This is the config file of a custom object.
# If you add this object correctly to your BiomeConfigs, it will spawn in the world.

# This is the creator of this BO3 object
Author: Unknown

# A short description of this BO3 object
Description: No description

# The BO3 version, don't change this! It can be used by external applications to do a version check.
Version: 4

# The settings mode, WriteAll, WriteWithoutComments or WriteDisable. See WorldConfig.
SettingsMode: WriteDisable

#######################################################################
# +-----------------------------------------------------------------+ #
# |                          Main settings                          | #
# +-----------------------------------------------------------------+ #
#######################################################################

IsOTGPlus: true
# This settings is currently unavailable for MCW/OTG+.
Tree: false

# The rarity of the BO3 from 0 to 100. Each spawn attempt has rarity% chance to succeed when using the CustomObject(...) resource.
# Ignored by MCW/OTG+ for Tree(..), Sapling(..) and CustomStructure(..).
Rarity: 100

# Minimum distance in chunks between structures with the same filename.
Frequency: 0

# This settings is currently unavailable for MCW/OTG+, you can easily work around this though by creating a master bo3 without blocks that
# has the real starting BO3 as a branch.
# You can then duplicate the master BO3 3 times and give each copy's branch a different rotation.
RotateRandomly: false

# The spawn height of the BO3 - randomY or highestBlock.
SpawnHeight: highestBlock

# The height limits for the BO3. Can be combined with randomY to spawn the BO3 at a random height
# between MinHeight and MaxHeight. Can be combined with highestBlock to make sure that the BO3 spawns
# only between MinHeight and MaxHeight.
MinHeight: 0

MaxHeight: 256

# This settings is disabled for MCW/OTG+.
ExcludedBiomes: All

# To optimise this BO3 for faster loading times you can use Notepad++ to find/replace comments and abbreviate things.
# Notepad++ find/replace with regex:
# Find: ^[#;].* replace to nothing removes all lines starting with # 
# Find: ^\s*$ replace to nothing removes most empty lines 
# Notepad++ find/replace without regex:
# *Warning: This will only work for OTG 1.10.2 v21 / OTG 1.11.2 v6 or higher. B( is not recognised by lower versions.
# Find: Block( replace to B(

#######################################################################
# +-----------------------------------------------------------------+ #
# |                      Source block settings                      | #
# +-----------------------------------------------------------------+ #
#######################################################################

# This settings is disabled for MCW/OTG+.
SourceBlocks: AIR

# This settings is disabled for MCW/OTG+.
MaxPercentageOutsideSourceBlock: 100

# This settings is disabled for MCW/OTG+.
OutsideSourceBlock: placeAnyway

# MineCraft Worlds mod settings #
# NOTE: you can delete any of these settings if you're not using them, the default values will automatically be used. #

# Copies the blocks and branches of an existing BO3 into this BO3.
#InheritBO3:

# Defaults to true, if true and this is the root BO3 for this branching structure then this BO3's smoothing and height settings are used for all its children (branches).
#OverrideChildSettings: true

# If this is set to true then this BO3 can spawn as a branch on top of or inside an existing BO3/branch (only within the same customstructure).
#CanOverride: false

# If this is set to true then this BO3 can only spawn underneath an existing BO3. Used to make sure that dungeons only appear underneath buildings
#MustBeBelowOther: false

# A comma-seperated list of BO3s, this BO3 must touch one of these when spawned or it will not be able to spawn.
#MustBeInside: 

# A comma-seperated list of BO3s, this BO3 cannot touch one of these when spawned, if it does it will not be able to spawn.
#CannotBeInside: 

# Defaults to true. Set to false if the BO3 is not allowed to spawn on a water block
#CanSpawnOnWater: true

# Defaults to false. Set to true if the BO3 is allowed to spawn only on a water block
#SpawnOnWaterOnly: false

# Defaults to false. Set to true if the BO3 and its smoothing area should ignore water when looking for the highest block to spawn on. Defaults to false (things spawn on top of water)
#SpawnUnderWater: false

# Defaults to false. Set to true if the BO3 should spawn at water level
#SpawnAtWaterLevel: false


# Spawns the BO3 at a Y offset of this value. Handy when using highestBlock for lowering BO3s into the surrounding terrain when there are layers of ground included in the BO3, also handy when using SpawnAtWaterLevel to lower objects like ships into the water.
#HeightOffset: 0

# If set to true removes all AIR blocks from the BO3 so that it can be flooded or buried.
#RemoveAir: true

# Replaces all the non-air blocks that are above this BO3 or its smoothing area with the given block material (should be WATER or AIR or NONE), also applies to smoothing areas although it intentionally leaves some of the terrain above them intact. WATER can be used in combination with SpawnUnderWater to fill any air blocks underneath waterlevel with water (and any above waterlevel with air).
#ReplaceAbove: AIR

# Replaces all air blocks underneath the BO3 (but not its smoothing area) with the designated material until a solid block is found.
#ReplaceBelow:

# Defaults to true. If set to true then every block in the BO3 of the materials defined in ReplaceWithGroundBlock or ReplaceWithSurfaceBlock will be replaced by the GroundBlock or SurfaceBlock materials configured for the biome the block is spawned in.
#ReplaceWithBiomeBlocks: true

# Defaults to DIRT, Replaces all the blocks of the given material in the BO3 with the GroundBlock configured for the biome it spawns in
#ReplaceWithGroundBlock: DIRT

# Defaults to GRASS, Replaces all the blocks of the given material in the BO3 with the SurfaceBlock configured for the biome it spawns in
#ReplaceWithSurfaceBlock: GRASS


# Makes the terrain around the BO3 slope gradually towards the edges of the BO3. The given value is the distance in blocks around the BO3 from where the slope should start and can be any positive number.
#SmoothRadius: 0

# Moves the smoothing area up or down relative to the BO3 (at the points where the smoothing area is connected to the BO3). Handy when using SmoothStartTop: false and the BO3 has some layers of ground included, in that case we can set the HeightOffset to a negative value to lower the BO3 into the ground and we can set the SmoothHeightOffset to a positive value to move the smoothing area starting height up
#SmoothHeightOffset: 0

# Should the smoothing area be attached at the bottom or the top of the edges of the BO3? Defaults to false (bottom). Using this setting can make things slower so try to avoid using it and use SmoothHeightOffset instead if for instance you have a BO3 with some ground layers included. The only reason you should need to use this setting is if you have a BO3 with edges that have an irregular height (like some hills).
#SmoothStartTop: false

# Should the smoothing area attach itself to "log" block or ignore them? Defaults to false (ignore logs).
#SmoothStartWood: false

# The block used for smoothing area surface blocks, defaults to biome SurfaceBlock
#SmoothingSurfaceBlock:

# The block used for smoothing area ground blocks, defaults to biome GroundBlock
#SmoothingGroundBlock:


# Define groups that this BO3 belongs to along with a minimum range in chunks that this BO3 must have between it and any other members of this group if it is to be allowed to spawn. Syntax is "GroupName:Frequency, GoupName2:Frequency2" etc so for example a BO3 that belongs to 3 groups: "BO3Group: Ships:10, Vehicles:5, FloatingThings:3"
#BO3Group:

# Defaults to false. Set to true if this BO3 should spawn at the player spawn point. When the server starts the spawn point is determined and the BO3's for the biome it is in are loaded, one of these BO3s that has IsSpawnPoint set to true (if any) is selected randomly and is spawned at the spawn point regardless of its rarity (so even Rarity:0, IsSpawnPoint: true BO3's can get spawned as the spawn point!).
#IsSpawnPoint: false

# Defaults to 8, if SpawnPointY > -1 and this BO3 is spawned at the spawn point then the player spawn point is placed within this BO3 at x y and z offsets (spawnPointX, spawnPointY, spawnPointZ) relative to x0y0z0 in this BO3.
#SpawnPointX: 8

# Defaults to highestBlock, if this is defined and this BO3 is spawned at the spawn point then the player spawn point is placed at a y offset of this value relative to y = 0 in this BO3.)
#SpawnPointY: -1

# Defaults to 7, if spawnPointY > -1 and this BO3 is spawned at the spawn point then the player spawn point is placed within this BO3 at a x y and z offsets (spawnPointX, spawnPointY, spawnPointZ) relative to x0y0z0 in this BO3.
#SpawnPointZ: 7

#######################################################################
# +-----------------------------------------------------------------+ #
# |                              Blocks                             | #
# +-----------------------------------------------------------------+ #
#######################################################################

# All the blocks used in the BO3 are listed here. Possible blocks:
# Block(x,y,z,id[.data][,nbtfile.nbt) or B(x,y,z,id[.data][,nbtfile.nbt)
# RandomBlock(x,y,z,id[:data][,nbtfile.nbt],chance[,id[:data][,nbtfile.nbt],chance[,...]])
# So RandomBlock(0,0,0,CHEST,chest.nbt,50,CHEST,anotherchest.nbt,100) will spawn a chest at
# the BO3 origin, and give it a 50% chance to have the contents of chest.nbt, or, if that
# fails, a 100% percent chance to have the contents of anotherchest.nbt.

Block(-8,0,-7,159:15)
Block(-8,0,-6,251:15)
Block(-8,0,-5,251:15)
Block(-8,0,-4,159:15)
Block(-8,0,-3,251:15)
Block(-8,0,-2,251:15)
Block(-8,0,-1,251:15)
Block(-8,0,0,159:15)
Block(-8,0,1,251:15)
Block(-8,0,2,251:15)
Block(-8,0,3,251:15)
Block(-8,0,4,251:15)
Block(-8,0,5,159:15)
Block(-8,0,6,159:15)
Block(-8,0,7,251:15)
Block(-8,1,-7,159:15)
Block(-8,1,-6,251:15)
Block(-8,1,-5,251:15)
Block(-8,1,-4,251:15)
Block(-8,1,-3,251:15)
Block(-8,1,-2,251:15)
Block(-8,1,-1,251:15)
Block(-8,1,0,251:15)
Block(-8,1,1,159:15)
Block(-8,1,2,159:15)
Block(-8,1,3,159:15)
Block(-8,1,4,159:15)
Block(-8,1,5,251:15)
Block(-8,1,6,159:15)
Block(-8,1,7,159:15)
Block(-8,2,-7,159:15)
Block(-8,2,-6,251:15)
Block(-8,2,-5,159:15)
Block(-8,2,-4,251:15)
Block(-8,2,-3,159:15)
Block(-8,2,-2,159:15)
Block(-8,2,-1,251:15)
Block(-8,2,0,159:15)
Block(-8,2,1,159:15)
Block(-8,2,2,251:15)
Block(-8,2,3,159:15)
Block(-8,2,4,251:15)
Block(-8,2,5,159:15)
Block(-8,2,6,159:15)
Block(-8,2,7,159:15)
Block(-8,3,-7,251:15)
Block(-8,3,-6,159:15)
Block(-8,3,-5,159:15)
Block(-8,3,-4,251:15)
Block(-8,3,-3,159:15)
Block(-8,3,-2,251:15)
Block(-8,3,-1,159:15)
Block(-8,3,0,251:15)
Block(-8,3,1,251:15)
Block(-8,3,2,251:15)
Block(-8,3,3,159:15)
Block(-8,3,4,159:15)
Block(-8,3,5,159:15)
Block(-8,3,6,159:15)
Block(-8,3,7,159:15)
Block(-8,4,-7,159:15)
Block(-8,4,-6,251:15)
Block(-8,4,-5,251:15)
Block(-8,4,-4,251:15)
Block(-8,4,-3,159:15)
Block(-8,4,-2,159:15)
Block(-8,4,-1,251:15)
Block(-8,4,0,159:15)
Block(-8,4,1,251:15)
Block(-8,4,2,251:15)
Block(-8,4,3,159:15)
Block(-8,4,4,159:15)
Block(-8,4,5,251:15)
Block(-8,4,6,159:15)
Block(-8,4,7,159:15)
Block(-8,5,-7,251:15)
Block(-8,5,-6,159:15)
Block(-8,5,-5,159:15)
Block(-8,5,-4,159:15)
Block(-8,5,-3,251:15)
Block(-8,5,-2,251:15)
Block(-8,5,-1,251:15)
Block(-8,5,0,251:15)
Block(-8,5,1,251:15)
Block(-8,5,2,251:15)
Block(-8,5,3,251:15)
Block(-8,5,4,159:15)
Block(-8,5,5,159:15)
Block(-8,5,6,159:15)
Block(-8,5,7,251:15)
Block(-8,6,-7,251:15)
Block(-8,6,-6,159:15)
Block(-8,6,-5,251:15)
Block(-8,6,-4,251:15)
Block(-8,6,-3,251:15)
Block(-8,6,-2,251:15)
Block(-8,6,-1,251:15)
Block(-8,6,0,159:15)
Block(-8,6,1,251:15)
Block(-8,6,2,251:15)
Block(-8,6,3,159:15)
Block(-8,6,4,159:15)
Block(-8,6,5,159:15)
Block(-8,6,6,159:15)
Block(-8,6,7,159:15)
Block(-8,7,-7,159:15)
Block(-8,7,-6,251:15)
Block(-8,7,-5,159:15)
Block(-8,7,-4,251:15)
Block(-8,7,-3,159:15)
Block(-8,7,-2,251:15)
Block(-8,7,-1,251:15)
Block(-8,7,0,159:15)
Block(-8,7,1,159:15)
Block(-8,7,2,251:15)
Block(-8,7,3,159:15)
Block(-8,7,4,159:15)
Block(-8,7,5,159:15)
Block(-8,7,6,159:15)
Block(-8,7,7,159:15)
Block(-8,8,-7,251:15)
Block(-8,8,-6,251:15)
Block(-8,8,-5,159:15)
Block(-8,8,-4,251:15)
Block(-8,8,-3,251:15)
Block(-8,8,-2,159:15)
Block(-8,8,-1,251:15)
Block(-8,8,0,159:15)
Block(-8,8,1,159:15)
Block(-8,8,2,159:15)
Block(-8,8,3,251:15)
Block(-8,8,4,251:15)
Block(-8,8,5,251:15)
Block(-8,8,6,159:15)
Block(-8,8,7,251:15)
Block(-8,9,-7,159:15)
Block(-8,9,-6,251:15)
Block(-8,9,-5,251:15)
Block(-8,9,-4,159:15)
Block(-8,9,-3,251:15)
Block(-8,9,-2,159:15)
Block(-8,9,-1,251:15)
Block(-8,9,0,159:15)
Block(-8,9,1,159:15)
Block(-8,9,2,159:15)
Block(-8,9,3,159:15)
Block(-8,9,4,251:15)
Block(-8,9,5,159:15)
Block(-8,9,6,159:15)
Block(-8,9,7,251:15)
Block(-8,10,-7,159:15)
Block(-8,10,-6,251:15)
Block(-8,10,-5,159:15)
Block(-8,10,-4,159:15)
Block(-8,10,-3,251:15)
Block(-8,10,-2,251:15)
Block(-8,10,-1,159:15)
Block(-8,10,0,159:15)
Block(-8,10,1,159:15)
Block(-8,10,2,159:15)
Block(-8,10,3,251:15)
Block(-8,10,4,251:15)
Block(-8,10,5,251:15)
Block(-8,10,6,159:15)
Block(-8,10,7,159:15)
Block(-8,11,-7,251:15)
Block(-8,11,-6,251:15)
Block(-8,11,-5,251:15)
Block(-8,11,-4,159:15)
Block(-8,11,-3,251:15)
Block(-8,11,-2,159:15)
Block(-8,11,-1,159:15)
Block(-8,11,0,251:15)
Block(-8,11,1,159:15)
Block(-8,11,2,159:15)
Block(-8,11,3,251:15)
Block(-8,11,4,159:15)
Block(-8,11,5,251:15)
Block(-8,11,6,251:15)
Block(-8,11,7,159:15)
Block(-8,12,-7,159:15)
Block(-8,12,-6,159:15)
Block(-8,12,-5,159:15)
Block(-8,12,-4,159:15)
Block(-8,12,-3,251:15)
Block(-8,12,-2,251:15)
Block(-8,12,-1,159:15)
Block(-8,12,0,159:15)
Block(-8,12,1,159:15)
Block(-8,12,2,159:15)
Block(-8,12,3,159:15)
Block(-8,12,4,251:15)
Block(-8,12,5,251:15)
Block(-8,12,6,251:15)
Block(-8,12,7,159:15)
Block(-8,13,-7,251:15)
Block(-8,13,-6,251:15)
Block(-8,13,-5,159:15)
Block(-8,13,-4,159:15)
Block(-8,13,-3,251:15)
Block(-8,13,-2,251:15)
Block(-8,13,-1,159:15)
Block(-8,13,0,159:15)
Block(-8,13,1,251:15)
Block(-8,13,2,251:15)
Block(-8,13,3,159:15)
Block(-8,13,4,251:15)
Block(-8,13,5,251:15)
Block(-8,13,6,251:15)
Block(-8,13,7,159:15)
Block(-8,14,-7,159:15)
Block(-8,14,-6,251:15)
Block(-8,14,-5,251:15)
Block(-8,14,-4,159:15)
Block(-8,14,-3,251:15)
Block(-8,14,-2,159:15)
Block(-8,14,-1,251:15)
Block(-8,14,0,159:15)
Block(-8,14,1,251:15)
Block(-8,14,2,251:15)
Block(-8,14,3,251:15)
Block(-8,14,4,159:15)
Block(-8,14,5,159:15)
Block(-8,14,6,251:15)
Block(-8,14,7,159:15)
Block(-8,15,-7,251:15)
Block(-8,15,-6,159:15)
Block(-8,15,-5,159:15)
Block(-8,15,-4,251:15)
Block(-8,15,-3,159:15)
Block(-8,15,-2,251:15)
Block(-8,15,-1,159:15)
Block(-8,15,0,251:15)
Block(-8,15,1,159:15)
Block(-8,15,2,159:15)
Block(-8,15,3,159:15)
Block(-8,15,4,251:15)
Block(-8,15,5,251:15)
Block(-8,15,6,159:15)
Block(-8,15,7,251:15)
Block(-8,16,-7,159:15)
Block(-8,16,-6,251:15)
Block(-8,16,-5,159:15)
Block(-8,16,-4,159:15)
Block(-8,16,-3,251:15)
Block(-8,16,-2,251:15)
Block(-8,16,-1,159:15)
Block(-8,16,0,251:15)
Block(-8,16,1,251:15)
Block(-8,16,2,159:15)
Block(-8,16,3,159:15)
Block(-8,16,4,251:15)
Block(-8,16,5,159:15)
Block(-8,16,6,251:15)
Block(-8,16,7,159:15)
Block(-8,17,-7,251:15)
Block(-8,17,-6,159:15)
Block(-8,17,-5,159:15)
Block(-8,17,-4,251:15)
Block(-8,17,-3,251:15)
Block(-8,17,-2,159:15)
Block(-8,17,-1,251:15)
Block(-8,17,0,251:15)
Block(-8,17,1,159:15)
Block(-8,17,2,251:15)
Block(-8,17,3,159:15)
Block(-8,17,4,159:15)
Block(-8,17,5,159:15)
Block(-8,17,6,251:15)
Block(-8,17,7,251:15)
Block(-8,18,-7,251:15)
Block(-8,18,-6,159:15)
Block(-8,18,-5,251:15)
Block(-8,18,-4,159:15)
Block(-8,18,-3,251:15)
Block(-8,18,-2,251:15)
Block(-8,18,-1,251:15)
Block(-8,18,0,159:15)
Block(-8,18,1,251:15)
Block(-8,18,2,251:15)
Block(-8,18,3,159:15)
Block(-8,18,4,251:15)
Block(-8,18,5,159:15)
Block(-8,18,6,251:15)
Block(-8,18,7,251:15)
Block(-8,19,-7,159:15)
Block(-8,19,-6,159:15)
Block(-8,19,-5,251:15)
Block(-8,19,-4,251:15)
Block(-8,19,-3,251:15)
Block(-8,19,-2,159:15)
Block(-8,19,-1,251:15)
Block(-8,19,0,251:15)
Block(-8,19,1,159:15)
Block(-8,19,2,159:15)
Block(-8,19,3,251:15)
Block(-8,19,4,159:15)
Block(-8,19,5,251:15)
Block(-8,19,6,251:15)
Block(-8,19,7,251:15)
Block(-8,20,-7,159:15)
Block(-8,20,-6,159:15)
Block(-8,20,-5,251:15)
Block(-8,20,-4,159:15)
Block(-8,20,-3,159:15)
Block(-8,20,-2,251:15)
Block(-8,20,-1,159:15)
Block(-8,20,0,251:15)
Block(-8,20,1,159:15)
Block(-8,20,2,251:15)
Block(-8,20,3,159:15)
Block(-8,20,4,159:15)
Block(-8,20,5,251:15)
Block(-8,20,6,251:15)
Block(-8,20,7,159:15)
Block(-8,21,-7,251:15)
Block(-8,21,-6,251:15)
Block(-8,21,-5,159:15)
Block(-8,21,-4,159:15)
Block(-8,21,-3,251:15)
Block(-8,21,-2,159:15)
Block(-8,21,-1,251:15)
Block(-8,21,0,159:15)
Block(-8,21,1,159:15)
Block(-8,21,2,251:15)
Block(-8,21,3,251:15)
Block(-8,21,4,251:15)
Block(-8,21,5,159:15)
Block(-8,21,6,159:15)
Block(-8,21,7,159:15)
Block(-8,22,-7,159:15)
Block(-8,22,-6,159:15)
Block(-8,22,-5,159:15)
Block(-8,22,-4,251:15)
Block(-8,22,-3,159:15)
Block(-8,22,-2,159:15)
Block(-8,22,-1,159:15)
Block(-8,22,0,159:15)
Block(-8,22,1,251:15)
Block(-8,22,2,251:15)
Block(-8,22,3,251:15)
Block(-8,22,4,251:15)
Block(-8,22,5,159:15)
Block(-8,22,6,159:15)
Block(-8,22,7,251:15)
Block(-8,23,-7,251:15)
Block(-8,23,-6,251:15)
Block(-8,23,-5,159:15)
Block(-8,23,-4,251:15)
Block(-8,23,-3,159:15)
Block(-8,23,-2,251:15)
Block(-8,23,-1,251:15)
Block(-8,23,0,159:15)
Block(-8,23,1,159:15)
Block(-8,23,2,251:15)
Block(-8,23,3,159:15)
Block(-8,23,4,251:15)
Block(-8,23,5,159:15)
Block(-8,23,6,251:15)
Block(-8,23,7,251:15)
Block(-8,24,-7,251:15)
Block(-8,24,-6,251:15)
Block(-8,24,-5,159:15)
Block(-8,24,-4,159:15)
Block(-8,24,-3,251:15)
Block(-8,24,-2,251:15)
Block(-8,24,-1,251:15)
Block(-8,24,0,159:15)
Block(-8,24,1,251:15)
Block(-8,24,2,159:15)
Block(-8,24,3,251:15)
Block(-8,24,4,159:15)
Block(-8,24,5,251:15)
Block(-8,24,6,159:15)
Block(-8,24,7,251:15)
Block(-8,25,-7,251:15)
Block(-8,25,-6,251:15)
Block(-8,25,-5,159:15)
Block(-8,25,-4,159:15)
Block(-8,25,-3,159:15)
Block(-8,25,-2,159:15)
Block(-8,25,-1,159:15)
Block(-8,25,0,159:15)
Block(-8,25,1,251:15)
Block(-8,25,2,251:15)
Block(-8,25,3,159:15)
Block(-8,25,4,159:15)
Block(-8,25,5,251:15)
Block(-8,25,6,159:15)
Block(-8,25,7,251:15)
Block(-8,26,-7,159:15)
Block(-8,26,-6,159:15)
Block(-8,26,-5,159:15)
Block(-8,26,-4,159:15)
Block(-8,26,-3,159:15)
Block(-8,26,-2,251:15)
Block(-8,26,-1,159:15)
Block(-8,26,0,159:15)
Block(-8,26,1,159:15)
Block(-8,26,2,251:15)
Block(-8,26,3,251:15)
Block(-8,26,4,159:15)
Block(-8,26,5,251:15)
Block(-8,26,6,251:15)
Block(-8,26,7,159:15)
Block(-8,27,-7,159:15)
Block(-8,27,-6,251:15)
Block(-8,27,-5,251:15)
Block(-8,27,-4,251:15)
Block(-8,27,-3,159:15)
Block(-8,27,-2,159:15)
Block(-8,27,-1,159:15)
Block(-8,27,0,159:15)
Block(-8,27,1,159:15)
Block(-8,27,2,159:15)
Block(-8,27,3,159:15)
Block(-8,27,4,251:15)
Block(-8,27,5,159:15)
Block(-8,27,6,251:15)
Block(-8,27,7,251:15)
Block(-8,28,-7,159:15)
Block(-8,28,-6,251:15)
Block(-8,28,-5,159:15)
Block(-8,28,-4,251:15)
Block(-8,28,-3,159:15)
Block(-8,28,-2,251:15)
Block(-8,28,-1,251:15)
Block(-8,28,0,159:15)
Block(-8,28,1,159:15)
Block(-8,28,2,159:15)
Block(-8,28,3,159:15)
Block(-8,28,4,159:15)
Block(-8,28,5,251:15)
Block(-8,28,6,159:15)
Block(-8,28,7,251:15)
Block(-8,29,-7,159:15)
Block(-8,29,-6,159:15)
Block(-8,29,-5,159:15)
Block(-8,29,-4,159:15)
Block(-8,29,-3,159:15)
Block(-8,29,-2,251:15)
Block(-8,29,-1,251:15)
Block(-8,29,0,159:15)
Block(-8,29,1,251:15)
Block(-8,29,2,159:15)
Block(-8,29,3,251:15)
Block(-8,29,4,251:15)
Block(-8,29,5,159:15)
Block(-8,29,6,159:15)
Block(-8,29,7,159:15)
Block(-8,30,-7,159:15)
Block(-8,30,-6,159:15)
Block(-8,30,-5,251:15)
Block(-8,30,-4,159:15)
Block(-8,30,-3,251:15)
Block(-8,30,-2,159:15)
Block(-8,30,-1,251:15)
Block(-8,30,0,251:15)
Block(-8,30,1,159:15)
Block(-8,30,2,251:15)
Block(-8,30,3,251:15)
Block(-8,30,4,251:15)
Block(-8,30,5,251:15)
Block(-8,30,6,251:15)
Block(-8,30,7,159:15)
Block(-8,31,-7,159:15)
Block(-8,31,-6,159:15)
Block(-8,31,-5,251:15)
Block(-8,31,-4,251:15)
Block(-8,31,-3,251:15)
Block(-8,31,-2,251:15)
Block(-8,31,-1,251:15)
Block(-8,31,0,251:15)
Block(-8,31,1,251:15)
Block(-8,31,2,159:15)
Block(-8,31,3,159:15)
Block(-8,31,4,159:15)
Block(-8,31,5,251:15)
Block(-8,31,6,251:15)
Block(-8,31,7,159:15)
Block(-8,32,-7,159:15)
Block(-8,32,-6,251:15)
Block(-8,32,-5,159:15)
Block(-8,32,-4,251:15)
Block(-8,32,-3,159:15)
Block(-8,32,-2,251:15)
Block(-8,32,-1,251:15)
Block(-8,32,0,159:15)
Block(-8,32,1,251:15)
Block(-8,32,2,159:15)
Block(-8,32,3,251:15)
Block(-8,32,4,251:15)
Block(-8,32,5,159:15)
Block(-8,32,6,251:15)
Block(-8,32,7,251:7)
Block(-8,33,-7,251:15)
Block(-8,33,-6,159:15)
Block(-8,33,-5,159:15)
Block(-8,33,-4,251:15)
Block(-8,33,-3,251:15)
Block(-8,33,-2,251:15)
Block(-8,33,-1,251:15)
Block(-8,33,0,251:15)
Block(-8,33,1,251:15)
Block(-8,33,2,159:15)
Block(-8,33,3,251:15)
Block(-8,33,4,251:15)
Block(-8,33,5,251:15)
Block(-8,33,6,251:15)
Block(-8,33,7,251:7)
Block(-8,34,-7,251:15)
Block(-8,34,-6,251:15)
Block(-8,34,-5,251:15)
Block(-8,34,-4,251:15)
Block(-8,34,-3,251:15)
Block(-8,34,-2,159:15)
Block(-8,34,-1,251:15)
Block(-8,34,0,159:15)
Block(-8,34,1,159:15)
Block(-8,34,2,159:15)
Block(-8,34,3,159:15)
Block(-8,34,4,251:15)
Block(-8,34,5,159:15)
Block(-8,34,6,159:15)
Block(-8,34,7,251:7)
Block(-8,35,-7,159:15)
Block(-8,35,-6,251:15)
Block(-8,35,-5,159:15)
Block(-8,35,-4,159:15)
Block(-8,35,-3,251:15)
Block(-8,35,-2,159:15)
Block(-8,35,-1,159:15)
Block(-8,35,0,251:15)
Block(-8,35,1,251:15)
Block(-8,35,2,251:15)
Block(-8,35,3,159:15)
Block(-8,35,4,159:15)
Block(-8,35,5,159:15)
Block(-8,35,6,251:15)
Block(-8,35,7,159:15)
Block(-8,36,-7,159:15)
Block(-8,36,-6,159:15)
Block(-8,36,-5,251:15)
Block(-8,36,-4,159:15)
Block(-8,36,-3,251:15)
Block(-8,36,-2,251:15)
Block(-8,36,-1,159:15)
Block(-8,36,0,159:15)
Block(-8,36,1,251:15)
Block(-8,36,2,159:15)
Block(-8,36,3,159:15)
Block(-8,36,4,159:15)
Block(-8,36,5,251:15)
Block(-8,36,6,159:15)
Block(-8,36,7,159:15)
Block(-8,37,-7,159:15)
Block(-8,37,-6,251:15)
Block(-8,37,-5,251:15)
Block(-8,37,-4,251:15)
Block(-8,37,-3,251:15)
Block(-8,37,-2,159:15)
Block(-8,37,-1,159:15)
Block(-8,37,0,159:15)
Block(-8,37,1,159:15)
Block(-8,37,2,159:15)
Block(-8,37,3,159:15)
Block(-8,37,4,159:15)
Block(-8,37,5,159:15)
Block(-8,37,6,251:15)
Block(-8,37,7,159:15)
Block(-8,38,-7,251:15)
Block(-8,38,-6,159:15)
Block(-8,38,-5,251:15)
Block(-8,38,-4,159:15)
Block(-8,38,-3,251:15)
Block(-8,38,-2,159:15)
Block(-8,38,-1,251:15)
Block(-8,38,0,251:15)
Block(-8,38,1,159:15)
Block(-8,38,2,251:15)
Block(-8,38,3,159:15)
Block(-8,38,4,251:15)
Block(-8,38,5,159:15)
Block(-8,38,6,251:15)
Block(-8,38,7,251:15)
Block(-8,39,-7,251:15)
Block(-8,39,-6,251:15)
Block(-8,39,-5,159:15)
Block(-8,39,-4,251:15)
Block(-8,39,-3,251:15)
Block(-8,39,-2,251:15)
Block(-8,39,-1,251:15)
Block(-8,39,0,159:15)
Block(-8,39,1,159:15)
Block(-8,39,2,251:15)
Block(-8,39,3,159:15)
Block(-8,39,4,251:15)
Block(-8,39,5,251:15)
Block(-8,39,6,251:15)
Block(-8,39,7,251:15)
Block(-8,40,-7,159:15)
Block(-8,40,-6,251:15)
Block(-8,40,-5,159:15)
Block(-8,40,-4,159:15)
Block(-8,40,-3,251:15)
Block(-8,40,-2,159:15)
Block(-8,40,-1,159:15)
Block(-8,40,0,251:15)
Block(-8,40,1,159:15)
Block(-8,40,2,159:15)
Block(-8,40,3,251:15)
Block(-8,40,4,159:15)
Block(-8,40,5,251:15)
Block(-8,40,6,159:15)
Block(-8,40,7,251:15)
Block(-8,41,-7,251:15)
Block(-8,41,-6,159:15)
Block(-8,41,-5,251:15)
Block(-8,41,-4,251:15)
Block(-8,41,-3,251:15)
Block(-8,41,-2,251:15)
Block(-8,41,-1,251:15)
Block(-8,41,0,251:15)
Block(-8,41,1,159:15)
Block(-8,41,2,251:15)
Block(-8,41,3,251:15)
Block(-8,41,4,159:15)
Block(-8,41,5,159:15)
Block(-8,41,6,159:15)
Block(-8,41,7,251:15)
Block(-8,42,-7,159:15)
Block(-8,42,-6,251:15)
Block(-8,42,-5,159:15)
Block(-8,42,-4,159:15)
Block(-8,42,-3,159:15)
Block(-8,42,-2,251:15)
Block(-8,42,-1,251:15)
Block(-8,42,0,251:15)
Block(-8,42,1,159:15)
Block(-8,42,2,251:15)
Block(-8,42,3,159:15)
Block(-8,42,4,159:15)
Block(-8,42,5,159:15)
Block(-8,42,6,251:15)
Block(-8,42,7,159:15)
Block(-8,43,-7,251:15)
Block(-8,43,-6,159:15)
Block(-8,43,-5,159:15)
Block(-8,43,-4,159:15)
Block(-8,43,-3,251:15)
Block(-8,43,-2,159:15)
Block(-8,43,-1,159:15)
Block(-8,43,0,159:15)
Block(-8,43,1,159:15)
Block(-8,43,2,251:15)
Block(-8,43,3,159:15)
Block(-8,43,4,251:15)
Block(-8,43,5,251:15)
Block(-8,43,6,159:15)
Block(-8,43,7,159:15)
Block(-8,44,-7,159:15)
Block(-8,44,-6,251:15)
Block(-8,44,-5,159:15)
Block(-8,44,-4,251:15)
Block(-8,44,-3,159:15)
Block(-8,44,-2,251:15)
Block(-8,44,-1,159:15)
Block(-8,44,0,159:15)
Block(-8,44,1,251:15)
Block(-8,44,2,159:15)
Block(-8,44,3,159:15)
Block(-8,44,4,251:15)
Block(-8,44,5,251:15)
Block(-8,44,6,251:15)
Block(-8,44,7,251:15)
Block(-8,45,-7,159:15)
Block(-8,45,-6,159:15)
Block(-8,45,-5,251:15)
Block(-8,45,-4,159:15)
Block(-8,45,-3,159:15)
Block(-8,45,-2,251:15)
Block(-8,45,-1,159:15)
Block(-8,45,0,251:15)
Block(-8,45,1,251:15)
Block(-8,45,2,159:15)
Block(-8,45,3,251:15)
Block(-8,45,4,251:15)
Block(-8,45,5,251:15)
Block(-8,45,6,251:15)
Block(-8,45,7,159:15)
Block(-8,46,-7,251:15)
Block(-8,46,-6,159:15)
Block(-8,46,-5,159:15)
Block(-8,46,-4,159:15)
Block(-8,46,-3,251:15)
Block(-8,46,-2,159:15)
Block(-8,46,-1,159:15)
Block(-8,46,0,251:15)
Block(-8,46,1,251:15)
Block(-8,46,2,251:15)
Block(-8,46,3,159:15)
Block(-8,46,4,251:15)
Block(-8,46,5,159:15)
Block(-8,46,6,251:15)
Block(-8,46,7,159:15)
Block(-8,47,-7,159:15)
Block(-8,47,-6,159:15)
Block(-8,47,-5,251:15)
Block(-8,47,-4,251:15)
Block(-8,47,-3,251:15)
Block(-8,47,-2,251:15)
Block(-8,47,-1,251:15)
Block(-8,47,0,251:15)
Block(-8,47,1,251:15)
Block(-8,47,2,159:15)
Block(-8,47,3,159:15)
Block(-8,47,4,159:15)
Block(-8,47,5,159:15)
Block(-8,47,6,251:15)
Block(-8,47,7,251:15)
Block(-8,48,-7,251:15)
Block(-8,48,-6,251:15)
Block(-8,48,-5,159:15)
Block(-8,48,-4,159:15)
Block(-8,48,-3,251:15)
Block(-8,48,-2,159:15)
Block(-8,48,-1,159:15)
Block(-8,48,0,251:15)
Block(-8,48,1,159:15)
Block(-8,48,2,159:15)
Block(-8,48,3,159:15)
Block(-8,48,4,159:15)
Block(-8,48,5,251:15)
Block(-8,48,6,159:15)
Block(-8,48,7,159:15)
Block(-8,49,-7,159:15)
Block(-8,49,-6,159:15)
Block(-8,49,-5,159:15)
Block(-8,49,-4,251:15)
Block(-8,49,-3,251:15)
Block(-8,49,-2,251:15)
Block(-8,49,-1,159:15)
Block(-8,49,0,251:15)
Block(-8,49,1,159:15)
Block(-8,49,2,251:15)
Block(-8,49,3,251:15)
Block(-8,49,4,159:15)
Block(-8,49,5,159:15)
Block(-8,49,6,251:15)
Block(-8,49,7,159:15)
Block(-8,50,-7,159:15)
Block(-8,50,-6,159:15)
Block(-8,50,-5,251:15)
Block(-8,50,-4,251:15)
Block(-8,50,-3,159:15)
Block(-8,50,-2,159:15)
Block(-8,50,-1,251:15)
Block(-8,50,0,159:15)
Block(-8,50,1,159:15)
Block(-8,50,2,159:15)
Block(-8,50,3,159:15)
Block(-8,50,4,159:15)
Block(-8,50,5,251:15)
Block(-8,50,6,251:15)
Block(-8,50,7,159:15)
Block(-8,51,-7,159:15)
Block(-8,51,-6,251:15)
Block(-8,51,-5,159:15)
Block(-8,51,-4,159:15)
Block(-8,51,-3,159:15)
Block(-8,51,-2,159:15)
Block(-8,51,-1,159:15)
Block(-8,51,0,251:15)
Block(-8,51,1,251:15)
Block(-8,51,2,251:15)
Block(-8,51,3,251:15)
Block(-8,51,4,251:15)
Block(-8,51,5,159:15)
Block(-8,51,6,251:15)
Block(-8,51,7,159:15)
Block(-8,52,-7,159:15)
Block(-8,52,-6,159:15)
Block(-8,52,-5,159:15)
Block(-8,52,-4,159:15)
Block(-8,52,-3,159:15)
Block(-8,52,-2,159:15)
Block(-8,52,-1,159:15)
Block(-8,52,0,159:15)
Block(-8,52,1,159:15)
Block(-8,52,2,251:15)
Block(-8,52,3,159:15)
Block(-8,52,4,251:15)
Block(-8,52,5,251:15)
Block(-8,52,6,251:15)
Block(-8,52,7,159:15)
Block(-8,53,-7,159:15)
Block(-8,53,-6,251:15)
Block(-8,53,-5,251:15)
Block(-8,53,-4,159:15)
Block(-8,53,-3,159:15)
Block(-8,53,-2,159:15)
Block(-8,53,-1,251:15)
Block(-8,53,0,159:15)
Block(-8,53,1,159:15)
Block(-8,53,2,251:15)
Block(-8,53,3,251:15)
Block(-8,53,4,159:15)
Block(-8,53,5,159:15)
Block(-8,53,6,251:15)
Block(-8,53,7,251:15)
Block(-8,54,-7,159:15)
Block(-8,54,-6,159:15)
Block(-8,54,-5,251:15)
Block(-8,54,-4,159:15)
Block(-8,54,-3,159:15)
Block(-8,54,-2,159:15)
Block(-8,54,-1,251:15)
Block(-8,54,0,159:15)
Block(-8,54,1,251:15)
Block(-8,54,2,159:15)
Block(-8,54,3,251:15)
Block(-8,54,4,251:15)
Block(-8,54,5,251:15)
Block(-8,54,6,251:15)
Block(-8,54,7,251:15)
Block(-8,55,-7,251:15)
Block(-8,55,-6,159:15)
Block(-8,55,-5,159:15)
Block(-8,55,-4,251:15)
Block(-8,55,-3,159:15)
Block(-8,55,-2,251:15)
Block(-8,55,-1,251:15)
Block(-8,55,0,159:15)
Block(-8,55,1,251:15)
Block(-8,55,2,159:15)
Block(-8,55,3,159:15)
Block(-8,55,4,251:15)
Block(-8,55,5,159:15)
Block(-8,55,6,251:15)
Block(-8,55,7,159:15)
Block(-8,56,-7,159:15)
Block(-8,56,-6,159:15)
Block(-8,56,-5,159:15)
Block(-8,56,-4,159:15)
Block(-8,56,-3,159:15)
Block(-8,56,-2,251:15)
Block(-8,56,-1,159:15)
Block(-8,56,0,159:15)
Block(-8,56,1,251:15)
Block(-8,56,2,251:15)
Block(-8,56,3,251:15)
Block(-8,56,4,159:15)
Block(-8,56,5,159:15)
Block(-8,56,6,251:15)
Block(-8,56,7,159:15)
Block(-8,57,-7,251:15)
Block(-8,57,-6,159:15)
Block(-8,57,-5,251:15)
Block(-8,57,-4,251:15)
Block(-8,57,-3,251:15)
Block(-8,57,-2,159:15)
Block(-8,57,-1,251:15)
Block(-8,57,0,159:15)
Block(-8,57,1,159:15)
Block(-8,57,2,159:15)
Block(-8,57,3,251:15)
Block(-8,57,4,251:15)
Block(-8,57,5,159:15)
Block(-8,57,6,251:15)
Block(-8,57,7,251:15)
Block(-8,58,-7,159:15)
Block(-8,58,-6,251:15)
Block(-8,58,-5,159:15)
Block(-8,58,-4,159:15)
Block(-8,58,-3,159:15)
Block(-8,58,-2,159:15)
Block(-8,58,-1,251:15)
Block(-8,58,0,159:15)
Block(-8,58,1,251:15)
Block(-8,58,2,251:15)
Block(-8,58,3,251:15)
Block(-8,58,4,251:15)
Block(-8,58,5,159:15)
Block(-8,58,6,251:15)
Block(-8,58,7,251:15)
Block(-8,59,-7,251:15)
Block(-8,59,-6,159:15)
Block(-8,59,-5,251:15)
Block(-8,59,-4,251:15)
Block(-8,59,-3,159:15)
Block(-8,59,-2,251:15)
Block(-8,59,-1,3:1)
Block(-8,59,0,251:15)
Block(-8,59,1,251:15)
Block(-8,59,2,159:15)
Block(-8,59,3,159:15)
Block(-8,59,4,159:15)
Block(-8,59,5,251:15)
Block(-8,59,6,251:15)
Block(-8,59,7,159:15)
Block(-7,0,-7,251:15)
Block(-7,0,-6,251:15)
Block(-7,0,-5,251:15)
Block(-7,0,-4,159:15)
Block(-7,0,-3,251:15)
Block(-7,0,-2,159:15)
Block(-7,0,-1,251:15)
Block(-7,0,0,251:15)
Block(-7,0,1,251:15)
Block(-7,0,2,159:15)
Block(-7,0,3,251:15)
Block(-7,0,4,159:15)
Block(-7,0,5,159:15)
Block(-7,0,6,251:15)
Block(-7,0,7,159:15)
Block(-7,1,-7,159:15)
Block(-7,1,-6,251:15)
Block(-7,1,-5,251:15)
Block(-7,1,-4,159:15)
Block(-7,1,-3,159:15)
Block(-7,1,-2,251:15)
Block(-7,1,-1,159:15)
Block(-7,1,0,251:15)
Block(-7,1,1,159:15)
Block(-7,1,2,159:15)
Block(-7,1,3,159:15)
Block(-7,1,4,251:15)
Block(-7,1,5,251:15)
Block(-7,1,6,251:15)
Block(-7,1,7,159:15)
Block(-7,2,-7,159:15)
Block(-7,2,-6,159:15)
Block(-7,2,-5,251:15)
Block(-7,2,-4,159:15)
Block(-7,2,-3,159:15)
Block(-7,2,-2,251:15)
Block(-7,2,-1,251:15)
Block(-7,2,0,251:15)
Block(-7,2,1,251:15)
Block(-7,2,2,159:15)
Block(-7,2,3,159:15)
Block(-7,2,4,159:15)
Block(-7,2,5,159:15)
Block(-7,2,6,159:15)
Block(-7,2,7,159:15)
Block(-7,3,-7,159:15)
Block(-7,3,-6,251:15)
Block(-7,3,-5,159:15)
Block(-7,3,-4,159:15)
Block(-7,3,-3,159:15)
Block(-7,3,-2,251:15)
Block(-7,3,-1,159:15)
Block(-7,3,0,159:15)
Block(-7,3,1,251:15)
Block(-7,3,2,159:15)
Block(-7,3,3,251:15)
Block(-7,3,4,159:15)
Block(-7,3,5,251:15)
Block(-7,3,6,251:15)
Block(-7,3,7,251:15)
Block(-7,4,-7,251:15)
Block(-7,4,-6,251:15)
Block(-7,4,-5,251:15)
Block(-7,4,-4,159:15)
Block(-7,4,-3,159:15)
Block(-7,4,-2,251:15)
Block(-7,4,-1,159:15)
Block(-7,4,0,159:15)
Block(-7,4,1,251:15)
Block(-7,4,2,159:15)
Block(-7,4,3,251:15)
Block(-7,4,4,159:15)
Block(-7,4,5,159:15)
Block(-7,4,6,159:15)
Block(-7,4,7,251:15)
Block(-7,5,-7,251:15)
Block(-7,5,-6,251:15)
Block(-7,5,-5,159:15)
Block(-7,5,-4,251:15)
Block(-7,5,-3,159:15)
Block(-7,5,-2,159:15)
Block(-7,5,-1,251:15)
Block(-7,5,0,159:15)
Block(-7,5,1,159:15)
Block(-7,5,2,251:15)
Block(-7,5,3,159:15)
Block(-7,5,4,251:15)
Block(-7,5,5,159:15)
Block(-7,5,6,159:15)
Block(-7,5,7,159:15)
Block(-7,6,-7,159:15)
Block(-7,6,-6,251:15)
Block(-7,6,-5,251:15)
Block(-7,6,-4,159:15)
Block(-7,6,-3,251:15)
Block(-7,6,-2,251:15)
Block(-7,6,-1,159:15)
Block(-7,6,0,251:15)
Block(-7,6,1,251:15)
Block(-7,6,2,159:15)
Block(-7,6,3,159:15)
Block(-7,6,4,251:15)
Block(-7,6,5,159:15)
Block(-7,6,6,159:15)
Block(-7,6,7,159:15)
Block(-7,7,-7,251:15)
Block(-7,7,-6,251:15)
Block(-7,7,-5,159:15)
Block(-7,7,-4,251:15)
Block(-7,7,-3,251:15)
Block(-7,7,-2,159:15)
Block(-7,7,-1,251:15)
Block(-7,7,0,159:15)
Block(-7,7,1,159:15)
Block(-7,7,2,159:15)
Block(-7,7,3,251:15)
Block(-7,7,4,251:15)
Block(-7,7,5,251:15)
Block(-7,7,6,159:15)
Block(-7,7,7,159:15)
Block(-7,8,-7,159:15)
Block(-7,8,-6,251:15)
Block(-7,8,-5,159:15)
Block(-7,8,-4,159:15)
Block(-7,8,-3,251:15)
Block(-7,8,-2,159:15)
Block(-7,8,-1,251:15)
Block(-7,8,0,159:15)
Block(-7,8,1,159:15)
Block(-7,8,2,251:15)
Block(-7,8,3,251:15)
Block(-7,8,4,251:15)
Block(-7,8,5,251:15)
Block(-7,8,6,251:15)
Block(-7,8,7,159:15)
Block(-7,9,-7,159:15)
Block(-7,9,-6,159:15)
Block(-7,9,-5,251:15)
Block(-7,9,-4,159:15)
Block(-7,9,-3,159:15)
Block(-7,9,-2,159:15)
Block(-7,9,-1,159:15)
Block(-7,9,0,159:15)
Block(-7,9,1,159:15)
Block(-7,9,2,159:15)
Block(-7,9,3,159:15)
Block(-7,9,4,251:15)
Block(-7,9,5,159:15)
Block(-7,9,6,159:15)
Block(-7,9,7,251:15)
Block(-7,10,-7,251:15)
Block(-7,10,-6,251:15)
Block(-7,10,-5,251:15)
Block(-7,10,-4,159:15)
Block(-7,10,-3,251:15)
Block(-7,10,-2,159:15)
Block(-7,10,-1,251:15)
Block(-7,10,0,159:15)
Block(-7,10,1,251:15)
Block(-7,10,2,159:15)
Block(-7,10,3,159:15)
Block(-7,10,4,251:15)
Block(-7,10,5,159:15)
Block(-7,10,6,159:15)
Block(-7,10,7,159:15)
Block(-7,11,-7,159:15)
Block(-7,11,-6,159:15)
Block(-7,11,-5,251:15)
Block(-7,11,-4,251:15)
Block(-7,11,-3,251:15)
Block(-7,11,-2,159:15)
Block(-7,11,-1,251:15)
Block(-7,11,0,159:15)
Block(-7,11,1,159:15)
Block(-7,11,2,159:15)
Block(-7,11,3,159:15)
Block(-7,11,4,251:15)
Block(-7,11,5,159:15)
Block(-7,11,6,159:15)
Block(-7,11,7,251:15)
Block(-7,12,-7,159:15)
Block(-7,12,-6,159:15)
Block(-7,12,-5,251:15)
Block(-7,12,-4,251:15)
Block(-7,12,-3,251:15)
Block(-7,12,-2,251:15)
Block(-7,12,-1,251:15)
Block(-7,12,0,251:15)
Block(-7,12,1,251:15)
Block(-7,12,2,159:15)
Block(-7,12,3,159:15)
Block(-7,12,4,251:15)
Block(-7,12,5,159:15)
Block(-7,12,6,251:15)
Block(-7,12,7,159:15)
Block(-7,13,-7,159:15)
Block(-7,13,-6,251:15)
Block(-7,13,-5,159:15)
Block(-7,13,-4,251:15)
Block(-7,13,-3,251:15)
Block(-7,13,-2,159:15)
Block(-7,13,-1,251:15)
Block(-7,13,0,159:15)
Block(-7,13,1,251:15)
Block(-7,13,2,159:15)
Block(-7,13,3,251:15)
Block(-7,13,4,251:15)
Block(-7,13,5,159:15)
Block(-7,13,6,159:15)
Block(-7,13,7,251:15)
Block(-7,14,-7,159:15)
Block(-7,14,-6,159:15)
Block(-7,14,-5,251:15)
Block(-7,14,-4,159:15)
Block(-7,14,-3,251:15)
Block(-7,14,-2,159:15)
Block(-7,14,-1,159:15)
Block(-7,14,0,251:15)
Block(-7,14,1,159:15)
Block(-7,14,2,159:15)
Block(-7,14,3,251:15)
Block(-7,14,4,251:15)
Block(-7,14,5,251:15)
Block(-7,14,6,159:15)
Block(-7,14,7,159:15)
Block(-7,15,-7,251:15)
Block(-7,15,-6,251:15)
Block(-7,15,-5,159:15)
Block(-7,15,-4,159:15)
Block(-7,15,-3,251:15)
Block(-7,15,-2,159:15)
Block(-7,15,-1,251:15)
Block(-7,15,0,251:15)
Block(-7,15,1,251:15)
Block(-7,15,2,159:15)
Block(-7,15,3,159:15)
Block(-7,15,4,251:15)
Block(-7,15,5,159:15)
Block(-7,15,6,159:15)
Block(-7,15,7,251:15)
Block(-7,16,-7,159:15)
Block(-7,16,-6,159:15)
Block(-7,16,-5,159:15)
Block(-7,16,-4,251:15)
Block(-7,16,-3,251:15)
Block(-7,16,-2,251:15)
Block(-7,16,-1,251:15)
Block(-7,16,0,251:15)
Block(-7,16,1,159:15)
Block(-7,16,2,251:15)
Block(-7,16,3,159:15)
Block(-7,16,4,159:15)
Block(-7,16,5,159:15)
Block(-7,16,6,251:15)
Block(-7,16,7,251:15)
Block(-7,17,-7,159:15)
Block(-7,17,-6,251:15)
Block(-7,17,-5,251:15)
Block(-7,17,-4,251:15)
Block(-7,17,-3,159:15)
Block(-7,17,-2,251:15)
Block(-7,17,-1,159:15)
Block(-7,17,0,159:15)
Block(-7,17,1,159:15)
Block(-7,17,2,159:15)
Block(-7,17,3,159:15)
Block(-7,17,4,159:15)
Block(-7,17,5,159:15)
Block(-7,17,6,159:15)
Block(-7,17,7,159:15)
Block(-7,18,-7,251:15)
Block(-7,18,-6,159:15)
Block(-7,18,-5,251:15)
Block(-7,18,-4,159:15)
Block(-7,18,-3,159:15)
Block(-7,18,-2,251:15)
Block(-7,18,-1,159:15)
Block(-7,18,0,159:15)
Block(-7,18,1,159:15)
Block(-7,18,2,159:15)
Block(-7,18,3,251:15)
Block(-7,18,4,159:15)
Block(-7,18,5,159:15)
Block(-7,18,6,159:15)
Block(-7,18,7,159:15)
Block(-7,19,-7,159:15)
Block(-7,19,-6,251:15)
Block(-7,19,-5,159:15)
Block(-7,19,-4,251:15)
Block(-7,19,-3,159:15)
Block(-7,19,-2,251:15)
Block(-7,19,-1,159:15)
Block(-7,19,0,159:15)
Block(-7,19,1,251:15)
Block(-7,19,2,251:15)
Block(-7,19,3,251:15)
Block(-7,19,4,251:15)
Block(-7,19,5,159:15)
Block(-7,19,6,251:15)
Block(-7,19,7,251:15)
Block(-7,20,-7,159:15)
Block(-7,20,-6,159:15)
Block(-7,20,-5,159:15)
Block(-7,20,-4,159:15)
Block(-7,20,-3,251:15)
Block(-7,20,-2,159:15)
Block(-7,20,-1,159:15)
Block(-7,20,0,251:15)
Block(-7,20,1,251:15)
Block(-7,20,2,159:15)
Block(-7,20,3,159:15)
Block(-7,20,4,159:15)
Block(-7,20,5,159:15)
Block(-7,20,6,159:15)
Block(-7,20,7,251:15)
Block(-7,21,-7,159:15)
Block(-7,21,-6,159:15)
Block(-7,21,-5,159:15)
Block(-7,21,-4,251:15)
Block(-7,21,-3,251:15)
Block(-7,21,-2,251:15)
Block(-7,21,-1,251:15)
Block(-7,21,0,159:15)
Block(-7,21,1,159:15)
Block(-7,21,2,159:15)
Block(-7,21,3,251:15)
Block(-7,21,4,251:15)
Block(-7,21,5,251:15)
Block(-7,21,6,159:15)
Block(-7,21,7,251:15)
Block(-7,22,-7,159:15)
Block(-7,22,-6,251:15)
Block(-7,22,-5,251:15)
Block(-7,22,-4,251:15)
Block(-7,22,-3,159:15)
Block(-7,22,-2,251:15)
Block(-7,22,-1,159:15)
Block(-7,22,0,251:15)
Block(-7,22,1,251:15)
Block(-7,22,2,251:15)
Block(-7,22,3,251:15)
Block(-7,22,4,251:15)
Block(-7,22,5,251:15)
Block(-7,22,6,159:15)
Block(-7,22,7,251:15)
Block(-7,23,-7,159:15)
Block(-7,23,-6,159:15)
Block(-7,23,-5,251:15)
Block(-7,23,-4,159:15)
Block(-7,23,-3,159:15)
Block(-7,23,-2,251:15)
Block(-7,23,-1,159:15)
Block(-7,23,0,251:15)
Block(-7,23,1,159:15)
Block(-7,23,2,159:15)
Block(-7,23,3,251:15)
Block(-7,23,4,251:15)
Block(-7,23,5,251:15)
Block(-7,23,6,251:15)
Block(-7,23,7,159:15)
Block(-7,24,-7,159:15)
Block(-7,24,-6,251:15)
Block(-7,24,-5,251:15)
Block(-7,24,-4,159:15)
Block(-7,24,-3,251:15)
Block(-7,24,-2,159:15)
Block(-7,24,-1,251:15)
Block(-7,24,0,251:15)
Block(-7,24,1,251:15)
Block(-7,24,2,159:15)
Block(-7,24,3,159:15)
Block(-7,24,4,251:15)
Block(-7,24,5,159:15)
Block(-7,24,6,159:15)
Block(-7,24,7,251:15)
Block(-7,25,-7,251:15)
Block(-7,25,-6,251:15)
Block(-7,25,-5,251:15)
Block(-7,25,-4,159:15)
Block(-7,25,-3,159:15)
Block(-7,25,-2,251:15)
Block(-7,25,-1,159:15)
Block(-7,25,0,159:15)
Block(-7,25,1,159:15)
Block(-7,25,2,251:15)
Block(-7,25,3,159:15)
Block(-7,25,4,159:15)
Block(-7,25,5,251:15)
Block(-7,25,6,251:15)
Block(-7,25,7,251:15)
Block(-7,26,-7,159:15)
Block(-7,26,-6,159:15)
Block(-7,26,-5,251:15)
Block(-7,26,-4,159:15)
Block(-7,26,-3,251:15)
Block(-7,26,-2,251:15)
Block(-7,26,-1,251:15)
Block(-7,26,0,251:15)
Block(-7,26,1,251:15)
Block(-7,26,2,251:15)
Block(-7,26,3,159:15)
Block(-7,26,4,159:15)
Block(-7,26,5,251:15)
Block(-7,26,6,251:15)
Block(-7,26,7,159:15)
Block(-7,27,-7,251:15)
Block(-7,27,-6,159:15)
Block(-7,27,-5,251:15)
Block(-7,27,-4,251:15)
Block(-7,27,-3,251:15)
Block(-7,27,-2,159:15)
Block(-7,27,-1,159:15)
Block(-7,27,0,251:15)
Block(-7,27,1,159:15)
Block(-7,27,2,251:15)
Block(-7,27,3,251:15)
Block(-7,27,4,159:15)
Block(-7,27,5,251:15)
Block(-7,27,6,251:15)
Block(-7,27,7,159:15)
Block(-7,28,-7,251:15)
Block(-7,28,-6,159:15)
Block(-7,28,-5,251:15)
Block(-7,28,-4,159:15)
Block(-7,28,-3,251:15)
Block(-7,28,-2,159:15)
Block(-7,28,-1,251:15)
Block(-7,28,0,159:15)
Block(-7,28,1,159:15)
Block(-7,28,2,159:15)
Block(-7,28,3,251:15)
Block(-7,28,4,159:15)
Block(-7,28,5,251:15)
Block(-7,28,6,159:15)
Block(-7,28,7,159:15)
Block(-7,29,-7,251:15)
Block(-7,29,-6,251:15)
Block(-7,29,-5,251:15)
Block(-7,29,-4,159:15)
Block(-7,29,-3,251:15)
Block(-7,29,-2,159:15)
Block(-7,29,-1,251:15)
Block(-7,29,0,159:15)
Block(-7,29,1,159:15)
Block(-7,29,2,251:15)
Block(-7,29,3,159:15)
Block(-7,29,4,251:15)
Block(-7,29,5,251:15)
Block(-7,29,6,159:15)
Block(-7,29,7,159:15)
Block(-7,30,-7,251:15)
Block(-7,30,-6,159:15)
Block(-7,30,-5,159:15)
Block(-7,30,-4,159:15)
Block(-7,30,-3,159:15)
Block(-7,30,-2,251:15)
Block(-7,30,-1,251:15)
Block(-7,30,0,251:15)
Block(-7,30,1,159:15)
Block(-7,30,2,159:15)
Block(-7,30,3,251:15)
Block(-7,30,4,159:15)
Block(-7,30,5,159:15)
Block(-7,30,6,251:15)
Block(-7,30,7,159:15)
Block(-7,31,-7,251:15)
Block(-7,31,-6,159:15)
Block(-7,31,-5,159:15)
Block(-7,31,-4,251:15)
Block(-7,31,-3,251:15)
Block(-7,31,-2,159:15)
Block(-7,31,-1,159:15)
Block(-7,31,0,251:15)
Block(-7,31,1,251:15)
Block(-7,31,2,159:15)
Block(-7,31,3,159:15)
Block(-7,31,4,159:15)
Block(-7,31,5,251:15)
Block(-7,31,6,159:15)
Block(-7,31,7,159:15)
Block(-7,32,-7,251:15)
Block(-7,32,-6,251:15)
Block(-7,32,-5,159:15)
Block(-7,32,-4,251:15)
Block(-7,32,-3,251:15)
Block(-7,32,-2,251:15)
Block(-7,32,-1,251:15)
Block(-7,32,0,159:15)
Block(-7,32,1,251:15)
Block(-7,32,2,159:15)
Block(-7,32,3,251:15)
Block(-7,32,4,251:15)
Block(-7,32,5,159:15)
Block(-7,32,6,159:15)
Block(-7,32,7,251:7)
Block(-7,33,-7,159:15)
Block(-7,33,-6,251:15)
Block(-7,33,-5,159:15)
Block(-7,33,-4,159:15)
Block(-7,33,-3,251:15)
Block(-7,33,-2,159:15)
Block(-7,33,-1,251:15)
Block(-7,33,0,159:15)
Block(-7,33,1,251:15)
Block(-7,33,2,159:15)
Block(-7,33,3,251:15)
Block(-7,33,4,251:15)
Block(-7,33,5,159:15)
Block(-7,33,6,159:15)
Block(-7,33,7,251:7)
Block(-7,34,-7,159:15)
Block(-7,34,-6,159:15)
Block(-7,34,-5,251:15)
Block(-7,34,-4,251:15)
Block(-7,34,-3,159:15)
Block(-7,34,-2,159:15)
Block(-7,34,-1,159:15)
Block(-7,34,0,159:15)
Block(-7,34,1,159:15)
Block(-7,34,2,251:15)
Block(-7,34,3,251:15)
Block(-7,34,4,159:15)
Block(-7,34,5,159:15)
Block(-7,34,6,251:15)
Block(-7,34,7,251:7)
Block(-7,35,-7,251:15)
Block(-7,35,-6,251:15)
Block(-7,35,-5,159:15)
Block(-7,35,-4,251:15)
Block(-7,35,-3,251:15)
Block(-7,35,-2,159:15)
Block(-7,35,-1,251:15)
Block(-7,35,0,251:15)
Block(-7,35,1,159:15)
Block(-7,35,2,159:15)
Block(-7,35,3,159:15)
Block(-7,35,4,159:15)
Block(-7,35,5,251:15)
Block(-7,35,6,251:15)
Block(-7,35,7,251:15)
Block(-7,36,-7,251:15)
Block(-7,36,-6,251:15)
Block(-7,36,-5,251:15)
Block(-7,36,-4,251:15)
Block(-7,36,-3,251:15)
Block(-7,36,-2,251:15)
Block(-7,36,-1,159:15)
Block(-7,36,0,159:15)
Block(-7,36,1,159:15)
Block(-7,36,2,159:15)
Block(-7,36,3,251:15)
Block(-7,36,4,159:15)
Block(-7,36,5,159:15)
Block(-7,36,6,251:15)
Block(-7,36,7,251:15)
Block(-7,37,-7,159:15)
Block(-7,37,-6,159:15)
Block(-7,37,-5,159:15)
Block(-7,37,-4,251:15)
Block(-7,37,-3,159:15)
Block(-7,37,-2,251:15)
Block(-7,37,-1,251:15)
Block(-7,37,0,251:15)
Block(-7,37,1,159:15)
Block(-7,37,2,251:15)
Block(-7,37,3,251:15)
Block(-7,37,4,251:15)
Block(-7,37,5,251:15)
Block(-7,37,6,159:15)
Block(-7,37,7,159:15)
Block(-7,38,-7,159:15)
Block(-7,38,-6,159:15)
Block(-7,38,-5,251:15)
Block(-7,38,-4,159:15)
Block(-7,38,-3,159:15)
Block(-7,38,-2,251:15)
Block(-7,38,-1,159:15)
Block(-7,38,0,251:15)
Block(-7,38,1,251:15)
Block(-7,38,2,159:15)
Block(-7,38,3,251:15)
Block(-7,38,4,251:15)
Block(-7,38,5,251:15)
Block(-7,38,6,251:15)
Block(-7,38,7,251:15)
Block(-7,39,-7,159:15)
Block(-7,39,-6,251:15)
Block(-7,39,-5,159:15)
Block(-7,39,-4,251:15)
Block(-7,39,-3,251:15)
Block(-7,39,-2,159:15)
Block(-7,39,-1,159:15)
Block(-7,39,0,251:15)
Block(-7,39,1,159:15)
Block(-7,39,2,159:15)
Block(-7,39,3,159:15)
Block(-7,39,4,159:15)
Block(-7,39,5,159:15)
Block(-7,39,6,251:15)
Block(-7,39,7,159:15)
Block(-7,40,-7,251:15)
Block(-7,40,-6,251:15)
Block(-7,40,-5,251:15)
Block(-7,40,-4,251:15)
Block(-7,40,-3,159:15)
Block(-7,40,-2,251:15)
Block(-7,40,-1,251:15)
Block(-7,40,0,251:15)
Block(-7,40,1,159:15)
Block(-7,40,2,251:15)
Block(-7,40,3,159:15)
Block(-7,40,4,159:15)
Block(-7,40,5,251:15)
Block(-7,40,6,251:15)
Block(-7,40,7,251:15)
Block(-7,41,-7,159:15)
Block(-7,41,-6,251:15)
Block(-7,41,-5,159:15)
Block(-7,41,-4,159:15)
Block(-7,41,-3,251:15)
Block(-7,41,-2,251:15)
Block(-7,41,-1,251:15)
Block(-7,41,0,251:15)
Block(-7,41,1,251:15)
Block(-7,41,2,159:15)
Block(-7,41,3,159:15)
Block(-7,41,4,159:15)
Block(-7,41,5,159:15)
Block(-7,41,6,251:15)
Block(-7,41,7,251:15)
Block(-7,42,-7,159:15)
Block(-7,42,-6,251:15)
Block(-7,42,-5,251:15)
Block(-7,42,-4,251:15)
Block(-7,42,-3,251:15)
Block(-7,42,-2,251:15)
Block(-7,42,-1,251:15)
Block(-7,42,0,251:15)
Block(-7,42,1,159:15)
Block(-7,42,2,159:15)
Block(-7,42,3,251:15)
Block(-7,42,4,251:15)
Block(-7,42,5,251:15)
Block(-7,42,6,251:15)
Block(-7,42,7,251:15)
Block(-7,43,-7,159:15)
Block(-7,43,-6,159:15)
Block(-7,43,-5,159:15)
Block(-7,43,-4,251:15)
Block(-7,43,-3,159:15)
Block(-7,43,-2,251:15)
Block(-7,43,-1,251:15)
Block(-7,43,0,159:15)
Block(-7,43,1,159:15)
Block(-7,43,2,251:15)
Block(-7,43,3,159:15)
Block(-7,43,4,251:15)
Block(-7,43,5,251:15)
Block(-7,43,6,251:15)
Block(-7,43,7,159:15)
Block(-7,44,-7,251:15)
Block(-7,44,-6,251:15)
Block(-7,44,-5,159:15)
Block(-7,44,-4,159:15)
Block(-7,44,-3,251:15)
Block(-7,44,-2,251:15)
Block(-7,44,-1,159:15)
Block(-7,44,0,159:15)
Block(-7,44,1,159:15)
Block(-7,44,2,251:15)
Block(-7,44,3,251:15)
Block(-7,44,4,159:15)
Block(-7,44,5,251:15)
Block(-7,44,6,159:15)
Block(-7,44,7,251:15)
Block(-7,45,-7,251:15)
Block(-7,45,-6,159:15)
Block(-7,45,-5,251:15)
Block(-7,45,-4,251:15)
Block(-7,45,-3,251:15)
Block(-7,45,-2,159:15)
Block(-7,45,-1,159:15)
Block(-7,45,0,159:15)
Block(-7,45,1,159:15)
Block(-7,45,2,251:15)
Block(-7,45,3,251:15)
Block(-7,45,4,159:15)
Block(-7,45,5,251:15)
Block(-7,45,6,251:15)
Block(-7,45,7,251:15)
Block(-7,46,-7,159:15)
Block(-7,46,-6,159:15)
Block(-7,46,-5,251:15)
Block(-7,46,-4,159:15)
Block(-7,46,-3,159:15)
Block(-7,46,-2,159:15)
Block(-7,46,-1,159:15)
Block(-7,46,0,159:15)
Block(-7,46,1,159:15)
Block(-7,46,2,159:15)
Block(-7,46,3,251:15)
Block(-7,46,4,159:15)
Block(-7,46,5,159:15)
Block(-7,46,6,159:15)
Block(-7,46,7,159:15)
Block(-7,47,-7,251:15)
Block(-7,47,-6,159:15)
Block(-7,47,-5,251:15)
Block(-7,47,-4,159:15)
Block(-7,47,-3,159:15)
Block(-7,47,-2,159:15)
Block(-7,47,-1,159:15)
Block(-7,47,0,251:15)
Block(-7,47,1,159:15)
Block(-7,47,2,159:15)
Block(-7,47,3,159:15)
Block(-7,47,4,251:15)
Block(-7,47,5,159:15)
Block(-7,47,6,159:15)
Block(-7,47,7,159:15)
Block(-7,48,-7,251:15)
Block(-7,48,-6,159:15)
Block(-7,48,-5,159:15)
Block(-7,48,-4,251:15)
Block(-7,48,-3,159:15)
Block(-7,48,-2,159:15)
Block(-7,48,-1,251:15)
Block(-7,48,0,159:15)
Block(-7,48,1,159:15)
Block(-7,48,2,251:15)
Block(-7,48,3,159:15)
Block(-7,48,4,159:15)
Block(-7,48,5,159:15)
Block(-7,48,6,159:15)
Block(-7,48,7,159:15)
Block(-7,49,-7,251:15)
Block(-7,49,-6,159:15)
Block(-7,49,-5,159:15)
Block(-7,49,-4,251:15)
Block(-7,49,-3,159:15)
Block(-7,49,-2,251:15)
Block(-7,49,-1,159:15)
Block(-7,49,0,251:15)
Block(-7,49,1,159:15)
Block(-7,49,2,159:15)
Block(-7,49,3,251:15)
Block(-7,49,4,251:15)
Block(-7,49,5,159:15)
Block(-7,49,6,251:15)
Block(-7,49,7,159:15)
Block(-7,50,-7,251:15)
Block(-7,50,-6,159:15)
Block(-7,50,-5,159:15)
Block(-7,50,-4,251:15)
Block(-7,50,-3,159:15)
Block(-7,50,-2,159:15)
Block(-7,50,-1,159:15)
Block(-7,50,0,159:15)
Block(-7,50,1,159:15)
Block(-7,50,2,251:15)
Block(-7,50,3,251:15)
Block(-7,50,4,159:15)
Block(-7,50,5,251:15)
Block(-7,50,6,251:15)
Block(-7,50,7,159:15)
Block(-7,51,-7,159:15)
Block(-7,51,-6,251:15)
Block(-7,51,-5,251:15)
Block(-7,51,-4,251:15)
Block(-7,51,-3,159:15)
Block(-7,51,-2,159:15)
Block(-7,51,-1,159:15)
Block(-7,51,0,251:15)
Block(-7,51,1,159:15)
Block(-7,51,2,251:15)
Block(-7,51,3,159:15)
Block(-7,51,4,159:15)
Block(-7,51,5,251:15)
Block(-7,51,6,251:15)
Block(-7,51,7,251:15)
Block(-7,52,-7,159:15)
Block(-7,52,-6,159:15)
Block(-7,52,-5,159:15)
Block(-7,52,-4,251:15)
Block(-7,52,-3,251:15)
Block(-7,52,-2,159:15)
Block(-7,52,-1,251:15)
Block(-7,52,0,159:15)
Block(-7,52,1,251:15)
Block(-7,52,2,159:15)
Block(-7,52,3,251:15)
Block(-7,52,4,251:15)
Block(-7,52,5,251:15)
Block(-7,52,6,159:15)
Block(-7,52,7,159:15)
Block(-7,53,-7,251:15)
Block(-7,53,-6,159:15)
Block(-7,53,-5,251:15)
Block(-7,53,-4,251:15)
Block(-7,53,-3,251:15)
Block(-7,53,-2,159:15)
Block(-7,53,-1,251:15)
Block(-7,53,0,159:15)
Block(-7,53,1,159:15)
Block(-7,53,2,251:15)
Block(-7,53,3,159:15)
Block(-7,53,4,251:15)
Block(-7,53,5,159:15)
Block(-7,53,6,159:15)
Block(-7,53,7,159:15)
Block(-7,54,-7,159:15)
Block(-7,54,-6,251:15)
Block(-7,54,-5,251:15)
Block(-7,54,-4,251:15)
Block(-7,54,-3,159:15)
Block(-7,54,-2,251:15)
Block(-7,54,-1,251:15)
Block(-7,54,0,159:15)
Block(-7,54,1,251:15)
Block(-7,54,2,251:15)
Block(-7,54,3,251:15)
Block(-7,54,4,251:15)
Block(-7,54,5,251:15)
Block(-7,54,6,251:15)
Block(-7,54,7,251:15)
Block(-7,55,-7,159:15)
Block(-7,55,-6,159:15)
Block(-7,55,-5,159:15)
Block(-7,55,-4,159:15)
Block(-7,55,-3,159:15)
Block(-7,55,-2,251:15)
Block(-7,55,-1,251:15)
Block(-7,55,0,251:15)
Block(-7,55,1,251:15)
Block(-7,55,2,159:15)
Block(-7,55,3,159:15)
Block(-7,55,4,159:15)
Block(-7,55,5,251:15)
Block(-7,55,6,159:15)
Block(-7,55,7,251:15)
Block(-7,56,-7,251:15)
Block(-7,56,-6,251:15)
Block(-7,56,-5,159:15)
Block(-7,56,-4,159:15)
Block(-7,56,-3,159:15)
Block(-7,56,-2,159:15)
Block(-7,56,-1,251:15)
Block(-7,56,0,159:15)
Block(-7,56,1,251:15)
Block(-7,56,2,159:15)
Block(-7,56,3,159:15)
Block(-7,56,4,251:15)
Block(-7,56,5,159:15)
Block(-7,56,6,159:15)
Block(-7,56,7,159:15)
Block(-7,57,-7,159:15)
Block(-7,57,-6,251:15)
Block(-7,57,-5,251:15)
Block(-7,57,-4,159:15)
Block(-7,57,-3,251:15)
Block(-7,57,-2,159:15)
Block(-7,57,-1,159:15)
Block(-7,57,0,251:15)
Block(-7,57,1,159:15)
Block(-7,57,2,159:15)
Block(-7,57,3,159:15)
Block(-7,57,4,159:15)
Block(-7,57,5,251:15)
Block(-7,57,6,159:15)
Block(-7,57,7,159:15)
Block(-7,58,-7,251:15)
Block(-7,58,-6,159:15)
Block(-7,58,-5,251:15)
Block(-7,58,-4,159:15)
Block(-7,58,-3,159:15)
Block(-7,58,-2,159:15)
Block(-7,58,-1,159:15)
Block(-7,58,0,251:15)
Block(-7,58,1,251:15)
Block(-7,58,2,159:15)
Block(-7,58,3,251:15)
Block(-7,58,4,159:15)
Block(-7,58,5,251:15)
Block(-7,58,6,159:15)
Block(-7,58,7,251:15)
Block(-7,59,-7,251:15)
Block(-7,59,-6,251:15)
Block(-7,59,-5,251:15)
Block(-7,59,-4,251:15)
Block(-7,59,-3,251:15)
Block(-7,59,-2,159:15)
Block(-7,59,-1,3:1)
Block(-7,59,0,251:15)
Block(-7,59,1,159:15)
Block(-7,59,2,159:15)
Block(-7,59,3,159:15)
Block(-7,59,4,159:15)
Block(-7,59,5,159:15)
Block(-7,59,6,251:15)
Block(-7,59,7,159:15)
Block(-6,0,-7,159:15)
Block(-6,0,-6,251:15)
Block(-6,0,-5,251:15)
Block(-6,0,-4,251:15)
Block(-6,0,-3,251:15)
Block(-6,0,-2,159:15)
Block(-6,0,-1,251:15)
Block(-6,0,0,251:15)
Block(-6,0,1,159:15)
Block(-6,0,2,251:15)
Block(-6,0,3,251:15)
Block(-6,0,4,251:15)
Block(-6,0,5,159:15)
Block(-6,0,6,159:15)
Block(-6,1,-7,251:15)
Block(-6,1,-6,251:15)
Block(-6,1,-5,251:15)
Block(-6,1,-4,251:15)
Block(-6,1,-3,251:15)
Block(-6,1,-2,251:15)
Block(-6,1,-1,159:15)
Block(-6,1,0,159:15)
Block(-6,1,1,159:15)
Block(-6,1,2,159:15)
Block(-6,1,3,159:15)
Block(-6,1,4,251:15)
Block(-6,1,5,159:15)
Block(-6,1,6,251:15)
Block(-6,2,-7,251:15)
Block(-6,2,-6,251:15)
Block(-6,2,-5,159:15)
Block(-6,2,-4,159:15)
Block(-6,2,-3,159:15)
Block(-6,2,-2,251:15)
Block(-6,2,-1,159:15)
Block(-6,2,0,251:15)
Block(-6,2,1,159:15)
Block(-6,2,2,159:15)
Block(-6,2,3,159:15)
Block(-6,2,4,251:15)
Block(-6,2,5,159:15)
Block(-6,2,6,159:15)
Block(-6,3,-7,251:15)
Block(-6,3,-6,159:15)
Block(-6,3,-5,251:15)
Block(-6,3,-4,251:15)
Block(-6,3,-3,159:15)
Block(-6,3,-2,251:15)
Block(-6,3,-1,159:15)
Block(-6,3,0,251:15)
Block(-6,3,1,251:15)
Block(-6,3,2,251:15)
Block(-6,3,3,251:15)
Block(-6,3,4,251:15)
Block(-6,3,5,251:15)
Block(-6,3,6,251:15)
Block(-6,4,-7,159:15)
Block(-6,4,-6,159:15)
Block(-6,4,-5,251:15)
Block(-6,4,-4,159:15)
Block(-6,4,-3,159:15)
Block(-6,4,-2,159:15)
Block(-6,4,-1,159:15)
Block(-6,4,0,159:15)
Block(-6,4,1,159:15)
Block(-6,4,2,159:15)
Block(-6,4,3,159:15)
Block(-6,4,4,159:15)
Block(-6,4,5,159:15)
Block(-6,4,6,159:15)
Block(-6,5,-7,251:15)
Block(-6,5,-6,251:15)
Block(-6,5,-5,159:15)
Block(-6,5,-4,159:15)
Block(-6,5,-3,251:15)
Block(-6,5,-2,251:15)
Block(-6,5,-1,251:15)
Block(-6,5,0,251:15)
Block(-6,5,1,251:15)
Block(-6,5,2,251:15)
Block(-6,5,3,159:15)
Block(-6,5,4,251:15)
Block(-6,5,5,159:15)
Block(-6,5,6,251:15)
Block(-6,6,-7,159:15)
Block(-6,6,-6,159:15)
Block(-6,6,-5,159:15)
Block(-6,6,-4,159:15)
Block(-6,6,-3,159:15)
Block(-6,6,-2,251:15)
Block(-6,6,-1,251:15)
Block(-6,6,0,251:15)
Block(-6,6,1,251:15)
Block(-6,6,2,159:15)
Block(-6,6,3,159:15)
Block(-6,6,4,159:15)
Block(-6,6,5,159:15)
Block(-6,6,6,159:15)
Block(-6,7,-7,159:15)
Block(-6,7,-6,251:15)
Block(-6,7,-5,159:15)
Block(-6,7,-4,251:15)
Block(-6,7,-3,159:15)
Block(-6,7,-2,251:15)
Block(-6,7,-1,251:15)
Block(-6,7,0,159:15)
Block(-6,7,1,159:15)
Block(-6,7,2,251:15)
Block(-6,7,3,251:15)
Block(-6,7,4,159:15)
Block(-6,7,5,251:15)
Block(-6,7,6,251:15)
Block(-6,8,-7,251:15)
Block(-6,8,-6,251:15)
Block(-6,8,-5,159:15)
Block(-6,8,-4,159:15)
Block(-6,8,-3,159:15)
Block(-6,8,-2,251:15)
Block(-6,8,-1,251:15)
Block(-6,8,0,159:15)
Block(-6,8,1,159:15)
Block(-6,8,2,159:15)
Block(-6,8,3,251:15)
Block(-6,8,4,159:15)
Block(-6,8,5,251:15)
Block(-6,8,6,159:15)
Block(-6,9,-7,251:15)
Block(-6,9,-6,159:15)
Block(-6,9,-5,159:15)
Block(-6,9,-4,251:15)
Block(-6,9,-3,159:15)
Block(-6,9,-2,251:15)
Block(-6,9,-1,251:15)
Block(-6,9,0,251:15)
Block(-6,9,1,251:15)
Block(-6,9,2,251:15)
Block(-6,9,3,159:15)
Block(-6,9,4,159:15)
Block(-6,9,5,251:15)
Block(-6,9,6,251:15)
Block(-6,10,-7,251:15)
Block(-6,10,-6,251:15)
Block(-6,10,-5,251:15)
Block(-6,10,-4,251:15)
Block(-6,10,-3,251:15)
Block(-6,10,-2,159:15)
Block(-6,10,-1,159:15)
Block(-6,10,0,159:15)
Block(-6,10,1,251:15)
Block(-6,10,2,159:15)
Block(-6,10,3,251:15)
Block(-6,10,4,159:15)
Block(-6,10,5,159:15)
Block(-6,10,6,251:15)
Block(-6,11,-7,159:15)
Block(-6,11,-6,251:15)
Block(-6,11,-5,159:15)
Block(-6,11,-4,159:15)
Block(-6,11,-3,159:15)
Block(-6,11,-2,159:15)
Block(-6,11,-1,159:15)
Block(-6,11,0,251:15)
Block(-6,11,1,159:15)
Block(-6,11,2,159:15)
Block(-6,11,3,159:15)
Block(-6,11,4,159:15)
Block(-6,11,5,251:15)
Block(-6,11,6,159:15)
Block(-6,12,-7,251:15)
Block(-6,12,-6,159:15)
Block(-6,12,-5,159:15)
Block(-6,12,-4,251:15)
Block(-6,12,-3,251:15)
Block(-6,12,-2,159:15)
Block(-6,12,-1,251:15)
Block(-6,12,0,251:15)
Block(-6,12,1,159:15)
Block(-6,12,2,159:15)
Block(-6,12,3,159:15)
Block(-6,12,4,251:15)
Block(-6,12,5,159:15)
Block(-6,12,6,159:15)
Block(-6,13,-7,159:15)
Block(-6,13,-6,159:15)
Block(-6,13,-5,159:15)
Block(-6,13,-4,159:15)
Block(-6,13,-3,159:15)
Block(-6,13,-2,251:15)
Block(-6,13,-1,251:15)
Block(-6,13,0,159:15)
Block(-6,13,1,251:15)
Block(-6,13,2,159:15)
Block(-6,13,3,251:15)
Block(-6,13,4,159:15)
Block(-6,13,5,251:15)
Block(-6,13,6,251:15)
Block(-6,14,-7,159:15)
Block(-6,14,-6,251:15)
Block(-6,14,-5,159:15)
Block(-6,14,-4,159:15)
Block(-6,14,-3,251:15)
Block(-6,14,-2,251:15)
Block(-6,14,-1,251:15)
Block(-6,14,0,159:15)
Block(-6,14,1,251:15)
Block(-6,14,2,159:15)
Block(-6,14,3,159:15)
Block(-6,14,4,251:15)
Block(-6,14,5,251:15)
Block(-6,14,6,251:15)
Block(-6,15,-7,251:15)
Block(-6,15,-6,251:15)
Block(-6,15,-5,251:15)
Block(-6,15,-4,159:15)
Block(-6,15,-3,159:15)
Block(-6,15,-2,251:15)
Block(-6,15,-1,159:15)
Block(-6,15,0,251:15)
Block(-6,15,1,159:15)
Block(-6,15,2,251:15)
Block(-6,15,3,251:15)
Block(-6,15,4,251:15)
Block(-6,15,5,251:15)
Block(-6,15,6,251:15)
Block(-6,16,-7,159:15)
Block(-6,16,-6,159:15)
Block(-6,16,-5,159:15)
Block(-6,16,-4,159:15)
Block(-6,16,-3,159:15)
Block(-6,16,-2,159:15)
Block(-6,16,-1,159:15)
Block(-6,16,0,159:15)
Block(-6,16,1,159:15)
Block(-6,16,2,251:15)
Block(-6,16,3,159:15)
Block(-6,16,4,251:15)
Block(-6,16,5,251:15)
Block(-6,16,6,251:15)
Block(-6,17,-7,251:15)
Block(-6,17,-6,251:15)
Block(-6,17,-5,159:15)
Block(-6,17,-4,251:15)
Block(-6,17,-3,251:15)
Block(-6,17,-2,251:15)
Block(-6,17,-1,159:15)
Block(-6,17,0,251:15)
Block(-6,17,1,251:15)
Block(-6,17,2,251:15)
Block(-6,17,3,251:15)
Block(-6,17,4,251:15)
Block(-6,17,5,251:15)
Block(-6,17,6,251:15)
Block(-6,18,-7,251:15)
Block(-6,18,-6,251:15)
Block(-6,18,-5,159:15)
Block(-6,18,-4,251:15)
Block(-6,18,-3,159:15)
Block(-6,18,-2,159:15)
Block(-6,18,-1,251:15)
Block(-6,18,0,159:15)
Block(-6,18,1,159:15)
Block(-6,18,2,251:15)
Block(-6,18,3,251:15)
Block(-6,18,4,159:15)
Block(-6,18,5,251:15)
Block(-6,18,6,251:15)
Block(-6,19,-7,159:15)
Block(-6,19,-6,251:15)
Block(-6,19,-5,251:15)
Block(-6,19,-4,251:15)
Block(-6,19,-3,251:15)
Block(-6,19,-2,159:15)
Block(-6,19,-1,159:15)
Block(-6,19,0,159:15)
Block(-6,19,1,159:15)
Block(-6,19,2,159:15)
Block(-6,19,3,251:15)
Block(-6,19,4,159:15)
Block(-6,19,5,159:15)
Block(-6,19,6,159:15)
Block(-6,20,-7,251:15)
Block(-6,20,-6,159:15)
Block(-6,20,-5,159:15)
Block(-6,20,-4,251:15)
Block(-6,20,-3,159:15)
Block(-6,20,-2,251:15)
Block(-6,20,-1,251:15)
Block(-6,20,0,159:15)
Block(-6,20,1,251:15)
Block(-6,20,2,251:15)
Block(-6,20,3,159:15)
Block(-6,20,4,159:15)
Block(-6,20,5,251:15)
Block(-6,20,6,251:15)
Block(-6,21,-7,251:15)
Block(-6,21,-6,159:15)
Block(-6,21,-5,159:15)
Block(-6,21,-4,251:15)
Block(-6,21,-3,159:15)
Block(-6,21,-2,159:15)
Block(-6,21,-1,251:15)
Block(-6,21,0,251:15)
Block(-6,21,1,159:15)
Block(-6,21,2,251:15)
Block(-6,21,3,159:15)
Block(-6,21,4,159:15)
Block(-6,21,5,159:15)
Block(-6,21,6,159:15)
Block(-6,22,-7,159:15)
Block(-6,22,-6,159:15)
Block(-6,22,-5,251:15)
Block(-6,22,-4,251:15)
Block(-6,22,-3,251:15)
Block(-6,22,-2,159:15)
Block(-6,22,-1,159:15)
Block(-6,22,0,159:15)
Block(-6,22,1,251:15)
Block(-6,22,2,159:15)
Block(-6,22,3,251:15)
Block(-6,22,4,159:15)
Block(-6,22,5,251:15)
Block(-6,22,6,251:15)
Block(-6,23,-7,159:15)
Block(-6,23,-6,159:15)
Block(-6,23,-5,251:15)
Block(-6,23,-4,251:15)
Block(-6,23,-3,251:15)
Block(-6,23,-2,251:15)
Block(-6,23,-1,251:15)
Block(-6,23,0,251:15)
Block(-6,23,1,159:15)
Block(-6,23,2,159:15)
Block(-6,23,3,159:15)
Block(-6,23,4,251:15)
Block(-6,23,5,251:15)
Block(-6,23,6,251:15)
Block(-6,24,-7,251:15)
Block(-6,24,-6,251:15)
Block(-6,24,-5,251:15)
Block(-6,24,-4,251:15)
Block(-6,24,-3,159:15)
Block(-6,24,-2,159:15)
Block(-6,24,-1,159:15)
Block(-6,24,0,251:15)
Block(-6,24,1,251:15)
Block(-6,24,2,251:15)
Block(-6,24,3,159:15)
Block(-6,24,4,251:15)
Block(-6,24,5,251:15)
Block(-6,24,6,159:15)
Block(-6,25,-7,159:15)
Block(-6,25,-6,251:15)
Block(-6,25,-5,251:15)
Block(-6,25,-4,159:15)
Block(-6,25,-3,251:15)
Block(-6,25,-2,159:15)
Block(-6,25,-1,159:15)
Block(-6,25,0,159:15)
Block(-6,25,1,251:15)
Block(-6,25,2,159:15)
Block(-6,25,3,251:15)
Block(-6,25,4,159:15)
Block(-6,25,5,159:15)
Block(-6,25,6,251:15)
Block(-6,26,-7,251:15)
Block(-6,26,-6,251:15)
Block(-6,26,-5,159:15)
Block(-6,26,-4,251:15)
Block(-6,26,-3,159:15)
Block(-6,26,-2,159:15)
Block(-6,26,-1,159:15)
Block(-6,26,0,159:15)
Block(-6,26,1,251:15)
Block(-6,26,2,159:15)
Block(-6,26,3,251:15)
Block(-6,26,4,159:15)
Block(-6,26,5,159:15)
Block(-6,26,6,251:15)
Block(-6,27,-7,251:15)
Block(-6,27,-6,251:15)
Block(-6,27,-5,251:15)
Block(-6,27,-4,159:15)
Block(-6,27,-3,159:15)
Block(-6,27,-2,159:15)
Block(-6,27,-1,251:15)
Block(-6,27,0,159:15)
Block(-6,27,1,159:15)
Block(-6,27,2,251:15)
Block(-6,27,3,251:15)
Block(-6,27,4,159:15)
Block(-6,27,5,159:15)
Block(-6,27,6,251:15)
Block(-6,28,-7,159:15)
Block(-6,28,-6,251:15)
Block(-6,28,-5,159:15)
Block(-6,28,-4,159:15)
Block(-6,28,-3,159:15)
Block(-6,28,-2,159:15)
Block(-6,28,-1,159:15)
Block(-6,28,0,159:15)
Block(-6,28,1,159:15)
Block(-6,28,2,159:15)
Block(-6,28,3,159:15)
Block(-6,28,4,251:15)
Block(-6,28,5,159:15)
Block(-6,28,6,159:15)
Block(-6,29,-7,159:15)
Block(-6,29,-6,251:15)
Block(-6,29,-5,251:15)
Block(-6,29,-4,159:15)
Block(-6,29,-3,251:15)
Block(-6,29,-2,159:15)
Block(-6,29,-1,159:15)
Block(-6,29,0,159:15)
Block(-6,29,1,159:15)
Block(-6,29,2,159:15)
Block(-6,29,3,159:15)
Block(-6,29,4,159:15)
Block(-6,29,5,251:15)
Block(-6,29,6,159:15)
Block(-6,30,-7,251:15)
Block(-6,30,-6,251:15)
Block(-6,30,-5,159:15)
Block(-6,30,-4,251:15)
Block(-6,30,-3,159:15)
Block(-6,30,-2,251:15)
Block(-6,30,-1,251:15)
Block(-6,30,0,251:15)
Block(-6,30,1,159:15)
Block(-6,30,2,159:15)
Block(-6,30,3,251:15)
Block(-6,30,4,159:15)
Block(-6,30,5,159:15)
Block(-6,30,6,159:15)
Block(-6,31,-7,159:15)
Block(-6,31,-6,159:15)
Block(-6,31,-5,159:15)
Block(-6,31,-4,159:15)
Block(-6,31,-3,251:15)
Block(-6,31,-2,159:15)
Block(-6,31,-1,251:15)
Block(-6,31,0,251:15)
Block(-6,31,1,159:15)
Block(-6,31,2,159:15)
Block(-6,31,3,251:15)
Block(-6,31,4,159:15)
Block(-6,31,5,159:15)
Block(-6,31,6,159:15)
Block(-6,32,-7,251:15)
Block(-6,32,-6,251:15)
Block(-6,32,-5,159:15)
Block(-6,32,-4,251:15)
Block(-6,32,-3,159:15)
Block(-6,32,-2,251:15)
Block(-6,32,-1,251:15)
Block(-6,32,0,251:15)
Block(-6,32,1,159:15)
Block(-6,32,2,251:15)
Block(-6,32,3,251:15)
Block(-6,32,4,159:15)
Block(-6,32,5,159:15)
Block(-6,32,6,251:7)
Block(-6,33,-7,251:15)
Block(-6,33,-6,251:15)
Block(-6,33,-5,251:15)
Block(-6,33,-4,159:15)
Block(-6,33,-3,251:15)
Block(-6,33,-2,159:15)
Block(-6,33,-1,251:15)
Block(-6,33,0,251:15)
Block(-6,33,1,251:15)
Block(-6,33,2,159:15)
Block(-6,33,3,159:15)
Block(-6,33,4,159:15)
Block(-6,33,5,251:15)
Block(-6,33,6,251:7)
Block(-6,34,-7,159:15)
Block(-6,34,-6,159:15)
Block(-6,34,-5,159:15)
Block(-6,34,-4,159:15)
Block(-6,34,-3,251:15)
Block(-6,34,-2,159:15)
Block(-6,34,-1,251:15)
Block(-6,34,0,159:15)
Block(-6,34,1,251:15)
Block(-6,34,2,159:15)
Block(-6,34,3,251:15)
Block(-6,34,4,251:15)
Block(-6,34,5,251:15)
Block(-6,34,6,251:7)
Block(-6,35,-7,251:15)
Block(-6,35,-6,159:15)
Block(-6,35,-5,251:15)
Block(-6,35,-4,159:15)
Block(-6,35,-3,159:15)
Block(-6,35,-2,251:15)
Block(-6,35,-1,251:15)
Block(-6,35,0,251:15)
Block(-6,35,1,159:15)
Block(-6,35,2,159:15)
Block(-6,35,3,159:15)
Block(-6,35,4,159:15)
Block(-6,35,5,251:15)
Block(-6,35,6,159:15)
Block(-6,36,-7,159:15)
Block(-6,36,-6,159:15)
Block(-6,36,-5,251:15)
Block(-6,36,-4,251:15)
Block(-6,36,-3,251:15)
Block(-6,36,-2,251:15)
Block(-6,36,-1,251:15)
Block(-6,36,0,251:15)
Block(-6,36,1,159:15)
Block(-6,36,2,159:15)
Block(-6,36,3,251:15)
Block(-6,36,4,251:15)
Block(-6,36,5,159:15)
Block(-6,36,6,251:15)
Block(-6,37,-7,159:15)
Block(-6,37,-6,251:15)
Block(-6,37,-5,159:15)
Block(-6,37,-4,251:15)
Block(-6,37,-3,251:15)
Block(-6,37,-2,159:15)
Block(-6,37,-1,251:15)
Block(-6,37,0,159:15)
Block(-6,37,1,251:15)
Block(-6,37,2,159:15)
Block(-6,37,3,251:15)
Block(-6,37,4,251:15)
Block(-6,37,5,159:15)
Block(-6,37,6,159:15)
Block(-6,38,-7,159:15)
Block(-6,38,-6,159:15)
Block(-6,38,-5,251:15)
Block(-6,38,-4,159:15)
Block(-6,38,-3,251:15)
Block(-6,38,-2,251:15)
Block(-6,38,-1,159:15)
Block(-6,38,0,159:15)
Block(-6,38,1,251:15)
Block(-6,38,2,159:15)
Block(-6,38,3,159:15)
Block(-6,38,4,251:15)
Block(-6,38,5,159:15)
Block(-6,38,6,251:15)
Block(-6,39,-7,159:15)
Block(-6,39,-6,159:15)
Block(-6,39,-5,251:15)
Block(-6,39,-4,159:15)
Block(-6,39,-3,159:15)
Block(-6,39,-2,251:15)
Block(-6,39,-1,159:15)
Block(-6,39,0,251:15)
Block(-6,39,1,251:15)
Block(-6,39,2,251:15)
Block(-6,39,3,159:15)
Block(-6,39,4,251:15)
Block(-6,39,5,251:15)
Block(-6,39,6,159:15)
Block(-6,40,-7,251:15)
Block(-6,40,-6,251:15)
Block(-6,40,-5,251:15)
Block(-6,40,-4,251:15)
Block(-6,40,-3,159:15)
Block(-6,40,-2,251:15)
Block(-6,40,-1,251:15)
Block(-6,40,0,251:15)
Block(-6,40,1,159:15)
Block(-6,40,2,159:15)
Block(-6,40,3,251:15)
Block(-6,40,4,159:15)
Block(-6,40,5,159:15)
Block(-6,40,6,251:15)
Block(-6,41,-7,159:15)
Block(-6,41,-6,159:15)
Block(-6,41,-5,251:15)
Block(-6,41,-4,159:15)
Block(-6,41,-3,251:15)
Block(-6,41,-2,159:15)
Block(-6,41,-1,159:15)
Block(-6,41,0,251:15)
Block(-6,41,1,159:15)
Block(-6,41,2,159:15)
Block(-6,41,3,159:15)
Block(-6,41,4,251:15)
Block(-6,41,5,159:15)
Block(-6,41,6,251:15)
Block(-6,42,-7,251:15)
Block(-6,42,-6,251:15)
Block(-6,42,-5,251:15)
Block(-6,42,-4,251:15)
Block(-6,42,-3,159:15)
Block(-6,42,-2,251:15)
Block(-6,42,-1,159:15)
Block(-6,42,0,159:15)
Block(-6,42,1,251:15)
Block(-6,42,2,251:15)
Block(-6,42,3,159:15)
Block(-6,42,4,159:15)
Block(-6,42,5,159:15)
Block(-6,42,6,159:15)
Block(-6,43,-7,251:15)
Block(-6,43,-6,159:15)
Block(-6,43,-5,159:15)
Block(-6,43,-4,159:15)
Block(-6,43,-3,159:15)
Block(-6,43,-2,251:15)
Block(-6,43,-1,251:15)
Block(-6,43,0,251:15)
Block(-6,43,1,251:15)
Block(-6,43,2,159:15)
Block(-6,43,3,251:15)
Block(-6,43,4,251:15)
Block(-6,43,5,159:15)
Block(-6,43,6,159:15)
Block(-6,44,-7,251:15)
Block(-6,44,-6,159:15)
Block(-6,44,-5,251:15)
Block(-6,44,-4,159:15)
Block(-6,44,-3,251:15)
Block(-6,44,-2,159:15)
Block(-6,44,-1,159:15)
Block(-6,44,0,251:15)
Block(-6,44,1,251:15)
Block(-6,44,2,251:15)
Block(-6,44,3,251:15)
Block(-6,44,4,251:15)
Block(-6,44,5,251:15)
Block(-6,44,6,251:15)
Block(-6,45,-7,251:15)
Block(-6,45,-6,159:15)
Block(-6,45,-5,251:15)
Block(-6,45,-4,251:15)
Block(-6,45,-3,159:15)
Block(-6,45,-2,251:15)
Block(-6,45,-1,251:15)
Block(-6,45,0,159:15)
Block(-6,45,1,251:15)
Block(-6,45,2,159:15)
Block(-6,45,3,159:15)
Block(-6,45,4,159:15)
Block(-6,45,5,251:15)
Block(-6,45,6,251:15)
Block(-6,46,-7,159:15)
Block(-6,46,-6,159:15)
Block(-6,46,-5,251:15)
Block(-6,46,-4,159:15)
Block(-6,46,-3,251:15)
Block(-6,46,-2,159:15)
Block(-6,46,-1,159:15)
Block(-6,46,0,159:15)
Block(-6,46,1,251:15)
Block(-6,46,2,251:15)
Block(-6,46,3,251:15)
Block(-6,46,4,251:15)
Block(-6,46,5,159:15)
Block(-6,46,6,251:15)
Block(-6,47,-7,251:15)
Block(-6,47,-6,159:15)
Block(-6,47,-5,251:15)
Block(-6,47,-4,251:15)
Block(-6,47,-3,251:15)
Block(-6,47,-2,159:15)
Block(-6,47,-1,159:15)
Block(-6,47,0,159:15)
Block(-6,47,1,251:15)
Block(-6,47,2,251:15)
Block(-6,47,3,159:15)
Block(-6,47,4,251:15)
Block(-6,47,5,159:15)
Block(-6,47,6,251:15)
Block(-6,48,-7,251:15)
Block(-6,48,-6,159:15)
Block(-6,48,-5,251:15)
Block(-6,48,-4,251:15)
Block(-6,48,-3,251:15)
Block(-6,48,-2,159:15)
Block(-6,48,-1,159:15)
Block(-6,48,0,159:15)
Block(-6,48,1,159:15)
Block(-6,48,2,159:15)
Block(-6,48,3,251:15)
Block(-6,48,4,251:15)
Block(-6,48,5,159:15)
Block(-6,48,6,251:15)
Block(-6,49,-7,251:15)
Block(-6,49,-6,251:15)
Block(-6,49,-5,159:15)
Block(-6,49,-4,251:15)
Block(-6,49,-3,159:15)
Block(-6,49,-2,159:15)
Block(-6,49,-1,251:15)
Block(-6,49,0,251:15)
Block(-6,49,1,159:15)
Block(-6,49,2,159:15)
Block(-6,49,3,251:15)
Block(-6,49,4,159:15)
Block(-6,49,5,159:15)
Block(-6,49,6,251:15)
Block(-6,50,-7,251:15)
Block(-6,50,-6,159:15)
Block(-6,50,-5,159:15)
Block(-6,50,-4,251:15)
Block(-6,50,-3,251:15)
Block(-6,50,-2,251:15)
Block(-6,50,-1,251:15)
Block(-6,50,0,251:15)
Block(-6,50,1,159:15)
Block(-6,50,2,251:15)
Block(-6,50,3,159:15)
Block(-6,50,4,251:15)
Block(-6,50,5,159:15)
Block(-6,50,6,251:15)
Block(-6,51,-7,251:15)
Block(-6,51,-6,159:15)
Block(-6,51,-5,251:15)
Block(-6,51,-4,251:15)
Block(-6,51,-3,251:15)
Block(-6,51,-2,251:15)
Block(-6,51,-1,159:15)
Block(-6,51,0,251:15)
Block(-6,51,1,159:15)
Block(-6,51,2,159:15)
Block(-6,51,3,159:15)
Block(-6,51,4,159:15)
Block(-6,51,5,159:15)
Block(-6,51,6,159:15)
Block(-6,52,-7,251:15)
Block(-6,52,-6,159:15)
Block(-6,52,-5,251:15)
Block(-6,52,-4,159:15)
Block(-6,52,-3,251:15)
Block(-6,52,-2,251:15)
Block(-6,52,-1,251:15)
Block(-6,52,0,251:15)
Block(-6,52,1,251:15)
Block(-6,52,2,159:15)
Block(-6,52,3,159:15)
Block(-6,52,4,251:15)
Block(-6,52,5,159:15)
Block(-6,52,6,159:15)
Block(-6,53,-7,251:15)
Block(-6,53,-6,159:15)
Block(-6,53,-5,159:15)
Block(-6,53,-4,251:15)
Block(-6,53,-3,159:15)
Block(-6,53,-2,159:15)
Block(-6,53,-1,159:15)
Block(-6,53,0,159:15)
Block(-6,53,1,159:15)
Block(-6,53,2,159:15)
Block(-6,53,3,251:15)
Block(-6,53,4,159:15)
Block(-6,53,5,251:15)
Block(-6,53,6,251:15)
Block(-6,54,-7,159:15)
Block(-6,54,-6,251:15)
Block(-6,54,-5,251:15)
Block(-6,54,-4,251:15)
Block(-6,54,-3,251:15)
Block(-6,54,-2,251:15)
Block(-6,54,-1,251:15)
Block(-6,54,0,251:15)
Block(-6,54,1,251:15)
Block(-6,54,2,159:15)
Block(-6,54,3,251:15)
Block(-6,54,4,159:15)
Block(-6,54,5,159:15)
Block(-6,54,6,251:15)
Block(-6,55,-7,251:15)
Block(-6,55,-6,251:15)
Block(-6,55,-5,159:15)
Block(-6,55,-4,159:15)
Block(-6,55,-3,159:15)
Block(-6,55,-2,159:15)
Block(-6,55,-1,251:15)
Block(-6,55,0,159:15)
Block(-6,55,1,159:15)
Block(-6,55,2,159:15)
Block(-6,55,3,159:15)
Block(-6,55,4,251:15)
Block(-6,55,5,159:15)
Block(-6,55,6,159:15)
Block(-6,56,-7,159:15)
Block(-6,56,-6,251:15)
Block(-6,56,-5,251:15)
Block(-6,56,-4,251:15)
Block(-6,56,-3,251:15)
Block(-6,56,-2,251:15)
Block(-6,56,-1,159:15)
Block(-6,56,0,251:15)
Block(-6,56,1,251:15)
Block(-6,56,2,159:15)
Block(-6,56,3,251:15)
Block(-6,56,4,159:15)
Block(-6,56,5,251:15)
Block(-6,56,6,251:15)
Block(-6,57,-7,251:15)
Block(-6,57,-6,159:15)
Block(-6,57,-5,159:15)
Block(-6,57,-4,251:15)
Block(-6,57,-3,159:15)
Block(-6,57,-2,251:15)
Block(-6,57,-1,251:15)
Block(-6,57,0,251:15)
Block(-6,57,1,159:15)
Block(-6,57,2,251:15)
Block(-6,57,3,159:15)
Block(-6,57,4,159:15)
Block(-6,57,5,251:15)
Block(-6,57,6,251:15)
Block(-6,58,-7,159:15)
Block(-6,58,-6,251:15)
Block(-6,58,-5,159:15)
Block(-6,58,-4,251:15)
Block(-6,58,-3,159:15)
Block(-6,58,-2,159:15)
Block(-6,58,-1,159:15)
Block(-6,58,0,251:15)
Block(-6,58,1,159:15)
Block(-6,58,2,251:15)
Block(-6,58,3,251:15)
Block(-6,58,4,251:15)
Block(-6,58,5,159:15)
Block(-6,58,6,159:15)
Block(-6,59,-7,159:15)
Block(-6,59,-6,251:15)
Block(-6,59,-5,251:15)
Block(-6,59,-4,2)
Block(-6,59,-3,251:15)
Block(-6,59,-2,251:15)
Block(-6,59,-1,159:15)
Block(-6,59,0,3:1)
Block(-6,59,1,159:15)
Block(-6,59,2,159:15)
Block(-6,59,3,159:15)
Block(-6,59,4,159:15)
Block(-6,59,5,159:15)
Block(-6,59,6,159:15)
Block(-5,0,-7,159:15)
Block(-5,0,-6,251:15)
Block(-5,0,-5,159:15)
Block(-5,0,-4,159:15)
Block(-5,0,-3,159:15)
Block(-5,0,-2,251:15)
Block(-5,0,-1,159:15)
Block(-5,0,0,159:15)
Block(-5,0,1,159:15)
Block(-5,0,2,159:15)
Block(-5,0,3,251:15)
Block(-5,0,4,251:15)
Block(-5,0,5,251:15)
Block(-5,0,6,159:15)
Block(-5,1,-7,251:15)
Block(-5,1,-6,159:15)
Block(-5,1,-5,251:15)
Block(-5,1,-4,251:15)
Block(-5,1,-3,251:15)
Block(-5,1,-2,159:15)
Block(-5,1,-1,159:15)
Block(-5,1,0,159:15)
Block(-5,1,1,159:15)
Block(-5,1,2,159:15)
Block(-5,1,3,159:15)
Block(-5,1,4,159:15)
Block(-5,1,5,251:15)
Block(-5,1,6,251:15)
Block(-5,2,-7,251:15)
Block(-5,2,-6,159:15)
Block(-5,2,-5,159:15)
Block(-5,2,-4,251:15)
Block(-5,2,-3,251:15)
Block(-5,2,-2,251:15)
Block(-5,2,-1,159:15)
Block(-5,2,0,251:15)
Block(-5,2,1,159:15)
Block(-5,2,2,159:15)
Block(-5,2,3,251:15)
Block(-5,2,4,159:15)
Block(-5,2,5,159:15)
Block(-5,2,6,159:15)
Block(-5,3,-7,251:15)
Block(-5,3,-6,159:15)
Block(-5,3,-5,251:15)
Block(-5,3,-4,159:15)
Block(-5,3,-3,159:15)
Block(-5,3,-2,251:15)
Block(-5,3,-1,251:15)
Block(-5,3,0,251:15)
Block(-5,3,1,251:15)
Block(-5,3,2,159:15)
Block(-5,3,3,159:15)
Block(-5,3,4,159:15)
Block(-5,3,5,159:15)
Block(-5,3,6,251:15)
Block(-5,4,-7,251:15)
Block(-5,4,-6,159:15)
Block(-5,4,-5,251:15)
Block(-5,4,-4,251:15)
Block(-5,4,-3,159:15)
Block(-5,4,-2,159:15)
Block(-5,4,-1,251:15)
Block(-5,4,0,159:15)
Block(-5,4,1,159:15)
Block(-5,4,2,159:15)
Block(-5,4,3,159:15)
Block(-5,4,4,251:15)
Block(-5,4,5,159:15)
Block(-5,4,6,159:15)
Block(-5,5,-7,251:15)
Block(-5,5,-6,159:15)
Block(-5,5,-5,251:15)
Block(-5,5,-4,251:15)
Block(-5,5,-3,159:15)
Block(-5,5,-2,251:15)
Block(-5,5,-1,159:15)
Block(-5,5,0,159:15)
Block(-5,5,1,159:15)
Block(-5,5,2,251:15)
Block(-5,5,3,251:15)
Block(-5,5,4,159:15)
Block(-5,5,5,251:15)
Block(-5,5,6,251:15)
Block(-5,6,-7,159:15)
Block(-5,6,-6,251:15)
Block(-5,6,-5,251:15)
Block(-5,6,-4,159:15)
Block(-5,6,-3,251:15)
Block(-5,6,-2,159:15)
Block(-5,6,-1,159:15)
Block(-5,6,0,159:15)
Block(-5,6,1,251:15)
Block(-5,6,2,159:15)
Block(-5,6,3,159:15)
Block(-5,6,4,159:15)
Block(-5,6,5,159:15)
Block(-5,6,6,159:15)
Block(-5,7,-7,159:15)
Block(-5,7,-6,159:15)
Block(-5,7,-5,159:15)
Block(-5,7,-4,159:15)
Block(-5,7,-3,251:15)
Block(-5,7,-2,159:15)
Block(-5,7,-1,159:15)
Block(-5,7,0,251:15)
Block(-5,7,1,251:15)
Block(-5,7,2,251:15)
Block(-5,7,3,159:15)
Block(-5,7,4,251:15)
Block(-5,7,5,159:15)
Block(-5,7,6,159:15)
Block(-5,8,-7,159:15)
Block(-5,8,-6,159:15)
Block(-5,8,-5,251:15)
Block(-5,8,-4,159:15)
Block(-5,8,-3,159:15)
Block(-5,8,-2,251:15)
Block(-5,8,-1,251:15)
Block(-5,8,0,159:15)
Block(-5,8,1,251:15)
Block(-5,8,2,251:15)
Block(-5,8,3,251:15)
Block(-5,8,4,251:15)
Block(-5,8,5,251:15)
Block(-5,8,6,159:15)
Block(-5,9,-7,251:15)
Block(-5,9,-6,251:15)
Block(-5,9,-5,251:15)
Block(-5,9,-4,159:15)
Block(-5,9,-3,251:15)
Block(-5,9,-2,159:15)
Block(-5,9,-1,251:15)
Block(-5,9,0,159:15)
Block(-5,9,1,251:15)
Block(-5,9,2,159:15)
Block(-5,9,3,251:15)
Block(-5,9,4,159:15)
Block(-5,9,5,159:15)
Block(-5,9,6,159:15)
Block(-5,10,-7,251:15)
Block(-5,10,-6,159:15)
Block(-5,10,-5,159:15)
Block(-5,10,-4,251:15)
Block(-5,10,-3,251:15)
Block(-5,10,-2,251:15)
Block(-5,10,-1,159:15)
Block(-5,10,0,251:15)
Block(-5,10,1,251:15)
Block(-5,10,2,159:15)
Block(-5,10,3,159:15)
Block(-5,10,4,159:15)
Block(-5,10,5,251:15)
Block(-5,10,6,251:15)
Block(-5,11,-7,159:15)
Block(-5,11,-6,251:15)
Block(-5,11,-5,159:15)
Block(-5,11,-4,251:15)
Block(-5,11,-3,159:15)
Block(-5,11,-2,159:15)
Block(-5,11,-1,251:15)
Block(-5,11,0,159:15)
Block(-5,11,1,159:15)
Block(-5,11,2,159:15)
Block(-5,11,3,159:15)
Block(-5,11,4,251:15)
Block(-5,11,5,251:15)
Block(-5,11,6,159:15)
Block(-5,12,-7,251:15)
Block(-5,12,-6,159:15)
Block(-5,12,-5,251:15)
Block(-5,12,-4,251:15)
Block(-5,12,-3,159:15)
Block(-5,12,-2,251:15)
Block(-5,12,-1,159:15)
Block(-5,12,0,159:15)
Block(-5,12,1,159:15)
Block(-5,12,2,159:15)
Block(-5,12,3,251:15)
Block(-5,12,4,251:15)
Block(-5,12,5,251:15)
Block(-5,12,6,159:15)
Block(-5,13,-7,159:15)
Block(-5,13,-6,251:15)
Block(-5,13,-5,251:15)
Block(-5,13,-4,159:15)
Block(-5,13,-3,159:15)
Block(-5,13,-2,159:15)
Block(-5,13,-1,159:15)
Block(-5,13,0,159:15)
Block(-5,13,1,251:15)
Block(-5,13,2,251:15)
Block(-5,13,3,251:15)
Block(-5,13,4,251:15)
Block(-5,13,5,159:15)
Block(-5,13,6,251:15)
Block(-5,14,-7,159:15)
Block(-5,14,-6,251:15)
Block(-5,14,-5,251:15)
Block(-5,14,-4,159:15)
Block(-5,14,-3,159:15)
Block(-5,14,-2,251:15)
Block(-5,14,-1,251:15)
Block(-5,14,0,251:15)
Block(-5,14,1,159:15)
Block(-5,14,2,251:15)
Block(-5,14,3,251:15)
Block(-5,14,4,251:15)
Block(-5,14,5,159:15)
Block(-5,14,6,251:15)
Block(-5,15,-7,159:15)
Block(-5,15,-6,251:15)
Block(-5,15,-5,251:15)
Block(-5,15,-4,159:15)
Block(-5,15,-3,251:15)
Block(-5,15,-2,251:15)
Block(-5,15,-1,251:15)
Block(-5,15,0,159:15)
Block(-5,15,1,251:15)
Block(-5,15,2,159:15)
Block(-5,15,3,251:15)
Block(-5,15,4,159:15)
Block(-5,15,5,159:15)
Block(-5,15,6,251:15)
Block(-5,16,-7,159:15)
Block(-5,16,-6,159:15)
Block(-5,16,-5,159:15)
Block(-5,16,-4,251:15)
Block(-5,16,-3,159:15)
Block(-5,16,-2,251:15)
Block(-5,16,-1,159:15)
Block(-5,16,0,251:15)
Block(-5,16,1,159:15)
Block(-5,16,2,159:15)
Block(-5,16,3,251:15)
Block(-5,16,4,159:15)
Block(-5,16,5,159:15)
Block(-5,16,6,251:15)
Block(-5,17,-7,251:15)
Block(-5,17,-6,251:15)
Block(-5,17,-5,159:15)
Block(-5,17,-4,159:15)
Block(-5,17,-3,159:15)
Block(-5,17,-2,251:15)
Block(-5,17,-1,251:15)
Block(-5,17,0,251:15)
Block(-5,17,1,251:15)
Block(-5,17,2,251:15)
Block(-5,17,3,251:15)
Block(-5,17,4,251:15)
Block(-5,17,5,251:15)
Block(-5,17,6,251:15)
Block(-5,18,-7,251:15)
Block(-5,18,-6,159:15)
Block(-5,18,-5,251:15)
Block(-5,18,-4,159:15)
Block(-5,18,-3,251:15)
Block(-5,18,-2,251:15)
Block(-5,18,-1,251:15)
Block(-5,18,0,251:15)
Block(-5,18,1,251:15)
Block(-5,18,2,251:15)
Block(-5,18,3,159:15)
Block(-5,18,4,251:15)
Block(-5,18,5,159:15)
Block(-5,18,6,159:15)
Block(-5,19,-7,251:15)
Block(-5,19,-6,251:15)
Block(-5,19,-5,251:15)
Block(-5,19,-4,159:15)
Block(-5,19,-3,159:15)
Block(-5,19,-2,251:15)
Block(-5,19,-1,159:15)
Block(-5,19,0,251:15)
Block(-5,19,1,159:15)
Block(-5,19,2,159:15)
Block(-5,19,3,159:15)
Block(-5,19,4,251:15)
Block(-5,19,5,251:15)
Block(-5,19,6,159:15)
Block(-5,20,-7,159:15)
Block(-5,20,-6,159:15)
Block(-5,20,-5,159:15)
Block(-5,20,-4,159:15)
Block(-5,20,-3,251:15)
Block(-5,20,-2,251:15)
Block(-5,20,-1,159:15)
Block(-5,20,0,251:15)
Block(-5,20,1,251:15)
Block(-5,20,2,251:15)
Block(-5,20,3,251:15)
Block(-5,20,4,159:15)
Block(-5,20,5,159:15)
Block(-5,20,6,159:15)
Block(-5,21,-7,159:15)
Block(-5,21,-6,251:15)
Block(-5,21,-5,159:15)
Block(-5,21,-4,251:15)
Block(-5,21,-3,251:15)
Block(-5,21,-2,159:15)
Block(-5,21,-1,159:15)
Block(-5,21,0,251:15)
Block(-5,21,1,159:15)
Block(-5,21,2,251:15)
Block(-5,21,3,251:15)
Block(-5,21,4,251:15)
Block(-5,21,5,251:15)
Block(-5,21,6,159:15)
Block(-5,22,-7,251:15)
Block(-5,22,-6,159:15)
Block(-5,22,-5,251:15)
Block(-5,22,-4,251:15)
Block(-5,22,-3,159:15)
Block(-5,22,-2,159:15)
Block(-5,22,-1,251:15)
Block(-5,22,0,159:15)
Block(-5,22,1,251:15)
Block(-5,22,2,159:15)
Block(-5,22,3,159:15)
Block(-5,22,4,159:15)
Block(-5,22,5,251:15)
Block(-5,22,6,251:15)
Block(-5,23,-7,251:15)
Block(-5,23,-6,251:15)
Block(-5,23,-5,159:15)
Block(-5,23,-4,159:15)
Block(-5,23,-3,159:15)
Block(-5,23,-2,159:15)
Block(-5,23,-1,251:15)
Block(-5,23,0,159:15)
Block(-5,23,1,159:15)
Block(-5,23,2,159:15)
Block(-5,23,3,251:15)
Block(-5,23,4,251:15)
Block(-5,23,5,159:15)
Block(-5,23,6,251:15)
Block(-5,24,-7,251:15)
Block(-5,24,-6,251:15)
Block(-5,24,-5,251:15)
Block(-5,24,-4,251:15)
Block(-5,24,-3,159:15)
Block(-5,24,-2,251:15)
Block(-5,24,-1,251:15)
Block(-5,24,0,251:15)
Block(-5,24,1,251:15)
Block(-5,24,2,251:15)
Block(-5,24,3,159:15)
Block(-5,24,4,159:15)
Block(-5,24,5,159:15)
Block(-5,24,6,251:15)
Block(-5,25,-7,251:15)
Block(-5,25,-6,251:15)
Block(-5,25,-5,251:15)
Block(-5,25,-4,159:15)
Block(-5,25,-3,159:15)
Block(-5,25,-2,251:15)
Block(-5,25,-1,251:15)
Block(-5,25,0,251:15)
Block(-5,25,1,159:15)
Block(-5,25,2,159:15)
Block(-5,25,3,159:15)
Block(-5,25,4,251:15)
Block(-5,25,5,251:15)
Block(-5,25,6,251:15)
Block(-5,26,-7,159:15)
Block(-5,26,-6,159:15)
Block(-5,26,-5,159:15)
Block(-5,26,-4,251:15)
Block(-5,26,-3,251:15)
Block(-5,26,-2,159:15)
Block(-5,26,-1,159:15)
Block(-5,26,0,251:15)
Block(-5,26,1,159:15)
Block(-5,26,2,251:15)
Block(-5,26,3,159:15)
Block(-5,26,4,251:15)
Block(-5,26,5,251:15)
Block(-5,26,6,251:15)
Block(-5,27,-7,251:15)
Block(-5,27,-6,159:15)
Block(-5,27,-5,251:15)
Block(-5,27,-4,251:15)
Block(-5,27,-3,251:15)
Block(-5,27,-2,159:15)
Block(-5,27,-1,251:15)
Block(-5,27,0,251:15)
Block(-5,27,1,251:15)
Block(-5,27,2,251:15)
Block(-5,27,3,251:15)
Block(-5,27,4,251:15)
Block(-5,27,5,251:15)
Block(-5,27,6,159:15)
Block(-5,28,-7,251:15)
Block(-5,28,-6,159:15)
Block(-5,28,-5,159:15)
Block(-5,28,-4,159:15)
Block(-5,28,-3,251:15)
Block(-5,28,-2,159:15)
Block(-5,28,-1,251:15)
Block(-5,28,0,159:15)
Block(-5,28,1,251:15)
Block(-5,28,2,251:15)
Block(-5,28,3,251:15)
Block(-5,28,4,159:15)
Block(-5,28,5,159:15)
Block(-5,28,6,159:15)
Block(-5,29,-7,159:15)
Block(-5,29,-6,251:15)
Block(-5,29,-5,159:15)
Block(-5,29,-4,159:15)
Block(-5,29,-3,251:15)
Block(-5,29,-2,159:15)
Block(-5,29,-1,159:15)
Block(-5,29,0,159:15)
Block(-5,29,1,251:15)
Block(-5,29,2,159:15)
Block(-5,29,3,251:15)
Block(-5,29,4,159:15)
Block(-5,29,5,159:15)
Block(-5,29,6,159:15)
Block(-5,30,-7,159:15)
Block(-5,30,-6,159:15)
Block(-5,30,-5,159:15)
Block(-5,30,-4,159:15)
Block(-5,30,-3,251:15)
Block(-5,30,-2,251:15)
Block(-5,30,-1,159:15)
Block(-5,30,0,159:15)
Block(-5,30,1,251:15)
Block(-5,30,2,251:15)
Block(-5,30,3,251:15)
Block(-5,30,4,159:15)
Block(-5,30,5,251:15)
Block(-5,30,6,251:15)
Block(-5,31,-7,159:15)
Block(-5,31,-6,251:15)
Block(-5,31,-5,251:15)
Block(-5,31,-4,251:15)
Block(-5,31,-3,159:15)
Block(-5,31,-2,251:15)
Block(-5,31,-1,251:15)
Block(-5,31,0,159:15)
Block(-5,31,1,251:15)
Block(-5,31,2,251:15)
Block(-5,31,3,159:15)
Block(-5,31,4,159:15)
Block(-5,31,5,251:15)
Block(-5,31,6,251:15)
Block(-5,32,-7,159:15)
Block(-5,32,-6,251:15)
Block(-5,32,-5,251:15)
Block(-5,32,-4,159:15)
Block(-5,32,-3,159:15)
Block(-5,32,-2,159:15)
Block(-5,32,-1,251:15)
Block(-5,32,0,251:15)
Block(-5,32,1,159:15)
Block(-5,32,2,159:15)
Block(-5,32,3,251:15)
Block(-5,32,4,159:15)
Block(-5,32,5,251:15)
Block(-5,32,6,251:7)
Block(-5,33,-7,251:15)
Block(-5,33,-6,159:15)
Block(-5,33,-5,159:15)
Block(-5,33,-4,251:15)
Block(-5,33,-3,159:15)
Block(-5,33,-2,159:15)
Block(-5,33,-1,251:15)
Block(-5,33,0,159:15)
Block(-5,33,1,159:15)
Block(-5,33,2,251:15)
Block(-5,33,3,251:15)
Block(-5,33,4,251:15)
Block(-5,33,5,251:15)
Block(-5,33,6,251:7)
Block(-5,34,-7,159:15)
Block(-5,34,-6,251:15)
Block(-5,34,-5,251:15)
Block(-5,34,-4,159:15)
Block(-5,34,-3,159:15)
Block(-5,34,-2,251:15)
Block(-5,34,-1,251:15)
Block(-5,34,0,159:15)
Block(-5,34,1,251:15)
Block(-5,34,2,159:15)
Block(-5,34,3,251:15)
Block(-5,34,4,159:15)
Block(-5,34,5,159:15)
Block(-5,34,6,251:15)
Block(-5,35,-7,251:15)
Block(-5,35,-6,159:15)
Block(-5,35,-5,159:15)
Block(-5,35,-4,159:15)
Block(-5,35,-3,159:15)
Block(-5,35,-2,251:15)
Block(-5,35,-1,159:15)
Block(-5,35,0,159:15)
Block(-5,35,1,251:15)
Block(-5,35,2,251:15)
Block(-5,35,3,251:15)
Block(-5,35,4,251:15)
Block(-5,35,5,159:15)
Block(-5,35,6,159:15)
Block(-5,36,-7,159:15)
Block(-5,36,-6,251:15)
Block(-5,36,-5,251:15)
Block(-5,36,-4,251:15)
Block(-5,36,-3,159:15)
Block(-5,36,-2,159:15)
Block(-5,36,-1,251:15)
Block(-5,36,0,159:15)
Block(-5,36,1,159:15)
Block(-5,36,2,251:15)
Block(-5,36,3,251:15)
Block(-5,36,4,159:15)
Block(-5,36,5,251:15)
Block(-5,36,6,159:15)
Block(-5,37,-7,159:15)
Block(-5,37,-6,159:15)
Block(-5,37,-5,159:15)
Block(-5,37,-4,251:15)
Block(-5,37,-3,251:15)
Block(-5,37,-2,159:15)
Block(-5,37,-1,159:15)
Block(-5,37,0,159:15)
Block(-5,37,1,251:15)
Block(-5,37,2,251:15)
Block(-5,37,3,159:15)
Block(-5,37,4,159:15)
Block(-5,37,5,159:15)
Block(-5,37,6,159:15)
Block(-5,38,-7,159:15)
Block(-5,38,-6,251:15)
Block(-5,38,-5,159:15)
Block(-5,38,-4,159:15)
Block(-5,38,-3,159:15)
Block(-5,38,-2,159:15)
Block(-5,38,-1,159:15)
Block(-5,38,0,159:15)
Block(-5,38,1,251:15)
Block(-5,38,2,159:15)
Block(-5,38,3,159:15)
Block(-5,38,4,251:15)
Block(-5,38,5,159:15)
Block(-5,38,6,251:15)
Block(-5,39,-7,251:15)
Block(-5,39,-6,159:15)
Block(-5,39,-5,251:15)
Block(-5,39,-4,251:15)
Block(-5,39,-3,251:15)
Block(-5,39,-2,251:15)
Block(-5,39,-1,159:15)
Block(-5,39,0,251:15)
Block(-5,39,1,159:15)
Block(-5,39,2,159:15)
Block(-5,39,3,251:15)
Block(-5,39,4,251:15)
Block(-5,39,5,159:15)
Block(-5,39,6,251:15)
Block(-5,40,-7,251:15)
Block(-5,40,-6,159:15)
Block(-5,40,-5,251:15)
Block(-5,40,-4,251:15)
Block(-5,40,-3,159:15)
Block(-5,40,-2,251:15)
Block(-5,40,-1,251:15)
Block(-5,40,0,251:15)
Block(-5,40,1,251:15)
Block(-5,40,2,159:15)
Block(-5,40,3,251:15)
Block(-5,40,4,251:15)
Block(-5,40,5,251:15)
Block(-5,40,6,159:15)
Block(-5,41,-7,251:15)
Block(-5,41,-6,251:15)
Block(-5,41,-5,251:15)
Block(-5,41,-4,159:15)
Block(-5,41,-3,159:15)
Block(-5,41,-2,251:15)
Block(-5,41,-1,159:15)
Block(-5,41,0,251:15)
Block(-5,41,1,159:15)
Block(-5,41,2,159:15)
Block(-5,41,3,159:15)
Block(-5,41,4,159:15)
Block(-5,41,5,251:15)
Block(-5,41,6,251:15)
Block(-5,42,-7,251:15)
Block(-5,42,-6,159:15)
Block(-5,42,-5,251:15)
Block(-5,42,-4,159:15)
Block(-5,42,-3,251:15)
Block(-5,42,-2,251:15)
Block(-5,42,-1,159:15)
Block(-5,42,0,251:15)
Block(-5,42,1,251:15)
Block(-5,42,2,159:15)
Block(-5,42,3,159:15)
Block(-5,42,4,251:15)
Block(-5,42,5,251:15)
Block(-5,42,6,159:15)
Block(-5,43,-7,251:15)
Block(-5,43,-6,251:15)
Block(-5,43,-5,251:15)
Block(-5,43,-4,251:15)
Block(-5,43,-3,251:15)
Block(-5,43,-2,159:15)
Block(-5,43,-1,159:15)
Block(-5,43,0,159:15)
Block(-5,43,1,251:15)
Block(-5,43,2,159:15)
Block(-5,43,3,251:15)
Block(-5,43,4,251:15)
Block(-5,43,5,251:15)
Block(-5,43,6,251:15)
Block(-5,44,-7,159:15)
Block(-5,44,-6,159:15)
Block(-5,44,-5,159:15)
Block(-5,44,-4,159:15)
Block(-5,44,-3,251:15)
Block(-5,44,-2,159:15)
Block(-5,44,-1,159:15)
Block(-5,44,0,251:15)
Block(-5,44,1,251:15)
Block(-5,44,2,251:15)
Block(-5,44,3,251:15)
Block(-5,44,4,251:15)
Block(-5,44,5,251:15)
Block(-5,44,6,251:15)
Block(-5,45,-7,159:15)
Block(-5,45,-6,159:15)
Block(-5,45,-5,251:15)
Block(-5,45,-4,159:15)
Block(-5,45,-3,251:15)
Block(-5,45,-2,251:15)
Block(-5,45,-1,159:15)
Block(-5,45,0,251:15)
Block(-5,45,1,251:15)
Block(-5,45,2,159:15)
Block(-5,45,3,251:15)
Block(-5,45,4,159:15)
Block(-5,45,5,251:15)
Block(-5,45,6,251:15)
Block(-5,46,-7,251:15)
Block(-5,46,-6,159:15)
Block(-5,46,-5,251:15)
Block(-5,46,-4,251:15)
Block(-5,46,-3,159:15)
Block(-5,46,-2,251:15)
Block(-5,46,-1,251:15)
Block(-5,46,0,159:15)
Block(-5,46,1,251:15)
Block(-5,46,2,159:15)
Block(-5,46,3,159:15)
Block(-5,46,4,159:15)
Block(-5,46,5,159:15)
Block(-5,46,6,251:15)
Block(-5,47,-7,251:15)
Block(-5,47,-6,251:15)
Block(-5,47,-5,159:15)
Block(-5,47,-4,159:15)
Block(-5,47,-3,159:15)
Block(-5,47,-2,251:15)
Block(-5,47,-1,159:15)
Block(-5,47,0,251:15)
Block(-5,47,1,159:15)
Block(-5,47,2,159:15)
Block(-5,47,3,159:15)
Block(-5,47,4,251:15)
Block(-5,47,5,251:15)
Block(-5,47,6,159:15)
Block(-5,48,-7,159:15)
Block(-5,48,-6,251:15)
Block(-5,48,-5,159:15)
Block(-5,48,-4,159:15)
Block(-5,48,-3,251:15)
Block(-5,48,-2,251:15)
Block(-5,48,-1,251:15)
Block(-5,48,0,251:15)
Block(-5,48,1,251:15)
Block(-5,48,2,251:15)
Block(-5,48,3,159:15)
Block(-5,48,4,159:15)
Block(-5,48,5,159:15)
Block(-5,48,6,251:15)
Block(-5,49,-7,251:15)
Block(-5,49,-6,159:15)
Block(-5,49,-5,251:15)
Block(-5,49,-4,251:15)
Block(-5,49,-3,159:15)
Block(-5,49,-2,251:15)
Block(-5,49,-1,159:15)
Block(-5,49,0,251:15)
Block(-5,49,1,251:15)
Block(-5,49,2,251:15)
Block(-5,49,3,159:15)
Block(-5,49,4,159:15)
Block(-5,49,5,159:15)
Block(-5,49,6,159:15)
Block(-5,50,-7,159:15)
Block(-5,50,-6,159:15)
Block(-5,50,-5,159:15)
Block(-5,50,-4,251:15)
Block(-5,50,-3,159:15)
Block(-5,50,-2,251:15)
Block(-5,50,-1,251:15)
Block(-5,50,0,159:15)
Block(-5,50,1,159:15)
Block(-5,50,2,251:15)
Block(-5,50,3,159:15)
Block(-5,50,4,251:15)
Block(-5,50,5,159:15)
Block(-5,50,6,251:15)
Block(-5,51,-7,159:15)
Block(-5,51,-6,159:15)
Block(-5,51,-5,159:15)
Block(-5,51,-4,251:15)
Block(-5,51,-3,159:15)
Block(-5,51,-2,159:15)
Block(-5,51,-1,251:15)
Block(-5,51,0,159:15)
Block(-5,51,1,159:15)
Block(-5,51,2,251:15)
Block(-5,51,3,159:15)
Block(-5,51,4,251:15)
Block(-5,51,5,159:15)
Block(-5,51,6,159:15)
Block(-5,52,-7,251:15)
Block(-5,52,-6,159:15)
Block(-5,52,-5,159:15)
Block(-5,52,-4,159:15)
Block(-5,52,-3,159:15)
Block(-5,52,-2,159:15)
Block(-5,52,-1,159:15)
Block(-5,52,0,251:15)
Block(-5,52,1,251:15)
Block(-5,52,2,159:15)
Block(-5,52,3,251:15)
Block(-5,52,4,251:15)
Block(-5,52,5,159:15)
Block(-5,52,6,251:15)
Block(-5,53,-7,251:15)
Block(-5,53,-6,159:15)
Block(-5,53,-5,159:15)
Block(-5,53,-4,251:15)
Block(-5,53,-3,159:15)
Block(-5,53,-2,159:15)
Block(-5,53,-1,251:15)
Block(-5,53,0,251:15)
Block(-5,53,1,159:15)
Block(-5,53,2,159:15)
Block(-5,53,3,251:15)
Block(-5,53,4,251:15)
Block(-5,53,5,251:15)
Block(-5,53,6,251:15)
Block(-5,54,-7,159:15)
Block(-5,54,-6,251:15)
Block(-5,54,-5,159:15)
Block(-5,54,-4,251:15)
Block(-5,54,-3,159:15)
Block(-5,54,-2,159:15)
Block(-5,54,-1,159:15)
Block(-5,54,0,159:15)
Block(-5,54,1,159:15)
Block(-5,54,2,159:15)
Block(-5,54,3,251:15)
Block(-5,54,4,159:15)
Block(-5,54,5,251:15)
Block(-5,54,6,251:15)
Block(-5,55,-7,251:15)
Block(-5,55,-6,251:15)
Block(-5,55,-5,159:15)
Block(-5,55,-4,251:15)
Block(-5,55,-3,159:15)
Block(-5,55,-2,159:15)
Block(-5,55,-1,159:15)
Block(-5,55,0,159:15)
Block(-5,55,1,159:15)
Block(-5,55,2,159:15)
Block(-5,55,3,159:15)
Block(-5,55,4,159:15)
Block(-5,55,5,159:15)
Block(-5,55,6,159:15)
Block(-5,56,-7,159:15)
Block(-5,56,-6,159:15)
Block(-5,56,-5,159:15)
Block(-5,56,-4,159:15)
Block(-5,56,-3,159:15)
Block(-5,56,-2,251:15)
Block(-5,56,-1,159:15)
Block(-5,56,0,159:15)
Block(-5,56,1,159:15)
Block(-5,56,2,251:15)
Block(-5,56,3,251:15)
Block(-5,56,4,251:15)
Block(-5,56,5,251:15)
Block(-5,56,6,251:15)
Block(-5,57,-7,251:15)
Block(-5,57,-6,159:15)
Block(-5,57,-5,159:15)
Block(-5,57,-4,251:15)
Block(-5,57,-3,159:15)
Block(-5,57,-2,159:15)
Block(-5,57,-1,159:15)
Block(-5,57,0,159:15)
Block(-5,57,1,159:15)
Block(-5,57,2,159:15)
Block(-5,57,3,159:15)
Block(-5,57,4,251:15)
Block(-5,57,5,159:15)
Block(-5,57,6,159:15)
Block(-5,58,-7,159:15)
Block(-5,58,-6,251:15)
Block(-5,58,-5,159:15)
Block(-5,58,-4,251:15)
Block(-5,58,-3,159:15)
Block(-5,58,-2,251:15)
Block(-5,58,-1,159:15)
Block(-5,58,0,251:15)
Block(-5,58,1,159:15)
Block(-5,58,2,251:15)
Block(-5,58,3,159:15)
Block(-5,58,4,251:15)
Block(-5,58,5,251:15)
Block(-5,58,6,251:15)
Block(-5,59,-7,251:15)
Block(-5,59,-6,2)
Block(-5,59,-5,2)
Block(-5,59,-4,2)
Block(-5,59,-3,251:15)
Block(-5,59,-2,251:15)
Block(-5,59,-1,2)
Block(-5,59,0,3:1)
Block(-5,59,1,159:15)
Block(-5,59,2,159:15)
Block(-5,59,3,159:15)
Block(-5,59,4,251:15)
Block(-5,59,5,159:15)
Block(-5,59,6,251:15)
Block(-4,0,-7,159:15)
Block(-4,0,-6,159:15)
Block(-4,0,-5,159:15)
Block(-4,0,-4,159:15)
Block(-4,0,-3,159:15)
Block(-4,0,-2,159:15)
Block(-4,0,-1,159:15)
Block(-4,0,0,251:15)
Block(-4,0,1,251:15)
Block(-4,0,2,159:15)
Block(-4,0,3,251:15)
Block(-4,0,4,251:15)
Block(-4,0,5,159:15)
Block(-4,1,-7,251:15)
Block(-4,1,-6,159:15)
Block(-4,1,-5,159:15)
Block(-4,1,-4,251:15)
Block(-4,1,-3,159:15)
Block(-4,1,-2,159:15)
Block(-4,1,-1,251:15)
Block(-4,1,0,251:15)
Block(-4,1,1,251:15)
Block(-4,1,2,251:15)
Block(-4,1,3,251:15)
Block(-4,1,4,251:15)
Block(-4,1,5,159:15)
Block(-4,2,-7,159:15)
Block(-4,2,-6,251:15)
Block(-4,2,-5,159:15)
Block(-4,2,-4,251:15)
Block(-4,2,-3,159:15)
Block(-4,2,-2,251:15)
Block(-4,2,-1,251:15)
Block(-4,2,0,251:15)
Block(-4,2,1,159:15)
Block(-4,2,2,251:15)
Block(-4,2,3,251:15)
Block(-4,2,4,251:15)
Block(-4,2,5,251:15)
Block(-4,3,-7,251:15)
Block(-4,3,-6,251:15)
Block(-4,3,-5,159:15)
Block(-4,3,-4,251:15)
Block(-4,3,-3,251:15)
Block(-4,3,-2,251:15)
Block(-4,3,-1,251:15)
Block(-4,3,0,159:15)
Block(-4,3,1,159:15)
Block(-4,3,2,159:15)
Block(-4,3,3,251:15)
Block(-4,3,4,251:15)
Block(-4,3,5,159:15)
Block(-4,4,-7,159:15)
Block(-4,4,-6,159:15)
Block(-4,4,-5,159:15)
Block(-4,4,-4,159:15)
Block(-4,4,-3,251:15)
Block(-4,4,-2,251:15)
Block(-4,4,-1,251:15)
Block(-4,4,0,251:15)
Block(-4,4,1,251:15)
Block(-4,4,2,251:15)
Block(-4,4,3,159:15)
Block(-4,4,4,251:15)
Block(-4,4,5,251:15)
Block(-4,5,-7,251:15)
Block(-4,5,-6,251:15)
Block(-4,5,-5,251:15)
Block(-4,5,-4,251:15)
Block(-4,5,-3,251:15)
Block(-4,5,-2,159:15)
Block(-4,5,-1,159:15)
Block(-4,5,0,251:15)
Block(-4,5,1,251:15)
Block(-4,5,2,159:15)
Block(-4,5,3,251:15)
Block(-4,5,4,251:15)
Block(-4,5,5,159:15)
Block(-4,6,-7,251:15)
Block(-4,6,-6,251:15)
Block(-4,6,-5,251:15)
Block(-4,6,-4,159:15)
Block(-4,6,-3,159:15)
Block(-4,6,-2,159:15)
Block(-4,6,-1,159:15)
Block(-4,6,0,251:15)
Block(-4,6,1,251:15)
Block(-4,6,2,251:15)
Block(-4,6,3,251:15)
Block(-4,6,4,159:15)
Block(-4,6,5,159:15)
Block(-4,7,-7,159:15)
Block(-4,7,-6,251:15)
Block(-4,7,-5,159:15)
Block(-4,7,-4,159:15)
Block(-4,7,-3,159:15)
Block(-4,7,-2,159:15)
Block(-4,7,-1,159:15)
Block(-4,7,0,251:15)
Block(-4,7,1,251:15)
Block(-4,7,2,251:15)
Block(-4,7,3,159:15)
Block(-4,7,4,159:15)
Block(-4,7,5,251:15)
Block(-4,8,-7,159:15)
Block(-4,8,-6,159:15)
Block(-4,8,-5,159:15)
Block(-4,8,-4,251:15)
Block(-4,8,-3,251:15)
Block(-4,8,-2,159:15)
Block(-4,8,-1,159:15)
Block(-4,8,0,251:15)
Block(-4,8,1,251:15)
Block(-4,8,2,159:15)
Block(-4,8,3,251:15)
Block(-4,8,4,251:15)
Block(-4,8,5,251:15)
Block(-4,9,-7,251:15)
Block(-4,9,-6,159:15)
Block(-4,9,-5,159:15)
Block(-4,9,-4,251:15)
Block(-4,9,-3,251:15)
Block(-4,9,-2,251:15)
Block(-4,9,-1,159:15)
Block(-4,9,0,251:15)
Block(-4,9,1,251:15)
Block(-4,9,2,251:15)
Block(-4,9,3,159:15)
Block(-4,9,4,159:15)
Block(-4,9,5,251:15)
Block(-4,10,-7,251:15)
Block(-4,10,-6,251:15)
Block(-4,10,-5,159:15)
Block(-4,10,-4,159:15)
Block(-4,10,-3,159:15)
Block(-4,10,-2,251:15)
Block(-4,10,-1,251:15)
Block(-4,10,0,159:15)
Block(-4,10,1,251:15)
Block(-4,10,2,251:15)
Block(-4,10,3,159:15)
Block(-4,10,4,159:15)
Block(-4,10,5,159:15)
Block(-4,11,-7,159:15)
Block(-4,11,-6,159:15)
Block(-4,11,-5,159:15)
Block(-4,11,-4,159:15)
Block(-4,11,-3,159:15)
Block(-4,11,-2,159:15)
Block(-4,11,-1,159:15)
Block(-4,11,0,251:15)
Block(-4,11,1,159:15)
Block(-4,11,2,251:15)
Block(-4,11,3,251:15)
Block(-4,11,4,159:15)
Block(-4,11,5,159:15)
Block(-4,12,-7,159:15)
Block(-4,12,-6,159:15)
Block(-4,12,-5,159:15)
Block(-4,12,-4,251:15)
Block(-4,12,-3,159:15)
Block(-4,12,-2,251:15)
Block(-4,12,-1,159:15)
Block(-4,12,0,159:15)
Block(-4,12,1,251:15)
Block(-4,12,2,159:15)
Block(-4,12,3,159:15)
Block(-4,12,4,159:15)
Block(-4,12,5,159:15)
Block(-4,13,-7,159:15)
Block(-4,13,-6,159:15)
Block(-4,13,-5,251:15)
Block(-4,13,-4,159:15)
Block(-4,13,-3,251:15)
Block(-4,13,-2,251:15)
Block(-4,13,-1,251:15)
Block(-4,13,0,251:15)
Block(-4,13,1,159:15)
Block(-4,13,2,251:15)
Block(-4,13,3,159:15)
Block(-4,13,4,159:15)
Block(-4,13,5,251:15)
Block(-4,14,-7,251:15)
Block(-4,14,-6,159:15)
Block(-4,14,-5,159:15)
Block(-4,14,-4,159:15)
Block(-4,14,-3,251:15)
Block(-4,14,-2,251:15)
Block(-4,14,-1,159:15)
Block(-4,14,0,159:15)
Block(-4,14,1,251:15)
Block(-4,14,2,159:15)
Block(-4,14,3,159:15)
Block(-4,14,4,251:15)
Block(-4,14,5,159:15)
Block(-4,15,-7,159:15)
Block(-4,15,-6,251:15)
Block(-4,15,-5,251:15)
Block(-4,15,-4,159:15)
Block(-4,15,-3,159:15)
Block(-4,15,-2,159:15)
Block(-4,15,-1,159:15)
Block(-4,15,0,251:15)
Block(-4,15,1,159:15)
Block(-4,15,2,159:15)
Block(-4,15,3,251:15)
Block(-4,15,4,251:15)
Block(-4,15,5,251:15)
Block(-4,16,-7,251:15)
Block(-4,16,-6,251:15)
Block(-4,16,-5,251:15)
Block(-4,16,-4,251:15)
Block(-4,16,-3,251:15)
Block(-4,16,-2,159:15)
Block(-4,16,-1,251:15)
Block(-4,16,0,159:15)
Block(-4,16,1,251:15)
Block(-4,16,2,159:15)
Block(-4,16,3,159:15)
Block(-4,16,4,159:15)
Block(-4,16,5,251:15)
Block(-4,17,-7,251:15)
Block(-4,17,-6,159:15)
Block(-4,17,-5,251:15)
Block(-4,17,-4,159:15)
Block(-4,17,-3,251:15)
Block(-4,17,-2,159:15)
Block(-4,17,-1,251:15)
Block(-4,17,0,251:15)
Block(-4,17,1,251:15)
Block(-4,17,2,251:15)
Block(-4,17,3,251:15)
Block(-4,17,4,251:15)
Block(-4,17,5,251:15)
Block(-4,18,-7,251:15)
Block(-4,18,-6,159:15)
Block(-4,18,-5,159:15)
Block(-4,18,-4,251:15)
Block(-4,18,-3,159:15)
Block(-4,18,-2,251:15)
Block(-4,18,-1,251:15)
Block(-4,18,0,251:15)
Block(-4,18,1,251:15)
Block(-4,18,2,159:15)
Block(-4,18,3,159:15)
Block(-4,18,4,251:15)
Block(-4,18,5,251:15)
Block(-4,19,-7,251:15)
Block(-4,19,-6,159:15)
Block(-4,19,-5,251:15)
Block(-4,19,-4,159:15)
Block(-4,19,-3,251:15)
Block(-4,19,-2,159:15)
Block(-4,19,-1,159:15)
Block(-4,19,0,159:15)
Block(-4,19,1,159:15)
Block(-4,19,2,159:15)
Block(-4,19,3,251:15)
Block(-4,19,4,251:15)
Block(-4,19,5,251:15)
Block(-4,20,-7,251:15)
Block(-4,20,-6,159:15)
Block(-4,20,-5,251:15)
Block(-4,20,-4,159:15)
Block(-4,20,-3,159:15)
Block(-4,20,-2,159:15)
Block(-4,20,-1,251:15)
Block(-4,20,0,159:15)
Block(-4,20,1,251:15)
Block(-4,20,2,251:15)
Block(-4,20,3,251:15)
Block(-4,20,4,251:15)
Block(-4,20,5,159:15)
Block(-4,21,-7,251:15)
Block(-4,21,-6,251:15)
Block(-4,21,-5,159:15)
Block(-4,21,-4,251:15)
Block(-4,21,-3,159:15)
Block(-4,21,-2,251:15)
Block(-4,21,-1,251:15)
Block(-4,21,0,159:15)
Block(-4,21,1,251:15)
Block(-4,21,2,159:15)
Block(-4,21,3,159:15)
Block(-4,21,4,251:15)
Block(-4,21,5,159:15)
Block(-4,22,-7,251:15)
Block(-4,22,-6,159:15)
Block(-4,22,-5,159:15)
Block(-4,22,-4,251:15)
Block(-4,22,-3,159:15)
Block(-4,22,-2,159:15)
Block(-4,22,-1,251:15)
Block(-4,22,0,159:15)
Block(-4,22,1,159:15)
Block(-4,22,2,251:15)
Block(-4,22,3,251:15)
Block(-4,22,4,251:15)
Block(-4,22,5,251:15)
Block(-4,23,-7,251:15)
Block(-4,23,-6,251:15)
Block(-4,23,-5,251:15)
Block(-4,23,-4,251:15)
Block(-4,23,-3,251:15)
Block(-4,23,-2,251:15)
Block(-4,23,-1,159:15)
Block(-4,23,0,251:15)
Block(-4,23,1,251:15)
Block(-4,23,2,159:15)
Block(-4,23,3,159:15)
Block(-4,23,4,159:15)
Block(-4,23,5,159:15)
Block(-4,24,-7,251:15)
Block(-4,24,-6,159:15)
Block(-4,24,-5,159:15)
Block(-4,24,-4,159:15)
Block(-4,24,-3,251:15)
Block(-4,24,-2,251:15)
Block(-4,24,-1,251:15)
Block(-4,24,0,159:15)
Block(-4,24,1,251:15)
Block(-4,24,2,251:15)
Block(-4,24,3,159:15)
Block(-4,24,4,159:15)
Block(-4,24,5,251:15)
Block(-4,25,-7,159:15)
Block(-4,25,-6,159:15)
Block(-4,25,-5,159:15)
Block(-4,25,-4,159:15)
Block(-4,25,-3,251:15)
Block(-4,25,-2,251:15)
Block(-4,25,-1,159:15)
Block(-4,25,0,251:15)
Block(-4,25,1,159:15)
Block(-4,25,2,251:15)
Block(-4,25,3,159:15)
Block(-4,25,4,159:15)
Block(-4,25,5,159:15)
Block(-4,26,-7,251:15)
Block(-4,26,-6,159:15)
Block(-4,26,-5,251:15)
Block(-4,26,-4,159:15)
Block(-4,26,-3,159:15)
Block(-4,26,-2,159:15)
Block(-4,26,-1,159:15)
Block(-4,26,0,159:15)
Block(-4,26,1,251:15)
Block(-4,26,2,159:15)
Block(-4,26,3,251:15)
Block(-4,26,4,159:15)
Block(-4,26,5,159:15)
Block(-4,27,-7,251:15)
Block(-4,27,-6,159:15)
Block(-4,27,-5,159:15)
Block(-4,27,-4,159:15)
Block(-4,27,-3,251:15)
Block(-4,27,-2,159:15)
Block(-4,27,-1,159:15)
Block(-4,27,0,159:15)
Block(-4,27,1,159:15)
Block(-4,27,2,159:15)
Block(-4,27,3,251:15)
Block(-4,27,4,159:15)
Block(-4,27,5,251:15)
Block(-4,28,-7,159:15)
Block(-4,28,-6,251:15)
Block(-4,28,-5,159:15)
Block(-4,28,-4,251:15)
Block(-4,28,-3,159:15)
Block(-4,28,-2,251:15)
Block(-4,28,-1,251:15)
Block(-4,28,0,251:15)
Block(-4,28,1,251:15)
Block(-4,28,2,159:15)
Block(-4,28,3,159:15)
Block(-4,28,4,251:15)
Block(-4,28,5,251:15)
Block(-4,29,-7,159:15)
Block(-4,29,-6,251:15)
Block(-4,29,-5,159:15)
Block(-4,29,-4,251:15)
Block(-4,29,-3,159:15)
Block(-4,29,-2,159:15)
Block(-4,29,-1,159:15)
Block(-4,29,0,159:15)
Block(-4,29,1,251:15)
Block(-4,29,2,251:15)
Block(-4,29,3,159:15)
Block(-4,29,4,159:15)
Block(-4,29,5,159:15)
Block(-4,30,-7,159:15)
Block(-4,30,-6,159:15)
Block(-4,30,-5,251:15)
Block(-4,30,-4,251:15)
Block(-4,30,-3,251:15)
Block(-4,30,-2,159:15)
Block(-4,30,-1,159:15)
Block(-4,30,0,251:15)
Block(-4,30,1,251:15)
Block(-4,30,2,159:15)
Block(-4,30,3,159:15)
Block(-4,30,4,251:15)
Block(-4,30,5,251:15)
Block(-4,31,-7,159:15)
Block(-4,31,-6,159:15)
Block(-4,31,-5,251:15)
Block(-4,31,-4,251:15)
Block(-4,31,-3,159:15)
Block(-4,31,-2,159:15)
Block(-4,31,-1,251:15)
Block(-4,31,0,251:15)
Block(-4,31,1,159:15)
Block(-4,31,2,159:15)
Block(-4,31,3,159:15)
Block(-4,31,4,159:15)
Block(-4,31,5,159:15)
Block(-4,32,-7,159:15)
Block(-4,32,-6,251:15)
Block(-4,32,-5,159:15)
Block(-4,32,-4,159:15)
Block(-4,32,-3,251:15)
Block(-4,32,-2,159:15)
Block(-4,32,-1,159:15)
Block(-4,32,0,251:15)
Block(-4,32,1,251:15)
Block(-4,32,2,251:15)
Block(-4,32,3,251:15)
Block(-4,32,4,159:15)
Block(-4,32,5,251:7)
Block(-4,33,-7,159:15)
Block(-4,33,-6,251:15)
Block(-4,33,-5,251:15)
Block(-4,33,-4,251:15)
Block(-4,33,-3,251:15)
Block(-4,33,-2,251:15)
Block(-4,33,-1,251:15)
Block(-4,33,0,159:15)
Block(-4,33,1,159:15)
Block(-4,33,2,251:15)
Block(-4,33,3,159:15)
Block(-4,33,4,159:15)
Block(-4,33,5,251:7)
Block(-4,34,-7,159:15)
Block(-4,34,-6,251:15)
Block(-4,34,-5,159:15)
Block(-4,34,-4,159:15)
Block(-4,34,-3,159:15)
Block(-4,34,-2,159:15)
Block(-4,34,-1,251:15)
Block(-4,34,0,159:15)
Block(-4,34,1,159:15)
Block(-4,34,2,251:15)
Block(-4,34,3,251:15)
Block(-4,34,4,251:15)
Block(-4,34,5,159:15)
Block(-4,35,-7,159:15)
Block(-4,35,-6,159:15)
Block(-4,35,-5,159:15)
Block(-4,35,-4,251:15)
Block(-4,35,-3,251:15)
Block(-4,35,-2,251:15)
Block(-4,35,-1,159:15)
Block(-4,35,0,159:15)
Block(-4,35,1,159:15)
Block(-4,35,2,251:15)
Block(-4,35,3,159:15)
Block(-4,35,4,159:15)
Block(-4,35,5,159:15)
Block(-4,36,-7,159:15)
Block(-4,36,-6,159:15)
Block(-4,36,-5,251:15)
Block(-4,36,-4,159:15)
Block(-4,36,-3,251:15)
Block(-4,36,-2,251:15)
Block(-4,36,-1,159:15)
Block(-4,36,0,159:15)
Block(-4,36,1,251:15)
Block(-4,36,2,159:15)
Block(-4,36,3,159:15)
Block(-4,36,4,159:15)
Block(-4,36,5,159:15)
Block(-4,37,-7,159:15)
Block(-4,37,-6,159:15)
Block(-4,37,-5,251:15)
Block(-4,37,-4,251:15)
Block(-4,37,-3,159:15)
Block(-4,37,-2,251:15)
Block(-4,37,-1,251:15)
Block(-4,37,0,251:15)
Block(-4,37,1,159:15)
Block(-4,37,2,251:15)
Block(-4,37,3,251:15)
Block(-4,37,4,251:15)
Block(-4,37,5,159:15)
Block(-4,38,-7,159:15)
Block(-4,38,-6,159:15)
Block(-4,38,-5,251:15)
Block(-4,38,-4,251:15)
Block(-4,38,-3,251:15)
Block(-4,38,-2,159:15)
Block(-4,38,-1,251:15)
Block(-4,38,0,159:15)
Block(-4,38,1,251:15)
Block(-4,38,2,159:15)
Block(-4,38,3,159:15)
Block(-4,38,4,159:15)
Block(-4,38,5,159:15)
Block(-4,39,-7,159:15)
Block(-4,39,-6,251:15)
Block(-4,39,-5,159:15)
Block(-4,39,-4,159:15)
Block(-4,39,-3,251:15)
Block(-4,39,-2,159:15)
Block(-4,39,-1,251:15)
Block(-4,39,0,251:15)
Block(-4,39,1,251:15)
Block(-4,39,2,159:15)
Block(-4,39,3,251:15)
Block(-4,39,4,159:15)
Block(-4,39,5,251:15)
Block(-4,40,-7,251:15)
Block(-4,40,-6,159:15)
Block(-4,40,-5,159:15)
Block(-4,40,-4,159:15)
Block(-4,40,-3,159:15)
Block(-4,40,-2,159:15)
Block(-4,40,-1,159:15)
Block(-4,40,0,251:15)
