

BranchFrequency: 10

BranchFrequencyGroup: CanOverride:0

CanOverride: true

SmoothRadius: -1

OverrideChildSettings: false

ReplaceAbove:
ReplaceBelow:

MustBeInside: VillageGeneratorStructurePlaceHolder, VillageGeneratorStructuresDelay, VillageGeneratorStructuresDelay2, VillageGeneratorStructuresDelay3, VillageGeneratorStructuresDelay4, VillageGeneratorStructuresDelay5, VillageGeneratorStructuresDelay6, VillageGeneratorStructuresDelay7, VillageGeneratorStructuresDelay8, VillageGeneratorStructuresDelay9, VillageGeneratorStructuresDelay10

Block(-8,0,-7,2)
Block(-8,0,-6,2)
Block(-8,0,-5,2)
Block(-8,0,-4,2)
Block(-8,0,-3,2)
Block(-8,0,-2,2)
Block(-8,0,-1,2)
Block(-8,0,0,2)
Block(-8,0,1,2)
Block(-8,0,2,2)
Block(-8,0,3,2)
Block(-8,0,4,2)
Block(-8,0,5,2)
Block(-8,0,6,2)
Block(-8,0,7,2)
Block(-8,0,8,2)
Block(-7,0,-7,2)
Block(-7,0,-6,2)
Block(-7,0,-5,2)
Block(-7,0,-4,2)
Block(-7,0,-3,2)
Block(-7,0,-2,2)
Block(-7,0,-1,2)
Block(-7,0,0,2)
Block(-7,0,1,2)
Block(-7,0,2,2)
Block(-7,0,3,2)
Block(-7,0,4,2)
Block(-7,0,5,2)
Block(-7,0,6,2)
Block(-7,0,7,2)
Block(-7,0,8,2)
Block(-6,0,-7,2)
Block(-6,0,-6,2)
Block(-6,0,-5,2)
Block(-6,0,-4,2)
Block(-6,0,-3,2)
Block(-6,0,-2,2)
Block(-6,0,-1,2)
Block(-6,0,0,2)
Block(-6,0,1,2)
Block(-6,0,2,2)
Block(-6,0,3,2)
Block(-6,0,4,2)
Block(-6,0,5,2)
Block(-6,0,6,2)
Block(-6,0,7,2)
Block(-6,0,8,2)
Block(-6,1,-4,106:8)
Block(-6,1,-3,106:8)
Block(-6,1,-2,106:8)
Block(-6,1,-1,106:8)
Block(-6,1,3,106:8)
Block(-6,1,4,106:8)
Block(-6,1,5,106:8)
Block(-6,1,6,106:8)
Block(-6,2,-4,106:8)
Block(-6,2,-3,106:8)
Block(-6,2,-2,106:8)
Block(-6,2,4,106:8)
Block(-6,2,5,106:8)
Block(-6,2,6,106:8)
Block(-6,3,-4,106:8)
Block(-6,3,-3,106:8)
Block(-6,3,5,106:8)
Block(-6,3,6,106:8)
Block(-6,4,-4,106:8)
Block(-6,4,6,106:8)
Block(-5,0,-7,2)
Block(-5,0,-6,2)
Block(-5,0,-5,2)
Block(-5,0,-4,3)
Block(-5,0,-3,3)
Block(-5,0,-2,3)
Block(-5,0,-1,3)
Block(-5,0,0,3)
Block(-5,0,1,3)
Block(-5,0,2,3)
Block(-5,0,3,3)
Block(-5,0,4,3)
Block(-5,0,5,3)
Block(-5,0,6,3)
Block(-5,0,7,2)
Block(-5,0,8,2)
Block(-5,1,-5,106:1)
Block(-5,1,-4,98)
Block(-5,1,-3,98)
Block(-5,1,-2,98)
Block(-5,1,-1,98)
Block(-5,1,0,98)
Block(-5,1,1,98)
Block(-5,1,2,98)
Block(-5,1,3,98)
Block(-5,1,4,98)
Block(-5,1,5,98)
Block(-5,1,6,98)
Block(-5,1,7,106:4)
Block(-5,2,-5,106:1)
Block(-5,2,-4,98)
Block(-5,2,-3,98)
Block(-5,2,-2,98)
Block(-5,2,-1,160:14)
Block(-5,2,0,160:14)
Block(-5,2,1,160:14)
Block(-5,2,2,160:14)
Block(-5,2,3,160:14)
Block(-5,2,4,98)
Block(-5,2,5,98)
Block(-5,2,6,98)
Block(-5,2,7,106:4)
Block(-5,3,-5,106:1)
Block(-5,3,-4,98)
Block(-5,3,-3,98)
Block(-5,3,-2,98)
Block(-5,3,-1,160:14)
Block(-5,3,0,160:14)
Block(-5,3,1,160:14)
Block(-5,3,2,160:14)
Block(-5,3,3,160:14)
Block(-5,3,4,98)
Block(-5,3,5,98)
Block(-5,3,6,98)
Block(-5,3,7,106:4)
Block(-5,4,-5,106:1)
Block(-5,4,-4,98)
Block(-5,4,-3,98)
Block(-5,4,-2,98)
Block(-5,4,-1,160:14)
Block(-5,4,0,160:14)
Block(-5,4,1,160:14)
Block(-5,4,2,160:14)
Block(-5,4,3,160:14)
Block(-5,4,4,98)
Block(-5,4,5,98)
Block(-5,4,6,98)
Block(-5,4,7,106:4)
Block(-5,5,-4,98)
Block(-5,5,-3,98)
Block(-5,5,-2,98)
Block(-5,5,-1,160:14)
Block(-5,5,0,160:14)
Block(-5,5,1,160:14)
Block(-5,5,2,160:14)
Block(-5,5,3,160:14)
Block(-5,5,4,98)
Block(-5,5,5,98)
Block(-5,5,6,98)
Block(-5,6,-4,98)
Block(-5,6,-3,98)
Block(-5,6,-2,98)
Block(-5,6,-1,160:14)
Block(-5,6,0,160:14)
Block(-5,6,1,160:14)
Block(-5,6,2,160:14)
Block(-5,6,3,160:14)
Block(-5,6,4,98)
Block(-5,6,5,98)
Block(-5,6,6,98)
Block(-5,7,-4,98)
Block(-5,7,-3,98)
Block(-5,7,-2,98)
Block(-5,7,-1,98)
Block(-5,7,0,160:14)
Block(-5,7,1,160:14)
Block(-5,7,2,160:14)
Block(-5,7,3,98)
Block(-5,7,4,98)
Block(-5,7,5,98)
Block(-5,7,6,98)
Block(-5,8,-4,98)
Block(-5,8,-3,98)
Block(-5,8,-2,98)
Block(-5,8,-1,98)
Block(-5,8,0,98)
Block(-5,8,1,160:14)
Block(-5,8,2,98)
Block(-5,8,3,98)
Block(-5,8,4,98)
Block(-5,8,5,98)
Block(-5,8,6,98)
Block(-5,9,-4,98)
Block(-5,9,-3,98)
Block(-5,9,-2,98)
Block(-5,9,-1,98)
Block(-5,9,0,98)
Block(-5,9,1,98)
Block(-5,9,2,98)
Block(-5,9,3,98)
Block(-5,9,4,98)
Block(-5,9,5,98)
Block(-5,9,6,98)
Block(-5,10,-4,136:2)
Block(-5,10,-3,35:14)
Block(-5,10,-2,98)
Block(-5,10,-1,98)
Block(-5,10,0,98)
Block(-5,10,1,35:14)
Block(-5,10,2,98)
Block(-5,10,3,98)
Block(-5,10,4,98)
Block(-5,10,5,35:14)
Block(-5,10,6,136:3)
Block(-5,11,-3,136:2)
Block(-5,11,-2,35:14)
Block(-5,11,-1,98)
Block(-5,11,0,35:14)
Block(-5,11,1,35:14)
Block(-5,11,2,35:14)
Block(-5,11,3,98)
Block(-5,11,4,35:14)
Block(-5,11,5,136:3)
Block(-5,12,-2,136:2)
Block(-5,12,-1,35:14)
Block(-5,12,0,98)
Block(-5,12,1,35:14)
Block(-5,12,2,98)
Block(-5,12,3,35:14)
Block(-5,12,4,136:3)
Block(-5,13,-1,136:2)
Block(-5,13,0,35:14)
Block(-5,13,1,98)
Block(-5,13,2,35:14)
Block(-5,13,3,136:3)
Block(-5,14,0,136:2)
Block(-5,14,1,35:14)
Block(-5,14,2,136:3)
Block(-5,15,1,126:3)
Block(-4,0,-7,2)
Block(-4,0,-6,2)
Block(-4,0,-5,2)
Block(-4,0,-4,3)
Block(-4,0,-3,5:5)
Block(-4,0,-2,5:5)
Block(-4,0,-1,5:5)
Block(-4,0,0,5:5)
Block(-4,0,1,5:5)
Block(-4,0,2,5:5)
Block(-4,0,3,5:5)
Block(-4,0,4,5:5)
Block(-4,0,5,5:5)
Block(-4,0,6,3)
Block(-4,0,7,2)
Block(-4,0,8,2)
Block(-4,1,-5,106:1)
Block(-4,1,-4,98)
Block(-4,1,-3,53:1)
Block(-4,1,-2,53:1)
Block(-4,1,-1,53:1)
Block(-4,1,0,68:3,1-Sign.nbt)
Block(-4,1,2,68:2,2-Sign.nbt)
Block(-4,1,3,53:1)
Block(-4,1,4,53:1)
Block(-4,1,5,53:1)
Block(-4,1,6,98)
Block(-4,1,7,106:4)
Block(-4,2,-5,106:1)
Block(-4,2,-4,98)
Block(-4,2,6,98)
Block(-4,2,7,106:4)
Block(-4,3,-5,106:1)
Block(-4,3,-4,98)
Block(-4,3,6,98)
Block(-4,3,7,106:4)
Block(-4,4,-4,98)
Block(-4,4,6,98)
Block(-4,5,-4,98)
Block(-4,5,6,98)
Block(-4,6,-4,98)
Block(-4,6,6,98)
Block(-4,7,-4,98)
Block(-4,7,6,98)
Block(-4,8,-4,98)
Block(-4,8,6,98)
Block(-4,9,-4,98)
Block(-4,9,6,98)
Block(-4,10,-4,136:2)
Block(-4,10,6,136:3)
Block(-4,11,-3,136:2)
Block(-4,11,5,136:3)
Block(-4,12,-2,136:2)
Block(-4,12,4,136:3)
Block(-4,13,-1,136:2)
Block(-4,13,3,136:3)
Block(-4,14,0,136:2)
Block(-4,14,2,136:3)
Block(-4,15,1,126:3)
Block(-3,0,-7,2)
Block(-3,0,-6,2)
Block(-3,0,-5,2)
Block(-3,0,-4,3)
Block(-3,0,-3,5:5)
Block(-3,0,-2,5:5)
Block(-3,0,-1,5:5)
Block(-3,0,0,5:5)
Block(-3,0,1,5:5)
Block(-3,0,2,5:5)
Block(-3,0,3,5:5)
Block(-3,0,4,5:5)
Block(-3,0,5,5:5)
Block(-3,0,6,3)
Block(-3,0,7,3)
Block(-3,0,8,3)
Block(-3,1,-5,106:1)
Block(-3,1,-4,98)
Block(-3,1,6,98)
Block(-3,1,7,98)
Block(-3,1,8,98)
Block(-3,2,-5,106:1)
Block(-3,2,-4,98)
Block(-3,2,6,98)
Block(-3,2,7,98)
Block(-3,2,8,98)
Block(-3,3,-4,98)
Block(-3,3,6,98)
Block(-3,3,7,98)
Block(-3,3,8,98)
Block(-3,4,-4,98)
Block(-3,4,6,98)
Block(-3,4,7,98)
Block(-3,4,8,98)
Block(-3,5,-4,98)
Block(-3,5,6,98)
Block(-3,5,7,98)
Block(-3,5,8,98)
Block(-3,6,-4,98)
Block(-3,6,6,98)
Block(-3,6,7,98)
Block(-3,6,8,35:14)
Block(-3,7,-4,98)
Block(-3,7,6,98)
Block(-3,7,7,35:14)
Block(-3,7,8,136:3)
Block(-3,8,-4,98)
Block(-3,8,6,98)
Block(-3,8,7,136:3)
Block(-3,9,-4,98)
Block(-3,9,6,98)
Block(-3,10,-4,136:2)
Block(-3,10,6,136:3)
Block(-3,11,-3,136:2)
Block(-3,11,5,136:3)
Block(-3,12,-2,136:2)
Block(-3,12,4,136:3)
Block(-3,13,-1,136:2)
Block(-3,13,3,136:3)
Block(-3,14,0,136:2)
Block(-3,14,2,136:3)
Block(-3,15,1,126:3)
Block(-2,0,-7,2)
Block(-2,0,-6,2)
Block(-2,0,-5,2)
Block(-2,0,-4,3)
Block(-2,0,-3,5:5)
Block(-2,0,-2,5:5)
Block(-2,0,-1,5:5)
Block(-2,0,0,5:5)
Block(-2,0,1,5:5)
Block(-2,0,2,5:5)
Block(-2,0,3,5:5)
Block(-2,0,4,5:5)
Block(-2,0,5,5:5)
Block(-2,0,6,3)
Block(-2,0,7,2)
Block(-2,0,8,2)
Block(-2,1,-5,106:1)
Block(-2,1,-4,98)
Block(-2,1,-3,53:1)
Block(-2,1,-2,53:1)
Block(-2,1,-1,53:1)
Block(-2,1,0,68:3,3-Sign.nbt)
Block(-2,1,2,68:2,4-Sign.nbt)
Block(-2,1,3,53:1)
Block(-2,1,4,53:1)
Block(-2,1,5,53:1)
Block(-2,1,6,98)
Block(-2,2,-4,160:14)
Block(-2,2,6,98)
Block(-2,3,-4,160:14)
Block(-2,3,6,98)
Block(-2,4,-4,160:14)
Block(-2,4,6,98)
Block(-2,5,-4,160:14)
Block(-2,5,6,98)
Block(-2,6,-4,160:14)
Block(-2,6,6,98)
Block(-2,7,-4,160:14)
Block(-2,7,6,98)
Block(-2,7,8,136:3)
Block(-2,8,-4,160:14)
Block(-2,8,6,98)
Block(-2,8,7,136:3)
Block(-2,9,-4,98)
Block(-2,9,6,98)
Block(-2,10,-4,136:2)
Block(-2,10,6,136:3)
Block(-2,11,-3,136:2)
Block(-2,11,5,136:3)
Block(-2,12,-2,136:2)
Block(-2,12,4,136:3)
Block(-2,13,-1,136:2)
Block(-2,13,3,136:3)
Block(-2,14,0,136:2)
Block(-2,14,2,136:3)
Block(-2,15,1,126:3)
Block(-1,0,-7,2)
Block(-1,0,-6,2)
Block(-1,0,-5,2)
Block(-1,0,-4,3)
Block(-1,0,-3,5:5)
Block(-1,0,-2,5:5)
Block(-1,0,-1,5:5)
Block(-1,0,0,5:5)
Block(-1,0,1,5:5)
Block(-1,0,2,5:5)
Block(-1,0,3,5:5)
Block(-1,0,4,5:5)
Block(-1,0,5,5:5)
Block(-1,0,6,3)
Block(-1,0,7,2)
Block(-1,0,8,2)
Block(-1,1,-4,98)
Block(-1,1,6,98)
Block(-1,2,-4,160:14)
Block(-1,2,6,98)
Block(-1,3,-4,160:14)
Block(-1,3,6,98)
Block(-1,4,-4,160:14)
Block(-1,4,6,98)
Block(-1,5,-4,160:14)
Block(-1,5,6,98)
Block(-1,6,-4,160:14)
Block(-1,6,6,98)
Block(-1,7,-4,160:14)
Block(-1,7,6,98)
Block(-1,7,8,136:3)
Block(-1,8,-4,160:14)
Block(-1,8,6,98)
Block(-1,8,7,136:3)
Block(-1,9,-4,98)
Block(-1,9,6,98)
Block(-1,10,-4,136:2)
Block(-1,10,6,136:3)
Block(-1,11,-3,136:2)
Block(-1,11,5,136:3)
Block(-1,12,-2,136:2)
Block(-1,12,4,136:3)
Block(-1,13,-1,136:2)
Block(-1,13,3,136:3)
Block(-1,14,0,136:2)
Block(-1,14,2,136:3)
Block(-1,15,1,126:3)
Block(0,0,-7,2)
Block(0,0,-6,2)
Block(0,0,-5,2)
Block(0,0,-4,3)
Block(0,0,-3,5:5)
Block(0,0,-2,5:5)
Block(0,0,-1,5:5)
Block(0,0,0,5:5)
Block(0,0,1,5:5)
Block(0,0,2,5:5)
Block(0,0,3,5:5)
Block(0,0,4,5:5)
Block(0,0,5,5:5)
Block(0,0,6,3)
Block(0,0,7,2)
Block(0,0,8,2)
Block(0,1,-4,98)
Block(0,1,-3,53:1)
Block(0,1,-2,53:1)
Block(0,1,-1,53:1)
Block(0,1,0,68:3,5-Sign.nbt)
Block(0,1,2,68:2,6-Sign.nbt)
Block(0,1,3,53:1)
Block(0,1,4,53:1)
Block(0,1,5,53:1)
Block(0,1,6,98)
Block(0,2,-4,98)
Block(0,2,6,98)
Block(0,3,-4,98)
Block(0,3,6,98)
Block(0,4,-4,98)
Block(0,4,6,98)
Block(0,5,-4,98)
Block(0,5,6,98)
Block(0,6,-4,98)
Block(0,6,-2,89)
Block(0,6,1,89)
Block(0,6,4,89)
Block(0,6,6,98)
Block(0,7,-4,98)
Block(0,7,-2,85)
Block(0,7,1,85)
Block(0,7,4,85)
Block(0,7,6,98)
Block(0,7,8,136:3)
Block(0,8,-4,98)
Block(0,8,-2,85)
Block(0,8,-1,85)
Block(0,8,0,85)
Block(0,8,1,85)
Block(0,8,2,85)
Block(0,8,3,85)
Block(0,8,4,85)
Block(0,8,6,98)
Block(0,8,7,136:3)
Block(0,9,-4,98)
Block(0,9,1,85)
Block(0,9,6,98)
Block(0,10,-4,136:2)
Block(0,10,1,85)
Block(0,10,6,136:3)
Block(0,11,-3,136:2)
Block(0,11,1,85)
Block(0,11,5,136:3)
Block(0,12,-2,136:2)
Block(0,12,1,85)
Block(0,12,4,136:3)
Block(0,13,-1,136:2)
Block(0,13,1,85)
Block(0,13,3,136:3)
Block(0,14,0,136:2)
Block(0,14,1,85)
Block(0,14,2,136:3)
Block(0,15,1,126:3)
Block(1,0,-7,2)
Block(1,0,-6,2)
Block(1,0,-5,2)
Block(1,0,-4,3)
Block(1,0,-3,5:5)
Block(1,0,-2,5:5)
Block(1,0,-1,5:5)
Block(1,0,0,5:5)
Block(1,0,1,5:5)
Block(1,0,2,5:5)
Block(1,0,3,5:5)
Block(1,0,4,5:5)
Block(1,0,5,5:5)
Block(1,0,6,3)
Block(1,0,7,2)
Block(1,0,8,2)
Block(1,1,-4,98)
Block(1,1,6,98)
Block(1,2,-4,160:14)
Block(1,2,6,98)
Block(1,3,-4,160:14)
Block(1,3,6,98)
Block(1,4,-4,160:14)
Block(1,4,6,98)
Block(1,5,-4,160:14)
Block(1,5,6,98)
Block(1,6,-4,160:14)
Block(1,6,6,98)
Block(1,7,-4,160:14)
Block(1,7,6,98)
Block(1,7,8,136:3)
Block(1,8,-4,160:14)
Block(1,8,6,98)
Block(1,8,7,136:3)
Block(1,9,-4,98)
Block(1,9,6,98)
Block(1,10,-4,136:2)
Block(1,10,6,136:3)
Block(1,11,-3,136:2)
Block(1,11,5,136:3)
Block(1,12,-2,136:2)
Block(1,12,4,136:3)
Block(1,13,-1,136:2)
Block(1,13,3,136:3)
Block(1,14,0,136:2)
Block(1,14,2,136:3)
Block(1,15,1,126:3)
Block(2,0,-7,2)
Block(2,0,-6,2)
Block(2,0,-5,2)
Block(2,0,-4,3)
Block(2,0,-3,5:5)
Block(2,0,-2,5:5)
Block(2,0,-1,5:5)
Block(2,0,0,5:5)
Block(2,0,1,5:5)
Block(2,0,2,5:5)
Block(2,0,3,5:5)
Block(2,0,4,5:5)
Block(2,0,5,5:5)
Block(2,0,6,3)
Block(2,0,7,2)
Block(2,0,8,2)
Block(2,1,-4,98)
Block(2,1,-3,53:1)
Block(2,1,-2,53:1)
Block(2,1,-1,53:1)
Block(2,1,0,68:3,7-Sign.nbt)
Block(2,1,2,68:2,8-Sign.nbt)
Block(2,1,3,53:1)
Block(2,1,4,53:1)
Block(2,1,5,53:1)
Block(2,1,6,98)
Block(2,2,-4,160:14)
Block(2,2,6,98)
Block(2,3,-4,160:14)
Block(2,3,6,98)
Block(2,4,-4,160:14)
Block(2,4,6,98)
Block(2,5,-4,160:14)
Block(2,5,6,98)
Block(2,6,-4,160:14)
Block(2,6,6,98)
Block(2,7,-4,160:14)
Block(2,7,6,98)
Block(2,7,8,136:3)
Block(2,8,-4,160:14)
Block(2,8,6,98)
Block(2,8,7,136:3)
Block(2,9,-4,98)
Block(2,9,6,98)
Block(2,10,-4,136:2)
Block(2,10,6,136:3)
Block(2,11,-3,136:2)
Block(2,11,5,136:3)
Block(2,12,-2,136:2)
Block(2,12,4,136:3)
Block(2,13,-1,136:2)
Block(2,13,3,136:3)
Block(2,14,0,136:2)
Block(2,14,2,136:3)
Block(2,15,1,126:3)
Block(3,0,-7,2)
Block(3,0,-6,2)
Block(3,0,-5,2)
Block(3,0,-4,3)
Block(3,0,-3,5:5)
Block(3,0,-2,5:5)
Block(3,0,-1,5:5)
Block(3,0,0,5:5)
Block(3,0,1,5:5)
Block(3,0,2,5:5)
Block(3,0,3,5:5)
Block(3,0,4,5:5)
Block(3,0,5,5:5)
Block(3,0,6,3)
Block(3,0,7,2)
Block(3,0,8,2)
Block(3,1,-4,98)
Block(3,1,6,98)
Block(3,2,-4,98)
Block(3,2,6,98)
Block(3,3,-4,98)
Block(3,3,6,98)
Block(3,4,-4,98)
Block(3,4,6,98)
Block(3,5,-4,98)
Block(3,5,6,98)
Block(3,6,-4,98)
Block(3,6,6,98)
Block(3,7,-4,98)
Block(3,7,6,98)
Block(3,7,8,136:3)
Block(3,8,-4,98)
Block(3,8,6,98)
Block(3,8,7,136:3)
Block(3,9,-4,98)
Block(3,9,6,98)
Block(3,10,-4,136:2)
Block(3,10,6,136:3)
Block(3,11,-3,136:2)
Block(3,11,5,136:3)
Block(3,12,-2,136:2)
Block(3,12,4,136:3)
Block(3,13,-1,136:2)
Block(3,13,3,136:3)
Block(3,14,0,136:2)
Block(3,14,2,136:3)
Block(3,15,1,126:3)
Block(4,0,-7,2)
Block(4,0,-6,2)
Block(4,0,-5,2)
Block(4,0,-4,3)
Block(4,0,-3,5:5)
Block(4,0,-2,5:5)
Block(4,0,-1,5:5)
Block(4,0,0,5:5)
Block(4,0,1,5:5)
Block(4,0,2,5:5)
Block(4,0,3,5:5)
Block(4,0,4,5:5)
Block(4,0,5,5:5)
Block(4,0,6,3)
Block(4,0,7,2)
Block(4,0,8,2)
Block(4,1,-4,98)
Block(4,1,-3,53:1)
Block(4,1,-2,53:1)
Block(4,1,-1,53:1)
Block(4,1,0,68:3,9-Sign.nbt)
Block(4,1,2,68:2,10-Sign.nbt)
Block(4,1,3,53:1)
Block(4,1,4,53:1)
Block(4,1,5,53:1)
Block(4,1,6,98)
Block(4,2,-4,160:14)
Block(4,2,6,98)
Block(4,3,-4,160:14)
Block(4,3,6,98)
Block(4,4,-4,160:14)
Block(4,4,6,98)
Block(4,5,-4,160:14)
Block(4,5,6,98)
Block(4,6,-4,160:14)
Block(4,6,6,98)
Block(4,7,-4,160:14)
Block(4,7,6,98)
Block(4,7,8,136:3)
Block(4,8,-4,160:14)
Block(4,8,6,98)
Block(4,8,7,136:3)
Block(4,9,-4,98)
Block(4,9,6,98)
Block(4,10,-4,136:2)
Block(4,10,6,136:3)
Block(4,11,-3,136:2)
Block(4,11,5,136:3)
Block(4,12,-2,136:2)
Block(4,12,4,136:3)
Block(4,13,-1,136:2)
Block(4,13,3,136:3)
Block(4,14,0,136:2)
Block(4,14,2,136:3)
Block(4,15,1,126:3)
Block(5,0,-7,2)
Block(5,0,-6,2)
Block(5,0,-5,2)
Block(5,0,-4,3)
Block(5,0,-3,5:5)
Block(5,0,-2,5:5)
Block(5,0,-1,5:5)
Block(5,0,0,5:5)
Block(5,0,1,5:5)
Block(5,0,2,5:5)
Block(5,0,3,5:5)
Block(5,0,4,5:5)
Block(5,0,5,5:5)
Block(5,0,6,3)
Block(5,0,7,2)
Block(5,0,8,2)
Block(5,1,-4,98)
Block(5,1,6,98)
Block(5,2,-4,160:14)
Block(5,2,6,98)
Block(5,3,-4,160:14)
Block(5,3,6,98)
Block(5,4,-4,160:14)
Block(5,4,6,98)
Block(5,5,-4,160:14)
Block(5,5,6,98)
Block(5,6,-4,160:14)
Block(5,6,6,98)
Block(5,7,-4,160:14)
Block(5,7,6,98)
Block(5,7,8,136:3)
Block(5,8,-4,160:14)
Block(5,8,6,98)
Block(5,8,7,136:3)
Block(5,9,-4,98)
Block(5,9,6,98)
Block(5,10,-4,136:2)
Block(5,10,6,136:3)
Block(5,11,-3,136:2)
Block(5,11,5,136:3)
Block(5,12,-2,136:2)
Block(5,12,4,136:3)
Block(5,13,-1,136:2)
Block(5,13,3,136:3)
Block(5,14,0,136:2)
Block(5,14,2,136:3)
Block(5,15,1,126:3)
Block(6,0,-7,2)
Block(6,0,-6,2)
Block(6,0,-5,2)
Block(6,0,-4,3)
Block(6,0,-3,5:5)
Block(6,0,-2,5:5)
Block(6,0,-1,5:5)
Block(6,0,0,5:5)
Block(6,0,1,5:5)
Block(6,0,2,5:5)
Block(6,0,3,5:5)
Block(6,0,4,5:5)
Block(6,0,5,5:5)
Block(6,0,6,3)
Block(6,0,7,3)
Block(6,0,8,3)
Block(6,1,-6,106:8)
Block(6,1,-5,106:8)
Block(6,1,-4,98)
Block(6,1,-3,53:1)
Block(6,1,-2,53:1)
Block(6,1,-1,53:1)
Block(6,1,0,68:3,11-Sign.nbt)
Block(6,1,2,68:2,12-Sign.nbt)
Block(6,1,3,53:1)
Block(6,1,4,53:1)
Block(6,1,5,53:1)
Block(6,1,6,98)
Block(6,1,7,98)
Block(6,1,8,98)
Block(6,2,-6,106:8)
Block(6,2,-5,106:8)
Block(6,2,-4,98)
Block(6,2,6,98)
Block(6,2,7,98)
Block(6,2,8,98)
Block(6,3,-6,106:8)
Block(6,3,-4,98)
Block(6,3,6,98)
Block(6,3,7,98)
Block(6,3,8,98)
Block(6,4,-4,98)
Block(6,4,6,98)
Block(6,4,7,98)
Block(6,4,8,98)
Block(6,5,-4,98)
Block(6,5,6,98)
Block(6,5,7,98)
Block(6,5,8,98)
Block(6,6,-4,98)
Block(6,6,6,98)
Block(6,6,7,98)
Block(6,6,8,35:14)
Block(6,7,-4,98)
Block(6,7,6,98)
Block(6,7,7,35:14)
Block(6,7,8,136:3)
Block(6,8,-4,98)
Block(6,8,6,98)
Block(6,8,7,136:3)
Block(6,9,-4,98)
Block(6,9,6,98)
Block(6,10,-4,136:2)
Block(6,10,6,136:3)
Block(6,11,-3,136:2)
Block(6,11,5,136:3)
Block(6,12,-2,136:2)
Block(6,12,4,136:3)
Block(6,13,-1,136:2)
Block(6,13,3,136:3)
Block(6,14,0,136:2)
Block(6,14,2,136:3)
Block(6,15,1,126:3)
Block(7,0,-7,2)
Block(7,0,-6,3)
Block(7,0,-5,3)
Block(7,0,-4,3)
Block(7,0,-3,5:5)
Block(7,0,-2,5:5)
Block(7,0,-1,5:5)
Block(7,0,0,5:5)
Block(7,0,1,5:5)
Block(7,0,2,5:5)
Block(7,0,3,5:5)
Block(7,0,4,5:5)
Block(7,0,5,5:5)
Block(7,0,6,3)
Block(7,0,7,2)
Block(7,0,8,2)
Block(7,1,-7,106:1)
Block(7,1,-6,98)
Block(7,1,-5,98)
Block(7,1,-4,98)
Block(7,1,6,98)
Block(7,2,-7,106:1)
Block(7,2,-6,98)
Block(7,2,-5,98)
Block(7,2,-4,98)
Block(7,2,6,98)
Block(7,3,-7,106:1)
Block(7,3,-6,98)
Block(7,3,-5,98)
Block(7,3,-4,98)
Block(7,3,6,98)
Block(7,4,-6,98)
Block(7,4,-5,98)
Block(7,4,-4,98)
Block(7,4,6,98)
Block(7,5,-6,98)
Block(7,5,-5,98)
Block(7,5,-4,98)
Block(7,5,6,98)
Block(7,6,-6,35:14)
Block(7,6,-5,35:14)
Block(7,6,-4,98)
Block(7,6,6,98)
Block(7,7,-6,136)
Block(7,7,-5,136)
Block(7,7,-4,98)
Block(7,7,6,98)
Block(7,8,-4,98)
Block(7,8,6,98)
Block(7,9,-4,98)
Block(7,9,6,98)
Block(7,10,-4,136:2)
Block(7,10,6,136:3)
Block(7,11,-3,136:2)
Block(7,11,5,136:3)
Block(7,12,-2,136:2)
Block(7,12,4,136:3)
Block(7,13,-1,136:2)
Block(7,13,3,136:3)
Block(7,14,0,136:2)
Block(7,14,2,136:3)
Block(7,15,1,126:3)

Branch(16,0,0,true,monastery-age-ofC1R0,NORTH,100,0)
Branch(0,0,16,true,monastery-age-ofC0R1,NORTH,100,0)
