

BranchFrequencyGroup: CanOverride:0

CanOverride: true

SmoothRadius: -1

OverrideChildSettings: false

ReplaceAbove:
ReplaceBelow:

MustBeInside: VillageGeneratorStructurePlaceHolder, VillageGeneratorStructuresDelay, VillageGeneratorStructuresDelay2, VillageGeneratorStructuresDelay3, VillageGeneratorStructuresDelay4, VillageGeneratorStructuresDelay5, VillageGeneratorStructuresDelay6, VillageGeneratorStructuresDelay7, VillageGeneratorStructuresDelay8, VillageGeneratorStructuresDelay9, VillageGeneratorStructuresDelay10

Block(-8,0,-7,2)
Block(-8,0,-6,2)
Block(-8,0,-5,2)
Block(-8,0,-4,2)
Block(-7,0,-7,2)
Block(-7,0,-6,2)
Block(-7,0,-5,2)
Block(-7,0,-4,2)
Block(-6,0,-7,2)
Block(-6,0,-6,2)
Block(-6,0,-5,2)
Block(-6,0,-4,2)
Block(-5,0,-7,2)
Block(-5,0,-6,2)
Block(-5,0,-5,2)
Block(-5,0,-4,2)
Block(-4,0,-7,2)
Block(-4,0,-6,2)
Block(-4,0,-5,2)
Block(-4,0,-4,2)
Block(-4,1,-7,106:8)
Block(-4,1,-6,106:8)
Block(-4,2,-6,106:8)
Block(-3,0,-7,3)
Block(-3,0,-6,3)
Block(-3,0,-5,2)
Block(-3,0,-4,2)
Block(-3,1,-7,98)
Block(-3,1,-6,98)
Block(-3,1,-5,106:4)
Block(-3,2,-7,98)
Block(-3,2,-6,98)
Block(-3,2,-5,106:4)
Block(-3,3,-7,98)
Block(-3,3,-6,98)
Block(-3,4,-7,98)
Block(-3,4,-6,35:14)
Block(-3,4,-5,136:3)
Block(-3,5,-7,35:14)
Block(-3,5,-6,136:3)
Block(-3,6,-7,136:3)
Block(-2,0,-7,2)
Block(-2,0,-6,3)
Block(-2,0,-5,2)
Block(-2,0,-4,2)
Block(-2,1,-6,98)
Block(-2,1,-5,106:4)
Block(-2,2,-6,98)
Block(-2,3,-6,98)
Block(-2,4,-6,98)
Block(-2,4,-5,136:3)
Block(-2,5,-6,136:3)
Block(-2,6,-7,136:3)
Block(-1,0,-7,2)
Block(-1,0,-6,3)
Block(-1,0,-5,2)
Block(-1,0,-4,2)
Block(-1,1,-6,98)
Block(-1,2,-6,98)
Block(-1,3,-6,98)
Block(-1,4,-6,98)
Block(-1,4,-5,136:3)
Block(-1,5,-6,136:3)
Block(-1,6,-7,136:3)
Block(0,0,-7,2)
Block(0,0,-6,3)
Block(0,0,-5,2)
Block(0,0,-4,2)
Block(0,1,-6,98)
Block(0,2,-6,160:14)
Block(0,3,-6,98)
Block(0,4,-6,98)
Block(0,4,-5,136:3)
Block(0,5,-6,136:3)
Block(0,6,-7,136:3)
Block(1,0,-7,2)
Block(1,0,-6,3)
Block(1,0,-5,2)
Block(1,0,-4,2)
Block(1,1,-6,98)
Block(1,2,-6,98)
Block(1,3,-6,98)
Block(1,4,-6,98)
Block(1,4,-5,136:3)
Block(1,5,-6,136:3)
Block(1,6,-7,136:3)
Block(2,0,-7,2)
Block(2,0,-6,3)
Block(2,0,-5,2)
Block(2,0,-4,2)
Block(2,1,-6,98)
Block(2,2,-6,98)
Block(2,3,-6,98)
Block(2,4,-6,98)
Block(2,4,-5,136:3)
Block(2,5,-6,136:3)
Block(2,6,-7,136:3)
Block(3,0,-7,2)
Block(3,0,-6,2)
Block(3,0,-5,2)
Block(3,0,-4,2)
Block(3,3,-6,98)
Block(3,4,-6,98)
Block(3,4,-5,136:3)
Block(3,5,-6,136:3)
Block(3,6,-7,136:3)
Block(4,0,-7,2)
Block(4,0,-6,3)
Block(4,0,-5,2)
Block(4,0,-4,2)
Block(4,1,-6,98)
Block(4,2,-6,98)
Block(4,3,-6,98)
Block(4,4,-6,98)
Block(4,4,-5,136:3)
Block(4,5,-6,136:3)
Block(4,6,-7,136:3)
Block(5,0,-7,2)
Block(5,0,-6,3)
Block(5,0,-5,2)
Block(5,0,-4,2)
Block(5,1,-6,98)
Block(5,1,-5,106:4)
Block(5,2,-6,98)
Block(5,3,-6,98)
Block(5,4,-6,98)
Block(5,4,-5,136:3)
Block(5,5,-6,136:3)
Block(5,6,-7,136:3)
Block(6,0,-7,3)
Block(6,0,-6,3)
Block(6,0,-5,2)
Block(6,0,-4,2)
Block(6,1,-7,98)
Block(6,1,-6,98)
Block(6,1,-5,106:4)
Block(6,2,-7,98)
Block(6,2,-6,98)
Block(6,2,-5,106:4)
Block(6,3,-7,98)
Block(6,3,-6,98)
Block(6,4,-7,98)
Block(6,4,-6,35:14)
Block(6,4,-5,136:3)
Block(6,5,-7,35:14)
Block(6,5,-6,136:3)
Block(6,6,-7,136:3)
Block(7,0,-7,2)
Block(7,0,-6,2)
Block(7,0,-5,2)
Block(7,0,-4,2)
Block(7,1,-7,106:2)
Block(7,1,-6,106:2)
Block(7,2,-6,106:2)

Branch(16,0,0,true,monastery-age-ofC1R1,NORTH,100,0)
