

BranchFrequencyGroup: CanOverride:0

CanOverride: true

SmoothRadius: -1

OverrideChildSettings: false

ReplaceAbove:
ReplaceBelow:

MustBeInside: VillageGeneratorStructurePlaceHolder, VillageGeneratorStructuresDelay, VillageGeneratorStructuresDelay2, VillageGeneratorStructuresDelay3, VillageGeneratorStructuresDelay4, VillageGeneratorStructuresDelay5, VillageGeneratorStructuresDelay6, VillageGeneratorStructuresDelay7, VillageGeneratorStructuresDelay8, VillageGeneratorStructuresDelay9, VillageGeneratorStructuresDelay10

Block(-8,0,-7,2)
Block(-8,0,-6,3)
Block(-8,0,-5,5:5)
Block(-8,0,-4,3)
Block(-8,0,-3,5:5)
Block(-8,0,-2,5:5)
Block(-8,0,-1,5:5)
Block(-8,0,0,5:5)
Block(-8,0,1,5:5)
Block(-8,0,2,5:5)
Block(-8,0,3,5:5)
Block(-8,0,4,5:5)
Block(-8,0,5,5:5)
Block(-8,0,6,3)
Block(-8,0,7,2)
Block(-8,0,8,2)
Block(-8,1,-7,106:1)
Block(-8,1,-6,98)
Block(-8,1,-4,98)
Block(-8,1,-3,53:1)
Block(-8,1,-2,53:1)
Block(-8,1,-1,53:1)
Block(-8,1,0,68:3,13-Sign.nbt)
Block(-8,1,2,68:2,14-Sign.nbt)
Block(-8,1,3,53:1)
Block(-8,1,4,53:1)
Block(-8,1,5,53:1)
Block(-8,1,6,98)
Block(-8,2,-7,106:1)
Block(-8,2,-6,98)
Block(-8,2,-4,98)
Block(-8,2,6,98)
Block(-8,3,-6,98)
Block(-8,3,-4,98)
Block(-8,3,6,98)
Block(-8,4,-6,98)
Block(-8,4,-4,98)
Block(-8,4,6,98)
Block(-8,5,-6,98)
Block(-8,5,-4,98)
Block(-8,5,6,98)
Block(-8,6,-6,98)
Block(-8,6,-4,98)
Block(-8,6,6,98)
Block(-8,7,-6,35:14)
Block(-8,7,-5,89)
Block(-8,7,-4,98)
Block(-8,7,6,98)
Block(-8,8,-6,136)
Block(-8,8,-5,136)
Block(-8,8,-4,98)
Block(-8,8,6,98)
Block(-8,9,-4,98)
Block(-8,9,6,98)
Block(-8,10,-4,136:2)
Block(-8,10,6,136:3)
Block(-8,11,-3,136:2)
Block(-8,11,5,136:3)
Block(-8,12,-2,136:2)
Block(-8,12,4,136:3)
Block(-8,13,-1,136:2)
Block(-8,13,3,136:3)
Block(-8,14,0,136:2)
Block(-8,14,2,136:3)
Block(-8,15,1,126:3)
Block(-7,0,-7,2)
Block(-7,0,-6,3)
Block(-7,0,-5,5:5)
Block(-7,0,-4,3)
Block(-7,0,-3,5:5)
Block(-7,0,-2,5:5)
Block(-7,0,-1,5:5)
Block(-7,0,0,5:5)
Block(-7,0,1,5:5)
Block(-7,0,2,5:5)
Block(-7,0,3,5:5)
Block(-7,0,4,5:5)
Block(-7,0,5,5:5)
Block(-7,0,6,3)
Block(-7,0,7,2)
Block(-7,0,8,2)
Block(-7,1,-6,98)
Block(-7,1,-4,98)
Block(-7,1,-3,85)
Block(-7,1,-2,85)
Block(-7,1,-1,85)
Block(-7,1,3,85)
Block(-7,1,4,85)
Block(-7,1,5,85)
Block(-7,1,6,98)
Block(-7,2,-6,98)
Block(-7,2,-4,98)
Block(-7,2,-3,171:12)
Block(-7,2,-2,171:12)
Block(-7,2,-1,171:12)
Block(-7,2,3,171:12)
Block(-7,2,4,171:12)
Block(-7,2,5,171:12)
Block(-7,2,6,98)
Block(-7,3,-6,98)
Block(-7,3,-4,98)
Block(-7,3,6,98)
Block(-7,4,-6,98)
Block(-7,4,-4,98)
Block(-7,4,6,98)
Block(-7,5,-6,98)
Block(-7,5,-4,98)
Block(-7,5,6,98)
Block(-7,6,-6,98)
Block(-7,6,-4,98)
Block(-7,6,-2,89)
Block(-7,6,1,89)
Block(-7,6,4,89)
Block(-7,6,6,98)
Block(-7,7,-6,98)
Block(-7,7,-4,98)
Block(-7,7,-2,85)
Block(-7,7,1,85)
Block(-7,7,4,85)
Block(-7,7,6,98)
Block(-7,8,-6,35:14)
Block(-7,8,-4,98)
Block(-7,8,-2,85)
Block(-7,8,-1,85)
Block(-7,8,0,85)
Block(-7,8,1,85)
Block(-7,8,2,85)
Block(-7,8,3,85)
Block(-7,8,4,85)
Block(-7,8,6,98)
Block(-7,9,-6,136)
Block(-7,9,-5,136)
Block(-7,9,-4,98)
Block(-7,9,1,85)
Block(-7,9,6,98)
Block(-7,10,-4,136:2)
Block(-7,10,1,85)
Block(-7,10,6,136:3)
Block(-7,11,-3,136:2)
Block(-7,11,1,85)
Block(-7,11,5,136:3)
Block(-7,12,-2,136:2)
Block(-7,12,1,85)
Block(-7,12,4,136:3)
Block(-7,13,-1,136:2)
Block(-7,13,1,85)
Block(-7,13,3,136:3)
Block(-7,14,0,136:2)
Block(-7,14,1,85)
Block(-7,14,2,136:3)
Block(-7,15,1,126:3)
Block(-6,0,-7,2)
Block(-6,0,-6,5:5)
Block(-6,0,-5,5:5)
Block(-6,0,-4,5:5)
Block(-6,0,-3,5:5)
Block(-6,0,-2,5:5)
Block(-6,0,-1,5:5)
Block(-6,0,0,5:5)
Block(-6,0,1,5:5)
Block(-6,0,2,5:5)
Block(-6,0,3,5:5)
Block(-6,0,4,5:5)
Block(-6,0,5,5:5)
Block(-6,0,6,3)
Block(-6,0,7,2)
Block(-6,0,8,2)
Block(-6,1,-6,64:7)
Block(-6,1,-4,64:5)
Block(-6,1,6,98)
Block(-6,2,-6,64:8)
Block(-6,2,-4,64:9)
Block(-6,2,6,98)
Block(-6,3,-6,98)
Block(-6,3,-4,98)
Block(-6,3,6,98)
Block(-6,4,-6,98)
Block(-6,4,-4,98)
Block(-6,4,6,98)
Block(-6,5,-6,35:14)
Block(-6,5,-4,98)
Block(-6,5,6,98)
Block(-6,6,-6,35:14)
Block(-6,6,-4,98)
Block(-6,6,6,98)
Block(-6,7,-6,98)
Block(-6,7,-4,98)
Block(-6,7,6,98)
Block(-6,8,-6,98)
Block(-6,8,-4,98)
Block(-6,8,6,98)
Block(-6,9,-6,35:14)
Block(-6,9,-5,89)
Block(-6,9,-4,98)
Block(-6,9,6,98)
Block(-6,10,-6,136)
Block(-6,10,-5,136)
Block(-6,10,-4,136:2)
Block(-6,10,6,136:3)
Block(-6,11,-3,136:2)
Block(-6,11,5,136:3)
Block(-6,12,-2,136:2)
Block(-6,12,4,136:3)
Block(-6,13,-1,136:2)
Block(-6,13,3,136:3)
Block(-6,14,0,136:2)
Block(-6,14,2,136:3)
Block(-6,15,1,126:3)
Block(-5,0,-7,2)
Block(-5,0,-6,5:5)
Block(-5,0,-5,5:5)
Block(-5,0,-4,5:5)
Block(-5,0,-3,5:5)
Block(-5,0,-2,5:5)
Block(-5,0,-1,5:5)
Block(-5,0,0,5:5)
Block(-5,0,1,5:5)
Block(-5,0,2,5:5)
Block(-5,0,3,5:5)
Block(-5,0,4,5:5)
Block(-5,0,5,5:5)
Block(-5,0,6,3)
Block(-5,0,7,2)
Block(-5,0,8,2)
Block(-5,1,-6,64:7)
Block(-5,1,-4,64:5)
Block(-5,1,6,98)
Block(-5,2,-6,64:9)
Block(-5,2,-4,64:8)
Block(-5,2,6,98)
Block(-5,3,-6,98)
Block(-5,3,-4,98)
Block(-5,3,6,98)
Block(-5,4,-6,98)
Block(-5,4,-4,98)
Block(-5,4,6,98)
Block(-5,5,-6,35:14)
Block(-5,5,-4,98)
Block(-5,5,6,98)
Block(-5,6,-6,35:14)
Block(-5,6,-4,98)
Block(-5,6,6,98)
Block(-5,7,-6,98)
Block(-5,7,-4,98)
Block(-5,7,6,98)
Block(-5,8,-6,98)
Block(-5,8,-4,98)
Block(-5,8,6,98)
Block(-5,9,-6,35:14)
Block(-5,9,-5,89)
Block(-5,9,-4,98)
Block(-5,9,6,98)
Block(-5,10,-6,136:1)
Block(-5,10,-5,136:1)
Block(-5,10,-4,136:2)
Block(-5,10,6,136:3)
Block(-5,11,-3,136:2)
Block(-5,11,5,136:3)
Block(-5,12,-2,136:2)
Block(-5,12,4,136:3)
Block(-5,13,-1,136:2)
Block(-5,13,3,136:3)
Block(-5,14,0,136:2)
Block(-5,14,2,136:3)
Block(-5,15,1,126:3)
Block(-4,0,-7,2)
Block(-4,0,-6,3)
Block(-4,0,-5,5:5)
Block(-4,0,-4,3)
Block(-4,0,-3,5:5)
Block(-4,0,-2,5:5)
Block(-4,0,-1,5:5)
Block(-4,0,0,5:5)
Block(-4,0,1,5:5)
Block(-4,0,2,5:5)
Block(-4,0,3,5:5)
Block(-4,0,4,5:5)
Block(-4,0,5,5:5)
Block(-4,0,6,3)
Block(-4,0,7,2)
Block(-4,0,8,2)
Block(-4,1,-6,98)
Block(-4,1,-4,98)
Block(-4,1,4,85)
Block(-4,1,5,53:2)
Block(-4,1,6,98)
Block(-4,1,7,106:4)
Block(-4,2,-6,98)
Block(-4,2,-4,98)
Block(-4,2,4,171:12)
Block(-4,2,6,98)
Block(-4,3,-6,98)
Block(-4,3,-4,98)
Block(-4,3,6,98)
Block(-4,4,-6,98)
Block(-4,4,-4,98)
Block(-4,4,6,98)
Block(-4,5,-6,98)
Block(-4,5,-4,98)
Block(-4,5,6,98)
Block(-4,6,-6,98)
Block(-4,6,-4,98)
Block(-4,6,6,98)
Block(-4,7,-6,98)
Block(-4,7,-4,98)
Block(-4,7,6,98)
Block(-4,8,-6,35:14)
Block(-4,8,-4,98)
Block(-4,8,6,98)
Block(-4,9,-6,136:1)
Block(-4,9,-5,136:1)
Block(-4,9,-4,98)
Block(-4,9,6,98)
Block(-4,10,-4,136:2)
Block(-4,10,6,136:3)
Block(-4,11,-3,136:2)
Block(-4,11,5,136:3)
Block(-4,12,-2,136:2)
Block(-4,12,4,136:3)
Block(-4,13,-1,136:2)
Block(-4,13,3,136:3)
Block(-4,14,0,136:2)
Block(-4,14,2,136:3)
Block(-4,15,1,126:3)
Block(-3,0,-7,2)
Block(-3,0,-6,3)
Block(-3,0,-5,5:5)
Block(-3,0,-4,3)
Block(-3,0,-3,5:5)
Block(-3,0,-2,5:5)
Block(-3,0,-1,5:5)
Block(-3,0,0,5:5)
Block(-3,0,1,5:5)
Block(-3,0,2,5:5)
Block(-3,0,3,5:5)
Block(-3,0,4,5:5)
Block(-3,0,5,5:5)
Block(-3,0,6,3)
Block(-3,0,7,2)
Block(-3,0,8,2)
Block(-3,1,-7,106:1)
Block(-3,1,-6,98)
Block(-3,1,-4,98)
Block(-3,1,4,85)
Block(-3,1,5,53:2)
Block(-3,1,6,98)
Block(-3,1,7,106:4)
Block(-3,2,-7,106:1)
Block(-3,2,-6,98)
Block(-3,2,-4,98)
Block(-3,2,4,171:12)
Block(-3,2,6,98)
Block(-3,2,7,106:4)
Block(-3,3,-6,98)
Block(-3,3,-4,98)
Block(-3,3,6,98)
Block(-3,4,-6,98)
Block(-3,4,-4,98)
Block(-3,4,4,89)
Block(-3,4,6,98)
Block(-3,5,-6,98)
Block(-3,5,-4,98)
Block(-3,5,4,85)
Block(-3,5,5,85)
Block(-3,5,6,98)
Block(-3,6,-6,98)
Block(-3,6,-4,98)
Block(-3,6,6,98)
Block(-3,7,-6,35:14)
Block(-3,7,-5,89)
Block(-3,7,-4,98)
Block(-3,7,6,98)
Block(-3,8,-6,136:1)
Block(-3,8,-5,136:1)
Block(-3,8,-4,98)
Block(-3,8,6,98)
Block(-3,9,-4,98)
Block(-3,9,6,98)
Block(-3,10,-4,136:2)
Block(-3,10,6,136:3)
Block(-3,11,-3,136:2)
Block(-3,11,5,136:3)
Block(-3,12,-2,136:2)
Block(-3,12,4,136:3)
Block(-3,13,-1,136:2)
Block(-3,13,3,136:3)
Block(-3,14,0,136:2)
Block(-3,14,2,136:3)
Block(-3,15,1,126:3)
Block(-2,0,-7,2)
Block(-2,0,-6,3)
Block(-2,0,-5,3)
Block(-2,0,-4,3)
Block(-2,0,-3,5:5)
Block(-2,0,-2,5:5)
Block(-2,0,-1,5:5)
Block(-2,0,0,5:5)
Block(-2,0,1,5:5)
Block(-2,0,2,5:5)
Block(-2,0,3,5:5)
Block(-2,0,4,5:5)
Block(-2,0,5,5:5)
Block(-2,0,6,3)
Block(-2,0,7,2)
Block(-2,0,8,2)
Block(-2,1,-7,106:1)
Block(-2,1,-6,98)
Block(-2,1,-5,98)
Block(-2,1,-4,98)
Block(-2,1,4,85)
Block(-2,1,5,53:2)
Block(-2,1,6,98)
Block(-2,1,7,106:4)
Block(-2,2,-7,106:1)
Block(-2,2,-6,98)
Block(-2,2,-5,98)
Block(-2,2,-4,98)
Block(-2,2,4,171:12)
Block(-2,2,6,98)
Block(-2,2,7,106:4)
Block(-2,3,-7,106:1)
Block(-2,3,-6,98)
Block(-2,3,-5,98)
Block(-2,3,-4,98)
Block(-2,3,6,98)
Block(-2,3,7,106:4)
Block(-2,4,-6,98)
Block(-2,4,-5,98)
Block(-2,4,-4,98)
Block(-2,4,6,98)
Block(-2,4,7,106:4)
Block(-2,5,-6,98)
Block(-2,5,-5,98)
Block(-2,5,-4,98)
Block(-2,5,6,98)
Block(-2,6,-6,35:14)
Block(-2,6,-5,35:14)
Block(-2,6,-4,98)
Block(-2,6,6,98)
Block(-2,7,-6,136:1)
Block(-2,7,-5,136:1)
Block(-2,7,-4,98)
Block(-2,7,6,98)
Block(-2,8,-4,98)
Block(-2,8,6,98)
Block(-2,9,-4,98)
Block(-2,9,6,98)
Block(-2,10,-4,136:2)
Block(-2,10,6,136:3)
Block(-2,11,-3,136:2)
Block(-2,11,5,136:3)
Block(-2,12,-2,136:2)
Block(-2,12,4,136:3)
Block(-2,13,-1,136:2)
Block(-2,13,3,136:3)
Block(-2,14,0,136:2)
Block(-2,14,2,136:3)
Block(-2,15,1,126:3)
Block(-1,0,-7,2)
Block(-1,0,-6,2)
Block(-1,0,-5,2)
Block(-1,0,-4,3)
Block(-1,0,-3,5:5)
Block(-1,0,-2,5:5)
Block(-1,0,-1,5:5)
Block(-1,0,0,5:5)
Block(-1,0,1,5:5)
Block(-1,0,2,5:5)
Block(-1,0,3,5:5)
Block(-1,0,4,3)
Block(-1,0,5,3)
Block(-1,0,6,3)
Block(-1,0,7,2)
Block(-1,0,8,2)
Block(-1,1,-6,106:2)
Block(-1,1,-5,106:2)
Block(-1,1,-4,98)
Block(-1,1,-3,125)
Block(-1,1,-2,125)
Block(-1,1,-1,125)
Block(-1,1,0,125)
Block(-1,1,2,125)
Block(-1,1,3,125)
Block(-1,1,4,125)
Block(-1,1,5,125)
Block(-1,1,6,98)
Block(-1,1,7,106:4)
Block(-1,2,-6,106:2)
Block(-1,2,-5,106:2)
Block(-1,2,-4,98)
Block(-1,2,-3,125)
Block(-1,2,-2,125)
Block(-1,2,-1,125)
Block(-1,2,0,125)
Block(-1,2,2,125)
Block(-1,2,3,125)
Block(-1,2,4,125)
Block(-1,2,5,125)
Block(-1,2,6,98)
Block(-1,2,7,106:4)
Block(-1,3,-6,106:2)
Block(-1,3,-4,98)
Block(-1,3,-3,125)
Block(-1,3,-2,125)
Block(-1,3,-1,125)
Block(-1,3,0,125)
Block(-1,3,1,5:5)
Block(-1,3,2,125)
Block(-1,3,3,125)
Block(-1,3,4,125)
Block(-1,3,5,125)
Block(-1,3,6,98)
Block(-1,3,7,106:4)
Block(-1,4,-4,98)
Block(-1,4,-3,125)
Block(-1,4,-2,125)
Block(-1,4,-1,125)
Block(-1,4,0,5:1)
Block(-1,4,1,5:5)
Block(-1,4,2,5:1)
Block(-1,4,3,125)
Block(-1,4,4,125)
Block(-1,4,5,125)
Block(-1,4,6,98)
Block(-1,4,7,106:4)
Block(-1,5,-4,98)
Block(-1,5,-3,125)
Block(-1,5,-2,125)
Block(-1,5,-1,125)
Block(-1,5,0,5:1)
Block(-1,5,1,5:5)
Block(-1,5,2,5:1)
Block(-1,5,3,125)
Block(-1,5,4,125)
Block(-1,5,5,125)
Block(-1,5,6,98)
Block(-1,6,-4,98)
Block(-1,6,-3,125)
Block(-1,6,-2,125)
Block(-1,6,-1,125)
Block(-1,6,0,5:1)
Block(-1,6,1,5:5)
Block(-1,6,2,5:1)
Block(-1,6,3,125)
Block(-1,6,4,125)
Block(-1,6,5,125)
Block(-1,6,6,98)
Block(-1,7,-4,98)
Block(-1,7,-3,125)
Block(-1,7,-2,125)
Block(-1,7,-1,125)
Block(-1,7,0,5:1)
Block(-1,7,1,5:5)
Block(-1,7,2,5:1)
Block(-1,7,3,125)
Block(-1,7,4,125)
Block(-1,7,5,125)
Block(-1,7,6,98)
Block(-1,8,-4,98)
Block(-1,8,-3,125)
Block(-1,8,-2,125)
Block(-1,8,-1,5:1)
Block(-1,8,0,5:1)
Block(-1,8,1,5:5)
Block(-1,8,2,5:1)
Block(-1,8,3,5:1)
Block(-1,8,4,125)
Block(-1,8,5,125)
Block(-1,8,6,98)
Block(-1,9,-4,98)
Block(-1,9,-3,125)
Block(-1,9,-2,5:5)
Block(-1,9,-1,5:5)
Block(-1,9,0,5:5)
Block(-1,9,1,5:5)
Block(-1,9,2,5:5)
Block(-1,9,3,5:5)
Block(-1,9,4,5:5)
Block(-1,9,5,125)
Block(-1,9,6,98)
Block(-1,10,-4,98)
Block(-1,10,-3,125)
Block(-1,10,-2,125)
Block(-1,10,-1,5:1)
Block(-1,10,0,5:1)
Block(-1,10,1,5:5)
Block(-1,10,2,5:1)
Block(-1,10,3,5:1)
Block(-1,10,4,125)
Block(-1,10,5,125)
Block(-1,10,6,136:3)
Block(-1,11,-4,98)
Block(-1,11,-3,98)
Block(-1,11,-2,125)
Block(-1,11,-1,125)
Block(-1,11,0,5:1)
Block(-1,11,1,5:5)
Block(-1,11,2,5:1)
Block(-1,11,3,125)
Block(-1,11,4,125)
Block(-1,11,5,136:3)
Block(-1,12,-4,98)
Block(-1,12,-3,98)
Block(-1,12,-2,98)
Block(-1,12,-1,125)
Block(-1,12,0,125)
Block(-1,12,1,5:5)
Block(-1,12,2,125)
Block(-1,12,3,125)
Block(-1,12,4,98)
Block(-1,13,-4,98)
Block(-1,13,-3,98)
Block(-1,13,-2,98)
Block(-1,13,-1,98)
Block(-1,13,0,125)
Block(-1,13,1,125)
Block(-1,13,2,125)
Block(-1,13,3,98)
Block(-1,13,4,98)
Block(-1,14,-4,98)
Block(-1,14,-3,98)
Block(-1,14,-2,98)
Block(-1,14,-1,98)
Block(-1,14,0,98)
Block(-1,14,1,125)
Block(-1,14,2,98)
Block(-1,14,3,98)
Block(-1,14,4,98)
Block(-1,15,-4,98)
Block(-1,15,-3,98)
Block(-1,15,0,98)
Block(-1,15,3,43:5)
Block(-1,15,4,98)
Block(-1,16,-4,98)
Block(-1,16,-3,98)
Block(-1,16,0,98)
Block(-1,16,3,98)
Block(-1,16,4,98)
Block(-1,17,-4,98)
Block(-1,17,-3,98)
Block(-1,17,0,98)
Block(-1,17,1,109:7)
Block(-1,17,2,109:6)
Block(-1,17,3,98)
Block(-1,17,4,98)
Block(-1,18,-4,98)
Block(-1,18,-3,98)
Block(-1,18,-2,109:7)
Block(-1,18,-1,109:6)
Block(-1,18,0,98)
Block(-1,18,1,98)
Block(-1,18,2,98)
Block(-1,18,3,98)
Block(-1,18,4,98)
Block(-1,19,-4,98)
Block(-1,19,-3,98)
Block(-1,19,-2,98)
Block(-1,19,-1,98)
Block(-1,19,0,98)
Block(-1,19,1,98)
Block(-1,19,2,98)
Block(-1,19,3,98)
Block(-1,19,4,98)
Block(-1,20,-4,98)
Block(-1,20,-3,98)
Block(-1,20,-2,98)
Block(-1,20,-1,98)
Block(-1,20,0,98)
Block(-1,20,1,98)
Block(-1,20,2,98)
Block(-1,20,3,98)
Block(-1,20,4,98)
Block(-1,21,-4,98)
Block(-1,21,-3,98)
Block(-1,21,-2,98)
Block(-1,21,-1,109:3)
Block(-1,21,1,109:2)
Block(-1,21,2,98)
Block(-1,21,3,98)
Block(-1,21,4,98)
Block(-1,22,-4,98)
Block(-1,22,-3,98)
Block(-1,22,-2,109:3)
Block(-1,22,2,109:2)
Block(-1,22,3,98)
Block(-1,22,4,98)
Block(-1,23,-4,98)
Block(-1,23,-3,109:3)
Block(-1,23,3,109:2)
Block(-1,23,4,98)
Block(-1,24,-4,44:5)
Block(-1,24,4,44:5)
Block(0,0,-7,2)
Block(0,0,-6,2)
Block(0,0,-5,2)
Block(0,0,-4,3)
Block(0,0,-3,5:5)
Block(0,0,-2,5:5)
Block(0,0,-1,5:5)
Block(0,0,0,5:5)
Block(0,0,1,5:5)
Block(0,0,2,5:5)
Block(0,0,3,5:5)
Block(0,0,4,3)
Block(0,0,5,3)
Block(0,0,6,3)
Block(0,0,7,2)
Block(0,0,8,2)
Block(0,1,-4,98)
Block(0,1,-3,84:1,15-RecordPlayer.nbt)
Block(0,1,3,65:2)
Block(0,1,4,98)
Block(0,1,5,98)
Block(0,1,6,98)
Block(0,1,7,106:4)
Block(0,2,-4,98)
Block(0,2,3,65:2)
Block(0,2,4,98)
Block(0,2,5,98)
Block(0,2,6,98)
Block(0,2,7,106:4)
Block(0,3,-4,98)
Block(0,3,3,65:2)
Block(0,3,4,98)
Block(0,3,5,98)
Block(0,3,6,98)
Block(0,3,7,106:4)
Block(0,4,-4,98)
Block(0,4,3,65:2)
Block(0,4,4,98)
Block(0,4,5,98)
Block(0,4,6,98)
Block(0,4,7,106:4)
Block(0,5,-4,98)
Block(0,5,3,65:2)
Block(0,5,4,98)
Block(0,5,5,98)
Block(0,5,6,98)
Block(0,5,7,106:4)
Block(0,6,-4,98)
Block(0,6,3,65:2)
Block(0,6,4,98)
Block(0,6,5,98)
Block(0,6,6,98)
Block(0,7,-4,98)
Block(0,7,3,65:2)
Block(0,7,4,98)
Block(0,7,5,98)
Block(0,7,6,98)
Block(0,8,-4,98)
Block(0,8,3,65:2)
Block(0,8,4,98)
Block(0,8,5,98)
Block(0,8,6,98)
Block(0,9,-4,98)
Block(0,9,3,65:2)
Block(0,9,4,98)
Block(0,9,5,98)
Block(0,9,6,98)
Block(0,10,-4,98)
Block(0,10,3,65:2)
Block(0,10,4,98)
Block(0,10,5,98)
Block(0,10,6,136:3)
Block(0,11,-4,98)
Block(0,11,3,65:2)
Block(0,11,4,98)
Block(0,11,5,136:3)
Block(0,12,-4,98)
Block(0,12,3,65:2)
Block(0,12,4,98)
Block(0,13,-4,98)
Block(0,13,-3,98)
Block(0,13,-2,98)
Block(0,13,-1,98)
Block(0,13,0,98)
Block(0,13,1,98)
Block(0,13,2,98)
Block(0,13,3,65:2)
Block(0,13,4,98)
Block(0,14,-4,98)
Block(0,14,4,98)
Block(0,15,-4,98)
Block(0,15,4,98)
Block(0,16,-4,98)
Block(0,16,4,98)
Block(0,17,-4,98)
Block(0,17,4,98)
Block(0,18,-4,98)
Block(0,18,4,98)
Block(0,19,-4,98)
Block(0,19,0,85)
Block(0,19,4,98)
Block(0,20,-4,98)
Block(0,20,4,98)
Block(0,21,-4,98)
Block(0,21,-3,136:2)
Block(0,21,-2,136)
Block(0,21,-1,136)
Block(0,21,0,136)
Block(0,21,1,136)
Block(0,21,2,136)
Block(0,21,3,136:3)
Block(0,21,4,98)
Block(0,22,-4,98)
Block(0,22,4,98)
Block(0,23,-4,109:1)
Block(0,23,4,109:1)
Block(1,0,-7,2)
Block(1,0,-6,2)
Block(1,0,-5,2)
Block(1,0,-4,3)
Block(1,0,-3,5:5)
Block(1,0,-2,5:5)
Block(1,0,-1,5:5)
Block(1,0,0,5:5)
Block(1,0,1,5:5)
Block(1,0,2,5:5)
Block(1,0,3,5:5)
Block(1,0,4,3)
Block(1,0,5,2)
Block(1,0,6,2)
Block(1,0,7,2)
Block(1,0,8,2)
Block(1,1,-4,98)
Block(1,1,-3,54:3,16-Chest.nbt)
Block(1,1,3,65:2)
Block(1,1,4,98)
Block(1,1,5,106:2)
Block(1,1,6,106:2)
Block(1,2,-4,98)
Block(1,2,3,65:2)
Block(1,2,4,98)
Block(1,2,5,106:2)
Block(1,2,6,106:2)
Block(1,3,-4,98)
Block(1,3,3,65:2)
Block(1,3,4,98)
Block(1,3,5,106:2)
Block(1,3,6,106:2)
Block(1,4,-4,98)
Block(1,4,3,65:2)
Block(1,4,4,98)
Block(1,4,5,106:2)
Block(1,4,6,106:2)
Block(1,5,-4,98)
Block(1,5,3,65:2)
Block(1,5,4,98)
Block(1,5,6,106:2)
Block(1,6,-4,98)
Block(1,6,3,65:2)
Block(1,6,4,98)
Block(1,7,-4,98)
Block(1,7,3,65:2)
Block(1,7,4,98)
Block(1,8,-4,98)
Block(1,8,3,65:2)
Block(1,8,4,98)
Block(1,9,-4,98)
Block(1,9,3,65:2)
Block(1,9,4,98)
Block(1,10,-4,98)
Block(1,10,3,65:2)
Block(1,10,4,98)
Block(1,11,-4,98)
Block(1,11,3,65:2)
Block(1,11,4,98)
Block(1,12,-4,98)
Block(1,12,3,65:2)
Block(1,12,4,98)
Block(1,13,-4,98)
Block(1,13,-3,98)
Block(1,13,-2,98)
Block(1,13,-1,98)
Block(1,13,0,98)
Block(1,13,1,98)
Block(1,13,2,98)
Block(1,13,3,65:2)
Block(1,13,4,98)
Block(1,14,-4,98)
Block(1,14,4,98)
Block(1,16,0,41)
Block(1,17,-4,109:5)
Block(1,17,0,41)
Block(1,17,4,109:5)
Block(1,18,-4,98)
Block(1,18,4,98)
Block(1,19,-4,98)
Block(1,19,0,85)
Block(1,19,4,98)
Block(1,20,-4,98)
Block(1,20,4,98)
Block(1,21,-4,98)
Block(1,21,-3,136:2)
Block(1,21,3,136:3)
Block(1,21,4,98)
Block(1,22,-4,109:1)
Block(1,22,-2,136)
Block(1,22,-1,136)
Block(1,22,0,136)
Block(1,22,1,136)
Block(1,22,2,136)
Block(1,22,4,109:1)
Block(2,0,-7,2)
Block(2,0,-6,2)
Block(2,0,-5,2)
Block(2,0,-4,3)
Block(2,0,-3,3)
Block(2,0,-2,5:5)
Block(2,0,-1,5:5)
Block(2,0,0,5:5)
Block(2,0,1,5:5)
Block(2,0,2,5:5)
Block(2,0,3,5:5)
Block(2,0,4,3)
Block(2,0,5,2)
Block(2,0,6,2)
Block(2,0,7,2)
Block(2,0,8,2)
Block(2,1,-4,98)
Block(2,1,-3,47)
Block(2,1,-2,47)
Block(2,1,-1,47)
Block(2,1,1,47)
Block(2,1,2,47)
Block(2,1,3,47)
Block(2,1,4,98)
Block(2,2,-4,98)
Block(2,2,-3,47)
Block(2,2,-2,47)
Block(2,2,-1,47)
Block(2,2,1,47)
Block(2,2,2,47)
Block(2,2,3,47)
Block(2,2,4,98)
Block(2,3,-4,98)
Block(2,3,-3,47)
Block(2,3,-2,47)
Block(2,3,-1,47)
Block(2,3,1,47)
Block(2,3,2,47)
Block(2,3,3,47)
Block(2,3,4,98)
Block(2,4,-4,98)
Block(2,4,-3,47)
Block(2,4,-2,47)
Block(2,4,-1,47)
Block(2,4,1,47)
Block(2,4,2,47)
Block(2,4,3,47)
Block(2,4,4,98)
Block(2,5,-4,98)
Block(2,5,4,98)
Block(2,6,-4,98)
Block(2,6,4,98)
Block(2,7,-4,98)
Block(2,7,4,98)
Block(2,8,-4,98)
Block(2,8,0,89)
Block(2,8,4,98)
Block(2,9,-4,98)
Block(2,9,0,85)
Block(2,9,4,98)
Block(2,10,-4,98)
Block(2,10,4,98)
Block(2,11,-4,98)
Block(2,11,4,98)
Block(2,12,-4,98)
Block(2,12,4,98)
Block(2,13,-4,98)
Block(2,13,-3,98)
Block(2,13,-2,98)
Block(2,13,-1,98)
Block(2,13,0,98)
Block(2,13,1,98)
Block(2,13,2,98)
Block(2,13,3,98)
Block(2,13,4,98)
Block(2,14,-4,98)
Block(2,14,4,98)
Block(2,16,-1,41)
Block(2,16,1,41)
Block(2,17,-4,109:4)
Block(2,17,-1,41)
Block(2,17,1,41)
Block(2,17,4,109:4)
Block(2,18,-4,98)
Block(2,18,0,41)
Block(2,18,4,98)
Block(2,19,-4,98)
Block(2,19,0,85)
Block(2,19,4,98)
Block(2,20,-4,98)
Block(2,20,4,98)
Block(2,21,-4,109:1)
Block(2,21,-3,136:2)
Block(2,21,3,136:3)
Block(2,21,4,109:1)
Block(2,22,-2,136:2)
Block(2,22,2,136:3)
Block(2,23,-1,136:2)
Block(2,23,0,136)
Block(2,23,1,136:3)
Block(3,0,-7,2)
Block(3,0,-6,2)
Block(3,0,-5,2)
Block(3,0,-4,3)
Block(3,0,-3,5:5)
Block(3,0,-2,5:5)
Block(3,0,-1,5:5)
Block(3,0,0,5:5)
Block(3,0,1,5:5)
Block(3,0,2,5:5)
Block(3,0,3,5:5)
Block(3,0,4,3)
Block(3,0,5,2)
Block(3,0,6,2)
Block(3,0,7,2)
Block(3,0,8,2)
Block(3,1,-4,98)
Block(3,1,-3,47)
Block(3,1,-2,47)
Block(3,1,2,47)
Block(3,1,3,47)
Block(3,1,4,98)
Block(3,2,-4,98)
Block(3,2,-3,47)
Block(3,2,-2,47)
Block(3,2,2,47)
Block(3,2,3,47)
Block(3,2,4,98)
Block(3,3,-4,98)
Block(3,3,-3,47)
Block(3,3,-2,47)
Block(3,3,2,47)
Block(3,3,3,47)
Block(3,3,4,98)
Block(3,4,-4,98)
Block(3,4,-3,47)
Block(3,4,-2,47)
Block(3,4,2,47)
Block(3,4,3,47)
Block(3,4,4,98)
Block(3,5,-4,98)
Block(3,5,4,98)
Block(3,6,-4,98)
Block(3,6,4,98)
Block(3,7,-4,98)
Block(3,7,4,98)
Block(3,8,-4,98)
Block(3,8,4,98)
Block(3,9,-4,98)
Block(3,9,0,85)
Block(3,9,4,98)
Block(3,10,-4,98)
Block(3,10,4,98)
Block(3,11,-4,98)
Block(3,11,4,98)
Block(3,12,-4,98)
Block(3,12,4,98)
Block(3,13,-4,98)
Block(3,13,-3,98)
Block(3,13,-2,98)
Block(3,13,-1,98)
Block(3,13,0,98)
Block(3,13,1,98)
Block(3,13,2,98)
Block(3,13,3,98)
Block(3,13,4,98)
Block(3,14,-4,98)
Block(3,14,4,98)
Block(3,15,-4,98)
Block(3,15,0,41)
Block(3,15,4,98)
Block(3,16,-4,98)
Block(3,16,-2,41)
Block(3,16,0,85)
Block(3,16,2,41)
Block(3,16,4,98)
Block(3,17,-4,98)
Block(3,17,-2,41)
Block(3,17,0,85)
Block(3,17,2,41)
Block(3,17,4,98)
Block(3,18,-4,98)
Block(3,18,-1,41)
Block(3,18,0,41)
Block(3,18,1,41)
Block(3,18,4,98)
Block(3,19,-4,98)
Block(3,19,0,85)
Block(3,19,4,98)
Block(3,20,-4,98)
Block(3,20,4,98)
Block(3,21,-3,136:2)
Block(3,21,3,136:3)
Block(3,22,-2,136:2)
Block(3,22,2,136:3)
Block(3,23,-1,136:2)
Block(3,23,1,136:3)
Block(3,24,0,126:3)
Block(4,0,-7,2)
Block(4,0,-6,2)
Block(4,0,-5,2)
Block(4,0,-4,3)
Block(4,0,-3,5:5)
Block(4,0,-2,5:5)
Block(4,0,-1,5:5)
Block(4,0,0,5:5)
Block(4,0,1,5:5)
Block(4,0,2,5:5)
Block(4,0,3,5:5)
Block(4,0,4,3)
Block(4,0,5,2)
Block(4,0,6,2)
Block(4,0,7,2)
Block(4,0,8,2)
Block(4,1,-4,98)
Block(4,1,-3,47)
Block(4,1,-2,47)
Block(4,1,0,116)
Block(4,1,2,47)
Block(4,1,3,47)
Block(4,1,4,98)
Block(4,2,-4,98)
Block(4,2,-3,47)
Block(4,2,-2,47)
Block(4,2,2,47)
Block(4,2,3,47)
Block(4,2,4,98)
Block(4,3,-4,98)
Block(4,3,-3,47)
Block(4,3,-2,47)
Block(4,3,2,47)
Block(4,3,3,47)
Block(4,3,4,98)
Block(4,4,-4,98)
Block(4,4,-3,47)
Block(4,4,-2,47)
Block(4,4,2,47)
Block(4,4,3,47)
Block(4,4,4,98)
Block(4,5,-4,98)
Block(4,5,4,98)
Block(4,6,-4,98)
Block(4,6,4,98)
Block(4,7,-4,98)
Block(4,7,0,89)
Block(4,7,4,98)
Block(4,8,-4,98)
Block(4,8,-2,89)
Block(4,8,0,85)
Block(4,8,2,89)
Block(4,8,4,98)
Block(4,9,-4,98)
Block(4,9,-2,85)
Block(4,9,-1,85)
Block(4,9,0,85)
Block(4,9,1,85)
Block(4,9,2,85)
Block(4,9,4,98)
Block(4,10,-4,98)
Block(4,10,0,85)
Block(4,10,4,98)
Block(4,11,-4,98)
Block(4,11,0,85)
Block(4,11,4,98)
Block(4,12,-4,98)
Block(4,12,0,85)
Block(4,12,4,98)
Block(4,13,-4,98)
Block(4,13,-3,98)
Block(4,13,-2,98)
Block(4,13,-1,98)
Block(4,13,0,98)
Block(4,13,1,98)
Block(4,13,2,98)
Block(4,13,3,98)
Block(4,13,4,98)
Block(4,14,-4,98)
Block(4,14,4,98)
Block(4,16,-1,41)
Block(4,16,1,41)
Block(4,17,-4,109:5)
Block(4,17,-1,41)
Block(4,17,1,41)
Block(4,17,4,109:5)
Block(4,18,-4,98)
Block(4,18,0,41)
Block(4,18,4,98)
Block(4,19,-4,98)
Block(4,19,0,85)
Block(4,19,4,98)
Block(4,20,-4,98)
Block(4,20,4,98)
Block(4,21,-4,109)
Block(4,21,-3,136:2)
Block(4,21,3,136:3)
Block(4,21,4,109)
Block(4,22,-2,136:2)
Block(4,22,2,136:3)
Block(4,23,-1,136:2)
Block(4,23,0,136:1)
Block(4,23,1,136:1)
Block(5,0,-7,2)
Block(5,0,-6,2)
Block(5,0,-5,2)
Block(5,0,-4,3)
Block(5,0,-3,3)
Block(5,0,-2,5:5)
Block(5,0,-1,5:5)
Block(5,0,0,5:5)
Block(5,0,1,5:5)
Block(5,0,2,5:5)
Block(5,0,3,5:5)
Block(5,0,4,3)
Block(5,0,5,2)
Block(5,0,6,2)
Block(5,0,7,2)
Block(5,0,8,2)
Block(5,1,-5,106:1)
Block(5,1,-4,98)
Block(5,1,-3,47)
Block(5,1,-2,47)
Block(5,1,2,47)
Block(5,1,3,47)
Block(5,1,4,98)
Block(5,1,5,106:4)
Block(5,2,-5,106:1)
Block(5,2,-4,98)
Block(5,2,-3,47)
Block(5,2,-2,47)
Block(5,2,2,47)
Block(5,2,3,47)
Block(5,2,4,98)
Block(5,2,5,106:4)
Block(5,3,-4,98)
Block(5,3,-3,47)
Block(5,3,-2,47)
Block(5,3,2,47)
Block(5,3,3,47)
Block(5,3,4,98)
Block(5,4,-4,98)
Block(5,4,-3,47)
Block(5,4,-2,47)
Block(5,4,2,47)
Block(5,4,3,47)
Block(5,4,4,98)
Block(5,5,-4,98)
Block(5,5,4,98)
Block(5,6,-4,98)
Block(5,6,4,98)
Block(5,7,-4,98)
Block(5,7,4,98)
Block(5,8,-4,98)
Block(5,8,4,98)
Block(5,9,-4,98)
Block(5,9,0,85)
Block(5,9,4,98)
Block(5,10,-4,98)
Block(5,10,4,98)
Block(5,11,-4,98)
Block(5,11,4,98)
Block(5,12,-4,98)
Block(5,12,4,98)
Block(5,13,-4,98)
Block(5,13,-3,98)
Block(5,13,-2,98)
Block(5,13,-1,98)
Block(5,13,0,98)
Block(5,13,1,98)
Block(5,13,2,98)
Block(5,13,3,98)
Block(5,13,4,98)
Block(5,14,-4,98)
Block(5,14,4,98)
Block(5,16,0,41)
Block(5,17,-4,109:4)
Block(5,17,0,41)
Block(5,17,4,109:4)
Block(5,18,-4,98)
Block(5,18,4,98)
Block(5,19,-4,98)
Block(5,19,0,85)
Block(5,19,4,98)
Block(5,20,-4,98)
Block(5,20,4,98)
Block(5,21,-4,98)
Block(5,21,-3,136:2)
Block(5,21,3,136:3)
Block(5,21,4,98)
Block(5,22,-4,109)
Block(5,22,-2,136:1)
Block(5,22,-1,136:1)
Block(5,22,0,136:1)
Block(5,22,1,136:1)
Block(5,22,2,136:3)
Block(5,22,4,109)
Block(6,0,-7,2)
Block(6,0,-6,2)
Block(6,0,-5,2)
Block(6,0,-4,3)
Block(6,0,-3,3)
Block(6,0,-2,5:5)
Block(6,0,-1,5:5)
Block(6,0,0,5:5)
Block(6,0,1,5:5)
Block(6,0,2,5:5)
Block(6,0,3,5:5)
Block(6,0,4,3)
Block(6,0,5,2)
Block(6,0,6,2)
Block(6,0,7,2)
Block(6,0,8,2)
Block(6,1,-5,106:1)
Block(6,1,-4,98)
Block(6,1,-3,47)
Block(6,1,-2,47)
Block(6,1,-1,47)
Block(6,1,0,47)
Block(6,1,1,47)
Block(6,1,2,47)
Block(6,1,3,47)
Block(6,1,4,98)
Block(6,1,5,106:4)
Block(6,2,-5,106:1)
Block(6,2,-4,98)
Block(6,2,-3,47)
Block(6,2,-2,47)
Block(6,2,-1,47)
Block(6,2,0,47)
Block(6,2,1,47)
Block(6,2,2,47)
Block(6,2,3,47)
Block(6,2,4,98)
Block(6,2,5,106:4)
Block(6,3,-5,106:1)
Block(6,3,-4,98)
Block(6,3,-3,47)
Block(6,3,-2,47)
Block(6,3,-1,47)
Block(6,3,0,47)
Block(6,3,1,47)
Block(6,3,2,47)
Block(6,3,3,47)
Block(6,3,4,98)
Block(6,3,5,106:4)
Block(6,4,-4,98)
Block(6,4,-3,47)
Block(6,4,-2,47)
Block(6,4,-1,47)
Block(6,4,0,47)
Block(6,4,1,47)
Block(6,4,2,47)
Block(6,4,3,47)
Block(6,4,4,98)
Block(6,5,-4,98)
Block(6,5,4,98)
Block(6,6,-4,98)
Block(6,6,4,98)
Block(6,7,-4,98)
Block(6,7,4,98)
Block(6,8,-4,98)
Block(6,8,0,89)
Block(6,8,4,98)
Block(6,9,-4,98)
Block(6,9,0,85)
Block(6,9,4,98)
Block(6,10,-4,98)
Block(6,10,4,98)
Block(6,11,-4,98)
Block(6,11,4,98)
Block(6,12,-4,98)
Block(6,12,4,98)
Block(6,13,-4,98)
Block(6,13,-3,98)
Block(6,13,-2,98)
Block(6,13,-1,98)
Block(6,13,0,98)
Block(6,13,1,98)
Block(6,13,2,98)
Block(6,13,3,98)
Block(6,13,4,98)
Block(6,14,-4,98)
Block(6,14,4,98)
Block(6,15,-4,98)
Block(6,15,4,98)
Block(6,16,-4,98)
Block(6,16,4,98)
Block(6,17,-4,98)
Block(6,17,4,98)
Block(6,18,-4,98)
Block(6,18,4,98)
Block(6,19,-4,98)
Block(6,19,0,85)
Block(6,19,4,98)
Block(6,20,-4,98)
Block(6,20,4,98)
Block(6,21,-4,98)
Block(6,21,-3,136:2)
Block(6,21,-2,136:1)
Block(6,21,-1,136:1)
Block(6,21,0,136:1)
Block(6,21,1,136:1)
Block(6,21,2,136:1)
Block(6,21,3,136:1)
Block(6,21,4,98)
Block(6,22,-4,98)
Block(6,22,4,98)
Block(6,23,-4,109)
Block(6,23,4,109)
Block(7,0,-7,2)
Block(7,0,-6,2)
Block(7,0,-5,2)
Block(7,0,-4,3)
Block(7,0,-3,3)
Block(7,0,-2,3)
Block(7,0,-1,3)
Block(7,0,0,3)
Block(7,0,1,3)
Block(7,0,2,3)
Block(7,0,3,3)
Block(7,0,4,3)
Block(7,0,5,2)
Block(7,0,6,2)
Block(7,0,7,2)
Block(7,0,8,2)
Block(7,1,-5,106:1)
Block(7,1,-4,98)
Block(7,1,-3,98)
Block(7,1,-2,98)
Block(7,1,-1,98)
Block(7,1,0,98)
Block(7,1,1,98)
Block(7,1,2,98)
Block(7,1,3,98)
Block(7,1,4,98)
Block(7,1,5,106:4)
Block(7,2,-5,106:1)
Block(7,2,-4,98)
Block(7,2,-3,98)
Block(7,2,-2,98)
Block(7,2,-1,98)
Block(7,2,0,98)
Block(7,2,1,98)
Block(7,2,2,98)
Block(7,2,3,98)
Block(7,2,4,98)
Block(7,2,5,106:4)
Block(7,3,-5,106:1)
Block(7,3,-4,98)
Block(7,3,-3,98)
Block(7,3,-2,98)
Block(7,3,-1,98)
Block(7,3,0,98)
Block(7,3,1,98)
Block(7,3,2,98)
Block(7,3,3,98)
Block(7,3,4,98)
Block(7,3,5,106:4)
Block(7,4,-5,106:1)
Block(7,4,-4,98)
Block(7,4,-3,98)
Block(7,4,-2,98)
Block(7,4,-1,98)
Block(7,4,0,98)
Block(7,4,1,98)
Block(7,4,2,98)
Block(7,4,3,98)
Block(7,4,4,98)
Block(7,4,5,106:4)
Block(7,5,-4,98)
Block(7,5,-3,98)
Block(7,5,-2,98)
Block(7,5,-1,98)
Block(7,5,0,98)
Block(7,5,1,98)
Block(7,5,2,98)
Block(7,5,3,98)
Block(7,5,4,98)
Block(7,6,-4,98)
Block(7,6,-3,98)
Block(7,6,-2,98)
Block(7,6,-1,98)
Block(7,6,0,98)
Block(7,6,1,98)
Block(7,6,2,98)
Block(7,6,3,98)
Block(7,6,4,98)
Block(7,7,-4,98)
Block(7,7,-3,98)
Block(7,7,-2,98)
Block(7,7,-1,98)
Block(7,7,0,98)
Block(7,7,1,98)
Block(7,7,2,98)
Block(7,7,3,98)
Block(7,7,4,98)
Block(7,8,-4,98)
Block(7,8,-3,98)
Block(7,8,-2,98)
Block(7,8,-1,98)
Block(7,8,0,98)
Block(7,8,1,98)
Block(7,8,2,98)
Block(7,8,3,98)
Block(7,8,4,98)
Block(7,9,-4,98)
Block(7,9,-3,98)
Block(7,9,-2,98)
Block(7,9,-1,98)
Block(7,9,0,98)
Block(7,9,1,98)
Block(7,9,2,98)
Block(7,9,3,98)
Block(7,9,4,98)
Block(7,10,-4,98)
Block(7,10,-3,98)
Block(7,10,-2,98)
Block(7,10,-1,98)
Block(7,10,0,98)
Block(7,10,1,98)
Block(7,10,2,98)
Block(7,10,3,98)
Block(7,10,4,98)
Block(7,11,-4,98)
Block(7,11,-3,98)
Block(7,11,-2,98)
Block(7,11,-1,98)
Block(7,11,0,98)
Block(7,11,1,98)
Block(7,11,2,98)
Block(7,11,3,98)
Block(7,11,4,98)
Block(7,12,-4,98)
Block(7,12,-3,98)
Block(7,12,-2,98)
Block(7,12,-1,98)
Block(7,12,0,98)
Block(7,12,1,98)
Block(7,12,2,98)
Block(7,12,3,98)
Block(7,12,4,98)
Block(7,13,-4,98)
Block(7,13,-3,98)
Block(7,13,-2,98)
Block(7,13,-1,98)
Block(7,13,0,98)
Block(7,13,1,98)
Block(7,13,2,98)
Block(7,13,3,98)
Block(7,13,4,98)
Block(7,14,-4,98)
Block(7,14,-3,98)
Block(7,14,-2,98)
Block(7,14,-1,98)
Block(7,14,0,98)
Block(7,14,1,98)
Block(7,14,2,98)
Block(7,14,3,98)
Block(7,14,4,98)
Block(7,15,-4,98)
Block(7,15,-3,98)
Block(7,15,0,98)
Block(7,15,3,98)
Block(7,15,4,98)
Block(7,16,-4,98)
Block(7,16,-3,98)
Block(7,16,0,98)
Block(7,16,3,98)
Block(7,16,4,98)
Block(7,17,-4,98)
Block(7,17,-3,98)
Block(7,17,-2,109:7)
Block(7,17,-1,109:6)
Block(7,17,0,98)
Block(7,17,1,109:7)
Block(7,17,2,109:6)
Block(7,17,3,98)
Block(7,17,4,98)
Block(7,18,-4,98)
Block(7,18,-3,98)
Block(7,18,-2,98)
Block(7,18,-1,98)
Block(7,18,0,98)
Block(7,18,1,98)
Block(7,18,2,98)
Block(7,18,3,98)
Block(7,18,4,98)
Block(7,19,-4,98)
Block(7,19,-3,98)
Block(7,19,-2,98)
Block(7,19,-1,98)
Block(7,19,0,98)
Block(7,19,1,98)
Block(7,19,2,98)
Block(7,19,3,98)
Block(7,19,4,98)
Block(7,20,-4,98)
Block(7,20,-3,98)
Block(7,20,-2,98)
Block(7,20,-1,98)
Block(7,20,0,98)
Block(7,20,1,98)
Block(7,20,2,98)
Block(7,20,3,98)
Block(7,20,4,98)
Block(7,21,-4,98)
Block(7,21,-3,98)
Block(7,21,-2,98)
Block(7,21,-1,109:3)
Block(7,21,1,109:2)
Block(7,21,2,98)
Block(7,21,3,98)
Block(7,21,4,98)
Block(7,22,-4,98)
Block(7,22,-3,98)
Block(7,22,-2,109:3)
Block(7,22,2,109:2)
Block(7,22,3,98)
Block(7,22,4,98)
Block(7,23,-4,98)
Block(7,23,-3,109:3)
Block(7,23,3,109:2)
Block(7,23,4,98)
Block(7,24,-4,44:5)
Block(7,24,4,44:5)

Branch(16,0,0,true,monastery-age-ofC2R0,NORTH,100,0)
