

BranchFrequency: 10

BranchFrequencyGroup: CanOverride:0

CanOverride: true

SmoothRadius: -1

OverrideChildSettings: false

ReplaceAbove:
ReplaceBelow:

MustBeInside: VillageGeneratorStructurePlaceHolder, VillageGeneratorStructuresDelay, VillageGeneratorStructuresDelay2, VillageGeneratorStructuresDelay3, VillageGeneratorStructuresDelay4, VillageGeneratorStructuresDelay5, VillageGeneratorStructuresDelay6, VillageGeneratorStructuresDelay7, VillageGeneratorStructuresDelay8, VillageGeneratorStructuresDelay9, VillageGeneratorStructuresDelay10

Block(-8,0,-7,3)
Block(-8,0,-6,3)
Block(-8,0,-5,3)
Block(-8,0,-4,3)
Block(-8,0,-3,3)
Block(-8,0,-2,3)
Block(-8,0,-1,3)
Block(-8,0,0,3)
Block(-8,0,1,3)
Block(-8,0,2,3)
Block(-8,0,3,3)
Block(-8,0,4,3)
Block(-8,0,5,3)
Block(-8,1,-7,2)
Block(-8,1,-6,2)
Block(-8,1,-5,2)
Block(-8,1,-4,2)
Block(-8,1,-3,2)
Block(-8,1,-2,2)
Block(-8,1,-1,2)
Block(-8,1,0,2)
Block(-8,1,1,2)
Block(-8,1,2,2)
Block(-8,1,3,2)
Block(-8,1,4,2)
Block(-8,1,5,2)
Block(-8,2,-1,31:1)
Block(-8,2,4,31:1)
Block(-8,9,-7,126:5)
Block(-8,9,-6,126:5)
Block(-8,9,-5,126:5)
Block(-8,9,-4,126:5)
Block(-8,9,-3,126:5)
Block(-8,9,-2,126:5)
Block(-8,9,-1,126:5)
Block(-8,9,0,126:5)
Block(-8,9,1,126:5)
Block(-8,9,2,126:5)
Block(-8,9,3,126:5)
Block(-8,9,4,126:5)
Block(-8,9,5,126:5)
Block(-7,0,-7,3)
Block(-7,0,-6,3)
Block(-7,0,-5,3)
Block(-7,0,-4,3)
Block(-7,0,-3,3)
Block(-7,0,-2,3)
Block(-7,0,-1,3)
Block(-7,0,0,3)
Block(-7,0,1,3)
Block(-7,0,2,3)
Block(-7,0,3,3)
Block(-7,0,4,3)
Block(-7,0,5,3)
Block(-7,1,-7,2)
Block(-7,1,-6,2)
Block(-7,1,-5,4)
Block(-7,1,-4,2)
Block(-7,1,-3,2)
Block(-7,1,-2,2)
Block(-7,1,-1,4)
Block(-7,1,0,2)
Block(-7,1,1,2)
Block(-7,1,2,2)
Block(-7,1,3,4)
Block(-7,1,4,2)
Block(-7,1,5,2)
Block(-7,2,-6,31:1)
Block(-7,2,-5,67)
Block(-7,2,-2,31:1)
Block(-7,2,-1,67)
Block(-7,2,0,31:1)
Block(-7,2,2,175:2)
Block(-7,2,3,67)
Block(-7,2,4,175:4)
Block(-7,2,5,31:1)
Block(-7,3,2,175:10)
Block(-7,3,4,175:10)
Block(-7,6,-6,85)
Block(-7,6,-5,109:4)
Block(-7,6,-1,109:4)
Block(-7,6,3,109:4)
Block(-7,6,4,85)
Block(-7,7,-6,85)
Block(-7,7,-5,17)
Block(-7,7,-4,5:1)
Block(-7,7,-3,5:1)
Block(-7,7,-2,5:1)
Block(-7,7,-1,17)
Block(-7,7,0,5:1)
Block(-7,7,1,5:1)
Block(-7,7,2,5:1)
Block(-7,7,3,17)
Block(-7,7,4,85)
Block(-7,8,-6,85)
Block(-7,8,-5,17)
Block(-7,8,-4,5:1)
Block(-7,8,-3,102)
Block(-7,8,-2,5:1)
Block(-7,8,-1,17)
Block(-7,8,0,5:1)
Block(-7,8,1,102)
Block(-7,8,2,5:1)
Block(-7,8,3,17)
Block(-7,8,4,85)
Block(-7,9,-7,126:13)
Block(-7,9,-6,126:13)
Block(-7,9,-5,5:5)
Block(-7,9,-4,5:5)
Block(-7,9,-3,5:5)
Block(-7,9,-2,5:5)
Block(-7,9,-1,5:5)
Block(-7,9,0,5:5)
Block(-7,9,1,5:5)
Block(-7,9,2,5:5)
Block(-7,9,3,5:5)
Block(-7,9,4,126:13)
Block(-7,9,5,126:13)
Block(-7,10,1,85)
Block(-7,10,2,85)
Block(-7,10,3,85)
Block(-6,0,-7,3)
Block(-6,0,-6,3)
Block(-6,0,-5,3)
Block(-6,0,-4,3)
Block(-6,0,-3,3)
Block(-6,0,-2,3)
Block(-6,0,-1,3)
Block(-6,0,0,3)
Block(-6,0,1,3)
Block(-6,0,2,3)
Block(-6,0,3,3)
Block(-6,0,4,3)
Block(-6,0,5,3)
Block(-6,1,-7,2)
Block(-6,1,-6,4)
Block(-6,1,-5,1:6)
Block(-6,1,-4,4)
Block(-6,1,-3,4)
Block(-6,1,-2,4)
Block(-6,1,-1,1:6)
Block(-6,1,0,4)
Block(-6,1,1,4)
Block(-6,1,2,4)
Block(-6,1,3,1:6)
Block(-6,1,4,4)
Block(-6,1,5,2)
Block(-6,2,-6,67:2)
Block(-6,2,-5,1:6)
Block(-6,2,-4,4)
Block(-6,2,-3,4)
Block(-6,2,-2,4)
Block(-6,2,-1,1:6)
Block(-6,2,0,4)
Block(-6,2,1,4)
Block(-6,2,2,4)
Block(-6,2,3,1:6)
Block(-6,2,4,67:3)
Block(-6,2,5,175:2)
Block(-6,3,-5,1:6)
Block(-6,3,-4,4)
Block(-6,3,-3,101)
Block(-6,3,-2,4)
Block(-6,3,-1,1:6)
Block(-6,3,0,4)
Block(-6,3,1,101)
Block(-6,3,2,4)
Block(-6,3,3,1:6)
Block(-6,3,5,175:10)
Block(-6,4,-5,1:6)
Block(-6,4,-4,4)
Block(-6,4,-3,4)
Block(-6,4,-2,4)
Block(-6,4,-1,1:6)
Block(-6,4,0,4)
Block(-6,4,1,4)
Block(-6,4,2,4)
Block(-6,4,3,1:6)
Block(-6,5,-5,1:6)
Block(-6,5,-4,98)
Block(-6,5,-3,98)
Block(-6,5,-2,98)
Block(-6,5,-1,1:6)
Block(-6,5,0,98)
Block(-6,5,1,98)
Block(-6,5,2,98)
Block(-6,5,3,1:6)
Block(-6,6,-6,109:6)
Block(-6,6,-5,1:6)
Block(-6,6,-4,98)
Block(-6,6,-3,98)
Block(-6,6,-2,98)
Block(-6,6,-1,1:6)
Block(-6,6,0,98)
Block(-6,6,1,98)
Block(-6,6,2,98)
Block(-6,6,3,1:6)
Block(-6,6,4,109:7)
Block(-6,7,-6,17)
Block(-6,7,-5,171:12)
Block(-6,7,-4,171:12)
Block(-6,7,-3,171:12)
Block(-6,7,-2,61:2,1-Furnace.nbt)
Block(-6,7,-1,5:1)
Block(-6,7,0,171:10)
Block(-6,7,1,171:10)
Block(-6,7,2,171:10)
Block(-6,7,3,171:10)
Block(-6,7,4,17)
Block(-6,8,-6,17)
Block(-6,8,-5,50:3)
Block(-6,8,-2,4)
Block(-6,8,-1,5:1)
Block(-6,8,4,17)
Block(-6,9,-6,17)
Block(-6,9,-5,126:9)
Block(-6,9,-4,126:9)
Block(-6,9,-3,126:9)
Block(-6,9,-2,4)
Block(-6,9,-1,5:1)
Block(-6,9,1,126:8)
Block(-6,9,2,126:8)
Block(-6,9,3,126:8)
Block(-6,9,4,17)
Block(-6,10,-7,164)
Block(-6,10,-6,164)
Block(-6,10,-5,164)
Block(-6,10,-4,164)
Block(-6,10,-3,164)
Block(-6,10,-2,4)
Block(-6,10,-1,164)
Block(-6,10,0,164:2)
Block(-6,10,1,5:1)
Block(-6,10,2,20)
Block(-6,10,3,5:1)
Block(-6,10,4,164:3)
Block(-6,10,5,164)
Block(-6,11,-2,4)
Block(-6,11,1,164:2)
Block(-6,11,2,20)
Block(-6,11,3,164:3)
Block(-6,12,-2,4)
Block(-6,12,2,5:5)
Block(-6,13,-2,4)
Block(-6,14,-2,4)
Block(-5,0,-7,3)
Block(-5,0,-6,3)
Block(-5,0,-5,3)
Block(-5,0,-4,3)
Block(-5,0,-3,3)
Block(-5,0,-2,3)
Block(-5,0,-1,3)
Block(-5,0,0,3)
Block(-5,0,1,3)
Block(-5,0,2,3)
Block(-5,0,3,3)
Block(-5,0,4,3)
Block(-5,0,5,3)
Block(-5,1,-7,13)
Block(-5,1,-6,13)
Block(-5,1,-5,4)
Block(-5,1,-4,5)
Block(-5,1,-3,5)
Block(-5,1,-2,5)
Block(-5,1,-1,5)
Block(-5,1,0,5)
Block(-5,1,1,5)
Block(-5,1,2,5)
Block(-5,1,3,4)
Block(-5,1,4,2)
Block(-5,1,5,2)
Block(-5,2,-5,4)
Block(-5,2,-3,53:2)
Block(-5,2,-2,5)
Block(-5,2,-1,4)
Block(-5,2,0,54:3,2-Chest.nbt)
Block(-5,2,3,4)
Block(-5,2,4,175:2)
Block(-5,2,5,31:1)
Block(-5,3,-5,4)
Block(-5,3,-2,53:2)
Block(-5,3,-1,4)
Block(-5,3,0,126:11)
Block(-5,3,3,4)
Block(-5,3,4,175:10)
Block(-5,4,-5,4)
Block(-5,4,-4,50:1)
Block(-5,4,-1,4)
Block(-5,4,0,54:3,3-Chest.nbt)
Block(-5,4,3,4)
Block(-5,5,-5,98)
Block(-5,5,-1,1:6)
Block(-5,5,3,98)
Block(-5,6,-5,98)
Block(-5,6,-4,5)
Block(-5,6,-3,5)
Block(-5,6,-1,5)
Block(-5,6,0,5)
Block(-5,6,1,5)
Block(-5,6,2,5)
Block(-5,6,3,98)
Block(-5,7,-6,5:1)
Block(-5,7,-5,171:12)
Block(-5,7,-4,171:12)
Block(-5,7,-3,85)
Block(-5,7,-2,85)
Block(-5,7,-1,5:1)
Block(-5,7,0,53)
Block(-5,7,1,171:10)
Block(-5,7,2,135:1)
Block(-5,7,3,135:1)
Block(-5,7,4,5:1)
Block(-5,8,-6,5:1)
Block(-5,8,-3,85)
Block(-5,8,-2,85)
Block(-5,8,-1,5:1)
Block(-5,8,4,5:1)
Block(-5,9,-6,5:1)
Block(-5,9,-5,126:9)
Block(-5,9,-4,126:9)
Block(-5,9,-3,126:9)
Block(-5,9,-2,126:9)
Block(-5,9,-1,5:1)
Block(-5,9,1,126:8)
Block(-5,9,2,126:8)
Block(-5,9,3,126:8)
Block(-5,9,4,5:1)
Block(-5,10,-6,5:1)
Block(-5,10,-5,5:1)
Block(-5,10,-4,5:1)
Block(-5,10,-3,5:1)
Block(-5,10,-2,5:1)
Block(-5,10,-1,5:1)
Block(-5,10,1,5:1)
Block(-5,10,2,171:13)
Block(-5,10,3,5:1)
Block(-5,10,4,5:1)
Block(-5,11,-7,164)
Block(-5,11,-6,164)
Block(-5,11,-5,164)
Block(-5,11,-4,164)
Block(-5,11,-3,164)
Block(-5,11,-2,164)
Block(-5,11,-1,164)
Block(-5,11,0,164)
Block(-5,11,1,164)
Block(-5,11,3,164)
Block(-5,11,4,164)
Block(-5,11,5,164)
Block(-5,12,2,5:5)
Block(-4,0,-7,3)
Block(-4,0,-6,3)
Block(-4,0,-5,3)
Block(-4,0,-4,3)
Block(-4,0,-3,3)
Block(-4,0,-2,3)
Block(-4,0,-1,3)
Block(-4,0,0,3)
Block(-4,0,1,3)
Block(-4,0,2,3)
Block(-4,0,3,3)
Block(-4,0,4,3)
Block(-4,0,5,3)
Block(-4,1,-7,13)
Block(-4,1,-6,13)
Block(-4,1,-5,4)
Block(-4,1,-4,5)
Block(-4,1,-3,5)
Block(-4,1,-2,5)
Block(-4,1,-1,5)
Block(-4,1,0,5)
Block(-4,1,1,5)
Block(-4,1,2,5)
Block(-4,1,3,4)
Block(-4,1,4,2)
Block(-4,1,5,2)
Block(-4,2,-5,193:1)
Block(-4,2,-1,4)
Block(-4,2,0,190)
Block(-4,2,3,4)
Block(-4,2,4,175:2)
Block(-4,3,-5,193:8)
Block(-4,3,-2,53:5)
Block(-4,3,-1,4)
Block(-4,3,0,5:3)
Block(-4,3,3,101)
Block(-4,3,4,175:10)
Block(-4,4,-5,4)
Block(-4,4,-3,53:6)
Block(-4,4,-2,53)
Block(-4,4,-1,4)
Block(-4,4,0,190)
Block(-4,4,3,4)
Block(-4,5,-5,98)
Block(-4,5,-3,53:3)
Block(-4,5,-1,1:6)
Block(-4,5,0,190)
Block(-4,5,3,98)
Block(-4,6,-5,98)
Block(-4,6,-4,53:3)
Block(-4,6,-1,5)
Block(-4,6,0,5)
Block(-4,6,1,5)
Block(-4,6,2,5)
Block(-4,6,3,98)
Block(-4,7,-6,5:1)
Block(-4,7,-5,171:12)
Block(-4,7,-1,5:1)
Block(-4,7,0,5)
Block(-4,7,1,171:10)
Block(-4,7,2,85)
Block(-4,7,3,85)
Block(-4,7,4,5:1)
Block(-4,8,-6,102)
Block(-4,8,-2,53:4)
Block(-4,8,-1,5:1)
Block(-4,8,0,53)
Block(-4,8,2,171:11)
Block(-4,8,3,171:11)
Block(-4,8,4,102)
Block(-4,9,-6,5:1)
Block(-4,9,-5,126:9)
Block(-4,9,-4,126:9)
Block(-4,9,-3,126:9)
Block(-4,9,-2,53:1)
Block(-4,9,-1,5:1)
Block(-4,9,1,126:8)
Block(-4,9,2,126:8)
Block(-4,9,3,126:8)
Block(-4,9,4,5:1)
Block(-4,10,-6,5:1)
Block(-4,10,-5,26:10)
Block(-4,10,-4,26:2)
Block(-4,10,-3,171:14)
Block(-4,10,-1,5:1)
Block(-4,10,1,171:13)
Block(-4,10,2,171:13)
Block(-4,10,3,54:2,4-Chest.nbt)
Block(-4,10,4,5:1)
Block(-4,11,-7,85)
Block(-4,11,-6,20)
Block(-4,11,-1,5:1)
Block(-4,11,4,20)
Block(-4,11,5,85)
Block(-4,12,-7,164)
Block(-4,12,-6,164)
Block(-4,12,-5,164)
Block(-4,12,-4,164)
Block(-4,12,-3,164)
Block(-4,12,-2,164)
Block(-4,12,-1,164)
Block(-4,12,0,164)
Block(-4,12,1,164)
Block(-4,12,2,5:5)
Block(-4,12,3,164)
Block(-4,12,4,164)
Block(-4,12,5,164)
Block(-3,0,-7,3)
Block(-3,0,-6,3)
Block(-3,0,-5,3)
Block(-3,0,-4,3)
Block(-3,0,-3,3)
Block(-3,0,-2,3)
Block(-3,0,-1,3)
Block(-3,0,0,3)
Block(-3,0,1,3)
Block(-3,0,2,3)
Block(-3,0,3,3)
Block(-3,0,4,3)
Block(-3,0,5,3)
Block(-3,1,-7,2)
Block(-3,1,-6,4)
Block(-3,1,-5,1:6)
Block(-3,1,-4,4)
Block(-3,1,-3,4)
Block(-3,1,-2,4)
Block(-3,1,-1,1:6)
Block(-3,1,0,5)
Block(-3,1,1,5)
Block(-3,1,2,5)
Block(-3,1,3,1:6)
Block(-3,1,4,4)
Block(-3,1,5,2)
Block(-3,2,-6,67:2)
Block(-3,2,-5,1:6)
Block(-3,2,-4,4)
Block(-3,2,-3,196:2)
Block(-3,2,-2,4)
Block(-3,2,-1,1:6)
Block(-3,2,0,54:3,5-Chest.nbt)
Block(-3,2,3,1:6)
Block(-3,2,4,67:3)
Block(-3,2,5,31:1)
Block(-3,3,-5,1:6)
Block(-3,3,-4,4)
Block(-3,3,-3,196:8)
Block(-3,3,-2,4)
Block(-3,3,-1,1:6)
Block(-3,3,0,126:11)
Block(-3,3,3,1:6)
Block(-3,4,-5,1:6)
Block(-3,4,-4,4)
Block(-3,4,-3,4)
Block(-3,4,-2,4)
Block(-3,4,-1,1:6)
Block(-3,4,0,54:3,6-Chest.nbt)
Block(-3,4,3,1:6)
Block(-3,5,-5,1:6)
Block(-3,5,-4,98)
Block(-3,5,-3,98)
Block(-3,5,-2,98)
Block(-3,5,-1,1:6)
Block(-3,5,3,1:6)
Block(-3,6,-6,109:6)
Block(-3,6,-5,1:6)
Block(-3,6,-4,5)
Block(-3,6,-3,5)
Block(-3,6,-2,5)
Block(-3,6,-1,5)
Block(-3,6,0,5)
Block(-3,6,1,5)
Block(-3,6,2,5)
Block(-3,6,3,1:6)
Block(-3,6,4,109:7)
Block(-3,7,-6,17)
Block(-3,7,-5,171:12)
Block(-3,7,-4,171:12)
Block(-3,7,-3,171:12)
Block(-3,7,-2,5)
Block(-3,7,-1,5:1)
Block(-3,7,0,84)
Block(-3,7,1,171:10)
Block(-3,7,2,135)
Block(-3,7,3,135)
Block(-3,7,4,17)
Block(-3,8,-6,17)
Block(-3,8,-5,50:3)
Block(-3,8,-2,53:1)
Block(-3,8,-1,5:1)
Block(-3,8,0,126:8)
Block(-3,8,2,50:2)
Block(-3,8,4,17)
Block(-3,9,-6,17)
Block(-3,9,-5,126:9)
Block(-3,9,-4,126:9)
Block(-3,9,-3,126:9)
Block(-3,9,-1,5:1)
Block(-3,9,0,53)
Block(-3,9,1,126:8)
Block(-3,9,2,126:8)
Block(-3,9,3,126:8)
Block(-3,9,4,17)
Block(-3,10,-7,85)
Block(-3,10,-6,17)
Block(-3,10,-5,171:14)
Block(-3,10,-4,171:14)
Block(-3,10,-3,171:14)
Block(-3,10,-1,5:1)
Block(-3,10,1,171:13)
Block(-3,10,2,26)
Block(-3,10,3,26:8)
Block(-3,10,4,17)
Block(-3,10,5,85)
Block(-3,11,-7,85)
Block(-3,11,-6,17)
Block(-3,11,-1,5:1)
Block(-3,11,4,17)
Block(-3,11,5,85)
Block(-3,12,-7,85)
Block(-3,12,-6,17)
Block(-3,12,-5,50:3)
Block(-3,12,-2,50:4)
Block(-3,12,-1,5:1)
Block(-3,12,0,50:3)
Block(-3,12,3,50:4)
Block(-3,12,4,17)
Block(-3,12,5,85)
Block(-3,13,-7,5:5)
Block(-3,13,-6,5:5)
Block(-3,13,-5,5:5)
Block(-3,13,-4,5:5)
Block(-3,13,-3,5:5)
Block(-3,13,-2,5:5)
Block(-3,13,-1,5:5)
Block(-3,13,0,5:5)
Block(-3,13,1,5:5)
Block(-3,13,2,5:5)
Block(-3,13,3,5:5)
Block(-3,13,4,5:5)
Block(-3,13,5,5:5)
Block(-2,0,-7,3)
Block(-2,0,-6,3)
Block(-2,0,-5,3)
Block(-2,0,-4,3)
Block(-2,0,-3,3)
Block(-2,0,-2,3)
Block(-2,0,-1,3)
Block(-2,0,0,3)
Block(-2,0,1,3)
Block(-2,0,2,3)
Block(-2,0,3,3)
Block(-2,0,4,3)
Block(-2,0,5,3)
Block(-2,1,-7,2)
Block(-2,1,-6,2)
Block(-2,1,-5,4)
Block(-2,1,-4,159:14)
Block(-2,1,-3,159:14)
Block(-2,1,-2,159:14)
Block(-2,1,-1,4)
Block(-2,1,0,5)
Block(-2,1,1,5)
Block(-2,1,2,5)
Block(-2,1,3,4)
Block(-2,1,4,2)
Block(-2,1,5,2)
Block(-2,2,-7,31:1)
Block(-2,2,-6,175:4)
Block(-2,2,-5,4)
Block(-2,2,-4,118:3)
Block(-2,2,-2,135:1)
Block(-2,2,-1,4)
Block(-2,2,0,190)
Block(-2,2,3,4)
Block(-2,2,4,175:2)
Block(-2,2,5,31:1)
Block(-2,3,-6,175:10)
Block(-2,3,-5,4)
Block(-2,3,-1,4)
Block(-2,3,0,5:3)
Block(-2,3,3,101)
Block(-2,3,4,175:10)
Block(-2,4,-5,4)
Block(-2,4,-1,4)
Block(-2,4,0,190)
Block(-2,4,3,4)
Block(-2,5,-5,98)
Block(-2,5,-4,109:5)
Block(-2,5,-3,109:5)
Block(-2,5,-2,109:5)
Block(-2,5,-1,98)
Block(-2,5,0,190)
Block(-2,5,3,98)
Block(-2,6,-5,98)
Block(-2,6,-4,5)
Block(-2,6,-3,5)
Block(-2,6,-2,5)
Block(-2,6,-1,5)
Block(-2,6,0,5)
Block(-2,6,1,5)
Block(-2,6,2,5)
Block(-2,6,3,98)
Block(-2,7,-6,5:1)
Block(-2,7,-5,135:3)
Block(-2,7,-4,85)
Block(-2,7,-3,171:12)
Block(-2,7,-2,53:1)
Block(-2,7,-1,5:1)
Block(-2,7,0,5:1)
Block(-2,7,1,197:2)
Block(-2,7,2,5:1)
Block(-2,7,3,5:1)
Block(-2,7,4,5:1)
Block(-2,8,-6,102)
Block(-2,8,-4,171)
Block(-2,8,-1,5:1)
Block(-2,8,0,5:1)
Block(-2,8,1,197:8)
Block(-2,8,2,5:1)
Block(-2,8,3,5:1)
Block(-2,8,4,5:1)
Block(-2,9,-6,5:1)
Block(-2,9,-5,126:9)
Block(-2,9,-4,126:9)
Block(-2,9,-3,126:9)
Block(-2,9,-1,5:1)
Block(-2,9,0,5:1)
Block(-2,9,1,5:1)
Block(-2,9,2,5:1)
Block(-2,9,3,5:1)
Block(-2,9,4,5:1)
Block(-2,10,-6,5:1)
Block(-2,10,-5,26:10)
Block(-2,10,-4,26:2)
Block(-2,10,-3,171:14)
Block(-2,10,-1,5:1)
Block(-2,10,0,171:13)
Block(-2,10,1,171:13)
Block(-2,10,2,26)
Block(-2,10,3,26:8)
Block(-2,10,4,5:1)
Block(-2,11,-7,85)
Block(-2,11,-6,20)
Block(-2,11,-1,5:1)
Block(-2,11,4,5:1)
Block(-2,11,5,85)
Block(-2,12,-7,164:1)
Block(-2,12,-6,164:1)
Block(-2,12,-5,164:1)
Block(-2,12,-4,164:1)
Block(-2,12,-3,164:1)
Block(-2,12,-2,164:1)
Block(-2,12,-1,164:1)
Block(-2,12,0,164:1)
Block(-2,12,1,5:5)
Block(-2,12,2,164:1)
Block(-2,12,3,164:1)
Block(-2,12,4,164:1)
Block(-2,12,5,164:1)
Block(-1,0,-7,3)
Block(-1,0,-6,3)
Block(-1,0,-5,3)
Block(-1,0,-4,3)
Block(-1,0,-3,3)
Block(-1,0,-2,3)
Block(-1,0,-1,3)
Block(-1,0,0,3)
Block(-1,0,1,3)
Block(-1,0,2,3)
Block(-1,0,3,3)
Block(-1,0,4,3)
Block(-1,0,5,3)
Block(-1,1,-7,2)
Block(-1,1,-6,2)
Block(-1,1,-5,4)
Block(-1,1,-4,159:14)
Block(-1,1,-3,159:14)
Block(-1,1,-2,159:14)
Block(-1,1,-1,4)
Block(-1,1,0,5)
Block(-1,1,1,5)
Block(-1,1,2,5)
Block(-1,1,3,4)
Block(-1,1,4,2)
Block(-1,1,5,2)
Block(-1,2,-7,31:1)
Block(-1,2,-6,175:4)
Block(-1,2,-5,4)
Block(-1,2,-2,189)
Block(-1,2,-1,4)
Block(-1,2,0,54:3,7-Chest.nbt)
Block(-1,2,3,4)
Block(-1,2,4,31:1)
Block(-1,3,-6,175:10)
Block(-1,3,-5,4)
Block(-1,3,-2,72)
Block(-1,3,-1,4)
Block(-1,3,0,126:11)
Block(-1,3,3,4)
Block(-1,4,-5,4)
Block(-1,4,-1,4)
Block(-1,4,0,54:3,8-Chest.nbt)
Block(-1,4,3,4)
Block(-1,5,-5,98)
Block(-1,5,-4,109:7)
Block(-1,5,-3,89)
Block(-1,5,-2,109:6)
Block(-1,5,-1,98)
Block(-1,5,3,98)
Block(-1,6,-5,98)
Block(-1,6,-4,5)
Block(-1,6,-3,5)
Block(-1,6,-2,5)
Block(-1,6,-1,5)
Block(-1,6,0,5)
Block(-1,6,1,5)
Block(-1,6,2,5)
Block(-1,6,3,98)
Block(-1,7,-6,5:1)
Block(-1,7,-5,135:3)
Block(-1,7,-4,85)
Block(-1,7,-3,171:12)
Block(-1,7,-2,171:12)
Block(-1,7,-1,171:12)
Block(-1,7,0,171:12)
Block(-1,7,1,171:12)
Block(-1,7,2,171:12)
Block(-1,7,3,171:12)
Block(-1,7,4,5:1)
Block(-1,8,-6,5:1)
Block(-1,8,-4,171)
Block(-1,8,4,5:1)
Block(-1,9,-6,5:1)
Block(-1,9,-5,126:9)
Block(-1,9,-4,126:9)
Block(-1,9,-3,126:9)
Block(-1,9,-1,126:9)
Block(-1,9,0,126:9)
Block(-1,9,1,126:9)
Block(-1,9,3,50:4)
Block(-1,9,4,5:1)
Block(-1,10,-6,5:1)
Block(-1,10,-5,5:1)
Block(-1,10,-4,5:1)
Block(-1,10,-3,5:1)
Block(-1,10,-1,5:1)
Block(-1,10,0,5:1)
Block(-1,10,1,5:1)
Block(-1,10,2,5:1)
Block(-1,10,3,5:1)
Block(-1,10,4,5:1)
Block(-1,11,-7,164:1)
Block(-1,11,-6,164:1)
Block(-1,11,-5,164:1)
Block(-1,11,-4,164:1)
Block(-1,11,-3,164:1)
Block(-1,11,-2,164:1)
Block(-1,11,-1,164:1)
Block(-1,11,0,164:2)
Block(-1,11,1,5:1)
Block(-1,11,2,164:1)
Block(-1,11,3,164:1)
Block(-1,11,4,164:1)
Block(-1,11,5,164:1)
Block(-1,12,1,5:5)
Block(0,0,-7,3)
Block(0,0,-6,3)
Block(0,0,-5,3)
Block(0,0,-4,3)
Block(0,0,-3,3)
Block(0,0,-2,3)
Block(0,0,-1,3)
Block(0,0,0,3)
Block(0,0,1,3)
Block(0,0,2,3)
Block(0,0,3,3)
Block(0,0,4,3)
Block(0,0,5,3)
Block(0,1,-7,2)
Block(0,1,-6,4)
Block(0,1,-5,1:6)
Block(0,1,-4,159:14)
Block(0,1,-3,159:14)
Block(0,1,-2,159:14)
Block(0,1,-1,1:6)
Block(0,1,0,4)
Block(0,1,1,4)
Block(0,1,2,4)
Block(0,1,3,1:6)
Block(0,1,4,4)
Block(0,1,5,2)
Block(0,2,-6,67:2)
Block(0,2,-5,1:6)
Block(0,2,-4,101)
Block(0,2,-2,101)
Block(0,2,-1,1:6)
Block(0,2,0,4)
Block(0,2,1,196:2)
Block(0,2,2,4)
Block(0,2,3,1:6)
Block(0,2,4,67:3)
Block(0,3,-5,1:6)
Block(0,3,-4,101)
Block(0,3,-2,101)
Block(0,3,-1,1:6)
Block(0,3,0,4)
Block(0,3,1,196:8)
Block(0,3,2,4)
Block(0,3,3,1:6)
Block(0,4,-5,1:6)
Block(0,4,-4,101)
Block(0,4,-2,101)
Block(0,4,-1,1:6)
Block(0,4,0,4)
Block(0,4,1,4)
Block(0,4,2,4)
Block(0,4,3,1:6)
Block(0,5,-5,1:6)
Block(0,5,-4,109:7)
Block(0,5,-2,109:6)
Block(0,5,-1,1:6)
Block(0,5,0,98)
Block(0,5,1,98)
Block(0,5,2,98)
Block(0,5,3,1:6)
Block(0,6,-6,109:6)
Block(0,6,-5,1:6)
Block(0,6,-4,98)
Block(0,6,-3,98)
Block(0,6,-2,98)
Block(0,6,-1,1:6)
Block(0,6,0,5)
Block(0,6,1,5)
Block(0,6,2,5)
Block(0,6,3,1:6)
Block(0,6,4,109:7)
Block(0,7,-6,17)
Block(0,7,-5,135)
Block(0,7,-4,135)
Block(0,7,-3,135)
Block(0,7,-2,171:12)
Block(0,7,-1,171:12)
Block(0,7,0,171:12)
Block(0,7,1,171:12)
Block(0,7,2,171:12)
Block(0,7,3,171:12)
Block(0,7,4,17)
Block(0,8,-6,17)
Block(0,8,-5,50:3)
Block(0,8,-2,50:2)
Block(0,8,4,17)
Block(0,9,-6,17)
Block(0,9,-5,126:9)
Block(0,9,-4,126:9)
Block(0,9,-3,126:9)
Block(0,9,-2,126:9)
Block(0,9,-1,126:9)
Block(0,9,0,126:9)
Block(0,9,1,126:9)
Block(0,9,4,17)
Block(0,10,-7,164:1)
Block(0,10,-6,164:1)
Block(0,10,-5,164:1)
Block(0,10,-4,164:1)
Block(0,10,-3,164:1)
Block(0,10,-2,164:1)
Block(0,10,-1,164:1)
Block(0,10,0,5:1)
Block(0,10,1,5:1)
Block(0,10,2,5:1)
Block(0,10,3,164:3)
Block(0,10,4,164:1)
Block(0,10,5,164:1)
Block(0,11,0,164:2)
Block(0,11,1,5:1)
Block(0,11,2,164:3)
Block(0,12,1,5:5)
Block(1,0,-7,3)
Block(1,0,-6,3)
Block(1,0,-5,3)
Block(1,0,-4,3)
Block(1,0,-3,3)
Block(1,0,-2,3)
Block(1,0,-1,3)
Block(1,0,0,3)
Block(1,0,1,3)
Block(1,0,2,3)
Block(1,0,3,3)
Block(1,0,4,3)
Block(1,0,5,3)
Block(1,1,-7,1:6)
Block(1,1,-6,1:6)
Block(1,1,-5,4)
Block(1,1,-4,1:6)
Block(1,1,-3,1:6)
Block(1,1,-2,1:6)
Block(1,1,-1,159:13)
Block(1,1,0,159:13)
Block(1,1,1,159:13)
Block(1,1,2,159:13)
Block(1,1,3,4)
Block(1,1,4,2)
Block(1,1,5,2)
Block(1,2,-5,67:1)
Block(1,2,-1,101)
Block(1,2,3,4)
Block(1,3,-1,101)
Block(1,3,3,4)
Block(1,4,-1,101)
Block(1,4,2,177:2,9-Banner.nbt)
Block(1,4,3,4)
Block(1,5,-1,109:5)
Block(1,5,0,109:5)
Block(1,5,1,109:5)
Block(1,5,2,109:5)
Block(1,5,3,98)
Block(1,6,-6,85)
Block(1,6,-5,109:5)
Block(1,6,-2,44:13)
Block(1,6,-1,98)
Block(1,6,0,5)
Block(1,6,1,5)
Block(1,6,2,5)
Block(1,6,3,98)
Block(1,7,-6,85)
Block(1,7,-5,17)
Block(1,7,-4,5:1)
Block(1,7,-3,5:1)
Block(1,7,-2,17)
Block(1,7,-1,5:1)
Block(1,7,0,5:1)
Block(1,7,1,5:1)
Block(1,7,2,171:12)
Block(1,7,3,171:12)
Block(1,7,4,5:1)
Block(1,8,-6,85)
Block(1,8,-5,17)
Block(1,8,-4,102)
Block(1,8,-3,5:1)
Block(1,8,-2,17)
Block(1,8,-1,5:1)
Block(1,8,0,5:1)
Block(1,8,1,5:1)
Block(1,8,4,5:1)
Block(1,9,-7,126:13)
Block(1,9,-6,126:13)
Block(1,9,-5,5:5)
Block(1,9,-4,5:5)
Block(1,9,-3,5:5)
Block(1,9,-2,5:5)
Block(1,9,-1,5:1)
Block(1,9,0,5:1)
Block(1,9,1,5:1)
Block(1,9,4,5:5)
Block(1,9,5,5:5)
Block(1,10,-1,164:2)
Block(1,10,0,5:1)
Block(1,10,1,5:1)
Block(1,10,3,164:3)
Block(1,11,0,164:2)
Block(1,11,1,5:1)
Block(1,11,2,164:3)
Block(1,12,1,5:5)
Block(2,0,-7,3)
Block(2,0,-6,3)
Block(2,0,-5,3)
Block(2,0,-4,3)
Block(2,0,-3,3)
Block(2,0,-2,3)
Block(2,0,-1,3)
Block(2,0,0,3)
Block(2,0,1,3)
Block(2,0,2,3)
Block(2,0,3,3)
Block(2,0,4,3)
Block(2,0,5,3)
Block(2,1,-7,1:6)
Block(2,1,-6,1:6)
Block(2,1,-5,1:6)
Block(2,1,-4,1:6)
Block(2,1,-3,1:6)
Block(2,1,-2,1:6)
Block(2,1,-1,159:13)
Block(2,1,0,159:13)
Block(2,1,1,159:13)
Block(2,1,2,159:13)
Block(2,1,3,4)
Block(2,1,4,2)
Block(2,1,5,2)
Block(2,2,3,4)
Block(2,3,3,4)
Block(2,4,3,4)
Block(2,5,0,89)
Block(2,5,1,89)
Block(2,5,2,109:6)
Block(2,5,3,98)
Block(2,6,-1,98)
Block(2,6,0,5)
Block(2,6,1,5)
Block(2,6,2,5)
Block(2,6,3,98)
Block(2,7,-2,5:1)
Block(2,7,-1,26:3)
Block(2,7,0,171:3)
Block(2,7,1,197:3)
Block(2,7,2,171:12)
Block(2,7,3,171:12)
Block(2,7,4,5:1)
Block(2,8,-2,5:1)
Block(2,8,1,197:8)
Block(2,8,4,102)
Block(2,9,-7,126:5)
Block(2,9,-6,126:5)
Block(2,9,-5,126:5)
Block(2,9,-4,126:5)
Block(2,9,-3,126:5)
Block(2,9,-2,5:5)
Block(2,9,1,5:1)
Block(2,9,4,5:5)
Block(2,9,5,126:5)
Block(2,10,-1,164:2)
Block(2,10,1,5:1)
Block(2,10,3,164:3)
Block(2,11,0,164:2)
Block(2,11,1,5:1)
Block(2,11,2,164:3)
Block(2,12,1,5:5)
Block(3,0,-7,3)
Block(3,0,-6,3)
Block(3,0,-5,3)
Block(3,0,-4,3)
Block(3,0,-3,3)
Block(3,0,-2,3)
Block(3,0,-1,3)
Block(3,0,0,3)
Block(3,0,1,3)
Block(3,0,2,3)
Block(3,0,3,3)
Block(3,0,4,3)
Block(3,0,5,3)
Block(3,1,-7,1:6)
Block(3,1,-6,1:6)
Block(3,1,-5,1:6)
Block(3,1,-4,1:6)
Block(3,1,-3,1:6)
Block(3,1,-2,1:6)
Block(3,1,-1,159:13)
Block(3,1,0,159:13)
Block(3,1,1,159:13)
Block(3,1,2,159:13)
Block(3,1,3,4)
Block(3,1,4,2)
Block(3,1,5,2)
Block(3,2,-1,101)
Block(3,2,3,4)
Block(3,2,4,31:1)
Block(3,3,-1,101)
Block(3,3,3,4)
Block(3,4,-1,101)
Block(3,4,2,177:2,10-Banner.nbt)
Block(3,4,3,4)
Block(3,5,-1,109:4)
Block(3,5,0,109:4)
Block(3,5,1,109:4)
Block(3,5,2,109:4)
Block(3,5,3,98)
Block(3,6,-1,98)
Block(3,6,0,5)
Block(3,6,1,5)
Block(3,6,2,5)
Block(3,6,3,98)
Block(3,7,-2,5:1)
Block(3,7,-1,26:11)
Block(3,7,0,171:3)
Block(3,7,1,5:1)
Block(3,7,2,171:12)
Block(3,7,3,171:12)
Block(3,7,4,5:1)
Block(3,8,-2,102)
Block(3,8,1,5:1)
Block(3,8,4,5:1)
Block(3,9,-3,126:5)
Block(3,9,-2,5:5)
Block(3,9,0,50:2)
Block(3,9,1,5:1)
Block(3,9,3,50:2)
Block(3,9,4,5:5)
Block(3,9,5,126:5)
Block(3,10,-1,164:2)
Block(3,10,1,5:1)
Block(3,10,3,164:3)
Block(3,11,0,164:2)
Block(3,11,1,5:1)
Block(3,11,2,164:3)
Block(3,12,1,5:5)
Block(4,0,-7,3)
Block(4,0,-6,3)
Block(4,0,-5,3)
Block(4,0,-4,3)
Block(4,0,-3,3)
Block(4,0,-2,3)
Block(4,0,-1,3)
Block(4,0,0,3)
Block(4,0,1,3)
Block(4,0,2,3)
Block(4,0,3,3)
Block(4,0,4,3)
Block(4,0,5,3)
Block(4,1,-7,1:6)
Block(4,1,-6,1:6)
Block(4,1,-5,1:6)
Block(4,1,-4,1:6)
Block(4,1,-3,1:6)
Block(4,1,-2,4)
Block(4,1,-1,1:6)
Block(4,1,0,4)
Block(4,1,1,4)
Block(4,1,2,4)
Block(4,1,3,1:6)
Block(4,1,4,4)
Block(4,1,5,2)
Block(4,2,-2,67:2)
Block(4,2,-1,1:6)
Block(4,2,0,4)
Block(4,2,1,4)
Block(4,2,2,4)
Block(4,2,3,1:6)
Block(4,2,4,67:3)
Block(4,2,5,31:1)
Block(4,3,-1,1:6)
Block(4,3,0,4)
Block(4,3,1,4)
Block(4,3,2,4)
Block(4,3,3,1:6)
Block(4,4,-1,1:6)
Block(4,4,0,4)
Block(4,4,1,4)
Block(4,4,2,4)
Block(4,4,3,1:6)
Block(4,5,-1,1:6)
Block(4,5,0,98)
Block(4,5,1,98)
Block(4,5,2,98)
Block(4,5,3,1:6)
Block(4,6,-2,109:6)
Block(4,6,-1,1:6)
Block(4,6,0,5)
Block(4,6,1,5)
Block(4,6,2,5)
Block(4,6,3,1:6)
Block(4,6,4,109:7)
Block(4,7,-2,17)
Block(4,7,-1,5:1)
Block(4,7,0,5:1)
Block(4,7,1,5:1)
Block(4,7,2,197)
Block(4,7,3,5:1)
Block(4,7,4,17)
Block(4,8,-2,17)
Block(4,8,-1,5:1)
Block(4,8,0,5:1)
Block(4,8,1,5:1)
Block(4,8,2,197:8)
Block(4,8,3,5:1)
Block(4,8,4,17)
Block(4,9,-3,126:5)
Block(4,9,-2,5:5)
Block(4,9,-1,5:1)
Block(4,9,0,5:1)
Block(4,9,1,5:1)
Block(4,9,2,5:1)
Block(4,9,3,5:1)
Block(4,9,4,5:5)
Block(4,9,5,126:5)
Block(4,10,-1,164:2)
Block(4,10,0,5:1)
Block(4,10,1,5:1)
Block(4,10,2,5:1)
Block(4,10,3,164:3)
Block(4,11,0,164:2)
Block(4,11,1,5:1)
Block(4,11,2,164:3)
Block(4,12,1,5:5)
Block(5,0,-7,3)
Block(5,0,-6,3)
Block(5,0,-5,3)
Block(5,0,-4,3)
Block(5,0,-3,3)
Block(5,0,-2,3)
Block(5,0,-1,3)
Block(5,0,0,3)
Block(5,0,1,3)
Block(5,0,2,3)
Block(5,0,3,3)
Block(5,0,4,3)
Block(5,0,5,3)
Block(5,1,-7,1:6)
Block(5,1,-6,1:6)
Block(5,1,-5,1:6)
Block(5,1,-4,1:6)
Block(5,1,-3,1:6)
Block(5,1,-2,1:6)
Block(5,1,-1,159:11)
Block(5,1,0,159:11)
Block(5,1,1,159:11)
Block(5,1,2,159:11)
Block(5,1,3,4)
Block(5,1,4,2)
Block(5,1,5,2)
Block(5,2,-1,101)
Block(5,2,0,54:5,11-Chest.nbt)
Block(5,2,1,189)
Block(5,2,2,135:2)
Block(5,2,3,4)
Block(5,2,4,175:2)
Block(5,3,-1,101)
Block(5,3,1,72)
Block(5,3,3,4)
Block(5,3,4,175:10)
Block(5,4,-1,101)
Block(5,4,3,4)
Block(5,5,-1,109:5)
Block(5,5,0,109:5)
Block(5,5,1,109:5)
Block(5,5,2,109:5)
Block(5,5,3,98)
Block(5,6,-1,98)
Block(5,6,0,5)
Block(5,6,1,5)
Block(5,6,2,5)
Block(5,6,3,98)
Block(5,7,-2,5:1)
Block(5,7,-1,54:5,12-Chest.nbt)
Block(5,7,0,171:7)
Block(5,7,1,54:5,13-Chest.nbt)
Block(5,7,2,171:7)
Block(5,7,3,54:5,14-Chest.nbt)
Block(5,7,4,5:1)
Block(5,8,-2,5:1)
Block(5,8,4,5:1)
Block(5,9,-3,126:5)
Block(5,9,-2,5:5)
Block(5,9,0,50:1)
Block(5,9,2,50:1)
Block(5,9,4,5:5)
Block(5,9,5,126:5)
Block(5,10,-1,164:2)
Block(5,10,0,85)
Block(5,10,1,85)
Block(5,10,2,85)
Block(5,10,3,164:3)
Block(5,11,0,164:2)
Block(5,11,1,85)
Block(5,11,2,164:3)
Block(5,12,1,5:5)
Block(6,0,-7,3)
Block(6,0,-6,3)
Block(6,0,-5,3)
Block(6,0,-4,3)
Block(6,0,-3,3)
Block(6,0,-2,3)
Block(6,0,-1,3)
Block(6,0,0,3)
Block(6,0,1,3)
Block(6,0,2,3)
Block(6,0,3,3)
Block(6,0,4,3)
Block(6,0,5,3)
Block(6,1,-7,1:6)
Block(6,1,-6,1:6)
Block(6,1,-5,1:6)
Block(6,1,-4,1:6)
Block(6,1,-3,1:6)
Block(6,1,-2,1:6)
Block(6,1,-1,159:11)
Block(6,1,0,159:11)
Block(6,1,1,159:11)
Block(6,1,2,159:11)
Block(6,1,3,4)
Block(6,1,4,2)
Block(6,1,5,2)
Block(6,2,-7,140,15-FlowerPot.nbt)
Block(6,2,3,4)
Block(6,2,4,175:2)
Block(6,3,3,4)
Block(6,3,4,175:10)
Block(6,4,3,4)
Block(6,5,0,89)
Block(6,5,1,89)
Block(6,5,2,109:6)
Block(6,5,3,98)
Block(6,6,-1,98)
Block(6,6,0,5)
Block(6,6,1,5)
Block(6,6,2,5)
Block(6,6,3,98)
Block(6,7,-2,5:1)
Block(6,7,-1,171:7)
Block(6,7,0,171:7)
Block(6,7,1,171:7)
Block(6,7,2,171:7)
Block(6,7,3,171:7)
Block(6,7,4,5:1)
Block(6,8,-2,102)
Block(6,8,4,102)
Block(6,9,-3,126:5)
Block(6,9,-2,5:5)
Block(6,9,4,5:5)
Block(6,9,5,126:5)
Block(6,10,-1,164:2)
Block(6,10,3,164:3)
Block(6,11,0,164:2)
Block(6,11,1,85)
Block(6,11,2,164:3)
Block(6,12,1,5:5)
Block(7,0,-7,3)
Block(7,0,-6,3)
Block(7,0,-5,3)
Block(7,0,-4,3)
Block(7,0,-3,3)
Block(7,0,-2,3)
Block(7,0,-1,3)
Block(7,0,0,3)
Block(7,0,1,3)
Block(7,0,2,3)
Block(7,0,3,3)
Block(7,0,4,3)
Block(7,0,5,3)
Block(7,1,-7,1:6)
Block(7,1,-6,1:6)
Block(7,1,-5,1:6)
Block(7,1,-4,1:6)
Block(7,1,-3,1:6)
Block(7,1,-2,1:6)
Block(7,1,-1,159:11)
Block(7,1,0,159:11)
Block(7,1,1,159:11)
Block(7,1,2,159:11)
Block(7,1,3,4)
Block(7,1,4,2)
Block(7,1,5,2)
Block(7,2,-7,85)
Block(7,2,-6,140,16-FlowerPot.nbt)
Block(7,2,-4,85)
Block(7,2,-3,140,17-FlowerPot.nbt)
Block(7,2,-1,101)
Block(7,2,0,54:4,18-Chest.nbt)
Block(7,2,1,5)
Block(7,2,2,54:4,19-Chest.nbt)
Block(7,2,3,4)
Block(7,2,4,31:1)
Block(7,3,-7,85)
Block(7,3,-4,85)
Block(7,3,-1,101)
Block(7,3,3,4)
Block(7,4,-7,85)
Block(7,4,-6,85)
Block(7,4,-5,85)
Block(7,4,-4,85)
Block(7,4,-1,101)
Block(7,4,3,4)
Block(7,5,-7,171)
Block(7,5,-6,171)
Block(7,5,-5,171)
Block(7,5,-4,171)
Block(7,5,-1,109:4)
Block(7,5,0,109:4)
Block(7,5,1,109:4)
Block(7,5,2,109:4)
Block(7,5,3,98)
Block(7,6,-1,98)
Block(7,6,0,5)
Block(7,6,1,5)
Block(7,6,2,5)
Block(7,6,3,98)
Block(7,7,-2,5:1)
Block(7,7,-1,26:3)
Block(7,7,0,171:7)
Block(7,7,1,26:3)
Block(7,7,2,171:7)
Block(7,7,3,26:3)
Block(7,7,4,5:1)
Block(7,8,-2,5:1)
Block(7,8,4,5:1)
Block(7,9,-3,126:5)
Block(7,9,-2,5:5)
Block(7,9,4,5:5)
Block(7,9,5,126:5)
Block(7,10,-1,164:2)
Block(7,10,3,164:3)
Block(7,11,0,164:2)
Block(7,11,1,85)
Block(7,11,2,164:3)
Block(7,12,1,5:5)

Branch(16,0,0,true,marketplaceC1R0,NORTH,100,0)
