

BranchFrequencyGroup: CanOverride:0

CanOverride: true

SmoothRadius: -1

OverrideChildSettings: false

ReplaceAbove:
ReplaceBelow:

MustBeInside: VillageGeneratorStructurePlaceHolder, VillageGeneratorStructuresDelay, VillageGeneratorStructuresDelay2, VillageGeneratorStructuresDelay3, VillageGeneratorStructuresDelay4, VillageGeneratorStructuresDelay5, VillageGeneratorStructuresDelay6, VillageGeneratorStructuresDelay7, VillageGeneratorStructuresDelay8, VillageGeneratorStructuresDelay9, VillageGeneratorStructuresDelay10

Block(-8,0,-7,3)
Block(-8,0,-6,3)
Block(-8,0,-5,3)
Block(-8,0,-4,3)
Block(-8,0,-3,3)
Block(-8,0,-2,3)
Block(-8,0,-1,3)
Block(-8,0,0,3)
Block(-8,0,1,3)
Block(-8,0,2,3)
Block(-8,0,3,3)
Block(-8,0,4,3)
Block(-8,0,5,3)
Block(-8,1,-7,1:6)
Block(-8,1,-6,1:6)
Block(-8,1,-5,1:6)
Block(-8,1,-4,1:6)
Block(-8,1,-3,1:6)
Block(-8,1,-2,4)
Block(-8,1,-1,1:6)
Block(-8,1,0,4)
Block(-8,1,1,4)
Block(-8,1,2,4)
Block(-8,1,3,1:6)
Block(-8,1,4,4)
Block(-8,1,5,2)
Block(-8,2,-7,5)
Block(-8,2,-6,5)
Block(-8,2,-5,5)
Block(-8,2,-4,5)
Block(-8,2,-2,67:2)
Block(-8,2,-1,1:6)
Block(-8,2,0,4)
Block(-8,2,1,4)
Block(-8,2,2,4)
Block(-8,2,3,1:6)
Block(-8,2,4,67:3)
Block(-8,3,-7,140,20-FlowerPot.nbt)
Block(-8,3,-6,140,21-FlowerPot.nbt)
Block(-8,3,-4,140,22-FlowerPot.nbt)
Block(-8,3,-1,1:6)
Block(-8,3,0,4)
Block(-8,3,1,4)
Block(-8,3,2,4)
Block(-8,3,3,1:6)
Block(-8,4,-7,85)
Block(-8,4,-6,85)
Block(-8,4,-5,85)
Block(-8,4,-4,85)
Block(-8,4,-1,1:6)
Block(-8,4,0,4)
Block(-8,4,1,4)
Block(-8,4,2,4)
Block(-8,4,3,1:6)
Block(-8,5,-7,171)
Block(-8,5,-6,171)
Block(-8,5,-5,171)
Block(-8,5,-4,171)
Block(-8,5,-1,1:6)
Block(-8,5,0,98)
Block(-8,5,1,98)
Block(-8,5,2,98)
Block(-8,5,3,1:6)
Block(-8,6,-2,109:6)
Block(-8,6,-1,1:6)
Block(-8,6,0,98)
Block(-8,6,1,98)
Block(-8,6,2,98)
Block(-8,6,3,1:6)
Block(-8,6,4,109:7)
Block(-8,7,-2,17)
Block(-8,7,-1,26:11)
Block(-8,7,0,171:7)
Block(-8,7,1,26:11)
Block(-8,7,2,171:7)
Block(-8,7,3,26:11)
Block(-8,7,4,17)
Block(-8,8,-2,17)
Block(-8,8,4,17)
Block(-8,9,-3,126:5)
Block(-8,9,-2,5:5)
Block(-8,9,-1,177:4,23-Banner.nbt)
Block(-8,9,0,50:2)
Block(-8,9,2,50:2)
Block(-8,9,3,177:4,24-Banner.nbt)
Block(-8,9,4,5:5)
Block(-8,9,5,126:5)
Block(-8,10,-1,164:2)
Block(-8,10,0,85)
Block(-8,10,1,85)
Block(-8,10,2,85)
Block(-8,10,3,164:3)
Block(-8,11,0,164:2)
Block(-8,11,1,85)
Block(-8,11,2,164:3)
Block(-8,12,1,5:5)
Block(-7,0,-7,3)
Block(-7,0,-6,3)
Block(-7,0,-5,3)
Block(-7,0,-4,3)
Block(-7,0,-3,3)
Block(-7,0,-2,3)
Block(-7,0,-1,3)
Block(-7,0,0,3)
Block(-7,0,1,3)
Block(-7,0,2,3)
Block(-7,0,3,3)
Block(-7,0,4,3)
Block(-7,0,5,3)
Block(-7,1,-7,1:6)
Block(-7,1,-6,1:6)
Block(-7,1,-5,1:6)
Block(-7,1,-4,1:6)
Block(-7,1,-3,1:6)
Block(-7,1,-2,1:6)
Block(-7,1,-1,4)
Block(-7,1,0,2)
Block(-7,1,1,2)
Block(-7,1,2,2)
Block(-7,1,3,4)
Block(-7,1,4,2)
Block(-7,1,5,2)
Block(-7,2,-7,85)
Block(-7,2,-4,85)
Block(-7,2,-1,67:1)
Block(-7,2,0,106:2)
Block(-7,2,1,175:2)
Block(-7,2,2,106:2)
Block(-7,2,3,67:1)
Block(-7,2,4,31:1)
Block(-7,3,-7,85)
Block(-7,3,-4,85)
Block(-7,3,0,106:2)
Block(-7,3,1,175:10)
Block(-7,3,2,106:2)
Block(-7,4,-7,85)
Block(-7,4,-6,85)
Block(-7,4,-5,85)
Block(-7,4,-4,85)
Block(-7,4,0,106:2)
Block(-7,4,2,106:2)
Block(-7,5,-7,171)
Block(-7,5,-6,171)
Block(-7,5,-5,171)
Block(-7,5,-4,171)
Block(-7,5,0,106:2)
Block(-7,5,2,106:2)
Block(-7,6,-2,85)
Block(-7,6,-1,109:5)
Block(-7,6,0,106:2)
Block(-7,6,2,106:2)
Block(-7,6,3,109:5)
Block(-7,6,4,85)
Block(-7,7,-2,85)
Block(-7,7,-1,17)
Block(-7,7,0,5:1)
Block(-7,7,1,5:1)
Block(-7,7,2,5:1)
Block(-7,7,3,17)
Block(-7,7,4,85)
Block(-7,8,-2,85)
Block(-7,8,-1,17)
Block(-7,8,0,5:1)
Block(-7,8,1,102)
Block(-7,8,2,5:1)
Block(-7,8,3,17)
Block(-7,8,4,85)
Block(-7,9,-3,126:5)
Block(-7,9,-2,126:13)
Block(-7,9,-1,17)
Block(-7,9,0,5:1)
Block(-7,9,1,5:1)
Block(-7,9,2,5:1)
Block(-7,9,3,17)
Block(-7,9,4,126:13)
Block(-7,9,5,126:5)
Block(-7,10,-1,164:2)
Block(-7,10,0,5:1)
Block(-7,10,1,5:1)
Block(-7,10,2,5:1)
Block(-7,10,3,164:3)
Block(-7,11,0,164:2)
Block(-7,11,1,5:1)
Block(-7,11,2,164:3)
Block(-7,12,1,5:5)
Block(-6,0,-7,3)
Block(-6,0,-6,3)
Block(-6,0,-5,3)
Block(-6,0,-4,3)
Block(-6,0,-3,3)
Block(-6,0,-2,3)
Block(-6,0,-1,3)
Block(-6,0,0,3)
Block(-6,0,1,3)
Block(-6,0,2,3)
Block(-6,0,3,3)
Block(-6,0,4,3)
Block(-6,0,5,3)
Block(-6,1,-7,1:6)
Block(-6,1,-6,1:6)
Block(-6,1,-5,1:6)
Block(-6,1,-4,1:6)
Block(-6,1,-3,1:6)
Block(-6,1,-2,2)
Block(-6,1,-1,2)
Block(-6,1,0,2)
Block(-6,1,1,2)
Block(-6,1,2,2)
Block(-6,1,3,2)
Block(-6,1,4,2)
Block(-6,1,5,2)
Block(-6,2,0,31:1)
Block(-6,2,1,31:1)
Block(-6,2,2,31:1)
Block(-6,2,3,175:2)
Block(-6,3,3,175:10)
Block(-6,7,0,106:2)
Block(-6,7,2,106:2)
Block(-6,7,3,106:2)
Block(-6,8,0,106:2)
Block(-6,8,2,106:2)
Block(-6,8,3,106:2)
Block(-6,9,-3,126:5)
Block(-6,9,-2,126:13)
Block(-6,9,0,106:2)
Block(-6,9,2,106:2)
Block(-6,9,3,106:2)
Block(-6,9,4,126:13)
Block(-6,9,5,126:5)
Block(-6,10,-1,164:2)
Block(-6,10,0,85)
Block(-6,10,1,85)
Block(-6,10,2,85)
Block(-6,10,3,164:3)
Block(-6,11,0,164:2)
Block(-6,11,1,85)
Block(-6,11,2,164:3)
Block(-6,12,1,5:5)
Block(-5,0,-7,3)
Block(-5,0,-6,3)
Block(-5,0,-5,3)
Block(-5,0,-4,3)
Block(-5,0,-3,3)
Block(-5,0,-2,3)
Block(-5,0,-1,3)
Block(-5,0,0,3)
Block(-5,0,1,3)
Block(-5,0,2,3)
Block(-5,0,3,3)
Block(-5,0,4,3)
Block(-5,0,5,3)
Block(-5,1,-7,2)
Block(-5,1,-6,2)
Block(-5,1,-5,2)
Block(-5,1,-4,2)
Block(-5,1,-3,2)
Block(-5,1,-2,2)
Block(-5,1,-1,2)
Block(-5,1,0,2)
Block(-5,1,1,2)
Block(-5,1,2,2)
Block(-5,1,3,2)
Block(-5,1,4,2)
Block(-5,1,5,2)
