

BranchFrequencyGroup: CanOverride:0

CanOverride: true

SmoothRadius: -1

OverrideChildSettings: false

ReplaceAbove:
ReplaceBelow:

MustBeInside: VillageGeneratorStructurePlaceHolder, VillageGeneratorStructuresDelay, VillageGeneratorStructuresDelay2, VillageGeneratorStructuresDelay3, VillageGeneratorStructuresDelay4, VillageGeneratorStructuresDelay5, VillageGeneratorStructuresDelay6, VillageGeneratorStructuresDelay7, VillageGeneratorStructuresDelay8, VillageGeneratorStructuresDelay9, VillageGeneratorStructuresDelay10

Block(-8,0,-7,4)
Block(-8,0,-6,4)
Block(-8,0,-5,4)
Block(-8,0,-4,112)
Block(-8,0,-3,112)
Block(-8,0,-2,112)
Block(-8,0,-1,4)
Block(-8,0,0,4)
Block(-8,0,1,3)
Block(-8,1,-7,4)
Block(-8,1,-6,4)
Block(-8,1,-5,1:6)
Block(-8,1,-1,1:6)
Block(-8,1,0,4)
Block(-8,1,1,2)
Block(-8,2,-7,4)
Block(-8,2,-6,4)
Block(-8,2,-5,1:6)
Block(-8,2,-1,1:6)
Block(-8,2,0,4)
Block(-8,2,1,175:2)
Block(-8,3,-7,2)
Block(-8,3,-6,4)
Block(-8,3,-5,1:6)
Block(-8,3,-4,109:7)
Block(-8,3,-2,109:6)
Block(-8,3,-1,1:6)
Block(-8,3,0,4)
Block(-8,3,1,175:10)
Block(-8,4,-7,31:2)
Block(-8,4,-6,4)
Block(-8,4,-5,4)
Block(-8,4,-4,5:1)
Block(-8,4,-3,5:1)
Block(-8,4,-2,5:1)
Block(-8,4,-1,4)
Block(-8,4,0,4)
Block(-8,5,-6,67:2)
Block(-8,5,-5,1:6)
Block(-8,5,-4,171:15)
Block(-8,5,-3,171:10)
Block(-8,5,-2,171:15)
Block(-8,5,-1,1:6)
Block(-8,5,0,67:3)
Block(-8,6,-5,1:6)
Block(-8,6,-1,1:6)
Block(-8,7,-5,1:6)
Block(-8,7,-4,50:3)
Block(-8,7,-2,50:4)
Block(-8,7,-1,1:6)
Block(-8,8,-5,1:6)
Block(-8,8,-4,5:5)
Block(-8,8,-3,5:5)
Block(-8,8,-2,5:5)
Block(-8,8,-1,1:6)
Block(-8,9,-6,109:6)
Block(-8,9,-5,179:2)
Block(-8,9,-4,179:2)
Block(-8,9,-3,179:2)
Block(-8,9,-2,179:2)
Block(-8,9,-1,179:2)
Block(-8,9,0,109:7)
Block(-8,10,-6,17)
Block(-8,10,-5,47)
Block(-8,10,-1,47)
Block(-8,10,0,17)
Block(-8,11,-6,17)
Block(-8,11,-5,47)
Block(-8,11,-1,47)
Block(-8,11,0,17)
Block(-8,12,-6,17)
Block(-8,12,-5,164:7)
Block(-8,12,-1,164:6)
Block(-8,12,0,17)
Block(-8,13,-6,17)
Block(-8,13,-5,5:5)
Block(-8,13,-4,5:5)
Block(-8,13,-3,5:5)
Block(-8,13,-2,5:5)
Block(-8,13,-1,5:5)
Block(-8,13,0,17)
Block(-8,14,-7,126:13)
Block(-8,14,-6,17)
Block(-8,14,-5,171:7)
Block(-8,14,-4,171:7)
Block(-8,14,0,17)
Block(-8,14,1,126:13)
Block(-8,15,-6,164:2)
Block(-8,15,0,164:3)
Block(-8,16,-5,164:2)
Block(-8,16,-1,164:3)
Block(-8,17,-4,164:2)
Block(-8,17,-2,164:3)
Block(-8,18,-3,5:5)
Block(-7,0,-7,3)
Block(-7,0,-6,3)
Block(-7,0,-5,4)
Block(-7,0,-4,112)
Block(-7,0,-3,112)
Block(-7,0,-2,112)
Block(-7,0,-1,4)
Block(-7,0,0,3)
Block(-7,0,1,3)
Block(-7,1,-7,3)
Block(-7,1,-6,3)
Block(-7,1,-5,4)
Block(-7,1,-1,4)
Block(-7,1,0,2)
Block(-7,1,1,2)
Block(-7,2,-7,3)
Block(-7,2,-6,3)
Block(-7,2,-5,4)
Block(-7,2,-1,4)
Block(-7,2,0,175:2)
Block(-7,3,-7,2)
Block(-7,3,-6,2)
Block(-7,3,-5,4)
Block(-7,3,-1,4)
Block(-7,3,0,175:10)
Block(-7,4,-7,31:2)
Block(-7,4,-6,175:3)
Block(-7,4,-5,4)
Block(-7,4,-4,126:9)
Block(-7,4,-3,126:9)
Block(-7,4,-2,126:9)
Block(-7,4,-1,4)
Block(-7,5,-6,175:10)
Block(-7,5,-5,98)
Block(-7,5,-4,163)
Block(-7,5,-3,171:15)
Block(-7,5,-2,163)
Block(-7,5,-1,98)
Block(-7,6,-5,98)
Block(-7,6,-1,98)
Block(-7,7,-7,161:13)
Block(-7,7,-5,98)
Block(-7,7,-1,98)
Block(-7,8,-5,98)
Block(-7,8,-4,164:7)
Block(-7,8,-3,126:13)
Block(-7,8,-2,164:6)
Block(-7,8,-1,98)
Block(-7,9,-5,179:2)
Block(-7,9,-4,179:2)
Block(-7,9,-3,179:2)
Block(-7,9,-2,179:2)
Block(-7,9,-1,179:2)
Block(-7,10,-6,5:2)
Block(-7,10,-5,47)
Block(-7,10,-1,47)
Block(-7,10,0,5:2)
Block(-7,11,-6,5:2)
Block(-7,11,-5,47)
Block(-7,11,-1,47)
Block(-7,11,0,5:2)
Block(-7,12,-6,5:2)
Block(-7,12,-5,47)
Block(-7,12,-1,47)
Block(-7,12,0,5:2)
Block(-7,13,-6,5)
Block(-7,13,-5,126:13)
Block(-7,13,-4,126:13)
Block(-7,13,-3,126:13)
Block(-7,13,-2,126:13)
Block(-7,13,-1,126:13)
Block(-7,13,0,5)
Block(-7,14,-7,126:13)
Block(-7,14,-6,5)
Block(-7,14,-5,26:10)
Block(-7,14,-4,26:2)
Block(-7,14,-1,54:2,53-Chest.nbt)
Block(-7,14,0,5)
Block(-7,14,1,126:13)
Block(-7,15,-6,164:2)
Block(-7,15,0,164:3)
Block(-7,16,-5,164:2)
Block(-7,16,-1,164:3)
Block(-7,17,-4,164:2)
Block(-7,17,-2,164:3)
Block(-7,18,-3,5:5)
Block(-6,0,-7,3)
Block(-6,0,-6,3)
Block(-6,0,-5,4)
Block(-6,0,-4,112)
Block(-6,0,-3,112)
Block(-6,0,-2,112)
Block(-6,0,-1,4)
Block(-6,0,0,3)
Block(-6,0,1,3)
Block(-6,1,-7,3)
Block(-6,1,-6,3)
Block(-6,1,-5,4)
Block(-6,1,-1,4)
Block(-6,1,0,2)
Block(-6,1,1,2)
Block(-6,2,-7,2)
Block(-6,2,-6,2)
Block(-6,2,-5,4)
Block(-6,2,-1,4)
Block(-6,3,-7,31:2)
Block(-6,3,-6,175:3)
Block(-6,3,-5,4)
Block(-6,3,-1,101)
Block(-6,4,-6,175:10)
Block(-6,4,-5,4)
Block(-6,4,-4,126:9)
Block(-6,4,-3,126:9)
Block(-6,4,-2,126:9)
Block(-6,4,-1,4)
Block(-6,5,-5,98)
Block(-6,5,-4,163:3)
Block(-6,5,-3,85)
Block(-6,5,-2,163:2)
Block(-6,5,-1,98)
Block(-6,6,-5,102)
Block(-6,6,-3,171:14)
Block(-6,6,-1,102)
Block(-6,7,-5,102)
Block(-6,7,-1,102)
Block(-6,8,-5,98)
Block(-6,8,-4,164:7)
Block(-6,8,-3,126:13)
Block(-6,8,-2,164:6)
Block(-6,8,-1,98)
Block(-6,9,-5,179:2)
Block(-6,9,-4,179:2)
Block(-6,9,-3,179:2)
Block(-6,9,-2,179:2)
Block(-6,9,-1,179:2)
Block(-6,10,-6,135:2)
Block(-6,10,-5,47)
Block(-6,10,-3,116)
Block(-6,10,-1,47)
Block(-6,10,0,135:3)
Block(-6,11,-6,102)
Block(-6,11,0,102)
Block(-6,12,-6,135:6)
Block(-6,12,-5,47)
Block(-6,12,-3,89)
Block(-6,12,-1,47)
Block(-6,12,0,135:7)
Block(-6,13,-6,5)
Block(-6,13,-5,126:13)
Block(-6,13,-4,126:13)
Block(-6,13,-3,5:5)
Block(-6,13,-2,126:13)
Block(-6,13,-1,126:13)
Block(-6,13,0,5)
Block(-6,14,-7,126:13)
Block(-6,14,-6,5)
Block(-6,14,-5,171:7)
Block(-6,14,-4,171:7)
Block(-6,14,0,5)
Block(-6,14,1,126:13)
Block(-6,15,-6,164:2)
Block(-6,15,0,164:3)
Block(-6,16,-5,164:2)
Block(-6,16,-1,164:3)
Block(-6,17,-4,164:2)
Block(-6,17,-2,164:3)
Block(-6,18,-3,5:5)
Block(-5,0,-7,3)
Block(-5,0,-6,3)
Block(-5,0,-5,4)
Block(-5,0,-4,112)
Block(-5,0,-3,112)
Block(-5,0,-2,112)
Block(-5,0,-1,4)
Block(-5,0,0,3)
Block(-5,0,1,3)
Block(-5,1,-7,3)
Block(-5,1,-6,3)
Block(-5,1,-5,4)
Block(-5,1,-1,4)
Block(-5,1,0,2)
Block(-5,1,1,2)
Block(-5,2,-7,2)
Block(-5,2,-6,2)
Block(-5,2,-5,4)
Block(-5,2,-1,4)
Block(-5,2,0,175:2)
Block(-5,3,-7,31:2)
Block(-5,3,-6,175:3)
Block(-5,3,-5,4)
Block(-5,3,-1,4)
Block(-5,3,0,175:10)
Block(-5,4,-6,175:10)
Block(-5,4,-5,4)
Block(-5,4,-4,126:9)
Block(-5,4,-3,126:9)
Block(-5,4,-2,126:9)
Block(-5,4,-1,4)
Block(-5,5,-5,98)
Block(-5,5,-4,163:3)
Block(-5,5,-3,163)
Block(-5,5,-2,163:2)
Block(-5,5,-1,98)
Block(-5,6,-5,98)
Block(-5,6,-1,98)
Block(-5,7,-5,98)
Block(-5,7,-1,98)
Block(-5,8,-5,98)
Block(-5,8,-4,164:7)
Block(-5,8,-3,126:13)
Block(-5,8,-2,164:6)
Block(-5,8,-1,98)
Block(-5,9,-5,179:2)
Block(-5,9,-4,179:2)
Block(-5,9,-3,179:2)
Block(-5,9,-2,179:2)
Block(-5,9,-1,179:2)
Block(-5,10,-6,5:2)
Block(-5,10,-5,47)
Block(-5,10,-1,47)
Block(-5,10,0,5:2)
Block(-5,11,-6,5:2)
Block(-5,11,-5,47)
Block(-5,11,-1,47)
Block(-5,11,0,5:2)
Block(-5,12,-6,5:2)
Block(-5,12,-5,47)
Block(-5,12,-1,47)
Block(-5,12,0,5:2)
Block(-5,13,-6,5)
Block(-5,13,-5,126:13)
Block(-5,13,-4,126:13)
Block(-5,13,-3,126:13)
Block(-5,13,-2,126:13)
Block(-5,13,-1,126:13)
Block(-5,13,0,5)
Block(-5,14,-7,126:13)
Block(-5,14,-6,5)
Block(-5,14,-5,26:10)
Block(-5,14,-4,26:2)
Block(-5,14,-1,54:2,62-Chest.nbt)
Block(-5,14,0,5)
Block(-5,14,1,126:13)
Block(-5,15,-6,164:2)
Block(-5,15,0,164:3)
Block(-5,16,-5,164:2)
Block(-5,16,-1,164:3)
Block(-5,17,-4,164:2)
Block(-5,17,-2,164:3)
Block(-5,18,-3,5:5)
Block(-4,0,-7,4)
Block(-4,0,-6,4)
Block(-4,0,-5,4)
Block(-4,0,-4,4)
Block(-4,0,-3,4)
Block(-4,0,-2,4)
Block(-4,0,-1,4)
Block(-4,0,0,4)
Block(-4,0,1,3)
Block(-4,1,-7,4)
Block(-4,1,-6,4)
Block(-4,1,-5,4)
Block(-4,1,-4,4)
Block(-4,1,-3,4)
Block(-4,1,-2,4)
Block(-4,1,-1,4)
Block(-4,1,0,4)
Block(-4,1,1,2)
Block(-4,2,-7,4)
Block(-4,2,-6,4)
Block(-4,2,-5,4)
Block(-4,2,-4,4)
Block(-4,2,-3,4)
Block(-4,2,-2,4)
Block(-4,2,-1,4)
Block(-4,2,0,4)
Block(-4,3,-7,139)
Block(-4,3,-6,4)
Block(-4,3,-5,4)
Block(-4,3,-4,4)
Block(-4,3,-3,101)
Block(-4,3,-2,4)
Block(-4,3,-1,4)
Block(-4,3,0,4)
Block(-4,4,-7,101)
Block(-4,4,-6,4)
Block(-4,4,-5,4)
Block(-4,4,-4,4)
Block(-4,4,-3,4)
Block(-4,4,-2,4)
Block(-4,4,-1,4)
Block(-4,4,0,4)
Block(-4,5,-6,67:2)
Block(-4,5,-5,1:6)
Block(-4,5,-4,98)
Block(-4,5,-3,98)
Block(-4,5,-2,98)
Block(-4,5,-1,1:6)
Block(-4,5,0,67:3)
Block(-4,6,-5,1:6)
Block(-4,6,-4,98)
Block(-4,6,-3,102)
Block(-4,6,-2,98)
Block(-4,6,-1,1:6)
Block(-4,7,-5,1:6)
Block(-4,7,-4,98)
Block(-4,7,-3,102)
Block(-4,7,-2,98)
Block(-4,7,-1,1:6)
Block(-4,8,-5,1:6)
Block(-4,8,-4,98)
Block(-4,8,-3,98)
Block(-4,8,-2,98)
Block(-4,8,-1,1:6)
Block(-4,9,-6,109:6)
Block(-4,9,-5,179:2)
Block(-4,9,-4,179:2)
Block(-4,9,-3,179:2)
Block(-4,9,-2,179:2)
Block(-4,9,-1,179:2)
Block(-4,9,0,109:7)
Block(-4,10,-6,17)
Block(-4,10,-5,47)
Block(-4,10,-4,47)
Block(-4,10,-3,47)
Block(-4,10,-2,47)
Block(-4,10,-1,47)
Block(-4,10,0,17)
Block(-4,11,-6,17)
Block(-4,11,-5,47)
Block(-4,11,-4,47)
Block(-4,11,-2,47)
Block(-4,11,-1,47)
Block(-4,11,0,17)
Block(-4,12,-6,17)
Block(-4,12,-5,164:7)
Block(-4,12,-4,47)
Block(-4,12,-3,47)
Block(-4,12,-2,47)
Block(-4,12,-1,164:6)
Block(-4,12,0,17)
Block(-4,13,-6,17)
Block(-4,13,-5,5:5)
Block(-4,13,-4,5:5)
Block(-4,13,-3,5:5)
Block(-4,13,-2,5:5)
Block(-4,13,-1,5:5)
Block(-4,13,0,17)
Block(-4,14,-7,126:13)
Block(-4,14,-6,17)
Block(-4,14,-5,171:7)
Block(-4,14,-4,171:7)
Block(-4,14,0,17)
Block(-4,14,1,126:13)
Block(-4,15,-6,164:2)
Block(-4,15,0,164:3)
Block(-4,16,-5,164:2)
Block(-4,16,-4,50:2)
Block(-4,16,-2,50:2)
Block(-4,16,-1,164:3)
Block(-4,17,-4,164:2)
Block(-4,17,-2,164:3)
Block(-4,18,-3,5:5)
Block(-3,0,-7,3)
Block(-3,0,-6,3)
Block(-3,0,-5,4)
Block(-3,0,-4,3)
Block(-3,0,-3,3)
Block(-3,0,-2,3)
Block(-3,0,-1,4)
Block(-3,0,0,3)
Block(-3,0,1,3)
Block(-3,1,-7,2)
Block(-3,1,-6,2)
Block(-3,1,-5,4)
Block(-3,1,-4,2)
Block(-3,1,-3,2)
Block(-3,1,-2,2)
Block(-3,1,-1,4)
Block(-3,1,0,2)
Block(-3,1,1,2)
Block(-3,2,-7,175:2)
Block(-3,2,-6,31:1)
Block(-3,2,-5,4)
Block(-3,2,-4,175:2)
Block(-3,2,-2,175:2)
Block(-3,2,-1,4)
Block(-3,2,0,31:1)
Block(-3,3,-7,175:10)
Block(-3,3,-5,4)
Block(-3,3,-4,175:10)
Block(-3,3,-2,175:10)
Block(-3,3,-1,4)
Block(-3,4,-5,4)
Block(-3,4,-1,4)
Block(-3,5,-5,67:1)
Block(-3,5,-1,67:1)
Block(-3,9,-6,85)
Block(-3,9,-5,109:5)
Block(-3,9,-1,109:5)
Block(-3,9,0,85)
Block(-3,10,-6,85)
Block(-3,10,-5,17)
Block(-3,10,-4,5:2)
Block(-3,10,-3,135:1)
Block(-3,10,-2,5:2)
Block(-3,10,-1,17)
Block(-3,10,0,85)
Block(-3,11,-6,85)
Block(-3,11,-5,17)
Block(-3,11,-4,5:2)
Block(-3,11,-3,102)
Block(-3,11,-2,5:2)
Block(-3,11,-1,17)
Block(-3,11,0,85)
Block(-3,12,-6,85)
Block(-3,12,-5,17)
Block(-3,12,-4,5:2)
Block(-3,12,-3,135:5)
Block(-3,12,-2,5:2)
Block(-3,12,-1,17)
Block(-3,12,0,85)
Block(-3,13,-6,85)
Block(-3,13,-5,17)
Block(-3,13,-4,5)
Block(-3,13,-3,5)
Block(-3,13,-2,5)
Block(-3,13,-1,17)
Block(-3,13,0,85)
Block(-3,14,-7,126:13)
Block(-3,14,-6,85)
Block(-3,14,-5,17)
Block(-3,14,-4,5)
Block(-3,14,-3,5)
Block(-3,14,-2,5)
Block(-3,14,-1,17)
Block(-3,14,0,85)
Block(-3,14,1,126:13)
Block(-3,15,-6,164:2)
Block(-3,15,-5,17)
Block(-3,15,-4,5)
Block(-3,15,-3,102)
Block(-3,15,-2,5)
Block(-3,15,-1,17)
Block(-3,15,0,164:3)
Block(-3,16,-5,164:2)
Block(-3,16,-4,5)
Block(-3,16,-3,102)
Block(-3,16,-2,5)
Block(-3,16,-1,164:3)
Block(-3,17,-4,164:2)
Block(-3,17,-3,5)
Block(-3,17,-2,164:3)
Block(-3,18,-3,5:5)
Block(-2,0,-7,3)
Block(-2,0,-6,3)
Block(-2,0,-5,3)
Block(-2,0,-4,3)
Block(-2,0,-3,3)
Block(-2,0,-2,3)
Block(-2,0,-1,3)
Block(-2,0,0,3)
Block(-2,0,1,3)
Block(-2,1,-7,2)
Block(-2,1,-6,2)
Block(-2,1,-5,2)
Block(-2,1,-4,2)
Block(-2,1,-3,2)
Block(-2,1,-2,2)
Block(-2,1,-1,2)
Block(-2,1,0,2)
Block(-2,1,1,2)
Block(-2,2,-6,31:1)
Block(-2,2,-5,31:1)
Block(-2,2,-2,31:1)
Block(-2,2,-1,31:1)
Block(-2,13,-6,85)
Block(-2,13,-5,85)
Block(-2,13,-4,85)
Block(-2,13,-3,85)
Block(-2,13,-2,85)
Block(-2,13,-1,85)
Block(-2,13,0,85)
Block(-2,14,-5,85)
Block(-2,14,-1,85)
Block(-2,15,-6,164:2)
Block(-2,15,-5,164:7)
Block(-2,15,-1,164:6)
Block(-2,15,0,164:3)
Block(-2,16,-5,164:2)
Block(-2,16,-4,164:7)
Block(-2,16,-2,164:6)
Block(-2,16,-1,164:3)
Block(-2,17,-4,164:2)
Block(-2,17,-3,126:13)
Block(-2,17,-2,164:3)
Block(-2,18,-3,5:5)
Block(-2,19,-3,126:5)
