

BranchFrequency: 10

BranchFrequencyGroup: CanOverride:0

CanOverride: true

SmoothRadius: -1

OverrideChildSettings: false

ReplaceAbove:
ReplaceBelow:

MustBeInside: VillageGeneratorStructurePlaceHolder, VillageGeneratorStructuresDelay, VillageGeneratorStructuresDelay2, VillageGeneratorStructuresDelay3, VillageGeneratorStructuresDelay4, VillageGeneratorStructuresDelay5, VillageGeneratorStructuresDelay6, VillageGeneratorStructuresDelay7, VillageGeneratorStructuresDelay8, VillageGeneratorStructuresDelay9, VillageGeneratorStructuresDelay10

Block(-8,0,-7,3)
Block(-8,0,-6,3)
Block(-8,0,-5,3)
Block(-8,0,-4,3)
Block(-8,0,-3,3)
Block(-8,0,-2,3)
Block(-8,0,-1,3)
Block(-8,0,0,3)
Block(-8,0,1,3)
Block(-8,0,2,3)
Block(-8,0,3,3)
Block(-8,0,4,3)
Block(-8,0,5,3)
Block(-8,0,6,4)
Block(-8,0,7,3)
Block(-8,0,8,4)
Block(-8,1,-7,2)
Block(-8,1,-6,2)
Block(-8,1,-5,2)
Block(-8,1,-4,2)
Block(-8,1,-3,2)
Block(-8,1,-2,2)
Block(-8,1,-1,2)
Block(-8,1,0,2)
Block(-8,1,1,2)
Block(-8,1,2,2)
Block(-8,1,3,2)
Block(-8,1,4,2)
Block(-8,1,5,2)
Block(-8,1,6,4)
Block(-8,1,7,2)
Block(-8,1,8,4)
Block(-8,2,4,31:1)
Block(-8,2,5,175:2)
Block(-8,2,6,4)
Block(-8,2,7,31:1)
Block(-8,2,8,4)
Block(-8,3,5,175:10)
Block(-8,3,6,4)
Block(-8,3,8,4)
Block(-8,4,6,4)
Block(-8,4,8,4)
Block(-8,5,6,67)
Block(-8,5,8,67)
Block(-8,16,4,164:2)
Block(-8,16,5,164:7)
Block(-8,17,5,164:2)
Block(-8,17,6,164:7)
Block(-8,17,8,164:6)
Block(-8,18,6,164:2)
Block(-8,18,7,164)
Block(-8,18,8,164)
Block(-7,0,-7,3)
Block(-7,0,-6,3)
Block(-7,0,-5,3)
Block(-7,0,-4,3)
Block(-7,0,-3,3)
Block(-7,0,-2,3)
Block(-7,0,-1,3)
Block(-7,0,0,3)
Block(-7,0,1,3)
Block(-7,0,2,3)
Block(-7,0,3,3)
Block(-7,0,4,3)
Block(-7,0,5,4)
Block(-7,0,6,4)
Block(-7,0,7,4)
Block(-7,0,8,4)
Block(-7,1,-7,2)
Block(-7,1,-6,2)
Block(-7,1,-5,2)
Block(-7,1,-4,2)
Block(-7,1,-3,2)
Block(-7,1,-2,2)
Block(-7,1,-1,2)
Block(-7,1,0,3)
Block(-7,1,1,3)
Block(-7,1,2,3)
Block(-7,1,3,3)
Block(-7,1,4,3)
Block(-7,1,5,4)
Block(-7,1,6,4)
Block(-7,1,7,4)
Block(-7,1,8,4)
Block(-7,2,0,2)
Block(-7,2,1,2)
Block(-7,2,2,2)
Block(-7,2,3,2)
Block(-7,2,4,2)
Block(-7,2,5,4)
Block(-7,2,6,4)
Block(-7,2,7,4)
Block(-7,2,8,4)
Block(-7,3,0,31:1)
Block(-7,3,3,31:1)
Block(-7,3,4,175:2)
Block(-7,3,5,4)
Block(-7,3,6,4)
Block(-7,3,7,4)
Block(-7,3,8,4)
Block(-7,4,4,175:10)
Block(-7,4,5,4)
Block(-7,4,6,4)
Block(-7,4,7,4)
Block(-7,4,8,4)
Block(-7,5,5,97:2)
Block(-7,5,6,97:2)
Block(-7,5,7,97:2)
Block(-7,5,8,97:2)
Block(-7,6,5,97:2)
Block(-7,6,6,1:6)
Block(-7,6,7,97:2)
Block(-7,6,8,1:6)
Block(-7,7,5,97:2)
Block(-7,7,6,1:6)
Block(-7,7,7,97:2)
Block(-7,7,8,1:6)
Block(-7,8,5,97:2)
Block(-7,8,6,1:6)
Block(-7,8,7,97:2)
Block(-7,8,8,1:6)
Block(-7,9,5,97:2)
Block(-7,9,6,160:11)
Block(-7,9,7,97:2)
Block(-7,9,8,160:11)
Block(-7,10,5,97:2)
Block(-7,10,6,160:11)
Block(-7,10,7,97:2)
Block(-7,10,8,160:11)
Block(-7,11,5,97:2)
Block(-7,11,6,160:11)
Block(-7,11,7,97:2)
Block(-7,11,8,160:11)
Block(-7,12,5,97:2)
Block(-7,12,6,1:6)
Block(-7,12,7,97:2)
Block(-7,12,8,1:6)
Block(-7,13,5,98)
Block(-7,13,6,1:6)
Block(-7,13,7,98)
Block(-7,13,8,1:6)
Block(-7,14,5,98)
Block(-7,14,6,1:6)
Block(-7,14,7,98)
Block(-7,14,8,1:6)
Block(-7,15,4,164:4)
Block(-7,15,5,98)
Block(-7,15,6,1:6)
Block(-7,15,7,98)
Block(-7,15,8,1:6)
Block(-7,16,4,164:2)
Block(-7,16,5,98)
Block(-7,16,6,1:6)
Block(-7,16,7,102)
Block(-7,16,8,1:6)
Block(-7,17,5,164:2)
Block(-7,17,6,1:6)
Block(-7,17,7,102)
Block(-7,17,8,1:6)
Block(-7,18,6,164:2)
Block(-7,18,7,5)
Block(-7,18,8,164:3)
Block(-7,19,7,164)
Block(-6,0,-7,3)
Block(-6,0,-6,3)
Block(-6,0,-5,3)
Block(-6,0,-4,3)
Block(-6,0,-3,3)
Block(-6,0,-2,3)
Block(-6,0,-1,3)
Block(-6,0,0,3)
Block(-6,0,1,3)
Block(-6,0,2,3)
Block(-6,0,3,3)
Block(-6,0,4,4)
Block(-6,0,5,112)
Block(-6,0,6,112)
Block(-6,0,7,112)
Block(-6,0,8,112)
Block(-6,1,-7,2)
Block(-6,1,-6,2)
Block(-6,1,-5,2)
Block(-6,1,-4,2)
Block(-6,1,-3,2)
Block(-6,1,-2,3)
Block(-6,1,-1,3)
Block(-6,1,0,3)
Block(-6,1,1,3)
Block(-6,1,2,3)
Block(-6,1,3,3)
Block(-6,1,4,4)
Block(-6,1,5,54:5,1-Chest.nbt)
Block(-6,1,6,54:5,2-Chest.nbt)
Block(-6,1,7,4)
Block(-6,1,8,54:5,3-Chest.nbt)
Block(-6,2,-4,31:1)
Block(-6,2,-3,31:1)
Block(-6,2,-2,2)
Block(-6,2,-1,2)
Block(-6,2,0,2)
Block(-6,2,1,2)
Block(-6,2,2,3)
Block(-6,2,3,3)
Block(-6,2,4,4)
Block(-6,2,5,126:13)
Block(-6,2,6,126:13)
Block(-6,2,7,4)
Block(-6,2,8,126:13)
Block(-6,3,-2,31:1)
Block(-6,3,2,2)
Block(-6,3,3,2)
Block(-6,3,4,4)
Block(-6,3,5,54:5,5-Chest.nbt)
Block(-6,3,6,54:5,6-Chest.nbt)
Block(-6,3,7,4)
Block(-6,4,2,31:1)
Block(-6,4,3,175:2)
Block(-6,4,4,4)
Block(-6,4,5,126:9)
Block(-6,4,6,126:9)
Block(-6,4,7,5:1)
Block(-6,4,8,126:9)
Block(-6,5,3,175:10)
Block(-6,5,4,97:2)
Block(-6,5,5,97:2)
Block(-6,5,6,97:2)
Block(-6,5,7,97:2)
Block(-6,5,8,97:2)
Block(-6,6,4,97:2)
Block(-6,6,5,97:2)
Block(-6,6,6,97:2)
Block(-6,6,7,97:2)
Block(-6,6,8,97:2)
Block(-6,7,4,97:2)
Block(-6,7,5,97:2)
Block(-6,7,6,97:2)
Block(-6,7,7,97:2)
Block(-6,7,8,97:2)
Block(-6,8,4,97:2)
Block(-6,8,5,126:13)
Block(-6,8,6,126:13)
Block(-6,8,7,126:13)
Block(-6,8,8,126:13)
Block(-6,9,4,97:2)
Block(-6,9,5,163:3)
Block(-6,9,6,171:10)
Block(-6,9,7,171:10)
Block(-6,9,8,171:10)
Block(-6,10,4,97:2)
Block(-6,11,4,97:2)
Block(-6,11,5,50:1)
Block(-6,12,4,97:2)
Block(-6,12,5,109:7)
Block(-6,12,6,109:5)
Block(-6,12,7,109:5)
Block(-6,12,8,109:5)
Block(-6,13,-6,164:2)
Block(-6,13,-5,164:7)
Block(-6,13,-4,85)
Block(-6,13,-3,85)
Block(-6,13,-2,85)
Block(-6,13,-1,85)
Block(-6,13,0,85)
Block(-6,13,1,85)
Block(-6,13,2,85)
Block(-6,13,3,85)
Block(-6,13,4,98)
Block(-6,13,5,98)
Block(-6,13,6,98)
Block(-6,13,7,98)
Block(-6,13,8,98)
Block(-6,14,-5,164:2)
Block(-6,14,-4,164:7)
Block(-6,14,-1,85)
Block(-6,14,0,53:4)
Block(-6,14,1,53:4)
Block(-6,14,2,53:4)
Block(-6,14,3,85)
Block(-6,14,4,98)
Block(-6,14,5,5)
Block(-6,14,6,5)
Block(-6,14,7,5)
Block(-6,14,8,5)
Block(-6,15,-4,164:2)
Block(-6,15,-3,164:7)
Block(-6,15,-1,85)
Block(-6,15,0,85)
Block(-6,15,1,85)
Block(-6,15,2,85)
Block(-6,15,3,164:6)
Block(-6,15,4,98)
Block(-6,15,5,54:3,7-Chest.nbt)
Block(-6,15,6,171:7)
Block(-6,15,7,171:7)
Block(-6,15,8,171:7)
Block(-6,16,-3,164:2)
Block(-6,16,-2,164)
Block(-6,16,-1,164)
Block(-6,16,0,164:2)
Block(-6,16,2,164:3)
Block(-6,16,3,164)
Block(-6,16,4,164:2)
Block(-6,17,1,126:5)
Block(-6,17,5,164:2)
Block(-6,17,6,50:1)
Block(-6,17,8,50:1)
Block(-6,18,6,164:2)
Block(-6,18,8,164:3)
Block(-6,19,7,5:5)
Block(-5,0,-7,3)
Block(-5,0,-6,3)
Block(-5,0,-5,4)
Block(-5,0,-4,3)
Block(-5,0,-3,3)
Block(-5,0,-2,3)
Block(-5,0,-1,4)
Block(-5,0,0,3)
Block(-5,0,1,3)
Block(-5,0,2,3)
Block(-5,0,3,4)
Block(-5,0,4,112)
Block(-5,0,5,112)
Block(-5,0,6,112)
Block(-5,0,7,112)
Block(-5,0,8,112)
Block(-5,1,-7,2)
Block(-5,1,-6,2)
Block(-5,1,-5,4)
Block(-5,1,-4,3)
Block(-5,1,-3,3)
Block(-5,1,-2,3)
Block(-5,1,-1,4)
Block(-5,1,0,3)
Block(-5,1,1,3)
Block(-5,1,2,3)
Block(-5,1,3,4)
Block(-5,1,4,54:3,9-Chest.nbt)
Block(-5,2,-6,175:2)
Block(-5,2,-5,4)
Block(-5,2,-4,2)
Block(-5,2,-3,2)
Block(-5,2,-2,2)
Block(-5,2,-1,4)
Block(-5,2,0,2)
Block(-5,2,1,2)
Block(-5,2,2,3)
Block(-5,2,3,4)
Block(-5,2,4,126:13)
Block(-5,3,-6,175:10)
Block(-5,3,-5,4)
Block(-5,3,-4,31:1)
Block(-5,3,-2,175:2)
Block(-5,3,-1,4)
Block(-5,3,0,175:2)
Block(-5,3,1,31:1)
Block(-5,3,2,2)
Block(-5,3,3,4)
Block(-5,3,4,54:3,11-Chest.nbt)
Block(-5,3,7,50:1)
Block(-5,4,-5,4)
Block(-5,4,-2,175:10)
Block(-5,4,-1,4)
Block(-5,4,0,175:10)
Block(-5,4,2,31:1)
Block(-5,4,3,4)
Block(-5,4,4,126:9)
Block(-5,4,5,126:9)
Block(-5,4,6,126:9)
Block(-5,4,7,5:1)
Block(-5,4,8,126:9)
Block(-5,5,-5,67)
Block(-5,5,-1,67)
Block(-5,5,3,67)
Block(-5,5,4,97:2)
Block(-5,5,5,97:2)
Block(-5,5,6,97:2)
Block(-5,5,7,97:2)
Block(-5,5,8,97:2)
Block(-5,6,4,97:2)
Block(-5,6,5,97:2)
Block(-5,6,6,97:2)
Block(-5,6,7,97:2)
Block(-5,6,8,97:2)
Block(-5,7,4,97:2)
Block(-5,7,5,97:2)
Block(-5,7,6,97:2)
Block(-5,7,7,97:2)
Block(-5,7,8,97:2)
Block(-5,8,4,97:2)
Block(-5,8,5,126:13)
Block(-5,8,6,126:13)
Block(-5,8,7,126:13)
Block(-5,8,8,126:13)
Block(-5,9,-6,85)
Block(-5,9,-5,109:4)
Block(-5,9,-1,109:4)
Block(-5,9,3,109:4)
Block(-5,9,4,97:2)
Block(-5,9,5,163)
Block(-5,9,6,163:3)
Block(-5,9,7,171:10)
Block(-5,9,8,171:10)
Block(-5,10,-6,85)
Block(-5,10,-5,17)
Block(-5,10,-4,5:2)
Block(-5,10,-3,135)
Block(-5,10,-2,5:2)
Block(-5,10,-1,17)
Block(-5,10,0,5:2)
Block(-5,10,1,135)
Block(-5,10,2,5:2)
Block(-5,10,3,17)
Block(-5,10,4,97:2)
Block(-5,11,-6,85)
Block(-5,11,-5,17)
Block(-5,11,-4,5:2)
Block(-5,11,-3,102)
Block(-5,11,-2,5:2)
Block(-5,11,-1,17)
Block(-5,11,0,5:2)
Block(-5,11,1,102)
Block(-5,11,2,5:2)
Block(-5,11,3,17)
Block(-5,11,4,97:2)
Block(-5,12,-7,126:13)
Block(-5,12,-6,85)
Block(-5,12,-5,17)
Block(-5,12,-4,5:2)
Block(-5,12,-3,135:4)
Block(-5,12,-2,5:2)
Block(-5,12,-1,17)
Block(-5,12,0,5:2)
Block(-5,12,1,135:4)
Block(-5,12,2,5:2)
Block(-5,12,3,17)
Block(-5,12,4,97:2)
Block(-5,12,5,109:7)
Block(-5,12,6,126:13)
Block(-5,12,7,126:13)
Block(-5,12,8,126:13)
Block(-5,13,-6,164:2)
Block(-5,13,-5,17)
Block(-5,13,-4,5)
Block(-5,13,-3,5)
Block(-5,13,-2,5)
Block(-5,13,-1,17)
Block(-5,13,0,5)
Block(-5,13,1,5)
Block(-5,13,2,5)
Block(-5,13,3,17)
Block(-5,13,4,5)
Block(-5,13,5,5)
Block(-5,13,6,5)
Block(-5,13,7,17)
Block(-5,13,8,5)
Block(-5,14,-5,164:2)
Block(-5,14,-4,5)
Block(-5,14,-3,5)
Block(-5,14,-2,5)
Block(-5,14,-1,17)
Block(-5,14,0,5)
Block(-5,14,1,5)
Block(-5,14,2,5)
Block(-5,14,3,17)
Block(-5,14,4,98)
Block(-5,14,5,5)
Block(-5,14,6,5)
Block(-5,14,7,5)
Block(-5,14,8,5)
Block(-5,15,-4,164:2)
Block(-5,15,-3,5)
Block(-5,15,-2,5)
Block(-5,15,-1,17)
Block(-5,15,0,5)
Block(-5,15,2,5)
Block(-5,15,3,17)
Block(-5,15,4,98)
Block(-5,15,5,54:3,13-Chest.nbt)
Block(-5,15,6,171:7)
Block(-5,15,7,171:7)
Block(-5,15,8,171:7)
Block(-5,16,-3,164:2)
Block(-5,16,-2,5)
Block(-5,16,-1,17)
Block(-5,16,0,5)
Block(-5,16,2,5)
Block(-5,16,3,17)
Block(-5,16,4,98)
Block(-5,17,-2,164:2)
Block(-5,17,-1,164)
Block(-5,17,0,164)
Block(-5,17,1,164)
Block(-5,17,2,164)
Block(-5,17,3,164)
Block(-5,17,4,164)
Block(-5,17,5,164)
Block(-5,18,6,164:2)
Block(-5,18,8,164:3)
Block(-5,19,7,5:5)
Block(-4,0,-7,3)
Block(-4,0,-6,4)
Block(-4,0,-5,4)
Block(-4,0,-4,4)
Block(-4,0,-3,4)
Block(-4,0,-2,4)
Block(-4,0,-1,4)
Block(-4,0,0,4)
Block(-4,0,1,4)
Block(-4,0,2,4)
Block(-4,0,3,4)
Block(-4,0,4,112)
Block(-4,0,5,112)
Block(-4,0,6,112)
Block(-4,0,7,112)
Block(-4,0,8,112)
Block(-4,1,-7,2)
Block(-4,1,-6,4)
Block(-4,1,-5,4)
Block(-4,1,-4,4)
Block(-4,1,-3,4)
Block(-4,1,-2,4)
Block(-4,1,-1,1:6)
Block(-4,1,0,4)
Block(-4,1,1,4)
Block(-4,1,2,4)
Block(-4,1,3,4)
Block(-4,1,4,4)
Block(-4,2,-7,31:1)
Block(-4,2,-6,4)
Block(-4,2,-5,4)
Block(-4,2,-4,4)
Block(-4,2,-3,4)
Block(-4,2,-2,4)
Block(-4,2,-1,1:6)
Block(-4,2,0,4)
Block(-4,2,1,4)
Block(-4,2,2,4)
Block(-4,2,3,4)
Block(-4,2,4,4)
Block(-4,3,-6,4)
Block(-4,3,-5,4)
Block(-4,3,-4,4)
Block(-4,3,-3,101)
Block(-4,3,-2,4)
Block(-4,3,-1,4)
Block(-4,3,0,4)
Block(-4,3,1,101)
Block(-4,3,2,4)
Block(-4,3,3,4)
Block(-4,3,4,4)
Block(-4,3,5,50:3)
Block(-4,4,-6,4)
Block(-4,4,-5,4)
Block(-4,4,-4,4)
Block(-4,4,-3,4)
Block(-4,4,-2,4)
Block(-4,4,-1,4)
Block(-4,4,0,4)
Block(-4,4,1,4)
Block(-4,4,2,4)
Block(-4,4,3,4)
Block(-4,4,4,5:1)
Block(-4,4,5,5:1)
Block(-4,4,6,5:1)
Block(-4,4,7,5:1)
Block(-4,4,8,5:1)
Block(-4,5,-6,67:2)
Block(-4,5,-5,1:6)
Block(-4,5,-4,98)
Block(-4,5,-3,98)
Block(-4,5,-2,98)
Block(-4,5,-1,1:6)
Block(-4,5,0,98)
Block(-4,5,1,98)
Block(-4,5,2,98)
Block(-4,5,3,1:6)
Block(-4,5,4,98)
Block(-4,5,5,97:2)
Block(-4,5,6,97:2)
Block(-4,5,7,97:2)
Block(-4,5,8,97:2)
Block(-4,6,-5,1:6)
Block(-4,6,-4,98)
Block(-4,6,-3,102)
Block(-4,6,-2,98)
Block(-4,6,-1,1:6)
Block(-4,6,0,98)
Block(-4,6,1,102)
Block(-4,6,2,98)
Block(-4,6,3,1:6)
Block(-4,6,4,98)
Block(-4,6,5,97:2)
Block(-4,6,6,55)
Block(-4,6,7,97:2)
Block(-4,6,8,97:2)
Block(-4,7,-5,1:6)
Block(-4,7,-4,98)
Block(-4,7,-3,102)
Block(-4,7,-2,98)
Block(-4,7,-1,1:6)
Block(-4,7,0,98)
Block(-4,7,1,102)
Block(-4,7,2,98)
Block(-4,7,3,1:6)
Block(-4,7,4,98)
Block(-4,7,5,55)
Block(-4,7,7,55)
Block(-4,7,8,55)
Block(-4,8,-5,1:6)
Block(-4,8,-4,98)
Block(-4,8,-3,98)
Block(-4,8,-2,98)
Block(-4,8,-1,1:6)
Block(-4,8,0,98)
Block(-4,8,1,98)
Block(-4,8,2,98)
Block(-4,8,3,1:6)
Block(-4,8,4,98)
Block(-4,8,5,98)
Block(-4,8,6,98)
Block(-4,8,7,1:6)
Block(-4,8,8,98)
Block(-4,9,-6,109:6)
Block(-4,9,-5,179:2)
Block(-4,9,-4,179:2)
Block(-4,9,-3,179:2)
Block(-4,9,-2,179:2)
Block(-4,9,-1,179:2)
Block(-4,9,0,179:2)
Block(-4,9,1,179:2)
Block(-4,9,2,179:2)
Block(-4,9,3,179:2)
Block(-4,9,4,179:2)
Block(-4,9,5,179:2)
Block(-4,9,6,179:2)
Block(-4,9,7,171:7)
Block(-4,9,8,171:7)
Block(-4,10,-6,17)
Block(-4,10,-5,171:7)
Block(-4,10,-4,163:1)
Block(-4,10,-3,163:1)
Block(-4,10,-2,163:1)
Block(-4,10,-1,171:7)
Block(-4,10,0,163:1)
Block(-4,10,1,163:1)
Block(-4,10,2,163:1)
Block(-4,10,3,171:7)
Block(-4,10,4,1:6)
Block(-4,10,5,98)
Block(-4,10,6,1:6)
Block(-4,11,-6,17)
Block(-4,11,4,1:6)
Block(-4,11,5,98)
Block(-4,11,6,1:6)
Block(-4,11,7,109:7)
Block(-4,11,8,109:6)
Block(-4,12,-7,126:13)
Block(-4,12,-6,17)
Block(-4,12,-5,164:7)
Block(-4,12,-1,164:5)
Block(-4,12,3,164:6)
Block(-4,12,4,1:6)
Block(-4,12,5,98)
Block(-4,12,6,1:6)
Block(-4,12,7,98)
Block(-4,12,8,98)
Block(-4,13,-6,164:2)
Block(-4,13,-5,5:5)
Block(-4,13,-4,5:5)
Block(-4,13,-3,5:5)
Block(-4,13,-2,5:5)
Block(-4,13,-1,5:5)
Block(-4,13,0,5:5)
Block(-4,13,1,5:5)
Block(-4,13,2,5:5)
Block(-4,13,3,5:5)
Block(-4,13,4,1:6)
Block(-4,13,5,1:4)
Block(-4,13,6,1:4)
Block(-4,13,7,1:4)
Block(-4,13,8,1:4)
Block(-4,14,-5,164:2)
Block(-4,14,-4,5)
Block(-4,14,-3,5)
Block(-4,14,-2,5)
Block(-4,14,-1,5)
Block(-4,14,0,5)
Block(-4,14,1,5)
Block(-4,14,2,5)
Block(-4,14,3,5)
Block(-4,14,4,98)
Block(-4,14,5,5)
Block(-4,14,6,5)
Block(-4,14,7,5)
Block(-4,14,8,5)
Block(-4,15,-4,164)
Block(-4,15,-3,5)
Block(-4,15,-2,26:9)
Block(-4,15,-1,171:15)
Block(-4,15,0,26:9)
Block(-4,15,1,171:15)
Block(-4,15,2,171:13)
Block(-4,15,3,171:15)
Block(-4,15,4,98)
Block(-4,15,5,171:7)
Block(-4,15,6,171:7)
Block(-4,15,7,171:7)
Block(-4,15,8,171:7)
Block(-4,16,-3,164:2)
Block(-4,16,4,98)
Block(-4,17,-2,164:2)
Block(-4,17,4,98)
Block(-4,18,-1,164)
Block(-4,18,0,164)
Block(-4,18,1,164)
Block(-4,18,2,164)
Block(-4,18,3,164)
Block(-4,18,4,164)
Block(-4,18,5,164)
Block(-4,18,6,164)
Block(-4,18,8,164)
Block(-4,19,7,5:5)
Block(-3,0,-7,3)
Block(-3,0,-6,3)
Block(-3,0,-5,4)
Block(-3,0,-4,1:6)
Block(-3,0,-3,1:6)
Block(-3,0,-2,1:6)
Block(-3,0,-1,1:6)
Block(-3,0,0,1:6)
Block(-3,0,1,1:6)
Block(-3,0,2,1:6)
Block(-3,0,3,1:6)
Block(-3,0,4,112)
Block(-3,0,5,112)
Block(-3,0,6,112)
Block(-3,0,7,112)
Block(-3,0,8,112)
Block(-3,1,-7,2)
Block(-3,1,-6,2)
Block(-3,1,-5,4)
Block(-3,1,-4,103)
Block(-3,1,-3,103)
Block(-3,1,0,5)
Block(-3,1,1,5)
Block(-3,1,3,45)
Block(-3,1,4,54:3,17-Chest.nbt)
Block(-3,2,-6,175:2)
Block(-3,2,-5,4)
Block(-3,2,-4,86:3)
Block(-3,2,1,5)
Block(-3,2,3,45)
Block(-3,2,4,126:13)
Block(-3,3,-6,175:10)
Block(-3,3,-5,4)
Block(-3,3,-1,109:5)
Block(-3,3,3,45)
Block(-3,3,4,54:3,18-Chest.nbt)
Block(-3,4,-5,4)
Block(-3,4,-4,126:9)
Block(-3,4,-3,126:9)
Block(-3,4,-2,126:9)
Block(-3,4,-1,5:1)
Block(-3,4,0,126:9)
Block(-3,4,1,126:9)
Block(-3,4,2,126:9)
Block(-3,4,3,5:1)
Block(-3,4,4,126:9)
Block(-3,4,5,126:9)
Block(-3,4,6,126:9)
Block(-3,4,7,5:1)
Block(-3,4,8,126:9)
Block(-3,5,-5,98)
Block(-3,5,-3,171:15)
Block(-3,5,-2,171:14)
Block(-3,5,-1,171:15)
Block(-3,5,0,171:14)
Block(-3,5,1,171:15)
Block(-3,5,2,171:14)
Block(-3,5,3,171:15)
Block(-3,5,4,98)
Block(-3,5,5,97:2)
Block(-3,5,6,97:2)
Block(-3,5,7,159:15)
Block(-3,5,8,159:15)
Block(-3,6,-5,98)
Block(-3,6,4,98)
Block(-3,6,5,97:2)
Block(-3,6,6,75:2)
Block(-3,6,7,159:15)
Block(-3,6,8,159:15)
Block(-3,7,-5,98)
Block(-3,7,4,98)
Block(-3,7,5,55)
Block(-3,7,7,159:15)
Block(-3,7,8,55)
Block(-3,8,-5,98)
Block(-3,8,-4,136:5)
Block(-3,8,-3,136:5)
Block(-3,8,-2,136:5)
Block(-3,8,-1,136:5)
Block(-3,8,0,136:5)
Block(-3,8,1,136:5)
Block(-3,8,2,136:5)
Block(-3,8,3,136:6)
Block(-3,8,4,155)
Block(-3,8,5,44:7)
Block(-3,8,6,44:7)
Block(-3,8,7,44:7)
Block(-3,8,8,44:7)
Block(-3,9,-5,179:2)
Block(-3,9,-4,179:2)
Block(-3,9,-3,179:2)
Block(-3,9,-2,179:2)
Block(-3,9,-1,179:2)
Block(-3,9,0,179:2)
Block(-3,9,1,179:2)
Block(-3,9,2,179:2)
Block(-3,9,3,134:3)
Block(-3,10,-6,5:2)
Block(-3,10,-5,163:3)
Block(-3,10,-4,171:10)
Block(-3,10,-3,171:10)
Block(-3,10,-2,171:10)
Block(-3,10,-1,171:10)
Block(-3,10,0,171:10)
Block(-3,10,1,171:10)
Block(-3,10,2,171:10)
Block(-3,11,-6,5:2)
Block(-3,11,6,50:1)
Block(-3,12,-7,126:13)
Block(-3,12,-6,5:2)
Block(-3,12,4,109:5)
Block(-3,13,-6,164:2)
Block(-3,13,-5,136:5)
Block(-3,13,-4,136:5)
Block(-3,13,-3,136:5)
Block(-3,13,-2,136:5)
Block(-3,13,-1,5:5)
Block(-3,13,0,136:5)
Block(-3,13,1,136:5)
Block(-3,13,2,136:5)
Block(-3,13,3,136:5)
Block(-3,13,4,1:4)
Block(-3,14,-5,164:2)
Block(-3,14,-4,5)
Block(-3,14,-3,5)
Block(-3,14,-2,5)
Block(-3,14,-1,5)
Block(-3,14,0,5)
Block(-3,14,1,5)
Block(-3,14,2,5)
Block(-3,14,3,5)
Block(-3,14,4,98)
Block(-3,14,5,5)
Block(-3,14,6,5)
Block(-3,14,7,5)
Block(-3,14,8,5)
Block(-3,15,-4,5:5)
Block(-3,15,-3,5)
Block(-3,15,-2,26:1)
Block(-3,15,-1,171:13)
Block(-3,15,0,26:1)
Block(-3,15,1,171:13)
Block(-3,15,2,171:15)
Block(-3,15,3,171:13)
Block(-3,15,5,171:7)
Block(-3,15,6,171:5)
Block(-3,15,7,171:5)
Block(-3,15,8,171:5)
Block(-3,16,-4,164)
Block(-3,16,-3,164)
Block(-3,17,-2,164:2)
Block(-3,17,4,109:5)
Block(-3,18,-1,5:5)
Block(-3,18,4,98)
Block(-3,19,0,126:5)
Block(-3,19,1,126:5)
Block(-3,19,2,126:5)
Block(-3,19,3,126:5)
Block(-3,19,4,126:5)
Block(-3,19,5,126:5)
Block(-3,19,6,126:5)
Block(-3,19,7,5:5)
Block(-3,19,8,126:5)
Block(-2,0,-7,3)
Block(-2,0,-6,3)
Block(-2,0,-5,4)
Block(-2,0,-4,1:6)
Block(-2,0,-3,1:6)
Block(-2,0,-2,1:6)
Block(-2,0,-1,1:6)
Block(-2,0,0,1:6)
Block(-2,0,1,1:6)
Block(-2,0,2,1:6)
Block(-2,0,3,1:6)
Block(-2,0,4,112)
Block(-2,0,5,112)
Block(-2,0,6,112)
Block(-2,0,7,112)
Block(-2,0,8,112)
Block(-2,1,-7,2)
Block(-2,1,-6,2)
Block(-2,1,-5,4)
Block(-2,1,-4,86)
Block(-2,1,0,5)
Block(-2,1,1,5)
Block(-2,1,3,45)
Block(-2,1,4,54:3,21-Chest.nbt)
Block(-2,2,-6,175:2)
Block(-2,2,-5,4)
Block(-2,2,-4,103)
Block(-2,2,1,5)
Block(-2,2,3,45)
Block(-2,2,4,126:13)
Block(-2,3,-6,175:10)
Block(-2,3,-5,101)
Block(-2,3,2,50:4)
Block(-2,3,3,45)
Block(-2,3,7,50:2)
Block(-2,4,-5,4)
Block(-2,4,-4,126:9)
Block(-2,4,-3,126:9)
Block(-2,4,-2,126:9)
Block(-2,4,-1,5:1)
Block(-2,4,0,126:9)
Block(-2,4,1,126:9)
Block(-2,4,2,126:9)
Block(-2,4,3,5:1)
Block(-2,4,4,126:9)
Block(-2,4,5,126:9)
Block(-2,4,6,126:9)
Block(-2,4,7,5:1)
Block(-2,4,8,5:1)
Block(-2,5,-5,98)
Block(-2,5,-4,171:15)
Block(-2,5,-3,171:14)
Block(-2,5,-2,163:1)
Block(-2,5,-1,171:14)
Block(-2,5,0,163:1)
Block(-2,5,1,171:14)
Block(-2,5,2,163:1)
Block(-2,5,3,171:14)
Block(-2,5,4,98)
Block(-2,5,5,97:2)
Block(-2,5,6,159:15)
Block(-2,5,7,171:15)
Block(-2,5,8,171:15)
Block(-2,6,-5,102)
Block(-2,6,4,98)
Block(-2,6,5,97:2)
Block(-2,6,6,159:15)
Block(-2,6,7,77:3)
Block(-2,7,-5,102)
Block(-2,7,4,98)
Block(-2,7,5,55)
Block(-2,7,6,55)
Block(-2,7,7,159:15)
Block(-2,7,8,159:15)
Block(-2,8,-5,98)
Block(-2,8,-4,136:7)
Block(-2,8,-3,126:11)
Block(-2,8,-2,136:4)
Block(-2,8,-1,136:4)
Block(-2,8,0,136:4)
Block(-2,8,1,136:4)
Block(-2,8,2,136:7)
Block(-2,8,3,136:6)
Block(-2,8,4,155)
Block(-2,8,5,44:7)
Block(-2,8,6,44:7)
Block(-2,8,7,44:7)
Block(-2,8,8,44:7)
Block(-2,9,-5,179:2)
Block(-2,9,-4,179:2)
Block(-2,9,-3,179:2)
Block(-2,9,-2,179:2)
Block(-2,9,-1,179:2)
Block(-2,9,0,179:2)
Block(-2,9,1,179:2)
Block(-2,9,2,179:2)
Block(-2,9,3,134:3)
Block(-2,10,-6,135:2)
Block(-2,10,-5,163:3)
Block(-2,10,-4,171:10)
Block(-2,10,-3,171:2)
Block(-2,10,-2,171:2)
Block(-2,10,-1,171:2)
Block(-2,10,0,171:2)
Block(-2,10,1,171:2)
Block(-2,10,2,171:10)
Block(-2,11,-6,102)
Block(-2,12,-7,126:13)
Block(-2,12,-6,135:6)
Block(-2,12,4,109:4)
Block(-2,13,-6,164:2)
Block(-2,13,-5,136:7)
Block(-2,13,-4,89)
Block(-2,13,-3,89)
Block(-2,13,-2,136:6)
Block(-2,13,-1,5:5)
Block(-2,13,0,136:7)
Block(-2,13,1,89)
Block(-2,13,2,89)
Block(-2,13,3,136:6)
Block(-2,13,4,1:4)
Block(-2,14,-5,5)
Block(-2,14,-4,5)
Block(-2,14,-3,5)
Block(-2,14,-2,5)
Block(-2,14,-1,5)
Block(-2,14,0,5)
Block(-2,14,1,5)
Block(-2,14,2,5)
Block(-2,14,3,5)
Block(-2,14,4,98)
Block(-2,14,5,5)
Block(-2,14,6,5)
Block(-2,14,7,5)
Block(-2,14,8,5)
Block(-2,15,-5,85)
Block(-2,15,-4,5)
Block(-2,15,-3,85)
Block(-2,15,-2,171:13)
Block(-2,15,-1,171:15)
Block(-2,15,0,171:13)
Block(-2,15,1,171:15)
Block(-2,15,2,171:13)
Block(-2,15,3,171:15)
Block(-2,15,5,171:7)
Block(-2,15,6,171:5)
Block(-2,15,7,171:5)
Block(-2,15,8,171:5)
Block(-2,16,-5,85)
Block(-2,16,-4,5)
Block(-2,16,-3,85)
Block(-2,17,-5,164)
Block(-2,17,-4,164)
Block(-2,17,-3,164)
Block(-2,17,-2,164:2)
Block(-2,17,4,109:4)
Block(-2,18,-1,5:5)
Block(-2,18,4,98)
Block(-2,19,0,126:5)
Block(-2,19,1,126:13)
Block(-2,19,2,126:13)
Block(-2,19,3,126:13)
Block(-2,19,4,125:5)
Block(-2,19,5,126:13)
Block(-2,19,6,126:13)
Block(-2,19,7,126:13)
Block(-2,19,8,126:13)
Block(-1,0,-7,3)
Block(-1,0,-6,3)
Block(-1,0,-5,4)
Block(-1,0,-4,1:6)
Block(-1,0,-3,1:6)
Block(-1,0,-2,1:6)
Block(-1,0,-1,1:6)
Block(-1,0,0,1:6)
Block(-1,0,1,1:6)
Block(-1,0,2,1:6)
Block(-1,0,3,1:6)
Block(-1,0,4,112)
Block(-1,0,5,112)
Block(-1,0,6,112)
Block(-1,0,7,112)
Block(-1,0,8,112)
Block(-1,1,-7,2)
Block(-1,1,-6,2)
Block(-1,1,-5,4)
Block(-1,1,0,5)
Block(-1,1,1,5)
Block(-1,1,3,45)
Block(-1,1,4,4)
Block(-1,1,5,54:4,22-Chest.nbt)
Block(-1,1,6,54:4,23-Chest.nbt)
Block(-1,1,7,4)
Block(-1,2,-7,31:1)
Block(-1,2,-6,175:2)
Block(-1,2,-5,4)
Block(-1,2,1,5)
Block(-1,2,3,45)
Block(-1,2,4,4)
Block(-1,2,5,126:13)
Block(-1,2,6,126:13)
Block(-1,2,7,4)
Block(-1,3,-6,175:10)
Block(-1,3,-5,4)
Block(-1,3,-1,109:4)
Block(-1,3,3,45)
Block(-1,3,5,54:4,24-Chest.nbt)
Block(-1,3,6,54:4,25-Chest.nbt)
Block(-1,3,7,4)
Block(-1,4,-5,4)
Block(-1,4,-4,126:9)
Block(-1,4,-3,126:9)
Block(-1,4,-2,126:9)
Block(-1,4,-1,5:1)
Block(-1,4,0,126:9)
Block(-1,4,1,126:9)
Block(-1,4,2,126:9)
Block(-1,4,3,5:1)
Block(-1,4,4,126:9)
Block(-1,4,5,126:9)
Block(-1,4,6,126:9)
Block(-1,4,7,5:1)
Block(-1,4,8,126:9)
Block(-1,5,-5,98)
Block(-1,5,-4,171:14)
Block(-1,5,-3,163:3)
Block(-1,5,-2,191)
Block(-1,5,-1,191)
Block(-1,5,0,191)
Block(-1,5,1,191)
Block(-1,5,2,191)
Block(-1,5,3,171:15)
Block(-1,5,4,1:6)
Block(-1,5,5,1:4)
Block(-1,5,6,1:4)
Block(-1,5,7,159:15)
Block(-1,5,8,159:15)
Block(-1,6,-5,98)
Block(-1,6,-2,171)
Block(-1,6,-1,171)
Block(-1,6,0,171)
Block(-1,6,1,171)
Block(-1,6,2,171)
Block(-1,6,4,1:6)
Block(-1,6,5,1:4)
Block(-1,6,6,159:15)
Block(-1,6,7,160:15)
Block(-1,6,8,160:15)
Block(-1,7,-5,98)
Block(-1,7,-1,89)
Block(-1,7,0,101)
Block(-1,7,1,89)
Block(-1,7,3,50:4)
Block(-1,7,4,1:6)
Block(-1,7,5,156:1)
Block(-1,7,6,156:1)
Block(-1,7,7,23:5,26-Trap.nbt)
Block(-1,7,8,23:5,27-Trap.nbt)
Block(-1,8,-5,98)
Block(-1,8,-4,136:7)
Block(-1,8,-3,126:11)
Block(-1,8,-2,136:6)
Block(-1,8,-1,1:6)
Block(-1,8,0,1:6)
Block(-1,8,1,1:6)
Block(-1,8,2,136:7)
Block(-1,8,3,136:6)
Block(-1,8,4,1:6)
Block(-1,8,7,156:5)
Block(-1,8,8,156:5)
Block(-1,9,-5,179:2)
Block(-1,9,-4,179:2)
Block(-1,9,-3,179:2)
Block(-1,9,-2,179:2)
Block(-1,9,-1,179:2)
Block(-1,9,0,179:2)
Block(-1,9,1,179:2)
Block(-1,9,2,179:2)
Block(-1,9,3,179:2)
Block(-1,9,4,1:6)
Block(-1,9,7,85)
Block(-1,9,8,85)
Block(-1,10,-6,5:2)
Block(-1,10,-5,163:3)
Block(-1,10,-4,171:10)
Block(-1,10,-3,171:2)
Block(-1,10,-2,171:10)
Block(-1,10,-1,171:10)
Block(-1,10,0,171:10)
Block(-1,10,1,171:2)
Block(-1,10,2,171:10)
Block(-1,10,3,171:7)
Block(-1,10,4,1:6)
Block(-1,11,-6,5:2)
Block(-1,11,4,1:6)
Block(-1,11,5,109:7)
Block(-1,12,-7,126:13)
Block(-1,12,-6,5:2)
Block(-1,12,4,1:6)
Block(-1,12,5,98)
Block(-1,12,6,98)
Block(-1,12,7,44:13)
Block(-1,12,8,44:13)
Block(-1,13,-6,164:2)
Block(-1,13,-5,136:4)
Block(-1,13,-4,136:4)
Block(-1,13,-3,136:4)
Block(-1,13,-2,136:6)
Block(-1,13,-1,5:5)
Block(-1,13,0,136:4)
Block(-1,13,1,136:4)
Block(-1,13,2,136:4)
Block(-1,13,3,136:4)
Block(-1,13,4,1:6)
Block(-1,13,5,1:4)
Block(-1,13,6,1:4)
Block(-1,13,7,1:4)
Block(-1,13,8,1:4)
Block(-1,14,-5,5)
Block(-1,14,-4,5)
Block(-1,14,-3,5)
Block(-1,14,-2,5)
Block(-1,14,-1,5)
Block(-1,14,0,5)
Block(-1,14,1,5)
Block(-1,14,2,5)
Block(-1,14,3,5)
Block(-1,14,4,98)
Block(-1,14,5,5)
Block(-1,14,6,5)
Block(-1,14,7,5)
Block(-1,14,8,5)
Block(-1,15,-5,85)
Block(-1,15,-3,171:13)
Block(-1,15,-2,171:15)
Block(-1,15,-1,171:13)
Block(-1,15,0,171:15)
Block(-1,15,1,171:13)
Block(-1,15,2,171:15)
Block(-1,15,3,171:13)
Block(-1,15,4,98)
Block(-1,15,5,171:7)
Block(-1,15,6,171:7)
Block(-1,15,7,171:7)
Block(-1,15,8,171:7)
Block(-1,16,4,98)
Block(-1,17,-5,164:6)
Block(-1,17,-4,5)
Block(-1,17,-3,50:3)
Block(-1,17,4,98)
Block(-1,17,6,50:2)
Block(-1,18,-5,164:2)
Block(-1,18,-4,5:5)
Block(-1,18,-3,5:5)
Block(-1,18,-2,5:5)
Block(-1,18,-1,5:5)
Block(-1,18,4,98)
Block(-1,19,0,126:5)
Block(-1,19,1,126:13)
Block(-1,19,4,98)
Block(-1,20,2,126:5)
Block(-1,20,3,126:5)
Block(-1,20,4,126:5)
Block(-1,20,5,126:5)
Block(-1,20,6,126:5)
Block(-1,20,7,126:5)
Block(-1,20,8,126:5)
Block(0,0,-7,3)
Block(0,0,-6,4)
Block(0,0,-5,4)
Block(0,0,-4,1:6)
Block(0,0,-3,1:6)
Block(0,0,-2,1:6)
Block(0,0,-1,1:6)
Block(0,0,0,1:6)
Block(0,0,1,1:6)
Block(0,0,2,1:6)
Block(0,0,3,1:6)
Block(0,0,4,1:6)
Block(0,0,5,1:6)
Block(0,0,6,1:6)
Block(0,0,7,1:6)
Block(0,0,8,1:6)
Block(0,1,-7,2)
Block(0,1,-6,4)
Block(0,1,-5,1:6)
Block(0,1,-1,1:6)
Block(0,1,3,1:6)
Block(0,1,4,45)
Block(0,1,5,45)
Block(0,1,6,45)
Block(0,1,7,1:6)
Block(0,1,8,45)
Block(0,2,-6,4)
Block(0,2,-5,1:6)
Block(0,2,-1,1:6)
Block(0,2,3,1:6)
Block(0,2,4,45)
Block(0,2,5,45)
Block(0,2,6,45)
Block(0,2,7,1:6)
Block(0,2,8,45)
Block(0,3,-6,4)
Block(0,3,-5,4)
Block(0,3,-4,109:7)
Block(0,3,-2,109:6)
Block(0,3,-1,1:6)
Block(0,3,0,109:7)
Block(0,3,2,109:6)
Block(0,3,3,1:6)
Block(0,3,4,45)
Block(0,3,5,45)
Block(0,3,6,45)
Block(0,3,7,1:6)
Block(0,3,8,45)
Block(0,4,-6,4)
Block(0,4,-5,4)
Block(0,4,-4,5:1)
Block(0,4,-3,5:1)
Block(0,4,-2,5:1)
Block(0,4,-1,5:1)
Block(0,4,0,5:1)
Block(0,4,1,5:1)
Block(0,4,2,5:1)
Block(0,4,3,5:1)
Block(0,4,4,5:1)
Block(0,4,5,5:1)
Block(0,4,6,5:1)
Block(0,4,7,5:1)
Block(0,4,8,5:1)
Block(0,5,-6,67:2)
Block(0,5,-5,1:6)
Block(0,5,-4,171:15)
Block(0,5,-3,171:14)
Block(0,5,-2,163)
Block(0,5,-1,171:14)
Block(0,5,0,163)
Block(0,5,1,171:14)
Block(0,5,2,163)
Block(0,5,3,171:14)
Block(0,5,4,98)
Block(0,5,5,1:4)
Block(0,5,6,1:4)
Block(0,5,7,1:4)
Block(0,5,8,1:4)
Block(0,6,-5,1:6)
Block(0,6,4,98)
Block(0,6,5,156:1)
Block(0,6,6,156:1)
Block(0,6,7,140,28-FlowerPot.nbt)
Block(0,6,8,140,29-FlowerPot.nbt)
Block(0,7,-5,1:6)
Block(0,7,4,98)
Block(0,8,-5,1:6)
Block(0,8,-4,136:7)
Block(0,8,-3,126:11)
Block(0,8,-2,136:6)
Block(0,8,-1,136:5)
Block(0,8,0,136:5)
Block(0,8,1,136:5)
Block(0,8,2,136:7)
Block(0,8,3,136:6)
Block(0,8,4,98)
Block(0,8,7,177:5,32-Banner.nbt)
Block(0,8,8,177:5,33-Banner.nbt)
Block(0,9,-6,109:6)
Block(0,9,-5,179:2)
Block(0,9,-4,179:2)
Block(0,9,-3,179:2)
Block(0,9,-2,179:2)
Block(0,9,-1,179:2)
Block(0,9,0,179:2)
Block(0,9,1,179:2)
Block(0,9,2,179:2)
Block(0,9,3,179:2)
Block(0,9,4,179:2)
Block(0,9,5,177:3,34-Banner.nbt)
Block(0,10,-6,17)
Block(0,10,-5,171:7)
Block(0,10,-4,171:10)
Block(0,10,-3,171:2)
Block(0,10,-2,171:10)
Block(0,10,-1,171:10)
Block(0,10,0,171:10)
Block(0,10,1,171:2)
Block(0,10,2,171:10)
Block(0,10,3,171:7)
Block(0,10,4,98)
Block(0,10,5,50:3)
Block(0,11,-6,17)
Block(0,11,4,98)
Block(0,12,-7,126:13)
Block(0,12,-6,17)
Block(0,12,-5,164:7)
Block(0,12,3,164:6)
Block(0,12,4,98)
Block(0,12,6,109:5)
Block(0,13,-6,164:2)
Block(0,13,-5,5:5)
Block(0,13,-4,5:5)
Block(0,13,-3,5:5)
Block(0,13,-2,5:5)
Block(0,13,-1,89)
Block(0,13,0,5:5)
Block(0,13,1,5:5)
Block(0,13,2,5:5)
Block(0,13,3,5:5)
Block(0,13,4,98)
Block(0,13,5,155)
Block(0,13,6,98)
Block(0,13,7,156:4)
Block(0,13,8,156:4)
Block(0,14,-5,5)
Block(0,14,-4,5)
Block(0,14,-3,5)
Block(0,14,-2,5)
Block(0,14,-1,5)
Block(0,14,0,5)
Block(0,14,1,5)
Block(0,14,2,5)
Block(0,14,3,5)
Block(0,14,4,98)
Block(0,14,5,98)
Block(0,14,6,98)
Block(0,14,7,98)
Block(0,14,8,98)
Block(0,15,-5,85)
Block(0,15,-4,5)
Block(0,15,-3,85)
Block(0,15,-2,171:13)
Block(0,15,-1,171:15)
Block(0,15,0,171:13)
Block(0,15,1,171:15)
Block(0,15,2,171:13)
Block(0,15,3,171:15)
Block(0,15,4,98)
Block(0,15,5,98)
Block(0,15,6,98)
Block(0,15,7,194)
Block(0,15,8,194)
Block(0,16,-5,85)
Block(0,16,-4,5)
Block(0,16,-3,85)
Block(0,16,4,98)
Block(0,16,5,98)
Block(0,16,6,98)
Block(0,16,7,194:8)
Block(0,16,8,194:9)
Block(0,17,-5,164:1)
Block(0,17,-4,164:1)
Block(0,17,-3,164:1)
Block(0,17,-2,164:2)
Block(0,17,3,50:4)
Block(0,17,4,98)
Block(0,17,5,98)
Block(0,17,6,98)
Block(0,17,7,98)
Block(0,17,8,98)
Block(0,18,-1,5:5)
Block(0,18,4,98)
Block(0,18,5,98)
Block(0,18,6,98)
Block(0,18,7,102)
Block(0,18,8,102)
Block(0,19,0,126:5)
Block(0,19,1,126:13)
Block(0,19,4,98)
Block(0,19,5,98)
Block(0,19,6,98)
Block(0,19,7,98)
Block(0,19,8,98)
Block(0,20,2,126:5)
Block(0,20,3,125:5)
Block(0,20,4,5:5)
Block(0,20,5,5:5)
Block(0,20,6,5:5)
Block(0,20,7,5:5)
Block(0,20,8,5:5)
Block(1,0,-7,3)
Block(1,0,-6,3)
Block(1,0,-5,4)
Block(1,0,-4,1:6)
Block(1,0,-3,1:6)
Block(1,0,-2,1:6)
Block(1,0,-1,1:6)
Block(1,0,0,1:6)
Block(1,0,1,1:6)
Block(1,0,2,1:6)
Block(1,0,3,1:6)
Block(1,0,4,112)
Block(1,0,5,112)
Block(1,0,6,112)
Block(1,0,7,112)
Block(1,0,8,112)
Block(1,1,-7,2)
Block(1,1,-6,2)
Block(1,1,-5,4)
Block(1,1,3,139)
Block(1,2,-6,31:1)
Block(1,2,-5,4)
Block(1,2,3,139)
Block(1,3,-5,4)
Block(1,3,-1,109:5)
Block(1,3,3,109:5)
Block(1,3,5,50:1)
Block(1,3,7,109:5)
Block(1,4,-5,4)
Block(1,4,-4,126:9)
Block(1,4,-3,126:9)
Block(1,4,-2,126:9)
Block(1,4,-1,5:1)
Block(1,4,0,126:9)
Block(1,4,1,126:9)
Block(1,4,2,126:9)
Block(1,4,3,5:1)
Block(1,4,4,126:9)
Block(1,4,5,126:9)
Block(1,4,6,126:9)
Block(1,4,7,5:1)
Block(1,4,8,126:9)
Block(1,5,-5,98)
Block(1,5,-4,171:14)
Block(1,5,-3,171:15)
Block(1,5,-2,171:14)
Block(1,5,-1,171:15)
Block(1,5,0,171:14)
Block(1,5,1,171:15)
Block(1,5,2,171:14)
Block(1,5,3,171:15)
Block(1,5,4,134:2)
Block(1,5,5,1:4)
Block(1,5,6,1:4)
Block(1,5,7,1:4)
Block(1,5,8,1:4)
Block(1,6,-5,98)
Block(1,7,-5,98)
Block(1,8,-5,98)
Block(1,8,-4,136:7)
Block(1,8,-3,126:11)
Block(1,8,-2,126:11)
Block(1,8,-1,126:11)
Block(1,8,0,126:11)
Block(1,8,1,126:11)
Block(1,8,2,126:11)
Block(1,8,3,136:6)
Block(1,8,4,109:5)
Block(1,9,-5,179:2)
Block(1,9,-4,179:2)
Block(1,9,-3,179:2)
Block(1,9,-2,179:2)
Block(1,9,-1,179:2)
Block(1,9,0,179:2)
Block(1,9,1,179:2)
Block(1,9,2,179:2)
Block(1,9,3,179:2)
Block(1,9,4,179:2)
Block(1,10,-6,5:2)
Block(1,10,-5,163:3)
Block(1,10,-4,171:10)
Block(1,10,-3,171:2)
Block(1,10,-2,171:2)
Block(1,10,-1,171:2)
Block(1,10,0,171:2)
Block(1,10,1,171:2)
Block(1,10,2,171:10)
Block(1,10,3,171:7)
Block(1,10,4,109:3)
Block(1,11,-6,5:2)
Block(1,12,-7,126:13)
Block(1,12,-6,5:2)
Block(1,12,4,109:5)
Block(1,12,7,95:1)
Block(1,12,8,95:1)
Block(1,13,-6,164:2)
Block(1,13,-5,136:7)
Block(1,13,-4,136:5)
Block(1,13,-3,136:5)
Block(1,13,-2,136:6)
Block(1,13,-1,5:5)
Block(1,13,0,136:5)
Block(1,13,1,136:5)
Block(1,13,2,136:5)
Block(1,13,3,136:6)
Block(1,13,4,98)
Block(1,13,5,155)
Block(1,13,6,98)
Block(1,13,7,89)
Block(1,13,8,89)
Block(1,14,-5,164:2)
Block(1,14,-4,5)
Block(1,14,-3,5)
Block(1,14,-2,5)
Block(1,14,-1,5)
Block(1,14,0,5)
Block(1,14,1,5)
Block(1,14,2,5)
Block(1,14,3,5)
Block(1,14,4,98)
Block(1,14,5,5)
Block(1,14,6,5)
Block(1,14,7,5)
Block(1,14,8,5)
Block(1,15,-4,5:5)
Block(1,15,-3,5)
Block(1,15,-2,171:15)
Block(1,15,-1,171:13)
Block(1,15,0,171:15)
Block(1,15,1,171:13)
Block(1,15,2,171:15)
Block(1,15,3,171:13)
Block(1,15,4,98)
Block(1,15,5,54:3,37-Chest.nbt)
Block(1,15,6,171:12)
Block(1,15,7,171:12)
Block(1,15,8,171:12)
Block(1,16,-4,164:1)
Block(1,16,-3,164:2)
Block(1,16,4,98)
Block(1,17,-2,164:2)
Block(1,17,0,50:2)
Block(1,17,4,98)
Block(1,17,6,50:1)
Block(1,18,-1,5:5)
Block(1,18,4,98)
Block(1,19,0,126:5)
Block(1,19,1,126:13)
Block(1,19,4,98)
Block(1,19,5,5:5)
Block(1,19,6,5:5)
Block(1,19,7,5:5)
Block(1,19,8,5:5)
Block(1,20,2,126:5)
Block(1,20,3,126:5)
Block(1,20,4,126:5)
Block(1,20,5,126:5)
Block(1,20,6,126:5)
Block(1,20,7,126:5)
Block(1,20,8,126:5)
Block(1,24,-1,109:4)
Block(1,24,0,44:13)
Block(1,24,1,109:4)
Block(1,25,-1,17:1)
Block(1,25,0,17:1)
Block(1,25,1,17:1)
Block(1,26,-1,85)
Block(1,26,1,85)
Block(1,27,-2,85)
Block(1,27,-1,85)
Block(1,27,0,85)
Block(1,27,1,85)
Block(1,27,2,85)
Block(1,28,-2,126:5)
Block(1,28,-1,126:5)
Block(1,28,0,126:5)
Block(1,28,1,126:5)
Block(1,28,2,126:5)
Block(2,0,-7,3)
Block(2,0,-6,3)
Block(2,0,-5,4)
Block(2,0,-4,1:6)
Block(2,0,-3,1:6)
Block(2,0,-2,1:6)
Block(2,0,-1,1:6)
Block(2,0,0,1:6)
Block(2,0,1,1:6)
Block(2,0,2,1:6)
Block(2,0,3,1:6)
Block(2,0,4,112)
Block(2,0,5,112)
Block(2,0,6,112)
Block(2,0,7,112)
Block(2,0,8,112)
Block(2,1,-7,2)
Block(2,1,-6,2)
Block(2,1,-5,4)
Block(2,2,-5,4)
Block(2,3,-5,101)
Block(2,3,3,44:13)
Block(2,4,-5,4)
Block(2,4,-4,126:9)
Block(2,4,-3,126:9)
Block(2,4,-2,126:9)
Block(2,4,-1,5:1)
Block(2,4,0,126:9)
Block(2,4,1,126:9)
Block(2,4,2,126:9)
Block(2,4,3,5:1)
Block(2,4,4,126:9)
Block(2,4,5,126:9)
Block(2,4,6,126:9)
Block(2,4,7,5:1)
Block(2,4,8,126:9)
Block(2,5,-5,98)
Block(2,5,-4,171:15)
Block(2,5,-3,171:14)
Block(2,5,-2,171:15)
Block(2,5,-1,171:14)
Block(2,5,0,171:15)
Block(2,5,1,171:14)
Block(2,5,2,171:15)
Block(2,5,3,171:14)
Block(2,5,4,134:2)
Block(2,5,5,1:4)
Block(2,5,6,1:4)
Block(2,5,7,1:4)
Block(2,5,8,1:4)
Block(2,6,-5,102)
Block(2,7,-5,102)
Block(2,8,-5,98)
Block(2,8,-4,136:7)
Block(2,8,-3,126:11)
Block(2,8,-2,126:11)
Block(2,8,-1,126:11)
Block(2,8,0,126:11)
Block(2,8,1,126:11)
Block(2,8,2,126:11)
Block(2,8,3,136:4)
Block(2,8,4,109:4)
Block(2,9,-5,179:2)
Block(2,9,-4,179:2)
Block(2,9,-3,179:2)
Block(2,9,-2,179:2)
Block(2,9,-1,179:2)
Block(2,9,0,179:2)
Block(2,9,1,179:2)
Block(2,9,2,179:2)
Block(2,9,3,179:2)
Block(2,9,4,179:2)
Block(2,10,-6,135:2)
Block(2,10,-5,163:3)
Block(2,10,-4,171:10)
Block(2,10,-3,171:10)
Block(2,10,-2,171:10)
Block(2,10,-1,171:10)
Block(2,10,0,171:10)
Block(2,10,1,171:10)
Block(2,10,2,171:10)
Block(2,10,3,171:7)
Block(2,10,4,109:3)
Block(2,11,-6,102)
Block(2,12,-7,126:13)
Block(2,12,-6,135:6)
Block(2,12,4,109:4)
Block(2,12,7,95:1)
Block(2,12,8,95:1)
Block(2,13,-6,164:2)
Block(2,13,-5,136:7)
Block(2,13,-4,89)
Block(2,13,-3,89)
Block(2,13,-2,136:6)
Block(2,13,-1,5:5)
Block(2,13,0,136:7)
Block(2,13,1,89)
Block(2,13,2,89)
Block(2,13,3,136:6)
Block(2,13,4,98)
Block(2,13,5,155)
Block(2,13,6,98)
Block(2,13,7,89)
Block(2,13,8,89)
Block(2,14,-5,164:2)
Block(2,14,-4,5)
Block(2,14,-3,5)
Block(2,14,-2,5)
Block(2,14,-1,5)
Block(2,14,0,4)
Block(2,14,1,5)
Block(2,14,2,5)
Block(2,14,3,1:6)
Block(2,14,4,98)
Block(2,14,5,5)
Block(2,14,6,5)
Block(2,14,7,5)
Block(2,14,8,5)
Block(2,15,-4,164:1)
Block(2,15,-3,5)
Block(2,15,-2,98)
Block(2,15,0,1:6)
Block(2,15,3,1:6)
Block(2,15,4,98)
Block(2,15,5,171:12)
Block(2,15,6,171:12)
Block(2,15,7,171:12)
Block(2,15,8,171:12)
Block(2,16,-3,164:2)
Block(2,16,-2,98)
Block(2,16,0,1:6)
Block(2,16,3,1:6)
Block(2,16,4,98)
Block(2,17,-2,164:2)
Block(2,17,-1,44:13)
Block(2,17,0,1:6)
Block(2,17,1,109:7)
Block(2,17,2,109:6)
Block(2,17,3,1:6)
Block(2,17,4,98)
Block(2,18,-1,1:6)
Block(2,18,0,1:6)
Block(2,18,1,98)
Block(2,18,2,98)
Block(2,18,3,1:6)
Block(2,18,4,98)
Block(2,19,-1,1:6)
Block(2,19,0,4)
Block(2,19,1,1:6)
Block(2,19,2,5:5)
Block(2,19,3,5:5)
Block(2,19,4,5:5)
Block(2,19,5,5:5)
Block(2,19,6,5:5)
Block(2,19,7,5:5)
Block(2,19,8,5:5)
Block(2,20,-1,1:6)
Block(2,20,0,101)
Block(2,20,1,1:6)
Block(2,21,-1,1:6)
Block(2,21,0,101)
Block(2,21,1,1:6)
Block(2,22,-1,1:6)
Block(2,22,0,4)
Block(2,22,1,1:6)
Block(2,23,-1,1:6)
Block(2,23,0,4)
Block(2,23,1,1:6)
Block(2,24,-2,109:4)
Block(2,24,-1,98)
Block(2,24,0,4)
Block(2,24,1,1:6)
Block(2,24,2,109:7)
Block(2,25,-2,17:1)
Block(2,25,-1,126:1)
Block(2,25,0,126:1)
Block(2,25,1,126:1)
Block(2,25,2,17:1)
Block(2,26,-2,85)
Block(2,26,2,85)
Block(2,27,-3,85)
Block(2,27,-2,85)
Block(2,27,2,85)
Block(2,27,3,85)
Block(2,28,-3,126:5)
Block(2,28,-2,126:5)
Block(2,28,-1,126:13)
Block(2,28,0,126:13)
Block(2,28,1,126:13)
Block(2,28,2,126:5)
Block(2,28,3,126:5)
Block(3,0,-7,3)
Block(3,0,-6,3)
Block(3,0,-5,4)
Block(3,0,-4,1:6)
Block(3,0,-3,1:6)
Block(3,0,-2,1:6)
Block(3,0,-1,1:6)
Block(3,0,0,1:6)
Block(3,0,1,1:6)
Block(3,0,2,1:6)
Block(3,0,3,1:6)
Block(3,0,4,112)
Block(3,0,5,112)
Block(3,0,6,112)
Block(3,0,7,112)
Block(3,0,8,112)
Block(3,1,-7,2)
Block(3,1,-6,2)
Block(3,1,-5,4)
Block(3,1,3,139)
Block(3,2,-6,175:2)
Block(3,2,-5,4)
Block(3,2,3,139)
Block(3,3,-6,175:10)
Block(3,3,-5,4)
Block(3,3,-3,50:2)
Block(3,3,-1,109:4)
Block(3,3,1,50:2)
Block(3,3,3,109:4)
Block(3,3,5,50:2)
Block(3,3,7,109:4)
Block(3,4,-5,4)
Block(3,4,-4,126:9)
Block(3,4,-3,126:9)
Block(3,4,-2,126:9)
Block(3,4,-1,5:1)
Block(3,4,0,126:9)
Block(3,4,1,126:9)
Block(3,4,2,126:9)
Block(3,4,3,5:1)
Block(3,4,4,126:9)
Block(3,4,5,126:9)
Block(3,4,6,126:9)
Block(3,4,7,5:1)
Block(3,4,8,126:9)
Block(3,5,-5,98)
Block(3,5,-4,171:14)
Block(3,5,-3,171:15)
Block(3,5,-2,171:14)
Block(3,5,-1,171:15)
Block(3,5,0,171:14)
Block(3,5,1,171:15)
Block(3,5,2,171:14)
Block(3,5,3,171:15)
Block(3,5,4,98)
Block(3,5,5,1:4)
Block(3,5,6,1:4)
Block(3,5,7,1:4)
Block(3,5,8,1:4)
Block(3,6,-5,98)
Block(3,6,4,98)
Block(3,6,7,70)
Block(3,6,8,70)
Block(3,7,-5,98)
Block(3,7,-1,50:2)
Block(3,7,4,98)
Block(3,8,-5,98)
Block(3,8,-4,136:4)
Block(3,8,-3,109:4)
Block(3,8,-2,109:4)
Block(3,8,-1,136:4)
Block(3,8,0,136:4)
Block(3,8,1,109:4)
Block(3,8,2,109:4)
Block(3,8,3,136:6)
Block(3,8,4,98)
Block(3,8,7,50:2)
Block(3,8,8,50:2)
Block(3,9,-5,179:2)
Block(3,9,-4,179:2)
Block(3,9,-3,179:2)
Block(3,9,-2,179:2)
Block(3,9,-1,179:2)
Block(3,9,0,179:2)
Block(3,9,1,134:1)
Block(3,9,2,134:1)
Block(3,9,3,179:2)
Block(3,9,4,179:2)
Block(3,9,5,177:3,38-Banner.nbt)
Block(3,9,6,177:4,39-Banner.nbt)
Block(3,10,-6,5:2)
Block(3,10,-5,163:3)
Block(3,10,-4,171:7)
Block(3,10,-3,171:7)
Block(3,10,-2,171:7)
Block(3,10,-1,171:7)
Block(3,10,0,171:7)
Block(3,10,3,171:7)
Block(3,10,4,98)
Block(3,10,5,50:3)
Block(3,11,-6,5:2)
Block(3,11,4,98)
Block(3,12,-7,126:13)
Block(3,12,-6,5:2)
Block(3,12,4,98)
Block(3,12,6,109:4)
Block(3,13,-6,164:2)
Block(3,13,-5,136:7)
Block(3,13,-4,136:4)
Block(3,13,-3,136:4)
Block(3,13,-2,136:4)
Block(3,13,-1,5:5)
Block(3,13,0,136:4)
Block(3,13,1,136:4)
Block(3,13,2,136:4)
Block(3,13,3,136:4)
Block(3,13,4,98)
Block(3,13,5,155)
Block(3,13,6,98)
Block(3,13,7,156:5)
Block(3,13,8,156:5)
Block(3,14,-5,164:2)
Block(3,14,-4,5)
Block(3,14,-3,5)
Block(3,14,-2,5)
Block(3,14,-1,5)
Block(3,14,0,98)
Block(3,14,1,134:1)
Block(3,14,2,134:1)
Block(3,14,3,98)
Block(3,14,4,98)
Block(3,14,5,5)
Block(3,14,6,5)
Block(3,14,7,5)
Block(3,14,8,5)
Block(3,15,-4,164:2)
Block(3,15,-3,5)
Block(3,15,0,109:1)
Block(3,15,3,98)
Block(3,15,4,98)
Block(3,15,5,26:10)
Block(3,15,6,26:2)
Block(3,15,7,163)
Block(3,15,8,54:4,42-Chest.nbt)
Block(3,16,-3,164:2)
Block(3,16,3,98)
Block(3,16,4,98)
Block(3,17,-2,67:7)
Block(3,17,0,109:5)
Block(3,17,3,98)
Block(3,17,4,98)
Block(3,17,6,50:2)
Block(3,18,-2,97:1)
Block(3,18,-1,109:5)
Block(3,18,0,98)
Block(3,18,1,126:9)
Block(3,18,2,4)
Block(3,18,3,98)
Block(3,18,4,98)
Block(3,18,5,164:4)
Block(3,18,6,164:4)
Block(3,18,7,164:4)
Block(3,18,8,164:4)
Block(3,19,-2,4)
Block(3,19,-1,125:1)
Block(3,19,0,126:1)
Block(3,19,2,4)
Block(3,19,3,126:5)
Block(3,19,4,126:5)
Block(3,19,5,126:5)
Block(3,19,6,126:5)
Block(3,19,7,164:2)
Block(3,19,8,164:3)
Block(3,20,-2,4)
Block(3,20,2,4)
Block(3,21,-2,4)
Block(3,21,2,4)
Block(3,22,-2,4)
Block(3,22,-1,50:3)
Block(3,22,1,109:5)
Block(3,22,2,4)
Block(3,23,-2,4)
Block(3,23,-1,109:5)
Block(3,23,0,134:5)
Block(3,23,1,109:1)
Block(3,23,2,4)
Block(3,24,-3,109:6)
Block(3,24,-2,4)
Block(3,24,-1,98)
Block(3,24,1,109:5)
Block(3,24,2,4)
Block(3,24,3,109:4)
Block(3,25,-3,17:1)
Block(3,25,-2,126:1)
Block(3,25,-1,126:1)
Block(3,25,0,126:1)
Block(3,25,1,126:1)
Block(3,25,2,126:1)
Block(3,25,3,17:1)
Block(3,26,-3,85)
Block(3,26,3,85)
Block(3,27,-4,85)
Block(3,27,-3,85)
Block(3,27,3,85)
Block(3,27,4,85)
Block(3,28,-4,126:5)
Block(3,28,-3,126:5)
Block(3,28,-2,126:13)
Block(3,28,-1,126:13)
Block(3,28,0,89)
Block(3,28,1,126:13)
Block(3,28,2,126:13)
Block(3,28,3,126:5)
Block(3,28,4,126:5)
Block(3,29,-1,164)
Block(3,29,0,164)
Block(3,29,1,164)
Block(4,0,-7,3)
Block(4,0,-6,4)
Block(4,0,-5,4)
Block(4,0,-4,1:6)
Block(4,0,-3,1:6)
Block(4,0,-2,1:6)
Block(4,0,-1,4)
Block(4,0,0,4)
Block(4,0,1,4)
Block(4,0,2,4)
Block(4,0,3,4)
Block(4,0,4,4)
Block(4,0,5,4)
Block(4,0,6,4)
Block(4,0,7,4)
Block(4,0,8,4)
Block(4,1,-7,2)
Block(4,1,-6,4)
Block(4,1,-5,4)
Block(4,1,-4,45)
Block(4,1,-3,193:2)
Block(4,1,-2,45)
Block(4,1,-1,1:6)
Block(4,1,0,4)
Block(4,1,1,4)
Block(4,1,2,4)
Block(4,1,3,1:6)
Block(4,1,4,4)
Block(4,1,5,4)
Block(4,1,6,4)
Block(4,1,7,1:6)
Block(4,1,8,45)
Block(4,2,-6,4)
Block(4,2,-5,4)
Block(4,2,-4,45)
Block(4,2,-3,193:8)
Block(4,2,-2,45)
Block(4,2,-1,1:6)
Block(4,2,0,4)
Block(4,2,1,4)
Block(4,2,2,4)
Block(4,2,3,1:6)
Block(4,2,4,4)
Block(4,2,5,4)
Block(4,2,6,4)
Block(4,2,7,1:6)
Block(4,2,8,45)
Block(4,3,-6,4)
Block(4,3,-5,4)
Block(4,3,-4,45)
Block(4,3,-3,45)
Block(4,3,-2,45)
Block(4,3,-1,4)
Block(4,3,0,4)
Block(4,3,1,4)
Block(4,3,2,4)
Block(4,3,3,4)
Block(4,3,4,4)
Block(4,3,5,4)
Block(4,3,6,4)
Block(4,3,7,4)
Block(4,3,8,45)
Block(4,4,-6,4)
Block(4,4,-5,4)
Block(4,4,-4,5:1)
Block(4,4,-3,5:1)
Block(4,4,-2,5:1)
Block(4,4,-1,4)
Block(4,4,0,5:1)
Block(4,4,1,134:1)
Block(4,4,2,134:1)
Block(4,4,3,1:6)
Block(4,4,4,4)
Block(4,4,5,4)
Block(4,4,6,4)
Block(4,4,7,4)
Block(4,4,8,4)
Block(4,5,-6,67:2)
Block(4,5,-5,1:6)
Block(4,5,-4,98)
Block(4,5,-3,171:7)
Block(4,5,-2,171:7)
Block(4,5,-1,1:6)
Block(4,5,0,98)
Block(4,5,3,98)
Block(4,5,4,98)
Block(4,5,5,98)
Block(4,5,6,1:6)
Block(4,5,7,98)
Block(4,5,8,98)
Block(4,6,-5,1:6)
Block(4,6,-4,98)
Block(4,6,-1,1:6)
Block(4,6,0,98)
Block(4,6,3,98)
Block(4,6,4,98)
Block(4,6,5,98)
Block(4,6,6,1:6)
Block(4,6,7,193:2)
Block(4,6,8,193:2)
Block(4,7,-5,1:6)
Block(4,7,-4,98)
Block(4,7,-3,109:7)
Block(4,7,-2,109:6)
Block(4,7,-1,1:6)
Block(4,7,0,98)
Block(4,7,1,109:7)
Block(4,7,2,109:6)
Block(4,7,3,98)
Block(4,7,4,98)
Block(4,7,5,160:11)
Block(4,7,6,1:6)
Block(4,7,7,193:9)
Block(4,7,8,193:8)
Block(4,8,-5,1:6)
Block(4,8,-4,98)
Block(4,8,-3,98)
Block(4,8,-2,98)
Block(4,8,-1,1:6)
Block(4,8,0,98)
Block(4,8,1,134:1)
Block(4,8,2,134:1)
Block(4,8,3,98)
Block(4,8,4,98)
Block(4,8,5,160:11)
Block(4,8,6,1:6)
Block(4,8,7,98)
Block(4,8,8,98)
Block(4,9,-6,109:6)
Block(4,9,-5,179:2)
Block(4,9,-4,179:2)
Block(4,9,-3,179:2)
Block(4,9,-2,179:2)
Block(4,9,-1,179:2)
Block(4,9,0,98)
Block(4,9,3,98)
Block(4,9,4,98)
Block(4,9,5,179:2)
Block(4,9,6,1:6)
Block(4,9,7,179:2)
Block(4,9,8,179:2)
Block(4,10,-6,17)
Block(4,10,-5,171:7)
Block(4,10,-4,171:7)
Block(4,10,-3,171:7)
Block(4,10,-2,171:7)
Block(4,10,-1,171:7)
Block(4,10,0,98)
Block(4,10,3,98)
Block(4,10,4,98)
Block(4,10,5,98)
Block(4,10,6,1:6)
Block(4,10,7,160:11)
Block(4,10,8,160:11)
Block(4,11,-6,17)
Block(4,11,0,98)
Block(4,11,3,98)
Block(4,11,4,98)
Block(4,11,5,98)
Block(4,11,6,1:6)
Block(4,11,7,160:11)
Block(4,11,8,160:11)
Block(4,12,-7,126:13)
Block(4,12,-6,17)
Block(4,12,-5,164:7)
Block(4,12,-1,164:4)
Block(4,12,0,98)
Block(4,12,3,98)
Block(4,12,4,98)
Block(4,12,5,98)
Block(4,12,6,1:6)
Block(4,12,7,109:7)
Block(4,12,8,109:6)
Block(4,13,-6,164:2)
Block(4,13,-5,5:5)
Block(4,13,-4,5:5)
Block(4,13,-3,5:5)
Block(4,13,-2,5:5)
Block(4,13,-1,5:5)
Block(4,13,0,98)
Block(4,13,1,134:1)
Block(4,13,2,134:1)
Block(4,13,3,1:6)
Block(4,13,4,98)
Block(4,13,5,98)
Block(4,13,6,1:6)
Block(4,13,7,98)
Block(4,13,8,98)
Block(4,14,-5,164:2)
Block(4,14,-4,5)
Block(4,14,-3,1:6)
Block(4,14,-2,5)
Block(4,14,-1,5)
Block(4,14,0,98)
Block(4,14,3,1:6)
Block(4,14,4,98)
Block(4,14,5,98)
Block(4,14,6,1:6)
Block(4,14,7,98)
Block(4,14,8,98)
Block(4,15,-4,164:2)
Block(4,15,-3,1:6)
Block(4,15,0,109)
Block(4,15,3,1:6)
Block(4,15,4,98)
Block(4,15,5,98)
Block(4,15,6,1:6)
Block(4,15,7,98)
Block(4,15,8,98)
Block(4,16,-3,1:6)
Block(4,16,-2,50:2)
Block(4,16,3,1:6)
Block(4,16,4,98)
Block(4,16,5,98)
Block(4,16,6,1:6)
Block(4,16,7,102)
Block(4,16,8,102)
Block(4,17,-3,1:6)
Block(4,17,-2,67:7)
Block(4,17,0,109:4)
Block(4,17,3,1:6)
Block(4,17,4,98)
Block(4,17,5,98)
Block(4,17,6,1:6)
Block(4,17,7,109:7)
Block(4,17,8,109:6)
Block(4,18,-3,1:6)
Block(4,18,-2,4)
Block(4,18,0,98)
Block(4,18,1,126:9)
Block(4,18,2,126:9)
Block(4,18,3,1:6)
Block(4,18,4,164:1)
Block(4,18,5,164:1)
Block(4,18,6,164:2)
Block(4,18,7,98)
Block(4,18,8,98)
Block(4,19,-3,1:6)
Block(4,19,-2,5:1)
Block(4,19,-1,125:1)
Block(4,19,0,126:1)
Block(4,19,3,1:6)
Block(4,19,7,164:2)
Block(4,19,8,164:3)
Block(4,20,-3,1:6)
Block(4,20,3,1:6)
Block(4,21,-3,1:6)
Block(4,21,2,50:1)
Block(4,21,3,1:6)
Block(4,22,-3,1:6)
Block(4,22,1,126:9)
Block(4,22,2,109:6)
Block(4,22,3,1:6)
Block(4,23,-3,1:6)
Block(4,23,-1,126:9)
Block(4,23,0,134:3)
Block(4,23,2,109:2)
Block(4,23,3,1:6)
Block(4,24,-4,109:6)
Block(4,24,-3,1:6)
Block(4,24,-2,109:7)
Block(4,24,2,109:6)
Block(4,24,3,1:6)
Block(4,24,4,109:7)
Block(4,25,-4,17:1)
Block(4,25,-3,126:1)
Block(4,25,-2,126:1)
Block(4,25,2,126:1)
Block(4,25,3,126:1)
Block(4,25,4,17:1)
Block(4,26,-4,85)
Block(4,26,4,85)
Block(4,27,-4,85)
Block(4,27,4,85)
Block(4,28,-4,126:5)
Block(4,28,-3,126:13)
Block(4,28,-2,126:13)
Block(4,28,2,126:13)
Block(4,28,3,126:13)
Block(4,28,4,126:5)
Block(4,29,-2,164)
Block(4,29,-1,164:2)
Block(4,29,0,126:13)
Block(4,29,1,164:3)
Block(4,29,2,164)
Block(4,30,0,5:5)
Block(5,0,-7,3)
Block(5,0,-6,3)
Block(5,0,-5,4)
Block(5,0,-4,1:6)
Block(5,0,-3,1:6)
Block(5,0,-2,1:6)
Block(5,0,-1,4)
Block(5,0,0,1:6)
Block(5,0,3,4)
Block(5,0,4,3)
Block(5,0,5,3)
Block(5,0,6,3)
Block(5,0,7,4)
Block(5,0,8,112)
Block(5,1,-7,2)
Block(5,1,-6,2)
Block(5,1,-5,4)
Block(5,1,-1,4)
Block(5,1,0,1:6)
Block(5,1,3,4)
Block(5,1,4,3)
Block(5,1,5,3)
Block(5,1,6,3)
Block(5,1,7,4)
Block(5,2,-7,31:1)
Block(5,2,-6,175:2)
Block(5,2,-5,4)
Block(5,2,-1,4)
Block(5,2,0,1:6)
Block(5,2,3,4)
Block(5,2,4,3)
Block(5,2,5,3)
Block(5,2,6,3)
Block(5,2,7,4)
Block(5,3,-6,175:10)
Block(5,3,-5,4)
Block(5,3,-3,50:1)
Block(5,3,-1,4)
Block(5,3,0,1:6)
Block(5,3,1,134:1)
Block(5,3,2,134:1)
Block(5,3,3,4)
Block(5,3,4,3)
Block(5,3,5,3)
Block(5,3,6,3)
Block(5,3,7,4)
Block(5,3,8,126:8)
Block(5,4,-5,4)
Block(5,4,-4,126:9)
Block(5,4,-3,126:9)
Block(5,4,-2,126:9)
Block(5,4,-1,89)
Block(5,4,0,1:6)
Block(5,4,3,4)
Block(5,4,4,2)
Block(5,4,5,2)
Block(5,4,6,2)
Block(5,4,7,43)
Block(5,4,8,43)
Block(5,5,-5,98)
Block(5,5,-4,171:7)
Block(5,5,-3,171:7)
Block(5,5,-2,171:7)
Block(5,5,-1,98)
Block(5,5,0,1:6)
Block(5,5,3,4)
Block(5,5,4,175:3)
Block(5,5,5,31:2)
Block(5,5,6,175:4)
Block(5,5,7,44)
Block(5,5,8,44)
Block(5,6,-5,98)
Block(5,6,-1,98)
Block(5,6,0,1:6)
Block(5,6,3,4)
Block(5,6,4,175:10)
Block(5,6,6,175:10)
Block(5,7,-5,98)
Block(5,7,-1,98)
Block(5,7,0,1:6)
Block(5,7,1,134:1)
Block(5,7,2,134:1)
Block(5,7,3,4)
Block(5,8,-5,98)
Block(5,8,-4,109:5)
Block(5,8,-3,109:5)
Block(5,8,-2,109:5)
Block(5,8,-1,98)
Block(5,8,0,1:6)
Block(5,8,3,4)
Block(5,9,-5,179:2)
Block(5,9,-4,98)
Block(5,9,-3,98)
Block(5,9,-2,98)
Block(5,9,-1,98)
Block(5,9,0,1:6)
Block(5,9,3,4)
Block(5,9,6,109:5)
Block(5,10,-6,5:2)
Block(5,10,-5,98)
Block(5,10,-4,171:15)
Block(5,10,-3,171:15)
Block(5,10,-2,171:15)
Block(5,10,-1,98)
Block(5,10,0,1:6)
Block(5,10,3,4)
Block(5,10,6,139)
Block(5,11,-6,5:2)
Block(5,11,-5,98)
Block(5,11,-1,98)
Block(5,11,0,1:6)
Block(5,11,3,4)
Block(5,11,6,139)
Block(5,12,-7,126:13)
Block(5,12,-6,5:2)
Block(5,12,-5,98)
Block(5,12,-4,109:7)
Block(5,12,-2,109:6)
Block(5,12,-1,98)
Block(5,12,0,1:6)
Block(5,12,1,134:1)
Block(5,12,2,134:1)
Block(5,12,3,4)
Block(5,12,6,139)
Block(5,13,-6,164:2)
Block(5,13,-5,98)
Block(5,13,-4,98)
Block(5,13,-3,98)
Block(5,13,-2,98)
Block(5,13,-1,98)
Block(5,13,0,1:6)
Block(5,13,3,4)
Block(5,13,6,139)
Block(5,14,-5,164:2)
Block(5,14,-3,4)
Block(5,14,-2,98)
Block(5,14,-1,98)
Block(5,14,0,1:6)
Block(5,14,3,4)
Block(5,14,6,139)
Block(5,15,-4,164:2)
Block(5,15,-3,4)
Block(5,15,-2,4)
Block(5,15,-1,134)
Block(5,15,0,1:6)
Block(5,15,3,4)
Block(5,15,6,139)
Block(5,16,-3,4)
Block(5,16,-2,4)
Block(5,16,0,1:6)
Block(5,16,3,97:1)
Block(5,16,6,139)
Block(5,17,-3,97:1)
Block(5,17,-2,97:1)
Block(5,17,0,1:6)
Block(5,17,1,109:7)
Block(5,17,2,126:9)
Block(5,17,3,97:1)
Block(5,17,4,164:1)
Block(5,17,5,164:1)
Block(5,17,6,164:7)
Block(5,18,-3,97:1)
Block(5,18,-2,97:1)
Block(5,18,0,1:6)
Block(5,18,1,126:1)
Block(5,18,2,126:1)
Block(5,18,3,97:1)
Block(5,18,6,164:2)
Block(5,18,7,164:7)
Block(5,18,8,164:6)
Block(5,19,-3,4)
Block(5,19,-2,4)
Block(5,19,0,1:6)
Block(5,19,3,101)
Block(5,19,7,164:2)
Block(5,19,8,164:3)
Block(5,20,-3,4)
Block(5,20,-2,126:1)
Block(5,20,-1,126:1)
Block(5,20,0,1:6)
Block(5,20,3,101)
Block(5,21,-3,101)
Block(5,21,0,1:6)
Block(5,21,3,4)
Block(5,22,-3,101)
Block(5,22,0,1:6)
Block(5,22,1,126:1)
Block(5,22,2,126:1)
Block(5,22,3,4)
Block(5,23,-3,4)
Block(5,23,0,1:6)
Block(5,23,3,101)
Block(5,24,-4,44:13)
Block(5,24,-3,98)
Block(5,24,-1,134)
Block(5,24,0,1:6)
Block(5,24,3,101)
Block(5,24,4,44:13)
Block(5,25,-4,17:1)
Block(5,25,-3,126:1)
Block(5,25,-2,126:1)
Block(5,25,0,1:6)
Block(5,25,1,126:1)
Block(5,25,2,126:1)
Block(5,25,3,126:1)
Block(5,25,4,17:1)
Block(5,26,0,1:6)
Block(5,27,-4,85)
Block(5,27,0,1:6)
Block(5,27,4,85)
Block(5,28,-4,126:5)
Block(5,28,-3,126:13)
Block(5,28,-2,89)
Block(5,28,0,1:6)
Block(5,28,2,89)
Block(5,28,3,126:13)
Block(5,28,4,126:5)
Block(5,29,-2,164:2)
Block(5,29,-1,126:13)
Block(5,29,0,1:6)
Block(5,29,1,126:13)
Block(5,29,2,164:3)
Block(5,30,-1,5:5)
Block(5,30,0,5:5)
Block(5,30,1,5:5)
Block(5,31,0,5:5)
Block(5,32,0,85)
Block(6,0,-7,3)
Block(6,0,-6,3)
Block(6,0,-5,4)
Block(6,0,-4,1:6)
Block(6,0,-3,1:6)
Block(6,0,-2,1:6)
Block(6,0,-1,4)
Block(6,0,3,4)
Block(6,0,4,3)
Block(6,0,5,3)
Block(6,0,6,3)
Block(6,0,7,4)
Block(6,0,8,112)
Block(6,1,-7,2)
Block(6,1,-6,2)
Block(6,1,-5,4)
Block(6,1,-1,134:2)
Block(6,1,3,4)
Block(6,1,4,3)
Block(6,1,5,3)
Block(6,1,6,3)
Block(6,1,7,4)
Block(6,2,-7,31:1)
Block(6,2,-5,4)
Block(6,2,0,134:2)
Block(6,2,3,4)
Block(6,2,4,3)
Block(6,2,5,3)
Block(6,2,6,3)
Block(6,2,7,4)
Block(6,3,-5,101)
Block(6,3,1,126:1)
Block(6,3,2,126:1)
Block(6,3,3,1:6)
Block(6,3,4,2)
Block(6,3,5,2)
Block(6,3,6,2)
Block(6,3,7,4)
Block(6,3,8,53:4)
Block(6,4,-5,4)
Block(6,4,-4,126:9)
Block(6,4,-3,126:9)
Block(6,4,-2,126:9)
Block(6,4,3,1:6)
Block(6,4,4,175:3)
Block(6,4,5,31:2)
Block(6,4,6,44)
Block(6,4,7,43)
Block(6,4,8,43)
Block(6,5,-5,98)
Block(6,5,-4,171:7)
Block(6,5,-3,171:7)
Block(6,5,-2,171:7)
Block(6,5,-1,134:2)
Block(6,5,3,1:6)
Block(6,5,4,175:10)
Block(6,6,-5,102)
Block(6,6,0,134:2)
Block(6,6,1,126:9)
Block(6,6,2,126:9)
Block(6,6,3,1:6)
Block(6,7,-5,102)
Block(6,7,3,1:6)
Block(6,8,-5,98)
Block(6,8,3,1:6)
Block(6,9,-5,179:2)
Block(6,9,-4,98)
Block(6,9,-3,98)
Block(6,9,-2,98)
Block(6,9,-1,109:5)
Block(6,9,3,1:6)
Block(6,10,-6,5:2)
Block(6,10,-5,171:15)
Block(6,10,-4,171:15)
Block(6,10,-3,171:15)
Block(6,10,-2,171:15)
Block(6,10,-1,134:2)
Block(6,10,0,109:5)
Block(6,10,2,50:4)
Block(6,10,3,1:6)
Block(6,11,-6,5:2)
Block(6,11,0,134:2)
Block(6,11,1,126:9)
Block(6,11,2,126:9)
Block(6,11,3,1:6)
Block(6,12,-7,126:13)
Block(6,12,-6,5:2)
Block(6,12,3,1:6)
Block(6,13,-6,164:2)
Block(6,13,-5,53:7)
Block(6,13,3,1:6)
Block(6,14,-5,164:2)
Block(6,14,-4,5)
Block(6,14,-3,5)
Block(6,14,-2,53:7)
Block(6,14,3,1:6)
Block(6,15,-4,164:2)
Block(6,15,-3,1:6)
Block(6,15,-2,4)
Block(6,15,3,1:6)
Block(6,16,-3,1:6)
Block(6,16,-2,4)
Block(6,16,-1,134)
Block(6,16,0,109:5)
Block(6,16,2,50:4)
Block(6,16,3,1:6)
Block(6,17,-3,1:6)
Block(6,17,-2,97:1)
Block(6,17,0,5:1)
Block(6,17,1,126:9)
Block(6,17,2,126:9)
Block(6,17,3,1:6)
Block(6,18,-3,1:6)
Block(6,18,-2,97:1)
Block(6,18,3,1:6)
Block(6,19,-3,1:6)
Block(6,19,-2,4)
Block(6,19,3,1:6)
Block(6,20,-3,1:6)
Block(6,20,-2,125:1)
Block(6,20,-1,126:9)
Block(6,20,3,1:6)
Block(6,21,-3,1:6)
Block(6,21,0,126:1)
Block(6,21,1,126:9)
Block(6,21,2,126:9)
Block(6,21,3,1:6)
Block(6,22,-3,1:6)
Block(6,22,3,1:6)
Block(6,23,-3,1:6)
Block(6,23,-2,50:2)
Block(6,23,3,1:6)
Block(6,24,-4,109:6)
Block(6,24,-3,1:6)
Block(6,24,-2,109:7)
Block(6,24,2,109:6)
Block(6,24,3,1:6)
Block(6,24,4,109:7)
Block(6,25,-4,17:1)
Block(6,25,-3,126:1)
Block(6,25,-2,126:1)
Block(6,25,-1,126:1)
Block(6,25,0,126:1)
Block(6,25,1,126:1)
Block(6,25,2,126:1)
Block(6,25,3,126:1)
Block(6,25,4,17:1)
Block(6,26,-4,85)
Block(6,26,4,85)
Block(6,27,-4,85)
Block(6,27,4,85)
Block(6,28,-4,126:5)
Block(6,28,-3,126:13)
Block(6,28,-2,126:13)
Block(6,28,2,126:13)
Block(6,28,3,126:13)
Block(6,28,4,126:5)
Block(6,29,-2,164:1)
Block(6,29,-1,164:2)
Block(6,29,0,126:13)
Block(6,29,1,164:1)
Block(6,29,2,164:3)
Block(6,30,0,5:5)
Block(7,0,-7,3)
Block(7,0,-6,3)
Block(7,0,-5,4)
Block(7,0,-4,1:6)
Block(7,0,-3,1:6)
Block(7,0,-2,1:6)
Block(7,0,-1,4)
Block(7,0,2,4)
Block(7,0,3,3)
Block(7,0,4,3)
Block(7,0,5,3)
Block(7,0,6,3)
Block(7,0,7,4)
Block(7,0,8,1:6)
Block(7,1,-7,2)
Block(7,1,-6,2)
Block(7,1,-5,4)
Block(7,1,-1,134:2)
Block(7,1,2,4)
Block(7,1,3,3)
Block(7,1,4,3)
Block(7,1,5,3)
Block(7,1,6,3)
Block(7,1,7,4)
Block(7,1,8,4)
Block(7,2,-6,175:2)
Block(7,2,-5,4)
Block(7,2,0,134:2)
Block(7,2,2,4)
Block(7,2,3,3)
Block(7,2,4,3)
Block(7,2,5,2)
Block(7,2,6,3)
Block(7,2,7,4)
Block(7,2,8,4)
Block(7,3,-6,175:10)
Block(7,3,-5,4)
Block(7,3,-3,50:2)
Block(7,3,1,126:1)
Block(7,3,2,4)
Block(7,3,3,2)
Block(7,3,4,2)
Block(7,3,5,43)
Block(7,3,6,43)
Block(7,3,7,43)
Block(7,3,8,2)
Block(7,4,-5,4)
Block(7,4,-4,126:9)
Block(7,4,-3,126:9)
Block(7,4,-2,126:9)
Block(7,4,2,4)
Block(7,4,3,175:3)
Block(7,4,4,175:4)
Block(7,4,6,44)
Block(7,4,7,44)
Block(7,4,8,44)
Block(7,5,-5,98)
Block(7,5,-4,171:7)
Block(7,5,-3,171:7)
Block(7,5,-2,171:7)
Block(7,5,-1,134:2)
Block(7,5,2,4)
Block(7,5,3,175:10)
Block(7,5,4,175:10)
Block(7,6,-5,98)
Block(7,6,0,134:2)
Block(7,6,1,126:9)
Block(7,6,2,4)
Block(7,7,-5,98)
Block(7,7,2,4)
Block(7,8,-5,98)
Block(7,8,-4,109:4)
Block(7,8,-3,109:4)
Block(7,8,-2,109:4)
Block(7,8,-1,50:2)
Block(7,8,2,4)
Block(7,9,-5,179:2)
Block(7,9,-4,98)
Block(7,9,-3,98)
Block(7,9,-2,98)
Block(7,9,-1,109:4)
Block(7,9,1,50:2)
Block(7,9,2,4)
Block(7,10,-6,5:2)
Block(7,10,-5,171:15)
Block(7,10,-4,171:15)
Block(7,10,-3,171:15)
Block(7,10,-2,171:15)
Block(7,10,-1,134:2)
Block(7,10,0,109:4)
Block(7,10,2,4)
Block(7,11,-6,5:2)
Block(7,11,0,134:2)
Block(7,11,1,126:9)
Block(7,11,2,4)
Block(7,12,-7,126:13)
Block(7,12,-6,5:2)
Block(7,12,-4,50:2)
Block(7,12,2,4)
Block(7,13,-6,164:2)
Block(7,13,-5,53:7)
Block(7,13,2,4)
Block(7,14,-5,164:2)
Block(7,14,-4,5)
Block(7,14,-3,5)
Block(7,14,-2,53:7)
Block(7,14,-1,50:2)
Block(7,14,2,4)
Block(7,15,-4,164:2)
Block(7,15,-3,126:9)
Block(7,15,-2,4)
Block(7,15,1,50:2)
Block(7,15,2,4)
Block(7,16,-3,5:5)
Block(7,16,-2,4)
Block(7,16,2,4)
Block(7,17,-2,4)
Block(7,17,-1,126:1)
Block(7,17,0,126:9)
Block(7,17,1,126:9)
Block(7,17,2,4)
Block(7,18,-2,97:1)
Block(7,18,2,97:1)
Block(7,19,-2,4)
Block(7,19,2,4)
Block(7,20,-2,4)
Block(7,20,-1,126:9)
Block(7,20,1,50:4)
Block(7,20,2,4)
Block(7,21,-2,4)
Block(7,21,0,126:1)
Block(7,21,1,126:9)
Block(7,21,2,4)
Block(7,22,-2,4)
Block(7,22,2,4)
Block(7,23,-2,4)
Block(7,23,1,50:4)
Block(7,23,2,4)
Block(7,24,-3,109:6)
Block(7,24,-2,4)
Block(7,24,-1,109:4)
Block(7,24,1,109:4)
Block(7,24,2,4)
Block(7,24,3,109:5)
Block(7,25,-3,17:1)
Block(7,25,-2,126:1)
Block(7,25,-1,126:1)
Block(7,25,0,126:1)
Block(7,25,1,126:1)
Block(7,25,2,126:1)
Block(7,25,3,17:1)
Block(7,26,-3,85)
Block(7,26,3,85)
Block(7,27,-4,85)
Block(7,27,-3,85)
Block(7,27,3,85)
Block(7,27,4,85)
Block(7,28,-4,126:5)
Block(7,28,-3,126:5)
Block(7,28,-2,126:13)
Block(7,28,-1,126:13)
Block(7,28,0,89)
Block(7,28,1,126:13)
Block(7,28,2,126:13)
Block(7,28,3,126:5)
Block(7,28,4,126:5)
Block(7,29,-1,164:1)
Block(7,29,0,164:1)
Block(7,29,1,164:3)

Branch(16,0,0,true,villaC1R0,NORTH,100,0)
Branch(0,0,16,true,villaC0R1,NORTH,100,0)
