

BranchFrequencyGroup: CanOverride:0

CanOverride: true

SmoothRadius: -1

OverrideChildSettings: false

ReplaceAbove:
ReplaceBelow:

MustBeInside: VillageGeneratorStructurePlaceHolder, VillageGeneratorStructuresDelay, VillageGeneratorStructuresDelay2, VillageGeneratorStructuresDelay3, VillageGeneratorStructuresDelay4, VillageGeneratorStructuresDelay5, VillageGeneratorStructuresDelay6, VillageGeneratorStructuresDelay7, VillageGeneratorStructuresDelay8, VillageGeneratorStructuresDelay9, VillageGeneratorStructuresDelay10

Block(-8,0,-7,3)
Block(-8,0,-6,3)
Block(-8,0,-5,3)
Block(-8,0,-4,3)
Block(-8,0,-3,3)
Block(-8,0,-2,3)
Block(-8,0,-1,3)
Block(-8,0,0,3)
Block(-8,0,1,3)
Block(-8,1,-7,2)
Block(-8,1,-6,2)
Block(-8,1,-5,2)
Block(-8,1,-4,2)
Block(-8,1,-3,2)
Block(-8,1,-2,2)
Block(-8,1,-1,2)
Block(-8,1,0,2)
Block(-8,1,1,2)
Block(-8,2,-7,31:1)
Block(-8,2,-5,31:1)
Block(-8,16,-7,164:6)
Block(-8,16,-6,164:3)
Block(-8,17,-7,164:3)
Block(-7,0,-7,4)
Block(-7,0,-6,3)
Block(-7,0,-5,3)
Block(-7,0,-4,3)
Block(-7,0,-3,3)
Block(-7,0,-2,3)
Block(-7,0,-1,3)
Block(-7,0,0,3)
Block(-7,0,1,3)
Block(-7,1,-7,4)
Block(-7,1,-6,3)
Block(-7,1,-5,3)
Block(-7,1,-4,3)
Block(-7,1,-3,2)
Block(-7,1,-2,2)
Block(-7,1,-1,2)
Block(-7,1,0,2)
Block(-7,1,1,2)
Block(-7,2,-7,4)
Block(-7,2,-6,2)
Block(-7,2,-5,2)
Block(-7,2,-4,2)
Block(-7,3,-7,4)
Block(-7,3,-6,175:2)
Block(-7,4,-7,4)
Block(-7,4,-6,175:10)
Block(-7,5,-7,97:2)
Block(-7,6,-7,97:2)
Block(-7,7,-7,97:2)
Block(-7,8,-7,97:2)
Block(-7,9,-7,97:2)
Block(-7,10,-7,97:2)
Block(-7,11,-7,97:2)
Block(-7,12,-7,97:2)
Block(-7,13,-7,98)
Block(-7,14,-7,98)
Block(-7,15,-7,98)
Block(-7,15,-6,164:4)
Block(-7,16,-7,98)
Block(-7,16,-6,164:3)
Block(-7,17,-7,164:3)
Block(-6,0,-7,112)
Block(-6,0,-6,4)
Block(-6,0,-5,3)
Block(-6,0,-4,3)
Block(-6,0,-3,3)
Block(-6,0,-2,3)
Block(-6,0,-1,3)
Block(-6,0,0,3)
Block(-6,0,1,3)
Block(-6,1,-7,54:5,4-Chest.nbt)
Block(-6,1,-6,4)
Block(-6,1,-5,3)
Block(-6,1,-4,3)
Block(-6,1,-3,3)
Block(-6,1,-2,3)
Block(-6,1,-1,3)
Block(-6,1,0,2)
Block(-6,1,1,2)
Block(-6,2,-7,126:13)
Block(-6,2,-6,4)
Block(-6,2,-5,3)
Block(-6,2,-4,2)
Block(-6,2,-3,2)
Block(-6,2,-2,2)
Block(-6,2,-1,2)
Block(-6,2,0,31:1)
Block(-6,2,1,31:1)
Block(-6,3,-6,4)
Block(-6,3,-5,2)
Block(-6,3,-4,31:1)
Block(-6,3,-3,31:1)
Block(-6,4,-7,126:9)
Block(-6,4,-6,4)
Block(-6,4,-5,31:1)
Block(-6,5,-7,97:2)
Block(-6,5,-6,97:2)
Block(-6,6,-7,97:2)
Block(-6,6,-6,97:2)
Block(-6,7,-7,97:2)
Block(-6,7,-6,97:2)
Block(-6,8,-7,126:13)
Block(-6,8,-6,97:2)
Block(-6,9,-7,163:2)
Block(-6,9,-6,97:2)
Block(-6,10,-6,97:2)
Block(-6,11,-7,50:1)
Block(-6,11,-6,97:2)
Block(-6,12,-7,109:6)
Block(-6,12,-6,97:2)
Block(-6,13,-7,98)
Block(-6,13,-6,98)
Block(-6,13,-5,85)
Block(-6,13,-4,85)
Block(-6,13,-3,85)
Block(-6,13,-2,85)
Block(-6,13,-1,85)
Block(-6,13,0,85)
Block(-6,14,-7,5)
Block(-6,14,-6,98)
Block(-6,14,-5,85)
Block(-6,14,-1,85)
Block(-6,15,-7,54:2,8-Chest.nbt)
Block(-6,15,-6,98)
Block(-6,15,-5,164:7)
Block(-6,15,-1,164:6)
Block(-6,15,0,164:3)
Block(-6,16,-6,164:3)
Block(-6,16,-5,164)
Block(-6,16,-4,164)
Block(-6,16,-3,164)
Block(-6,16,-2,164)
Block(-6,16,-1,164:3)
Block(-6,17,-7,164:3)
Block(-5,0,-7,112)
Block(-5,0,-6,112)
Block(-5,0,-5,4)
Block(-5,0,-4,3)
Block(-5,0,-3,3)
Block(-5,0,-2,3)
Block(-5,0,-1,4)
Block(-5,0,0,3)
Block(-5,0,1,3)
Block(-5,1,-6,54:2,10-Chest.nbt)
Block(-5,1,-5,4)
Block(-5,1,-4,3)
Block(-5,1,-3,3)
Block(-5,1,-2,3)
Block(-5,1,-1,4)
Block(-5,1,0,2)
Block(-5,1,1,2)
Block(-5,2,-6,126:13)
Block(-5,2,-5,4)
Block(-5,2,-4,3)
Block(-5,2,-3,2)
Block(-5,2,-2,2)
Block(-5,2,-1,4)
Block(-5,2,0,175:2)
Block(-5,2,1,175:2)
Block(-5,3,-6,54:2,12-Chest.nbt)
Block(-5,3,-5,4)
Block(-5,3,-4,2)
Block(-5,3,-2,175:2)
Block(-5,3,-1,4)
Block(-5,3,0,175:10)
Block(-5,3,1,175:10)
Block(-5,4,-7,126:9)
Block(-5,4,-6,126:9)
Block(-5,4,-5,4)
Block(-5,4,-4,31:1)
Block(-5,4,-2,175:10)
Block(-5,4,-1,4)
Block(-5,5,-7,97:2)
Block(-5,5,-6,97:2)
Block(-5,5,-5,67)
Block(-5,5,-1,67)
Block(-5,6,-7,97:2)
Block(-5,6,-6,97:2)
Block(-5,7,-7,97:2)
Block(-5,7,-6,97:2)
Block(-5,8,-7,126:13)
Block(-5,8,-6,97:2)
Block(-5,9,-7,163:2)
Block(-5,9,-6,97:2)
Block(-5,9,-5,109:4)
Block(-5,9,-1,109:4)
Block(-5,9,0,85)
Block(-5,10,-6,97:2)
Block(-5,10,-5,17)
Block(-5,10,-4,5:2)
Block(-5,10,-3,135)
Block(-5,10,-2,5:2)
Block(-5,10,-1,17)
Block(-5,10,0,85)
Block(-5,11,-6,97:2)
Block(-5,11,-5,17)
Block(-5,11,-4,5:2)
Block(-5,11,-3,102)
Block(-5,11,-2,5:2)
Block(-5,11,-1,17)
Block(-5,11,0,85)
Block(-5,12,-7,109:6)
Block(-5,12,-6,97:2)
Block(-5,12,-5,17)
Block(-5,12,-4,5:2)
Block(-5,12,-3,135:4)
Block(-5,12,-2,5:2)
Block(-5,12,-1,17)
Block(-5,12,0,85)
Block(-5,13,-7,5)
Block(-5,13,-6,98)
Block(-5,13,-5,17)
Block(-5,13,-4,5)
Block(-5,13,-3,5)
Block(-5,13,-2,5)
Block(-5,13,-1,17)
Block(-5,13,0,85)
Block(-5,14,-7,5)
Block(-5,14,-6,98)
Block(-5,14,-5,17)
Block(-5,14,-4,5)
Block(-5,14,-3,5)
Block(-5,14,-2,5)
Block(-5,14,-1,17)
Block(-5,14,0,85)
Block(-5,14,1,126:13)
Block(-5,15,-7,54:2,14-Chest.nbt)
Block(-5,15,-6,98)
Block(-5,15,-5,17)
Block(-5,15,-4,5)
Block(-5,15,-3,5)
Block(-5,15,-2,5)
Block(-5,15,-1,17)
Block(-5,15,0,164:3)
Block(-5,16,-6,98)
Block(-5,16,-5,17)
Block(-5,16,-4,5)
Block(-5,16,-3,5)
Block(-5,16,-2,5)
Block(-5,16,-1,164:3)
Block(-5,17,-7,164)
Block(-5,17,-6,164)
Block(-5,17,-5,164)
Block(-5,17,-4,164)
Block(-5,17,-3,164)
Block(-5,17,-2,164)
Block(-4,0,-7,112)
Block(-4,0,-6,112)
Block(-4,0,-5,4)
Block(-4,0,-4,4)
Block(-4,0,-3,4)
Block(-4,0,-2,4)
Block(-4,0,-1,4)
Block(-4,0,0,4)
Block(-4,0,1,3)
Block(-4,1,-6,54:2,15-Chest.nbt)
Block(-4,1,-5,4)
Block(-4,1,-4,4)
Block(-4,1,-3,4)
Block(-4,1,-2,4)
Block(-4,1,-1,4)
Block(-4,1,0,4)
Block(-4,1,1,2)
Block(-4,2,-6,126:13)
Block(-4,2,-5,4)
Block(-4,2,-4,4)
Block(-4,2,-3,4)
Block(-4,2,-2,4)
Block(-4,2,-1,4)
Block(-4,2,0,4)
Block(-4,2,1,175:2)
Block(-4,3,-6,54:2,16-Chest.nbt)
Block(-4,3,-5,4)
Block(-4,3,-4,4)
Block(-4,3,-3,101)
Block(-4,3,-2,4)
Block(-4,3,-1,4)
Block(-4,3,0,4)
Block(-4,3,1,175:10)
Block(-4,4,-7,5:1)
Block(-4,4,-6,5:1)
Block(-4,4,-5,4)
Block(-4,4,-4,4)
Block(-4,4,-3,4)
Block(-4,4,-2,4)
Block(-4,4,-1,4)
Block(-4,4,0,4)
Block(-4,5,-7,97:2)
Block(-4,5,-6,97:2)
Block(-4,5,-5,1:6)
Block(-4,5,-4,98)
Block(-4,5,-3,98)
Block(-4,5,-2,98)
Block(-4,5,-1,1:6)
Block(-4,5,0,67:3)
Block(-4,6,-7,97:2)
Block(-4,6,-6,97:2)
Block(-4,6,-5,1:6)
Block(-4,6,-4,98)
Block(-4,6,-3,102)
Block(-4,6,-2,98)
Block(-4,6,-1,1:6)
Block(-4,7,-7,97:2)
Block(-4,7,-6,97:2)
Block(-4,7,-5,1:6)
Block(-4,7,-4,98)
Block(-4,7,-3,102)
Block(-4,7,-2,98)
Block(-4,7,-1,1:6)
Block(-4,8,-7,98)
Block(-4,8,-6,98)
Block(-4,8,-5,1:6)
Block(-4,8,-4,98)
Block(-4,8,-3,98)
Block(-4,8,-2,98)
Block(-4,8,-1,1:6)
Block(-4,9,-7,179:2)
Block(-4,9,-6,179:2)
Block(-4,9,-5,1:6)
Block(-4,9,-4,179:2)
Block(-4,9,-3,179:2)
Block(-4,9,-2,179:2)
Block(-4,9,-1,179:2)
Block(-4,9,0,109:7)
Block(-4,10,-7,1:6)
Block(-4,10,-6,98)
Block(-4,10,-5,1:6)
Block(-4,10,-4,171:13)
Block(-4,10,-3,163:1)
Block(-4,10,-2,163:1)
Block(-4,10,-1,171:13)
Block(-4,10,0,17)
Block(-4,11,-7,1:6)
Block(-4,11,-6,98)
Block(-4,11,-5,1:6)
Block(-4,11,0,17)
Block(-4,12,-7,1:6)
Block(-4,12,-6,98)
Block(-4,12,-5,1:6)
Block(-4,12,-4,50:3)
Block(-4,12,0,17)
Block(-4,13,-7,1:4)
Block(-4,13,-6,1:4)
Block(-4,13,-5,98)
Block(-4,13,-4,53:7)
Block(-4,13,-3,53:5)
Block(-4,13,-2,53:5)
Block(-4,13,-1,53:6)
Block(-4,13,0,17)
Block(-4,14,-7,5)
Block(-4,14,-6,5)
Block(-4,14,-5,98)
Block(-4,14,-4,5)
Block(-4,14,-3,5)
Block(-4,14,-2,5)
Block(-4,14,-1,5)
Block(-4,14,0,17)
Block(-4,14,1,126:13)
Block(-4,15,-7,171:7)
Block(-4,15,-6,171:7)
Block(-4,15,-5,98)
Block(-4,15,-4,163:1)
Block(-4,15,-3,163:1)
Block(-4,15,-2,163:1)
Block(-4,15,-1,5)
Block(-4,15,0,164:3)
Block(-4,16,-5,98)
Block(-4,16,-1,164:3)
Block(-4,17,-5,98)
Block(-4,17,-4,50:3)
Block(-4,17,-2,164:3)
Block(-4,18,-7,164)
Block(-4,18,-6,164)
Block(-4,18,-5,164)
Block(-4,18,-4,164)
Block(-4,18,-3,164)
Block(-3,0,-7,112)
Block(-3,0,-6,112)
Block(-3,0,-5,1:6)
Block(-3,0,-4,112)
Block(-3,0,-3,112)
Block(-3,0,-2,112)
Block(-3,0,-1,4)
Block(-3,0,0,3)
Block(-3,0,1,3)
Block(-3,1,-6,4)
Block(-3,1,-5,45)
Block(-3,1,-4,88)
Block(-3,1,-3,88)
Block(-3,1,-2,88)
Block(-3,1,-1,4)
Block(-3,1,0,2)
Block(-3,1,1,2)
Block(-3,2,-6,4)
Block(-3,2,-5,45)
Block(-3,2,-4,115:3)
Block(-3,2,-3,115:3)
Block(-3,2,-2,115)
Block(-3,2,-1,4)
Block(-3,2,0,175:2)
Block(-3,3,-6,67:2)
Block(-3,3,-5,45)
Block(-3,3,-1,4)
Block(-3,3,0,175:10)
Block(-3,4,-7,126:9)
Block(-3,4,-6,126:9)
Block(-3,4,-5,5:1)
Block(-3,4,-4,126:9)
Block(-3,4,-3,126:9)
Block(-3,4,-2,126:9)
Block(-3,4,-1,4)
Block(-3,5,-7,159:15)
Block(-3,5,-6,97:2)
Block(-3,5,-5,97:2)
Block(-3,5,-4,5:4)
Block(-3,5,-3,171:11)
Block(-3,5,-2,5:4)
Block(-3,5,-1,98)
Block(-3,6,-7,159:15)
Block(-3,6,-6,97:2)
Block(-3,6,-5,97:2)
Block(-3,6,-4,140,19-FlowerPot.nbt)
Block(-3,6,-2,140,20-FlowerPot.nbt)
Block(-3,6,-1,98)
Block(-3,7,-7,97:2)
Block(-3,7,-6,97:2)
Block(-3,7,-5,97:2)
Block(-3,7,-1,98)
Block(-3,8,-7,44:7)
Block(-3,8,-6,44:7)
Block(-3,8,-5,43:7)
Block(-3,8,-4,135:7)
Block(-3,8,-3,135:5)
Block(-3,8,-2,135:6)
Block(-3,8,-1,98)
Block(-3,9,-4,134:2)
Block(-3,9,-3,179:2)
Block(-3,9,-2,179:2)
Block(-3,9,-1,179:2)
Block(-3,10,-3,171:13)
Block(-3,10,-2,171:13)
Block(-3,10,-1,171:13)
Block(-3,10,0,5:2)
Block(-3,11,-7,50:1)
Block(-3,11,0,5:2)
Block(-3,12,-5,109:5)
Block(-3,12,0,5:2)
Block(-3,13,-5,1:4)
Block(-3,13,-4,53:7)
Block(-3,13,-1,53:6)
Block(-3,13,0,5)
Block(-3,14,-7,5)
Block(-3,14,-6,5)
Block(-3,14,-5,97:2)
Block(-3,14,-4,5)
Block(-3,14,-3,5)
Block(-3,14,-2,5)
Block(-3,14,-1,5)
Block(-3,14,0,5)
Block(-3,14,1,126:13)
Block(-3,15,-7,171:5)
Block(-3,15,-6,171:7)
Block(-3,15,-2,85)
Block(-3,15,-1,5)
Block(-3,15,0,164:3)
Block(-3,16,-2,171)
Block(-3,16,-1,164:3)
Block(-3,17,-5,109:5)
Block(-3,17,-2,164:3)
Block(-3,18,-5,98)
Block(-3,18,-4,126:13)
Block(-3,18,-3,5:5)
Block(-3,19,-7,126:5)
Block(-3,19,-6,126:5)
Block(-3,19,-5,126:5)
Block(-3,19,-4,126:5)
Block(-2,0,-7,112)
Block(-2,0,-6,112)
Block(-2,0,-5,1:6)
Block(-2,0,-4,112)
Block(-2,0,-3,112)
Block(-2,0,-2,112)
Block(-2,0,-1,4)
Block(-2,0,0,3)
Block(-2,0,1,3)
Block(-2,1,-5,45)
Block(-2,1,-4,114:1)
Block(-2,1,-3,114:1)
Block(-2,1,-2,114:1)
Block(-2,1,-1,4)
Block(-2,1,0,2)
Block(-2,1,1,2)
Block(-2,2,-5,45)
Block(-2,2,-1,4)
Block(-2,3,-5,45)
Block(-2,3,-1,101)
Block(-2,4,-7,126:9)
Block(-2,4,-6,126:9)
Block(-2,4,-5,5:1)
Block(-2,4,-4,126:9)
Block(-2,4,-3,126:9)
Block(-2,4,-2,126:9)
Block(-2,4,-1,4)
Block(-2,5,-7,171:15)
Block(-2,5,-6,193:3)
Block(-2,5,-4,171:11)
Block(-2,5,-3,171:7)
Block(-2,5,-2,171:11)
Block(-2,5,-1,98)
Block(-2,6,-6,193:8)
Block(-2,6,-1,102)
Block(-2,7,-7,97:2)
Block(-2,7,-6,97:2)
Block(-2,7,-5,97:2)
Block(-2,7,-1,102)
Block(-2,8,-7,44:7)
Block(-2,8,-6,44:7)
Block(-2,8,-5,43:7)
Block(-2,8,-4,135:7)
Block(-2,8,-3,126:10)
Block(-2,8,-2,135:6)
Block(-2,8,-1,98)
Block(-2,9,-4,134:2)
Block(-2,9,-3,179:2)
Block(-2,9,-2,179:2)
Block(-2,9,-1,179:2)
Block(-2,10,-3,171:13)
Block(-2,10,-2,171:13)
Block(-2,10,-1,163:2)
Block(-2,10,0,135:3)
Block(-2,11,0,102)
Block(-2,12,-5,109:4)
Block(-2,12,0,135:7)
Block(-2,13,-5,1:4)
Block(-2,13,-4,53:7)
Block(-2,13,-1,53:6)
Block(-2,13,0,5)
Block(-2,14,-7,5)
Block(-2,14,-6,5)
Block(-2,14,-5,97:2)
Block(-2,14,-4,5)
Block(-2,14,-3,5)
Block(-2,14,-2,5)
Block(-2,14,-1,5)
Block(-2,14,0,5)
Block(-2,14,1,126:13)
Block(-2,15,-7,171:5)
Block(-2,15,-6,171:7)
Block(-2,15,-2,163)
Block(-2,15,-1,5)
Block(-2,15,0,164)
Block(-2,16,-1,164:3)
Block(-2,17,-5,109:4)
Block(-2,17,-2,164:3)
Block(-2,18,-5,98)
Block(-2,18,-4,126:13)
Block(-2,18,-3,5:5)
Block(-2,19,-7,126:13)
Block(-2,19,-6,126:13)
Block(-2,19,-5,126:13)
Block(-2,19,-4,126:5)
Block(-1,0,-7,112)
Block(-1,0,-6,112)
Block(-1,0,-5,1:6)
Block(-1,0,-4,112)
Block(-1,0,-3,112)
Block(-1,0,-2,112)
Block(-1,0,-1,4)
Block(-1,0,0,3)
Block(-1,0,1,3)
Block(-1,1,-5,45)
Block(-1,1,-1,4)
Block(-1,1,0,2)
Block(-1,1,1,2)
Block(-1,2,-5,45)
Block(-1,2,-1,4)
Block(-1,2,0,175:2)
Block(-1,3,-7,50:2)
Block(-1,3,-5,45)
Block(-1,3,-4,50:2)
Block(-1,3,-2,50:2)
Block(-1,3,-1,4)
Block(-1,3,0,175:10)
Block(-1,4,-7,126:9)
Block(-1,4,-6,126:9)
Block(-1,4,-5,5:1)
Block(-1,4,-4,126:9)
Block(-1,4,-3,126:9)
Block(-1,4,-2,126:9)
Block(-1,4,-1,4)
Block(-1,5,-7,159:15)
Block(-1,5,-6,98)
Block(-1,5,-5,98)
Block(-1,5,-4,171:11)
Block(-1,5,-3,171:7)
Block(-1,5,-2,171:11)
Block(-1,5,-1,98)
Block(-1,6,-7,159:15)
Block(-1,6,-6,98)
Block(-1,6,-5,98)
Block(-1,6,-1,98)
Block(-1,7,-7,156:1)
Block(-1,7,-6,156:1)
Block(-1,7,-5,98)
Block(-1,7,-4,50:3)
Block(-1,7,-2,50:4)
Block(-1,7,-1,98)
Block(-1,8,-5,1:6)
Block(-1,8,-4,135:7)
Block(-1,8,-3,126:10)
Block(-1,8,-2,135:6)
Block(-1,8,-1,98)
Block(-1,9,-5,1:6)
Block(-1,9,-4,179:2)
Block(-1,9,-3,179:2)
Block(-1,9,-2,179:2)
Block(-1,9,-1,179:2)
Block(-1,10,-5,1:6)
Block(-1,10,-4,171:13)
Block(-1,10,-3,171:13)
Block(-1,10,-2,171:13)
Block(-1,10,-1,163:2)
Block(-1,10,0,5:2)
Block(-1,11,-6,109:6)
Block(-1,11,-5,1:6)
Block(-1,11,0,5:2)
Block(-1,12,-7,98)
Block(-1,12,-6,98)
Block(-1,12,-5,1:6)
Block(-1,12,-4,50:3)
Block(-1,12,0,5:2)
Block(-1,13,-7,1:4)
Block(-1,13,-6,1:4)
Block(-1,13,-5,98)
Block(-1,13,-4,5)
Block(-1,13,-3,5)
Block(-1,13,-2,5)
Block(-1,13,-1,5)
Block(-1,13,0,5)
Block(-1,14,-7,5)
Block(-1,14,-6,5)
Block(-1,14,-5,98)
Block(-1,14,-4,5)
Block(-1,14,-3,5)
Block(-1,14,-2,5)
Block(-1,14,-1,5)
Block(-1,14,0,5)
Block(-1,14,1,126:13)
Block(-1,15,-7,171:7)
Block(-1,15,-6,171:7)
Block(-1,15,-5,98)
Block(-1,15,-1,5)
Block(-1,15,0,5:5)
Block(-1,16,-5,98)
Block(-1,16,-1,164:3)
Block(-1,16,0,164)
Block(-1,17,-7,50:2)
Block(-1,17,-5,98)
Block(-1,17,-4,50:3)
Block(-1,17,-2,164:3)
Block(-1,18,-5,98)
Block(-1,18,-4,126:13)
Block(-1,18,-3,5:5)
Block(-1,19,-5,126:13)
Block(-1,19,-4,126:5)
Block(-1,20,-7,126:5)
Block(-1,20,-6,126:5)
Block(0,0,-7,112)
Block(0,0,-6,1:6)
Block(0,0,-5,1:6)
Block(0,0,-4,1:6)
Block(0,0,-3,112)
Block(0,0,-2,1:6)
Block(0,0,-1,4)
Block(0,0,0,4)
Block(0,0,1,3)
Block(0,1,-7,196:2)
Block(0,1,-6,45)
Block(0,1,-5,1:6)
Block(0,1,-4,45)
Block(0,1,-3,196:2)
Block(0,1,-2,45)
Block(0,1,-1,4)
Block(0,1,0,4)
Block(0,1,1,2)
Block(0,2,-7,196:8)
Block(0,2,-6,45)
Block(0,2,-5,1:6)
Block(0,2,-4,45)
Block(0,2,-3,196:8)
Block(0,2,-2,45)
Block(0,2,-1,4)
Block(0,2,0,4)
Block(0,3,-7,45)
Block(0,3,-6,45)
Block(0,3,-5,1:6)
Block(0,3,-4,45)
Block(0,3,-3,45)
Block(0,3,-2,45)
Block(0,3,-1,4)
Block(0,3,0,4)
Block(0,4,-7,5:1)
Block(0,4,-6,5:1)
Block(0,4,-5,5:1)
Block(0,4,-4,5:1)
Block(0,4,-3,5:1)
Block(0,4,-2,5:1)
Block(0,4,-1,4)
Block(0,4,0,4)
Block(0,5,-7,1:4)
Block(0,5,-6,1:4)
Block(0,5,-5,98)
Block(0,5,-4,171:11)
Block(0,5,-3,171:7)
Block(0,5,-2,171:11)
Block(0,5,-1,1:6)
Block(0,5,0,67:3)
Block(0,6,-7,156:1)
Block(0,6,-6,156:1)
Block(0,6,-5,98)
Block(0,6,-1,1:6)
Block(0,7,-5,98)
Block(0,7,-4,177:3,30-Banner.nbt)
Block(0,7,-2,177:2,31-Banner.nbt)
Block(0,7,-1,1:6)
Block(0,8,-5,98)
Block(0,8,-4,135:7)
Block(0,8,-3,126:10)
Block(0,8,-2,135:6)
Block(0,8,-1,1:6)
Block(0,9,-6,177:2,35-Banner.nbt)
Block(0,9,-5,179:2)
Block(0,9,-4,179:2)
Block(0,9,-3,179:2)
Block(0,9,-2,179:2)
Block(0,9,-1,179:2)
Block(0,9,0,109:7)
Block(0,10,-6,50:4)
Block(0,10,-5,98)
Block(0,10,-4,171:13)
Block(0,10,-3,171:13)
Block(0,10,-2,171:13)
Block(0,10,-1,171:13)
Block(0,10,0,17)
Block(0,11,-5,98)
Block(0,11,0,17)
Block(0,12,-7,109:5)
Block(0,12,-5,98)
Block(0,12,0,17)
Block(0,13,-7,98)
Block(0,13,-6,155)
Block(0,13,-5,98)
Block(0,13,-4,53:7)
Block(0,13,-1,53:6)
Block(0,13,0,17)
Block(0,14,-7,98)
Block(0,14,-6,98)
Block(0,14,-5,98)
Block(0,14,-4,97:2)
Block(0,14,-3,5)
Block(0,14,-2,5)
Block(0,14,-1,5)
Block(0,14,0,17)
Block(0,14,1,126:13)
Block(0,15,-7,98)
Block(0,15,-6,98)
Block(0,15,-5,98)
Block(0,15,-4,61:3,36-Furnace.nbt)
Block(0,15,-1,163:1)
Block(0,15,0,5)
Block(0,16,-7,98)
Block(0,16,-6,98)
Block(0,16,-5,98)
Block(0,16,0,5)
Block(0,17,-7,98)
Block(0,17,-6,98)
Block(0,17,-5,98)
Block(0,17,-4,1:6)
Block(0,17,-2,164:3)
Block(0,17,-1,164)
Block(0,17,0,164)
Block(0,18,-7,98)
Block(0,18,-6,98)
Block(0,18,-5,98)
Block(0,18,-4,1:6)
Block(0,18,-3,5:5)
Block(0,19,-7,98)
Block(0,19,-6,98)
Block(0,19,-5,5:5)
Block(0,19,-4,126:5)
Block(0,20,-7,5:5)
Block(0,20,-6,126:5)
Block(1,0,-7,112)
Block(1,0,-6,112)
Block(1,0,-5,112)
Block(1,0,-4,112)
Block(1,0,-3,112)
Block(1,0,-2,1:6)
Block(1,0,-1,4)
Block(1,0,0,3)
Block(1,0,1,3)
Block(1,1,-2,67:2)
Block(1,1,-1,4)
Block(1,1,0,2)
Block(1,1,1,13)
Block(1,2,-1,4)
Block(1,2,0,175:2)
Block(1,3,-7,50:1)
Block(1,3,-5,109:5)
Block(1,3,-3,50:1)
Block(1,3,-1,4)
Block(1,3,0,175:10)
Block(1,4,-7,126:9)
Block(1,4,-6,126:9)
Block(1,4,-5,5:1)
Block(1,4,-4,126:9)
Block(1,4,-3,126:9)
Block(1,4,-2,126:9)
Block(1,4,-1,4)
Block(1,5,-7,1:4)
Block(1,5,-6,1:4)
Block(1,5,-5,134:3)
Block(1,5,-4,171:11)
Block(1,5,-3,171:7)
Block(1,5,-2,171:11)
Block(1,5,-1,98)
Block(1,6,-1,98)
Block(1,7,-1,98)
Block(1,8,-5,109:5)
Block(1,8,-4,126:10)
Block(1,8,-3,126:10)
Block(1,8,-2,135:6)
Block(1,8,-1,98)
Block(1,9,-5,179:2)
Block(1,9,-4,179:2)
Block(1,9,-3,179:2)
Block(1,9,-2,179:2)
Block(1,9,-1,179:2)
Block(1,10,-5,109:2)
Block(1,10,-4,163:3)
Block(1,10,-3,171:13)
Block(1,10,-2,171:13)
Block(1,10,-1,171:13)
Block(1,10,0,5:2)
Block(1,11,0,5:2)
Block(1,12,-5,109:5)
Block(1,12,0,5:2)
Block(1,13,-7,98)
Block(1,13,-6,155)
Block(1,13,-5,98)
Block(1,13,-4,53:7)
Block(1,13,-1,53:6)
Block(1,13,0,5)
Block(1,14,-7,5)
Block(1,14,-6,5)
Block(1,14,-5,98)
Block(1,14,-4,97:2)
Block(1,14,-3,5)
Block(1,14,-2,5)
Block(1,14,-1,5)
Block(1,14,0,5)
Block(1,14,1,126:13)
Block(1,15,-7,85)
Block(1,15,-6,163:2)
Block(1,15,-5,98)
Block(1,15,-4,58)
Block(1,15,-1,85)
Block(1,15,0,5)
Block(1,16,-7,171:14)
Block(1,16,-5,98)
Block(1,16,-1,171)
Block(1,16,0,102)
Block(1,17,-7,50:1)
Block(1,17,-5,98)
Block(1,17,0,5)
Block(1,18,-5,98)
Block(1,18,-4,126:13)
Block(1,18,-3,5:5)
Block(1,18,-2,5:5)
Block(1,18,-1,5:5)
Block(1,18,0,5:5)
Block(1,19,-7,5:5)
Block(1,19,-6,5:5)
Block(1,19,-5,5:5)
Block(1,19,-4,126:5)
Block(1,20,-7,126:5)
Block(1,20,-6,126:5)
Block(2,0,-7,112)
Block(2,0,-6,112)
Block(2,0,-5,112)
Block(2,0,-4,112)
Block(2,0,-3,112)
Block(2,0,-2,1:6)
Block(2,0,-1,4)
Block(2,0,0,3)
Block(2,0,1,3)
Block(2,1,-2,67:2)
Block(2,1,-1,4)
Block(2,1,0,13)
Block(2,1,1,13)
Block(2,2,-1,71:3)
Block(2,3,-1,71:8)
Block(2,4,-7,126:9)
Block(2,4,-6,126:9)
Block(2,4,-5,5:1)
Block(2,4,-4,126:9)
Block(2,4,-3,126:9)
Block(2,4,-2,126:9)
Block(2,4,-1,4)
Block(2,5,-7,1:4)
Block(2,5,-6,1:4)
Block(2,5,-5,134:3)
Block(2,5,-4,171:11)
Block(2,5,-3,171:7)
Block(2,5,-2,171:11)
Block(2,5,-1,98)
Block(2,6,-1,102)
Block(2,7,-1,102)
Block(2,8,-5,109:4)
Block(2,8,-4,126:10)
Block(2,8,-3,126:10)
Block(2,8,-2,135:6)
Block(2,8,-1,98)
Block(2,9,-5,179:2)
Block(2,9,-4,179:2)
Block(2,9,-3,179:2)
Block(2,9,-2,179:2)
Block(2,9,-1,179:2)
Block(2,10,-5,109:2)
Block(2,10,-4,163:3)
Block(2,10,-3,171:13)
Block(2,10,-2,171:13)
Block(2,10,-1,171:13)
Block(2,10,0,135:3)
Block(2,11,0,102)
Block(2,12,-5,109:4)
Block(2,12,0,135:7)
Block(2,13,-7,98)
Block(2,13,-6,155)
Block(2,13,-5,98)
Block(2,13,-4,53:7)
Block(2,13,-1,53:6)
Block(2,13,0,5)
Block(2,14,-7,5)
Block(2,14,-6,5)
Block(2,14,-5,98)
Block(2,14,-4,5)
Block(2,14,-3,5)
Block(2,14,-2,5)
Block(2,14,-1,5)
Block(2,14,0,5)
Block(2,14,1,126:13)
Block(2,15,-7,171:12)
Block(2,15,-6,171:12)
Block(2,15,-5,98)
Block(2,15,-4,5:4)
Block(2,15,-1,163)
Block(2,15,0,5)
Block(2,16,-5,98)
Block(2,16,0,5)
Block(2,17,-5,98)
Block(2,17,-4,50:3)
Block(2,17,-2,164:3)
Block(2,17,-1,164:1)
Block(2,17,0,164:1)
Block(2,18,-5,98)
Block(2,18,-4,126:13)
Block(2,18,-3,5:5)
Block(2,19,-7,5:5)
Block(2,19,-6,5:5)
Block(2,19,-5,5:5)
Block(2,19,-4,126:5)
Block(3,0,-7,112)
Block(3,0,-6,112)
Block(3,0,-5,112)
Block(3,0,-4,112)
Block(3,0,-3,112)
Block(3,0,-2,1:6)
Block(3,0,-1,4)
Block(3,0,0,3)
Block(3,0,1,3)
Block(3,1,-2,67:2)
Block(3,1,-1,4)
Block(3,1,0,2)
Block(3,1,1,13)
Block(3,2,-1,4)
Block(3,3,-7,50:2)
Block(3,3,-5,109:4)
Block(3,3,-3,50:2)
Block(3,3,-2,69:4)
Block(3,3,-1,4)
Block(3,4,-7,126:9)
Block(3,4,-6,126:9)
Block(3,4,-5,5:1)
Block(3,4,-4,126:9)
Block(3,4,-3,126:9)
Block(3,4,-2,126:9)
Block(3,4,-1,4)
Block(3,5,-7,1:4)
Block(3,5,-6,1:4)
Block(3,5,-5,98)
Block(3,5,-4,171:11)
Block(3,5,-3,171:11)
Block(3,5,-2,171:11)
Block(3,5,-1,98)
Block(3,6,-5,98)
Block(3,6,-1,98)
Block(3,7,-5,98)
Block(3,7,-3,50:2)
Block(3,7,-1,98)
Block(3,8,-5,98)
Block(3,8,-4,135:7)
Block(3,8,-3,95:4)
Block(3,8,-2,135:6)
Block(3,8,-1,98)
Block(3,9,-7,177:4,40-Banner.nbt)
Block(3,9,-6,177:2,41-Banner.nbt)
Block(3,9,-5,179:2)
Block(3,9,-4,179:2)
Block(3,9,-3,179:2)
Block(3,9,-2,179:2)
Block(3,9,-1,179:2)
Block(3,10,-6,50:4)
Block(3,10,-5,98)
Block(3,10,-4,171:13)
Block(3,10,-3,171:13)
Block(3,10,-2,171:13)
Block(3,10,-1,84)
Block(3,10,0,5:2)
Block(3,11,-5,98)
Block(3,11,0,5:2)
Block(3,12,-7,109:4)
Block(3,12,-5,98)
Block(3,12,-2,50:2)
Block(3,12,0,5:2)
Block(3,13,-7,98)
Block(3,13,-6,155)
Block(3,13,-5,98)
Block(3,13,-4,53:7)
Block(3,13,-3,53:4)
Block(3,13,-2,53:4)
Block(3,13,-1,53:4)
Block(3,13,0,5)
Block(3,14,-7,5)
Block(3,14,-6,5)
Block(3,14,-5,98)
Block(3,14,-4,5)
Block(3,14,-3,126)
Block(3,14,-2,5)
Block(3,14,-1,5)
Block(3,14,0,5)
Block(3,14,1,126:13)
Block(3,15,-7,26)
Block(3,15,-6,26:8)
Block(3,15,-5,98)
Block(3,15,-4,5:4)
Block(3,15,-1,5)
Block(3,15,0,5:5)
Block(3,16,-5,98)
Block(3,16,-1,164:3)
Block(3,16,0,164:1)
Block(3,17,-7,50:2)
Block(3,17,-5,98)
Block(3,17,-2,164:3)
Block(3,18,-7,164:4)
Block(3,18,-6,164:4)
Block(3,18,-5,98)
Block(3,18,-4,126:13)
Block(3,18,-3,5:5)
Block(3,19,-7,126:5)
Block(3,19,-6,126:5)
Block(3,19,-5,126:5)
Block(3,19,-4,126:5)
Block(4,0,-7,112)
Block(4,0,-6,4)
Block(4,0,-5,4)
Block(4,0,-4,1:6)
Block(4,0,-3,112)
Block(4,0,-2,1:6)
Block(4,0,-1,4)
Block(4,0,0,4)
Block(4,0,1,3)
Block(4,1,-7,196)
Block(4,1,-6,45)
Block(4,1,-5,1:6)
Block(4,1,-4,45)
Block(4,1,-3,193)
Block(4,1,-2,45)
Block(4,1,-1,4)
Block(4,1,0,4)
Block(4,1,1,2)
Block(4,2,-7,196:8)
Block(4,2,-6,45)
Block(4,2,-5,1:6)
Block(4,2,-4,45)
Block(4,2,-3,193:8)
Block(4,2,-2,45)
Block(4,2,-1,4)
Block(4,2,0,4)
Block(4,3,-7,45)
Block(4,3,-6,45)
Block(4,3,-5,4)
Block(4,3,-4,45)
Block(4,3,-3,45)
Block(4,3,-2,45)
Block(4,3,-1,4)
Block(4,3,0,4)
Block(4,4,-7,4)
Block(4,4,-6,4)
Block(4,4,-5,4)
Block(4,4,-4,5:1)
Block(4,4,-3,5:1)
Block(4,4,-2,5:1)
Block(4,4,-1,4)
Block(4,4,0,4)
Block(4,5,-7,1:6)
Block(4,5,-6,98)
Block(4,5,-5,1:6)
Block(4,5,-4,98)
Block(4,5,-3,197)
Block(4,5,-2,98)
Block(4,5,-1,1:6)
Block(4,5,0,67:3)
Block(4,6,-7,1:6)
Block(4,6,-6,98)
Block(4,6,-5,1:6)
Block(4,6,-4,98)
Block(4,6,-3,197:8)
Block(4,6,-2,98)
Block(4,6,-1,1:6)
Block(4,7,-7,1:6)
Block(4,7,-6,160:11)
Block(4,7,-5,1:6)
Block(4,7,-4,98)
Block(4,7,-3,98)
Block(4,7,-2,98)
Block(4,7,-1,1:6)
Block(4,8,-7,1:6)
Block(4,8,-6,160:11)
Block(4,8,-5,1:6)
Block(4,8,-4,98)
Block(4,8,-3,89)
Block(4,8,-2,98)
Block(4,8,-1,1:6)
Block(4,9,-7,1:6)
Block(4,9,-6,179:2)
Block(4,9,-5,1:6)
Block(4,9,-4,98)
Block(4,9,-3,98)
Block(4,9,-2,98)
Block(4,9,-1,1:6)
Block(4,9,0,109:7)
Block(4,10,-7,1:6)
Block(4,10,-6,98)
Block(4,10,-5,98)
Block(4,10,-4,98)
Block(4,10,-3,197)
Block(4,10,-2,98)
Block(4,10,-1,98)
Block(4,10,0,17)
Block(4,11,-7,1:6)
Block(4,11,-6,98)
Block(4,11,-5,98)
Block(4,11,-4,98)
Block(4,11,-3,197:8)
Block(4,11,-2,98)
Block(4,11,-1,98)
Block(4,11,0,17)
Block(4,12,-7,1:6)
Block(4,12,-6,98)
Block(4,12,-5,98)
Block(4,12,-4,98)
Block(4,12,-3,98)
Block(4,12,-2,98)
Block(4,12,-1,98)
Block(4,12,0,17)
Block(4,13,-7,1:6)
Block(4,13,-6,1:6)
Block(4,13,-5,98)
Block(4,13,-4,98)
Block(4,13,-3,98)
Block(4,13,-2,98)
Block(4,13,-1,98)
Block(4,13,0,17)
Block(4,14,-7,1:6)
Block(4,14,-6,98)
Block(4,14,-5,98)
Block(4,14,-4,98)
Block(4,14,-3,126)
Block(4,14,-2,97:2)
Block(4,14,-1,5)
Block(4,14,0,17)
Block(4,14,1,126:13)
Block(4,15,-7,1:6)
Block(4,15,-6,98)
Block(4,15,-5,98)
Block(4,15,-4,98)
Block(4,15,-2,97:2)
Block(4,15,-1,5)
Block(4,15,0,164:1)
Block(4,16,-7,1:6)
Block(4,16,-6,98)
Block(4,16,-5,98)
Block(4,16,-4,98)
Block(4,16,-3,126:8)
Block(4,16,-2,97:2)
Block(4,16,-1,164:3)
Block(4,17,-7,1:6)
Block(4,17,-6,98)
Block(4,17,-5,98)
Block(4,17,-4,98)
Block(4,17,-3,5)
Block(4,17,-2,164:3)
Block(4,18,-7,164:3)
Block(4,18,-6,164:1)
Block(4,18,-5,164:1)
Block(4,18,-4,164:1)
Block(4,18,-3,5:5)
Block(5,0,-7,112)
Block(5,0,-6,112)
Block(5,0,-5,4)
Block(5,0,-4,112)
Block(5,0,-3,112)
Block(5,0,-2,112)
Block(5,0,-1,4)
Block(5,0,0,3)
Block(5,0,1,3)
Block(5,1,-5,4)
Block(5,1,-1,4)
Block(5,1,0,2)
Block(5,1,1,2)
Block(5,2,-6,50:1)
Block(5,2,-5,4)
Block(5,2,-1,4)
Block(5,2,0,175:2)
Block(5,3,-7,126:8)
Block(5,3,-6,126:8)
Block(5,3,-5,4)
Block(5,3,-1,4)
Block(5,3,0,175:10)
Block(5,4,-7,2)
Block(5,4,-6,2)
Block(5,4,-5,4)
Block(5,4,-4,126:9)
Block(5,4,-3,126:9)
Block(5,4,-2,126:9)
Block(5,4,-1,4)
Block(5,5,-7,175:4)
Block(5,5,-6,175:3)
Block(5,5,-5,98)
Block(5,5,-4,171:10)
Block(5,5,-3,171:15)
Block(5,5,-2,171:10)
Block(5,5,-1,98)
Block(5,6,-7,175:10)
Block(5,6,-6,175:10)
Block(5,6,-5,98)
Block(5,6,-1,98)
Block(5,7,-5,98)
Block(5,7,-1,98)
Block(5,8,-5,98)
Block(5,8,-4,164:7)
Block(5,8,-3,95:4)
Block(5,8,-2,164:6)
Block(5,8,-1,98)
Block(5,9,-7,109:5)
Block(5,9,-5,179:2)
Block(5,9,-4,179:2)
Block(5,9,-3,179:2)
Block(5,9,-2,179:2)
Block(5,9,-1,179:2)
Block(5,10,-7,139)
Block(5,10,-6,5:2)
Block(5,10,-5,118:3)
Block(5,10,-1,5:4)
Block(5,10,0,5:2)
Block(5,11,-7,139)
Block(5,11,-6,5:2)
Block(5,11,0,5:2)
Block(5,12,-7,139)
Block(5,12,-6,5:2)
Block(5,12,-4,50:1)
Block(5,12,-2,50:1)
Block(5,12,0,5:2)
Block(5,13,-7,139)
Block(5,13,-6,5)
Block(5,13,-5,126:13)
Block(5,13,-4,126:13)
Block(5,13,-3,126:13)
Block(5,13,-2,126:13)
Block(5,13,-1,126:13)
Block(5,13,0,5)
Block(5,14,-7,139)
Block(5,14,-6,5)
Block(5,14,-5,26:10)
Block(5,14,-4,26:2)
Block(5,14,-1,54:2,43-Chest.nbt)
Block(5,14,0,5)
Block(5,14,1,126:13)
Block(5,15,-7,139)
Block(5,15,-6,164:2)
Block(5,15,0,164:3)
Block(5,16,-7,139)
Block(5,16,-5,164:2)
Block(5,16,-4,50:1)
Block(5,16,-2,50:1)
Block(5,16,-1,164:3)
Block(5,17,-7,164:6)
Block(5,17,-6,164:1)
Block(5,17,-5,164:1)
Block(5,17,-4,164:2)
Block(5,17,-2,164:3)
Block(5,18,-7,164:3)
Block(5,18,-3,5:5)
Block(6,0,-7,112)
Block(6,0,-6,112)
Block(6,0,-5,4)
Block(6,0,-4,112)
Block(6,0,-3,112)
Block(6,0,-2,112)
Block(6,0,-1,4)
Block(6,0,0,3)
Block(6,0,1,3)
Block(6,1,-7,130:4)
Block(6,1,-5,4)
Block(6,1,-4,145:3)
Block(6,1,-1,4)
Block(6,1,0,2)
Block(6,1,1,2)
Block(6,2,-5,4)
Block(6,2,-1,4)
Block(6,3,-7,53:4)
Block(6,3,-6,53:4)
Block(6,3,-5,4)
Block(6,3,-1,4)
Block(6,4,-7,2)
Block(6,4,-6,2)
Block(6,4,-5,4)
Block(6,4,-4,126:9)
Block(6,4,-3,126:9)
Block(6,4,-2,126:9)
Block(6,4,-1,4)
Block(6,5,-7,31:2)
Block(6,5,-6,175:3)
Block(6,5,-5,98)
Block(6,5,-4,171:15)
Block(6,5,-3,171:10)
Block(6,5,-2,171:15)
Block(6,5,-1,98)
Block(6,6,-6,175:10)
Block(6,6,-5,98)
Block(6,6,-1,102)
Block(6,7,-5,98)
Block(6,7,-1,102)
Block(6,8,-5,98)
Block(6,8,-4,164:7)
Block(6,8,-3,126:13)
Block(6,8,-2,164:6)
Block(6,8,-1,98)
Block(6,9,-5,179:2)
Block(6,9,-4,179:2)
Block(6,9,-3,179:2)
Block(6,9,-2,179:2)
Block(6,9,-1,179:2)
Block(6,10,-6,5:2)
Block(6,10,-1,5:4)
Block(6,10,0,135:3)
Block(6,11,-6,5:2)
Block(6,11,0,102)
Block(6,12,-6,5:2)
Block(6,12,0,135:7)
Block(6,13,-6,5)
Block(6,13,-5,126:13)
Block(6,13,-4,126:13)
Block(6,13,-3,126:13)
Block(6,13,-2,126:13)
Block(6,13,-1,126:13)
Block(6,13,0,5)
Block(6,14,-7,126:13)
Block(6,14,-6,5)
Block(6,14,-5,171:7)
Block(6,14,-4,171:7)
Block(6,14,0,5)
Block(6,14,1,126:13)
Block(6,15,-6,164:2)
Block(6,15,0,164:3)
Block(6,16,-5,164:2)
Block(6,16,-1,164:3)
Block(6,17,-4,164:2)
Block(6,17,-2,164:3)
Block(6,18,-3,5:5)
Block(7,0,-7,1:6)
Block(7,0,-6,1:6)
Block(7,0,-5,4)
Block(7,0,-4,112)
Block(7,0,-3,112)
Block(7,0,-2,112)
Block(7,0,-1,4)
Block(7,0,0,3)
Block(7,0,1,3)
Block(7,1,-7,4)
Block(7,1,-6,4)
Block(7,1,-5,4)
Block(7,1,-1,4)
Block(7,1,0,2)
Block(7,1,1,2)
Block(7,2,-7,4)
Block(7,2,-6,4)
Block(7,2,-5,4)
Block(7,2,-1,4)
Block(7,3,-7,2)
Block(7,3,-6,2)
Block(7,3,-5,4)
Block(7,3,-1,4)
Block(7,4,-7,31:2)
Block(7,4,-6,175:3)
Block(7,4,-5,4)
Block(7,4,-4,126:9)
Block(7,4,-3,126:9)
Block(7,4,-2,126:9)
Block(7,4,-1,4)
Block(7,5,-6,175:10)
Block(7,5,-5,98)
Block(7,5,-4,171:10)
Block(7,5,-3,171:15)
Block(7,5,-2,171:10)
Block(7,5,-1,98)
Block(7,6,-5,98)
Block(7,6,-1,98)
Block(7,7,-5,98)
Block(7,7,-1,98)
Block(7,8,-5,98)
Block(7,8,-4,164:7)
Block(7,8,-3,126:13)
Block(7,8,-2,164:6)
Block(7,8,-1,98)
Block(7,9,-5,179:2)
Block(7,9,-4,179:2)
Block(7,9,-3,179:2)
Block(7,9,-2,179:2)
Block(7,9,-1,179:2)
Block(7,10,-6,5:2)
Block(7,10,-5,5:4)
Block(7,10,-1,5:4)
Block(7,10,0,5:2)
Block(7,11,-6,5:2)
Block(7,11,-5,117,44-Cauldron.nbt)
Block(7,11,0,5:2)
Block(7,12,-6,5:2)
Block(7,12,0,5:2)
Block(7,13,-6,5)
Block(7,13,-5,126:13)
Block(7,13,-4,126:13)
Block(7,13,-3,126:13)
Block(7,13,-2,126:13)
Block(7,13,-1,126:13)
Block(7,13,0,5)
Block(7,14,-7,126:13)
Block(7,14,-6,5)
Block(7,14,-5,26:10)
Block(7,14,-4,26:2)
Block(7,14,-1,54:2,45-Chest.nbt)
Block(7,14,0,5)
Block(7,14,1,126:13)
Block(7,15,-6,164:2)
Block(7,15,0,164:3)
Block(7,16,-5,164:2)
Block(7,16,-1,164:3)
Block(7,17,-4,164:2)
Block(7,17,-2,164:3)
Block(7,18,-3,5:5)

Branch(16,0,0,true,villaC1R1,NORTH,100,0)
