

BranchFrequency: 10

BranchFrequencyGroup: CanOverride:0

CanOverride: true

SmoothRadius: -1

OverrideChildSettings: false

ReplaceAbove:
ReplaceBelow:

MustBeInside: VillageGeneratorStructurePlaceHolder, VillageGeneratorStructuresDelay, VillageGeneratorStructuresDelay2, VillageGeneratorStructuresDelay3, VillageGeneratorStructuresDelay4, VillageGeneratorStructuresDelay5, VillageGeneratorStructuresDelay6, VillageGeneratorStructuresDelay7, VillageGeneratorStructuresDelay8, VillageGeneratorStructuresDelay9, VillageGeneratorStructuresDelay10

Block(-8,0,-7,2)
Block(-8,0,-6,2)
Block(-8,0,-5,2)
Block(-8,0,-4,2)
Block(-8,0,-3,2)
Block(-8,0,-2,2)
Block(-8,0,-1,2)
Block(-8,0,0,2)
Block(-8,0,1,2)
Block(-8,0,2,2)
Block(-8,0,3,2)
Block(-8,0,4,2)
Block(-8,0,5,2)
Block(-8,0,6,2)
Block(-8,0,7,2)
Block(-8,0,8,2)
Block(-8,4,-7,134)
Block(-8,4,-6,134)
Block(-8,4,-5,134)
Block(-8,4,-4,134)
Block(-8,4,-3,134)
Block(-8,4,-2,134)
Block(-8,4,-1,134)
Block(-8,4,0,134)
Block(-8,4,1,134)
Block(-8,4,2,134)
Block(-8,4,3,134)
Block(-8,4,4,134)
Block(-8,4,5,134)
Block(-8,4,6,134)
Block(-8,4,7,134)
Block(-8,4,8,134)
Block(-7,0,-7,2)
Block(-7,0,-6,3)
Block(-7,0,-5,3)
Block(-7,0,-4,3)
Block(-7,0,-3,3)
Block(-7,0,-2,3)
Block(-7,0,-1,3)
Block(-7,0,0,3)
Block(-7,0,1,3)
Block(-7,0,2,3)
Block(-7,0,3,3)
Block(-7,0,4,3)
Block(-7,0,5,3)
Block(-7,0,6,3)
Block(-7,0,7,3)
Block(-7,0,8,3)
Block(-7,1,-6,17:1)
Block(-7,1,-5,17:1)
Block(-7,1,-4,17:1)
Block(-7,1,-3,17:1)
Block(-7,1,-2,17:1)
Block(-7,1,-1,17:1)
Block(-7,1,0,17:1)
Block(-7,1,1,17:1)
Block(-7,1,2,17:1)
Block(-7,1,3,17:1)
Block(-7,1,4,17:1)
Block(-7,1,5,17:1)
Block(-7,1,6,17:1)
Block(-7,1,7,17:1)
Block(-7,1,8,17:1)
Block(-7,2,-6,17:1)
Block(-7,2,-5,17:1)
Block(-7,2,-4,159)
Block(-7,2,-3,159)
Block(-7,2,-2,159)
Block(-7,2,-1,17:1)
Block(-7,2,0,159)
Block(-7,2,1,159)
Block(-7,2,2,159)
Block(-7,2,3,17:1)
Block(-7,2,4,159)
Block(-7,2,5,159)
Block(-7,2,6,159)
Block(-7,2,7,17:1)
Block(-7,2,8,159)
Block(-7,3,-6,17:1)
Block(-7,3,-5,17:1)
Block(-7,3,-4,159)
Block(-7,3,-3,159)
Block(-7,3,-2,159)
Block(-7,3,-1,17:1)
Block(-7,3,0,159)
Block(-7,3,1,159)
Block(-7,3,2,159)
Block(-7,3,3,17:1)
Block(-7,3,4,159)
Block(-7,3,5,159)
Block(-7,3,6,159)
Block(-7,3,7,17:1)
Block(-7,3,8,159)
Block(-7,4,-7,134:2)
Block(-7,4,-6,159)
Block(-7,4,-5,159)
Block(-7,4,-4,159)
Block(-7,4,-3,159)
Block(-7,4,-2,159)
Block(-7,4,-1,159)
Block(-7,4,0,159)
Block(-7,4,1,159)
Block(-7,4,2,159)
Block(-7,4,3,159)
Block(-7,4,4,159)
Block(-7,4,5,159)
Block(-7,4,6,159)
Block(-7,4,7,159)
Block(-7,4,8,159)
Block(-7,5,-6,134:2)
Block(-7,5,-5,134)
Block(-7,5,-4,134)
Block(-7,5,-3,134)
Block(-7,5,-2,134)
Block(-7,5,-1,134)
Block(-7,5,0,134)
Block(-7,5,1,134)
Block(-7,5,2,134)
Block(-7,5,3,134)
Block(-7,5,4,134)
Block(-7,5,5,134)
Block(-7,5,6,134)
Block(-7,5,7,134)
Block(-7,5,8,134)
Block(-6,0,-7,2)
Block(-6,0,-6,3)
Block(-6,0,-5,170)
Block(-6,0,-4,170)
Block(-6,0,-3,170)
Block(-6,0,-2,170)
Block(-6,0,-1,170)
Block(-6,0,0,170)
Block(-6,0,1,170)
Block(-6,0,2,170)
Block(-6,0,3,170)
Block(-6,0,4,170)
Block(-6,0,5,170)
Block(-6,0,6,170)
Block(-6,0,7,170)
Block(-6,0,8,170)
Block(-6,1,-6,17:1)
Block(-6,1,-5,170)
Block(-6,1,-1,85)
Block(-6,1,3,85)
Block(-6,1,7,85)
Block(-6,2,-6,17:1)
Block(-6,3,-6,17:1)
Block(-6,3,-1,50:1)
Block(-6,3,3,50:1)
Block(-6,3,7,50:1)
Block(-6,4,-7,134:2)
Block(-6,4,-6,159)
Block(-6,5,-6,134:2)
Block(-6,6,-5,134)
Block(-6,6,-4,134)
Block(-6,6,-3,134)
Block(-6,6,-2,134)
Block(-6,6,-1,134)
Block(-6,6,0,134)
Block(-6,6,1,134)
Block(-6,6,2,134)
Block(-6,6,3,134)
Block(-6,6,4,134)
Block(-6,6,5,134)
Block(-6,6,6,134)
Block(-6,6,7,134)
Block(-6,6,8,134)
Block(-5,0,-7,2)
Block(-5,0,-6,3)
Block(-5,0,-5,170)
Block(-5,0,-4,170)
Block(-5,0,-3,170)
Block(-5,0,-2,170)
Block(-5,0,-1,170)
Block(-5,0,0,170)
Block(-5,0,1,170)
Block(-5,0,2,170)
Block(-5,0,3,170)
Block(-5,0,4,170)
Block(-5,0,5,170)
Block(-5,0,6,170)
Block(-5,0,7,170)
Block(-5,0,8,170)
Block(-5,1,-6,17:1)
Block(-5,1,-5,170)
Block(-5,1,-1,85)
Block(-5,1,3,85)
Block(-5,1,7,85)
Block(-5,2,-6,159)
Block(-5,3,-6,159)
Block(-5,4,-7,134:2)
Block(-5,4,-6,159)
Block(-5,5,-6,134:2)
Block(-5,6,-5,134:2)
Block(-5,6,-4,126:9)
Block(-5,6,-3,126:9)
Block(-5,6,-2,126:9)
Block(-5,6,-1,126:9)
Block(-5,6,0,126:9)
Block(-5,6,1,126:9)
Block(-5,6,2,126:9)
Block(-5,6,3,126:9)
Block(-5,6,4,126:9)
Block(-5,6,5,126:9)
Block(-5,6,6,126:9)
Block(-5,6,7,126:9)
Block(-5,6,8,126:9)
Block(-4,0,-7,2)
Block(-4,0,-6,3)
Block(-4,0,-5,170)
Block(-4,0,-4,170)
Block(-4,0,-3,170)
Block(-4,0,-2,170)
Block(-4,0,-1,170)
Block(-4,0,0,170)
Block(-4,0,1,170)
Block(-4,0,2,170)
Block(-4,0,3,170)
Block(-4,0,4,170)
Block(-4,0,5,170)
Block(-4,0,6,170)
Block(-4,0,7,170)
Block(-4,0,8,170)
Block(-4,1,-6,17:1)
Block(-4,1,-1,85)
Block(-4,1,3,85)
Block(-4,1,7,85)
Block(-4,2,-6,159)
Block(-4,3,-6,159)
Block(-4,4,-7,134:2)
Block(-4,4,-6,159)
Block(-4,5,-6,134:2)
Block(-4,6,-5,134:2)
Block(-4,6,-4,126:9)
Block(-4,6,-3,134:1)
Block(-4,6,-2,134:1)
Block(-4,6,-1,134:1)
Block(-4,6,0,134:1)
Block(-4,6,1,134:1)
Block(-4,6,2,134:1)
Block(-4,6,3,134:1)
Block(-4,6,4,134:1)
Block(-4,6,5,134:1)
Block(-4,6,6,134:1)
Block(-4,6,7,134:1)
Block(-4,6,8,134:1)
Block(-3,0,-7,2)
Block(-3,0,-6,3)
Block(-3,0,-5,170)
Block(-3,0,-4,170)
Block(-3,0,-3,170)
Block(-3,0,-2,170)
Block(-3,0,-1,170)
Block(-3,0,0,170)
Block(-3,0,1,170)
Block(-3,0,2,170)
Block(-3,0,3,170)
Block(-3,0,4,170)
Block(-3,0,5,170)
Block(-3,0,6,170)
Block(-3,0,7,170)
Block(-3,0,8,170)
Block(-3,1,-6,17:1)
Block(-3,1,-1,85)
Block(-3,1,3,85)
Block(-3,1,7,85)
Block(-3,2,-6,159)
Block(-3,3,-6,159)
Block(-3,4,-7,134:2)
Block(-3,4,-6,159)
Block(-3,4,-2,17:1)
Block(-3,4,-1,17:9)
Block(-3,4,0,17:9)
Block(-3,4,1,17:9)
Block(-3,4,2,17:9)
Block(-3,4,3,17:9)
Block(-3,4,4,17:9)
Block(-3,4,5,17:9)
Block(-3,4,6,17:9)
Block(-3,4,7,17:9)
Block(-3,4,8,17:9)
Block(-3,5,-6,134:2)
Block(-3,5,-2,134:1)
Block(-3,5,-1,134:1)
Block(-3,5,0,134:1)
Block(-3,5,1,134:1)
Block(-3,5,2,134:1)
Block(-3,5,3,134:1)
Block(-3,5,4,134:1)
Block(-3,5,5,134:1)
Block(-3,5,6,134:1)
Block(-3,5,7,134:1)
Block(-3,5,8,134:1)
Block(-3,6,-5,134:2)
Block(-3,6,-4,126:9)
Block(-3,6,-3,134:3)
Block(-2,0,-7,2)
Block(-2,0,-6,3)
Block(-2,0,-5,170)
Block(-2,0,-4,170)
Block(-2,0,-3,170)
Block(-2,0,-2,170)
Block(-2,0,-1,4)
Block(-2,0,0,4)
Block(-2,0,1,4)
Block(-2,0,2,4)
Block(-2,0,3,4)
Block(-2,0,4,4)
Block(-2,0,5,4)
Block(-2,0,6,4)
Block(-2,0,7,4)
Block(-2,0,8,4)
Block(-2,1,-6,17:1)
Block(-2,1,-1,85)
Block(-2,1,0,85)
Block(-2,1,1,107:3)
Block(-2,1,2,85)
Block(-2,1,3,85)
Block(-2,1,4,85)
Block(-2,1,5,107:1)
Block(-2,1,6,85)
Block(-2,1,7,85)
Block(-2,1,8,85)
Block(-2,2,-6,17:1)
Block(-2,2,-1,85)
Block(-2,2,3,85)
Block(-2,2,7,85)
Block(-2,3,-6,17:1)
Block(-2,3,-5,50:3)
Block(-2,3,-1,85)
Block(-2,3,3,85)
Block(-2,3,7,85)
Block(-2,4,-7,134:2)
Block(-2,4,-6,159)
Block(-2,4,-2,17:5)
Block(-2,4,-1,134:1)
Block(-2,4,0,134:1)
Block(-2,4,1,134:1)
Block(-2,4,2,134:1)
Block(-2,4,3,134:1)
Block(-2,4,4,134:1)
Block(-2,4,5,134:1)
Block(-2,4,6,134:1)
Block(-2,4,7,134:1)
Block(-2,4,8,134:1)
Block(-2,5,-6,134:2)
Block(-2,5,-2,134:3)
Block(-2,6,-5,134:2)
Block(-2,6,-4,126:9)
Block(-2,6,-3,134:3)
Block(-1,0,-7,2)
Block(-1,0,-6,3)
Block(-1,0,-5,170)
Block(-1,0,-4,170)
Block(-1,0,-3,170)
Block(-1,0,-2,170)
Block(-1,0,-1,4)
Block(-1,0,0,2)
Block(-1,0,1,2)
Block(-1,0,2,2)
Block(-1,0,3,2)
Block(-1,0,4,2)
Block(-1,0,5,2)
Block(-1,0,6,2)
Block(-1,0,7,2)
Block(-1,0,8,2)
Block(-1,1,-6,17:1)
Block(-1,1,-1,85)
Block(-1,2,-6,159)
Block(-1,3,-6,159)
Block(-1,4,-7,134:2)
Block(-1,4,-6,159)
Block(-1,4,-2,17:5)
Block(-1,4,-1,134:3)
Block(-1,5,-6,134:2)
Block(-1,5,-2,134:3)
Block(-1,6,-5,134:2)
Block(-1,6,-4,126:9)
Block(-1,6,-3,134:3)
Block(0,0,-7,2)
Block(0,0,-6,3)
Block(0,0,-5,170)
Block(0,0,-4,170)
Block(0,0,-3,170)
Block(0,0,-2,170)
Block(0,0,-1,4)
Block(0,0,0,2)
Block(0,0,1,2)
Block(0,0,2,2)
Block(0,0,3,2)
Block(0,0,4,2)
Block(0,0,5,2)
Block(0,0,6,2)
Block(0,0,7,2)
Block(0,0,8,2)
Block(0,1,-6,17:1)
Block(0,1,-1,107:2)
Block(0,2,-6,159)
Block(0,3,-6,159)
Block(0,4,-7,134:2)
Block(0,4,-6,159)
Block(0,4,-2,17:5)
Block(0,4,-1,134:3)
Block(0,5,-6,134:2)
Block(0,5,-2,134:3)
Block(0,6,-5,134:2)
Block(0,6,-4,126:9)
Block(0,6,-3,134:3)
Block(1,0,-7,2)
Block(1,0,-5,170)
Block(1,0,-4,170)
Block(1,0,-3,170)
Block(1,0,-2,170)
Block(1,0,-1,4)
Block(1,0,0,2)
Block(1,0,1,2)
Block(1,0,2,2)
Block(1,0,3,2)
Block(1,0,4,2)
Block(1,0,5,2)
Block(1,0,6,2)
Block(1,0,7,2)
Block(1,0,8,2)
Block(1,1,-6,17:1)
Block(1,1,-1,85)
Block(1,2,-6,17:1)
Block(1,2,-1,85)
Block(1,3,-6,17:1)
Block(1,3,-1,85)
Block(1,4,-7,134:2)
Block(1,4,-6,159)
Block(1,4,-2,17:5)
Block(1,4,-1,134:3)
Block(1,5,-6,134:2)
Block(1,5,-5,17:9)
Block(1,5,-4,17:9)
Block(1,5,-3,17:9)
Block(1,5,-2,134:3)
Block(1,6,-5,134:2)
Block(1,6,-4,17:1)
Block(1,6,-3,134:3)
Block(2,0,-7,2)
Block(2,0,-6,3)
Block(2,0,-5,170)
Block(2,0,-4,170)
Block(2,0,-3,170)
Block(2,0,-2,170)
Block(2,0,-1,4)
Block(2,0,0,2)
Block(2,0,1,2)
Block(2,0,2,2)
Block(2,0,3,2)
Block(2,0,4,2)
Block(2,0,5,2)
Block(2,0,6,2)
Block(2,0,7,2)
Block(2,0,8,2)
Block(2,1,-6,17:1)
Block(2,1,-1,85)
Block(2,2,-6,17:1)
Block(2,2,-1,85)
Block(2,3,-6,17:1)
Block(2,3,-1,85)
Block(2,4,-7,134:2)
Block(2,4,-6,159)
Block(2,4,-2,17:5)
Block(2,4,-1,134:3)
Block(2,5,-6,134:2)
Block(2,5,-5,17:9)
Block(2,5,-4,17:9)
Block(2,5,-3,17:9)
Block(2,5,-2,134:3)
Block(2,6,-5,134:2)
Block(2,6,-4,17:1)
Block(2,6,-3,134:3)
Block(3,0,-7,2)
Block(3,0,-6,3)
Block(3,0,-5,170)
Block(3,0,-4,170)
Block(3,0,-3,170)
Block(3,0,-2,170)
Block(3,0,-1,4)
Block(3,0,0,2)
Block(3,0,1,2)
Block(3,0,2,2)
Block(3,0,3,2)
Block(3,0,4,2)
Block(3,0,5,2)
Block(3,0,6,2)
Block(3,0,7,2)
Block(3,0,8,2)
Block(3,1,-6,17:1)
Block(3,1,-1,107:2)
Block(3,2,-6,159)
Block(3,3,-6,159)
Block(3,4,-7,134:2)
Block(3,4,-6,159)
Block(3,4,-2,17:5)
Block(3,4,-1,134:3)
Block(3,5,-6,134:2)
Block(3,5,-2,134:3)
Block(3,6,-5,134:2)
Block(3,6,-4,126:9)
Block(3,6,-3,134:3)
Block(4,0,-7,2)
Block(4,0,-6,3)
Block(4,0,-5,170)
Block(4,0,-4,170)
Block(4,0,-3,170)
Block(4,0,-2,170)
Block(4,0,-1,4)
Block(4,0,0,2)
Block(4,0,1,2)
Block(4,0,2,2)
Block(4,0,3,2)
Block(4,0,4,2)
Block(4,0,5,2)
Block(4,0,6,2)
Block(4,0,7,2)
Block(4,0,8,2)
Block(4,1,-6,17:1)
Block(4,1,-1,85)
Block(4,2,-6,159)
Block(4,3,-6,159)
Block(4,4,-7,134:2)
Block(4,4,-6,159)
Block(4,4,-2,17:5)
Block(4,4,-1,134:3)
Block(4,5,-6,134:2)
Block(4,5,-2,134:3)
Block(4,6,-5,134:2)
Block(4,6,-4,126:9)
Block(4,6,-3,134:3)
Block(5,0,-7,2)
Block(5,0,-6,3)
Block(5,0,-5,170)
Block(5,0,-4,170)
Block(5,0,-3,170)
Block(5,0,-2,170)
Block(5,0,-1,4)
Block(5,0,0,4)
Block(5,0,1,4)
Block(5,0,2,4)
Block(5,0,3,4)
Block(5,0,4,4)
Block(5,0,5,4)
Block(5,0,6,4)
Block(5,0,7,4)
Block(5,0,8,4)
Block(5,1,-6,17:1)
Block(5,1,-1,85)
Block(5,1,0,85)
Block(5,1,1,107:3)
Block(5,1,2,85)
Block(5,1,3,85)
Block(5,1,4,85)
Block(5,1,5,107:3)
Block(5,1,6,85)
Block(5,1,7,85)
Block(5,1,8,85)
Block(5,2,-6,17:1)
Block(5,2,-1,85)
Block(5,2,3,85)
Block(5,2,7,85)
Block(5,3,-6,17:1)
Block(5,3,-5,50:3)
Block(5,3,-1,85)
Block(5,3,3,85)
Block(5,3,7,85)
Block(5,4,-7,134:2)
Block(5,4,-6,159)
Block(5,4,-2,17:5)
Block(5,4,-1,134)
Block(5,4,0,134)
Block(5,4,1,134)
Block(5,4,2,134)
Block(5,4,3,134)
Block(5,4,4,134)
Block(5,4,5,134)
Block(5,4,6,134)
Block(5,4,7,134)
Block(5,4,8,134)
Block(5,5,-6,134:2)
Block(5,5,-2,134:3)
Block(5,6,-5,134:2)
Block(5,6,-4,126:9)
Block(5,6,-3,134:3)
Block(6,0,-7,2)
Block(6,0,-6,3)
Block(6,0,-5,170)
Block(6,0,-4,170)
Block(6,0,-3,170)
Block(6,0,-2,170)
Block(6,0,-1,170)
Block(6,0,0,170)
Block(6,0,1,170)
Block(6,0,2,170)
Block(6,0,3,170)
Block(6,0,4,170)
Block(6,0,5,170)
Block(6,0,6,170)
Block(6,0,7,170)
Block(6,0,8,170:4)
Block(6,1,-6,17:1)
Block(6,1,-1,85)
Block(6,1,3,85)
Block(6,1,7,85)
Block(6,2,-6,159)
Block(6,3,-6,159)
Block(6,4,-7,134:2)
Block(6,4,-6,159)
Block(6,4,-2,17:1)
Block(6,4,-1,17:9)
Block(6,4,0,17:9)
Block(6,4,1,17:9)
Block(6,4,2,17:9)
Block(6,4,3,17:9)
Block(6,4,4,17:9)
Block(6,4,5,17:9)
Block(6,4,6,17:9)
Block(6,4,7,17:9)
Block(6,4,8,17:9)
Block(6,5,-6,134:2)
Block(6,5,-2,134)
Block(6,5,-1,134)
Block(6,5,0,134)
Block(6,5,1,134)
Block(6,5,2,134)
Block(6,5,3,134)
Block(6,5,4,134)
Block(6,5,5,134)
Block(6,5,6,134)
Block(6,5,7,134)
Block(6,5,8,134)
Block(6,6,-5,134:2)
Block(6,6,-4,126:9)
Block(6,6,-3,134:3)
Block(7,0,-7,2)
Block(7,0,-6,3)
Block(7,0,-5,170)
Block(7,0,-4,170)
Block(7,0,-3,170)
Block(7,0,-2,170)
Block(7,0,-1,170)
Block(7,0,0,170)
Block(7,0,1,170)
Block(7,0,2,170)
Block(7,0,3,170)
Block(7,0,4,170)
Block(7,0,5,170)
Block(7,0,6,170)
Block(7,0,7,170)
Block(7,0,8,170)
Block(7,1,-6,17:1)
Block(7,1,-1,85)
Block(7,1,3,85)
Block(7,1,7,85)
Block(7,2,-6,159)
Block(7,3,-6,159)
Block(7,4,-7,134:2)
Block(7,4,-6,159)
Block(7,5,-6,134:2)
Block(7,6,-5,134:2)
Block(7,6,-4,126:9)
Block(7,6,-3,134)
Block(7,6,-2,134)
Block(7,6,-1,134)
Block(7,6,0,134)
Block(7,6,1,134)
Block(7,6,2,134)
Block(7,6,3,134)
Block(7,6,4,134)
Block(7,6,5,134)
Block(7,6,6,134)
Block(7,6,7,134)
Block(7,6,8,134)

Branch(16,0,0,true,horse-stableC1R0,NORTH,100,0)
Branch(0,0,16,true,horse-stableC0R1,NORTH,100,0)
