

BranchFrequencyGroup: CanOverride:0

CanOverride: true

SmoothRadius: -1

OverrideChildSettings: false

ReplaceAbove:
ReplaceBelow:

MustBeInside: VillageGeneratorStructurePlaceHolder, VillageGeneratorStructuresDelay, VillageGeneratorStructuresDelay2, VillageGeneratorStructuresDelay3, VillageGeneratorStructuresDelay4, VillageGeneratorStructuresDelay5, VillageGeneratorStructuresDelay6, VillageGeneratorStructuresDelay7, VillageGeneratorStructuresDelay8, VillageGeneratorStructuresDelay9, VillageGeneratorStructuresDelay10

Block(-8,0,-7,2)
Block(-8,0,-6,3)
Block(-8,0,-5,2)
Block(-8,0,-4,2)
Block(-8,0,-3,2)
Block(-8,0,-2,2)
Block(-8,0,-1,2)
Block(-8,0,0,2)
Block(-8,0,1,2)
Block(-8,0,2,2)
Block(-8,0,3,2)
Block(-8,0,4,2)
Block(-8,0,5,2)
Block(-8,0,6,2)
Block(-8,0,7,2)
Block(-8,0,8,2)
Block(-8,1,-6,5:1)
Block(-8,1,-4,113)
Block(-8,2,-6,113)
Block(-8,2,-4,113)
Block(-8,3,-6,113)
Block(-8,3,-4,113)
Block(-8,4,-6,113)
Block(-8,4,-4,113)
Block(-8,5,-6,113)
Block(-8,5,-4,113)
Block(-8,6,-6,136:2)
Block(-8,6,-4,136:3)
Block(-8,7,-5,126:3)
Block(-7,0,-7,2)
Block(-7,0,-6,3)
Block(-7,0,-5,3)
Block(-7,0,-4,3)
Block(-7,0,-3,2)
Block(-7,0,-2,2)
Block(-7,0,-1,2)
Block(-7,0,0,2)
Block(-7,0,1,2)
Block(-7,0,2,2)
Block(-7,0,3,2)
Block(-7,0,4,2)
Block(-7,0,5,2)
Block(-7,0,6,2)
Block(-7,0,7,2)
Block(-7,0,8,2)
Block(-7,1,-6,35:14)
Block(-7,1,-5,5:1)
Block(-7,1,-4,5:1)
Block(-7,2,-4,5:1)
Block(-7,3,-4,5:1)
Block(-7,6,-6,136:2)
Block(-7,6,-4,136:3)
Block(-7,7,-5,126:3)
Block(-6,0,-7,2)
Block(-6,0,-6,3)
Block(-6,0,-5,3)
Block(-6,0,-4,3)
Block(-6,0,-3,2)
Block(-6,0,-2,2)
Block(-6,0,-1,2)
Block(-6,0,0,2)
Block(-6,0,1,2)
Block(-6,0,2,2)
Block(-6,0,3,2)
Block(-6,0,4,2)
Block(-6,0,5,2)
Block(-6,0,6,2)
Block(-6,0,7,2)
Block(-6,0,8,2)
Block(-6,1,-6,35:14)
Block(-6,1,-5,5:1)
Block(-6,1,-4,5:1)
Block(-6,2,-4,5:1)
Block(-6,3,-4,5:1)
Block(-6,6,-6,136:2)
Block(-6,6,-4,136:3)
Block(-6,7,-5,126:3)
Block(-5,0,-7,2)
Block(-5,0,-6,3)
Block(-5,0,-5,2)
Block(-5,0,-4,2)
Block(-5,0,-3,2)
Block(-5,0,-2,2)
Block(-5,0,-1,2)
Block(-5,0,0,2)
Block(-5,0,1,2)
Block(-5,0,2,2)
Block(-5,0,3,2)
Block(-5,0,4,2)
Block(-5,0,5,2)
Block(-5,0,6,2)
Block(-5,0,7,2)
Block(-5,0,8,2)
Block(-5,1,-6,5:1)
Block(-5,1,-4,113)
Block(-5,2,-6,113)
Block(-5,2,-4,113)
Block(-5,3,-6,113)
Block(-5,3,-4,113)
Block(-5,4,-6,113)
Block(-5,4,-4,113)
Block(-5,5,-6,113)
Block(-5,5,-4,113)
Block(-5,6,-6,136:2)
Block(-5,6,-4,136:3)
Block(-5,7,-5,126:3)
Block(-4,0,-7,2)
Block(-4,0,-6,3)
Block(-4,0,-5,3)
Block(-4,0,-4,3)
Block(-4,0,-3,2)
Block(-4,0,-2,2)
Block(-4,0,-1,2)
Block(-4,0,0,2)
Block(-4,0,1,2)
Block(-4,0,2,2)
Block(-4,0,3,2)
Block(-4,0,4,2)
Block(-4,0,5,2)
Block(-4,0,6,2)
Block(-4,0,7,2)
Block(-4,0,8,2)
Block(-4,1,-6,35:14)
Block(-4,1,-5,5:1)
Block(-4,1,-4,5:1)
Block(-4,2,-4,5:1)
Block(-4,3,-4,5:1)
Block(-4,6,-6,136:2)
Block(-4,6,-4,136:3)
Block(-4,7,-5,126:3)
Block(-3,0,-7,2)
Block(-3,0,-6,3)
Block(-3,0,-5,3)
Block(-3,0,-4,3)
Block(-3,0,-3,2)
Block(-3,0,-2,2)
Block(-3,0,-1,2)
Block(-3,0,0,2)
Block(-3,0,1,2)
Block(-3,0,2,2)
Block(-3,0,3,2)
Block(-3,0,4,2)
Block(-3,0,5,2)
Block(-3,0,6,2)
Block(-3,0,7,2)
Block(-3,0,8,2)
Block(-3,1,-6,35:14)
Block(-3,1,-5,5:1)
Block(-3,1,-4,5:1)
Block(-3,2,-4,5:1)
Block(-3,3,-4,5:1)
Block(-3,6,-6,136:2)
Block(-3,6,-4,136:3)
Block(-3,7,-5,126:3)
Block(-2,0,-7,2)
Block(-2,0,-6,3)
Block(-2,0,-5,2)
Block(-2,0,-4,2)
Block(-2,0,-3,2)
Block(-2,0,-2,2)
Block(-2,0,-1,2)
Block(-2,0,0,2)
Block(-2,0,1,2)
Block(-2,0,2,2)
Block(-2,0,3,2)
Block(-2,0,4,2)
Block(-2,0,5,2)
Block(-2,0,6,2)
Block(-2,0,7,2)
Block(-2,0,8,2)
Block(-2,1,-6,5:1)
Block(-2,1,-4,113)
Block(-2,2,-6,113)
Block(-2,2,-4,113)
Block(-2,3,-6,113)
Block(-2,3,-4,113)
Block(-2,4,-6,113)
Block(-2,4,-4,113)
Block(-2,5,-6,113)
Block(-2,5,-4,113)
Block(-2,6,-6,136:2)
Block(-2,6,-4,136:3)
Block(-2,7,-5,126:3)
Block(-1,0,-7,2)
Block(-1,0,-6,3)
Block(-1,0,-5,3)
Block(-1,0,-4,3)
Block(-1,0,-3,2)
Block(-1,0,-2,2)
Block(-1,0,-1,2)
Block(-1,0,0,2)
Block(-1,0,1,2)
Block(-1,0,2,2)
Block(-1,0,3,2)
Block(-1,0,4,2)
Block(-1,0,5,2)
Block(-1,0,6,2)
Block(-1,0,7,2)
Block(-1,0,8,2)
Block(-1,1,-6,35:14)
Block(-1,1,-5,5:1)
Block(-1,1,-4,5:1)
Block(-1,2,-4,5:1)
Block(-1,3,-4,5:1)
Block(-1,6,-6,136:2)
Block(-1,6,-4,136:3)
Block(-1,7,-5,126:3)
Block(0,0,-7,2)
Block(0,0,-6,3)
Block(0,0,-5,3)
Block(0,0,-4,3)
Block(0,0,-3,2)
Block(0,0,-2,2)
Block(0,0,-1,2)
Block(0,0,0,2)
Block(0,0,1,2)
Block(0,0,2,2)
Block(0,0,3,2)
Block(0,0,4,2)
Block(0,0,5,2)
Block(0,0,6,2)
Block(0,0,7,2)
Block(0,0,8,2)
Block(0,1,-6,35:14)
Block(0,1,-5,5:1)
Block(0,1,-4,5:1)
Block(0,2,-4,5:1)
Block(0,3,-4,5:1)
Block(0,6,-6,136:2)
Block(0,6,-4,136:3)
Block(0,7,-5,126:3)
Block(1,0,-7,2)
Block(1,0,-6,3)
Block(1,0,-5,2)
Block(1,0,-4,2)
Block(1,0,-3,2)
Block(1,0,-2,2)
Block(1,0,-1,2)
Block(1,0,0,2)
Block(1,0,1,2)
Block(1,0,2,2)
Block(1,0,3,2)
Block(1,0,4,2)
Block(1,0,5,2)
Block(1,0,6,2)
Block(1,0,7,2)
Block(1,0,8,2)
Block(1,1,-6,5:1)
Block(1,1,-4,113)
Block(1,2,-6,113)
Block(1,2,-4,113)
Block(1,3,-6,113)
Block(1,3,-4,113)
Block(1,4,-6,113)
Block(1,4,-4,113)
Block(1,5,-6,113)
Block(1,5,-4,113)
Block(1,6,-6,136:2)
Block(1,6,-4,136:3)
Block(1,7,-5,126:3)
Block(2,0,-7,2)
Block(2,0,-6,3)
Block(2,0,-5,3)
Block(2,0,-4,3)
Block(2,0,-3,2)
Block(2,0,-2,2)
Block(2,0,-1,2)
Block(2,0,0,2)
Block(2,0,1,2)
Block(2,0,2,2)
Block(2,0,3,2)
Block(2,0,4,2)
Block(2,0,5,2)
Block(2,0,6,2)
Block(2,0,7,2)
Block(2,0,8,2)
Block(2,1,-6,35:14)
Block(2,1,-5,5:1)
Block(2,1,-4,5:1)
Block(2,2,-4,5:1)
Block(2,3,-4,5:1)
Block(2,6,-6,136:2)
Block(2,6,-4,136:3)
Block(2,7,-5,126:3)
Block(3,0,-7,2)
Block(3,0,-6,3)
Block(3,0,-5,3)
Block(3,0,-4,3)
Block(3,0,-3,2)
Block(3,0,-2,2)
Block(3,0,-1,2)
Block(3,0,0,2)
Block(3,0,1,2)
Block(3,0,2,2)
Block(3,0,3,2)
Block(3,0,4,2)
Block(3,0,5,2)
Block(3,0,6,2)
Block(3,0,7,2)
Block(3,0,8,2)
Block(3,1,-6,35:14)
Block(3,1,-5,5:1)
Block(3,1,-4,5:1)
Block(3,2,-4,5:1)
Block(3,3,-4,5:1)
Block(3,6,-6,136:2)
Block(3,6,-4,136:3)
Block(3,7,-5,126:3)
Block(4,0,-7,2)
Block(4,0,-6,3)
Block(4,0,-5,2)
Block(4,0,-4,2)
Block(4,0,-3,2)
Block(4,0,-2,2)
Block(4,0,-1,2)
Block(4,0,0,2)
Block(4,0,1,2)
Block(4,0,2,2)
Block(4,0,3,2)
Block(4,0,4,2)
Block(4,0,5,2)
Block(4,0,6,2)
Block(4,0,7,2)
Block(4,0,8,2)
Block(4,1,-6,5:1)
Block(4,1,-4,113)
Block(4,2,-6,113)
Block(4,2,-4,113)
Block(4,3,-6,113)
Block(4,3,-4,113)
Block(4,4,-6,113)
Block(4,4,-4,113)
Block(4,5,-6,113)
Block(4,5,-4,113)
Block(4,6,-6,136:2)
Block(4,6,-4,136:3)
Block(4,7,-5,126:3)
Block(5,0,-7,2)
Block(5,0,-6,3)
Block(5,0,-5,3)
Block(5,0,-4,3)
Block(5,0,-3,2)
Block(5,0,-2,3)
Block(5,0,-1,3)
Block(5,0,0,2)
Block(5,0,1,3)
Block(5,0,2,3)
Block(5,0,3,2)
Block(5,0,4,3)
Block(5,0,5,3)
Block(5,0,6,2)
Block(5,0,7,2)
Block(5,0,8,2)
Block(5,1,-6,35:14)
Block(5,1,-5,5:1)
Block(5,1,-4,5:1)
Block(5,1,-3,113)
Block(5,1,-2,5:1)
Block(5,1,-1,5:1)
Block(5,1,0,113)
Block(5,1,1,5:1)
Block(5,1,2,5:1)
Block(5,1,3,113)
Block(5,1,4,5:1)
Block(5,1,5,5:1)
Block(5,1,6,113)
Block(5,2,-4,5:1)
Block(5,2,-3,113)
Block(5,2,-2,5:1)
Block(5,2,-1,5:1)
Block(5,2,0,113)
Block(5,2,1,5:1)
Block(5,2,2,5:1)
Block(5,2,3,113)
Block(5,2,4,5:1)
Block(5,2,5,5:1)
Block(5,2,6,113)
Block(5,3,-4,5:1)
Block(5,3,-3,113)
Block(5,3,-2,5:1)
Block(5,3,-1,5:1)
Block(5,3,0,113)
Block(5,3,1,5:1)
Block(5,3,2,5:1)
Block(5,3,3,113)
Block(5,3,4,5:1)
Block(5,3,5,5:1)
Block(5,3,6,113)
Block(5,4,-3,113)
Block(5,4,0,113)
Block(5,4,3,113)
Block(5,4,6,113)
Block(5,5,-3,113)
Block(5,5,0,113)
Block(5,5,3,113)
Block(5,5,6,113)
Block(5,6,-6,136:2)
Block(5,6,-4,136:3)
Block(5,6,-3,136)
Block(5,6,-2,136)
Block(5,6,-1,136)
Block(5,6,0,136)
Block(5,6,1,136)
Block(5,6,2,136)
Block(5,6,3,136)
Block(5,6,4,136)
Block(5,6,5,136)
Block(5,6,6,136)
Block(5,6,7,136)
Block(5,6,8,136)
Block(5,7,-5,126:3)
Block(6,0,-7,2)
Block(6,0,-6,3)
Block(6,0,-5,3)
Block(6,0,-4,3)
Block(6,0,-3,2)
Block(6,0,-2,3)
Block(6,0,-1,3)
Block(6,0,0,2)
Block(6,0,1,3)
Block(6,0,2,3)
Block(6,0,3,2)
Block(6,0,4,3)
Block(6,0,5,3)
Block(6,0,6,2)
Block(6,0,7,2)
Block(6,0,8,2)
Block(6,1,-6,35:14)
Block(6,1,-5,5:1)
Block(6,1,-4,5:1)
Block(6,1,-2,5:1)
Block(6,1,-1,5:1)
Block(6,1,1,5:1)
Block(6,1,2,5:1)
Block(6,1,4,5:1)
Block(6,1,5,5:1)
Block(6,1,7,113)
Block(6,2,7,113)
Block(6,3,7,113)
Block(6,4,7,113)
Block(6,5,7,113)
Block(6,6,-6,136:2)
Block(6,6,6,113)
Block(6,6,7,113)
Block(6,6,8,113)
Block(6,7,-5,126:3)
Block(6,7,-4,126:3)
Block(6,7,-3,126:3)
Block(6,7,-2,126:3)
Block(6,7,-1,126:3)
Block(6,7,0,126:3)
Block(6,7,1,126:3)
Block(6,7,2,126:3)
Block(6,7,3,126:3)
Block(6,7,4,126:3)
Block(6,7,5,126:3)
Block(6,7,6,126:3)
Block(6,7,7,126:3)
Block(6,7,8,126:3)
Block(7,0,-7,2)
Block(7,0,-6,3)
Block(7,0,-5,3)
Block(7,0,-4,3)
Block(7,0,-3,3)
Block(7,0,-2,3)
Block(7,0,-1,3)
Block(7,0,0,3)
Block(7,0,1,3)
Block(7,0,2,3)
Block(7,0,3,3)
Block(7,0,4,3)
Block(7,0,5,3)
Block(7,0,6,3)
Block(7,0,7,2)
Block(7,0,8,2)
Block(7,1,-6,5:1)
Block(7,1,-5,35:14)
Block(7,1,-4,35:14)
Block(7,1,-3,5:1)
Block(7,1,-2,35:14)
Block(7,1,-1,35:14)
Block(7,1,0,5:1)
Block(7,1,1,35:14)
Block(7,1,2,35:14)
Block(7,1,3,5:1)
Block(7,1,4,35:14)
Block(7,1,5,35:14)
Block(7,1,6,5:1)
Block(7,2,-6,113)
Block(7,2,-3,113)
Block(7,2,0,113)
Block(7,2,3,113)
Block(7,2,6,113)
Block(7,3,-6,113)
Block(7,3,-3,113)
Block(7,3,0,113)
Block(7,3,3,113)
Block(7,3,6,113)
Block(7,4,-6,113)
Block(7,4,-3,113)
Block(7,4,0,113)
Block(7,4,3,113)
Block(7,4,6,113)
Block(7,5,-6,113)
Block(7,5,-3,113)
Block(7,5,0,113)
Block(7,5,3,113)
Block(7,5,6,113)
Block(7,6,-6,136:1)
Block(7,6,-5,136:1)
Block(7,6,-4,136:1)
Block(7,6,-3,136:1)
Block(7,6,-2,136:1)
Block(7,6,-1,136:1)
Block(7,6,0,136:1)
Block(7,6,1,136:1)
Block(7,6,2,136:1)
Block(7,6,3,136:1)
Block(7,6,4,136:1)
Block(7,6,5,136:1)
Block(7,6,6,136:1)
Block(7,6,7,136:1)
Block(7,6,8,136:1)

Branch(16,0,0,true,market-age-of-empiresC2R0,NORTH,100,0)
