

BranchFrequencyGroup: CanOverride:0

CanOverride: true

SmoothRadius: -1

OverrideChildSettings: false

ReplaceAbove:
ReplaceBelow:

MustBeInside: VillageGeneratorStructurePlaceHolder, VillageGeneratorStructuresDelay, VillageGeneratorStructuresDelay2, VillageGeneratorStructuresDelay3, VillageGeneratorStructuresDelay4, VillageGeneratorStructuresDelay5, VillageGeneratorStructuresDelay6, VillageGeneratorStructuresDelay7, VillageGeneratorStructuresDelay8, VillageGeneratorStructuresDelay9, VillageGeneratorStructuresDelay10

Block(-8,0,-7,2)
Block(-8,0,-6,2)
Block(-8,0,-5,2)
Block(-8,0,-4,2)
Block(-8,0,-3,2)
Block(-8,0,-2,2)
Block(-8,0,-1,2)
Block(-8,0,0,2)
Block(-8,0,1,2)
Block(-8,0,2,2)
Block(-8,0,3,2)
Block(-8,0,4,2)
Block(-8,0,5,2)
Block(-8,0,6,2)
Block(-8,0,7,2)
Block(-8,0,8,2)
Block(-7,0,-7,2)
Block(-7,0,-6,2)
Block(-7,0,-5,2)
Block(-7,0,-4,2)
Block(-7,0,-3,2)
Block(-7,0,-2,2)
Block(-7,0,-1,2)
Block(-7,0,0,2)
Block(-7,0,1,2)
Block(-7,0,2,2)
Block(-7,0,3,2)
Block(-7,0,4,2)
Block(-7,0,5,2)
Block(-7,0,6,2)
Block(-7,0,7,2)
Block(-7,0,8,2)
Block(-6,0,-7,2)
Block(-6,0,-6,2)
Block(-6,0,-5,2)
Block(-6,0,-4,2)
Block(-6,0,-3,2)
Block(-6,0,-2,2)
Block(-6,0,-1,2)
Block(-6,0,0,2)
Block(-6,0,1,2)
Block(-6,0,2,2)
Block(-6,0,3,2)
Block(-6,0,4,2)
Block(-6,0,5,2)
Block(-6,0,6,2)
Block(-6,0,7,2)
Block(-6,0,8,2)
Block(-5,0,-7,2)
Block(-5,0,-6,2)
Block(-5,0,-5,2)
Block(-5,0,-4,2)
Block(-5,0,-3,2)
Block(-5,0,-2,2)
Block(-5,0,-1,2)
Block(-5,0,0,2)
Block(-5,0,1,2)
Block(-5,0,2,2)
Block(-5,0,3,2)
Block(-5,0,4,2)
Block(-5,0,5,2)
Block(-5,0,6,2)
Block(-5,0,7,3)
Block(-5,0,8,2)
Block(-5,1,5,113)
Block(-5,1,7,5:1)
Block(-5,2,5,113)
Block(-5,2,7,113)
Block(-5,3,5,113)
Block(-5,3,7,113)
Block(-5,4,5,113)
Block(-5,4,7,113)
Block(-5,5,5,113)
Block(-5,5,7,113)
Block(-5,6,5,136:2)
Block(-5,6,7,136:3)
Block(-5,7,6,126:3)
Block(-4,0,-7,2)
Block(-4,0,-6,2)
Block(-4,0,-5,2)
Block(-4,0,-4,2)
Block(-4,0,-3,2)
Block(-4,0,-2,2)
Block(-4,0,-1,2)
Block(-4,0,0,2)
Block(-4,0,1,2)
Block(-4,0,2,2)
Block(-4,0,3,2)
Block(-4,0,4,2)
Block(-4,0,5,3)
Block(-4,0,6,3)
Block(-4,0,7,3)
Block(-4,0,8,2)
Block(-4,1,5,5:1)
Block(-4,1,6,5:1)
Block(-4,1,7,35:14)
Block(-4,2,5,5:1)
Block(-4,3,5,5:1)
Block(-4,6,5,136:2)
Block(-4,6,7,136:3)
Block(-4,7,6,126:3)
Block(-3,0,-7,2)
Block(-3,0,-6,2)
Block(-3,0,-5,2)
Block(-3,0,-4,2)
Block(-3,0,-3,2)
Block(-3,0,-2,2)
Block(-3,0,-1,2)
Block(-3,0,0,2)
Block(-3,0,1,2)
Block(-3,0,2,2)
Block(-3,0,3,2)
Block(-3,0,4,2)
Block(-3,0,5,3)
Block(-3,0,6,3)
Block(-3,0,7,3)
Block(-3,0,8,2)
Block(-3,1,5,5:1)
Block(-3,1,6,5:1)
Block(-3,1,7,35:14)
Block(-3,2,5,5:1)
Block(-3,3,5,5:1)
Block(-3,6,5,136:2)
Block(-3,6,7,136:3)
Block(-3,7,6,126:3)
Block(-2,0,-7,2)
Block(-2,0,-6,2)
Block(-2,0,-5,2)
Block(-2,0,-4,2)
Block(-2,0,-3,2)
Block(-2,0,-2,2)
Block(-2,0,-1,2)
Block(-2,0,0,2)
Block(-2,0,1,2)
Block(-2,0,2,2)
Block(-2,0,3,2)
Block(-2,0,4,2)
Block(-2,0,5,2)
Block(-2,0,6,2)
Block(-2,0,7,3)
Block(-2,0,8,2)
Block(-2,1,5,113)
Block(-2,1,7,5:1)
Block(-2,2,5,113)
Block(-2,2,7,113)
Block(-2,3,5,113)
Block(-2,3,7,113)
Block(-2,4,5,113)
Block(-2,4,7,113)
Block(-2,5,5,113)
Block(-2,5,7,113)
Block(-2,6,5,136:2)
Block(-2,6,7,136:3)
Block(-2,7,6,126:3)
Block(-1,0,-7,2)
Block(-1,0,-6,2)
Block(-1,0,-5,2)
Block(-1,0,-4,2)
Block(-1,0,-3,2)
Block(-1,0,-2,2)
Block(-1,0,-1,2)
Block(-1,0,0,2)
Block(-1,0,1,2)
Block(-1,0,2,2)
Block(-1,0,3,2)
Block(-1,0,4,2)
Block(-1,0,5,3)
Block(-1,0,6,3)
Block(-1,0,7,3)
Block(-1,0,8,2)
Block(-1,1,5,5:1)
Block(-1,1,6,5:1)
Block(-1,1,7,35:14)
Block(-1,2,5,5:1)
Block(-1,3,5,5:1)
Block(-1,6,5,136:2)
Block(-1,6,7,136:3)
Block(-1,7,6,126:3)
Block(0,0,-7,2)
Block(0,0,-6,2)
Block(0,0,-5,2)
Block(0,0,-4,2)
Block(0,0,-3,2)
Block(0,0,-2,2)
Block(0,0,-1,2)
Block(0,0,0,2)
Block(0,0,1,2)
Block(0,0,2,2)
Block(0,0,3,2)
Block(0,0,4,2)
Block(0,0,5,3)
Block(0,0,6,3)
Block(0,0,7,3)
Block(0,0,8,2)
Block(0,1,5,5:1)
Block(0,1,6,5:1)
Block(0,1,7,35:14)
Block(0,2,5,5:1)
Block(0,3,5,5:1)
Block(0,6,5,136:2)
Block(0,6,7,136:3)
Block(0,7,6,126:3)
Block(1,0,-7,2)
Block(1,0,-6,2)
Block(1,0,-5,2)
Block(1,0,-4,2)
Block(1,0,-3,2)
Block(1,0,-2,2)
Block(1,0,-1,2)
Block(1,0,0,2)
Block(1,0,1,2)
Block(1,0,2,2)
Block(1,0,3,2)
Block(1,0,4,2)
Block(1,0,5,2)
Block(1,0,6,2)
Block(1,0,7,3)
Block(1,0,8,2)
Block(1,1,5,113)
Block(1,1,7,5:1)
Block(1,2,5,113)
Block(1,2,7,113)
Block(1,3,5,113)
Block(1,3,7,113)
Block(1,4,5,113)
Block(1,4,7,113)
Block(1,5,5,113)
Block(1,5,7,113)
Block(1,6,5,136:2)
Block(1,6,7,136:3)
Block(1,7,6,126:3)
Block(2,0,-7,2)
Block(2,0,-6,2)
Block(2,0,-5,2)
Block(2,0,-4,2)
Block(2,0,-3,2)
Block(2,0,-2,2)
Block(2,0,-1,2)
Block(2,0,0,2)
Block(2,0,1,2)
Block(2,0,2,2)
Block(2,0,3,2)
Block(2,0,4,2)
Block(2,0,5,3)
Block(2,0,6,3)
Block(2,0,7,3)
Block(2,0,8,2)
Block(2,1,5,5:1)
Block(2,1,6,5:1)
Block(2,1,7,35:14)
Block(2,2,5,5:1)
Block(2,3,5,5:1)
Block(2,6,5,136:2)
Block(2,6,7,136:3)
Block(2,7,6,126:3)
Block(3,0,-7,2)
Block(3,0,-6,2)
Block(3,0,-5,2)
Block(3,0,-4,2)
Block(3,0,-3,2)
Block(3,0,-2,2)
Block(3,0,-1,2)
Block(3,0,0,2)
Block(3,0,1,2)
Block(3,0,2,2)
Block(3,0,3,2)
Block(3,0,4,2)
Block(3,0,5,3)
Block(3,0,6,3)
Block(3,0,7,3)
Block(3,0,8,2)
Block(3,1,5,5:1)
Block(3,1,6,5:1)
Block(3,1,7,35:14)
Block(3,2,5,5:1)
Block(3,3,5,5:1)
Block(3,6,5,136:2)
Block(3,6,7,136:3)
Block(3,7,6,126:3)
Block(4,0,-7,2)
Block(4,0,-6,2)
Block(4,0,-5,2)
Block(4,0,-4,2)
Block(4,0,-3,2)
Block(4,0,-2,2)
Block(4,0,-1,2)
Block(4,0,0,2)
Block(4,0,1,2)
Block(4,0,2,2)
Block(4,0,3,2)
Block(4,0,4,2)
Block(4,0,5,2)
Block(4,0,6,2)
Block(4,0,7,3)
Block(4,0,8,2)
Block(4,1,5,113)
Block(4,1,7,5:1)
Block(4,2,5,113)
Block(4,2,7,113)
Block(4,3,5,113)
Block(4,3,7,113)
Block(4,4,5,113)
Block(4,4,7,113)
Block(4,5,5,113)
Block(4,5,7,113)
Block(4,6,5,136:2)
Block(4,6,7,136:3)
Block(4,7,6,126:3)
Block(5,0,-7,2)
Block(5,0,-6,2)
Block(5,0,-5,2)
Block(5,0,-4,2)
Block(5,0,-3,2)
Block(5,0,-2,2)
Block(5,0,-1,3)
Block(5,0,0,3)
Block(5,0,1,2)
Block(5,0,2,3)
Block(5,0,3,3)
Block(5,0,4,2)
Block(5,0,5,3)
Block(5,0,6,3)
Block(5,0,7,3)
Block(5,0,8,2)
Block(5,1,-2,113)
Block(5,1,-1,5:1)
Block(5,1,0,5:1)
Block(5,1,1,113)
Block(5,1,2,5:1)
Block(5,1,3,5:1)
Block(5,1,4,113)
Block(5,1,5,5:1)
Block(5,1,6,5:1)
Block(5,1,7,35:14)
Block(5,2,-2,113)
Block(5,2,-1,5:1)
Block(5,2,0,5:1)
Block(5,2,1,113)
Block(5,2,2,5:1)
Block(5,2,3,5:1)
Block(5,2,4,113)
Block(5,2,5,5:1)
Block(5,3,-2,113)
Block(5,3,-1,5:1)
Block(5,3,0,5:1)
Block(5,3,1,113)
Block(5,3,2,5:1)
Block(5,3,3,5:1)
Block(5,3,4,113)
Block(5,3,5,5:1)
Block(5,4,-2,113)
Block(5,4,1,113)
Block(5,4,4,113)
Block(5,5,-2,113)
Block(5,5,1,113)
Block(5,5,4,113)
Block(5,6,-7,136)
Block(5,6,-6,136)
Block(5,6,-5,136)
Block(5,6,-4,136)
Block(5,6,-3,136)
Block(5,6,-2,136)
Block(5,6,-1,136)
Block(5,6,0,136)
Block(5,6,1,136)
Block(5,6,2,136)
Block(5,6,3,136)
Block(5,6,4,136)
Block(5,6,5,136)
Block(5,6,7,136:3)
Block(5,7,6,126:3)
Block(6,0,-7,2)
Block(6,0,-6,2)
Block(6,0,-5,2)
Block(6,0,-4,2)
Block(6,0,-3,2)
Block(6,0,-2,2)
Block(6,0,-1,3)
Block(6,0,0,3)
Block(6,0,1,2)
Block(6,0,2,3)
Block(6,0,3,3)
Block(6,0,4,2)
Block(6,0,5,3)
Block(6,0,6,3)
Block(6,0,7,3)
Block(6,0,8,2)
Block(6,1,-3,113:14)
Block(6,1,-1,5:1)
Block(6,1,0,5:1)
Block(6,1,2,5:1)
Block(6,1,3,5:1)
Block(6,1,5,5:1)
Block(6,1,6,5:1)
Block(6,1,7,35:14)
Block(6,2,-3,113)
Block(6,3,-3,113)
Block(6,4,-3,113)
Block(6,5,-3,113)
Block(6,6,-7,113)
Block(6,6,-6,113)
Block(6,6,-5,113)
Block(6,6,-4,113)
Block(6,6,-3,113:2)
Block(6,6,-2,113)
Block(6,6,7,136:3)
Block(6,7,-7,126:3)
Block(6,7,-6,126:3)
Block(6,7,-5,126:3)
Block(6,7,-4,126:3)
Block(6,7,-3,126:3)
Block(6,7,-2,126:3)
Block(6,7,-1,126:3)
Block(6,7,0,126:3)
Block(6,7,1,126:3)
Block(6,7,2,126:3)
Block(6,7,3,126:3)
Block(6,7,4,126:3)
Block(6,7,5,126:3)
Block(6,7,6,126:3)
Block(7,0,-7,2)
Block(7,0,-6,2)
Block(7,0,-5,2)
Block(7,0,-4,2)
Block(7,0,-3,2)
Block(7,0,-2,3)
Block(7,0,-1,3)
Block(7,0,0,3)
Block(7,0,1,3)
Block(7,0,2,3)
Block(7,0,3,3)
Block(7,0,4,3)
Block(7,0,5,3)
Block(7,0,6,3)
Block(7,0,7,3)
Block(7,0,8,2)
Block(7,1,-2,5:1)
Block(7,1,-1,35:14)
Block(7,1,0,35:14)
Block(7,1,1,5:1)
Block(7,1,2,35:14)
Block(7,1,3,35:14)
Block(7,1,4,5:1)
Block(7,1,5,35:14)
Block(7,1,6,35:14)
Block(7,1,7,5:1)
Block(7,2,-2,113)
Block(7,2,1,113)
Block(7,2,4,113)
Block(7,2,7,113)
Block(7,3,-2,113)
Block(7,3,1,113)
Block(7,3,4,113)
Block(7,3,7,113)
Block(7,4,-2,113)
Block(7,4,1,113)
Block(7,4,4,113)
Block(7,4,7,113)
Block(7,5,-2,113)
Block(7,5,1,113)
Block(7,5,4,113)
Block(7,5,7,113)
Block(7,6,-7,136:1)
Block(7,6,-6,136:1)
Block(7,6,-5,136:1)
Block(7,6,-4,136:1)
Block(7,6,-3,136:1)
Block(7,6,-2,136:1)
Block(7,6,-1,136:1)
Block(7,6,0,136:1)
Block(7,6,1,136:1)
Block(7,6,2,136:1)
Block(7,6,3,136:1)
Block(7,6,4,136:1)
Block(7,6,5,136:1)
Block(7,6,6,136:1)
Block(7,6,7,136:1)

Branch(16,0,0,true,market-age-of-empiresC2R1,NORTH,100,0)
