

BranchFrequencyGroup: CanOverride:0

CanOverride: true

SmoothRadius: -1

OverrideChildSettings: false

ReplaceAbove:
ReplaceBelow:

MustBeInside: VillageGeneratorStructurePlaceHolder, VillageGeneratorStructuresDelay, VillageGeneratorStructuresDelay2, VillageGeneratorStructuresDelay3, VillageGeneratorStructuresDelay4, VillageGeneratorStructuresDelay5, VillageGeneratorStructuresDelay6, VillageGeneratorStructuresDelay7, VillageGeneratorStructuresDelay8, VillageGeneratorStructuresDelay9, VillageGeneratorStructuresDelay10

Block(-8,0,-7,2)
Block(-8,0,-6,2)
Block(-8,0,-5,2)
Block(-8,0,-4,2)
Block(-8,0,-3,2)
Block(-8,0,-2,2)
Block(-8,0,-1,2)
Block(-8,0,0,2)
Block(-8,0,1,2)
Block(-8,0,2,2)
Block(-8,0,3,2)
Block(-8,0,4,2)
Block(-8,0,5,2)
Block(-8,0,6,2)
Block(-8,0,7,2)
Block(-8,0,8,2)
Block(-7,0,-7,98)
Block(-7,0,-6,98)
Block(-7,0,-5,98)
Block(-7,0,-4,98)
Block(-7,0,-3,98)
Block(-7,0,-2,98)
Block(-7,0,-1,98)
Block(-7,0,0,98)
Block(-7,0,1,98)
Block(-7,0,2,98)
Block(-7,0,3,98)
Block(-7,0,4,98)
Block(-7,0,5,98)
Block(-7,0,6,98)
Block(-7,0,7,98)
Block(-7,0,8,98)
Block(-7,1,-7,98)
Block(-7,1,-6,98)
Block(-7,1,-5,98)
Block(-7,1,-4,98)
Block(-7,1,-3,98)
Block(-7,1,-2,5:5)
Block(-7,1,-1,98)
Block(-7,1,0,98)
Block(-7,1,1,98)
Block(-7,1,2,98)
Block(-7,1,3,98)
Block(-7,1,4,98)
Block(-7,1,5,98)
Block(-7,1,6,98)
Block(-7,1,7,98)
Block(-7,1,8,5:5)
Block(-7,2,-7,98)
Block(-7,2,-6,98)
Block(-7,2,-5,98)
Block(-7,2,-4,98)
Block(-7,2,-3,98)
Block(-7,2,-2,5:5)
Block(-7,2,-1,98)
Block(-7,2,0,98)
Block(-7,2,1,98)
Block(-7,2,2,98)
Block(-7,2,3,98)
Block(-7,2,4,98)
Block(-7,2,5,98)
Block(-7,2,6,98)
Block(-7,2,7,98)
Block(-7,2,8,5:5)
Block(-7,3,-7,5:5)
Block(-7,3,-6,5:5)
Block(-7,3,-5,5:5)
Block(-7,3,-4,5:5)
Block(-7,3,-3,5:5)
Block(-7,3,-2,5:5)
Block(-7,3,-1,5:5)
Block(-7,3,0,5:5)
Block(-7,3,1,5:5)
Block(-7,3,2,5:5)
Block(-7,3,3,5:5)
Block(-7,3,4,5:5)
Block(-7,3,5,5:5)
Block(-7,3,6,5:5)
Block(-7,3,7,5:5)
Block(-7,3,8,5:5)
Block(-7,4,-7,5:2)
Block(-7,4,-6,5:2)
Block(-7,4,-5,5:2)
Block(-7,4,-4,5:2)
Block(-7,4,-3,5:2)
Block(-7,4,-2,5:5)
Block(-7,4,-1,5:2)
Block(-7,4,0,5:2)
Block(-7,4,1,5:2)
Block(-7,4,2,5:2)
Block(-7,4,3,5:2)
Block(-7,4,4,5:2)
Block(-7,4,5,5:2)
Block(-7,4,6,5:2)
Block(-7,4,7,5:2)
Block(-7,4,8,5:5)
Block(-7,5,-7,5:5)
Block(-7,5,-6,5:5)
Block(-7,5,-5,5:5)
Block(-7,5,-4,5:5)
Block(-7,5,-3,5:5)
Block(-7,5,-2,5:5)
Block(-7,5,-1,5:5)
Block(-7,5,0,5:5)
Block(-7,5,1,5:5)
Block(-7,5,2,5:5)
Block(-7,5,3,5:5)
Block(-7,5,4,5:5)
Block(-7,5,5,5:5)
Block(-7,5,6,5:5)
Block(-7,5,7,5:5)
Block(-7,5,8,5:5)
Block(-7,6,-7,5:2)
Block(-7,6,-6,5:2)
Block(-7,6,-5,5:2)
Block(-7,6,-4,5:2)
Block(-7,6,-3,5:2)
Block(-7,6,-2,5:5)
Block(-7,6,-1,5:2)
Block(-7,6,0,5:2)
Block(-7,6,1,5:2)
Block(-7,6,2,5:2)
Block(-7,6,3,5:2)
Block(-7,6,4,5:2)
Block(-7,6,5,5:2)
Block(-7,6,6,5:2)
Block(-7,6,7,5:2)
Block(-7,6,8,5:5)
Block(-7,7,-7,5:2)
Block(-7,7,-6,5:2)
Block(-7,7,-5,5:2)
Block(-7,7,-4,5:2)
Block(-7,7,-3,5:2)
Block(-7,7,-2,5:5)
Block(-7,7,-1,5:2)
Block(-7,7,0,5:2)
Block(-7,7,1,5:2)
Block(-7,7,2,5:2)
Block(-7,7,3,5:2)
Block(-7,7,4,5:2)
Block(-7,7,5,5:2)
Block(-7,7,6,5:2)
Block(-7,7,7,5:2)
Block(-7,7,8,5:5)
Block(-7,8,-7,5:2)
Block(-7,8,-6,5:2)
Block(-7,8,-5,5:2)
Block(-7,8,-4,5:2)
Block(-7,8,-3,5:2)
Block(-7,8,-2,5:5)
Block(-7,8,-1,5:2)
Block(-7,8,0,5:2)
Block(-7,8,1,5:2)
Block(-7,8,2,5:2)
Block(-7,8,3,5:2)
Block(-7,8,4,5:2)
Block(-7,8,5,5:2)
Block(-7,8,6,5:2)
Block(-7,8,7,5:2)
Block(-7,8,8,5:5)
Block(-7,9,-7,5:5)
Block(-7,9,-6,5:5)
Block(-7,9,-5,5:5)
Block(-7,9,-4,5:5)
Block(-7,9,-3,5:5)
Block(-7,9,-2,5:5)
Block(-7,9,-1,5:5)
Block(-7,9,0,5:5)
Block(-7,9,1,5:5)
Block(-7,9,2,5:5)
Block(-7,9,3,5:5)
Block(-7,9,4,5:5)
Block(-7,9,5,5:5)
Block(-7,9,6,5:5)
Block(-7,9,7,5:5)
Block(-7,9,8,5:5)
Block(-7,10,-7,35:14)
Block(-7,10,-6,35:14)
Block(-7,10,-5,35:14)
Block(-7,10,-4,35:14)
Block(-7,10,-3,35:14)
Block(-7,10,-2,35:14)
Block(-7,10,-1,35:14)
Block(-7,10,0,35:14)
Block(-7,10,1,35:14)
Block(-7,10,2,35:14)
Block(-7,10,3,35:14)
Block(-7,10,4,35:14)
Block(-7,10,5,35:14)
Block(-7,10,6,35:14)
Block(-7,10,7,35:14)
Block(-7,10,8,35:14)
Block(-7,11,-7,5:2)
Block(-7,11,-6,5:2)
Block(-7,11,-5,5:2)
Block(-7,11,-4,5:2)
Block(-7,11,-3,5:2)
Block(-7,11,-2,5:2)
Block(-7,11,-1,5:2)
Block(-7,11,0,5:2)
Block(-7,11,1,5:2)
Block(-7,11,2,5:2)
Block(-7,11,3,5:2)
Block(-7,11,4,5:2)
Block(-7,11,5,5:2)
Block(-7,11,6,5:2)
Block(-7,11,7,5:2)
Block(-7,11,8,5:5)
Block(-7,12,-7,5:2)
Block(-7,12,-6,5:2)
Block(-7,12,-5,5:2)
Block(-7,12,-4,5:2)
Block(-7,12,-3,5:2)
Block(-7,12,-2,5:2)
Block(-7,12,-1,5:2)
Block(-7,12,0,5:2)
Block(-7,12,1,5:2)
Block(-7,12,2,5:2)
Block(-7,12,3,5:2)
Block(-7,12,4,5:2)
Block(-7,12,5,5:2)
Block(-7,12,6,5:2)
Block(-7,12,7,5:2)
Block(-7,12,8,5:5)
Block(-7,13,-7,5:2)
Block(-7,13,-6,5:2)
Block(-7,13,-5,5:2)
Block(-7,13,-4,5:2)
Block(-7,13,-3,5:2)
Block(-7,13,-2,5:2)
Block(-7,13,-1,5:2)
Block(-7,13,0,5:2)
Block(-7,13,1,5:2)
Block(-7,13,2,5:2)
Block(-7,13,3,5:2)
Block(-7,13,4,5:2)
Block(-7,13,5,5:2)
Block(-7,13,6,5:2)
Block(-7,13,7,5:2)
Block(-7,13,8,5:5)
Block(-7,14,-7,5:5)
Block(-7,14,-6,5:5)
Block(-7,14,-5,5:5)
Block(-7,14,-4,5:5)
Block(-7,14,-3,5:5)
Block(-7,14,-2,5:5)
Block(-7,14,-1,5:5)
Block(-7,14,0,5:5)
Block(-7,14,1,5:5)
Block(-7,14,2,5:5)
Block(-7,14,3,5:5)
Block(-7,14,4,5:5)
Block(-7,14,5,5:5)
Block(-7,14,6,5:5)
Block(-7,14,7,5:5)
Block(-7,14,8,5:5)
Block(-7,15,-7,5:2)
Block(-7,15,-6,5:2)
Block(-7,15,-5,5:2)
Block(-7,15,-4,136)
Block(-7,15,-3,136)
Block(-7,15,-2,136)
Block(-7,15,-1,136)
Block(-7,15,0,136)
Block(-7,15,1,5:2)
Block(-7,15,2,5:2)
Block(-7,15,3,5:2)
Block(-7,15,4,5:2)
Block(-7,15,5,5:2)
Block(-7,15,6,136)
Block(-7,15,7,136)
Block(-7,15,8,136)
Block(-7,16,-7,5:2)
Block(-7,16,-6,5:2)
Block(-7,16,-5,136:3)
Block(-7,16,1,136:2)
Block(-7,16,2,5:2)
Block(-7,16,3,5:2)
Block(-7,16,4,5:2)
Block(-7,16,5,136:3)
Block(-7,17,-7,5:2)
Block(-7,17,-6,136:3)
Block(-7,17,2,136:2)
Block(-7,17,3,5:2)
Block(-7,17,4,136:3)
Block(-7,18,-7,126:3)
Block(-7,18,3,126:3)
Block(-6,0,-7,123:1)
Block(-6,0,-6,123:1)
Block(-6,0,-5,123:1)
Block(-6,0,-4,123:1)
Block(-6,0,-3,123:1)
Block(-6,0,-2,123:1)
Block(-6,0,-1,123:1)
Block(-6,0,0,123:1)
Block(-6,0,1,123:1)
Block(-6,0,2,123:1)
Block(-6,0,3,123:1)
Block(-6,0,4,123:1)
Block(-6,0,5,123:1)
Block(-6,0,6,123:1)
Block(-6,0,7,123:1)
Block(-6,0,8,98)
Block(-6,1,8,98)
Block(-6,2,8,98)
Block(-6,3,8,5:5)
Block(-6,4,8,5:2)
Block(-6,5,-7,50:1)
Block(-6,5,-6,50:1)
Block(-6,5,-5,50:1)
Block(-6,5,-4,50:1)
Block(-6,5,-3,50:1)
Block(-6,5,-2,50:1)
Block(-6,5,-1,50:1)
Block(-6,5,0,50:1)
Block(-6,5,1,50:1)
Block(-6,5,2,50:1)
Block(-6,5,3,50:1)
Block(-6,5,4,50:1)
Block(-6,5,5,50:1)
Block(-6,5,6,50:1)
Block(-6,5,7,50:1)
Block(-6,5,8,5:5)
Block(-6,6,8,5:2)
Block(-6,7,8,5:2)
Block(-6,8,8,5:2)
Block(-6,9,-7,5:5)
Block(-6,9,-6,5:5)
Block(-6,9,-5,5:5)
Block(-6,9,-4,5:5)
Block(-6,9,-3,5:5)
Block(-6,9,-2,5:5)
Block(-6,9,-1,5:5)
Block(-6,9,0,5:5)
Block(-6,9,1,5:5)
Block(-6,9,2,5:5)
Block(-6,9,3,5:5)
Block(-6,9,4,5:5)
Block(-6,9,5,5:5)
Block(-6,9,6,5:5)
Block(-6,9,7,5:5)
Block(-6,9,8,5:5)
Block(-6,10,8,35:14)
Block(-6,11,8,5:2)
Block(-6,12,8,5:2)
Block(-6,13,8,5:5)
Block(-6,14,8,5:5)
Block(-6,15,-7,50:1)
Block(-6,15,-6,50:1)
Block(-6,15,-5,50:1)
Block(-6,15,1,50:1)
Block(-6,15,2,50:1)
Block(-6,15,3,50:1)
Block(-6,15,4,50:1)
Block(-6,15,5,50:1)
Block(-6,15,7,50:4)
Block(-6,15,8,5:2)
Block(-6,16,-5,136)
Block(-6,16,-4,136)
Block(-6,16,-3,136)
Block(-6,16,-2,136)
Block(-6,16,-1,136)
Block(-6,16,0,136)
Block(-6,16,1,136:2)
Block(-6,16,5,136)
Block(-6,16,6,136)
Block(-6,16,7,136)
Block(-6,16,8,136)
Block(-6,17,-6,136:3)
Block(-6,17,2,136:2)
Block(-6,17,4,136:3)
Block(-6,18,-7,126:3)
Block(-6,18,3,126:3)
Block(-5,0,-7,123:1)
Block(-5,0,-6,123:1)
Block(-5,0,-5,123:1)
Block(-5,0,-4,123:1)
Block(-5,0,-3,123:1)
Block(-5,0,-2,123:1)
Block(-5,0,-1,123:1)
Block(-5,0,0,123:1)
Block(-5,0,1,123:1)
Block(-5,0,2,123:1)
Block(-5,0,3,123:1)
Block(-5,0,4,123:1)
Block(-5,0,5,123:1)
Block(-5,0,6,123:1)
Block(-5,0,7,123:1)
Block(-5,0,8,98)
Block(-5,1,8,98)
Block(-5,2,8,98)
Block(-5,3,8,5:5)
Block(-5,4,8,5:2)
Block(-5,5,8,5:5)
Block(-5,6,8,5:2)
Block(-5,7,8,5:2)
Block(-5,8,8,5:2)
Block(-5,9,-7,5:5)
Block(-5,9,-6,5:5)
Block(-5,9,-5,5:5)
Block(-5,9,-4,5:5)
Block(-5,9,-3,5:5)
Block(-5,9,-2,5:5)
Block(-5,9,-1,5:5)
Block(-5,9,0,5:5)
Block(-5,9,1,5:5)
Block(-5,9,2,5:5)
Block(-5,9,3,5:5)
Block(-5,9,4,5:5)
Block(-5,9,5,5:5)
Block(-5,9,6,5:5)
Block(-5,9,7,5:5)
Block(-5,9,8,5:5)
Block(-5,10,8,35:14)
Block(-5,11,8,5:2)
Block(-5,12,8,5:5)
Block(-5,13,8,5:2)
Block(-5,14,8,5:5)
Block(-5,15,7,50:4)
Block(-5,15,8,5:2)
Block(-5,16,8,5:2)
Block(-5,17,-6,136)
Block(-5,17,-5,136)
Block(-5,17,-4,136)
Block(-5,17,-3,136)
Block(-5,17,-2,136)
Block(-5,17,-1,136)
Block(-5,17,0,136)
Block(-5,17,1,136)
Block(-5,17,2,136)
Block(-5,17,4,136)
Block(-5,17,5,136)
Block(-5,17,6,136)
Block(-5,17,7,136)
Block(-5,17,8,136)
Block(-5,18,-7,126:3)
Block(-5,18,3,126:3)
Block(-4,0,-7,123:1)
Block(-4,0,-6,123:1)
Block(-4,0,-5,123:1)
Block(-4,0,-4,123:1)
Block(-4,0,-3,123:1)
Block(-4,0,-2,123:1)
Block(-4,0,-1,123:1)
Block(-4,0,0,123:1)
Block(-4,0,1,123:1)
Block(-4,0,2,123:1)
Block(-4,0,3,123:1)
Block(-4,0,4,123:1)
Block(-4,0,5,123:1)
Block(-4,0,6,123:1)
Block(-4,0,7,123:1)
Block(-4,0,8,98)
Block(-4,1,8,98)
Block(-4,2,8,98)
Block(-4,3,8,5:5)
Block(-4,4,8,5:2)
Block(-4,5,8,5:5)
Block(-4,6,8,5:2)
Block(-4,7,8,5:2)
Block(-4,8,8,5:2)
Block(-4,9,-7,5:5)
Block(-4,9,-6,5:5)
Block(-4,9,-5,5:5)
Block(-4,9,-4,5:5)
Block(-4,9,-3,5:5)
Block(-4,9,-2,5:5)
Block(-4,9,-1,5:5)
Block(-4,9,0,5:5)
Block(-4,9,1,5:5)
Block(-4,9,2,5:5)
Block(-4,9,3,5:5)
Block(-4,9,4,5:5)
Block(-4,9,5,5:5)
Block(-4,9,6,5:5)
Block(-4,9,7,136:1)
Block(-4,9,8,5:5)
Block(-4,10,6,113)
Block(-4,10,8,35:14)
Block(-4,11,8,5:5)
Block(-4,12,8,5:2)
Block(-4,13,8,5:2)
Block(-4,14,8,5:5)
Block(-4,15,7,50:4)
Block(-4,15,8,5:2)
Block(-4,16,8,5:2)
Block(-4,17,8,5:2)
Block(-4,18,-7,136)
Block(-4,18,-6,136)
Block(-4,18,-5,136)
Block(-4,18,-4,136)
Block(-4,18,-3,136)
Block(-4,18,-2,136)
Block(-4,18,-1,136)
Block(-4,18,0,136)
Block(-4,18,1,136)
Block(-4,18,2,136)
Block(-4,18,3,136)
Block(-4,18,4,136)
Block(-4,18,5,136)
Block(-4,18,6,136)
Block(-4,18,7,136)
Block(-4,18,8,136)
Block(-3,0,-7,123:1)
Block(-3,0,-6,123:1)
Block(-3,0,-5,123:1)
Block(-3,0,-4,123:1)
Block(-3,0,-3,123:1)
Block(-3,0,-2,123:1)
Block(-3,0,-1,123:1)
Block(-3,0,0,123:1)
Block(-3,0,1,123:1)
Block(-3,0,2,123:1)
Block(-3,0,3,123:1)
Block(-3,0,4,123:1)
Block(-3,0,5,123:1)
Block(-3,0,6,123:1)
Block(-3,0,7,123:1)
Block(-3,0,8,98)
Block(-3,1,8,98)
Block(-3,2,8,98)
Block(-3,3,8,5:5)
Block(-3,4,8,5:2)
Block(-3,5,8,5:5)
Block(-3,6,8,5:2)
Block(-3,7,8,5:2)
Block(-3,8,7,136:1)
Block(-3,8,8,5:2)
Block(-3,9,-7,5:5)
Block(-3,9,-6,5:5)
Block(-3,9,-5,5:5)
Block(-3,9,-4,5:5)
Block(-3,9,-3,5:5)
Block(-3,9,-2,5:5)
Block(-3,9,-1,5:5)
Block(-3,9,0,5:5)
Block(-3,9,1,5:5)
Block(-3,9,2,5:5)
Block(-3,9,3,5:5)
Block(-3,9,4,5:5)
Block(-3,9,5,5:5)
Block(-3,9,6,5:5)
Block(-3,9,8,5:5)
Block(-3,10,6,113)
Block(-3,10,8,35:14)
Block(-3,11,8,5:5)
Block(-3,12,8,5:5)
Block(-3,13,8,5:5)
Block(-3,14,8,5:5)
Block(-3,15,7,50:4)
Block(-3,15,8,5:2)
Block(-3,16,8,5:2)
Block(-3,17,8,5:2)
Block(-3,18,8,5:2)
Block(-3,19,-7,136)
Block(-3,19,-6,136)
Block(-3,19,-5,136)
Block(-3,19,-4,136)
Block(-3,19,-3,136)
Block(-3,19,-2,136)
Block(-3,19,-1,136)
Block(-3,19,0,136)
Block(-3,19,1,136)
Block(-3,19,2,136)
Block(-3,19,3,136)
Block(-3,19,4,136)
Block(-3,19,5,136)
Block(-3,19,6,136)
Block(-3,19,7,136)
Block(-3,19,8,136)
Block(-2,0,-7,123)
Block(-2,0,-6,123)
Block(-2,0,-5,123)
Block(-2,0,-4,123)
Block(-2,0,-3,123)
Block(-2,0,-2,123)
Block(-2,0,-1,123)
Block(-2,0,0,123)
Block(-2,0,1,123)
Block(-2,0,2,123)
Block(-2,0,3,123)
Block(-2,0,4,123)
Block(-2,0,5,123)
Block(-2,0,6,123)
Block(-2,0,7,123)
Block(-2,0,8,98)
Block(-2,1,8,98)
Block(-2,2,8,98)
Block(-2,3,8,5:5)
Block(-2,4,8,5:5)
Block(-2,5,8,5:5)
Block(-2,6,8,5:5)
Block(-2,7,7,136:1)
Block(-2,7,8,5:5)
Block(-2,8,8,5:5)
Block(-2,9,-7,5:5)
Block(-2,9,-6,5:5)
Block(-2,9,-5,5:5)
Block(-2,9,-4,5:5)
Block(-2,9,-3,5:5)
Block(-2,9,-2,5:5)
Block(-2,9,-1,5:5)
Block(-2,9,0,5:5)
Block(-2,9,1,5:5)
Block(-2,9,2,5:5)
Block(-2,9,3,5:5)
Block(-2,9,4,5:5)
Block(-2,9,5,5:5)
Block(-2,9,6,5:5)
Block(-2,9,8,5:5)
Block(-2,10,6,113)
Block(-2,10,8,35:14)
Block(-2,11,8,5:2)
Block(-2,12,8,5:2)
Block(-2,13,8,5:2)
Block(-2,14,8,5:5)
Block(-2,15,7,50:4)
Block(-2,15,8,5:2)
Block(-2,16,8,5:2)
Block(-2,17,8,5:2)
Block(-2,18,8,5:2)
Block(-2,19,8,5:2)
Block(-2,20,-7,136)
Block(-2,20,-6,136)
Block(-2,20,-5,136)
Block(-2,20,-4,136)
Block(-2,20,-3,136)
Block(-2,20,-2,136)
Block(-2,20,-1,136)
Block(-2,20,0,136)
Block(-2,20,1,136)
Block(-2,20,2,136)
Block(-2,20,3,136)
Block(-2,20,4,136)
Block(-2,20,5,136)
Block(-2,20,6,136)
Block(-2,20,7,136)
Block(-2,20,8,136)
Block(-1,0,-7,123:1)
Block(-1,0,-6,123:1)
Block(-1,0,-5,123:1)
Block(-1,0,-4,123:1)
Block(-1,0,-3,123:1)
Block(-1,0,-2,123:1)
Block(-1,0,-1,123:1)
Block(-1,0,0,123:1)
Block(-1,0,1,123:1)
Block(-1,0,2,123:1)
Block(-1,0,3,123:1)
Block(-1,0,4,123:1)
Block(-1,0,5,123:1)
Block(-1,0,6,123:1)
Block(-1,0,7,123:1)
Block(-1,0,8,98)
Block(-1,1,6,136)
Block(-1,1,8,98)
Block(-1,2,8,98)
Block(-1,3,8,5:5)
Block(-1,4,8,5:2)
Block(-1,5,8,5:5)
Block(-1,6,7,136:1)
Block(-1,6,8,5:2)
Block(-1,7,8,5:2)
Block(-1,8,8,5:2)
Block(-1,9,-7,5:5)
Block(-1,9,-6,5:5)
Block(-1,9,-5,5:5)
Block(-1,9,-4,5:5)
Block(-1,9,-3,5:5)
Block(-1,9,-2,5:5)
Block(-1,9,-1,5:5)
Block(-1,9,0,5:5)
Block(-1,9,1,5:5)
Block(-1,9,2,5:5)
Block(-1,9,3,5:5)
Block(-1,9,4,5:5)
Block(-1,9,5,5:5)
Block(-1,9,6,5:5)
Block(-1,9,8,5:5)
Block(-1,10,-7,50:5)
Block(-1,10,-4,50:5)
Block(-1,10,0,50:5)
Block(-1,10,3,50:5)
Block(-1,10,6,113)
Block(-1,10,8,35:14)
Block(-1,11,8,5:5)
Block(-1,12,8,5:5)
Block(-1,13,8,5:5)
Block(-1,14,8,5:5)
Block(-1,15,7,50:4)
Block(-1,15,8,5:2)
Block(-1,16,8,5:2)
Block(-1,17,8,5:2)
Block(-1,18,8,5:2)
Block(-1,19,8,5:2)
Block(-1,20,8,5:2)
Block(-1,21,-7,136)
Block(-1,21,-6,136)
Block(-1,21,-5,136)
Block(-1,21,-4,136)
Block(-1,21,-3,136)
Block(-1,21,-2,136)
Block(-1,21,-1,136)
Block(-1,21,0,136)
Block(-1,21,1,136)
Block(-1,21,2,136)
Block(-1,21,3,136)
Block(-1,21,4,136)
Block(-1,21,5,136)
Block(-1,21,6,136)
Block(-1,21,7,136)
Block(-1,21,8,136)
Block(0,0,-7,123:1)
Block(0,0,-6,123:1)
Block(0,0,-5,123:1)
Block(0,0,-4,123:1)
Block(0,0,-3,123:1)
Block(0,0,-2,123:1)
Block(0,0,-1,123:1)
Block(0,0,0,123:1)
Block(0,0,1,123:1)
Block(0,0,2,123:1)
Block(0,0,3,123:1)
Block(0,0,4,123:1)
Block(0,0,5,123:1)
Block(0,0,6,123:1)
Block(0,0,7,123:1)
Block(0,0,8,98)
Block(0,1,8,98)
Block(0,2,6,136)
Block(0,2,8,98)
Block(0,3,8,5:5)
Block(0,4,8,5:2)
Block(0,5,7,136:1)
Block(0,5,8,5:5)
Block(0,6,8,5:2)
Block(0,7,8,5:2)
Block(0,8,8,5:2)
Block(0,9,-7,5:5)
Block(0,9,-6,5:5)
Block(0,9,-5,5:5)
Block(0,9,-4,5:5)
Block(0,9,-3,5:5)
Block(0,9,-2,5:5)
Block(0,9,-1,5:5)
Block(0,9,0,5:5)
Block(0,9,1,5:5)
Block(0,9,2,5:5)
Block(0,9,3,5:5)
Block(0,9,4,5:5)
Block(0,9,5,5:5)
Block(0,9,6,5:5)
Block(0,9,7,5:5)
Block(0,9,8,5:5)
Block(0,10,6,113)
Block(0,10,7,113)
Block(0,10,8,35:14)
Block(0,11,8,102)
Block(0,12,8,102)
Block(0,13,8,102)
Block(0,14,8,5:5)
Block(0,15,7,50:4)
Block(0,15,8,5:2)
Block(0,16,8,5:2)
Block(0,17,8,5:2)
Block(0,18,8,5:2)
Block(0,19,8,5:2)
Block(0,20,8,5:2)
Block(0,21,-7,136:1)
Block(0,21,-6,136:1)
Block(0,21,-5,136:1)
Block(0,21,-4,136:1)
Block(0,21,-3,136:1)
Block(0,21,-2,136:1)
Block(0,21,-1,136:1)
Block(0,21,0,136:1)
Block(0,21,1,136:1)
Block(0,21,2,136:1)
Block(0,21,3,136:1)
Block(0,21,4,136:1)
Block(0,21,5,136:1)
Block(0,21,6,136:1)
Block(0,21,7,136:1)
Block(0,21,8,136:1)
Block(1,0,-7,123:1)
Block(1,0,-6,123:1)
Block(1,0,-5,123:1)
Block(1,0,-4,123:1)
Block(1,0,-3,123:1)
Block(1,0,-2,123:1)
Block(1,0,-1,123:1)
Block(1,0,0,123:1)
Block(1,0,1,123:1)
Block(1,0,2,123:1)
Block(1,0,3,123:1)
Block(1,0,4,123:1)
Block(1,0,5,123:1)
Block(1,0,6,123:1)
Block(1,0,7,123:1)
Block(1,0,8,98)
Block(1,1,8,98)
Block(1,2,8,98)
Block(1,3,6,136)
Block(1,3,8,5:5)
Block(1,4,7,136:1)
Block(1,4,8,5:2)
Block(1,5,8,5:5)
Block(1,6,8,5:2)
Block(1,7,8,5:2)
Block(1,8,8,5:2)
Block(1,9,-7,5:5)
Block(1,9,-6,5:5)
Block(1,9,-5,5:5)
Block(1,9,-4,5:5)
Block(1,9,-3,5:5)
Block(1,9,-2,5:5)
Block(1,9,-1,5:5)
Block(1,9,0,5:5)
Block(1,9,1,5:5)
Block(1,9,2,5:5)
Block(1,9,3,5:5)
Block(1,9,4,5:5)
Block(1,9,5,5:5)
Block(1,9,6,5:5)
Block(1,9,7,5:5)
Block(1,9,8,5:5)
Block(1,10,8,35:14)
Block(1,11,8,102)
Block(1,12,8,102)
Block(1,13,8,102)
Block(1,14,8,5:5)
Block(1,15,7,50:4)
Block(1,15,8,5:2)
Block(1,16,8,5:2)
Block(1,17,8,5:2)
Block(1,18,8,5:2)
Block(1,19,8,5:2)
Block(1,20,-7,136:1)
Block(1,20,-6,136:1)
Block(1,20,-5,136:1)
Block(1,20,-4,136:1)
Block(1,20,-3,136:1)
Block(1,20,-2,136:1)
Block(1,20,-1,136:1)
Block(1,20,0,136:1)
Block(1,20,1,136:1)
Block(1,20,2,136:1)
Block(1,20,3,136:1)
Block(1,20,4,136:1)
Block(1,20,5,136:1)
Block(1,20,6,136:1)
Block(1,20,7,136:1)
Block(1,20,8,136:1)
Block(2,0,-7,123:1)
Block(2,0,-6,123:1)
Block(2,0,-5,123:1)
Block(2,0,-4,123:1)
Block(2,0,-3,123:1)
Block(2,0,-2,123:1)
Block(2,0,-1,123:1)
Block(2,0,0,123:1)
Block(2,0,1,123:1)
Block(2,0,2,123:1)
Block(2,0,3,123:1)
Block(2,0,4,123:1)
Block(2,0,5,123:1)
Block(2,0,6,123:1)
Block(2,0,7,123:1)
Block(2,0,8,98)
Block(2,1,8,98)
Block(2,2,8,98)
Block(2,3,8,5:5)
Block(2,4,6,126:3)
Block(2,4,7,126:3)
Block(2,4,8,5:2)
Block(2,5,-7,50:2)
Block(2,5,-6,50:2)
Block(2,5,-5,50:2)
Block(2,5,-4,50:2)
Block(2,5,-3,50:2)
Block(2,5,-2,50:2)
Block(2,5,-1,50:2)
Block(2,5,0,50:2)
Block(2,5,1,50:2)
Block(2,5,2,50:2)
Block(2,5,3,50:2)
Block(2,5,4,50:2)
Block(2,5,5,50:2)
Block(2,5,6,50:2)
Block(2,5,7,50:2)
Block(2,5,8,5:5)
Block(2,6,8,5:2)
Block(2,7,8,5:2)
Block(2,8,8,5:2)
Block(2,9,-7,5:5)
Block(2,9,-6,5:5)
Block(2,9,-5,5:5)
Block(2,9,-4,5:5)
Block(2,9,-3,5:5)
Block(2,9,-2,5:5)
Block(2,9,-1,5:5)
Block(2,9,0,5:5)
Block(2,9,1,5:5)
Block(2,9,2,5:5)
Block(2,9,3,5:5)
Block(2,9,4,5:5)
Block(2,9,5,5:5)
Block(2,9,6,5:5)
Block(2,9,7,5:5)
Block(2,9,8,5:5)
Block(2,10,8,35:14)
Block(2,11,8,102)
Block(2,12,8,102)
Block(2,13,8,102)
Block(2,14,8,5:5)
Block(2,15,7,50:4)
Block(2,15,8,5:2)
Block(2,16,8,5:2)
Block(2,17,8,5:2)
Block(2,18,8,5:2)
Block(2,19,-7,136:1)
Block(2,19,-6,136:1)
Block(2,19,-5,136:1)
Block(2,19,-4,136:1)
Block(2,19,-3,136:1)
Block(2,19,-2,136:1)
Block(2,19,-1,136:1)
Block(2,19,0,136:1)
Block(2,19,1,136:1)
Block(2,19,2,136:1)
Block(2,19,3,136:1)
Block(2,19,4,136:1)
Block(2,19,5,136:1)
Block(2,19,6,136:1)
Block(2,19,7,136:1)
Block(2,19,8,136:1)
Block(3,0,-7,98)
Block(3,0,-6,98)
Block(3,0,-5,98)
Block(3,0,-4,98)
Block(3,0,-3,98)
Block(3,0,-2,98)
Block(3,0,-1,98)
Block(3,0,0,98)
Block(3,0,1,98)
Block(3,0,2,98)
Block(3,0,3,98)
Block(3,0,4,98)
Block(3,0,5,98)
Block(3,0,6,98)
Block(3,0,7,98)
Block(3,0,8,98)
Block(3,1,-7,98)
Block(3,1,-6,98)
Block(3,1,-5,98)
Block(3,1,-4,98)
Block(3,1,-3,98)
Block(3,1,-2,5:5)
Block(3,1,-1,98)
Block(3,1,0,98)
Block(3,1,1,98)
Block(3,1,5,98)
Block(3,1,6,98)
Block(3,1,7,98)
Block(3,1,8,5:5)
Block(3,2,-7,98)
Block(3,2,-6,98)
Block(3,2,-5,98)
Block(3,2,-4,98)
Block(3,2,-3,98)
Block(3,2,-2,5:5)
Block(3,2,-1,98)
Block(3,2,0,98)
Block(3,2,1,98)
Block(3,2,5,98)
Block(3,2,6,98)
Block(3,2,7,98)
Block(3,2,8,5:5)
Block(3,3,-7,5:5)
Block(3,3,-6,5:5)
Block(3,3,-5,5:5)
Block(3,3,-4,5:5)
Block(3,3,-3,5:5)
Block(3,3,-2,5:5)
Block(3,3,-1,5:5)
Block(3,3,0,5:5)
Block(3,3,1,5:5)
Block(3,3,5,5:5)
Block(3,3,6,5:5)
Block(3,3,7,5:5)
Block(3,3,8,5:5)
Block(3,4,-7,5:2)
Block(3,4,-6,5:2)
Block(3,4,-5,5:2)
Block(3,4,-4,5:2)
Block(3,4,-3,5:2)
Block(3,4,-2,5:5)
Block(3,4,-1,5:2)
Block(3,4,0,5:2)
Block(3,4,1,5:2)
Block(3,4,2,5:2)
Block(3,4,3,5:2)
Block(3,4,4,5:2)
Block(3,4,5,5:2)
Block(3,4,6,5:2)
Block(3,4,7,5:2)
Block(3,4,8,5:5)
Block(3,5,-7,5:5)
Block(3,5,-6,5:5)
Block(3,5,-5,5:5)
Block(3,5,-4,5:5)
Block(3,5,-3,5:5)
Block(3,5,-2,5:5)
Block(3,5,-1,5:5)
Block(3,5,0,5:5)
Block(3,5,1,5:5)
Block(3,5,2,5:5)
Block(3,5,3,5:5)
Block(3,5,4,5:5)
Block(3,5,5,5:5)
Block(3,5,6,5:5)
Block(3,5,7,5:5)
Block(3,5,8,5:5)
Block(3,6,-7,5:2)
Block(3,6,-6,5:2)
Block(3,6,-5,5:2)
Block(3,6,-4,5:2)
Block(3,6,-3,5:2)
Block(3,6,-2,5:5)
Block(3,6,-1,5:2)
Block(3,6,0,5:2)
Block(3,6,1,5:2)
Block(3,6,2,5:2)
Block(3,6,3,5:2)
Block(3,6,4,5:2)
Block(3,6,5,5:2)
Block(3,6,6,5:2)
Block(3,6,7,5:2)
Block(3,6,8,5:5)
Block(3,7,-7,5:2)
Block(3,7,-6,5:2)
Block(3,7,-5,5:2)
Block(3,7,-4,5:2)
Block(3,7,-3,5:2)
Block(3,7,-2,5:5)
Block(3,7,-1,5:2)
Block(3,7,0,5:2)
Block(3,7,1,5:2)
Block(3,7,2,5:2)
Block(3,7,3,5:2)
Block(3,7,4,5:2)
Block(3,7,5,5:2)
Block(3,7,6,5:2)
Block(3,7,7,5:2)
Block(3,7,8,5:5)
Block(3,8,-7,5:2)
Block(3,8,-6,5:2)
Block(3,8,-5,5:2)
Block(3,8,-4,5:2)
Block(3,8,-3,5:2)
Block(3,8,-2,5:5)
Block(3,8,-1,5:2)
Block(3,8,0,5:2)
Block(3,8,1,5:2)
Block(3,8,2,5:2)
Block(3,8,3,5:2)
Block(3,8,4,5:2)
Block(3,8,5,5:2)
Block(3,8,6,5:2)
Block(3,8,7,5:2)
Block(3,8,8,5:5)
Block(3,9,-7,5:5)
Block(3,9,-6,5:5)
Block(3,9,-5,5:5)
Block(3,9,-4,5:5)
Block(3,9,-3,5:5)
Block(3,9,-2,5:5)
Block(3,9,-1,5:5)
Block(3,9,0,5:5)
Block(3,9,1,5:5)
Block(3,9,2,5:5)
Block(3,9,3,5:5)
Block(3,9,4,5:5)
Block(3,9,5,5:5)
Block(3,9,6,5:5)
Block(3,9,7,5:5)
Block(3,9,8,5:5)
Block(3,10,8,35:14)
Block(3,11,8,5:5)
Block(3,12,8,5:2)
Block(3,13,8,5:2)
Block(3,14,8,5:5)
Block(3,15,7,50:4)
Block(3,15,8,5:2)
Block(3,16,8,5:2)
Block(3,17,8,5:2)
Block(3,18,-7,136:1)
Block(3,18,-6,136:1)
Block(3,18,-5,136:1)
Block(3,18,-4,136:1)
Block(3,18,-3,136:1)
Block(3,18,-2,136:1)
Block(3,18,-1,136:1)
Block(3,18,0,136:1)
Block(3,18,1,136:1)
Block(3,18,2,136:1)
Block(3,18,3,136:1)
Block(3,18,4,136:1)
Block(3,18,5,136:1)
Block(3,18,6,136:1)
Block(3,18,7,136:1)
Block(3,18,8,136:1)
Block(4,0,-7,2)
Block(4,0,-6,2)
Block(4,0,-5,2)
Block(4,0,-4,2)
Block(4,0,-3,2)
Block(4,0,-2,2)
Block(4,0,-1,2)
Block(4,0,0,2)
Block(4,0,1,2)
Block(4,0,2,2)
Block(4,0,3,2)
Block(4,0,4,2)
Block(4,0,5,2)
Block(4,0,6,2)
Block(4,0,7,2)
Block(4,0,8,2)
Block(4,9,-7,5:5)
Block(4,9,-6,5:5)
Block(4,9,-5,5:5)
Block(4,9,-4,5:5)
Block(4,9,-3,5:5)
Block(4,9,-2,5:5)
Block(4,9,-1,5:5)
Block(4,9,0,5:5)
Block(4,9,1,5:5)
Block(4,9,2,5:5)
Block(4,9,3,5:5)
Block(4,9,4,5:5)
Block(4,9,5,5:5)
Block(4,9,6,5:5)
Block(4,9,7,5:5)
Block(4,9,8,5:5)
Block(4,10,8,35:14)
Block(4,11,8,5:2)
Block(4,12,8,5:5)
Block(4,13,8,5:2)
Block(4,14,8,5:5)
Block(4,15,7,50:4)
Block(4,15,8,5:2)
Block(4,16,8,5:2)
Block(4,17,-6,136:3)
Block(4,17,-5,136:1)
Block(4,17,-4,136:1)
Block(4,17,-3,136:1)
Block(4,17,-2,136:1)
Block(4,17,-1,136:1)
Block(4,17,0,136:1)
Block(4,17,1,136:1)
Block(4,17,2,136:2)
Block(4,17,4,136:1)
Block(4,17,5,136:1)
Block(4,17,6,136:1)
Block(4,17,7,136:1)
Block(4,17,8,136:1)
Block(4,18,-7,126:3)
Block(4,18,3,126:3)
Block(5,0,-7,2)
Block(5,0,-6,2)
Block(5,0,-5,2)
Block(5,0,-4,2)
Block(5,0,-3,2)
Block(5,0,-2,2)
Block(5,0,-1,2)
Block(5,0,0,2)
Block(5,0,1,2)
Block(5,0,2,2)
Block(5,0,3,2)
Block(5,0,4,2)
Block(5,0,5,2)
Block(5,0,6,2)
Block(5,0,7,2)
Block(5,0,8,2)
Block(5,9,-7,5:5)
Block(5,9,-6,5:5)
Block(5,9,-5,5:5)
Block(5,9,-4,5:5)
Block(5,9,-3,5:5)
Block(5,9,-2,5:5)
Block(5,9,-1,5:5)
Block(5,9,0,5:5)
Block(5,9,1,5:5)
Block(5,9,2,5:5)
Block(5,9,3,5:5)
Block(5,9,4,5:5)
Block(5,9,5,5:5)
Block(5,9,6,5:5)
Block(5,9,7,5:5)
Block(5,9,8,5:5)
Block(5,10,8,35:14)
Block(5,11,8,5:2)
Block(5,12,8,5:2)
Block(5,13,8,5:5)
Block(5,14,8,5:5)
Block(5,15,-7,50:2)
Block(5,15,-6,50:2)
Block(5,15,-5,50:2)
Block(5,15,1,50:2)
Block(5,15,2,50:2)
Block(5,15,3,50:2)
Block(5,15,4,50:2)
Block(5,15,5,50:2)
Block(5,15,7,50:4)
Block(5,15,8,5:2)
Block(5,16,-5,136:3)
Block(5,16,-4,136:1)
Block(5,16,-3,136:1)
Block(5,16,-2,136:1)
Block(5,16,-1,136:1)
Block(5,16,0,136:1)
Block(5,16,1,136:1)
Block(5,16,5,136:1)
Block(5,16,6,136:1)
Block(5,16,7,136:1)
Block(5,16,8,136:1)
Block(5,17,-6,136:3)
Block(5,17,2,136:2)
Block(5,17,4,136:3)
Block(5,18,-7,126:3)
Block(5,18,3,126:3)
Block(6,0,-7,2)
Block(6,0,-6,2)
Block(6,0,-5,2)
Block(6,0,-4,2)
Block(6,0,-3,2)
Block(6,0,-2,2)
Block(6,0,-1,2)
Block(6,0,0,2)
Block(6,0,1,2)
Block(6,0,2,2)
Block(6,0,3,2)
Block(6,0,4,2)
Block(6,0,5,2)
Block(6,0,6,2)
Block(6,0,7,2)
Block(6,0,8,2)
Block(6,1,-2,113)
Block(6,1,8,113)
Block(6,2,-2,113)
Block(6,2,8,113)
Block(6,3,-2,113)
Block(6,3,8,113)
Block(6,4,-2,113)
Block(6,4,8,113)
Block(6,5,-2,113)
Block(6,5,8,113)
Block(6,6,-2,113)
Block(6,6,8,113)
Block(6,7,-2,113)
Block(6,7,8,113)
Block(6,8,-2,113)
Block(6,8,8,113)
Block(6,9,-7,5:5)
Block(6,9,-6,5:5)
Block(6,9,-5,5:5)
Block(6,9,-4,5:5)
Block(6,9,-3,5:5)
Block(6,9,-2,5:5)
Block(6,9,-1,5:5)
Block(6,9,0,5:5)
Block(6,9,1,5:5)
Block(6,9,2,5:5)
Block(6,9,3,5:5)
Block(6,9,4,5:5)
Block(6,9,5,5:5)
Block(6,9,6,5:5)
Block(6,9,7,5:5)
Block(6,9,8,5:5)
Block(6,10,-7,35:14)
Block(6,10,-6,35:14)
Block(6,10,-5,35:14)
Block(6,10,-4,35:14)
Block(6,10,-3,35:14)
Block(6,10,-2,35:14)
Block(6,10,-1,35:14)
Block(6,10,0,35:14)
Block(6,10,1,35:14)
Block(6,10,2,35:14)
Block(6,10,3,35:14)
Block(6,10,4,35:14)
Block(6,10,5,35:14)
Block(6,10,6,35:14)
Block(6,10,7,35:14)
Block(6,10,8,35:14)
Block(6,11,-7,102)
Block(6,11,-6,102)
Block(6,11,-5,5:5)
Block(6,11,-4,5:2)
Block(6,11,-3,5:2)
Block(6,11,-2,5:5)
Block(6,11,-1,5:2)
Block(6,11,0,5:2)
Block(6,11,1,5:5)
Block(6,11,2,102)
Block(6,11,3,102)
Block(6,11,4,102)
Block(6,11,5,5:5)
Block(6,11,6,5:2)
Block(6,11,7,5:2)
Block(6,11,8,5:5)
Block(6,12,-7,102)
Block(6,12,-6,102)
Block(6,12,-5,5:2)
Block(6,12,-4,5:5)
Block(6,12,-3,5:2)
Block(6,12,-2,5:5)
Block(6,12,-1,5:2)
Block(6,12,0,5:5)
Block(6,12,1,5:2)
Block(6,12,2,102)
Block(6,12,3,102)
Block(6,12,4,102)
Block(6,12,5,5:2)
Block(6,12,6,5:5)
Block(6,12,7,5:2)
Block(6,12,8,5:5)
Block(6,13,-7,102)
Block(6,13,-6,102)
Block(6,13,-5,5:2)
Block(6,13,-4,5:2)
Block(6,13,-3,5:5)
Block(6,13,-2,5:5)
Block(6,13,-1,5:5)
Block(6,13,0,5:2)
Block(6,13,1,5:2)
Block(6,13,2,102)
Block(6,13,3,102)
Block(6,13,4,102)
Block(6,13,5,5:2)
Block(6,13,6,5:2)
Block(6,13,7,5:5)
Block(6,13,8,5:5)
Block(6,14,-7,5:5)
Block(6,14,-6,5:5)
Block(6,14,-5,5:5)
Block(6,14,-4,5:5)
Block(6,14,-3,5:5)
Block(6,14,-2,5:5)
Block(6,14,-1,5:5)
Block(6,14,0,5:5)
Block(6,14,1,5:5)
Block(6,14,2,5:5)
Block(6,14,3,5:5)
Block(6,14,4,5:5)
Block(6,14,5,5:5)
Block(6,14,6,5:5)
Block(6,14,7,5:5)
Block(6,14,8,5:5)
Block(6,15,-7,5:2)
Block(6,15,-6,5:2)
Block(6,15,-5,5:2)
Block(6,15,-4,136:1)
Block(6,15,-3,136:1)
Block(6,15,-2,136:1)
Block(6,15,-1,136:1)
Block(6,15,0,136:1)
Block(6,15,1,5:2)
Block(6,15,2,5:2)
Block(6,15,3,5:2)
Block(6,15,4,5:2)
Block(6,15,5,5:2)
Block(6,15,6,136:1)
Block(6,15,7,136:1)
Block(6,15,8,136:1)
Block(6,16,-7,5:2)
Block(6,16,-6,5:2)
Block(6,16,-5,136:3)
Block(6,16,1,136:2)
Block(6,16,2,5:2)
Block(6,16,3,5:2)
Block(6,16,4,5:2)
Block(6,16,5,136:3)
Block(6,17,-7,5:2)
Block(6,17,-6,136:3)
Block(6,17,2,136:2)
Block(6,17,3,5:2)
Block(6,17,4,136:3)
Block(6,18,-7,126:3)
Block(6,18,3,126:3)
Block(7,0,-7,2)
Block(7,0,-6,2)
Block(7,0,-5,2)
Block(7,0,-4,2)
Block(7,0,-3,2)
Block(7,0,-2,2)
Block(7,0,-1,2)
Block(7,0,0,2)
Block(7,0,1,2)
Block(7,0,2,2)
Block(7,0,3,2)
Block(7,0,4,2)
Block(7,0,5,2)
Block(7,0,6,2)
Block(7,0,7,2)
Block(7,0,8,2)

Branch(16,0,0,true,market-age-of-empiresC1R1,NORTH,100,0)
Branch(0,0,16,true,market-age-of-empiresC0R2,NORTH,100,0)
