

BranchFrequency: 10

BranchFrequencyGroup: CanOverride:0

CanOverride: true

SmoothRadius: -1

OverrideChildSettings: false

ReplaceAbove:
ReplaceBelow:

MustBeInside: VillageGeneratorStructurePlaceHolder, VillageGeneratorStructuresDelay, VillageGeneratorStructuresDelay2, VillageGeneratorStructuresDelay3, VillageGeneratorStructuresDelay4, VillageGeneratorStructuresDelay5, VillageGeneratorStructuresDelay6, VillageGeneratorStructuresDelay7, VillageGeneratorStructuresDelay8, VillageGeneratorStructuresDelay9, VillageGeneratorStructuresDelay10

Block(-8,0,-7,2)
Block(-8,0,-6,2)
Block(-8,0,-5,2)
Block(-8,0,-4,3:1)
Block(-8,0,-3,2)
Block(-8,0,-2,2)
Block(-8,0,-1,2)
Block(-8,0,0,3:1)
Block(-8,0,1,3:1)
Block(-8,1,-3,164)
Block(-8,1,-2,31:1)
Block(-8,1,-1,31:1)
Block(-8,6,-3,124)
Block(-8,7,-3,178:15)
Block(-7,0,-7,2)
Block(-7,0,-6,2)
Block(-7,0,-5,3:1)
Block(-7,0,-4,3:1)
Block(-7,0,-3,2)
Block(-7,0,-2,2)
Block(-7,0,-1,3:1)
Block(-7,0,0,3:1)
Block(-7,0,1,2)
Block(-7,1,-3,164:5)
Block(-7,1,-2,31:1)
Block(-7,2,-3,164)
Block(-7,5,-4,164:2)
Block(-7,5,-3,164)
Block(-7,5,-2,164:3)
Block(-7,6,-3,191)
Block(-6,0,-7,2)
Block(-6,0,-6,2)
Block(-6,0,-5,3:1)
Block(-6,0,-4,2)
Block(-6,0,-3,2)
Block(-6,0,-2,2)
Block(-6,0,-1,3:1)
Block(-6,0,0,2)
Block(-6,0,1,2)
Block(-6,1,-3,31:1)
Block(-6,1,-2,31:1)
Block(-6,2,-6,126:13)
Block(-6,2,-5,126:13)
Block(-6,2,-4,126:13)
Block(-6,2,-3,164:5)
Block(-6,2,-2,126:13)
Block(-6,2,-1,126:13)
Block(-6,2,0,126:13)
Block(-6,3,-5,191)
Block(-6,3,-4,5)
Block(-6,3,-2,5)
Block(-6,3,-1,191)
Block(-6,4,-5,191)
Block(-6,4,-4,5)
Block(-6,4,-2,5)
Block(-6,4,-1,191)
Block(-6,5,-4,53:2)
Block(-6,5,-3,5)
Block(-6,5,-2,53:3)
Block(-6,6,-3,191)
Block(-5,0,-7,2)
Block(-5,0,-6,2)
Block(-5,0,-5,3:1)
Block(-5,0,-4,2)
Block(-5,0,-3,2)
Block(-5,0,-2,2)
Block(-5,0,-1,3:1)
Block(-5,0,0,2)
Block(-5,0,1,2)
Block(-5,1,-5,53:4)
Block(-5,1,-3,31:1)
Block(-5,1,-2,31:1)
Block(-5,1,-1,53:4)
Block(-5,1,0,31:1)
Block(-5,2,-5,53)
Block(-5,2,-4,126:13)
Block(-5,2,-3,126:13)
Block(-5,2,-2,126:13)
Block(-5,2,-1,53)
Block(-5,3,-6,164:2)
Block(-5,3,-5,125:5)
Block(-5,3,-4,126:8)
Block(-5,3,-2,126:8)
Block(-5,3,-1,125:5)
Block(-5,3,0,164:3)
Block(-5,4,-5,5)
Block(-5,4,-4,54:3,1-Chest.nbt)
Block(-5,4,-2,54:2,2-Chest.nbt)
Block(-5,4,-1,5)
Block(-5,5,-5,53:2)
Block(-5,5,-4,53:7)
Block(-5,5,-3,50:1)
Block(-5,5,-2,53:6)
Block(-5,5,-1,53:3)
Block(-5,6,-4,126)
Block(-5,6,-3,125)
Block(-5,6,-2,126)
Block(-4,0,-7,2)
Block(-4,0,-6,2)
Block(-4,0,-5,2)
Block(-4,0,-4,2)
Block(-4,0,-3,2)
Block(-4,0,-2,2)
Block(-4,0,-1,2)
Block(-4,0,0,2)
Block(-4,0,1,2)
Block(-4,1,-5,53:5)
Block(-4,1,-3,31:1)
Block(-4,1,-2,31:1)
Block(-4,1,-1,53:5)
Block(-4,1,1,31:1)
Block(-4,2,-5,53:1)
Block(-4,2,-4,126:13)
Block(-4,2,-3,126:13)
Block(-4,2,-2,126:13)
Block(-4,2,-1,53:1)
Block(-4,3,-6,164:2)
Block(-4,3,-5,125:5)
Block(-4,3,-4,126:8)
Block(-4,3,-2,126:8)
Block(-4,3,-1,125:5)
Block(-4,3,0,164:3)
Block(-4,4,-5,5)
Block(-4,4,-4,54:3,3-Chest.nbt)
Block(-4,4,-2,54:2,4-Chest.nbt)
Block(-4,4,-1,5)
Block(-4,5,-5,53:2)
Block(-4,5,-4,53:7)
Block(-4,5,-2,53:6)
Block(-4,5,-1,53:3)
Block(-4,6,-4,126)
Block(-4,6,-3,126:8)
Block(-4,6,-2,126)
Block(-3,0,-7,2)
Block(-3,0,-6,2)
Block(-3,0,-5,3:1)
Block(-3,0,-4,3:1)
Block(-3,0,-3,2)
Block(-3,0,-2,2)
Block(-3,0,-1,3:1)
Block(-3,0,0,3:1)
Block(-3,0,1,2)
Block(-3,1,-3,38:8)
Block(-3,1,-2,31:1)
Block(-3,2,-6,126:13)
Block(-3,2,-5,164:5)
Block(-3,2,-4,126:13)
Block(-3,2,-3,126:13)
Block(-3,2,-2,126:13)
Block(-3,2,-1,164:5)
Block(-3,2,0,126:13)
Block(-3,3,-5,5)
Block(-3,3,-4,171:14)
Block(-3,3,-3,171:14)
Block(-3,3,-2,171:14)
Block(-3,3,-1,5)
Block(-3,4,-5,164:1)
Block(-3,4,-1,164:1)
Block(-3,5,-5,164:5)
Block(-3,5,-4,177:3,5-Banner.nbt)
Block(-3,5,-2,177:2,6-Banner.nbt)
Block(-3,5,-1,164:5)
Block(-3,6,-4,126)
Block(-3,6,-3,126:8)
Block(-3,6,-2,126)
Block(-2,0,-7,2)
Block(-2,0,-6,3)
Block(-2,0,-5,3:1)
Block(-2,0,-4,2)
Block(-2,0,-3,2)
Block(-2,0,-2,2)
Block(-2,0,-1,3:1)
Block(-2,0,0,3)
Block(-2,0,1,2)
Block(-2,1,-7,53:2)
Block(-2,1,-6,53:7)
Block(-2,1,-3,31:1)
Block(-2,1,-2,31:1)
Block(-2,1,0,53:6)
Block(-2,1,1,53:3)
Block(-2,2,-6,53:2)
Block(-2,2,-5,126:13)
Block(-2,2,-4,126:13)
Block(-2,2,-3,126:13)
Block(-2,2,-2,126:13)
Block(-2,2,-1,126:13)
Block(-2,2,0,53:3)
Block(-2,3,-6,68:2,7-Sign.nbt)
Block(-2,3,-5,5)
Block(-2,3,-4,171:14)
Block(-2,3,-3,171:14)
Block(-2,3,-2,171:14)
Block(-2,3,-1,5)
Block(-2,3,0,68:3,8-Sign.nbt)
Block(-2,6,-5,126:5)
Block(-2,6,-4,126:5)
Block(-2,6,-3,126:13)
Block(-2,6,-2,126:5)
Block(-2,6,-1,126:5)
Block(-1,0,-7,2)
Block(-1,0,-6,2)
Block(-1,0,-5,3:1)
Block(-1,0,-4,2)
Block(-1,0,-3,2)
Block(-1,0,-2,2)
Block(-1,0,-1,3:1)
Block(-1,0,0,2)
Block(-1,0,1,2)
Block(-1,1,-3,31:1)
Block(-1,1,-2,31:1)
Block(-1,1,1,31:1)
Block(-1,2,-6,126:13)
Block(-1,2,-5,164:4)
Block(-1,2,-4,126:13)
Block(-1,2,-3,126:13)
Block(-1,2,-2,126:13)
Block(-1,2,-1,164:4)
Block(-1,2,0,126:13)
Block(-1,3,-5,5)
Block(-1,3,-4,171:14)
Block(-1,3,-3,171:14)
Block(-1,3,-2,171:14)
Block(-1,3,-1,5)
Block(-1,4,-5,164)
Block(-1,4,-1,164)
Block(-1,5,-5,164:4)
Block(-1,5,-4,177:3,9-Banner.nbt)
Block(-1,5,-2,177:2,10-Banner.nbt)
Block(-1,5,-1,164:4)
Block(-1,6,-4,126)
Block(-1,6,-3,126:8)
Block(-1,6,-2,126)
Block(0,0,-7,2)
Block(0,0,-6,2)
Block(0,0,-4,3:1)
Block(0,0,-3,2)
Block(0,0,-2,2)
Block(0,0,-1,3:1)
Block(0,0,0,2)
Block(0,0,1,2)
Block(0,1,-5,53:4)
Block(0,1,-3,31:1)
Block(0,1,-2,31:1)
Block(0,1,-1,53:4)
Block(0,1,0,38:8)
Block(0,1,1,31:1)
Block(0,2,-5,53)
Block(0,2,-4,126:13)
Block(0,2,-3,126:13)
Block(0,2,-2,126:13)
Block(0,2,-1,53)
Block(0,3,-6,164:2)
Block(0,3,-5,125:5)
Block(0,3,-1,125:5)
Block(0,3,0,164:3)
Block(0,4,-5,5)
Block(0,4,-1,5)
Block(0,5,-5,53:2)
Block(0,5,-4,53:7)
Block(0,5,-2,53:6)
Block(0,5,-1,53:3)
Block(0,6,-4,126)
Block(0,6,-3,126:8)
Block(0,6,-2,126)
Block(1,0,-7,2)
Block(1,0,-6,2)
Block(1,0,-5,2)
Block(1,0,-4,2)
Block(1,0,-3,2)
Block(1,0,-2,2)
Block(1,0,-1,2)
Block(1,0,0,2)
Block(1,0,1,3:1)
Block(1,1,-6,31:1)
Block(1,1,-5,53:5)
Block(1,1,-4,31:1)
Block(1,1,-3,31:1)
Block(1,1,-2,31:1)
Block(1,1,-1,53:5)
Block(1,2,-5,53:1)
Block(1,2,-4,126:13)
Block(1,2,-3,126:13)
Block(1,2,-2,126:13)
Block(1,2,-1,53:1)
Block(1,3,-6,164:2)
Block(1,3,-5,125:5)
Block(1,3,-4,26:10)
Block(1,3,-3,26:2)
Block(1,3,-2,58)
Block(1,3,-1,125:5)
Block(1,3,0,164:3)
Block(1,4,-5,5)
Block(1,4,-4,50:3)
Block(1,4,-2,50:4)
Block(1,4,-1,5)
Block(1,5,-5,53:2)
Block(1,5,-4,53:7)
Block(1,5,-2,53:6)
Block(1,5,-1,53:3)
Block(1,6,-4,126)
Block(1,6,-3,126:8)
Block(1,6,-2,126)
Block(2,0,-7,2)
Block(2,0,-6,2)
Block(2,0,-5,2)
Block(2,0,-4,2)
Block(2,0,-3,2)
Block(2,0,-2,2)
Block(2,0,-1,2)
Block(2,0,0,2)
Block(2,0,1,2)
Block(2,1,-6,31:1)
Block(2,1,-5,31:1)
Block(2,1,-4,31:1)
Block(2,1,-3,31:1)
Block(2,1,-2,31:1)
Block(2,1,-1,31:1)
Block(2,2,-6,126:13)
Block(2,2,-5,126:13)
Block(2,2,-4,126:13)
Block(2,2,-3,164:4)
Block(2,2,-2,126:13)
Block(2,2,-1,126:13)
Block(2,2,0,126:13)
Block(2,3,-5,191)
Block(2,3,-4,5)
Block(2,3,-3,5)
Block(2,3,-2,5)
Block(2,3,-1,191)
Block(2,4,-5,191)
Block(2,4,-4,5)
Block(2,4,-3,102)
Block(2,4,-2,5)
Block(2,4,-1,191)
Block(2,5,-4,53:2)
Block(2,5,-3,53:5)
Block(2,5,-2,53:3)
Block(2,6,-3,53:1)
Block(3,0,-7,2)
Block(3,0,-6,2)
Block(3,0,-5,2)
Block(3,0,-4,2)
Block(3,0,-3,2)
Block(3,0,-2,2)
Block(3,0,-1,2)
Block(3,0,0,2)
Block(3,0,1,2)
Block(3,1,-4,31:1)
Block(3,1,-3,31:1)
Block(3,1,-2,38:8)
Block(3,1,-1,31:1)
Block(3,1,0,31:1)
Block(3,1,1,31:1)
Block(3,2,-3,162:5)
Block(4,0,-7,2)
Block(4,0,-6,2)
Block(4,0,-5,2)
Block(4,0,-4,2)
Block(4,0,-3,2)
Block(4,0,-2,2)
Block(4,0,-1,2)
Block(4,0,0,2)
Block(4,0,1,3)
Block(4,1,-6,31:1)
Block(4,1,-4,31:1)
Block(4,1,-3,164:4)
Block(4,1,-2,31:1)
Block(4,1,-1,31:1)
Block(4,1,0,31:1)
Block(4,2,-3,162:5)
Block(5,0,-7,2)
Block(5,0,-6,2)
Block(5,0,-5,2)
Block(5,0,-4,2)
Block(5,0,-3,3)
Block(5,0,-2,2)
Block(5,0,-1,2)
Block(5,0,0,2)
Block(5,0,1,2)
Block(5,1,-5,31:1)
Block(5,1,-4,31:1)
Block(5,1,-3,162:5)
Block(5,1,-2,31:1)
Block(5,1,-1,31:1)
Block(5,1,0,31:1)
Block(5,2,-3,164:1)
Block(6,0,-7,2)
Block(6,0,-6,2)
Block(6,0,-5,2)
Block(6,0,-4,2)
Block(6,0,-3,3)
Block(6,0,-2,2)
Block(6,0,-1,2)
Block(6,0,0,2)
Block(6,0,1,3:1)
Block(6,1,-6,31:1)
Block(6,1,-5,31:1)
Block(6,1,-4,77:4)
Block(6,1,-3,162:5)
Block(6,1,-2,77:3)
Block(6,1,-1,31:1)
Block(6,2,-3,77:5)
Block(7,0,-7,2)
Block(7,0,-6,2)
Block(7,0,-5,2)
Block(7,0,-4,2)
Block(7,0,-3,2)
Block(7,0,-2,2)
Block(7,0,-1,2)
Block(7,0,0,2)
Block(7,0,1,2)
Block(7,1,-6,31:1)
Block(7,1,-5,31:1)
Block(7,1,-4,31:1)
Block(7,1,-3,77:1)
Block(7,1,-2,37)
Block(7,1,-1,31:1)
