#######################################################################
# +-----------------------------------------------------------------+ #
# |                            BO3 object                           | #
# +-----------------------------------------------------------------+ #
#######################################################################

# This BO3 is made for use with MCW and OTG+.
# The descriptions in this file are only accurate for MCW and OTG+.
# For TerrainControl and OTG these descriptions are only accurate if the BO3 is used as a CustomObject.
# MCW and OTG+ completely reimplemented CustomStructure, check the MCW/OTG+ documentation for more information.

# This is the config file of a custom object.
# If you add this object correctly to your BiomeConfigs, it will spawn in the world.

# This is the creator of this BO3 object
Author: Unknown

# A short description of this BO3 object
Description: No description

# The BO3 version, don't change this! It can be used by external applications to do a version check.
Version: 4

# The settings mode, WriteAll, WriteWithoutComments or WriteDisable. See WorldConfig.
SettingsMode: WriteDisable

#######################################################################
# +-----------------------------------------------------------------+ #
# |                          Main settings                          | #
# +-----------------------------------------------------------------+ #
#######################################################################

IsOTGPlus: true
# This settings is currently unavailable for MCW/OTG+.
Tree: false

# The rarity of the BO3 from 0 to 100. Each spawn attempt has rarity% chance to succeed when using the CustomObject(...) resource.
# Ignored by MCW/OTG+ for Tree(..), Sapling(..) and CustomStructure(..).
Rarity: 100

# Minimum distance in chunks between structures with the same filename.
Frequency: 0

# This settings is currently unavailable for MCW/OTG+, you can easily work around this though by creating a master bo3 without blocks that
# has the real starting BO3 as a branch.
# You can then duplicate the master BO3 3 times and give each copy's branch a different rotation.
RotateRandomly: false

# The spawn height of the BO3 - randomY or highestBlock.
SpawnHeight: highestBlock

# The height limits for the BO3. Can be combined with randomY to spawn the BO3 at a random height
# between MinHeight and MaxHeight. Can be combined with highestBlock to make sure that the BO3 spawns
# only between MinHeight and MaxHeight.
MinHeight: 0

MaxHeight: 256

# This settings is disabled for MCW/OTG+.
ExcludedBiomes: All

# To optimise this BO3 for faster loading times you can use Notepad++ to find/replace comments and abbreviate things.
# Notepad++ find/replace with regex:
# Find: ^[#;].* replace to nothing removes all lines starting with # 
# Find: ^\s*$ replace to nothing removes most empty lines 
# Notepad++ find/replace without regex:
# *Warning: This will only work for OTG 1.10.2 v21 / OTG 1.11.2 v6 or higher. B( is not recognised by lower versions.
# Find: Block( replace to B(

#######################################################################
# +-----------------------------------------------------------------+ #
# |                      Source block settings                      | #
# +-----------------------------------------------------------------+ #
#######################################################################

# This settings is disabled for MCW/OTG+.
SourceBlocks: AIR

# This settings is disabled for MCW/OTG+.
MaxPercentageOutsideSourceBlock: 100

# This settings is disabled for MCW/OTG+.
OutsideSourceBlock: placeAnyway

# MineCraft Worlds mod settings #
# NOTE: you can delete any of these settings if you're not using them, the default values will automatically be used. #

# Copies the blocks and branches of an existing BO3 into this BO3.
#InheritBO3:

# Defaults to true, if true and this is the root BO3 for this branching structure then this BO3's smoothing and height settings are used for all its children (branches).
#OverrideChildSettings: true

# If this is set to true then this BO3 can spawn as a branch on top of or inside an existing BO3/branch (only within the same customstructure).
#CanOverride: false

# If this is set to true then this BO3 can only spawn underneath an existing BO3. Used to make sure that dungeons only appear underneath buildings
#MustBeBelowOther: false

# A comma-seperated list of BO3s, this BO3 must touch one of these when spawned or it will not be able to spawn.
#MustBeInside: 

# A comma-seperated list of BO3s, this BO3 cannot touch one of these when spawned, if it does it will not be able to spawn.
#CannotBeInside: 

# Defaults to true. Set to false if the BO3 is not allowed to spawn on a water block
#CanSpawnOnWater: true

# Defaults to false. Set to true if the BO3 is allowed to spawn only on a water block
#SpawnOnWaterOnly: false

# Defaults to false. Set to true if the BO3 and its smoothing area should ignore water when looking for the highest block to spawn on. Defaults to false (things spawn on top of water)
#SpawnUnderWater: false

# Defaults to false. Set to true if the BO3 should spawn at water level
#SpawnAtWaterLevel: false


# Spawns the BO3 at a Y offset of this value. Handy when using highestBlock for lowering BO3s into the surrounding terrain when there are layers of ground included in the BO3, also handy when using SpawnAtWaterLevel to lower objects like ships into the water.
#HeightOffset: 0

# If set to true removes all AIR blocks from the BO3 so that it can be flooded or buried.
#RemoveAir: true

# Replaces all the non-air blocks that are above this BO3 or its smoothing area with the given block material (should be WATER or AIR or NONE), also applies to smoothing areas although it intentionally leaves some of the terrain above them intact. WATER can be used in combination with SpawnUnderWater to fill any air blocks underneath waterlevel with water (and any above waterlevel with air).
#ReplaceAbove: AIR

# Replaces all air blocks underneath the BO3 (but not its smoothing area) with the designated material until a solid block is found.
#ReplaceBelow:

# Defaults to true. If set to true then every block in the BO3 of the materials defined in ReplaceWithGroundBlock or ReplaceWithSurfaceBlock will be replaced by the GroundBlock or SurfaceBlock materials configured for the biome the block is spawned in.
#ReplaceWithBiomeBlocks: true

# Defaults to DIRT, Replaces all the blocks of the given material in the BO3 with the GroundBlock configured for the biome it spawns in
#ReplaceWithGroundBlock: DIRT

# Defaults to GRASS, Replaces all the blocks of the given material in the BO3 with the SurfaceBlock configured for the biome it spawns in
#ReplaceWithSurfaceBlock: GRASS


# Makes the terrain around the BO3 slope gradually towards the edges of the BO3. The given value is the distance in blocks around the BO3 from where the slope should start and can be any positive number.
#SmoothRadius: 0

# Moves the smoothing area up or down relative to the BO3 (at the points where the smoothing area is connected to the BO3). Handy when using SmoothStartTop: false and the BO3 has some layers of ground included, in that case we can set the HeightOffset to a negative value to lower the BO3 into the ground and we can set the SmoothHeightOffset to a positive value to move the smoothing area starting height up
#SmoothHeightOffset: 0

# Should the smoothing area be attached at the bottom or the top of the edges of the BO3? Defaults to false (bottom). Using this setting can make things slower so try to avoid using it and use SmoothHeightOffset instead if for instance you have a BO3 with some ground layers included. The only reason you should need to use this setting is if you have a BO3 with edges that have an irregular height (like some hills).
#SmoothStartTop: false

# Should the smoothing area attach itself to "log" block or ignore them? Defaults to false (ignore logs).
#SmoothStartWood: false

# The block used for smoothing area surface blocks, defaults to biome SurfaceBlock
#SmoothingSurfaceBlock:

# The block used for smoothing area ground blocks, defaults to biome GroundBlock
#SmoothingGroundBlock:


# Define groups that this BO3 belongs to along with a minimum range in chunks that this BO3 must have between it and any other members of this group if it is to be allowed to spawn. Syntax is "GroupName:Frequency, GoupName2:Frequency2" etc so for example a BO3 that belongs to 3 groups: "BO3Group: Ships:10, Vehicles:5, FloatingThings:3"
#BO3Group:

# Defaults to false. Set to true if this BO3 should spawn at the player spawn point. When the server starts the spawn point is determined and the BO3's for the biome it is in are loaded, one of these BO3s that has IsSpawnPoint set to true (if any) is selected randomly and is spawned at the spawn point regardless of its rarity (so even Rarity:0, IsSpawnPoint: true BO3's can get spawned as the spawn point!).
#IsSpawnPoint: false

# Defaults to 8, if SpawnPointY > -1 and this BO3 is spawned at the spawn point then the player spawn point is placed within this BO3 at x y and z offsets (spawnPointX, spawnPointY, spawnPointZ) relative to x0y0z0 in this BO3.
#SpawnPointX: 8

# Defaults to highestBlock, if this is defined and this BO3 is spawned at the spawn point then the player spawn point is placed at a y offset of this value relative to y = 0 in this BO3.)
#SpawnPointY: -1

# Defaults to 7, if spawnPointY > -1 and this BO3 is spawned at the spawn point then the player spawn point is placed within this BO3 at a x y and z offsets (spawnPointX, spawnPointY, spawnPointZ) relative to x0y0z0 in this BO3.
#SpawnPointZ: 7

#######################################################################
# +-----------------------------------------------------------------+ #
# |                              Blocks                             | #
# +-----------------------------------------------------------------+ #
#######################################################################

# All the blocks used in the BO3 are listed here. Possible blocks:
# Block(x,y,z,id[.data][,nbtfile.nbt) or B(x,y,z,id[.data][,nbtfile.nbt)
# RandomBlock(x,y,z,id[:data][,nbtfile.nbt],chance[,id[:data][,nbtfile.nbt],chance[,...]])
# So RandomBlock(0,0,0,CHEST,chest.nbt,50,CHEST,anotherchest.nbt,100) will spawn a chest at
# the BO3 origin, and give it a 50% chance to have the contents of chest.nbt, or, if that
# fails, a 100% percent chance to have the contents of anotherchest.nbt.

Block(-8,0,-7,159:15)
Block(-8,0,-6,251:15)
Block(-8,0,-5,159:15)
Block(-8,0,-4,159:15)
Block(-8,0,-3,251:15)
Block(-8,0,-2,251:15)
Block(-8,0,-1,251:15)
Block(-8,0,0,159:15)
Block(-8,0,1,251:15)
Block(-8,0,2,251:15)
Block(-8,0,3,251:15)
Block(-8,0,4,159:15)
Block(-8,0,5,159:15)
Block(-8,0,6,159:15)
Block(-8,0,7,159:15)
Block(-8,0,8,251:15)
Block(-8,1,-7,159:15)
Block(-8,1,-6,159:15)
Block(-8,1,-5,159:15)
Block(-8,1,-4,251:15)
Block(-8,1,-3,159:15)
Block(-8,1,-2,159:15)
Block(-8,1,-1,251:15)
Block(-8,1,0,251:15)
Block(-8,1,1,251:15)
Block(-8,1,2,251:15)
Block(-8,1,3,251:15)
Block(-8,1,4,251:15)
Block(-8,1,5,159:15)
Block(-8,1,6,251:15)
Block(-8,1,7,251:15)
Block(-8,1,8,159:15)
Block(-8,2,-7,159:15)
Block(-8,2,-6,159:15)
Block(-8,2,-5,159:15)
Block(-8,2,-4,159:15)
Block(-8,2,-3,159:15)
Block(-8,2,-2,159:15)
Block(-8,2,-1,159:15)
Block(-8,2,0,251:15)
Block(-8,2,1,159:15)
Block(-8,2,2,251:15)
Block(-8,2,3,159:15)
Block(-8,2,4,159:15)
Block(-8,2,5,159:15)
Block(-8,2,6,251:15)
Block(-8,2,7,159:15)
Block(-8,2,8,251:15)
Block(-8,3,-7,159:15)
Block(-8,3,-6,251:15)
Block(-8,3,-5,159:15)
Block(-8,3,-4,251:15)
Block(-8,3,-3,251:15)
Block(-8,3,-2,159:15)
Block(-8,3,-1,251:15)
Block(-8,3,0,251:15)
Block(-8,3,1,251:15)
Block(-8,3,2,159:15)
Block(-8,3,3,159:15)
Block(-8,3,4,159:15)
Block(-8,3,5,251:15)
Block(-8,3,6,251:15)
Block(-8,3,7,251:15)
Block(-8,3,8,159:15)
Block(-8,4,-7,251:15)
Block(-8,4,-6,159:15)
Block(-8,4,-5,159:15)
Block(-8,4,-4,159:15)
Block(-8,4,-3,159:15)
Block(-8,4,-2,251:15)
Block(-8,4,-1,159:15)
Block(-8,4,0,159:15)
Block(-8,4,1,251:15)
Block(-8,4,2,251:15)
Block(-8,4,3,159:15)
Block(-8,4,4,159:15)
Block(-8,4,5,251:15)
Block(-8,4,6,159:15)
Block(-8,4,7,159:15)
Block(-8,4,8,159:15)
Block(-8,5,-7,251:15)
Block(-8,5,-6,251:15)
Block(-8,5,-5,251:15)
Block(-8,5,-4,251:15)
Block(-8,5,-3,251:15)
Block(-8,5,-2,159:15)
Block(-8,5,-1,251:15)
Block(-8,5,0,251:15)
Block(-8,5,1,159:15)
Block(-8,5,2,251:15)
Block(-8,5,3,159:15)
Block(-8,5,4,251:15)
Block(-8,5,5,159:15)
Block(-8,5,6,159:15)
Block(-8,5,7,251:15)
Block(-8,5,8,159:15)
Block(-8,6,-7,159:15)
Block(-8,6,-6,251:15)
Block(-8,6,-5,159:15)
Block(-8,6,-4,251:15)
Block(-8,6,-3,159:15)
Block(-8,6,-2,251:15)
Block(-8,6,-1,251:15)
Block(-8,6,0,251:15)
Block(-8,6,1,159:15)
Block(-8,6,2,251:15)
Block(-8,6,3,251:15)
Block(-8,6,4,159:15)
Block(-8,6,5,251:15)
Block(-8,6,6,251:15)
Block(-8,6,7,251:15)
Block(-8,6,8,251:15)
Block(-8,7,-7,159:15)
Block(-8,7,-6,251:15)
Block(-8,7,-5,159:15)
Block(-8,7,-4,251:15)
Block(-8,7,-3,251:15)
Block(-8,7,-2,251:15)
Block(-8,7,-1,159:15)
Block(-8,7,0,251:15)
Block(-8,7,1,159:15)
Block(-8,7,2,251:15)
Block(-8,7,3,251:15)
Block(-8,7,4,251:15)
Block(-8,7,5,251:15)
Block(-8,7,6,159:15)
Block(-8,7,7,159:15)
Block(-8,7,8,159:15)
Block(-8,8,-7,251:15)
Block(-8,8,-6,251:15)
Block(-8,8,-5,159:15)
Block(-8,8,-4,251:15)
Block(-8,8,-3,159:15)
Block(-8,8,-2,251:15)
Block(-8,8,-1,251:15)
Block(-8,8,0,251:15)
Block(-8,8,1,251:15)
Block(-8,8,2,251:15)
Block(-8,8,3,251:15)
Block(-8,8,4,159:15)
Block(-8,8,5,159:15)
Block(-8,8,6,159:15)
Block(-8,8,7,159:15)
Block(-8,8,8,159:15)
Block(-8,9,-7,159:15)
Block(-8,9,-6,251:15)
Block(-8,9,-5,159:15)
Block(-8,9,-4,251:15)
Block(-8,9,-3,159:15)
Block(-8,9,-2,159:15)
Block(-8,9,-1,251:15)
Block(-8,9,0,159:15)
Block(-8,9,1,251:15)
Block(-8,9,2,159:15)
Block(-8,9,3,159:15)
Block(-8,9,4,159:15)
Block(-8,9,5,159:15)
Block(-8,9,6,159:15)
Block(-8,9,7,159:15)
Block(-8,9,8,159:15)
Block(-8,10,-7,159:15)
Block(-8,10,-6,251:15)
Block(-8,10,-5,251:15)
Block(-8,10,-4,251:15)
Block(-8,10,-3,251:15)
Block(-8,10,-2,251:15)
Block(-8,10,-1,159:15)
Block(-8,10,0,159:15)
Block(-8,10,1,159:15)
Block(-8,10,2,251:15)
Block(-8,10,3,159:15)
Block(-8,10,4,251:15)
Block(-8,10,5,251:15)
Block(-8,10,6,251:15)
Block(-8,10,7,251:15)
Block(-8,10,8,251:15)
Block(-8,11,-7,159:15)
Block(-8,11,-6,159:15)
Block(-8,11,-5,159:15)
Block(-8,11,-4,251:15)
Block(-8,11,-3,251:15)
Block(-8,11,-2,159:15)
Block(-8,11,-1,251:15)
Block(-8,11,0,251:15)
Block(-8,11,1,251:15)
Block(-8,11,2,159:15)
Block(-8,11,3,251:15)
Block(-8,11,4,159:15)
Block(-8,11,5,159:15)
Block(-8,11,6,251:15)
Block(-8,11,7,251:15)
Block(-8,11,8,251:15)
Block(-8,12,-7,159:15)
Block(-8,12,-6,251:15)
Block(-8,12,-5,251:15)
Block(-8,12,-4,159:15)
Block(-8,12,-3,251:15)
Block(-8,12,-2,159:15)
Block(-8,12,-1,159:15)
Block(-8,12,0,159:15)
Block(-8,12,1,159:15)
Block(-8,12,2,159:15)
Block(-8,12,3,251:15)
Block(-8,12,4,251:15)
Block(-8,12,5,251:15)
Block(-8,12,6,159:15)
Block(-8,12,7,159:15)
Block(-8,12,8,251:15)
Block(-8,13,2,251:15)
Block(-8,13,3,159:15)
Block(-8,13,4,251:15)
Block(-8,13,5,159:15)
Block(-8,13,6,159:15)
Block(-8,13,7,159:15)
Block(-8,13,8,159:15)
Block(-8,14,2,159:15)
Block(-8,14,3,251:15)
Block(-8,14,4,159:15)
Block(-8,14,5,159:15)
Block(-8,14,6,159:15)
Block(-8,14,7,251:15)
Block(-8,14,8,251:15)
Block(-8,15,2,251:15)
Block(-8,15,3,251:15)
Block(-8,15,4,251:15)
Block(-8,15,5,251:15)
Block(-8,15,6,159:15)
Block(-8,15,7,159:15)
Block(-8,15,8,159:15)
Block(-8,16,2,251:15)
Block(-8,16,3,251:15)
Block(-8,16,4,159:15)
Block(-8,16,5,251:15)
Block(-8,16,6,251:15)
Block(-8,16,7,159:15)
Block(-8,16,8,159:15)
Block(-8,17,2,251:15)
Block(-8,17,3,251:15)
Block(-8,17,4,251:15)
Block(-8,17,5,159:15)
Block(-8,17,6,251:15)
Block(-8,17,7,251:15)
Block(-8,17,8,159:15)
Block(-8,18,2,251:15)
Block(-8,18,3,159:15)
Block(-8,18,4,159:15)
Block(-8,18,5,251:15)
Block(-8,18,6,159:15)
Block(-8,18,7,159:15)
Block(-8,18,8,159:15)
Block(-8,19,2,159:15)
Block(-8,19,3,159:15)
Block(-8,19,4,159:15)
Block(-8,19,5,251:15)
Block(-8,19,6,251:15)
Block(-8,19,7,251:15)
Block(-8,19,8,159:15)
Block(-8,20,2,159:15)
Block(-8,20,3,159:15)
Block(-8,20,4,159:15)
Block(-8,20,5,159:15)
Block(-8,20,6,159:15)
Block(-8,20,7,159:15)
Block(-8,20,8,159:15)
Block(-8,21,2,159:15)
Block(-8,21,3,159:15)
Block(-8,21,4,251:15)
Block(-8,21,5,159:15)
Block(-8,21,6,251:15)
Block(-8,21,7,251:15)
Block(-8,21,8,159:15)
Block(-8,22,2,159:15)
Block(-8,22,3,159:15)
Block(-8,22,4,251:15)
Block(-8,22,5,251:15)
Block(-8,22,6,251:15)
Block(-8,22,7,251:15)
Block(-8,22,8,251:15)
Block(-8,23,2,251:15)
Block(-8,23,3,159:15)
Block(-8,23,4,159:15)
Block(-8,23,5,251:15)
Block(-8,23,6,159:15)
Block(-8,23,7,251:15)
Block(-8,23,8,251:15)
Block(-8,24,2,159:15)
Block(-8,24,3,251:15)
Block(-8,24,4,251:15)
Block(-8,24,5,159:15)
Block(-8,24,6,251:15)
Block(-8,24,7,251:15)
Block(-8,24,8,159:15)
Block(-8,25,2,251:15)
Block(-8,25,3,251:15)
Block(-8,25,4,159:15)
Block(-8,25,5,251:15)
Block(-8,25,6,251:15)
Block(-8,25,7,251:15)
Block(-8,25,8,251:15)
Block(-7,0,-7,159:15)
Block(-7,0,-6,159:15)
Block(-7,0,-5,159:15)
Block(-7,0,-4,251:15)
Block(-7,0,-3,159:15)
Block(-7,0,-2,251:15)
Block(-7,0,-1,159:15)
Block(-7,0,0,251:15)
Block(-7,0,1,159:15)
Block(-7,0,2,251:15)
Block(-7,0,3,251:15)
Block(-7,0,4,251:15)
Block(-7,0,5,251:15)
Block(-7,0,6,251:15)
Block(-7,0,7,251:15)
Block(-7,0,8,251:15)
Block(-7,1,-7,251:15)
Block(-7,1,-6,159:15)
Block(-7,1,-5,251:15)
Block(-7,1,-4,159:15)
Block(-7,1,-3,251:15)
Block(-7,1,-2,159:15)
Block(-7,1,-1,159:15)
Block(-7,1,0,251:15)
Block(-7,1,1,251:15)
Block(-7,1,2,159:15)
Block(-7,1,3,159:15)
Block(-7,1,4,251:15)
Block(-7,1,5,251:15)
Block(-7,1,6,159:15)
Block(-7,1,7,251:15)
Block(-7,1,8,159:15)
Block(-7,2,-7,159:15)
Block(-7,2,-6,251:15)
Block(-7,2,-5,251:15)
Block(-7,2,-4,159:15)
Block(-7,2,-3,159:15)
Block(-7,2,-2,251:15)
Block(-7,2,-1,251:15)
Block(-7,2,0,251:15)
Block(-7,2,1,251:15)
Block(-7,2,2,251:15)
Block(-7,2,3,159:15)
Block(-7,2,4,251:15)
Block(-7,2,5,251:15)
Block(-7,2,6,159:15)
Block(-7,2,7,159:15)
Block(-7,2,8,159:15)
Block(-7,3,-7,251:15)
Block(-7,3,-6,159:15)
Block(-7,3,-5,159:15)
Block(-7,3,-4,159:15)
Block(-7,3,-3,251:15)
Block(-7,3,-2,251:15)
Block(-7,3,-1,251:15)
Block(-7,3,0,251:15)
Block(-7,3,1,251:15)
Block(-7,3,2,159:15)
Block(-7,3,3,159:15)
Block(-7,3,4,251:15)
Block(-7,3,5,159:15)
Block(-7,3,6,159:15)
Block(-7,3,7,251:15)
Block(-7,3,8,159:15)
Block(-7,4,-7,159:15)
Block(-7,4,-6,159:15)
Block(-7,4,-5,251:15)
Block(-7,4,-4,159:15)
Block(-7,4,-3,251:15)
Block(-7,4,-2,159:15)
Block(-7,4,-1,159:15)
Block(-7,4,0,159:15)
Block(-7,4,1,159:15)
Block(-7,4,2,159:15)
Block(-7,4,3,159:15)
Block(-7,4,4,159:15)
Block(-7,4,5,251:15)
Block(-7,4,6,159:15)
Block(-7,4,7,251:15)
Block(-7,4,8,251:15)
Block(-7,5,-7,251:15)
Block(-7,5,-6,251:15)
Block(-7,5,-5,251:15)
Block(-7,5,-4,159:15)
Block(-7,5,-3,159:15)
Block(-7,5,-2,251:15)
Block(-7,5,-1,251:15)
Block(-7,5,0,251:15)
Block(-7,5,1,251:15)
Block(-7,5,2,251:15)
Block(-7,5,3,251:15)
Block(-7,5,4,159:15)
Block(-7,5,5,159:15)
Block(-7,5,6,159:15)
Block(-7,5,7,159:15)
Block(-7,5,8,159:15)
Block(-7,6,-7,251:15)
Block(-7,6,-6,159:15)
Block(-7,6,-5,251:15)
Block(-7,6,-4,251:15)
Block(-7,6,-3,159:15)
Block(-7,6,-2,159:15)
Block(-7,6,-1,251:15)
Block(-7,6,0,251:15)
Block(-7,6,1,159:15)
Block(-7,6,2,159:15)
Block(-7,6,3,159:15)
Block(-7,6,4,251:15)
Block(-7,6,5,159:15)
Block(-7,6,6,159:15)
Block(-7,6,7,159:15)
Block(-7,6,8,251:15)
Block(-7,7,-7,251:15)
Block(-7,7,-6,251:15)
Block(-7,7,-5,159:15)
Block(-7,7,-4,159:15)
Block(-7,7,-3,251:15)
Block(-7,7,-2,251:15)
Block(-7,7,-1,251:15)
Block(-7,7,0,251:15)
Block(-7,7,1,251:15)
Block(-7,7,2,251:15)
Block(-7,7,3,159:15)
Block(-7,7,4,159:15)
Block(-7,7,5,251:15)
Block(-7,7,6,251:15)
Block(-7,7,7,159:15)
Block(-7,7,8,251:15)
Block(-7,8,-7,251:15)
Block(-7,8,-6,159:15)
Block(-7,8,-5,251:15)
Block(-7,8,-4,251:15)
Block(-7,8,-3,159:15)
Block(-7,8,-2,159:15)
Block(-7,8,-1,251:15)
Block(-7,8,0,159:15)
Block(-7,8,1,251:15)
Block(-7,8,2,159:15)
Block(-7,8,3,159:15)
Block(-7,8,4,251:15)
Block(-7,8,5,251:15)
Block(-7,8,6,251:15)
Block(-7,8,7,159:15)
Block(-7,8,8,159:15)
Block(-7,9,-7,159:15)
Block(-7,9,-6,251:15)
Block(-7,9,-5,159:15)
Block(-7,9,-4,251:15)
Block(-7,9,-3,159:15)
Block(-7,9,-2,159:15)
Block(-7,9,-1,159:15)
Block(-7,9,0,251:15)
Block(-7,9,1,251:15)
Block(-7,9,2,251:15)
Block(-7,9,3,251:15)
Block(-7,9,4,159:15)
Block(-7,9,5,251:15)
Block(-7,9,6,251:15)
Block(-7,9,7,159:15)
Block(-7,9,8,159:15)
Block(-7,10,-7,159:15)
Block(-7,10,-6,251:15)
Block(-7,10,-5,251:15)
Block(-7,10,-4,251:15)
Block(-7,10,-3,251:15)
Block(-7,10,-2,251:15)
Block(-7,10,-1,251:15)
Block(-7,10,0,251:15)
Block(-7,10,1,159:15)
Block(-7,10,2,159:15)
Block(-7,10,3,159:15)
Block(-7,10,4,251:15)
Block(-7,10,5,159:15)
Block(-7,10,6,251:15)
Block(-7,10,7,251:15)
Block(-7,10,8,251:15)
Block(-7,11,-7,251:15)
Block(-7,11,-6,159:15)
Block(-7,11,-5,159:15)
Block(-7,11,-4,159:15)
Block(-7,11,-3,251:15)
Block(-7,11,-2,251:15)
Block(-7,11,-1,251:15)
Block(-7,11,0,159:15)
Block(-7,11,1,159:15)
Block(-7,11,2,159:15)
Block(-7,11,3,251:15)
Block(-7,11,4,251:15)
Block(-7,11,5,159:15)
Block(-7,11,6,159:15)
Block(-7,11,7,251:15)
Block(-7,11,8,251:15)
Block(-7,12,-7,159:15)
Block(-7,12,-6,251:15)
Block(-7,12,-5,251:15)
Block(-7,12,-4,159:15)
Block(-7,12,-3,159:15)
Block(-7,12,-2,159:15)
Block(-7,12,-1,251:15)
Block(-7,12,0,251:15)
Block(-7,12,1,159:15)
Block(-7,12,2,251:15)
Block(-7,12,3,251:15)
Block(-7,12,4,159:15)
Block(-7,12,5,251:15)
Block(-7,12,6,159:15)
Block(-7,12,7,159:15)
Block(-7,12,8,251:15)
Block(-7,13,2,159:15)
Block(-7,13,3,251:15)
Block(-7,13,4,159:15)
Block(-7,13,5,251:15)
Block(-7,13,6,159:15)
Block(-7,13,7,251:15)
Block(-7,13,8,251:15)
Block(-7,14,2,159:15)
Block(-7,14,3,159:15)
Block(-7,14,4,159:15)
Block(-7,14,5,159:15)
Block(-7,14,6,251:15)
Block(-7,14,7,159:15)
Block(-7,14,8,251:15)
Block(-7,15,2,159:15)
Block(-7,15,3,159:15)
Block(-7,15,4,159:15)
Block(-7,15,5,251:15)
Block(-7,15,6,251:15)
Block(-7,15,7,159:15)
Block(-7,15,8,159:15)
Block(-7,16,2,159:15)
Block(-7,16,3,159:15)
Block(-7,16,4,159:15)
Block(-7,16,5,251:15)
Block(-7,16,6,159:15)
Block(-7,16,7,159:15)
Block(-7,16,8,159:15)
Block(-7,17,2,251:15)
Block(-7,17,3,159:15)
Block(-7,17,4,251:15)
Block(-7,17,5,251:15)
Block(-7,17,6,159:15)
Block(-7,17,7,159:15)
Block(-7,17,8,159:15)
Block(-7,18,2,251:15)
Block(-7,18,3,159:15)
Block(-7,18,4,251:15)
Block(-7,18,5,159:15)
Block(-7,18,6,251:15)
Block(-7,18,7,251:15)
Block(-7,18,8,251:15)
Block(-7,19,2,251:15)
Block(-7,19,3,159:15)
Block(-7,19,4,251:15)
Block(-7,19,5,159:15)
Block(-7,19,6,159:15)
Block(-7,19,7,159:15)
Block(-7,19,8,159:15)
Block(-7,20,2,251:15)
Block(-7,20,3,251:15)
Block(-7,20,4,159:15)
Block(-7,20,5,251:15)
Block(-7,20,6,251:15)
Block(-7,20,7,159:15)
Block(-7,20,8,251:15)
Block(-7,21,2,159:15)
Block(-7,21,3,159:15)
Block(-7,21,4,251:15)
Block(-7,21,5,159:15)
Block(-7,21,6,159:15)
Block(-7,21,7,251:15)
Block(-7,21,8,159:15)
Block(-7,22,2,159:15)
Block(-7,22,3,251:15)
Block(-7,22,4,251:15)
Block(-7,22,5,251:15)
Block(-7,22,6,159:15)
Block(-7,22,7,251:15)
Block(-7,22,8,159:15)
Block(-7,23,2,159:15)
Block(-7,23,3,251:15)
Block(-7,23,4,251:15)
Block(-7,23,5,251:15)
Block(-7,23,6,251:15)
Block(-7,23,7,251:15)
Block(-7,23,8,251:15)
Block(-7,24,2,159:15)
Block(-7,24,3,159:15)
Block(-7,24,4,159:15)
Block(-7,24,5,159:15)
Block(-7,24,6,251:15)
Block(-7,24,7,159:15)
Block(-7,24,8,251:15)
Block(-7,25,2,251:15)
Block(-7,25,3,251:15)
Block(-7,25,4,251:15)
Block(-7,25,5,159:15)
Block(-7,25,6,159:15)
Block(-7,25,7,251:15)
Block(-7,25,8,159:15)
Block(-6,0,-7,159:15)
Block(-6,0,-6,251:15)
Block(-6,0,-5,251:15)
Block(-6,0,-4,251:15)
Block(-6,0,-3,251:15)
Block(-6,0,-2,251:15)
Block(-6,0,-1,251:15)
Block(-6,0,0,251:15)
Block(-6,0,1,159:15)
Block(-6,0,2,251:15)
Block(-6,0,3,159:15)
Block(-6,0,4,251:15)
Block(-6,0,5,251:15)
Block(-6,0,6,159:15)
Block(-6,0,7,159:15)
Block(-6,0,8,159:15)
Block(-6,1,-7,251:15)
Block(-6,1,-6,251:15)
Block(-6,1,-5,159:15)
Block(-6,1,-4,251:15)
Block(-6,1,-3,159:15)
Block(-6,1,-2,251:15)
Block(-6,1,-1,251:15)
Block(-6,1,0,251:15)
Block(-6,1,1,159:15)
Block(-6,1,2,159:15)
Block(-6,1,3,159:15)
Block(-6,1,4,159:15)
Block(-6,1,5,251:15)
Block(-6,1,6,251:15)
Block(-6,1,7,159:15)
Block(-6,1,8,159:15)
Block(-6,2,-7,251:15)
Block(-6,2,-6,159:15)
Block(-6,2,-5,251:15)
Block(-6,2,-4,251:15)
Block(-6,2,-3,251:15)
Block(-6,2,-2,251:15)
Block(-6,2,-1,159:15)
Block(-6,2,0,159:15)
Block(-6,2,1,159:15)
Block(-6,2,2,251:15)
Block(-6,2,3,251:15)
Block(-6,2,4,251:15)
Block(-6,2,5,159:15)
Block(-6,2,6,159:15)
Block(-6,2,7,159:15)
Block(-6,2,8,159:15)
Block(-6,3,-7,251:15)
Block(-6,3,-6,251:15)
Block(-6,3,-5,251:15)
Block(-6,3,-4,251:15)
Block(-6,3,-3,251:15)
Block(-6,3,-2,159:15)
Block(-6,3,-1,159:15)
Block(-6,3,0,251:15)
Block(-6,3,1,159:15)
Block(-6,3,2,251:15)
Block(-6,3,3,251:15)
Block(-6,3,4,251:15)
Block(-6,3,5,251:15)
Block(-6,3,6,159:15)
Block(-6,3,7,251:15)
Block(-6,3,8,251:15)
Block(-6,4,-7,251:15)
Block(-6,4,-6,159:15)
Block(-6,4,-5,251:15)
Block(-6,4,-4,159:15)
Block(-6,4,-3,251:15)
Block(-6,4,-2,251:15)
Block(-6,4,-1,159:15)
Block(-6,4,0,251:15)
Block(-6,4,1,159:15)
Block(-6,4,2,251:15)
Block(-6,4,3,159:15)
Block(-6,4,4,251:15)
Block(-6,4,5,251:15)
Block(-6,4,6,251:15)
Block(-6,4,7,251:15)
Block(-6,4,8,251:15)
Block(-6,5,-7,251:15)
Block(-6,5,-6,159:15)
Block(-6,5,-5,159:15)
Block(-6,5,-4,251:15)
Block(-6,5,-3,159:15)
Block(-6,5,-2,251:15)
Block(-6,5,-1,251:15)
Block(-6,5,0,159:15)
Block(-6,5,1,251:15)
Block(-6,5,2,251:15)
Block(-6,5,3,159:15)
Block(-6,5,4,251:15)
Block(-6,5,5,251:15)
Block(-6,5,6,251:15)
Block(-6,5,7,251:15)
Block(-6,5,8,159:15)
Block(-6,6,-7,159:15)
Block(-6,6,-6,159:15)
Block(-6,6,-5,251:15)
Block(-6,6,-4,251:15)
Block(-6,6,-3,159:15)
Block(-6,6,-2,251:15)
Block(-6,6,-1,251:15)
Block(-6,6,0,251:15)
Block(-6,6,1,251:15)
Block(-6,6,2,159:15)
Block(-6,6,3,251:15)
Block(-6,6,4,251:15)
Block(-6,6,5,251:15)
Block(-6,6,6,251:15)
Block(-6,6,7,251:15)
Block(-6,6,8,251:15)
Block(-6,7,-7,251:15)
Block(-6,7,-6,159:15)
Block(-6,7,-5,251:15)
Block(-6,7,-4,159:15)
Block(-6,7,-3,251:15)
Block(-6,7,-2,251:15)
Block(-6,7,-1,251:15)
Block(-6,7,0,251:15)
Block(-6,7,1,159:15)
Block(-6,7,2,159:15)
Block(-6,7,3,251:15)
Block(-6,7,4,159:15)
Block(-6,7,5,159:15)
Block(-6,7,6,251:15)
Block(-6,7,7,159:15)
Block(-6,7,8,159:15)
Block(-6,8,-7,159:15)
Block(-6,8,-6,159:15)
Block(-6,8,-5,159:15)
Block(-6,8,-4,159:15)
Block(-6,8,-3,159:15)
Block(-6,8,-2,159:15)
Block(-6,8,-1,159:15)
Block(-6,8,0,159:15)
Block(-6,8,1,251:15)
Block(-6,8,2,251:15)
Block(-6,8,3,159:15)
Block(-6,8,4,159:15)
Block(-6,8,5,159:15)
Block(-6,8,6,251:15)
Block(-6,8,7,159:15)
Block(-6,8,8,251:15)
Block(-6,9,-7,159:15)
Block(-6,9,-6,159:15)
Block(-6,9,-5,251:15)
Block(-6,9,-4,251:15)
Block(-6,9,-3,251:15)
Block(-6,9,-2,251:15)
Block(-6,9,-1,251:15)
Block(-6,9,0,251:15)
Block(-6,9,1,251:15)
Block(-6,9,2,251:15)
Block(-6,9,3,251:15)
Block(-6,9,4,251:15)
Block(-6,9,5,159:15)
Block(-6,9,6,159:15)
Block(-6,9,7,251:15)
Block(-6,9,8,159:15)
Block(-6,10,-7,159:15)
Block(-6,10,-6,159:15)
Block(-6,10,-5,251:15)
Block(-6,10,-4,159:15)
Block(-6,10,-3,159:15)
Block(-6,10,-2,251:15)
Block(-6,10,-1,251:15)
Block(-6,10,0,159:15)
Block(-6,10,1,251:15)
Block(-6,10,2,159:15)
Block(-6,10,3,159:15)
Block(-6,10,4,251:15)
Block(-6,10,5,159:15)
Block(-6,10,6,251:15)
Block(-6,10,7,251:15)
Block(-6,10,8,159:15)
Block(-6,11,-7,251:15)
Block(-6,11,-6,251:15)
Block(-6,11,-5,159:15)
Block(-6,11,-4,251:15)
Block(-6,11,-3,159:15)
Block(-6,11,-2,159:15)
Block(-6,11,-1,251:15)
Block(-6,11,0,251:15)
Block(-6,11,1,159:15)
Block(-6,11,2,159:15)
Block(-6,11,3,251:15)
Block(-6,11,4,251:15)
Block(-6,11,5,159:15)
Block(-6,11,6,251:15)
Block(-6,11,7,159:15)
Block(-6,11,8,251:15)
Block(-6,12,-7,251:15)
Block(-6,12,-6,159:15)
Block(-6,12,-5,159:15)
Block(-6,12,-4,159:15)
Block(-6,12,-3,159:15)
Block(-6,12,-2,251:15)
Block(-6,12,-1,251:15)
Block(-6,12,0,159:15)
Block(-6,12,1,159:15)
Block(-6,12,2,159:15)
Block(-6,12,3,159:15)
Block(-6,12,4,159:15)
Block(-6,12,5,159:15)
Block(-6,12,6,159:15)
Block(-6,12,7,159:15)
Block(-6,12,8,159:15)
Block(-6,13,-7,251:15)
Block(-6,13,0,251:15)
Block(-6,13,1,251:15)
Block(-6,13,2,159:15)
Block(-6,13,3,251:15)
Block(-6,13,4,159:15)
Block(-6,13,5,159:15)
Block(-6,13,6,251:15)
Block(-6,13,7,159:15)
Block(-6,13,8,159:15)
Block(-6,14,-7,251:15)
Block(-6,14,0,159:15)
Block(-6,14,1,159:15)
Block(-6,14,2,251:15)
Block(-6,14,3,251:15)
Block(-6,14,4,159:15)
Block(-6,14,5,251:15)
Block(-6,14,6,159:15)
Block(-6,14,7,159:15)
Block(-6,14,8,251:15)
Block(-6,15,-7,159:15)
Block(-6,15,0,159:15)
Block(-6,15,1,159:15)
Block(-6,15,2,159:15)
Block(-6,15,3,159:15)
Block(-6,15,4,251:15)
Block(-6,15,5,251:15)
Block(-6,15,6,251:15)
Block(-6,15,7,251:15)
Block(-6,15,8,251:15)
Block(-6,16,-7,251:15)
Block(-6,16,0,251:15)
Block(-6,16,1,159:15)
Block(-6,16,2,251:15)
Block(-6,16,3,251:15)
Block(-6,16,4,159:15)
Block(-6,16,5,251:15)
Block(-6,16,6,251:15)
Block(-6,16,7,251:15)
Block(-6,16,8,251:15)
Block(-6,17,-7,159:15)
Block(-6,17,0,159:15)
Block(-6,17,1,251:15)
Block(-6,17,2,251:15)
Block(-6,17,3,251:15)
Block(-6,17,4,159:15)
Block(-6,17,5,159:15)
Block(-6,17,6,251:15)
Block(-6,17,7,251:15)
Block(-6,17,8,159:15)
Block(-6,18,0,251:15)
Block(-6,18,1,251:15)
Block(-6,18,2,159:15)
Block(-6,18,3,159:15)
Block(-6,18,4,251:15)
Block(-6,18,5,251:15)
Block(-6,18,6,159:15)
Block(-6,18,7,159:15)
Block(-6,18,8,159:15)
Block(-6,19,0,251:15)
Block(-6,19,1,159:15)
Block(-6,19,2,159:15)
Block(-6,19,3,159:15)
Block(-6,19,4,159:15)
Block(-6,19,5,159:15)
Block(-6,19,6,159:15)
Block(-6,19,7,251:15)
Block(-6,19,8,159:15)
Block(-6,20,0,251:15)
Block(-6,20,1,251:15)
Block(-6,20,2,159:15)
Block(-6,20,3,159:15)
Block(-6,20,4,159:15)
Block(-6,20,5,251:15)
Block(-6,20,6,251:15)
Block(-6,20,7,251:15)
Block(-6,20,8,159:15)
Block(-6,21,0,159:15)
Block(-6,21,1,251:15)
Block(-6,21,2,251:15)
Block(-6,21,3,159:15)
Block(-6,21,4,159:15)
Block(-6,21,5,159:15)
Block(-6,21,6,251:15)
Block(-6,21,7,159:15)
Block(-6,21,8,251:15)
Block(-6,22,0,159:15)
Block(-6,22,1,251:15)
Block(-6,22,2,251:15)
Block(-6,22,3,159:15)
Block(-6,22,4,159:15)
Block(-6,22,5,159:15)
Block(-6,22,6,159:15)
Block(-6,22,7,159:15)
Block(-6,22,8,159:15)
Block(-6,23,0,251:15)
Block(-6,23,1,159:15)
Block(-6,23,2,251:15)
Block(-6,23,3,251:15)
Block(-6,23,4,159:15)
Block(-6,23,5,159:15)
Block(-6,23,6,251:15)
Block(-6,23,7,159:15)
Block(-6,23,8,251:15)
Block(-6,24,0,251:15)
Block(-6,24,1,251:15)
Block(-6,24,2,159:15)
Block(-6,24,3,251:15)
Block(-6,24,4,251:15)
Block(-6,24,5,159:15)
Block(-6,24,6,251:15)
Block(-6,24,7,251:15)
Block(-6,24,8,159:15)
Block(-6,25,0,251:15)
Block(-6,25,1,159:15)
Block(-6,25,2,159:15)
Block(-6,25,3,251:15)
Block(-6,25,4,251:15)
Block(-6,25,5,159:15)
Block(-6,25,6,251:15)
Block(-6,25,7,251:15)
Block(-6,25,8,159:15)
Block(-6,26,0,251:15)
Block(-6,26,1,159:15)
Block(-6,26,2,251:15)
Block(-6,27,0,251:15)
Block(-6,27,1,251:15)
Block(-6,27,2,251:15)
Block(-6,28,0,251:15)
Block(-6,28,1,251:15)
Block(-6,28,2,159:15)
Block(-6,29,0,251:15)
Block(-6,29,1,159:15)
Block(-6,29,2,159:15)
Block(-6,30,0,159:15)
Block(-6,30,1,251:15)
Block(-6,30,2,251:15)
Block(-6,31,0,251:15)
Block(-6,31,1,251:15)
Block(-6,31,2,251:15)
Block(-6,32,0,159:15)
Block(-6,32,1,159:15)
Block(-6,32,2,251:15)
Block(-6,33,0,251:15)
Block(-6,33,1,251:15)
Block(-6,33,2,251:15)
Block(-6,34,0,159:15)
Block(-6,34,1,159:15)
Block(-6,34,2,159:15)
Block(-6,35,0,159:15)
Block(-6,35,1,251:15)
Block(-6,35,2,251:15)
Block(-6,36,0,251:15)
Block(-6,36,1,251:15)
Block(-6,36,2,159:15)
Block(-6,37,0,251:15)
Block(-6,37,1,251:15)
Block(-6,37,2,251:15)
Block(-6,38,0,251:15)
Block(-6,38,1,251:15)
Block(-6,38,2,159:15)
Block(-6,39,0,251:15)
Block(-6,39,1,159:15)
Block(-6,39,2,159:15)
Block(-6,40,0,159:15)
Block(-6,40,1,159:15)
Block(-6,40,2,251:15)
Block(-5,0,-7,251:15)
Block(-5,0,-6,159:15)
Block(-5,0,-5,159:15)
Block(-5,0,-4,251:15)
Block(-5,0,-3,159:15)
Block(-5,0,-2,251:15)
Block(-5,0,-1,159:15)
Block(-5,0,0,159:15)
Block(-5,0,1,159:15)
Block(-5,0,2,251:15)
Block(-5,0,3,159:15)
Block(-5,0,4,251:15)
Block(-5,0,5,159:15)
Block(-5,0,6,251:15)
Block(-5,0,7,251:15)
Block(-5,0,8,251:15)
Block(-5,1,-7,251:15)
Block(-5,1,-6,251:15)
Block(-5,1,-5,159:15)
Block(-5,1,-4,251:15)
Block(-5,1,-3,159:15)
Block(-5,1,-2,251:15)
Block(-5,1,-1,159:15)
Block(-5,1,0,251:15)
Block(-5,1,1,159:15)
Block(-5,1,2,159:15)
Block(-5,1,3,251:15)
Block(-5,1,4,251:15)
Block(-5,1,5,159:15)
Block(-5,1,6,251:15)
Block(-5,1,7,159:15)
Block(-5,1,8,251:15)
Block(-5,2,-7,159:15)
Block(-5,2,-6,251:15)
Block(-5,2,-5,159:15)
Block(-5,2,-4,251:15)
Block(-5,2,-3,159:15)
Block(-5,2,-2,159:15)
Block(-5,2,-1,251:15)
Block(-5,2,0,251:15)
Block(-5,2,1,159:15)
Block(-5,2,2,251:15)
Block(-5,2,3,159:15)
Block(-5,2,4,159:15)
Block(-5,2,5,251:15)
Block(-5,2,6,251:15)
Block(-5,2,7,159:15)
Block(-5,2,8,159:15)
Block(-5,3,-7,251:15)
Block(-5,3,-6,159:15)
Block(-5,3,-5,159:15)
Block(-5,3,-4,251:15)
Block(-5,3,-3,251:15)
Block(-5,3,-2,159:15)
Block(-5,3,-1,159:15)
Block(-5,3,0,251:15)
Block(-5,3,1,159:15)
Block(-5,3,2,251:15)
Block(-5,3,3,251:15)
Block(-5,3,4,251:15)
Block(-5,3,5,251:15)
Block(-5,3,6,251:15)
Block(-5,3,7,251:15)
Block(-5,3,8,159:15)
Block(-5,4,-7,251:15)
Block(-5,4,-6,251:15)
Block(-5,4,-5,251:15)
Block(-5,4,-4,251:15)
Block(-5,4,-3,251:15)
Block(-5,4,-2,251:15)
Block(-5,4,-1,159:15)
Block(-5,4,0,251:15)
Block(-5,4,1,251:15)
Block(-5,4,2,251:15)
Block(-5,4,3,251:15)
Block(-5,4,4,251:15)
Block(-5,4,5,159:15)
Block(-5,4,6,159:15)
Block(-5,4,7,251:15)
Block(-5,4,8,159:15)
Block(-5,5,-7,251:15)
Block(-5,5,-6,251:15)
Block(-5,5,-5,251:15)
Block(-5,5,-4,251:15)
Block(-5,5,-3,159:15)
Block(-5,5,-2,159:15)
Block(-5,5,-1,159:15)
Block(-5,5,0,251:15)
Block(-5,5,1,251:15)
Block(-5,5,2,159:15)
Block(-5,5,3,251:15)
Block(-5,5,4,251:15)
Block(-5,5,5,251:15)
Block(-5,5,6,159:15)
Block(-5,5,7,159:15)
Block(-5,5,8,159:15)
Block(-5,6,-7,159:15)
Block(-5,6,-6,251:15)
Block(-5,6,-5,159:15)
Block(-5,6,-4,159:15)
Block(-5,6,-3,159:15)
Block(-5,6,-2,159:15)
Block(-5,6,-1,159:15)
Block(-5,6,0,159:15)
Block(-5,6,1,159:15)
Block(-5,6,2,251:15)
Block(-5,6,3,159:15)
Block(-5,6,4,251:15)
Block(-5,6,5,159:15)
Block(-5,6,6,159:15)
Block(-5,6,7,159:15)
Block(-5,6,8,251:15)
Block(-5,7,-7,159:15)
Block(-5,7,-6,251:15)
Block(-5,7,-5,251:15)
Block(-5,7,-4,159:15)
Block(-5,7,-3,251:15)
Block(-5,7,-2,251:15)
Block(-5,7,-1,159:15)
Block(-5,7,0,251:15)
Block(-5,7,1,159:15)
Block(-5,7,2,251:15)
Block(-5,7,3,159:15)
Block(-5,7,4,251:15)
Block(-5,7,5,159:15)
Block(-5,7,6,251:15)
Block(-5,7,7,159:15)
Block(-5,7,8,159:15)
Block(-5,8,-7,159:15)
Block(-5,8,-6,159:15)
Block(-5,8,-5,251:15)
Block(-5,8,-4,159:15)
Block(-5,8,-3,251:15)
Block(-5,8,-2,251:15)
Block(-5,8,-1,251:15)
Block(-5,8,0,159:15)
Block(-5,8,1,159:15)
Block(-5,8,2,251:15)
Block(-5,8,3,251:15)
Block(-5,8,4,251:15)
Block(-5,8,5,251:15)
Block(-5,8,6,251:15)
Block(-5,8,7,159:15)
Block(-5,8,8,251:15)
Block(-5,9,-7,159:15)
Block(-5,9,-6,251:15)
Block(-5,9,-5,159:15)
Block(-5,9,-4,159:15)
Block(-5,9,-3,251:15)
Block(-5,9,-2,159:15)
Block(-5,9,-1,251:15)
Block(-5,9,0,159:15)
Block(-5,9,1,159:15)
Block(-5,9,2,251:15)
Block(-5,9,3,251:15)
Block(-5,9,4,159:15)
Block(-5,9,5,251:15)
Block(-5,9,6,251:15)
Block(-5,9,7,159:15)
Block(-5,9,8,159:15)
Block(-5,10,-7,159:15)
Block(-5,10,-6,251:15)
Block(-5,10,-5,251:15)
Block(-5,10,-4,159:15)
Block(-5,10,-3,159:15)
Block(-5,10,-2,159:15)
Block(-5,10,-1,251:15)
Block(-5,10,0,159:15)
Block(-5,10,1,251:15)
Block(-5,10,2,251:15)
Block(-5,10,3,251:15)
Block(-5,10,4,159:15)
Block(-5,10,5,251:15)
Block(-5,10,6,251:15)
Block(-5,10,7,251:15)
Block(-5,10,8,159:15)
Block(-5,11,-7,251:15)
Block(-5,11,-6,159:15)
Block(-5,11,-5,251:15)
Block(-5,11,-4,251:15)
Block(-5,11,-3,159:15)
Block(-5,11,-2,251:15)
Block(-5,11,-1,251:15)
Block(-5,11,0,251:15)
Block(-5,11,1,159:15)
Block(-5,11,2,159:15)
Block(-5,11,3,159:15)
Block(-5,11,4,159:15)
Block(-5,11,5,251:15)
Block(-5,11,6,251:15)
Block(-5,11,7,251:15)
Block(-5,11,8,251:15)
Block(-5,12,-7,251:15)
Block(-5,12,-6,159:15)
Block(-5,12,-5,251:15)
Block(-5,12,-4,251:15)
Block(-5,12,-3,159:15)
Block(-5,12,-2,159:15)
Block(-5,12,-1,251:15)
Block(-5,12,0,159:15)
Block(-5,12,1,251:15)
Block(-5,12,2,251:15)
Block(-5,12,3,251:15)
Block(-5,12,4,251:15)
Block(-5,12,5,159:15)
Block(-5,12,6,159:15)
Block(-5,12,7,159:15)
Block(-5,12,8,251:15)
Block(-5,13,-7,251:15)
Block(-5,13,-6,251:15)
Block(-5,13,-5,251:15)
Block(-5,13,-2,159:15)
Block(-5,13,-1,251:15)
Block(-5,13,0,159:15)
Block(-5,13,1,159:15)
Block(-5,13,2,159:15)
Block(-5,13,3,159:15)
Block(-5,13,4,159:15)
Block(-5,13,5,251:15)
Block(-5,13,6,251:15)
Block(-5,13,7,251:15)
Block(-5,13,8,159:15)
Block(-5,14,-7,251:15)
Block(-5,14,-6,159:15)
Block(-5,14,-5,251:15)
Block(-5,14,-2,159:15)
Block(-5,14,-1,251:15)
Block(-5,14,0,159:15)
Block(-5,14,1,251:15)
Block(-5,14,2,159:15)
Block(-5,14,3,159:15)
Block(-5,14,4,251:15)
Block(-5,14,5,159:15)
Block(-5,14,6,159:15)
Block(-5,14,7,159:15)
Block(-5,14,8,251:15)
Block(-5,15,-7,159:15)
Block(-5,15,-6,251:15)
Block(-5,15,-5,251:15)
Block(-5,15,-2,251:15)
Block(-5,15,-1,251:15)
Block(-5,15,0,251:15)
Block(-5,15,1,251:15)
Block(-5,15,2,159:15)
Block(-5,15,3,251:15)
Block(-5,15,4,159:15)
Block(-5,15,5,159:15)
Block(-5,15,6,159:15)
Block(-5,15,7,159:15)
Block(-5,15,8,159:15)
Block(-5,16,-7,159:15)
Block(-5,16,-6,159:15)
Block(-5,16,-5,159:15)
Block(-5,16,-2,251:15)
Block(-5,16,-1,159:15)
Block(-5,16,0,251:15)
Block(-5,16,1,159:15)
Block(-5,16,2,159:15)
Block(-5,16,3,251:15)
Block(-5,16,4,159:15)
Block(-5,16,5,251:15)
Block(-5,16,6,251:15)
Block(-5,16,7,159:15)
Block(-5,16,8,159:15)
Block(-5,17,-7,159:15)
Block(-5,17,-6,159:15)
Block(-5,17,-5,159:15)
Block(-5,17,-2,251:15)
Block(-5,17,-1,251:15)
Block(-5,17,0,159:15)
Block(-5,17,1,251:15)
Block(-5,17,2,251:15)
Block(-5,17,3,251:15)
Block(-5,17,4,159:15)
Block(-5,17,5,159:15)
Block(-5,17,6,251:15)
Block(-5,17,7,251:15)
Block(-5,17,8,251:15)
Block(-5,18,-2,251:15)
Block(-5,18,-1,251:15)
Block(-5,18,0,159:15)
Block(-5,18,1,159:15)
Block(-5,18,2,159:15)
Block(-5,18,3,159:15)
Block(-5,18,4,251:15)
Block(-5,18,5,251:15)
Block(-5,18,6,159:15)
Block(-5,18,7,251:15)
Block(-5,18,8,251:15)
Block(-5,19,-2,159:15)
Block(-5,19,-1,251:15)
Block(-5,19,0,159:15)
Block(-5,19,1,251:15)
Block(-5,19,2,159:15)
Block(-5,19,3,159:15)
Block(-5,19,4,159:15)
Block(-5,19,5,251:15)
Block(-5,19,6,251:15)
Block(-5,19,7,251:15)
Block(-5,19,8,159:15)
Block(-5,20,-2,251:15)
Block(-5,20,-1,159:15)
Block(-5,20,0,159:15)
Block(-5,20,1,251:15)
Block(-5,20,2,159:15)
Block(-5,20,3,159:15)
Block(-5,20,4,159:15)
Block(-5,20,5,159:15)
Block(-5,20,6,251:15)
Block(-5,20,7,159:15)
Block(-5,20,8,159:15)
Block(-5,21,-2,251:15)
Block(-5,21,-1,159:15)
Block(-5,21,0,159:15)
Block(-5,21,1,159:15)
Block(-5,21,2,251:15)
Block(-5,21,3,159:15)
Block(-5,21,4,159:15)
Block(-5,21,5,251:15)
Block(-5,21,6,159:15)
Block(-5,21,7,159:15)
Block(-5,21,8,251:15)
Block(-5,22,-2,251:15)
Block(-5,22,-1,251:15)
Block(-5,22,0,159:15)
Block(-5,22,1,251:15)
Block(-5,22,2,159:15)
Block(-5,22,3,159:15)
Block(-5,22,4,251:15)
Block(-5,22,5,159:15)
Block(-5,22,6,251:15)
Block(-5,22,7,159:15)
Block(-5,22,8,159:15)
Block(-5,23,-2,251:15)
Block(-5,23,-1,251:15)
Block(-5,23,0,251:15)
Block(-5,23,1,251:15)
Block(-5,23,2,251:15)
Block(-5,23,3,251:15)
Block(-5,23,4,251:15)
Block(-5,23,5,251:15)
Block(-5,23,6,251:15)
Block(-5,23,7,251:15)
Block(-5,23,8,159:15)
Block(-5,24,-2,251:15)
Block(-5,24,-1,251:15)
Block(-5,24,0,159:15)
Block(-5,24,1,251:15)
Block(-5,24,2,159:15)
Block(-5,24,3,159:15)
Block(-5,24,4,251:15)
Block(-5,24,5,159:15)
Block(-5,24,6,251:15)
Block(-5,24,7,251:15)
Block(-5,24,8,251:15)
Block(-5,25,-2,251:15)
Block(-5,25,-1,251:15)
Block(-5,25,0,159:15)
Block(-5,25,1,159:15)
Block(-5,25,2,251:15)
Block(-5,25,3,159:15)
Block(-5,25,4,159:15)
Block(-5,25,5,251:15)
Block(-5,25,6,251:15)
Block(-5,25,7,251:15)
Block(-5,25,8,251:15)
Block(-5,26,-2,159:15)
Block(-5,26,-1,251:15)
Block(-5,26,0,251:15)
Block(-5,26,1,251:15)
Block(-5,26,2,159:15)
Block(-5,26,3,251:15)
Block(-5,26,4,251:15)
Block(-5,27,-2,159:15)
Block(-5,27,-1,251:15)
Block(-5,27,0,159:15)
Block(-5,27,1,159:15)
Block(-5,27,2,159:15)
Block(-5,27,3,159:15)
Block(-5,27,4,159:15)
Block(-5,28,-2,251:15)
Block(-5,28,-1,159:15)
Block(-5,28,0,251:15)
Block(-5,28,1,159:15)
Block(-5,28,2,159:15)
Block(-5,28,3,251:15)
Block(-5,28,4,251:15)
Block(-5,29,-2,251:15)
Block(-5,29,-1,159:15)
Block(-5,29,0,159:15)
Block(-5,29,1,251:15)
Block(-5,29,2,159:15)
Block(-5,29,3,159:15)
Block(-5,29,4,251:15)
Block(-5,30,-2,159:15)
Block(-5,30,-1,159:15)
Block(-5,30,0,159:15)
Block(-5,30,1,251:15)
Block(-5,30,2,159:15)
Block(-5,30,3,159:15)
Block(-5,30,4,251:15)
Block(-5,31,-2,159:15)
Block(-5,31,-1,251:15)
Block(-5,31,0,251:15)
Block(-5,31,1,159:15)
Block(-5,31,2,159:15)
Block(-5,31,3,251:15)
Block(-5,31,4,251:15)
Block(-5,32,-2,159:15)
Block(-5,32,-1,159:15)
Block(-5,32,0,251:15)
Block(-5,32,1,159:15)
Block(-5,32,2,159:15)
Block(-5,32,3,159:15)
Block(-5,32,4,251:15)
Block(-5,33,-2,159:15)
Block(-5,33,-1,159:15)
Block(-5,33,0,251:15)
Block(-5,33,1,251:15)
Block(-5,33,2,251:15)
Block(-5,33,3,159:15)
Block(-5,33,4,251:15)
Block(-5,34,-2,159:15)
Block(-5,34,-1,251:15)
Block(-5,34,0,159:15)
Block(-5,34,1,159:15)
Block(-5,34,2,251:15)
Block(-5,34,3,159:15)
Block(-5,34,4,159:15)
Block(-5,35,-2,251:15)
Block(-5,35,-1,159:15)
Block(-5,35,0,159:15)
Block(-5,35,1,251:15)
Block(-5,35,2,159:15)
Block(-5,35,3,159:15)
Block(-5,35,4,251:15)
Block(-5,36,-2,159:15)
Block(-5,36,-1,251:15)
Block(-5,36,0,251:15)
Block(-5,36,1,159:15)
Block(-5,36,2,251:15)
Block(-5,36,3,251:15)
Block(-5,36,4,159:15)
Block(-5,37,-2,159:15)
Block(-5,37,-1,159:15)
Block(-5,37,0,251:15)
Block(-5,37,1,159:15)
Block(-5,37,2,251:15)
Block(-5,37,3,251:15)
Block(-5,37,4,251:15)
Block(-5,38,-2,159:15)
Block(-5,38,-1,159:15)
Block(-5,38,0,251:15)
Block(-5,38,1,251:15)
Block(-5,38,2,159:15)
Block(-5,38,3,251:15)
Block(-5,38,4,159:15)
Block(-5,39,-2,251:15)
Block(-5,39,-1,159:15)
Block(-5,39,0,251:15)
Block(-5,39,1,159:15)
Block(-5,39,2,251:15)
Block(-5,39,3,251:15)
Block(-5,39,4,159:15)
Block(-5,40,-2,251:15)
Block(-5,40,-1,159:15)
Block(-5,40,0,159:15)
Block(-5,40,1,159:15)
Block(-5,40,2,251:15)
Block(-5,40,3,251:15)
Block(-5,40,4,159:15)
Block(-4,0,-7,159:15)
Block(-4,0,-6,251:15)
Block(-4,0,-5,251:15)
Block(-4,0,-4,159:15)
Block(-4,0,-3,251:15)
Block(-4,0,-2,251:15)
Block(-4,0,-1,159:15)
Block(-4,0,0,251:15)
Block(-4,0,1,159:15)
Block(-4,0,2,251:15)
Block(-4,0,3,251:15)
Block(-4,0,4,159:15)
Block(-4,0,5,159:15)
Block(-4,0,6,159:15)
Block(-4,0,7,251:15)
Block(-4,0,8,159:15)
Block(-4,1,-7,251:15)
Block(-4,1,-6,251:15)
Block(-4,1,-5,251:15)
Block(-4,1,-4,251:15)
Block(-4,1,-3,159:15)
Block(-4,1,-2,159:15)
Block(-4,1,-1,251:15)
Block(-4,1,0,251:15)
Block(-4,1,1,159:15)
Block(-4,1,2,159:15)
Block(-4,1,3,251:15)
Block(-4,1,4,159:15)
Block(-4,1,5,251:15)
Block(-4,1,6,251:15)
Block(-4,1,7,251:15)
Block(-4,1,8,159:15)
Block(-4,2,-7,251:15)
Block(-4,2,-6,251:15)
Block(-4,2,-5,159:15)
Block(-4,2,-4,251:15)
Block(-4,2,-3,159:15)
Block(-4,2,-2,251:15)
Block(-4,2,-1,251:15)
Block(-4,2,0,159:15)
Block(-4,2,1,251:15)
Block(-4,2,2,251:15)
Block(-4,2,3,251:15)
Block(-4,2,4,159:15)
Block(-4,2,5,251:15)
Block(-4,2,6,251:15)
Block(-4,2,7,251:15)
Block(-4,2,8,159:15)
Block(-4,3,-7,251:15)
Block(-4,3,-6,159:15)
Block(-4,3,-5,251:15)
Block(-4,3,-4,251:15)
Block(-4,3,-3,251:15)
Block(-4,3,-2,251:15)
Block(-4,3,-1,251:15)
Block(-4,3,0,159:15)
Block(-4,3,1,251:15)
Block(-4,3,2,159:15)
Block(-4,3,3,251:15)
Block(-4,3,4,251:15)
Block(-4,3,5,251:15)
Block(-4,3,6,159:15)
Block(-4,3,7,251:15)
Block(-4,3,8,159:15)
Block(-4,4,-7,251:15)
Block(-4,4,-6,159:15)
Block(-4,4,-5,251:15)
Block(-4,4,-4,251:15)
Block(-4,4,-3,251:15)
Block(-4,4,-2,251:15)
Block(-4,4,-1,251:15)
Block(-4,4,0,251:15)
Block(-4,4,1,159:15)
Block(-4,4,2,159:15)
Block(-4,4,3,159:15)
Block(-4,4,4,159:15)
Block(-4,4,5,159:15)
Block(-4,4,6,159:15)
Block(-4,4,7,159:15)
Block(-4,4,8,251:15)
Block(-4,5,-7,159:15)
Block(-4,5,-6,251:15)
Block(-4,5,-5,251:15)
Block(-4,5,-4,159:15)
Block(-4,5,-3,251:15)
Block(-4,5,-2,251:15)
Block(-4,5,-1,251:15)
Block(-4,5,0,251:15)
Block(-4,5,1,251:15)
Block(-4,5,2,251:15)
Block(-4,5,3,159:15)
Block(-4,5,4,251:15)
Block(-4,5,5,251:15)
Block(-4,5,6,159:15)
Block(-4,5,7,251:15)
Block(-4,5,8,159:15)
Block(-4,6,-7,251:15)
Block(-4,6,-6,251:15)
Block(-4,6,-5,159:15)
Block(-4,6,-4,251:15)
Block(-4,6,-3,159:15)
Block(-4,6,-2,159:15)
Block(-4,6,-1,251:15)
Block(-4,6,0,251:15)
Block(-4,6,1,251:15)
Block(-4,6,2,251:15)
Block(-4,6,3,251:15)
Block(-4,6,4,159:15)
Block(-4,6,5,251:15)
Block(-4,6,6,251:15)
Block(-4,6,7,159:15)
Block(-4,6,8,159:15)
Block(-4,7,-7,159:15)
Block(-4,7,-6,251:15)
Block(-4,7,-5,251:15)
Block(-4,7,-4,159:15)
Block(-4,7,-3,251:15)
Block(-4,7,-2,251:15)
Block(-4,7,-1,159:15)
Block(-4,7,0,251:15)
Block(-4,7,1,251:15)
Block(-4,7,2,159:15)
Block(-4,7,3,159:15)
Block(-4,7,4,159:15)
Block(-4,7,5,251:15)
Block(-4,7,6,159:15)
Block(-4,7,7,251:15)
Block(-4,7,8,159:15)
Block(-4,8,-7,159:15)
Block(-4,8,-6,159:15)
Block(-4,8,-5,159:15)
Block(-4,8,-4,159:15)
Block(-4,8,-3,251:15)
Block(-4,8,-2,251:15)
Block(-4,8,-1,159:15)
Block(-4,8,0,251:15)
Block(-4,8,1,251:15)
Block(-4,8,2,159:15)
Block(-4,8,3,159:15)
Block(-4,8,4,159:15)
Block(-4,8,5,251:15)
Block(-4,8,6,251:15)
Block(-4,8,7,251:15)
Block(-4,8,8,251:15)
Block(-4,9,-7,251:15)
Block(-4,9,-6,251:15)
Block(-4,9,-5,159:15)
Block(-4,9,-4,159:15)
Block(-4,9,-3,159:15)
Block(-4,9,-2,251:15)
Block(-4,9,-1,251:15)
Block(-4,9,0,251:15)
Block(-4,9,1,251:15)
Block(-4,9,2,251:15)
Block(-4,9,3,159:15)
Block(-4,9,4,159:15)
Block(-4,9,5,159:15)
Block(-4,9,6,251:15)
Block(-4,9,7,251:15)
Block(-4,9,8,159:15)
Block(-4,10,-7,251:15)
Block(-4,10,-6,251:15)
Block(-4,10,-5,159:15)
Block(-4,10,-4,251:15)
Block(-4,10,-3,251:15)
Block(-4,10,-2,251:15)
Block(-4,10,-1,159:15)
Block(-4,10,0,251:15)
Block(-4,10,1,159:15)
Block(-4,10,2,159:15)
Block(-4,10,3,251:15)
Block(-4,10,4,251:15)
Block(-4,10,5,159:15)
Block(-4,10,6,159:15)
Block(-4,10,7,159:15)
Block(-4,10,8,251:15)
Block(-4,11,-7,159:15)
Block(-4,11,-6,251:15)
Block(-4,11,-5,251:15)
Block(-4,11,-4,159:15)
Block(-4,11,-3,159:15)
Block(-4,11,-2,159:15)
Block(-4,11,-1,251:15)
Block(-4,11,0,251:15)
Block(-4,11,1,159:15)
Block(-4,11,2,251:15)
Block(-4,11,3,159:15)
Block(-4,11,4,251:15)
Block(-4,11,5,159:15)
Block(-4,11,6,159:15)
Block(-4,11,7,159:15)
Block(-4,11,8,159:15)
Block(-4,12,-7,251:15)
Block(-4,12,-6,251:15)
Block(-4,12,-5,251:15)
Block(-4,12,-4,251:15)
Block(-4,12,-3,159:15)
Block(-4,12,-2,159:15)
Block(-4,12,-1,251:15)
Block(-4,12,0,159:15)
Block(-4,12,1,159:15)
Block(-4,12,2,159:15)
Block(-4,12,3,251:15)
Block(-4,12,4,251:15)
Block(-4,12,5,251:15)
Block(-4,12,6,159:15)
Block(-4,12,7,159:15)
Block(-4,12,8,159:15)
Block(-4,13,-7,159:15)
Block(-4,13,-6,159:15)
Block(-4,13,-5,251:15)
Block(-4,13,-4,251:15)
Block(-4,13,-3,251:15)
Block(-4,13,-2,159:15)
Block(-4,13,-1,159:15)
Block(-4,13,0,159:15)
Block(-4,13,1,159:15)
Block(-4,13,2,251:15)
Block(-4,13,3,251:15)
Block(-4,13,4,159:15)
Block(-4,13,5,251:15)
Block(-4,13,6,159:15)
Block(-4,13,7,159:15)
Block(-4,13,8,251:15)
Block(-4,14,-7,159:15)
Block(-4,14,-6,251:15)
Block(-4,14,-5,159:15)
Block(-4,14,-4,159:15)
Block(-4,14,-3,251:15)
Block(-4,14,-2,251:15)
Block(-4,14,-1,251:15)
Block(-4,14,0,159:15)
Block(-4,14,1,251:15)
Block(-4,14,2,251:15)
Block(-4,14,3,251:15)
Block(-4,14,4,251:15)
Block(-4,14,5,251:15)
Block(-4,14,6,159:15)
Block(-4,14,7,159:15)
Block(-4,14,8,251:15)
Block(-4,15,-7,159:15)
Block(-4,15,-6,159:15)
Block(-4,15,-5,159:15)
Block(-4,15,-4,159:15)
Block(-4,15,-3,251:15)
Block(-4,15,-2,159:15)
Block(-4,15,-1,159:15)
Block(-4,15,0,251:15)
Block(-4,15,1,159:15)
Block(-4,15,2,159:15)
Block(-4,15,3,159:15)
Block(-4,15,4,159:15)
Block(-4,15,5,159:15)
Block(-4,15,6,251:15)
Block(-4,15,7,159:15)
Block(-4,15,8,251:15)
Block(-4,16,-7,159:15)
Block(-4,16,-6,159:15)
Block(-4,16,-5,251:15)
Block(-4,16,-4,159:15)
Block(-4,16,-3,251:15)
Block(-4,16,-2,159:15)
Block(-4,16,-1,159:15)
Block(-4,16,0,159:15)
Block(-4,16,1,251:15)
Block(-4,16,2,251:15)
Block(-4,16,3,159:15)
Block(-4,16,4,159:15)
Block(-4,16,5,251:15)
Block(-4,16,6,251:15)
Block(-4,16,7,159:15)
Block(-4,16,8,251:15)
Block(-4,17,-7,251:15)
Block(-4,17,-6,251:15)
Block(-4,17,-5,159:15)
Block(-4,17,-4,159:15)
Block(-4,17,-3,159:15)
Block(-4,17,-2,251:15)
Block(-4,17,-1,251:15)
Block(-4,17,0,159:15)
Block(-4,17,1,159:15)
Block(-4,17,2,159:15)
Block(-4,17,3,159:15)
Block(-4,17,4,251:15)
Block(-4,17,5,251:15)
Block(-4,17,6,159:15)
Block(-4,17,7,251:15)
Block(-4,17,8,159:15)
Block(-4,18,-3,251:15)
Block(-4,18,-2,251:15)
Block(-4,18,-1,251:15)
Block(-4,18,0,159:15)
Block(-4,18,1,159:15)
Block(-4,18,2,251:15)
Block(-4,18,3,159:15)
Block(-4,18,4,159:15)
Block(-4,18,5,159:15)
Block(-4,18,6,251:15)
Block(-4,18,7,251:15)
Block(-4,18,8,159:15)
Block(-4,19,-3,159:15)
Block(-4,19,-2,159:15)
Block(-4,19,-1,251:15)
Block(-4,19,0,251:15)
Block(-4,19,1,251:15)
Block(-4,19,2,159:15)
Block(-4,19,3,251:15)
Block(-4,19,4,251:15)
Block(-4,19,5,159:15)
Block(-4,19,6,251:15)
Block(-4,19,7,159:15)
Block(-4,19,8,251:15)
Block(-4,20,-3,251:15)
Block(-4,20,-2,251:15)
Block(-4,20,-1,251:15)
Block(-4,20,0,251:15)
Block(-4,20,1,159:15)
Block(-4,20,2,251:15)
Block(-4,20,3,251:15)
Block(-4,20,4,159:15)
Block(-4,20,5,159:15)
Block(-4,20,6,159:15)
Block(-4,20,7,159:15)
Block(-4,20,8,251:15)
Block(-4,21,-3,251:15)
Block(-4,21,-2,251:15)
Block(-4,21,-1,159:15)
Block(-4,21,0,251:15)
Block(-4,21,1,251:15)
Block(-4,21,2,251:15)
Block(-4,21,3,159:15)
Block(-4,21,4,251:15)
Block(-4,21,5,251:15)
Block(-4,21,6,251:15)
Block(-4,21,7,251:15)
Block(-4,21,8,159:15)
Block(-4,22,-3,159:15)
Block(-4,22,-2,251:15)
Block(-4,22,-1,251:15)
Block(-4,22,0,251:15)
Block(-4,22,1,251:15)
Block(-4,22,2,159:15)
Block(-4,22,3,251:15)
Block(-4,22,4,159:15)
Block(-4,22,5,159:15)
Block(-4,22,6,251:15)
Block(-4,22,7,251:15)
Block(-4,22,8,251:15)
Block(-4,23,-3,251:15)
Block(-4,23,-2,251:15)
Block(-4,23,-1,251:15)
Block(-4,23,0,251:15)
Block(-4,23,1,251:15)
Block(-4,23,2,159:15)
Block(-4,23,3,251:15)
Block(-4,23,4,159:15)
Block(-4,23,5,159:15)
Block(-4,23,6,251:15)
Block(-4,23,7,159:15)
Block(-4,23,8,159:15)
Block(-4,24,-3,159:15)
Block(-4,24,-2,251:15)
Block(-4,24,-1,159:15)
Block(-4,24,0,251:15)
Block(-4,24,1,159:15)
Block(-4,24,2,251:15)
Block(-4,24,3,159:15)
Block(-4,24,4,159:15)
Block(-4,24,5,159:15)
Block(-4,24,6,159:15)
Block(-4,24,7,159:15)
Block(-4,24,8,251:15)
Block(-4,25,-3,159:15)
Block(-4,25,-2,251:15)
Block(-4,25,-1,251:15)
Block(-4,25,0,251:15)
Block(-4,25,1,159:15)
Block(-4,25,2,251:15)
Block(-4,25,3,159:15)
Block(-4,25,4,159:15)
Block(-4,25,5,159:15)
Block(-4,25,6,251:15)
Block(-4,25,7,159:15)
Block(-4,25,8,251:15)
Block(-4,26,-3,251:15)
Block(-4,26,-2,159:15)
Block(-4,26,-1,159:15)
Block(-4,26,0,159:15)
Block(-4,26,1,251:15)
Block(-4,26,2,251:15)
Block(-4,26,3,251:15)
Block(-4,26,4,159:15)
Block(-4,26,5,251:15)
Block(-4,26,8,159:15)
Block(-4,27,-3,251:15)
Block(-4,27,-2,251:15)
Block(-4,27,-1,159:15)
Block(-4,27,0,159:15)
Block(-4,27,1,251:15)
Block(-4,27,2,251:15)
Block(-4,27,3,159:15)
Block(-4,27,4,251:15)
Block(-4,27,5,159:15)
Block(-4,27,8,159:15)
Block(-4,28,-3,251:15)
Block(-4,28,-2,251:15)
Block(-4,28,-1,159:15)
Block(-4,28,0,159:15)
Block(-4,28,1,251:15)
Block(-4,28,2,159:15)
Block(-4,28,3,159:15)
Block(-4,28,4,251:15)
Block(-4,28,5,159:15)
Block(-4,28,8,159:15)
Block(-4,29,-3,251:15)
Block(-4,29,-2,159:15)
Block(-4,29,-1,251:15)
Block(-4,29,0,159:15)
Block(-4,29,1,159:15)
Block(-4,29,2,159:15)
Block(-4,29,3,159:15)
Block(-4,29,4,251:15)
Block(-4,29,5,251:15)
Block(-4,29,8,251:15)
Block(-4,30,-3,159:15)
Block(-4,30,-2,159:15)
Block(-4,30,-1,251:15)
Block(-4,30,0,159:15)
Block(-4,30,1,251:15)
Block(-4,30,2,159:15)
Block(-4,30,3,159:15)
Block(-4,30,4,159:15)
Block(-4,30,5,251:15)
Block(-4,30,8,251:15)
Block(-4,31,-3,251:15)
Block(-4,31,-2,251:15)
Block(-4,31,-1,159:15)
Block(-4,31,0,251:15)
Block(-4,31,1,251:15)
Block(-4,31,2,251:15)
Block(-4,31,3,159:15)
Block(-4,31,4,251:15)
Block(-4,31,5,251:15)
Block(-4,31,8,159:15)
Block(-4,32,-3,159:15)
Block(-4,32,-2,251:15)
Block(-4,32,-1,251:15)
Block(-4,32,0,159:15)
Block(-4,32,1,251:15)
Block(-4,32,2,251:15)
Block(-4,32,3,159:15)
Block(-4,32,4,251:15)
Block(-4,32,5,251:15)
Block(-4,32,8,251:15)
Block(-4,33,-3,251:15)
Block(-4,33,-2,251:15)
Block(-4,33,-1,251:15)
Block(-4,33,0,159:15)
Block(-4,33,1,159:15)
Block(-4,33,2,159:15)
Block(-4,33,3,159:15)
Block(-4,33,4,159:15)
Block(-4,33,5,159:15)
Block(-4,34,-3,251:15)
Block(-4,34,-2,159:15)
Block(-4,34,-1,159:15)
Block(-4,34,0,159:15)
Block(-4,34,1,159:15)
Block(-4,34,2,251:15)
Block(-4,34,3,159:15)
Block(-4,34,4,251:15)
Block(-4,34,5,159:15)
Block(-4,35,-3,251:15)
Block(-4,35,-2,251:15)
Block(-4,35,-1,159:15)
Block(-4,35,0,159:15)
Block(-4,35,1,159:15)
Block(-4,35,2,159:15)
Block(-4,35,3,251:15)
Block(-4,35,4,159:15)
Block(-4,35,5,251:15)
Block(-4,36,-3,159:15)
Block(-4,36,-2,159:15)
Block(-4,36,-1,159:15)
Block(-4,36,0,251:15)
Block(-4,36,1,159:15)
Block(-4,36,2,251:15)
Block(-4,36,3,159:15)
Block(-4,36,4,251:15)
Block(-4,36,5,159:15)
Block(-4,37,-3,159:15)
Block(-4,37,-2,159:15)
Block(-4,37,-1,251:15)
Block(-4,37,0,251:15)
Block(-4,37,1,251:15)
Block(-4,37,2,159:15)
Block(-4,37,3,251:15)
Block(-4,37,4,159:15)
Block(-4,37,5,251:15)
Block(-4,38,-3,159:15)
Block(-4,38,-2,159:15)
Block(-4,38,-1,251:15)
Block(-4,38,0,159:15)
Block(-4,38,1,251:15)
Block(-4,38,2,251:15)
Block(-4,38,3,159:15)
Block(-4,38,4,251:15)
Block(-4,38,5,159:15)
Block(-4,39,-3,251:15)
Block(-4,39,-2,251:15)
Block(-4,39,-1,251:15)
Block(-4,39,0,251:15)
Block(-4,39,1,159:15)
Block(-4,39,2,251:15)
Block(-4,39,3,251:15)
Block(-4,39,4,251:15)
Block(-4,39,5,159:15)
Block(-4,40,-3,251:15)
Block(-4,40,-2,251:15)
Block(-4,40,-1,251:15)
Block(-4,40,0,251:15)
Block(-4,40,1,251:15)
Block(-4,40,2,251:15)
Block(-4,40,3,251:15)
Block(-4,40,4,251:15)
Block(-4,40,5,159:15)
Block(-3,0,-7,159:15)
Block(-3,0,-6,251:15)
Block(-3,0,-5,159:15)
Block(-3,0,-4,251:15)
Block(-3,0,-3,251:15)
Block(-3,0,-2,251:15)
Block(-3,0,-1,159:15)
Block(-3,0,0,159:15)
Block(-3,0,1,159:15)
Block(-3,0,2,159:15)
Block(-3,0,3,251:15)
Block(-3,0,4,159:15)
Block(-3,0,5,251:15)
Block(-3,0,6,251:15)
Block(-3,0,7,159:15)
Block(-3,0,8,159:15)
Block(-3,1,-7,159:15)
Block(-3,1,-6,159:15)
Block(-3,1,-5,159:15)
Block(-3,1,-4,159:15)
Block(-3,1,-3,159:15)
Block(-3,1,-2,159:15)
Block(-3,1,-1,159:15)
Block(-3,1,0,159:15)
Block(-3,1,1,159:15)
Block(-3,1,2,251:15)
Block(-3,1,3,251:15)
Block(-3,1,4,251:15)
Block(-3,1,5,251:15)
Block(-3,1,6,251:15)
Block(-3,1,7,251:15)
Block(-3,1,8,159:15)
Block(-3,2,-7,251:15)
Block(-3,2,-6,159:15)
Block(-3,2,-5,251:15)
Block(-3,2,-4,159:15)
Block(-3,2,-3,159:15)
Block(-3,2,-2,159:15)
Block(-3,2,-1,159:15)
Block(-3,2,0,251:15)
Block(-3,2,1,159:15)
Block(-3,2,2,159:15)
Block(-3,2,3,159:15)
Block(-3,2,4,251:15)
Block(-3,2,5,159:15)
Block(-3,2,6,159:15)
Block(-3,2,7,251:15)
Block(-3,2,8,251:15)
Block(-3,3,-7,159:15)
Block(-3,3,-6,159:15)
Block(-3,3,-5,159:15)
Block(-3,3,-4,159:15)
Block(-3,3,-3,251:15)
Block(-3,3,-2,159:15)
Block(-3,3,-1,159:15)
Block(-3,3,0,251:15)
Block(-3,3,1,159:15)
Block(-3,3,2,159:15)
Block(-3,3,3,159:15)
Block(-3,3,4,159:15)
Block(-3,3,5,159:15)
Block(-3,3,6,251:15)
Block(-3,3,7,159:15)
Block(-3,3,8,159:15)
Block(-3,4,-7,159:15)
Block(-3,4,-6,251:15)
Block(-3,4,-5,251:15)
Block(-3,4,-4,159:15)
Block(-3,4,-3,251:15)
Block(-3,4,-2,159:15)
Block(-3,4,-1,159:15)
Block(-3,4,0,159:15)
Block(-3,4,1,159:15)
Block(-3,4,2,251:15)
Block(-3,4,3,159:15)
Block(-3,4,4,251:15)
Block(-3,4,5,159:15)
Block(-3,4,6,159:15)
Block(-3,4,7,251:15)
Block(-3,4,8,251:15)
Block(-3,5,-7,251:15)
Block(-3,5,-6,251:15)
Block(-3,5,-5,251:15)
Block(-3,5,-4,159:15)
Block(-3,5,-3,159:15)
Block(-3,5,-2,251:15)
Block(-3,5,-1,251:15)
Block(-3,5,0,159:15)
Block(-3,5,1,251:15)
Block(-3,5,2,251:15)
Block(-3,5,3,159:15)
Block(-3,5,4,251:15)
Block(-3,5,5,251:15)
Block(-3,5,6,159:15)
Block(-3,5,7,159:15)
Block(-3,5,8,159:15)
Block(-3,6,-7,159:15)
Block(-3,6,-6,159:15)
Block(-3,6,-5,251:15)
Block(-3,6,-4,251:15)
Block(-3,6,-3,159:15)
Block(-3,6,-2,159:15)
Block(-3,6,-1,251:15)
Block(-3,6,0,159:15)
Block(-3,6,1,159:15)
Block(-3,6,2,251:15)
Block(-3,6,3,251:15)
Block(-3,6,4,159:15)
Block(-3,6,5,251:15)
Block(-3,6,6,159:15)
Block(-3,6,7,159:15)
Block(-3,6,8,251:15)
Block(-3,7,-7,159:15)
Block(-3,7,-6,159:15)
Block(-3,7,-5,251:15)
Block(-3,7,-4,159:15)
Block(-3,7,-3,159:15)
Block(-3,7,-2,159:15)
Block(-3,7,-1,159:15)
Block(-3,7,0,159:15)
Block(-3,7,1,159:15)
Block(-3,7,2,251:15)
Block(-3,7,3,251:15)
Block(-3,7,4,251:15)
Block(-3,7,5,159:15)
Block(-3,7,6,159:15)
Block(-3,7,7,251:15)
Block(-3,7,8,159:15)
Block(-3,8,-7,251:15)
Block(-3,8,-6,251:15)
Block(-3,8,-5,251:15)
Block(-3,8,-4,251:15)
Block(-3,8,-3,251:15)
Block(-3,8,-2,251:15)
Block(-3,8,-1,251:15)
Block(-3,8,0,251:15)
Block(-3,8,1,159:15)
Block(-3,8,2,251:15)
Block(-3,8,3,251:15)
Block(-3,8,4,159:15)
Block(-3,8,5,159:15)
Block(-3,8,6,251:15)
Block(-3,8,7,251:15)
Block(-3,8,8,159:15)
Block(-3,9,-7,251:15)
Block(-3,9,-6,159:15)
Block(-3,9,-5,159:15)
Block(-3,9,-4,251:15)
Block(-3,9,-3,159:15)
Block(-3,9,-2,251:15)
Block(-3,9,-1,159:15)
Block(-3,9,0,159:15)
Block(-3,9,1,251:15)
Block(-3,9,2,159:15)
Block(-3,9,3,159:15)
Block(-3,9,4,159:15)
Block(-3,9,5,159:15)
Block(-3,9,6,251:15)
Block(-3,9,7,251:15)
Block(-3,9,8,251:15)
Block(-3,10,-7,251:15)
Block(-3,10,-6,159:15)
Block(-3,10,-5,159:15)
Block(-3,10,-4,159:15)
Block(-3,10,-3,159:15)
Block(-3,10,-2,159:15)
Block(-3,10,-1,251:15)
Block(-3,10,0,251:15)
Block(-3,10,1,159:15)
Block(-3,10,2,251:15)
Block(-3,10,3,251:15)
Block(-3,10,4,251:15)
Block(-3,10,5,251:15)
Block(-3,10,6,159:15)
Block(-3,10,7,159:15)
Block(-3,10,8,251:15)
Block(-3,11,-7,159:15)
Block(-3,11,-6,251:15)
Block(-3,11,-5,159:15)
Block(-3,11,-4,159:15)
Block(-3,11,-3,159:15)
Block(-3,11,-2,251:15)
Block(-3,11,-1,251:15)
Block(-3,11,0,159:15)
Block(-3,11,1,251:15)
Block(-3,11,2,251:15)
Block(-3,11,3,251:15)
Block(-3,11,4,159:15)
Block(-3,11,5,159:15)
Block(-3,11,6,159:15)
Block(-3,11,7,251:15)
Block(-3,11,8,159:15)
Block(-3,12,-7,251:15)
Block(-3,12,-6,251:15)
Block(-3,12,-5,159:15)
Block(-3,12,-4,251:15)
Block(-3,12,-3,251:15)
Block(-3,12,-2,251:15)
Block(-3,12,-1,159:15)
Block(-3,12,0,159:15)
Block(-3,12,1,251:15)
Block(-3,12,2,251:15)
Block(-3,12,3,159:15)
Block(-3,12,4,251:15)
Block(-3,12,5,159:15)
Block(-3,12,6,159:15)
Block(-3,12,7,159:15)
Block(-3,12,8,159:15)
Block(-3,13,-7,159:15)
Block(-3,13,-6,251:15)
Block(-3,13,-5,159:15)
Block(-3,13,-4,159:15)
Block(-3,13,-3,251:15)
Block(-3,13,-2,251:15)
Block(-3,13,-1,159:15)
Block(-3,13,0,159:15)
Block(-3,13,1,251:15)
Block(-3,13,2,159:15)
Block(-3,13,3,159:15)
Block(-3,13,4,251:15)
Block(-3,13,5,251:15)
Block(-3,13,6,251:15)
Block(-3,13,7,251:15)
Block(-3,13,8,159:15)
Block(-3,14,-7,159:15)
Block(-3,14,-6,159:15)
Block(-3,14,-5,251:15)
Block(-3,14,-4,251:15)
Block(-3,14,-3,159:15)
Block(-3,14,-2,159:15)
Block(-3,14,-1,159:15)
Block(-3,14,0,251:15)
Block(-3,14,1,159:15)
Block(-3,14,2,159:15)
Block(-3,14,3,251:15)
Block(-3,14,4,251:15)
Block(-3,14,5,251:15)
Block(-3,14,6,251:15)
Block(-3,14,7,251:15)
Block(-3,14,8,251:15)
Block(-3,15,-7,251:15)
Block(-3,15,-6,159:15)
Block(-3,15,-5,251:15)
Block(-3,15,-4,251:15)
Block(-3,15,-3,159:15)
Block(-3,15,-2,159:15)
Block(-3,15,-1,251:15)
Block(-3,15,0,251:15)
Block(-3,15,1,159:15)
Block(-3,15,2,251:15)
Block(-3,15,3,251:15)
Block(-3,15,4,159:15)
Block(-3,15,5,159:15)
Block(-3,15,6,159:15)
Block(-3,15,7,251:15)
Block(-3,15,8,251:15)
Block(-3,16,-7,159:15)
Block(-3,16,-6,251:15)
Block(-3,16,-5,251:15)
Block(-3,16,-4,159:15)
Block(-3,16,-3,159:15)
Block(-3,16,-2,159:15)
Block(-3,16,-1,159:15)
Block(-3,16,0,251:15)
Block(-3,16,1,251:15)
Block(-3,16,2,159:15)
Block(-3,16,3,251:15)
Block(-3,16,4,159:15)
Block(-3,16,5,251:15)
Block(-3,16,6,251:15)
Block(-3,16,7,251:15)
Block(-3,16,8,251:15)
Block(-3,17,-7,251:15)
Block(-3,17,-6,159:15)
Block(-3,17,-5,159:15)
Block(-3,17,-4,251:15)
Block(-3,17,-3,251:15)
Block(-3,17,-2,251:15)
Block(-3,17,-1,159:15)
Block(-3,17,0,159:15)
Block(-3,17,1,251:15)
Block(-3,17,2,251:15)
Block(-3,17,3,159:15)
Block(-3,17,4,251:15)
Block(-3,17,5,251:15)
Block(-3,17,6,251:15)
Block(-3,17,7,159:15)
Block(-3,17,8,159:15)
Block(-3,18,-4,251:15)
Block(-3,18,-3,251:15)
Block(-3,18,-2,251:15)
Block(-3,18,-1,159:15)
Block(-3,18,0,159:15)
Block(-3,18,1,159:15)
Block(-3,18,2,159:15)
Block(-3,18,3,159:15)
Block(-3,18,4,251:15)
Block(-3,18,5,159:15)
Block(-3,18,6,159:15)
Block(-3,18,7,251:15)
Block(-3,18,8,159:15)
Block(-3,19,-4,159:15)
Block(-3,19,-3,159:15)
Block(-3,19,-2,159:15)
Block(-3,19,-1,251:15)
Block(-3,19,0,159:15)
Block(-3,19,1,159:15)
Block(-3,19,2,251:15)
Block(-3,19,3,251:15)
Block(-3,19,4,159:15)
Block(-3,19,5,251:15)
Block(-3,19,6,159:15)
Block(-3,19,7,159:15)
Block(-3,19,8,251:15)
Block(-3,20,-4,251:15)
Block(-3,20,-3,251:15)
Block(-3,20,-2,251:15)
Block(-3,20,-1,251:15)
Block(-3,20,0,159:15)
Block(-3,20,1,251:15)
Block(-3,20,2,251:15)
Block(-3,20,3,159:15)
Block(-3,20,4,159:15)
Block(-3,20,5,251:15)
Block(-3,20,6,159:15)
Block(-3,20,7,159:15)
Block(-3,20,8,159:15)
Block(-3,21,-4,251:15)
Block(-3,21,-3,251:15)
Block(-3,21,-2,159:15)
Block(-3,21,-1,159:15)
Block(-3,21,0,159:15)
Block(-3,21,1,159:15)
Block(-3,21,2,159:15)
Block(-3,21,3,159:15)
Block(-3,21,4,159:15)
Block(-3,21,5,251:15)
Block(-3,21,6,159:15)
Block(-3,21,7,251:15)
Block(-3,21,8,251:15)
Block(-3,22,-4,159:15)
Block(-3,22,-3,251:15)
Block(-3,22,-2,251:15)
Block(-3,22,-1,251:15)
Block(-3,22,0,159:15)
Block(-3,22,1,159:15)
Block(-3,22,2,251:15)
Block(-3,22,3,159:15)
Block(-3,22,4,159:15)
Block(-3,22,5,159:15)
Block(-3,22,6,251:15)
Block(-3,22,7,159:15)
Block(-3,22,8,159:15)
Block(-3,23,-4,159:15)
Block(-3,23,-3,251:15)
Block(-3,23,-2,251:15)
Block(-3,23,-1,159:15)
Block(-3,23,0,159:15)
Block(-3,23,1,251:15)
Block(-3,23,2,251:15)
Block(-3,23,3,251:15)
Block(-3,23,4,159:15)
Block(-3,23,5,251:15)
Block(-3,23,6,159:15)
Block(-3,23,7,159:15)
Block(-3,23,8,159:15)
Block(-3,24,-4,159:15)
Block(-3,24,-3,251:15)
Block(-3,24,-2,159:15)
Block(-3,24,-1,159:15)
Block(-3,24,0,251:15)
Block(-3,24,1,251:15)
Block(-3,24,2,251:15)
Block(-3,24,3,251:15)
Block(-3,24,4,251:15)
Block(-3,24,5,251:15)
Block(-3,24,6,159:15)
Block(-3,24,7,159:15)
Block(-3,24,8,159:15)
Block(-3,25,-4,251:15)
Block(-3,25,-3,251:15)
Block(-3,25,-2,251:15)
Block(-3,25,-1,251:15)
Block(-3,25,0,251:15)
Block(-3,25,1,251:15)
Block(-3,25,2,159:15)
Block(-3,25,3,159:15)
Block(-3,25,4,159:15)
Block(-3,25,5,159:15)
Block(-3,25,6,251:15)
Block(-3,25,7,251:15)
Block(-3,25,8,251:15)
Block(-3,26,-4,251:15)
Block(-3,26,-3,159:15)
Block(-3,26,-2,251:15)
Block(-3,26,-1,251:15)
Block(-3,26,0,251:15)
Block(-3,26,1,159:15)
Block(-3,26,2,159:15)
Block(-3,26,3,159:15)
Block(-3,26,4,251:15)
Block(-3,26,5,251:15)
Block(-3,26,6,159:15)
Block(-3,26,7,159:15)
Block(-3,26,8,251:15)
Block(-3,27,-4,159:15)
Block(-3,27,-3,159:15)
Block(-3,27,-2,251:15)
Block(-3,27,-1,159:15)
Block(-3,27,0,159:15)
Block(-3,27,1,159:15)
Block(-3,27,2,251:15)
Block(-3,27,3,159:15)
Block(-3,27,4,251:15)
Block(-3,27,5,159:15)
Block(-3,27,6,159:15)
Block(-3,27,7,159:15)
Block(-3,27,8,159:15)
Block(-3,28,-4,251:15)
Block(-3,28,-3,251:15)
Block(-3,28,-2,159:15)
Block(-3,28,-1,251:15)
Block(-3,28,0,251:15)
Block(-3,28,1,159:15)
Block(-3,28,2,251:15)
Block(-3,28,3,251:15)
Block(-3,28,4,159:15)
Block(-3,28,5,159:15)
Block(-3,28,6,159:15)
Block(-3,28,7,251:15)
Block(-3,28,8,251:15)
Block(-3,29,-4,251:15)
Block(-3,29,-3,159:15)
Block(-3,29,-2,159:15)
Block(-3,29,-1,251:15)
Block(-3,29,0,251:15)
Block(-3,29,1,251:15)
Block(-3,29,2,251:15)
Block(-3,29,3,159:15)
Block(-3,29,4,159:15)
Block(-3,29,5,159:15)
Block(-3,29,6,159:15)
Block(-3,29,7,159:15)
Block(-3,29,8,251:15)
Block(-3,30,-4,159:15)
Block(-3,30,-3,251:15)
Block(-3,30,-2,251:15)
Block(-3,30,-1,159:15)
Block(-3,30,0,159:15)
Block(-3,30,1,159:15)
Block(-3,30,2,159:15)
Block(-3,30,3,159:15)
Block(-3,30,4,251:15)
Block(-3,30,5,159:15)
Block(-3,30,6,251:15)
Block(-3,30,7,251:15)
Block(-3,30,8,251:15)
Block(-3,31,-4,159:15)
Block(-3,31,-3,159:15)
Block(-3,31,-2,159:15)
Block(-3,31,-1,251:15)
Block(-3,31,0,251:15)
Block(-3,31,1,251:15)
Block(-3,31,2,251:15)
Block(-3,31,3,159:15)
Block(-3,31,4,159:15)
Block(-3,31,5,159:15)
Block(-3,31,6,159:15)
Block(-3,31,7,251:15)
Block(-3,31,8,251:15)
Block(-3,32,-4,159:15)
Block(-3,32,-3,251:15)
Block(-3,32,-2,251:15)
Block(-3,32,-1,159:15)
Block(-3,32,0,159:15)
Block(-3,32,1,159:15)
Block(-3,32,2,159:15)
Block(-3,32,3,251:15)
Block(-3,32,4,251:15)
Block(-3,32,5,159:15)
Block(-3,32,6,159:15)
Block(-3,32,7,159:15)
Block(-3,32,8,159:15)
Block(-3,33,-4,251:15)
Block(-3,33,-3,251:15)
Block(-3,33,-2,251:15)
Block(-3,33,-1,251:15)
Block(-3,33,0,159:15)
Block(-3,33,1,159:15)
Block(-3,33,2,251:15)
Block(-3,33,3,159:15)
Block(-3,33,4,251:15)
Block(-3,33,5,251:15)
Block(-3,33,6,159:15)
Block(-3,34,-4,159:15)
Block(-3,34,-3,251:15)
Block(-3,34,-2,159:15)
Block(-3,34,-1,251:15)
Block(-3,34,0,251:15)
Block(-3,34,1,159:15)
Block(-3,34,2,159:15)
Block(-3,34,3,159:15)
Block(-3,34,4,251:15)
Block(-3,34,5,159:15)
Block(-3,34,6,251:15)
Block(-3,35,-4,159:15)
Block(-3,35,-3,159:15)
Block(-3,35,-2,251:15)
Block(-3,35,-1,251:15)
Block(-3,35,0,159:15)
Block(-3,35,1,251:15)
Block(-3,35,2,251:15)
Block(-3,35,3,251:15)
Block(-3,35,4,159:15)
Block(-3,35,5,251:15)
Block(-3,35,6,251:15)
Block(-3,36,-4,251:15)
Block(-3,36,-3,159:15)
Block(-3,36,-2,251:15)
Block(-3,36,-1,251:15)
Block(-3,36,0,251:15)
Block(-3,36,1,159:15)
Block(-3,36,2,159:15)
Block(-3,36,3,159:15)
Block(-3,36,4,251:15)
Block(-3,36,5,159:15)
Block(-3,36,6,159:15)
Block(-3,37,-4,251:15)
Block(-3,37,-3,159:15)
Block(-3,37,-2,159:15)
Block(-3,37,-1,251:15)
Block(-3,37,0,159:15)
Block(-3,37,1,251:15)
Block(-3,37,2,159:15)
Block(-3,37,3,159:15)
Block(-3,37,4,251:15)
Block(-3,37,5,159:15)
Block(-3,37,6,159:15)
Block(-3,38,-4,159:15)
Block(-3,38,-3,159:15)
Block(-3,38,-2,159:15)
Block(-3,38,-1,251:15)
Block(-3,38,0,159:15)
Block(-3,38,1,159:15)
Block(-3,38,2,159:15)
Block(-3,38,3,159:15)
Block(-3,38,4,159:15)
Block(-3,38,5,159:15)
Block(-3,38,6,159:15)
Block(-3,39,-4,251:15)
Block(-3,39,-3,251:15)
Block(-3,39,-2,159:15)
Block(-3,39,-1,251:15)
Block(-3,39,0,159:15)
Block(-3,39,1,159:15)
Block(-3,39,2,159:15)
Block(-3,39,3,251:15)
Block(-3,39,4,159:15)
Block(-3,39,5,159:15)
Block(-3,39,6,251:15)
Block(-3,40,-4,251:15)
Block(-3,40,-3,159:15)
Block(-3,40,-2,159:15)
Block(-3,40,-1,251:15)
Block(-3,40,0,159:15)
Block(-3,40,1,251:15)
Block(-3,40,2,159:15)
Block(-3,40,3,251:15)
Block(-3,40,4,251:15)
Block(-3,40,5,251:15)
Block(-3,40,6,251:15)
Block(-2,0,-7,159:15)
Block(-2,0,-6,159:15)
Block(-2,0,-5,251:15)
Block(-2,0,-4,159:15)
Block(-2,0,-3,251:15)
Block(-2,0,-2,159:15)
Block(-2,0,-1,159:15)
Block(-2,0,0,251:15)
Block(-2,0,1,159:15)
Block(-2,0,2,251:15)
Block(-2,0,3,159:15)
Block(-2,0,4,159:15)
Block(-2,0,5,251:15)
Block(-2,0,6,159:15)
Block(-2,0,7,159:15)
Block(-2,0,8,159:15)
Block(-2,1,-7,251:15)
Block(-2,1,-6,251:15)
Block(-2,1,-5,251:15)
Block(-2,1,-4,159:15)
Block(-2,1,-3,159:15)
Block(-2,1,-2,159:15)
Block(-2,1,-1,159:15)
Block(-2,1,0,251:15)
Block(-2,1,1,251:15)
Block(-2,1,2,159:15)
Block(-2,1,3,159:15)
Block(-2,1,4,251:15)
Block(-2,1,5,159:15)
Block(-2,1,6,251:15)
Block(-2,1,7,251:15)
Block(-2,1,8,159:15)
Block(-2,2,-7,251:15)
Block(-2,2,-6,251:15)
Block(-2,2,-5,159:15)
Block(-2,2,-4,251:15)
Block(-2,2,-3,251:15)
Block(-2,2,-2,159:15)
Block(-2,2,-1,159:15)
Block(-2,2,0,251:15)
Block(-2,2,1,251:15)
Block(-2,2,2,251:15)
Block(-2,2,3,159:15)
Block(-2,2,4,159:15)
Block(-2,2,5,251:15)
Block(-2,2,6,251:15)
Block(-2,2,7,251:15)
Block(-2,2,8,251:15)
Block(-2,3,-7,159:15)
Block(-2,3,-6,251:15)
Block(-2,3,-5,251:15)
Block(-2,3,-4,251:15)
Block(-2,3,-3,159:15)
Block(-2,3,-2,251:15)
Block(-2,3,-1,159:15)
Block(-2,3,0,251:15)
Block(-2,3,1,159:15)
Block(-2,3,2,159:15)
Block(-2,3,3,159:15)
Block(-2,3,4,251:15)
Block(-2,3,5,251:15)
Block(-2,3,6,159:15)
Block(-2,3,7,251:15)
Block(-2,3,8,251:15)
Block(-2,4,-7,251:15)
Block(-2,4,-6,159:15)
Block(-2,4,-5,159:15)
Block(-2,4,-4,251:15)
Block(-2,4,-3,159:15)
Block(-2,4,-2,251:15)
Block(-2,4,-1,159:15)
Block(-2,4,0,251:15)
Block(-2,4,1,159:15)
Block(-2,4,2,159:15)
Block(-2,4,3,159:15)
Block(-2,4,4,159:15)
Block(-2,4,5,159:15)
Block(-2,4,6,251:15)
Block(-2,4,7,159:15)
Block(-2,4,8,251:15)
Block(-2,5,-7,159:15)
Block(-2,5,-6,159:15)
Block(-2,5,-5,159:15)
Block(-2,5,-4,159:15)
Block(-2,5,-3,159:15)
Block(-2,5,-2,251:15)
Block(-2,5,-1,159:15)
Block(-2,5,0,159:15)
Block(-2,5,1,251:15)
Block(-2,5,2,251:15)
Block(-2,5,3,159:15)
Block(-2,5,4,159:15)
Block(-2,5,5,159:15)
Block(-2,5,6,251:15)
Block(-2,5,7,159:15)
Block(-2,5,8,251:15)
Block(-2,6,-7,159:15)
Block(-2,6,-6,251:15)
Block(-2,6,-5,159:15)
Block(-2,6,-4,159:15)
Block(-2,6,-3,251:15)
Block(-2,6,-2,159:15)
Block(-2,6,-1,251:15)
Block(-2,6,0,251:15)
Block(-2,6,1,251:15)
Block(-2,6,2,159:15)
Block(-2,6,3,251:15)
Block(-2,6,4,159:15)
Block(-2,6,5,159:15)
Block(-2,6,6,159:15)
Block(-2,6,7,159:15)
Block(-2,6,8,159:15)
Block(-2,7,-7,159:15)
Block(-2,7,-6,159:15)
Block(-2,7,-5,159:15)
Block(-2,7,-4,251:15)
Block(-2,7,-3,159:15)
Block(-2,7,-2,159:15)
Block(-2,7,-1,159:15)
Block(-2,7,0,251:15)
Block(-2,7,1,251:15)
Block(-2,7,2,159:15)
Block(-2,7,3,159:15)
Block(-2,7,4,159:15)
Block(-2,7,5,159:15)
Block(-2,7,6,251:15)
Block(-2,7,7,251:15)
Block(-2,7,8,251:15)
Block(-2,8,-7,159:15)
Block(-2,8,-6,251:15)
Block(-2,8,-5,251:15)
Block(-2,8,-4,159:15)
Block(-2,8,-3,251:15)
Block(-2,8,-2,251:15)
Block(-2,8,-1,159:15)
Block(-2,8,0,159:15)
Block(-2,8,1,251:15)
Block(-2,8,2,159:15)
Block(-2,8,3,251:15)
Block(-2,8,4,251:15)
Block(-2,8,5,159:15)
Block(-2,8,6,251:15)
Block(-2,8,7,159:15)
Block(-2,8,8,251:15)
Block(-2,9,-7,159:15)
Block(-2,9,-6,251:15)
Block(-2,9,-5,159:15)
Block(-2,9,-4,251:15)
Block(-2,9,-3,159:15)
Block(-2,9,-2,159:15)
Block(-2,9,-1,159:15)
Block(-2,9,0,159:15)
Block(-2,9,1,159:15)
Block(-2,9,2,251:15)
Block(-2,9,3,251:15)
Block(-2,9,4,159:15)
Block(-2,9,5,251:15)
Block(-2,9,6,251:15)
Block(-2,9,7,159:15)
Block(-2,9,8,159:15)
Block(-2,10,-7,159:15)
Block(-2,10,-6,159:15)
Block(-2,10,-5,159:15)
Block(-2,10,-4,251:15)
Block(-2,10,-3,251:15)
Block(-2,10,-2,251:15)
Block(-2,10,-1,251:15)
Block(-2,10,0,159:15)
Block(-2,10,1,159:15)
Block(-2,10,2,159:15)
Block(-2,10,3,251:15)
Block(-2,10,4,251:15)
Block(-2,10,5,251:15)
Block(-2,10,6,251:15)
Block(-2,10,7,159:15)
Block(-2,10,8,159:15)
Block(-2,11,-7,159:15)
Block(-2,11,-6,159:15)
Block(-2,11,-5,251:15)
Block(-2,11,-4,251:15)
Block(-2,11,-3,159:15)
Block(-2,11,-2,251:15)
Block(-2,11,-1,159:15)
Block(-2,11,0,251:15)
Block(-2,11,1,159:15)
Block(-2,11,2,159:15)
Block(-2,11,3,251:15)
Block(-2,11,4,251:15)
Block(-2,11,5,159:15)
Block(-2,11,6,251:15)
Block(-2,11,7,251:15)
Block(-2,11,8,159:15)
Block(-2,12,-7,251:15)
Block(-2,12,-6,159:15)
Block(-2,12,-5,251:15)
Block(-2,12,-4,159:15)
Block(-2,12,-3,159:15)
Block(-2,12,-2,251:15)
Block(-2,12,-1,159:15)
Block(-2,12,0,251:15)
Block(-2,12,1,159:15)
Block(-2,12,2,251:15)
Block(-2,12,3,251:15)
Block(-2,12,4,159:15)
Block(-2,12,5,159:15)
Block(-2,12,6,159:15)
Block(-2,12,7,251:15)
Block(-2,12,8,159:15)
Block(-2,13,-7,251:15)
Block(-2,13,-6,159:15)
Block(-2,13,-5,159:15)
Block(-2,13,-4,159:15)
Block(-2,13,-3,159:15)
Block(-2,13,-2,251:15)
Block(-2,13,-1,251:15)
Block(-2,13,0,251:15)
Block(-2,13,1,251:15)
Block(-2,13,2,159:15)
Block(-2,13,3,159:15)
Block(-2,13,4,159:15)
Block(-2,13,5,251:15)
Block(-2,13,6,159:15)
Block(-2,13,7,251:15)
Block(-2,13,8,159:15)
Block(-2,14,-7,251:15)
Block(-2,14,-6,159:15)
Block(-2,14,-5,251:15)
Block(-2,14,-4,159:15)
Block(-2,14,-3,159:15)
Block(-2,14,-2,251:15)
Block(-2,14,-1,159:15)
Block(-2,14,0,159:15)
Block(-2,14,1,251:15)
Block(-2,14,2,251:15)
Block(-2,14,3,159:15)
Block(-2,14,4,251:15)
Block(-2,14,5,159:15)
Block(-2,14,6,159:15)
Block(-2,14,7,251:15)
Block(-2,14,8,251:15)
Block(-2,15,-7,159:15)
Block(-2,15,-6,251:15)
Block(-2,15,-5,159:15)
Block(-2,15,-4,159:15)
Block(-2,15,-3,251:15)
Block(-2,15,-2,159:15)
Block(-2,15,-1,159:15)
Block(-2,15,0,159:15)
Block(-2,15,1,159:15)
Block(-2,15,2,159:15)
Block(-2,15,3,251:15)
Block(-2,15,4,251:15)
Block(-2,15,5,159:15)
Block(-2,15,6,159:15)
Block(-2,15,7,159:15)
Block(-2,15,8,159:15)
Block(-2,16,-7,159:15)
Block(-2,16,-6,251:15)
Block(-2,16,-5,251:15)
Block(-2,16,-4,251:15)
Block(-2,16,-3,159:15)
Block(-2,16,-2,251:15)
Block(-2,16,-1,159:15)
Block(-2,16,0,159:15)
Block(-2,16,1,251:15)
Block(-2,16,2,251:15)
Block(-2,16,3,159:15)
Block(-2,16,4,251:15)
Block(-2,16,5,251:15)
Block(-2,16,6,159:15)
Block(-2,16,7,159:15)
Block(-2,16,8,251:15)
Block(-2,17,-7,251:15)
Block(-2,17,-6,251:15)
Block(-2,17,-5,251:15)
Block(-2,17,-4,251:15)
Block(-2,17,-3,251:15)
Block(-2,17,-2,251:15)
Block(-2,17,-1,251:15)
Block(-2,17,0,159:15)
Block(-2,17,1,251:15)
Block(-2,17,2,159:15)
Block(-2,17,3,251:15)
Block(-2,17,4,251:15)
Block(-2,17,5,159:15)
Block(-2,17,6,159:15)
Block(-2,17,7,251:15)
Block(-2,17,8,251:15)
Block(-2,18,-4,159:15)
Block(-2,18,-3,251:15)
Block(-2,18,-2,251:15)
Block(-2,18,-1,251:15)
Block(-2,18,0,251:15)
Block(-2,18,1,159:15)
Block(-2,18,2,251:15)
Block(-2,18,3,159:15)
Block(-2,18,4,251:15)
Block(-2,18,5,159:15)
Block(-2,18,6,159:15)
Block(-2,18,7,159:15)
Block(-2,18,8,251:15)
Block(-2,19,-4,159:15)
Block(-2,19,-3,159:15)
Block(-2,19,-2,159:15)
Block(-2,19,-1,251:15)
Block(-2,19,0,159:15)
Block(-2,19,1,251:15)
Block(-2,19,2,251:15)
Block(-2,19,3,159:15)
Block(-2,19,4,159:15)
Block(-2,19,5,251:15)
Block(-2,19,6,251:15)
Block(-2,19,7,159:15)
Block(-2,19,8,251:15)
Block(-2,20,-4,159:15)
Block(-2,20,-3,251:15)
Block(-2,20,-2,251:15)
Block(-2,20,-1,159:15)
Block(-2,20,0,251:15)
Block(-2,20,1,159:15)
Block(-2,20,2,159:15)
Block(-2,20,3,251:15)
Block(-2,20,4,159:15)
Block(-2,20,5,159:15)
Block(-2,20,6,251:15)
Block(-2,20,7,251:15)
Block(-2,20,8,251:15)
Block(-2,21,-4,159:15)
Block(-2,21,-3,159:15)
Block(-2,21,-2,159:15)
Block(-2,21,-1,251:15)
Block(-2,21,0,251:15)
Block(-2,21,1,251:15)
Block(-2,21,2,159:15)
Block(-2,21,3,251:15)
Block(-2,21,4,251:15)
Block(-2,21,5,159:15)
Block(-2,21,6,159:15)
Block(-2,21,7,251:15)
Block(-2,21,8,251:15)
Block(-2,22,-4,159:15)
Block(-2,22,-3,159:15)
Block(-2,22,-2,251:15)
Block(-2,22,-1,251:15)
Block(-2,22,0,159:15)
Block(-2,22,1,159:15)
Block(-2,22,2,251:15)
Block(-2,22,3,159:15)
Block(-2,22,4,159:15)
Block(-2,22,5,159:15)
Block(-2,22,6,251:15)
Block(-2,22,7,251:15)
Block(-2,22,8,251:15)
Block(-2,23,-4,159:15)
Block(-2,23,-3,251:15)
Block(-2,23,-2,159:15)
Block(-2,23,-1,159:15)
Block(-2,23,0,251:15)
Block(-2,23,1,159:15)
Block(-2,23,2,159:15)
Block(-2,23,3,159:15)
Block(-2,23,4,159:15)
Block(-2,23,5,159:15)
Block(-2,23,6,159:15)
Block(-2,23,7,159:15)
Block(-2,23,8,251:15)
Block(-2,24,-4,251:15)
Block(-2,24,-3,159:15)
Block(-2,24,-2,251:15)
Block(-2,24,-1,251:15)
Block(-2,24,0,251:15)
Block(-2,24,1,159:15)
Block(-2,24,2,159:15)
Block(-2,24,3,251:15)
Block(-2,24,4,159:15)
Block(-2,24,5,251:15)
Block(-2,24,6,159:15)
Block(-2,24,7,251:15)
Block(-2,24,8,251:15)
Block(-2,25,-4,251:15)
Block(-2,25,-3,159:15)
Block(-2,25,-2,251:15)
Block(-2,25,-1,251:15)
Block(-2,25,0,251:15)
Block(-2,25,1,159:15)
Block(-2,25,2,251:15)
Block(-2,25,3,159:15)
Block(-2,25,4,159:15)
Block(-2,25,5,251:15)
Block(-2,25,6,159:15)
Block(-2,25,7,159:15)
Block(-2,25,8,159:15)
Block(-2,26,-4,251:15)
Block(-2,26,-3,251:15)
Block(-2,26,-2,251:15)
Block(-2,26,-1,159:15)
Block(-2,26,0,251:15)
Block(-2,26,1,251:15)
Block(-2,26,2,251:15)
Block(-2,26,3,251:15)
Block(-2,26,4,251:15)
Block(-2,26,5,159:15)
Block(-2,26,6,159:15)
Block(-2,26,7,251:15)
Block(-2,26,8,251:15)
Block(-2,27,-4,159:15)
Block(-2,27,-3,251:15)
Block(-2,27,-2,159:15)
Block(-2,27,-1,159:15)
Block(-2,27,0,159:15)
Block(-2,27,1,251:15)
Block(-2,27,2,159:15)
Block(-2,27,3,251:15)
Block(-2,27,4,251:15)
Block(-2,27,5,251:15)
Block(-2,27,6,251:15)
Block(-2,27,7,251:15)
Block(-2,27,8,251:15)
Block(-2,28,-4,159:15)
Block(-2,28,-3,159:15)
Block(-2,28,-2,251:15)
Block(-2,28,-1,251:15)
Block(-2,28,0,251:15)
Block(-2,28,1,159:15)
Block(-2,28,2,251:15)
Block(-2,28,3,251:15)
Block(-2,28,4,159:15)
Block(-2,28,5,159:15)
Block(-2,28,6,159:15)
Block(-2,28,7,251:15)
Block(-2,28,8,251:15)
Block(-2,29,-4,251:15)
Block(-2,29,-3,159:15)
Block(-2,29,-2,159:15)
Block(-2,29,-1,159:15)
Block(-2,29,0,159:15)
Block(-2,29,1,251:15)
Block(-2,29,2,251:15)
Block(-2,29,3,159:15)
Block(-2,29,4,159:15)
Block(-2,29,5,159:15)
Block(-2,29,6,251:15)
Block(-2,29,7,159:15)
Block(-2,29,8,251:15)
Block(-2,30,-4,251:15)
Block(-2,30,-3,251:15)
Block(-2,30,-2,159:15)
Block(-2,30,-1,251:15)
Block(-2,30,0,251:15)
Block(-2,30,1,251:15)
Block(-2,30,2,251:15)
Block(-2,30,3,251:15)
Block(-2,30,4,251:15)
Block(-2,30,5,159:15)
Block(-2,30,6,251:15)
Block(-2,30,7,251:15)
Block(-2,30,8,159:15)
Block(-2,31,-4,251:15)
Block(-2,31,-3,159:15)
Block(-2,31,-2,251:15)
Block(-2,31,-1,159:15)
Block(-2,31,0,159:15)
Block(-2,31,1,251:15)
Block(-2,31,2,251:15)
Block(-2,31,3,251:15)
Block(-2,31,4,159:15)
Block(-2,31,5,251:15)
Block(-2,31,6,251:15)
Block(-2,31,7,159:15)
Block(-2,31,8,251:15)
Block(-2,32,-4,159:15)
Block(-2,32,-3,159:15)
Block(-2,32,-2,251:15)
Block(-2,32,-1,251:15)
Block(-2,32,0,159:15)
Block(-2,32,1,251:15)
Block(-2,32,2,251:15)
Block(-2,32,3,251:15)
Block(-2,32,4,251:15)
Block(-2,32,5,251:15)
Block(-2,32,6,251:15)
Block(-2,32,7,251:15)
Block(-2,32,8,159:15)
Block(-2,33,-4,159:15)
Block(-2,33,-3,159:15)
Block(-2,33,-2,159:15)
Block(-2,33,-1,159:15)
Block(-2,33,0,251:15)
Block(-2,33,1,251:15)
Block(-2,33,2,159:15)
Block(-2,33,3,159:15)
Block(-2,33,4,251:15)
Block(-2,33,5,159:15)
Block(-2,33,6,251:15)
Block(-2,34,-4,159:15)
Block(-2,34,-3,159:15)
Block(-2,34,-2,159:15)
Block(-2,34,-1,251:15)
Block(-2,34,0,159:15)
Block(-2,34,1,251:15)
Block(-2,34,2,251:15)
Block(-2,34,3,159:15)
Block(-2,34,4,251:15)
Block(-2,34,5,159:15)
Block(-2,34,6,159:15)
Block(-2,35,-4,159:15)
Block(-2,35,-3,159:15)
Block(-2,35,-2,251:15)
Block(-2,35,-1,251:15)
Block(-2,35,0,159:15)
Block(-2,35,1,251:15)
Block(-2,35,2,159:15)
Block(-2,35,3,159:15)
Block(-2,35,4,251:15)
Block(-2,35,5,251:15)
Block(-2,35,6,251:15)
Block(-2,36,-4,159:15)
Block(-2,36,-3,251:15)
Block(-2,36,-2,159:15)
Block(-2,36,-1,159:15)
Block(-2,36,0,159:15)
Block(-2,36,1,251:15)
Block(-2,36,2,251:15)
Block(-2,36,3,159:15)
Block(-2,36,4,159:15)
Block(-2,36,5,251:15)
Block(-2,36,6,251:15)
Block(-2,37,-4,159:15)
Block(-2,37,-3,159:15)
Block(-2,37,-2,251:15)
Block(-2,37,-1,251:15)
Block(-2,37,0,159:15)
Block(-2,37,1,159:15)
Block(-2,37,2,159:15)
Block(-2,37,3,251:15)
Block(-2,37,4,159:15)
Block(-2,37,5,159:15)
Block(-2,37,6,251:15)
Block(-2,38,-4,159:15)
Block(-2,38,-3,159:15)
Block(-2,38,-2,251:15)
Block(-2,38,-1,159:15)
Block(-2,38,0,251:15)
Block(-2,38,1,159:15)
Block(-2,38,2,251:15)
Block(-2,38,3,159:15)
Block(-2,38,4,159:15)
Block(-2,38,5,159:15)
Block(-2,38,6,251:15)
Block(-2,39,-4,159:15)
Block(-2,39,-3,251:15)
Block(-2,39,-2,159:15)
Block(-2,39,-1,159:15)
Block(-2,39,0,159:15)
Block(-2,39,1,159:15)
Block(-2,39,2,159:15)
Block(-2,39,3,251:15)
Block(-2,39,4,159:15)
Block(-2,39,5,159:15)
Block(-2,39,6,159:15)
Block(-2,40,-4,251:15)
Block(-2,40,-3,251:15)
Block(-2,40,-2,159:15)
Block(-2,40,-1,159:15)
Block(-2,40,0,251:15)
Block(-2,40,1,251:15)
Block(-2,40,2,159:15)
Block(-2,40,3,159:15)
Block(-2,40,4,251:15)
Block(-2,40,5,159:15)
Block(-2,40,6,159:15)
Block(-1,0,-7,159:15)
Block(-1,0,-6,159:15)
Block(-1,0,-5,251:15)
Block(-1,0,-4,159:15)
Block(-1,0,-3,251:15)
Block(-1,0,-2,159:15)
Block(-1,0,-1,251:15)
Block(-1,0,0,251:15)
Block(-1,0,1,159:15)
Block(-1,0,2,159:15)
Block(-1,0,3,159:15)
Block(-1,0,4,251:15)
Block(-1,0,5,251:15)
Block(-1,0,6,251:15)
Block(-1,0,7,159:15)
Block(-1,0,8,251:15)
Block(-1,1,-7,159:15)
Block(-1,1,-6,159:15)
Block(-1,1,-5,251:15)
Block(-1,1,-4,159:15)
Block(-1,1,-3,159:15)
Block(-1,1,-2,251:15)
Block(-1,1,-1,159:15)
Block(-1,1,0,251:15)
Block(-1,1,1,159:15)
Block(-1,1,2,159:15)
Block(-1,1,3,159:15)
Block(-1,1,4,159:15)
Block(-1,1,5,159:15)
Block(-1,1,6,159:15)
Block(-1,1,7,251:15)
Block(-1,1,8,251:15)
Block(-1,2,-7,159:15)
Block(-1,2,-6,251:15)
Block(-1,2,-5,159:15)
Block(-1,2,-4,159:15)
Block(-1,2,-3,251:15)
Block(-1,2,-2,159:15)
Block(-1,2,-1,159:15)
Block(-1,2,0,251:15)
Block(-1,2,1,251:15)
Block(-1,2,2,159:15)
Block(-1,2,3,251:15)
Block(-1,2,4,251:15)
Block(-1,2,5,159:15)
Block(-1,2,6,159:15)
Block(-1,2,7,251:15)
Block(-1,2,8,159:15)
Block(-1,3,-7,159:15)
Block(-1,3,-6,159:15)
Block(-1,3,-5,251:15)
Block(-1,3,-4,251:15)
Block(-1,3,-3,251:15)
Block(-1,3,-2,159:15)
Block(-1,3,-1,159:15)
Block(-1,3,0,159:15)
Block(-1,3,1,159:15)
Block(-1,3,2,159:15)
Block(-1,3,3,159:15)
Block(-1,3,4,251:15)
Block(-1,3,5,251:15)
Block(-1,3,6,159:15)
Block(-1,3,7,159:15)
Block(-1,3,8,251:15)
Block(-1,4,-7,251:15)
Block(-1,4,-6,159:15)
Block(-1,4,-5,251:15)
Block(-1,4,-4,251:15)
Block(-1,4,-3,251:15)
Block(-1,4,-2,159:15)
Block(-1,4,-1,251:15)
Block(-1,4,0,159:15)
Block(-1,4,1,251:15)
Block(-1,4,2,159:15)
Block(-1,4,3,251:15)
Block(-1,4,4,251:15)
Block(-1,4,5,159:15)
Block(-1,4,6,251:15)
Block(-1,4,7,159:15)
Block(-1,4,8,251:15)
Block(-1,5,-7,251:15)
Block(-1,5,-6,251:15)
Block(-1,5,-5,159:15)
Block(-1,5,-4,159:15)
Block(-1,5,-3,251:15)
Block(-1,5,-2,159:15)
Block(-1,5,-1,159:15)
Block(-1,5,0,251:15)
Block(-1,5,1,251:15)
Block(-1,5,2,159:15)
Block(-1,5,3,251:15)
Block(-1,5,4,159:15)
Block(-1,5,5,159:15)
Block(-1,5,6,251:15)
Block(-1,5,7,251:15)
Block(-1,5,8,251:15)
Block(-1,6,-7,159:15)
Block(-1,6,-6,251:15)
Block(-1,6,-5,251:15)
Block(-1,6,-4,251:15)
Block(-1,6,-3,251:15)
Block(-1,6,-2,159:15)
Block(-1,6,-1,159:15)
Block(-1,6,0,251:15)
Block(-1,6,1,251:15)
Block(-1,6,2,251:15)
Block(-1,6,3,251:15)
Block(-1,6,4,251:15)
Block(-1,6,5,251:15)
Block(-1,6,6,251:15)
Block(-1,6,7,251:15)
Block(-1,6,8,159:15)
Block(-1,7,-7,159:15)
Block(-1,7,-6,159:15)
Block(-1,7,-5,159:15)
Block(-1,7,-4,251:15)
Block(-1,7,-3,251:15)
Block(-1,7,-2,159:15)
Block(-1,7,-1,251:15)
Block(-1,7,0,251:15)
Block(-1,7,1,159:15)
Block(-1,7,2,159:15)
Block(-1,7,3,251:15)
Block(-1,7,4,251:15)
Block(-1,7,5,159:15)
Block(-1,7,6,251:15)
Block(-1,7,7,251:15)
Block(-1,7,8,159:15)
Block(-1,8,-7,159:15)
Block(-1,8,-6,251:15)
Block(-1,8,-5,251:15)
Block(-1,8,-4,159:15)
Block(-1,8,-3,251:15)
Block(-1,8,-2,159:15)
Block(-1,8,-1,251:15)
Block(-1,8,0,159:15)
Block(-1,8,1,159:15)
Block(-1,8,2,251:15)
Block(-1,8,3,159:15)
Block(-1,8,4,251:15)
Block(-1,8,5,159:15)
Block(-1,8,6,251:15)
Block(-1,8,7,159:15)
Block(-1,8,8,159:15)
Block(-1,9,-7,251:15)
Block(-1,9,-6,251:15)
Block(-1,9,-5,159:15)
Block(-1,9,-4,251:15)
Block(-1,9,-3,159:15)
Block(-1,9,-2,159:15)
Block(-1,9,-1,159:15)
Block(-1,9,0,159:15)
Block(-1,9,1,159:15)
Block(-1,9,2,159:15)
Block(-1,9,3,159:15)
Block(-1,9,4,159:15)
Block(-1,9,5,159:15)
Block(-1,9,6,159:15)
Block(-1,9,7,159:15)
Block(-1,9,8,159:15)
Block(-1,10,-7,159:15)
Block(-1,10,-6,251:15)
Block(-1,10,-5,159:15)
Block(-1,10,-4,251:15)
Block(-1,10,-3,159:15)
Block(-1,10,-2,159:15)
Block(-1,10,-1,159:15)
Block(-1,10,0,251:15)
Block(-1,10,1,159:15)
Block(-1,10,2,159:15)
Block(-1,10,3,159:15)
Block(-1,10,4,159:15)
Block(-1,10,5,159:15)
Block(-1,10,6,159:15)
Block(-1,10,7,251:15)
Block(-1,10,8,251:15)
Block(-1,11,-7,251:15)
Block(-1,11,-6,159:15)
Block(-1,11,-5,159:15)
Block(-1,11,-4,251:15)
Block(-1,11,-3,251:15)
Block(-1,11,-2,251:15)
Block(-1,11,-1,251:15)
Block(-1,11,0,251:15)
Block(-1,11,1,251:15)
Block(-1,11,2,251:15)
Block(-1,11,3,159:15)
Block(-1,11,4,251:15)
Block(-1,11,5,159:15)
Block(-1,11,6,251:15)
Block(-1,11,7,251:15)
Block(-1,11,8,159:15)
Block(-1,12,-7,251:15)
Block(-1,12,-6,251:15)
Block(-1,12,-5,159:15)
Block(-1,12,-4,251:15)
Block(-1,12,-3,251:15)
Block(-1,12,-2,251:15)
Block(-1,12,-1,159:15)
Block(-1,12,0,159:15)
Block(-1,12,1,251:15)
Block(-1,12,2,251:15)
Block(-1,12,3,159:15)
Block(-1,12,4,251:15)
Block(-1,12,5,159:15)
Block(-1,12,6,251:15)
Block(-1,12,7,251:15)
Block(-1,12,8,251:15)
Block(-1,13,-7,159:15)
Block(-1,13,-6,251:15)
Block(-1,13,-5,251:15)
Block(-1,13,-4,251:15)
Block(-1,13,-3,251:15)
Block(-1,13,-2,159:15)
Block(-1,13,-1,251:15)
Block(-1,13,0,159:15)
Block(-1,13,1,251:15)
Block(-1,13,2,251:15)
Block(-1,13,3,251:15)
Block(-1,13,4,251:15)
Block(-1,13,5,159:15)
Block(-1,13,6,159:15)
Block(-1,13,7,251:15)
Block(-1,13,8,251:15)
Block(-1,14,-7,159:15)
Block(-1,14,-6,251:15)
Block(-1,14,-5,251:15)
Block(-1,14,-4,251:15)
Block(-1,14,-3,251:15)
Block(-1,14,-2,159:15)
Block(-1,14,-1,251:15)
Block(-1,14,0,251:15)
Block(-1,14,1,251:15)
Block(-1,14,2,251:15)
Block(-1,14,3,251:15)
Block(-1,14,4,251:15)
Block(-1,14,5,159:15)
Block(-1,14,6,251:15)
Block(-1,14,7,251:15)
Block(-1,14,8,159:15)
Block(-1,15,-7,159:15)
Block(-1,15,-6,251:15)
Block(-1,15,-5,251:15)
Block(-1,15,-4,159:15)
Block(-1,15,-3,251:15)
Block(-1,15,-2,159:15)
Block(-1,15,-1,159:15)
Block(-1,15,0,251:15)
Block(-1,15,1,159:15)
Block(-1,15,2,159:15)
Block(-1,15,3,251:15)
Block(-1,15,4,159:15)
Block(-1,15,5,159:15)
Block(-1,15,6,159:15)
Block(-1,15,7,159:15)
Block(-1,15,8,251:15)
Block(-1,16,-7,159:15)
Block(-1,16,-6,251:15)
Block(-1,16,-5,159:15)
Block(-1,16,-4,251:15)
Block(-1,16,-3,159:15)
Block(-1,16,-2,159:15)
Block(-1,16,-1,159:15)
Block(-1,16,0,251:15)
Block(-1,16,1,159:15)
Block(-1,16,2,251:15)
Block(-1,16,3,159:15)
Block(-1,16,4,159:15)
Block(-1,16,5,159:15)
Block(-1,16,6,251:15)
Block(-1,16,7,159:15)
Block(-1,16,8,251:15)
Block(-1,17,-7,159:15)
Block(-1,17,-6,251:15)
Block(-1,17,-5,251:15)
Block(-1,17,-4,159:15)
Block(-1,17,-3,159:15)
Block(-1,17,-2,251:15)
Block(-1,17,-1,159:15)
Block(-1,17,0,159:15)
Block(-1,17,1,251:15)
Block(-1,17,2,251:15)
Block(-1,17,3,251:15)
Block(-1,17,4,159:15)
Block(-1,17,5,159:15)
Block(-1,17,6,159:15)
Block(-1,17,7,159:15)
Block(-1,17,8,251:15)
Block(-1,18,-4,251:15)
Block(-1,18,-3,159:15)
Block(-1,18,-2,251:15)
Block(-1,18,-1,159:15)
Block(-1,18,0,251:15)
Block(-1,18,1,251:15)
Block(-1,18,2,159:15)
Block(-1,18,3,159:15)
Block(-1,18,4,251:15)
Block(-1,18,5,251:15)
Block(-1,18,6,251:15)
Block(-1,18,7,251:15)
Block(-1,18,8,251:15)
Block(-1,19,-4,159:15)
Block(-1,19,-3,251:15)
Block(-1,19,-2,159:15)
Block(-1,19,-1,159:15)
Block(-1,19,0,159:15)
Block(-1,19,1,251:15)
Block(-1,19,2,251:15)
Block(-1,19,3,159:15)
Block(-1,19,4,251:15)
Block(-1,19,5,159:15)
Block(-1,19,6,251:15)
Block(-1,19,7,159:15)
Block(-1,19,8,251:15)
Block(-1,20,-4,159:15)
Block(-1,20,-3,159:15)
Block(-1,20,-2,251:15)
Block(-1,20,-1,251:15)
Block(-1,20,0,251:15)
Block(-1,20,1,251:15)
Block(-1,20,2,159:15)
Block(-1,20,3,251:15)
Block(-1,20,4,159:15)
Block(-1,20,5,159:15)
Block(-1,20,6,251:15)
Block(-1,20,7,159:15)
Block(-1,20,8,159:15)
Block(-1,21,-4,251:15)
Block(-1,21,-3,251:15)
Block(-1,21,-2,251:15)
Block(-1,21,-1,159:15)
Block(-1,21,0,251:15)
Block(-1,21,1,159:15)
Block(-1,21,2,251:15)
Block(-1,21,3,159:15)
Block(-1,21,4,159:15)
Block(-1,21,5,159:15)
Block(-1,21,6,251:15)
Block(-1,21,7,159:15)
Block(-1,21,8,251:15)
Block(-1,22,-4,159:15)
Block(-1,22,-3,251:15)
Block(-1,22,-2,251:15)
Block(-1,22,-1,159:15)
Block(-1,22,0,251:15)
Block(-1,22,1,159:15)
Block(-1,22,2,251:15)
Block(-1,22,3,159:15)
Block(-1,22,4,251:15)
Block(-1,22,5,251:15)
Block(-1,22,6,251:15)
Block(-1,22,7,159:15)
Block(-1,22,8,251:15)
Block(-1,23,-4,159:15)
Block(-1,23,-3,251:15)
Block(-1,23,-2,251:15)
Block(-1,23,-1,251:15)
Block(-1,23,0,159:15)
Block(-1,23,1,159:15)
Block(-1,23,2,159:15)
Block(-1,23,3,251:15)
Block(-1,23,4,159:15)
Block(-1,23,5,159:15)
Block(-1,23,6,251:15)
Block(-1,23,7,251:15)
Block(-1,23,8,159:15)
Block(-1,24,-4,159:15)
Block(-1,24,-3,159:15)
Block(-1,24,-2,159:15)
Block(-1,24,-1,159:15)
Block(-1,24,0,159:15)
Block(-1,24,1,251:15)
Block(-1,24,2,251:15)
Block(-1,24,3,159:15)
Block(-1,24,4,251:15)
Block(-1,24,5,251:15)
Block(-1,24,6,251:15)
Block(-1,24,7,159:15)
Block(-1,24,8,159:15)
Block(-1,25,-4,251:15)
Block(-1,25,-3,159:15)
Block(-1,25,-2,251:15)
Block(-1,25,-1,251:15)
Block(-1,25,0,159:15)
Block(-1,25,1,159:15)
Block(-1,25,2,251:15)
Block(-1,25,3,159:15)
Block(-1,25,4,251:15)
Block(-1,25,5,159:15)
Block(-1,25,6,159:15)
Block(-1,25,7,159:15)
Block(-1,25,8,159:15)
Block(-1,26,-4,159:15)
Block(-1,26,-3,251:15)
Block(-1,26,-2,251:15)
Block(-1,26,-1,251:15)
Block(-1,26,0,159:15)
Block(-1,26,1,159:15)
Block(-1,26,2,159:15)
Block(-1,26,3,159:15)
Block(-1,26,4,251:15)
Block(-1,26,5,159:15)
Block(-1,26,6,251:15)
Block(-1,26,7,159:15)
Block(-1,26,8,251:15)
Block(-1,27,-4,159:15)
Block(-1,27,-3,251:15)
Block(-1,27,-2,159:15)
Block(-1,27,-1,251:15)
Block(-1,27,0,251:15)
Block(-1,27,1,251:15)
Block(-1,27,2,159:15)
Block(-1,27,3,159:15)
Block(-1,27,4,159:15)
Block(-1,27,5,251:15)
Block(-1,27,6,159:15)
Block(-1,27,7,251:15)
Block(-1,27,8,251:15)
Block(-1,28,-4,251:15)
Block(-1,28,-3,251:15)
Block(-1,28,-2,159:15)
Block(-1,28,-1,251:15)
Block(-1,28,0,159:15)
Block(-1,28,1,251:15)
Block(-1,28,2,251:15)
Block(-1,28,3,159:15)
Block(-1,28,4,159:15)
Block(-1,28,5,251:15)
Block(-1,28,6,251:15)
Block(-1,28,7,159:15)
Block(-1,28,8,159:15)
Block(-1,29,-4,159:15)
Block(-1,29,-3,159:15)
Block(-1,29,-2,251:15)
Block(-1,29,-1,159:15)
Block(-1,29,0,159:15)
Block(-1,29,1,251:15)
Block(-1,29,2,251:15)
Block(-1,29,3,251:15)
Block(-1,29,4,251:15)
Block(-1,29,5,159:15)
Block(-1,29,6,251:15)
Block(-1,29,7,159:15)
Block(-1,29,8,251:15)
Block(-1,30,-4,251:15)
Block(-1,30,-3,251:15)
Block(-1,30,-2,251:15)
Block(-1,30,-1,251:15)
Block(-1,30,0,251:15)
Block(-1,30,1,159:15)
Block(-1,30,2,159:15)
Block(-1,30,3,251:15)
Block(-1,30,4,159:15)
Block(-1,30,5,159:15)
Block(-1,30,6,159:15)
Block(-1,30,7,251:15)
Block(-1,30,8,251:15)
Block(-1,31,-4,159:15)
Block(-1,31,-3,251:15)
Block(-1,31,-2,159:15)
Block(-1,31,-1,159:15)
Block(-1,31,0,251:15)
Block(-1,31,1,159:15)
Block(-1,31,2,251:15)
Block(-1,31,3,159:15)
Block(-1,31,4,251:15)
Block(-1,31,5,251:15)
Block(-1,31,6,251:15)
Block(-1,31,7,251:15)
Block(-1,31,8,159:15)
Block(-1,32,-4,251:15)
Block(-1,32,-3,251:15)
Block(-1,32,-2,251:15)
Block(-1,32,-1,159:15)
Block(-1,32,0,159:15)
Block(-1,32,1,159:15)
Block(-1,32,2,251:15)
Block(-1,32,3,251:15)
Block(-1,32,4,159:15)
Block(-1,32,5,159:15)
Block(-1,32,6,159:15)
Block(-1,32,7,159:15)
Block(-1,32,8,159:15)
Block(-1,33,-4,251:15)
Block(-1,33,-3,251:15)
Block(-1,33,-2,251:15)
Block(-1,33,-1,251:15)
Block(-1,33,0,159:15)
Block(-1,33,1,159:15)
Block(-1,33,2,159:15)
Block(-1,33,3,159:15)
Block(-1,33,4,159:15)
Block(-1,33,5,251:15)
Block(-1,33,6,159:15)
Block(-1,34,-4,251:15)
Block(-1,34,-3,251:15)
Block(-1,34,-2,251:15)
Block(-1,34,-1,251:15)
Block(-1,34,0,251:15)
Block(-1,34,1,251:15)
Block(-1,34,2,159:15)
Block(-1,34,3,251:15)
Block(-1,34,4,251:15)
Block(-1,34,5,159:15)
Block(-1,34,6,251:15)
Block(-1,35,-4,159:15)
Block(-1,35,-3,159:15)
Block(-1,35,-2,251:15)
Block(-1,35,-1,251:15)
Block(-1,35,0,251:15)
Block(-1,35,1,159:15)
Block(-1,35,2,159:15)
Block(-1,35,3,251:15)
Block(-1,35,4,159:15)
Block(-1,35,5,159:15)
Block(-1,35,6,159:15)
Block(-1,36,-4,159:15)
Block(-1,36,-3,159:15)
Block(-1,36,-2,251:15)
Block(-1,36,-1,251:15)
Block(-1,36,0,159:15)
Block(-1,36,1,159:15)
Block(-1,36,2,251:15)
Block(-1,36,3,251:15)
Block(-1,36,4,159:15)
Block(-1,36,5,159:15)
Block(-1,36,6,159:15)
Block(-1,37,-4,251:15)
Block(-1,37,-3,159:15)
Block(-1,37,-2,159:15)
Block(-1,37,-1,159:15)
Block(-1,37,0,159:15)
Block(-1,37,1,159:15)
Block(-1,37,2,159:15)
Block(-1,37,3,251:15)
Block(-1,37,4,159:15)
Block(-1,37,5,159:15)
Block(-1,37,6,251:15)
Block(-1,38,-4,159:15)
Block(-1,38,-3,251:15)
Block(-1,38,-2,159:15)
Block(-1,38,-1,159:15)
Block(-1,38,0,251:15)
Block(-1,38,1,251:15)
Block(-1,38,2,159:15)
Block(-1,38,3,251:15)
Block(-1,38,4,159:15)
Block(-1,38,5,251:15)
Block(-1,38,6,159:15)
Block(-1,39,-4,251:15)
Block(-1,39,-3,159:15)
Block(-1,39,-2,159:15)
Block(-1,39,-1,159:15)
Block(-1,39,0,251:15)
Block(-1,39,1,159:15)
Block(-1,39,2,251:15)
Block(-1,39,3,159:15)
Block(-1,39,4,159:15)
Block(-1,39,5,251:15)
Block(-1,39,6,251:15)
Block(-1,40,-4,251:15)
Block(-1,40,-3,159:15)
Block(-1,40,-2,251:15)
Block(-1,40,-1,251:15)
Block(-1,40,0,159:15)
Block(-1,40,1,159:15)
Block(-1,40,2,159:15)
Block(-1,40,3,159:15)
Block(-1,40,4,159:15)
Block(-1,40,5,159:15)
Block(-1,40,6,159:15)
Block(0,0,-7,159:15)
Block(0,0,-6,251:15)
Block(0,0,-5,251:15)
Block(0,0,-4,251:15)
Block(0,0,-3,251:15)
Block(0,0,-2,159:15)
Block(0,0,-1,251:15)
Block(0,0,0,251:15)
Block(0,0,1,159:15)
Block(0,0,2,159:15)
Block(0,0,3,251:15)
Block(0,0,4,159:15)
Block(0,0,5,251:15)
Block(0,0,6,251:15)
Block(0,0,7,159:15)
Block(0,0,8,251:15)
Block(0,1,-7,251:15)
Block(0,1,-6,251:15)
Block(0,1,-5,159:15)
Block(0,1,-4,159:15)
Block(0,1,-3,251:15)
Block(0,1,-2,159:15)
Block(0,1,-1,159:15)
Block(0,1,0,159:15)
Block(0,1,1,251:15)
Block(0,1,2,251:15)
Block(0,1,3,159:15)
Block(0,1,4,251:15)
Block(0,1,5,251:15)
Block(0,1,6,251:15)
Block(0,1,7,159:15)
Block(0,1,8,159:15)
Block(0,2,-7,251:15)
Block(0,2,-6,159:15)
Block(0,2,-5,159:15)
Block(0,2,-4,251:15)
Block(0,2,-3,159:15)
Block(0,2,-2,251:15)
Block(0,2,-1,251:15)
Block(0,2,0,159:15)
Block(0,2,1,159:15)
Block(0,2,2,251:15)
Block(0,2,3,251:15)
Block(0,2,4,159:15)
Block(0,2,5,159:15)
Block(0,2,6,159:15)
Block(0,2,7,251:15)
Block(0,2,8,251:15)
Block(0,3,-7,251:15)
Block(0,3,-6,251:15)
Block(0,3,-5,251:15)
Block(0,3,-4,159:15)
Block(0,3,-3,159:15)
Block(0,3,-2,251:15)
Block(0,3,-1,159:15)
Block(0,3,0,159:15)
Block(0,3,1,159:15)
Block(0,3,2,159:15)
Block(0,3,3,159:15)
Block(0,3,4,159:15)
Block(0,3,5,251:15)
Block(0,3,6,159:15)
Block(0,3,7,251:15)
Block(0,3,8,251:15)
Block(0,4,-7,159:15)
Block(0,4,-6,251:15)
Block(0,4,-5,251:15)
Block(0,4,-4,251:15)
Block(0,4,-3,159:15)
Block(0,4,-2,159:15)
Block(0,4,-1,251:15)
Block(0,4,0,251:15)
Block(0,4,1,159:15)
Block(0,4,2,159:15)
Block(0,4,3,251:15)
Block(0,4,4,251:15)
Block(0,4,5,251:15)
Block(0,4,6,251:15)
Block(0,4,7,159:15)
Block(0,4,8,159:15)
Block(0,5,-7,159:15)
Block(0,5,-6,251:15)
Block(0,5,-5,251:15)
Block(0,5,-4,251:15)
Block(0,5,-3,251:15)
Block(0,5,-2,251:15)
Block(0,5,-1,251:15)
Block(0,5,0,159:15)
Block(0,5,1,251:15)
Block(0,5,2,159:15)
Block(0,5,3,159:15)
Block(0,5,4,251:15)
Block(0,5,5,159:15)
Block(0,5,6,251:15)
Block(0,5,7,251:15)
Block(0,5,8,251:15)
Block(0,6,-7,251:15)
Block(0,6,-6,251:15)
Block(0,6,-5,251:15)
Block(0,6,-4,159:15)
Block(0,6,-3,159:15)
Block(0,6,-2,251:15)
Block(0,6,-1,251:15)
Block(0,6,0,159:15)
Block(0,6,1,251:15)
Block(0,6,2,251:15)
Block(0,6,3,159:15)
Block(0,6,4,159:15)
Block(0,6,5,251:15)
Block(0,6,6,159:15)
Block(0,6,7,159:15)
Block(0,6,8,159:15)
Block(0,7,-7,251:15)
Block(0,7,-6,251:15)
Block(0,7,-5,251:15)
Block(0,7,-4,251:15)
Block(0,7,-3,159:15)
Block(0,7,-2,251:15)
Block(0,7,-1,159:15)
Block(0,7,0,159:15)
Block(0,7,1,251:15)
Block(0,7,2,251:15)
Block(0,7,3,159:15)
Block(0,7,4,251:15)
Block(0,7,5,251:15)
Block(0,7,6,159:15)
Block(0,7,7,159:15)
Block(0,7,8,251:15)
Block(0,8,-7,159:15)
Block(0,8,-6,251:15)
Block(0,8,-5,159:15)
Block(0,8,-4,159:15)
Block(0,8,-3,251:15)
Block(0,8,-2,251:15)
Block(0,8,-1,251:15)
Block(0,8,0,251:15)
Block(0,8,1,159:15)
Block(0,8,2,159:15)
Block(0,8,3,251:15)
Block(0,8,4,251:15)
Block(0,8,5,251:15)
Block(0,8,6,159:15)
Block(0,8,7,251:15)
Block(0,8,8,159:15)
Block(0,9,-7,159:15)
Block(0,9,-6,159:15)
Block(0,9,-5,159:15)
Block(0,9,-4,159:15)
Block(0,9,-3,251:15)
Block(0,9,-2,251:15)
Block(0,9,-1,159:15)
Block(0,9,0,251:15)
Block(0,9,1,251:15)
Block(0,9,2,159:15)
Block(0,9,3,159:15)
Block(0,9,4,159:15)
Block(0,9,5,159:15)
Block(0,9,6,251:15)
Block(0,9,7,251:15)
Block(0,9,8,159:15)
Block(0,10,-7,159:15)
Block(0,10,-6,251:15)
Block(0,10,-5,251:15)
Block(0,10,-4,251:15)
Block(0,10,-3,251:15)
Block(0,10,-2,159:15)
Block(0,10,-1,251:15)
Block(0,10,0,159:15)
Block(0,10,1,251:15)
Block(0,10,2,159:15)
Block(0,10,3,251:15)
Block(0,10,4,159:15)
Block(0,10,5,159:15)
Block(0,10,6,159:15)
Block(0,10,7,251:15)
Block(0,10,8,159:15)
Block(0,11,-7,159:15)
Block(0,11,-6,251:15)
Block(0,11,-5,251:15)
Block(0,11,-4,159:15)
Block(0,11,-3,251:15)
Block(0,11,-2,251:15)
Block(0,11,-1,251:15)
Block(0,11,0,251:15)
Block(0,11,1,159:15)
Block(0,11,2,159:15)
Block(0,11,3,251:15)
Block(0,11,4,159:15)
Block(0,11,5,159:15)
Block(0,11,6,251:15)
Block(0,11,7,251:15)
Block(0,11,8,251:15)
Block(0,12,-7,251:15)
Block(0,12,-6,251:15)
Block(0,12,-5,159:15)
Block(0,12,-4,159:15)
Block(0,12,-3,159:15)
Block(0,12,-2,251:15)
Block(0,12,-1,251:15)
Block(0,12,0,159:15)
Block(0,12,1,251:15)
Block(0,12,2,159:15)
Block(0,12,3,251:15)
Block(0,12,4,251:15)
Block(0,12,5,159:15)
Block(0,12,6,159:15)
Block(0,12,7,251:15)
Block(0,12,8,251:15)
Block(0,13,-7,159:15)
Block(0,13,-6,251:15)
Block(0,13,-5,251:15)
Block(0,13,-4,251:15)
Block(0,13,-3,251:15)
Block(0,13,-2,159:15)
Block(0,13,-1,251:15)
Block(0,13,0,159:15)
Block(0,13,1,159:15)
Block(0,13,2,251:15)
Block(0,13,3,159:15)
Block(0,13,4,251:15)
Block(0,13,5,251:15)
Block(0,13,6,251:15)
Block(0,13,7,159:15)
Block(0,13,8,159:15)
Block(0,14,-7,251:15)
Block(0,14,-6,251:15)
Block(0,14,-5,159:15)
Block(0,14,-4,159:15)
Block(0,14,-3,159:15)
Block(0,14,-2,251:15)
Block(0,14,-1,159:15)
Block(0,14,0,251:15)
Block(0,14,1,159:15)
Block(0,14,2,159:15)
Block(0,14,3,251:15)
Block(0,14,4,251:15)
Block(0,14,5,159:15)
Block(0,14,6,159:15)
Block(0,14,7,251:15)
Block(0,14,8,159:15)
Block(0,15,-7,251:15)
Block(0,15,-6,251:15)
Block(0,15,-5,251:15)
Block(0,15,-4,159:15)
Block(0,15,-3,251:15)
Block(0,15,-2,159:15)
Block(0,15,-1,159:15)
Block(0,15,0,251:15)
Block(0,15,1,251:15)
Block(0,15,2,159:15)
Block(0,15,3,159:15)
Block(0,15,4,159:15)
Block(0,15,5,251:15)
Block(0,15,6,159:15)
Block(0,15,7,251:15)
Block(0,15,8,251:15)
Block(0,16,-7,159:15)
Block(0,16,-6,159:15)
Block(0,16,-5,251:15)
Block(0,16,-4,251:15)
Block(0,16,-3,251:15)
Block(0,16,-2,159:15)
Block(0,16,-1,159:15)
Block(0,16,0,251:15)
Block(0,16,1,251:15)
Block(0,16,2,251:15)
Block(0,16,3,159:15)
Block(0,16,4,159:15)
Block(0,16,5,159:15)
Block(0,16,6,159:15)
Block(0,16,7,251:15)
Block(0,16,8,159:15)
Block(0,17,-7,159:15)
Block(0,17,-6,251:15)
Block(0,17,-5,251:15)
Block(0,17,-4,251:15)
Block(0,17,-3,159:15)
Block(0,17,-2,251:15)
Block(0,17,-1,159:15)
Block(0,17,0,159:15)
Block(0,17,1,159:15)
Block(0,17,2,251:15)
Block(0,17,3,251:15)
Block(0,17,4,159:15)
Block(0,17,5,251:15)
Block(0,17,6,251:15)
Block(0,17,7,159:15)
Block(0,17,8,251:15)
Block(0,18,-4,251:15)
Block(0,18,-3,159:15)
Block(0,18,-2,159:15)
Block(0,18,-1,251:15)
Block(0,18,0,251:15)
Block(0,18,1,251:15)
Block(0,18,2,251:15)
Block(0,18,3,159:15)
Block(0,18,4,251:15)
Block(0,18,5,251:15)
Block(0,18,6,159:15)
Block(0,18,7,159:15)
Block(0,18,8,251:15)
Block(0,19,-4,159:15)
Block(0,19,-3,251:15)
Block(0,19,-2,251:15)
Block(0,19,-1,251:15)
Block(0,19,0,251:15)
Block(0,19,1,159:15)
Block(0,19,2,251:15)
Block(0,19,3,159:15)
Block(0,19,4,159:15)
Block(0,19,5,251:15)
Block(0,19,6,251:15)
Block(0,19,7,159:15)
Block(0,19,8,251:15)
Block(0,20,-4,159:15)
Block(0,20,-3,159:15)
Block(0,20,-2,251:15)
Block(0,20,-1,159:15)
Block(0,20,0,251:15)
Block(0,20,1,251:15)
Block(0,20,2,159:15)
Block(0,20,3,251:15)
Block(0,20,4,251:15)
Block(0,20,5,159:15)
Block(0,20,6,159:15)
Block(0,20,7,159:15)
Block(0,20,8,159:15)
Block(0,21,-4,251:15)
Block(0,21,-3,251:15)
Block(0,21,-2,251:15)
Block(0,21,-1,159:15)
Block(0,21,0,251:15)
Block(0,21,1,159:15)
Block(0,21,2,159:15)
Block(0,21,3,251:15)
Block(0,21,4,251:15)
Block(0,21,5,159:15)
Block(0,21,6,251:15)
Block(0,21,7,159:15)
Block(0,21,8,251:15)
Block(0,22,-4,159:15)
Block(0,22,-3,159:15)
Block(0,22,-2,251:15)
Block(0,22,-1,159:15)
Block(0,22,0,251:15)
Block(0,22,1,159:15)
Block(0,22,2,251:15)
Block(0,22,3,251:15)
Block(0,22,4,251:15)
Block(0,22,5,251:15)
Block(0,22,6,159:15)
Block(0,22,7,159:15)
Block(0,22,8,251:15)
Block(0,23,-4,251:15)
Block(0,23,-3,159:15)
Block(0,23,-2,251:15)
Block(0,23,-1,159:15)
Block(0,23,0,251:15)
Block(0,23,1,159:15)
Block(0,23,2,251:15)
Block(0,23,3,159:15)
Block(0,23,4,251:15)
Block(0,23,5,251:15)
Block(0,23,6,251:15)
Block(0,23,7,159:15)
Block(0,23,8,159:15)
Block(0,24,-4,251:15)
Block(0,24,-3,159:15)
Block(0,24,-2,159:15)
Block(0,24,-1,251:15)
Block(0,24,0,159:15)
Block(0,24,1,159:15)
Block(0,24,2,159:15)
Block(0,24,3,251:15)
Block(0,24,4,159:15)
Block(0,24,5,159:15)
Block(0,24,6,251:15)
Block(0,24,7,159:15)
Block(0,24,8,159:15)
Block(0,25,-4,251:15)
Block(0,25,-3,159:15)
Block(0,25,-2,251:15)
Block(0,25,-1,159:15)
Block(0,25,0,159:15)
Block(0,25,1,251:15)
Block(0,25,2,159:15)
Block(0,25,3,159:15)
Block(0,25,4,251:15)
Block(0,25,5,159:15)
Block(0,25,6,159:15)
Block(0,25,7,251:15)
Block(0,25,8,159:15)
Block(0,26,-4,251:15)
Block(0,26,-3,251:15)
Block(0,26,-2,159:15)
Block(0,26,-1,251:15)
Block(0,26,0,159:15)
