

BranchFrequency: 10

BranchFrequencyGroup: CanOverride:0

CanOverride: true

SmoothRadius: -1

OverrideChildSettings: false

ReplaceAbove:
ReplaceBelow:

MustBeInside: VillageGeneratorStructurePlaceHolder, VillageGeneratorStructuresDelay, VillageGeneratorStructuresDelay2, VillageGeneratorStructuresDelay3, VillageGeneratorStructuresDelay4, VillageGeneratorStructuresDelay5, VillageGeneratorStructuresDelay6, VillageGeneratorStructuresDelay7, VillageGeneratorStructuresDelay8, VillageGeneratorStructuresDelay9, VillageGeneratorStructuresDelay10

Block(-8,0,0,98)
Block(-8,0,1,98)
Block(-8,0,2,98)
Block(-8,0,3,98)
Block(-8,0,4,98)
Block(-8,0,5,98)
Block(-8,0,6,98)
Block(-8,0,7,98)
Block(-8,0,8,98)
Block(-8,1,0,98)
Block(-8,1,1,98)
Block(-8,1,2,98)
Block(-8,1,3,98)
Block(-8,1,4,98)
Block(-8,1,5,98)
Block(-8,1,6,98)
Block(-8,1,7,98)
Block(-8,1,8,98)
Block(-8,2,0,98)
Block(-8,2,1,98)
Block(-8,2,2,98)
Block(-8,2,3,98)
Block(-8,2,4,98)
Block(-8,2,5,98)
Block(-8,2,6,98)
Block(-8,2,7,98)
Block(-8,2,8,98)
Block(-8,3,0,98)
Block(-8,3,1,98)
Block(-8,3,2,98)
Block(-8,3,3,98)
Block(-8,3,4,98)
Block(-8,3,5,98)
Block(-8,3,6,98)
Block(-8,3,7,98)
Block(-8,3,8,98)
Block(-8,4,0,98)
Block(-8,4,1,98)
Block(-8,4,2,98)
Block(-8,4,3,98)
Block(-8,4,4,98)
Block(-8,4,5,98)
Block(-8,4,6,98)
Block(-8,4,7,98)
Block(-8,4,8,98)
Block(-8,5,0,35:14)
Block(-8,5,1,35:14)
Block(-8,5,2,35:14)
Block(-8,5,3,35:14)
Block(-8,5,4,35:14)
Block(-8,5,5,35:14)
Block(-8,5,6,35:14)
Block(-8,5,7,35:14)
Block(-8,5,8,35:14)
Block(-8,6,0,98)
Block(-8,6,1,98)
Block(-8,6,2,98)
Block(-8,6,3,98)
Block(-8,6,4,98)
Block(-8,6,5,98)
Block(-8,6,6,98)
Block(-8,6,7,98)
Block(-8,6,8,98)
Block(-8,7,0,98)
Block(-8,7,1,98)
Block(-8,7,2,98)
Block(-8,7,3,98)
Block(-8,7,4,98)
Block(-8,7,5,98)
Block(-8,7,6,98)
Block(-8,7,7,98)
Block(-8,7,8,98)
Block(-8,8,0,98)
Block(-8,8,1,98)
Block(-8,8,2,98)
Block(-8,8,3,98)
Block(-8,8,4,98)
Block(-8,8,5,98)
Block(-8,8,6,98)
Block(-8,8,7,98)
Block(-8,8,8,98)
Block(-8,9,0,98)
Block(-8,9,1,98)
Block(-8,9,2,98)
Block(-8,9,3,98)
Block(-8,9,4,98)
Block(-8,9,5,98)
Block(-8,9,6,98)
Block(-8,9,7,98)
Block(-8,9,8,98)
Block(-8,10,0,98)
Block(-8,10,1,98)
Block(-8,10,2,98)
Block(-8,10,3,98)
Block(-8,10,4,98)
Block(-8,10,5,98)
Block(-8,10,6,98)
Block(-8,10,7,98)
Block(-8,10,8,98)
Block(-8,11,0,136)
Block(-8,11,1,136)
Block(-8,11,2,136)
Block(-8,11,3,136)
Block(-8,11,4,136)
Block(-8,11,5,136)
Block(-8,11,6,136)
Block(-8,11,7,136)
Block(-8,11,8,136)
Block(-7,0,-6,98)
Block(-7,0,-5,98)
Block(-7,0,-4,98)
Block(-7,0,-3,98)
Block(-7,0,-2,98)
Block(-7,0,-1,98)
Block(-7,0,0,98)
Block(-7,0,1,65:5)
Block(-7,0,8,98)
Block(-7,1,-6,98)
Block(-7,1,-5,98)
Block(-7,1,-4,98)
Block(-7,1,-3,98)
Block(-7,1,-2,98)
Block(-7,1,-1,98)
Block(-7,1,0,98)
Block(-7,1,1,65:5)
Block(-7,1,8,98)
Block(-7,2,-6,98)
Block(-7,2,-5,98)
Block(-7,2,-4,98)
Block(-7,2,-3,98)
Block(-7,2,-2,98)
Block(-7,2,-1,98)
Block(-7,2,0,98)
Block(-7,2,1,65:5)
Block(-7,2,8,98)
Block(-7,3,-6,98)
Block(-7,3,-5,98)
Block(-7,3,-4,98)
Block(-7,3,-3,98)
Block(-7,3,-2,98)
Block(-7,3,-1,98)
Block(-7,3,0,98)
Block(-7,3,1,65:5)
Block(-7,3,8,98)
Block(-7,4,-6,136:2)
Block(-7,4,-5,136)
Block(-7,4,-4,136)
Block(-7,4,-3,136)
Block(-7,4,-2,136)
Block(-7,4,-1,136)
Block(-7,4,0,98)
Block(-7,4,1,65:5)
Block(-7,4,8,98)
Block(-7,5,0,35:14)
Block(-7,5,1,65:5)
Block(-7,5,7,89)
Block(-7,5,8,35:14)
Block(-7,6,0,98)
Block(-7,6,1,65:5)
Block(-7,6,2,98)
Block(-7,6,3,98)
Block(-7,6,4,98)
Block(-7,6,5,98)
Block(-7,6,6,98)
Block(-7,6,7,98)
Block(-7,6,8,98)
Block(-7,7,0,98)
Block(-7,7,7,54:2,1-Chest.nbt)
Block(-7,7,8,98)
Block(-7,8,0,98)
Block(-7,8,8,98)
Block(-7,9,0,98)
Block(-7,9,8,98)
Block(-7,10,0,98)
Block(-7,10,8,98)
Block(-7,11,0,136:2)
Block(-7,11,8,98)
Block(-7,12,1,136:2)
Block(-7,12,2,136)
Block(-7,12,3,136)
Block(-7,12,4,136)
Block(-7,12,5,136)
Block(-7,12,6,136)
Block(-7,12,7,136)
Block(-7,12,8,136)
Block(-7,16,8,109:6)
Block(-7,17,8,98)
Block(-7,18,8,139)
Block(-7,19,8,136:2)
Block(-6,0,-6,98)
Block(-6,0,8,98)
Block(-6,1,-6,98)
Block(-6,1,8,98)
Block(-6,2,-6,98)
Block(-6,2,8,98)
Block(-6,3,-6,98)
Block(-6,3,8,98)
Block(-6,4,-6,136:2)
Block(-6,4,8,98)
Block(-6,5,-5,136:2)
Block(-6,5,-4,136)
Block(-6,5,-3,136)
Block(-6,5,-2,136)
Block(-6,5,-1,136)
Block(-6,5,0,35:14)
Block(-6,5,8,35:14)
Block(-6,6,0,98)
Block(-6,6,1,98)
Block(-6,6,2,98)
Block(-6,6,3,98)
Block(-6,6,4,98)
Block(-6,6,5,98)
Block(-6,6,6,98)
Block(-6,6,7,98)
Block(-6,6,8,98)
Block(-6,7,0,98)
Block(-6,7,1,44:5)
Block(-6,7,7,54:2,2-Chest.nbt)
Block(-6,7,8,98)
Block(-6,8,0,98)
Block(-6,8,8,98)
Block(-6,9,0,98)
Block(-6,9,8,98)
Block(-6,10,0,98)
Block(-6,10,8,98)
Block(-6,11,0,136:2)
Block(-6,11,8,98)
Block(-6,12,1,136:2)
Block(-6,12,8,98)
Block(-6,13,2,136)
Block(-6,13,3,136)
Block(-6,13,4,136)
Block(-6,13,5,136)
Block(-6,13,6,136)
Block(-6,13,7,136)
Block(-6,13,8,136)
Block(-6,16,8,109:6)
Block(-6,17,8,98)
Block(-6,19,8,136:2)
Block(-5,0,-6,98)
Block(-5,0,8,98)
Block(-5,1,8,98)
Block(-5,2,8,98)
Block(-5,3,-6,98)
Block(-5,3,8,98)
Block(-5,4,-6,136:2)
Block(-5,4,8,98)
Block(-5,5,-5,136:2)
Block(-5,5,0,35:14)
Block(-5,5,8,98)
Block(-5,6,-4,136:2)
Block(-5,6,-3,136)
Block(-5,6,-2,136)
Block(-5,6,-1,136)
Block(-5,6,0,98)
Block(-5,6,1,98)
Block(-5,6,2,98)
Block(-5,6,3,98)
Block(-5,6,4,98)
Block(-5,6,5,98)
Block(-5,6,6,98)
Block(-5,6,7,98)
Block(-5,6,8,98)
Block(-5,7,0,98)
Block(-5,7,1,44:5)
Block(-5,7,8,98)
Block(-5,8,8,98)
Block(-5,9,8,98)
Block(-5,10,0,98)
Block(-5,10,8,98)
Block(-5,11,0,136:2)
Block(-5,11,8,98)
Block(-5,12,1,136:2)
Block(-5,12,8,98)
Block(-5,13,2,136:2)
Block(-5,13,8,98)
Block(-5,14,3,136:2)
Block(-5,14,4,136)
Block(-5,14,5,136)
Block(-5,14,6,136)
Block(-5,14,7,136)
Block(-5,14,8,136)
Block(-5,16,8,109:6)
Block(-5,17,8,98)
Block(-5,19,8,136:2)
Block(-4,0,-6,98)
Block(-4,0,8,98)
Block(-4,1,8,98)
Block(-4,2,8,98)
Block(-4,3,-6,98)
Block(-4,3,8,98)
Block(-4,4,-6,136:2)
Block(-4,4,8,98)
Block(-4,5,-5,136:2)
Block(-4,5,0,35:14)
Block(-4,5,8,98)
Block(-4,6,-4,136:2)
Block(-4,6,0,98)
Block(-4,6,1,98)
Block(-4,6,2,98)
Block(-4,6,3,98)
Block(-4,6,4,98)
Block(-4,6,5,98)
Block(-4,6,6,98)
Block(-4,6,7,98)
Block(-4,6,8,98)
Block(-4,7,-3,136:2)
Block(-4,7,-2,136)
Block(-4,7,-1,136)
Block(-4,7,0,98)
Block(-4,7,1,44:5)
Block(-4,7,7,54:2,3-Chest.nbt)
Block(-4,7,8,98)
Block(-4,8,8,98)
Block(-4,9,8,98)
Block(-4,10,0,98)
Block(-4,10,8,98)
Block(-4,11,0,136:2)
Block(-4,11,8,98)
Block(-4,12,1,136:2)
Block(-4,12,8,98)
Block(-4,13,2,136:2)
Block(-4,13,8,98)
Block(-4,14,3,136:2)
Block(-4,14,4,89)
Block(-4,14,7,89)
Block(-4,14,8,98)
Block(-4,15,4,136)
Block(-4,15,5,136)
Block(-4,15,6,136)
Block(-4,15,7,136)
Block(-4,15,8,136)
Block(-4,16,8,109:6)
Block(-4,17,8,98)
Block(-4,19,8,136:2)
Block(-3,0,-6,98)
Block(-3,0,8,98)
Block(-3,1,-6,98)
Block(-3,1,8,98)
Block(-3,2,-6,98)
Block(-3,2,8,98)
Block(-3,3,-6,98)
Block(-3,3,8,98)
Block(-3,4,-6,136:2)
Block(-3,4,8,98)
Block(-3,5,-5,136:2)
Block(-3,5,0,35:14)
Block(-3,5,8,98)
Block(-3,6,-4,136:2)
Block(-3,6,0,98)
Block(-3,6,1,98)
Block(-3,6,2,98)
Block(-3,6,3,98)
Block(-3,6,4,98)
Block(-3,6,5,98)
Block(-3,6,6,98)
Block(-3,6,7,98)
Block(-3,6,8,98)
Block(-3,7,-3,136:2)
Block(-3,7,-1,89)
Block(-3,7,0,98)
Block(-3,7,1,44:5)
Block(-3,7,7,54:2,4-Chest.nbt)
Block(-3,7,8,98)
Block(-3,8,-2,126:3)
Block(-3,8,-1,126:3)
Block(-3,8,0,98)
Block(-3,8,8,98)
Block(-3,9,0,98)
Block(-3,9,8,98)
Block(-3,10,0,98)
Block(-3,10,8,98)
Block(-3,11,0,136:2)
Block(-3,11,8,98)
Block(-3,12,1,136:2)
Block(-3,12,8,98)
Block(-3,13,2,136:2)
Block(-3,13,8,98)
Block(-3,14,3,136:2)
Block(-3,14,4,89)
Block(-3,14,7,89)
Block(-3,14,8,98)
Block(-3,15,4,136:1)
Block(-3,15,5,136:1)
Block(-3,15,6,136:1)
Block(-3,15,7,136:1)
Block(-3,15,8,136:1)
Block(-3,16,8,109:6)
Block(-3,17,8,98)
Block(-3,18,8,139)
Block(-3,19,8,136:2)
Block(-2,0,-6,98)
Block(-2,0,8,98)
Block(-2,1,8,98)
Block(-2,2,8,98)
Block(-2,3,-6,98)
Block(-2,3,8,98)
Block(-2,4,-6,136:2)
Block(-2,4,8,98)
Block(-2,5,-5,136:2)
Block(-2,5,0,35:14)
Block(-2,5,8,98)
Block(-2,6,-4,136:2)
Block(-2,6,0,98)
Block(-2,6,1,98)
Block(-2,6,2,98)
Block(-2,6,3,98)
Block(-2,6,4,98)
Block(-2,6,5,98)
Block(-2,6,6,98)
Block(-2,6,7,98)
Block(-2,6,8,98)
Block(-2,7,-3,136:1)
Block(-2,7,-2,136:1)
Block(-2,7,-1,136:1)
Block(-2,7,0,98)
Block(-2,7,1,44:5)
Block(-2,7,8,98)
Block(-2,8,8,98)
Block(-2,9,8,98)
Block(-2,10,0,98)
Block(-2,10,8,98)
Block(-2,11,0,136:2)
Block(-2,11,8,98)
Block(-2,12,1,136:2)
Block(-2,12,8,98)
Block(-2,13,2,136:2)
Block(-2,13,8,98)
Block(-2,14,3,136:1)
Block(-2,14,4,136:1)
Block(-2,14,5,136:1)
Block(-2,14,6,136:1)
Block(-2,14,7,136:1)
Block(-2,14,8,136:1)
Block(-2,16,8,109:6)
Block(-2,17,8,98)
Block(-2,19,8,136:2)
Block(-1,0,-7,106:1)
Block(-1,0,-6,98)
Block(-1,0,8,98)
Block(-1,1,-6,106:8)
Block(-1,1,8,98)
Block(-1,2,-6,106:8)
Block(-1,2,8,98)
Block(-1,3,-6,98)
Block(-1,3,8,98)
Block(-1,4,-6,136:2)
Block(-1,4,8,98)
Block(-1,5,-5,136:2)
Block(-1,5,0,35:14)
Block(-1,5,8,98)
Block(-1,6,-4,136:1)
Block(-1,6,-3,136:1)
Block(-1,6,-2,136:1)
Block(-1,6,-1,136:1)
Block(-1,6,0,98)
Block(-1,6,1,98)
Block(-1,6,2,98)
Block(-1,6,3,98)
Block(-1,6,4,98)
Block(-1,6,5,98)
Block(-1,6,6,98)
Block(-1,6,7,98)
Block(-1,6,8,98)
Block(-1,7,0,98)
Block(-1,7,1,44:5)
Block(-1,7,7,54:2,5-Chest.nbt)
Block(-1,7,8,98)
Block(-1,8,8,98)
Block(-1,9,8,98)
Block(-1,10,0,98)
Block(-1,10,8,98)
Block(-1,11,0,136:2)
Block(-1,11,8,98)
Block(-1,12,1,136:2)
Block(-1,12,8,98)
Block(-1,13,2,136:2)
Block(-1,13,3,136:1)
Block(-1,13,4,136:1)
Block(-1,13,5,136:1)
Block(-1,13,6,136:1)
Block(-1,13,7,136:1)
Block(-1,13,8,136:1)
Block(-1,16,8,109:6)
Block(-1,17,8,98)
Block(-1,19,8,136:2)
Block(0,0,-7,106:1)
Block(0,0,-6,98)
Block(0,0,8,98)
Block(0,1,-7,106:1)
Block(0,1,-6,98)
Block(0,1,8,98)
Block(0,2,-7,106:1)
Block(0,2,-6,98)
Block(0,2,8,98)
Block(0,3,-6,98)
Block(0,3,8,98)
Block(0,4,-6,136:2)
Block(0,4,8,98)
Block(0,5,-5,136:1)
Block(0,5,-4,136:1)
Block(0,5,-3,136:1)
Block(0,5,-2,136:1)
Block(0,5,-1,136:1)
Block(0,5,0,35:14)
Block(0,5,8,35:14)
Block(0,6,0,98)
Block(0,6,1,98)
Block(0,6,2,98)
Block(0,6,3,98)
Block(0,6,4,98)
Block(0,6,5,98)
Block(0,6,6,98)
Block(0,6,7,98)
Block(0,6,8,98)
Block(0,7,0,98)
Block(0,7,1,44:5)
Block(0,7,2,44:5)
Block(0,7,3,44:5)
Block(0,7,4,44:5)
Block(0,7,5,44:5)
Block(0,7,6,44:5)
Block(0,7,7,54:2,6-Chest.nbt)
Block(0,7,8,98)
Block(0,8,0,98)
Block(0,8,8,98)
Block(0,9,0,98)
Block(0,9,8,98)
Block(0,10,0,98)
Block(0,10,8,98)
Block(0,11,0,136:2)
Block(0,11,8,98)
Block(0,12,1,136:1)
Block(0,12,2,136:1)
Block(0,12,3,136:1)
Block(0,12,4,136:1)
Block(0,12,5,136:1)
Block(0,12,6,136:1)
Block(0,12,7,136:1)
Block(0,12,8,136:1)
Block(0,16,8,109:6)
Block(0,17,8,98)
Block(0,19,8,136:2)
Block(1,0,-7,106:1)
Block(1,0,-6,98)
Block(1,0,-5,98)
Block(1,0,-4,98)
Block(1,0,-3,98)
Block(1,0,-2,98)
Block(1,0,-1,98)
Block(1,0,0,98)
Block(1,0,4,139)
Block(1,0,8,98)
Block(1,1,-7,106:1)
Block(1,1,-6,98)
Block(1,1,-5,98)
Block(1,1,-4,98)
Block(1,1,-3,98)
Block(1,1,-2,98)
Block(1,1,-1,98)
Block(1,1,0,98)
Block(1,1,4,139)
Block(1,1,8,98)
Block(1,2,-7,106:1)
Block(1,2,-6,98)
Block(1,2,-5,98)
Block(1,2,-4,98)
Block(1,2,-3,98)
Block(1,2,-2,98)
Block(1,2,-1,98)
Block(1,2,0,98)
Block(1,2,4,139)
Block(1,2,8,98)
Block(1,3,-6,98)
Block(1,3,-5,98)
Block(1,3,-4,98)
Block(1,3,-3,98)
Block(1,3,-2,98)
Block(1,3,-1,98)
Block(1,3,0,98)
Block(1,3,1,109:7)
Block(1,3,3,109:6)
Block(1,3,4,98)
Block(1,3,5,109:7)
Block(1,3,7,109:6)
Block(1,3,8,98)
Block(1,4,-6,136:1)
Block(1,4,-5,136:1)
Block(1,4,-4,136:1)
Block(1,4,-3,136:1)
Block(1,4,-2,136:1)
Block(1,4,-1,136:1)
Block(1,4,0,98)
Block(1,4,1,98)
Block(1,4,2,98)
Block(1,4,3,43:5)
Block(1,4,4,98)
Block(1,4,5,98)
Block(1,4,6,98)
Block(1,4,7,98)
Block(1,4,8,98)
Block(1,5,0,35:14)
Block(1,5,1,35:14)
Block(1,5,2,35:14)
Block(1,5,3,35:14)
Block(1,5,4,35:14)
Block(1,5,5,35:14)
Block(1,5,6,35:14)
Block(1,5,7,35:14)
Block(1,5,8,35:14)
Block(1,6,0,98)
Block(1,6,1,98)
Block(1,6,2,98)
Block(1,6,3,98)
Block(1,6,4,98)
Block(1,6,5,98)
Block(1,6,6,98)
Block(1,6,7,98)
Block(1,6,8,98)
Block(1,7,0,98)
Block(1,7,1,98)
Block(1,7,2,98)
Block(1,7,3,98)
Block(1,7,4,98)
Block(1,7,5,98)
Block(1,7,6,98)
Block(1,7,7,98)
Block(1,7,8,98)
Block(1,8,0,98)
Block(1,8,1,98)
Block(1,8,4,43:5)
Block(1,8,7,98)
Block(1,8,8,98)
Block(1,9,0,98)
Block(1,9,1,98)
Block(1,9,4,43:5)
Block(1,9,7,98)
Block(1,9,8,98)
Block(1,10,0,98)
Block(1,10,1,98)
Block(1,10,2,98)
Block(1,10,3,98)
Block(1,10,4,98)
Block(1,10,5,98)
Block(1,10,6,98)
Block(1,10,7,98)
Block(1,10,8,98)
Block(1,11,0,136:2)
Block(1,11,1,136:1)
Block(1,11,2,136:1)
Block(1,11,3,136:1)
Block(1,11,4,136:1)
Block(1,11,5,136:1)
Block(1,11,6,136:1)
Block(1,11,7,136:1)
Block(1,11,8,136:1)
Block(1,16,8,109:6)
Block(1,17,8,98)
Block(1,18,8,139)
Block(1,19,8,136:2)
Block(2,0,-6,106:1)
Block(2,0,-5,98)
Block(2,2,-5,109:5)
Block(2,2,-1,109:5)
Block(2,3,-5,136:2)
Block(2,3,-1,136:3)
Block(2,4,-4,136:2)
Block(2,4,-3,126:11)
Block(2,4,-2,136:3)
Block(2,5,-3,126:3)
Block(3,0,-5,98)
Block(3,3,-5,136:2)
Block(3,3,-1,136:3)
Block(3,4,-4,136:2)
Block(3,4,-2,136:3)
Block(3,5,-3,126:3)
Block(4,0,-5,98)
Block(4,2,-5,109:4)
Block(4,2,-1,109:4)
Block(4,3,-5,136:2)
Block(4,3,-1,136:3)
Block(4,4,-4,136:2)
Block(4,4,-2,136:3)
Block(4,5,-3,126:3)
Block(5,0,-5,98)
Block(5,0,-1,139)
Block(5,1,-5,139)
Block(5,1,-1,139)
Block(5,2,-5,98)
Block(5,2,-1,98)
Block(5,3,-5,136:2)
Block(5,3,-1,136:3)
Block(5,4,-4,136:2)
Block(5,4,-2,136:3)
Block(5,5,-3,126:3)
Block(6,0,-5,98)
Block(6,2,-5,109:5)
Block(6,2,-1,109:5)
Block(6,3,-5,136:2)
Block(6,3,-1,136:3)
Block(6,4,-4,136:2)
Block(6,4,-2,136:3)
Block(6,5,-3,126:3)
Block(7,0,-5,98)
Block(7,3,-5,136:2)
Block(7,3,-1,136:3)
Block(7,4,-4,136:2)
Block(7,4,-2,136:3)
Block(7,5,-3,126:3)

Branch(16,0,0,true,archery-range-ageC1R0,NORTH,100,0)
Branch(0,0,16,true,archery-range-ageC0R1,NORTH,100,0)
