

BranchFrequencyGroup: CanOverride:0

CanOverride: true

SmoothRadius: -1

OverrideChildSettings: false

ReplaceAbove:
ReplaceBelow:

MustBeInside: VillageGeneratorStructurePlaceHolder, VillageGeneratorStructuresDelay, VillageGeneratorStructuresDelay2, VillageGeneratorStructuresDelay3, VillageGeneratorStructuresDelay4, VillageGeneratorStructuresDelay5, VillageGeneratorStructuresDelay6, VillageGeneratorStructuresDelay7, VillageGeneratorStructuresDelay8, VillageGeneratorStructuresDelay9, VillageGeneratorStructuresDelay10

Block(-8,0,-5,98)
Block(-8,2,-5,109:4)
Block(-8,2,-1,109:4)
Block(-8,3,-5,136:2)
Block(-8,3,-1,136:3)
Block(-8,4,-4,136:2)
Block(-8,4,-2,136:3)
Block(-8,5,-3,126:3)
Block(-7,0,-5,98)
Block(-7,0,-1,139)
Block(-7,1,-5,139)
Block(-7,1,-1,139)
Block(-7,2,-5,98)
Block(-7,2,-1,98)
Block(-7,3,-5,136:2)
Block(-7,3,-1,136:3)
Block(-7,4,-4,136:2)
Block(-7,4,-2,136:3)
Block(-7,5,-3,126:3)
Block(-6,0,-5,98)
Block(-6,2,-5,109:5)
Block(-6,2,-1,109:5)
Block(-6,3,-5,136:2)
Block(-6,3,-1,136:3)
Block(-6,4,-4,136:2)
Block(-6,4,-2,136:3)
Block(-6,5,-3,126:3)
Block(-5,0,-5,98)
Block(-5,3,-5,136:2)
Block(-5,3,-1,136:3)
Block(-5,4,-4,136:2)
Block(-5,4,-2,136:3)
Block(-5,5,-3,126:3)
Block(-4,0,-5,98)
Block(-4,2,-5,109:4)
Block(-4,2,-1,109:4)
Block(-4,3,-5,136:2)
Block(-4,3,-1,136:3)
Block(-4,4,-4,136:2)
Block(-4,4,-2,136:3)
Block(-4,5,-3,126:3)
Block(-3,0,-5,98)
Block(-3,0,-4,98)
Block(-3,0,-3,98)
Block(-3,0,-2,98)
Block(-3,0,-1,98)
Block(-3,1,-5,139)
Block(-3,1,-1,139)
Block(-3,2,-5,98)
Block(-3,2,-4,109:7)
Block(-3,2,-2,109:6)
Block(-3,2,-1,98)
Block(-3,3,-5,136:2)
Block(-3,3,-4,98)
Block(-3,3,-3,98)
Block(-3,3,-2,98)
Block(-3,3,-1,136:3)
Block(-3,4,-4,136:2)
Block(-3,4,-3,125:3)
Block(-3,4,-2,136:3)
Block(-3,5,-3,126:3)
