

BranchFrequencyGroup: CanOverride:0

CanOverride: true

SmoothRadius: -1

OverrideChildSettings: false

ReplaceAbove:
ReplaceBelow:

MustBeInside: VillageGeneratorStructurePlaceHolder, VillageGeneratorStructuresDelay, VillageGeneratorStructuresDelay2, VillageGeneratorStructuresDelay3, VillageGeneratorStructuresDelay4, VillageGeneratorStructuresDelay5, VillageGeneratorStructuresDelay6, VillageGeneratorStructuresDelay7, VillageGeneratorStructuresDelay8, VillageGeneratorStructuresDelay9, VillageGeneratorStructuresDelay10

Block(-7,16,-7,109:4)
Block(-7,16,-6,109:4)
Block(-7,16,-5,109:4)
Block(-7,16,-4,109:4)
Block(-7,16,-3,109:4)
Block(-7,16,-2,109:4)
Block(-7,17,-7,98)
Block(-7,17,-6,98)
Block(-7,17,-5,98)
Block(-7,17,-4,98)
Block(-7,17,-3,98)
Block(-7,17,-2,98)
Block(-7,18,-5,139)
Block(-7,18,-2,139)
Block(-7,19,-7,136)
Block(-7,19,-6,136)
Block(-7,19,-5,136)
Block(-7,19,-4,136)
Block(-7,19,-3,136)
Block(-7,19,-2,136)
Block(-6,0,-7,98)
Block(-6,0,-6,98)
Block(-6,0,-5,98)
Block(-6,0,-4,98)
Block(-6,0,-3,98)
Block(-6,1,-7,98)
Block(-6,1,-6,98)
Block(-6,1,-5,98)
Block(-6,1,-4,98)
Block(-6,1,-3,98)
Block(-6,2,-7,98)
Block(-6,2,-6,98)
Block(-6,2,-5,98)
Block(-6,2,-4,98)
Block(-6,2,-3,98)
Block(-6,3,-7,98)
Block(-6,3,-6,98)
Block(-6,3,-5,98)
Block(-6,3,-4,98)
Block(-6,3,-3,98)
Block(-6,4,-7,98)
Block(-6,4,-6,98)
Block(-6,4,-5,98)
Block(-6,4,-4,98)
Block(-6,4,-3,98)
Block(-6,5,-7,98)
Block(-6,5,-6,98)
Block(-6,5,-5,98)
Block(-6,5,-4,98)
Block(-6,5,-3,98)
Block(-6,6,-7,98)
Block(-6,6,-6,98)
Block(-6,6,-5,98)
Block(-6,6,-4,98)
Block(-6,6,-3,98)
Block(-6,7,-7,98)
Block(-6,7,-6,98)
Block(-6,7,-5,98)
Block(-6,7,-4,98)
Block(-6,7,-3,98)
Block(-6,8,-7,98)
Block(-6,8,-6,98)
Block(-6,8,-5,98)
Block(-6,8,-4,98)
Block(-6,8,-3,98)
Block(-6,9,-7,35:14)
Block(-6,9,-6,35:14)
Block(-6,9,-5,35:14)
Block(-6,9,-4,35:14)
Block(-6,9,-3,35:14)
Block(-6,10,-7,98)
Block(-6,10,-6,98)
Block(-6,10,-5,98)
Block(-6,10,-4,98)
Block(-6,10,-3,98)
Block(-6,11,-7,98)
Block(-6,11,-6,98)
Block(-6,11,-5,98)
Block(-6,11,-4,98)
Block(-6,11,-3,98)
Block(-6,12,-7,98)
Block(-6,12,-6,98)
Block(-6,12,-5,98)
Block(-6,12,-4,98)
Block(-6,12,-3,98)
Block(-6,13,-7,98)
Block(-6,13,-6,98)
Block(-6,13,-5,98)
Block(-6,13,-4,98)
Block(-6,13,-3,98)
Block(-6,14,-7,98)
Block(-6,14,-6,98)
Block(-6,14,-5,98)
Block(-6,14,-4,98)
Block(-6,14,-3,98)
Block(-6,15,-7,98)
Block(-6,15,-6,98)
Block(-6,15,-5,98)
Block(-6,15,-4,98)
Block(-6,15,-3,98)
Block(-6,16,-7,98)
Block(-6,16,-6,98)
Block(-6,16,-5,98)
Block(-6,16,-4,98)
Block(-6,16,-3,98)
Block(-6,16,-2,109:7)
Block(-6,17,-2,98)
Block(-6,19,-2,136:3)
Block(-6,20,-7,136:2)
Block(-6,20,-6,136)
Block(-6,20,-5,136)
Block(-6,20,-4,136)
Block(-6,20,-3,136:3)
Block(-5,0,-7,98)
Block(-5,0,-6,98)
Block(-5,0,-5,98)
Block(-5,0,-4,98)
Block(-5,0,-3,98)
Block(-5,0,-2,98)
Block(-5,0,-1,98)
Block(-5,0,0,98)
Block(-5,1,-7,98)
Block(-5,1,-6,98)
Block(-5,1,-5,98)
Block(-5,1,-4,98)
Block(-5,1,-3,98)
Block(-5,1,-2,98)
Block(-5,1,-1,98)
Block(-5,1,0,98)
Block(-5,2,-7,98)
Block(-5,2,-6,98)
Block(-5,2,-5,98)
Block(-5,2,-4,98)
Block(-5,2,-3,98)
Block(-5,2,-2,98)
Block(-5,2,-1,98)
Block(-5,2,0,98)
Block(-5,3,-7,98)
Block(-5,3,-6,98)
Block(-5,3,-5,98)
Block(-5,3,-4,98)
Block(-5,3,-3,98)
Block(-5,3,-2,98)
Block(-5,3,-1,98)
Block(-5,3,0,98)
Block(-5,4,-7,98)
Block(-5,4,-6,98)
Block(-5,4,-5,98)
Block(-5,4,-4,98)
Block(-5,4,-3,98)
Block(-5,4,-2,98)
Block(-5,4,-1,98)
Block(-5,4,0,98)
Block(-5,5,-7,98)
Block(-5,5,-6,98)
Block(-5,5,-5,98)
Block(-5,5,-4,98)
Block(-5,5,-3,98)
Block(-5,5,-2,98)
Block(-5,5,-1,98)
Block(-5,5,0,98)
Block(-5,6,-7,98)
Block(-5,6,-6,98)
Block(-5,6,-5,98)
Block(-5,6,-4,98)
Block(-5,6,-3,98)
Block(-5,6,-2,98)
Block(-5,6,-1,98)
Block(-5,6,0,98)
Block(-5,7,-7,98)
Block(-5,7,-6,98)
Block(-5,7,-5,98)
Block(-5,7,-4,98)
Block(-5,7,-3,98)
Block(-5,7,-2,98)
Block(-5,7,-1,98)
Block(-5,7,0,98)
Block(-5,8,-7,98)
Block(-5,8,-6,98)
Block(-5,8,-5,98)
Block(-5,8,-4,98)
Block(-5,8,-3,98)
Block(-5,8,-2,98)
Block(-5,8,-1,98)
Block(-5,8,0,98)
Block(-5,9,-7,98)
Block(-5,9,-6,98)
Block(-5,9,-5,98)
Block(-5,9,-4,98)
Block(-5,9,-3,98)
Block(-5,9,-2,35:14)
Block(-5,9,-1,35:14)
Block(-5,9,0,35:14)
Block(-5,10,-7,98)
Block(-5,10,-6,98)
Block(-5,10,-5,98)
Block(-5,10,-4,98)
Block(-5,10,-3,98)
Block(-5,11,-7,98)
Block(-5,11,-6,98)
Block(-5,11,-5,98)
Block(-5,11,-4,98)
Block(-5,11,-3,98)
Block(-5,12,-7,98)
Block(-5,12,-6,98)
Block(-5,12,-5,98)
Block(-5,12,-4,98)
Block(-5,12,-3,98)
Block(-5,13,-7,98)
Block(-5,13,-6,98)
Block(-5,13,-5,98)
Block(-5,13,-4,98)
Block(-5,13,-3,98)
Block(-5,14,-7,98)
Block(-5,14,-6,98)
Block(-5,14,-5,98)
Block(-5,14,-4,98)
Block(-5,14,-3,98)
Block(-5,15,-7,98)
Block(-5,15,-6,98)
Block(-5,15,-5,98)
Block(-5,15,-4,98)
Block(-5,15,-3,98)
Block(-5,16,-7,98)
Block(-5,16,-6,98)
Block(-5,16,-5,98)
Block(-5,16,-4,98)
Block(-5,16,-3,98)
Block(-5,16,-2,109:7)
Block(-5,17,-2,98)
Block(-5,19,-2,136:3)
Block(-5,20,-7,136:2)
Block(-5,20,-3,136:3)
Block(-5,21,-6,136:2)
Block(-5,21,-5,136)
Block(-5,21,-4,136)
Block(-4,0,-7,98)
Block(-4,0,-6,98)
Block(-4,0,-5,98)
Block(-4,0,-4,98)
Block(-4,0,-3,98)
Block(-4,0,-2,98)
Block(-4,0,-1,98)
Block(-4,0,0,98)
Block(-4,1,-7,98)
Block(-4,1,-6,98)
Block(-4,1,-5,98)
Block(-4,1,-4,98)
Block(-4,1,-3,98)
Block(-4,1,-2,98)
Block(-4,1,-1,98)
Block(-4,1,0,98)
Block(-4,2,-7,98)
Block(-4,2,-6,98)
Block(-4,2,-5,98)
Block(-4,2,-4,98)
Block(-4,2,-3,98)
Block(-4,2,-2,98)
Block(-4,2,-1,98)
Block(-4,2,0,98)
Block(-4,3,-7,98)
Block(-4,3,-6,98)
Block(-4,3,-5,98)
Block(-4,3,-4,98)
Block(-4,3,-3,98)
Block(-4,3,-2,98)
Block(-4,3,-1,98)
Block(-4,3,0,98)
Block(-4,4,-7,98)
Block(-4,4,-6,98)
Block(-4,4,-5,98)
Block(-4,4,-4,98)
Block(-4,4,-3,98)
Block(-4,4,-2,98)
Block(-4,4,-1,98)
Block(-4,4,0,98)
Block(-4,5,-7,98)
Block(-4,5,-6,98)
Block(-4,5,-5,98)
Block(-4,5,-4,98)
Block(-4,5,-3,35:14)
Block(-4,5,-2,98)
Block(-4,5,-1,98)
Block(-4,5,0,98)
Block(-4,6,-7,98)
Block(-4,6,-6,98)
Block(-4,6,-5,98)
Block(-4,6,-4,98)
Block(-4,6,-3,98)
Block(-4,6,-2,98)
Block(-4,6,-1,98)
Block(-4,6,0,98)
Block(-4,7,-7,98)
Block(-4,7,-6,98)
Block(-4,7,-5,98)
Block(-4,7,-4,98)
Block(-4,7,-3,98)
Block(-4,7,-2,98)
Block(-4,7,-1,98)
Block(-4,7,0,98)
Block(-4,8,-7,98)
Block(-4,8,-6,98)
Block(-4,8,-5,98)
Block(-4,8,-4,98)
Block(-4,8,-3,98)
Block(-4,8,-2,98)
Block(-4,8,-1,98)
Block(-4,8,0,98)
Block(-4,9,-7,98)
Block(-4,9,-6,98)
Block(-4,9,0,35:14)
Block(-4,10,-7,98)
Block(-4,10,-6,98)
Block(-4,11,-7,98)
Block(-4,11,-6,98)
Block(-4,11,-3,98)
Block(-4,12,-7,98)
Block(-4,12,-6,98)
Block(-4,12,-3,98)
Block(-4,13,-7,98)
Block(-4,13,-6,98)
Block(-4,13,-3,98)
Block(-4,14,-7,98)
Block(-4,14,-6,98)
Block(-4,14,-3,98)
Block(-4,15,-7,98)
Block(-4,15,-6,98)
Block(-4,15,-3,98)
Block(-4,16,-7,98)
Block(-4,16,-6,98)
Block(-4,16,-5,98)
Block(-4,16,-4,98)
Block(-4,16,-3,98)
Block(-4,16,-2,109:7)
Block(-4,17,-2,98)
Block(-4,19,-2,136:3)
Block(-4,20,-7,136:2)
Block(-4,20,-3,136:3)
Block(-4,21,-6,136:2)
Block(-4,21,-4,136:3)
Block(-4,22,-5,126:3)
Block(-3,0,-7,98)
Block(-3,0,-6,98)
Block(-3,0,-5,98)
Block(-3,0,-4,98)
Block(-3,0,-3,98)
Block(-3,0,-2,98)
Block(-3,0,-1,98)
Block(-3,0,0,98)
Block(-3,1,-7,98)
Block(-3,1,-6,98)
Block(-3,1,-5,98)
Block(-3,1,-4,98)
Block(-3,1,-3,98)
Block(-3,1,-2,98)
Block(-3,1,-1,98)
Block(-3,1,0,98)
Block(-3,2,-7,98)
Block(-3,2,-6,98)
Block(-3,2,-5,98)
Block(-3,2,-4,98)
Block(-3,2,-3,98)
Block(-3,2,-2,98)
Block(-3,2,-1,98)
Block(-3,2,0,98)
Block(-3,3,-7,98)
Block(-3,3,-6,98)
Block(-3,3,-5,98)
Block(-3,3,-4,98)
Block(-3,3,-3,98)
Block(-3,3,-2,98)
Block(-3,3,-1,98)
Block(-3,3,0,98)
Block(-3,4,-7,98)
Block(-3,4,-6,98)
Block(-3,4,-5,98)
Block(-3,4,-4,98)
Block(-3,4,-3,98)
Block(-3,4,-2,98)
Block(-3,4,-1,98)
Block(-3,4,0,98)
Block(-3,5,-7,98)
Block(-3,5,-6,98)
Block(-3,5,-5,98)
Block(-3,5,-4,98)
Block(-3,5,-3,35:14)
Block(-3,5,-2,98)
Block(-3,5,-1,98)
Block(-3,5,0,98)
Block(-3,6,-7,98)
Block(-3,6,-6,98)
Block(-3,6,-5,98)
Block(-3,6,-4,98)
Block(-3,6,-3,98)
Block(-3,6,-2,98)
Block(-3,6,-1,98)
Block(-3,6,0,98)
Block(-3,7,-7,98)
Block(-3,7,-6,98)
Block(-3,7,-5,98)
Block(-3,7,-4,98)
Block(-3,7,-3,98)
Block(-3,7,-2,98)
Block(-3,7,-1,98)
Block(-3,7,0,98)
Block(-3,8,-7,98)
Block(-3,8,-6,98)
Block(-3,8,-5,98)
Block(-3,8,-4,98)
Block(-3,8,-3,98)
Block(-3,8,-2,109:1)
Block(-3,8,-1,109:1)
Block(-3,8,0,98)
Block(-3,9,-7,98)
Block(-3,9,-6,98)
Block(-3,9,-5,65:3)
Block(-3,9,-3,35:14)
Block(-3,9,0,35:14)
Block(-3,10,-7,98)
Block(-3,10,-6,98)
Block(-3,10,-5,65:3)
Block(-3,10,-3,98)
Block(-3,11,-7,98)
Block(-3,11,-6,98)
Block(-3,11,-5,65:3)
Block(-3,11,-3,98)
Block(-3,12,-7,98)
Block(-3,12,-6,98)
Block(-3,12,-5,65:3)
Block(-3,12,-3,98)
Block(-3,13,-7,98)
Block(-3,13,-6,98)
Block(-3,13,-5,65:3)
Block(-3,13,-3,98)
Block(-3,14,-7,98)
Block(-3,14,-6,98)
Block(-3,14,-5,65:3)
Block(-3,14,-3,98)
Block(-3,15,-7,98)
Block(-3,15,-6,98)
Block(-3,15,-5,65:3)
Block(-3,15,-3,98)
Block(-3,16,-7,98)
Block(-3,16,-6,98)
Block(-3,16,-5,65:3)
Block(-3,16,-4,98)
Block(-3,16,-3,98)
Block(-3,16,-2,109:7)
Block(-3,17,-2,98)
Block(-3,18,-2,139)
Block(-3,19,-2,136:3)
Block(-3,20,-7,136:2)
Block(-3,20,-3,136:3)
Block(-3,21,-6,136:2)
Block(-3,21,-5,89)
Block(-3,21,-4,136:3)
Block(-3,22,-5,126:3)
Block(-2,0,-7,98)
Block(-2,0,-6,98)
Block(-2,0,-5,98)
Block(-2,0,-4,98)
Block(-2,0,-3,98)
Block(-2,0,-2,98)
Block(-2,0,-1,98)
Block(-2,0,0,98)
Block(-2,1,-7,98)
Block(-2,1,-6,98)
Block(-2,1,-5,98)
Block(-2,1,-4,98)
Block(-2,1,-3,98)
Block(-2,1,-2,98)
Block(-2,1,-1,98)
Block(-2,1,0,98)
Block(-2,2,-7,98)
Block(-2,2,-6,98)
Block(-2,2,-5,98)
Block(-2,2,-4,98)
Block(-2,2,-3,98)
Block(-2,2,-2,98)
Block(-2,2,-1,98)
Block(-2,2,0,98)
Block(-2,3,-7,98)
Block(-2,3,-6,98)
Block(-2,3,-5,98)
Block(-2,3,-4,98)
Block(-2,3,-3,98)
Block(-2,3,-2,98)
Block(-2,3,-1,98)
Block(-2,3,0,98)
Block(-2,4,-7,98)
Block(-2,4,-6,98)
Block(-2,4,-5,98)
Block(-2,4,-4,98)
Block(-2,4,-3,98)
Block(-2,4,-2,98)
Block(-2,4,-1,98)
Block(-2,4,0,98)
Block(-2,5,-7,98)
Block(-2,5,-6,98)
Block(-2,5,-5,98)
Block(-2,5,-4,98)
Block(-2,5,-3,35:14)
Block(-2,5,-2,98)
Block(-2,5,-1,98)
Block(-2,5,0,98)
Block(-2,6,-7,98)
Block(-2,6,-6,98)
Block(-2,6,-5,98)
Block(-2,6,-4,98)
Block(-2,6,-3,98)
Block(-2,6,-2,98)
Block(-2,6,-1,98)
Block(-2,6,0,98)
Block(-2,7,-7,98)
Block(-2,7,-6,98)
Block(-2,7,-5,98)
Block(-2,7,-4,98)
Block(-2,7,-3,98)
Block(-2,7,-2,109:1)
Block(-2,7,-1,109:1)
Block(-2,7,0,98)
Block(-2,8,-7,98)
Block(-2,8,-6,98)
Block(-2,8,-5,98)
Block(-2,8,-4,98)
Block(-2,8,-3,98)
Block(-2,8,0,35:14)
Block(-2,9,-7,98)
Block(-2,9,-6,98)
Block(-2,9,-3,35:14)
Block(-2,10,-7,98)
Block(-2,10,-6,98)
Block(-2,10,-3,98)
Block(-2,11,-7,98)
Block(-2,11,-6,98)
Block(-2,11,-3,98)
Block(-2,12,-7,98)
Block(-2,12,-6,98)
Block(-2,12,-3,98)
Block(-2,13,-7,98)
Block(-2,13,-6,98)
Block(-2,13,-3,98)
Block(-2,14,-7,98)
Block(-2,14,-6,98)
Block(-2,14,-3,98)
Block(-2,15,-7,98)
Block(-2,15,-6,98)
Block(-2,15,-4,89)
Block(-2,15,-3,98)
Block(-2,16,-7,98)
Block(-2,16,-6,98)
Block(-2,16,-5,98)
Block(-2,16,-4,98)
Block(-2,16,-3,98)
Block(-2,16,-2,109:7)
Block(-2,17,-2,98)
Block(-2,19,-2,136:3)
Block(-2,20,-7,136:2)
Block(-2,20,-3,136:3)
Block(-2,21,-6,136:2)
Block(-2,21,-4,136:3)
Block(-2,22,-5,126:3)
Block(-1,0,-7,98)
Block(-1,0,-6,98)
Block(-1,0,-5,98)
Block(-1,0,-4,98)
Block(-1,0,-3,98)
Block(-1,0,-2,98)
Block(-1,0,-1,98)
Block(-1,0,0,98)
Block(-1,1,-7,98)
Block(-1,1,-6,98)
Block(-1,1,-5,98)
Block(-1,1,-4,98)
Block(-1,1,-3,98)
Block(-1,1,-2,98)
Block(-1,1,-1,98)
Block(-1,1,0,98)
Block(-1,2,-7,98)
Block(-1,2,-6,98)
Block(-1,2,-5,98)
Block(-1,2,-4,98)
Block(-1,2,-3,98)
Block(-1,2,-2,98)
Block(-1,2,-1,98)
Block(-1,2,0,98)
Block(-1,3,-7,98)
Block(-1,3,-6,98)
Block(-1,3,-5,98)
Block(-1,3,-4,98)
Block(-1,3,-3,98)
Block(-1,3,-2,98)
Block(-1,3,-1,98)
Block(-1,3,0,98)
Block(-1,4,-7,98)
Block(-1,4,-6,98)
Block(-1,4,-5,98)
Block(-1,4,-4,98)
Block(-1,4,-3,98)
Block(-1,4,-2,98)
Block(-1,4,-1,98)
Block(-1,4,0,98)
Block(-1,5,-7,98)
Block(-1,5,-6,98)
Block(-1,5,-5,98)
Block(-1,5,-4,98)
Block(-1,5,-3,35:14)
Block(-1,5,-2,98)
Block(-1,5,-1,98)
Block(-1,5,0,98)
Block(-1,6,-7,98)
Block(-1,6,-6,98)
Block(-1,6,-5,98)
Block(-1,6,-4,98)
Block(-1,6,-3,98)
Block(-1,6,-2,109:1)
Block(-1,6,-1,109:1)
Block(-1,6,0,98)
Block(-1,7,-7,98)
Block(-1,7,-6,98)
Block(-1,7,-5,98)
Block(-1,7,-4,98)
Block(-1,7,-3,98)
Block(-1,7,0,35:14)
Block(-1,8,-7,98)
Block(-1,8,-6,98)
Block(-1,8,-5,98)
Block(-1,8,-4,98)
Block(-1,8,-3,98)
Block(-1,9,-7,98)
Block(-1,9,-6,98)
Block(-1,9,-5,98)
Block(-1,9,-4,98)
Block(-1,9,-3,35:14)
Block(-1,10,-7,98)
Block(-1,10,-6,98)
Block(-1,10,-5,98)
Block(-1,10,-4,98)
Block(-1,10,-3,98)
Block(-1,11,-7,98)
Block(-1,11,-6,98)
Block(-1,11,-5,98)
Block(-1,11,-4,98)
Block(-1,11,-3,98)
Block(-1,12,-7,98)
Block(-1,12,-6,98)
Block(-1,12,-5,98)
Block(-1,12,-4,98)
Block(-1,12,-3,98)
Block(-1,13,-7,98)
Block(-1,13,-6,98)
Block(-1,13,-5,98)
Block(-1,13,-4,98)
Block(-1,13,-3,98)
Block(-1,14,-7,98)
Block(-1,14,-6,98)
Block(-1,14,-5,98)
Block(-1,14,-4,98)
Block(-1,14,-3,98)
Block(-1,15,-7,98)
Block(-1,15,-6,98)
Block(-1,15,-5,98)
Block(-1,15,-4,98)
Block(-1,15,-3,98)
Block(-1,16,-7,98)
Block(-1,16,-6,98)
Block(-1,16,-5,98)
Block(-1,16,-4,98)
Block(-1,16,-3,98)
Block(-1,16,-2,109:7)
Block(-1,17,-2,98)
Block(-1,19,-2,136:3)
Block(-1,20,-7,136:2)
Block(-1,20,-3,136:3)
Block(-1,21,-6,136:1)
Block(-1,21,-5,136:1)
Block(-1,21,-4,136:1)
Block(0,0,-7,98)
Block(0,0,-6,98)
Block(0,0,-5,98)
Block(0,0,-4,98)
Block(0,0,-3,98)
Block(0,0,-2,98)
Block(0,0,-1,98)
Block(0,0,0,98)
Block(0,1,-7,98)
Block(0,1,-6,98)
Block(0,1,-5,98)
Block(0,1,-4,98)
Block(0,1,-3,98)
Block(0,1,-2,98)
Block(0,1,-1,98)
Block(0,1,0,98)
Block(0,2,-7,98)
Block(0,2,-6,98)
Block(0,2,-5,98)
Block(0,2,-4,98)
Block(0,2,-3,98)
Block(0,2,-2,98)
Block(0,2,-1,98)
Block(0,2,0,98)
Block(0,3,-7,98)
Block(0,3,-6,98)
Block(0,3,-5,98)
Block(0,3,-4,98)
Block(0,3,-3,98)
Block(0,3,-2,98)
Block(0,3,-1,98)
Block(0,3,0,98)
Block(0,4,-7,98)
Block(0,4,-6,98)
Block(0,4,-5,98)
Block(0,4,-4,98)
Block(0,4,-3,98)
Block(0,4,-2,98)
Block(0,4,-1,98)
Block(0,4,0,98)
Block(0,5,-7,35:14)
Block(0,5,-6,35:14)
Block(0,5,-5,35:14)
Block(0,5,-4,35:14)
Block(0,5,-3,35:14)
Block(0,5,-2,109:1)
Block(0,5,-1,109:1)
Block(0,5,0,98)
Block(0,6,-7,98)
Block(0,6,-6,98)
Block(0,6,-5,98)
Block(0,6,-4,98)
Block(0,6,-3,98)
Block(0,6,0,35:14)
Block(0,7,-7,98)
Block(0,7,-6,98)
Block(0,7,-5,98)
Block(0,7,-4,98)
Block(0,7,-3,98)
Block(0,8,-7,98)
Block(0,8,-6,98)
Block(0,8,-5,98)
Block(0,8,-4,98)
Block(0,8,-3,98)
Block(0,9,-7,35:14)
Block(0,9,-6,35:14)
Block(0,9,-5,35:14)
Block(0,9,-4,35:14)
Block(0,9,-3,35:14)
Block(0,10,-7,98)
Block(0,10,-6,98)
Block(0,10,-5,98)
Block(0,10,-4,98)
Block(0,10,-3,98)
Block(0,11,-7,98)
Block(0,11,-6,98)
Block(0,11,-5,98)
Block(0,11,-4,98)
Block(0,11,-3,98)
Block(0,12,-7,98)
Block(0,12,-6,98)
Block(0,12,-5,98)
Block(0,12,-4,98)
Block(0,12,-3,98)
Block(0,13,-7,98)
Block(0,13,-6,98)
Block(0,13,-5,98)
Block(0,13,-4,98)
Block(0,13,-3,98)
Block(0,14,-7,98)
Block(0,14,-6,98)
Block(0,14,-5,98)
Block(0,14,-4,98)
Block(0,14,-3,98)
Block(0,15,-7,98)
Block(0,15,-6,98)
Block(0,15,-5,98)
Block(0,15,-4,98)
Block(0,15,-3,98)
Block(0,16,-7,98)
Block(0,16,-6,98)
Block(0,16,-5,98)
Block(0,16,-4,98)
Block(0,16,-3,98)
Block(0,16,-2,109:7)
Block(0,17,-2,98)
Block(0,19,-2,136:3)
Block(0,20,-7,136:1)
Block(0,20,-6,136:1)
Block(0,20,-5,136:1)
Block(0,20,-4,136:1)
Block(0,20,-3,136:3)
Block(1,0,-7,109:2)
Block(1,0,-6,109:6)
Block(1,0,-5,98)
Block(1,0,-4,98)
Block(1,0,-3,98)
Block(1,0,-2,98)
Block(1,0,-1,98)
Block(1,0,0,98)
Block(1,1,-6,109:2)
Block(1,1,-5,98)
Block(1,1,-4,98)
Block(1,1,-3,98)
Block(1,1,-2,98)
Block(1,1,-1,98)
Block(1,1,0,98)
Block(1,2,-5,109:2)
Block(1,2,-4,98)
Block(1,2,-3,98)
Block(1,2,-2,98)
Block(1,2,-1,98)
Block(1,2,0,98)
Block(1,3,-4,109:2)
Block(1,3,-3,98)
Block(1,3,-2,98)
Block(1,3,-1,98)
Block(1,3,0,98)
Block(1,4,-3,109:2)
Block(1,4,-2,98)
Block(1,4,-1,98)
Block(1,4,0,98)
Block(1,5,0,35:14)
Block(1,16,-7,109:5)
Block(1,16,-6,109:5)
Block(1,16,-5,109:5)
Block(1,16,-4,109:5)
Block(1,16,-3,109:5)
Block(1,16,-2,109:5)
Block(1,17,-7,98)
Block(1,17,-6,98)
Block(1,17,-5,98)
Block(1,17,-4,98)
Block(1,17,-3,98)
Block(1,17,-2,98)
Block(1,18,-5,139)
Block(1,18,-2,139)
Block(1,19,-7,136:1)
Block(1,19,-6,136:1)
Block(1,19,-5,136:1)
Block(1,19,-4,136:1)
Block(1,19,-3,136:1)
Block(1,19,-2,136:3)
Block(2,0,-7,109:2)
Block(2,0,-6,98)
Block(2,0,-5,98)
Block(2,0,-4,98)
Block(2,0,-3,98)
Block(2,0,-2,98)
Block(2,0,-1,98)
Block(2,0,0,98)
Block(2,1,-6,109:2)
Block(2,1,-5,98)
Block(2,1,-4,98)
Block(2,1,-3,98)
Block(2,1,-2,98)
Block(2,1,-1,98)
Block(2,1,0,98)
Block(2,2,-5,109:2)
Block(2,2,-4,98)
Block(2,2,-3,98)
Block(2,2,-2,98)
Block(2,2,-1,98)
Block(2,2,0,98)
Block(2,3,-4,109:2)
Block(2,3,-3,98)
Block(2,3,-2,98)
Block(2,3,-1,98)
Block(2,3,0,98)
Block(2,4,-3,109:2)
Block(2,4,-2,98)
Block(2,4,-1,98)
Block(2,4,0,98)
Block(2,5,0,35:14)
Block(3,0,-6,98)
Block(3,0,-5,98)
Block(3,0,-4,98)
Block(3,0,-3,98)
Block(3,0,-2,98)
Block(3,0,-1,98)
Block(3,0,0,98)
Block(3,1,-6,98)
Block(3,1,-5,98)
Block(3,1,-4,98)
Block(3,1,-3,98)
Block(3,1,-2,98)
Block(3,1,-1,98)
Block(3,1,0,98)
Block(3,2,-6,35:14)
Block(3,2,-5,98)
Block(3,2,-4,98)
Block(3,2,-3,98)
Block(3,2,-2,98)
Block(3,2,-1,98)
Block(3,2,0,98)
Block(3,3,-5,35:14)
Block(3,3,-4,98)
Block(3,3,-3,98)
Block(3,3,-2,98)
Block(3,3,-1,98)
Block(3,3,0,98)
Block(3,4,-4,35:14)
Block(3,4,-3,98)
Block(3,4,-2,98)
Block(3,4,-1,98)
Block(3,4,0,98)
Block(3,5,-3,35:14)
Block(3,5,-2,35:14)
Block(3,5,-1,35:14)
Block(3,5,0,35:14)
Block(4,0,-2,98)
Block(4,0,-1,98)
Block(4,1,-2,98)
Block(4,1,-1,98)
Block(4,2,-3,136:2)
Block(4,2,-2,98)
Block(4,2,-1,98)
Block(4,2,0,136:3)
Block(4,3,-2,136:2)
Block(4,3,-1,136:3)
Block(5,0,-4,109:4)
Block(5,0,-2,98)
Block(5,0,-1,98)
Block(5,1,-4,125:3)
Block(5,1,-2,98)
Block(5,1,-1,98)
Block(5,2,-4,109)
Block(5,2,-3,136:2)
Block(5,2,-2,98)
Block(5,2,-1,98)
Block(5,2,0,136:3)
Block(5,3,-2,136:2)
Block(5,3,-1,136:3)
Block(6,0,-4,125:3)
Block(6,0,-2,98)
Block(6,0,-1,98)
Block(6,1,-4,35:14)
Block(6,1,-2,98)
Block(6,1,-1,98)
Block(6,2,-4,125:3)
Block(6,2,-3,136:2)
Block(6,2,-2,98)
Block(6,2,-1,98)
Block(6,2,0,136:3)
Block(6,3,-2,136:2)
Block(6,3,-1,136:3)
Block(7,0,-4,109:5)
Block(7,0,-2,98)
Block(7,0,-1,98)
Block(7,1,-4,125:3)
Block(7,1,-2,98)
Block(7,1,-1,98)
Block(7,2,-4,109:1)
Block(7,2,-3,136:2)
Block(7,2,-2,98)
Block(7,2,-1,98)
Block(7,2,0,136:3)
Block(7,3,-2,136:2)
Block(7,3,-1,136:3)

Branch(16,0,0,true,archery-range-ageC1R1,NORTH,100,0)
