

BranchFrequencyGroup: CanOverride:0

CanOverride: true

SmoothRadius: -1

OverrideChildSettings: false

ReplaceAbove:
ReplaceBelow:

MustBeInside: VillageGeneratorStructurePlaceHolder, VillageGeneratorStructuresDelay, VillageGeneratorStructuresDelay2, VillageGeneratorStructuresDelay3, VillageGeneratorStructuresDelay4, VillageGeneratorStructuresDelay5, VillageGeneratorStructuresDelay6, VillageGeneratorStructuresDelay7, VillageGeneratorStructuresDelay8, VillageGeneratorStructuresDelay9, VillageGeneratorStructuresDelay10

Block(-8,0,-2,98)
Block(-8,0,-1,98)
Block(-8,1,-2,98)
Block(-8,1,-1,98)
Block(-8,2,-3,136:2)
Block(-8,2,-2,98)
Block(-8,2,-1,98)
Block(-8,2,0,136:3)
Block(-8,3,-2,136:2)
Block(-8,3,-1,136:3)
Block(-7,0,-4,109:4)
Block(-7,0,-2,98)
Block(-7,0,-1,98)
Block(-7,1,-4,125:3)
Block(-7,1,-2,98)
Block(-7,1,-1,98)
Block(-7,2,-4,109)
Block(-7,2,-3,136:2)
Block(-7,2,-2,98)
Block(-7,2,-1,98)
Block(-7,2,0,136:3)
Block(-7,3,-2,136:2)
Block(-7,3,-1,136:3)
Block(-6,0,-4,125:3)
Block(-6,0,-2,98)
Block(-6,0,-1,98)
Block(-6,1,-4,35:14)
Block(-6,1,-2,98)
Block(-6,1,-1,98)
Block(-6,2,-4,125:3)
Block(-6,2,-3,136:2)
Block(-6,2,-2,98)
Block(-6,2,-1,98)
Block(-6,2,0,136:3)
Block(-6,3,-2,136:2)
Block(-6,3,-1,136:3)
Block(-5,0,-4,109:5)
Block(-5,0,-2,98)
Block(-5,0,-1,98)
Block(-5,1,-4,125:3)
Block(-5,1,-2,98)
Block(-5,1,-1,98)
Block(-5,2,-4,109:1)
Block(-5,2,-3,136:2)
Block(-5,2,-2,98)
Block(-5,2,-1,98)
Block(-5,2,0,136:3)
Block(-5,3,-2,136:2)
Block(-5,3,-1,136:3)
Block(-4,0,-2,98)
Block(-4,0,-1,98)
Block(-4,1,-2,98)
Block(-4,1,-1,98)
Block(-4,2,-3,136:2)
Block(-4,2,-2,98)
Block(-4,2,-1,98)
Block(-4,2,0,136:3)
Block(-4,3,-2,136:2)
Block(-4,3,-1,136:3)
Block(-3,0,-2,98)
Block(-3,0,-1,98)
Block(-3,1,-2,98)
Block(-3,1,-1,98)
Block(-3,2,-3,136:2)
Block(-3,2,-2,98)
Block(-3,2,-1,98)
Block(-3,2,0,136:3)
Block(-3,3,-2,136:2)
Block(-3,3,-1,136:3)
