#######################################################################
# +-----------------------------------------------------------------+ #
# |                            BO3 object                           | #
# +-----------------------------------------------------------------+ #
#######################################################################

# This BO3 is made for use with MCW and OTG+.
# The descriptions in this file are only accurate for MCW and OTG+.
# For TerrainControl and OTG these descriptions are only accurate if the BO3 is used as a CustomObject.
# MCW and OTG+ completely reimplemented CustomStructure, check the MCW/OTG+ documentation for more information.

# This is the config file of a custom object.
# If you add this object correctly to your BiomeConfigs, it will spawn in the world.

# This is the creator of this BO3 object
Author: Unknown

# A short description of this BO3 object
Description: No description

# The BO3 version, don't change this! It can be used by external applications to do a version check.
Version: 4

# The settings mode, WriteAll, WriteWithoutComments or WriteDisable. See WorldConfig.
SettingsMode: WriteDisable

#######################################################################
# +-----------------------------------------------------------------+ #
# |                          Main settings                          | #
# +-----------------------------------------------------------------+ #
#######################################################################

IsOTGPlus: true
# This settings is currently unavailable for MCW/OTG+.
Tree: false

# The rarity of the BO3 from 0 to 100. Each spawn attempt has rarity% chance to succeed when using the CustomObject(...) resource.
# Ignored by MCW/OTG+ for Tree(..), Sapling(..) and CustomStructure(..).
Rarity: 100

# Minimum distance in chunks between structures with the same filename.
Frequency: 0

# This settings is currently unavailable for MCW/OTG+, you can easily work around this though by creating a master bo3 without blocks that
# has the real starting BO3 as a branch.
# You can then duplicate the master BO3 3 times and give each copy's branch a different rotation.
RotateRandomly: false

# The spawn height of the BO3 - randomY or highestBlock.
SpawnHeight: highestBlock

# The height limits for the BO3. Can be combined with randomY to spawn the BO3 at a random height
# between MinHeight and MaxHeight. Can be combined with highestBlock to make sure that the BO3 spawns
# only between MinHeight and MaxHeight.
MinHeight: 0

MaxHeight: 256

# This settings is disabled for MCW/OTG+.
ExcludedBiomes: All

# To optimise this BO3 for faster loading times you can use Notepad++ to find/replace comments and abbreviate things.
# Notepad++ find/replace with regex:
# Find: ^[#;].* replace to nothing removes all lines starting with # 
# Find: ^\s*$ replace to nothing removes most empty lines 
# Notepad++ find/replace without regex:
# *Warning: This will only work for OTG 1.10.2 v21 / OTG 1.11.2 v6 or higher. B( is not recognised by lower versions.
# Find: Block( replace to B(

#######################################################################
# +-----------------------------------------------------------------+ #
# |                      Source block settings                      | #
# +-----------------------------------------------------------------+ #
#######################################################################

# This settings is disabled for MCW/OTG+.
SourceBlocks: AIR

# This settings is disabled for MCW/OTG+.
MaxPercentageOutsideSourceBlock: 100

# This settings is disabled for MCW/OTG+.
OutsideSourceBlock: placeAnyway

# MineCraft Worlds mod settings #
# NOTE: you can delete any of these settings if you're not using them, the default values will automatically be used. #

# Copies the blocks and branches of an existing BO3 into this BO3.
#InheritBO3:

# Defaults to true, if true and this is the root BO3 for this branching structure then this BO3's smoothing and height settings are used for all its children (branches).
#OverrideChildSettings: true

# If this is set to true then this BO3 can spawn as a branch on top of or inside an existing BO3/branch (only within the same customstructure).
#CanOverride: false

# If this is set to true then this BO3 can only spawn underneath an existing BO3. Used to make sure that dungeons only appear underneath buildings
#MustBeBelowOther: false

# A comma-seperated list of BO3s, this BO3 must touch one of these when spawned or it will not be able to spawn.
#MustBeInside: 

# A comma-seperated list of BO3s, this BO3 cannot touch one of these when spawned, if it does it will not be able to spawn.
#CannotBeInside: 

# Defaults to true. Set to false if the BO3 is not allowed to spawn on a water block
#CanSpawnOnWater: true

# Defaults to false. Set to true if the BO3 is allowed to spawn only on a water block
#SpawnOnWaterOnly: false

# Defaults to false. Set to true if the BO3 and its smoothing area should ignore water when looking for the highest block to spawn on. Defaults to false (things spawn on top of water)
#SpawnUnderWater: false

# Defaults to false. Set to true if the BO3 should spawn at water level
#SpawnAtWaterLevel: false


# Spawns the BO3 at a Y offset of this value. Handy when using highestBlock for lowering BO3s into the surrounding terrain when there are layers of ground included in the BO3, also handy when using SpawnAtWaterLevel to lower objects like ships into the water.
#HeightOffset: 0

# If set to true removes all AIR blocks from the BO3 so that it can be flooded or buried.
#RemoveAir: true

# Replaces all the non-air blocks that are above this BO3 or its smoothing area with the given block material (should be WATER or AIR or NONE), also applies to smoothing areas although it intentionally leaves some of the terrain above them intact. WATER can be used in combination with SpawnUnderWater to fill any air blocks underneath waterlevel with water (and any above waterlevel with air).
#ReplaceAbove: AIR

# Replaces all air blocks underneath the BO3 (but not its smoothing area) with the designated material until a solid block is found.
#ReplaceBelow:

# Defaults to true. If set to true then every block in the BO3 of the materials defined in ReplaceWithGroundBlock or ReplaceWithSurfaceBlock will be replaced by the GroundBlock or SurfaceBlock materials configured for the biome the block is spawned in.
#ReplaceWithBiomeBlocks: true

# Defaults to DIRT, Replaces all the blocks of the given material in the BO3 with the GroundBlock configured for the biome it spawns in
#ReplaceWithGroundBlock: DIRT

# Defaults to GRASS, Replaces all the blocks of the given material in the BO3 with the SurfaceBlock configured for the biome it spawns in
#ReplaceWithSurfaceBlock: GRASS


# Makes the terrain around the BO3 slope gradually towards the edges of the BO3. The given value is the distance in blocks around the BO3 from where the slope should start and can be any positive number.
#SmoothRadius: 0

# Moves the smoothing area up or down relative to the BO3 (at the points where the smoothing area is connected to the BO3). Handy when using SmoothStartTop: false and the BO3 has some layers of ground included, in that case we can set the HeightOffset to a negative value to lower the BO3 into the ground and we can set the SmoothHeightOffset to a positive value to move the smoothing area starting height up
#SmoothHeightOffset: 0

# Should the smoothing area be attached at the bottom or the top of the edges of the BO3? Defaults to false (bottom). Using this setting can make things slower so try to avoid using it and use SmoothHeightOffset instead if for instance you have a BO3 with some ground layers included. The only reason you should need to use this setting is if you have a BO3 with edges that have an irregular height (like some hills).
#SmoothStartTop: false

# Should the smoothing area attach itself to "log" block or ignore them? Defaults to false (ignore logs).
#SmoothStartWood: false

# The block used for smoothing area surface blocks, defaults to biome SurfaceBlock
#SmoothingSurfaceBlock:

# The block used for smoothing area ground blocks, defaults to biome GroundBlock
#SmoothingGroundBlock:


# Define groups that this BO3 belongs to along with a minimum range in chunks that this BO3 must have between it and any other members of this group if it is to be allowed to spawn. Syntax is "GroupName:Frequency, GoupName2:Frequency2" etc so for example a BO3 that belongs to 3 groups: "BO3Group: Ships:10, Vehicles:5, FloatingThings:3"
#BO3Group:

# Defaults to false. Set to true if this BO3 should spawn at the player spawn point. When the server starts the spawn point is determined and the BO3's for the biome it is in are loaded, one of these BO3s that has IsSpawnPoint set to true (if any) is selected randomly and is spawned at the spawn point regardless of its rarity (so even Rarity:0, IsSpawnPoint: true BO3's can get spawned as the spawn point!).
#IsSpawnPoint: false

# Defaults to 8, if SpawnPointY > -1 and this BO3 is spawned at the spawn point then the player spawn point is placed within this BO3 at x y and z offsets (spawnPointX, spawnPointY, spawnPointZ) relative to x0y0z0 in this BO3.
#SpawnPointX: 8

# Defaults to highestBlock, if this is defined and this BO3 is spawned at the spawn point then the player spawn point is placed at a y offset of this value relative to y = 0 in this BO3.)
#SpawnPointY: -1

# Defaults to 7, if spawnPointY > -1 and this BO3 is spawned at the spawn point then the player spawn point is placed within this BO3 at a x y and z offsets (spawnPointX, spawnPointY, spawnPointZ) relative to x0y0z0 in this BO3.
#SpawnPointZ: 7

#######################################################################
# +-----------------------------------------------------------------+ #
# |                              Blocks                             | #
# +-----------------------------------------------------------------+ #
#######################################################################

# All the blocks used in the BO3 are listed here. Possible blocks:
# Block(x,y,z,id[.data][,nbtfile.nbt) or B(x,y,z,id[.data][,nbtfile.nbt)
# RandomBlock(x,y,z,id[:data][,nbtfile.nbt],chance[,id[:data][,nbtfile.nbt],chance[,...]])
# So RandomBlock(0,0,0,CHEST,chest.nbt,50,CHEST,anotherchest.nbt,100) will spawn a chest at
# the BO3 origin, and give it a 50% chance to have the contents of chest.nbt, or, if that
# fails, a 100% percent chance to have the contents of anotherchest.nbt.

Block(-1,0,-3,159:15)
Block(-1,0,-2,251:15)
Block(-1,0,-1,251:7)
Block(-1,1,-3,159:15)
Block(-1,1,-2,159:15)
Block(-1,1,-1,251:7)
Block(-1,2,-3,251:15)
Block(-1,2,-2,251:7)
Block(-1,2,-1,251:7)
Block(-1,3,-3,251:15)
Block(-1,3,-2,251:7)
Block(-1,3,-1,251:7)
Block(-1,4,-3,251:15)
Block(-1,4,-2,251:7)
Block(-1,4,-1,251:7)
Block(-1,5,-3,159:15)
Block(-1,5,-2,251:7)
Block(-1,5,-1,251:7)
Block(-1,6,-3,159:15)
Block(-1,6,-2,251:7)
Block(-1,6,-1,251:7)
Block(-1,7,-3,159:15)
Block(-1,7,-2,251:7)
Block(-1,7,-1,251:7)
Block(-1,8,-3,251:15)
Block(-1,8,-2,251:7)
Block(-1,8,-1,251:7)
Block(-1,9,-3,251:15)
Block(-1,9,-2,251:7)
Block(-1,9,-1,251:7)
Block(-1,10,-3,251:15)
Block(-1,10,-2,251:7)
Block(-1,10,-1,251:7)
Block(-1,11,-3,251:7)
Block(-1,11,-2,251:7)
Block(-1,11,-1,251:7)
Block(-1,12,-3,251:7)
Block(-1,12,-2,251:7)
Block(-1,12,-1,251:7)
Block(-1,13,-3,251:7)
Block(-1,13,-2,251:7)
Block(-1,13,-1,251:15)
Block(-1,14,-3,251:7)
Block(-1,14,-2,159:15)
Block(-1,14,-1,159:15)
Block(-1,15,-3,251:15)
Block(-1,15,-2,251:15)
Block(-1,15,-1,159:15)
Block(-1,16,-3,159:15)
Block(-1,16,-2,159:15)
Block(-1,16,-1,251:15)
Block(-1,17,-3,251:15)
Block(-1,17,-2,159:15)
Block(-1,17,-1,159:15)
Block(-1,18,-3,251:15)
Block(-1,18,-2,251:15)
Block(-1,18,-1,159:15)
Block(0,0,-5,251:7)
Block(0,0,-4,251:15)
Block(0,0,-3,159:15)
Block(0,0,-2,251:15)
Block(0,0,-1,159:15)
Block(0,0,0,251:7)
Block(0,0,1,251:15)
Block(0,1,-5,251:7)
Block(0,1,-4,159:15)
Block(0,1,-3,251:15)
Block(0,1,-2,251:15)
Block(0,1,-1,159:15)
Block(0,1,0,251:7)
Block(0,1,1,251:15)
Block(0,2,-5,251:15)
Block(0,2,-4,159:15)
Block(0,2,-3,159:15)
Block(0,2,-2,251:15)
Block(0,2,-1,159:15)
Block(0,2,0,251:7)
Block(0,2,1,251:15)
Block(0,3,-5,159:15)
Block(0,3,-4,159:15)
Block(0,3,-3,251:15)
Block(0,3,-2,159:15)
Block(0,3,-1,159:15)
Block(0,3,0,251:7)
Block(0,3,1,251:15)
Block(0,4,-5,251:15)
Block(0,4,-4,159:15)
Block(0,4,-3,251:15)
Block(0,4,-2,251:15)
Block(0,4,-1,251:15)
Block(0,4,0,251:15)
Block(0,4,1,251:15)
Block(0,5,-5,251:15)
Block(0,5,-4,251:15)
Block(0,5,-3,251:15)
Block(0,5,-2,159:15)
Block(0,5,-1,251:15)
Block(0,5,0,251:15)
Block(0,5,1,159:15)
Block(0,6,-5,159:15)
Block(0,6,-4,251:15)
Block(0,6,-3,251:15)
Block(0,6,-2,251:15)
Block(0,6,-1,251:15)
Block(0,6,0,251:7)
Block(0,6,1,251:15)
Block(0,7,-5,159:15)
Block(0,7,-4,251:15)
Block(0,7,-3,251:15)
Block(0,7,-2,251:15)
Block(0,7,-1,251:15)
Block(0,7,0,251:7)
Block(0,7,1,251:7)
Block(0,8,-5,251:15)
Block(0,8,-4,251:15)
Block(0,8,-3,159:15)
Block(0,8,-2,159:15)
Block(0,8,-1,251:15)
Block(0,8,0,251:7)
Block(0,8,1,251:7)
Block(0,9,-5,251:15)
Block(0,9,-4,159:15)
Block(0,9,-3,251:15)
Block(0,9,-2,251:15)
Block(0,9,-1,159:15)
Block(0,9,0,251:7)
Block(0,9,1,251:7)
Block(0,10,-5,159:15)
Block(0,10,-4,251:15)
Block(0,10,-3,159:15)
Block(0,10,-2,251:15)
Block(0,10,-1,159:15)
Block(0,10,0,159:15)
Block(0,10,1,251:7)
Block(0,11,-5,251:15)
Block(0,11,-4,251:15)
Block(0,11,-3,251:15)
Block(0,11,-2,251:15)
Block(0,11,-1,159:15)
Block(0,11,0,251:15)
Block(0,11,1,159:15)
Block(0,12,-5,251:15)
Block(0,12,-4,251:7)
Block(0,12,-3,251:15)
Block(0,12,-2,251:15)
Block(0,12,-1,159:15)
Block(0,12,0,251:15)
Block(0,12,1,251:15)
Block(0,13,-5,251:7)
Block(0,13,-4,251:7)
Block(0,13,-3,159:15)
Block(0,13,-2,251:15)
Block(0,13,-1,159:15)
Block(0,13,0,251:15)
Block(0,13,1,159:15)
Block(0,14,-5,251:7)
Block(0,14,-4,251:7)
Block(0,14,-3,251:15)
Block(0,14,-2,159:15)
Block(0,14,-1,159:15)
Block(0,14,0,251:15)
Block(0,14,1,159:15)
Block(0,15,-5,251:15)
Block(0,15,-4,251:15)
Block(0,15,-3,159:15)
Block(0,15,-2,159:15)
Block(0,15,-1,251:15)
Block(0,15,0,159:15)
Block(0,15,1,251:15)
Block(0,16,-5,251:15)
Block(0,16,-4,159:15)
Block(0,16,-3,159:15)
Block(0,16,-2,159:15)
Block(0,16,-1,251:15)
Block(0,16,0,159:15)
Block(0,16,1,159:15)
Block(0,17,-5,251:15)
Block(0,17,-4,159:15)
Block(0,17,-3,251:15)
Block(0,17,-2,251:15)
Block(0,17,-1,159:15)
Block(0,17,0,159:15)
Block(0,17,1,251:15)
Block(0,18,-5,251:15)
Block(0,18,-4,251:15)
Block(0,18,-3,159:15)
Block(0,18,-2,159:15)
Block(0,18,-1,159:15)
Block(0,18,0,159:15)
Block(0,18,1,159:15)
Block(1,0,-6,251:7)
Block(1,0,-5,159:15)
Block(1,0,-4,251:15)
Block(1,0,-3,159:15)
Block(1,0,-2,159:15)
Block(1,0,-1,159:15)
Block(1,0,0,159:15)
Block(1,0,1,159:15)
Block(1,0,2,159:15)
Block(1,1,-6,251:7)
Block(1,1,-5,159:15)
Block(1,1,-4,159:15)
Block(1,1,-3,251:15)
Block(1,1,-2,159:15)
Block(1,1,-1,159:15)
Block(1,1,0,251:15)
Block(1,1,1,251:15)
Block(1,1,2,251:15)
Block(1,2,-6,251:15)
Block(1,2,-5,251:15)
Block(1,2,-4,159:15)
Block(1,2,-3,251:15)
Block(1,2,-2,159:15)
Block(1,2,-1,159:15)
Block(1,2,0,251:15)
Block(1,2,1,251:15)
Block(1,2,2,251:15)
Block(1,3,-6,251:15)
Block(1,3,-5,159:15)
Block(1,3,-4,251:15)
Block(1,3,-3,251:15)
Block(1,3,-2,251:15)
Block(1,3,-1,159:15)
Block(1,3,0,159:15)
Block(1,3,1,159:15)
Block(1,3,2,251:15)
Block(1,4,-6,251:15)
Block(1,4,-5,251:15)
Block(1,4,-4,251:15)
Block(1,4,-3,251:15)
Block(1,4,-2,251:15)
Block(1,4,-1,159:15)
Block(1,4,0,251:15)
Block(1,4,1,251:15)
Block(1,4,2,159:15)
Block(1,5,-6,251:15)
Block(1,5,-5,159:15)
Block(1,5,-4,251:15)
Block(1,5,-3,159:15)
Block(1,5,-2,159:15)
Block(1,5,-1,159:15)
Block(1,5,0,159:15)
Block(1,5,1,251:15)
Block(1,5,2,159:15)
Block(1,6,-6,159:15)
Block(1,6,-5,159:15)
Block(1,6,-4,251:15)
Block(1,6,-3,251:15)
Block(1,6,-2,251:15)
Block(1,6,-1,251:15)
Block(1,6,0,159:15)
Block(1,6,1,159:15)
Block(1,6,2,159:15)
Block(1,7,-6,159:15)
Block(1,7,-5,251:15)
Block(1,7,-4,251:15)
Block(1,7,-3,251:15)
Block(1,7,-2,251:15)
Block(1,7,-1,251:15)
Block(1,7,0,159:15)
Block(1,7,1,159:15)
Block(1,7,2,251:15)
Block(1,8,-6,251:15)
Block(1,8,-5,159:15)
Block(1,8,-4,251:15)
Block(1,8,-3,159:15)
Block(1,8,-2,251:15)
Block(1,8,-1,159:15)
Block(1,8,0,251:15)
Block(1,8,1,251:15)
Block(1,8,2,251:7)
Block(1,9,-6,159:15)
Block(1,9,-5,251:15)
Block(1,9,-4,251:15)
Block(1,9,-3,159:15)
Block(1,9,-2,159:15)
Block(1,9,-1,159:15)
Block(1,9,0,159:15)
Block(1,9,1,159:15)
Block(1,9,2,251:7)
Block(1,10,-6,159:15)
Block(1,10,-5,251:15)
Block(1,10,-4,159:15)
Block(1,10,-3,251:15)
Block(1,10,-2,251:15)
Block(1,10,-1,251:15)
Block(1,10,0,251:15)
Block(1,10,1,159:15)
Block(1,10,2,251:7)
Block(1,11,-6,251:15)
Block(1,11,-5,251:15)
Block(1,11,-4,159:15)
Block(1,11,-3,251:15)
Block(1,11,-2,159:15)
Block(1,11,-1,251:15)
Block(1,11,0,251:15)
Block(1,11,1,159:15)
Block(1,11,2,251:7)
Block(1,12,-6,251:15)
Block(1,12,-5,251:15)
Block(1,12,-4,159:15)
Block(1,12,-3,251:15)
Block(1,12,-2,159:15)
Block(1,12,-1,159:15)
Block(1,12,0,159:15)
Block(1,12,1,251:15)
Block(1,12,2,251:15)
Block(1,13,-6,251:7)
Block(1,13,-5,159:15)
Block(1,13,-4,159:15)
Block(1,13,-3,251:15)
Block(1,13,-2,159:15)
Block(1,13,-1,251:15)
Block(1,13,0,159:15)
Block(1,13,1,251:15)
Block(1,13,2,159:15)
Block(1,14,-6,251:7)
Block(1,14,-5,159:15)
Block(1,14,-4,159:15)
Block(1,14,-3,251:15)
Block(1,14,-2,251:15)
Block(1,14,-1,251:15)
Block(1,14,0,159:15)
Block(1,14,1,159:15)
Block(1,14,2,251:15)
Block(1,15,-6,251:7)
Block(1,15,-5,159:15)
Block(1,15,-4,159:15)
Block(1,15,-3,251:15)
Block(1,15,-2,251:15)
Block(1,15,-1,251:15)
Block(1,15,0,251:15)
Block(1,15,1,159:15)
Block(1,15,2,159:15)
Block(1,16,-6,251:15)
Block(1,16,-5,159:15)
Block(1,16,-4,159:15)
Block(1,16,-3,251:15)
Block(1,16,-2,159:15)
Block(1,16,-1,251:15)
Block(1,16,0,159:15)
Block(1,16,1,159:15)
Block(1,16,2,159:15)
Block(1,17,-6,251:15)
Block(1,17,-5,159:15)
Block(1,17,-4,251:15)
Block(1,17,-3,159:15)
Block(1,17,-2,159:15)
Block(1,17,-1,159:15)
Block(1,17,0,159:15)
Block(1,17,1,251:15)
Block(1,17,2,251:15)
Block(1,18,-6,251:15)
Block(1,18,-5,159:15)
Block(1,18,-4,159:15)
Block(1,18,-3,159:15)
Block(1,18,-2,159:15)
Block(1,18,-1,159:15)
Block(1,18,0,159:15)
Block(1,18,1,251:15)
Block(1,18,2,159:15)
Block(2,0,-7,251:7)
Block(2,0,-6,159:15)
Block(2,0,-5,159:15)
Block(2,0,-4,159:15)
Block(2,0,-3,159:15)
Block(2,0,-2,251:15)
Block(2,0,-1,251:15)
Block(2,0,0,251:15)
Block(2,0,1,251:15)
Block(2,0,2,159:15)
Block(2,0,3,251:15)
Block(2,1,-7,251:7)
Block(2,1,-6,251:15)
Block(2,1,-5,159:15)
Block(2,1,-4,159:15)
Block(2,1,-3,159:15)
Block(2,1,-2,159:15)
Block(2,1,-1,251:15)
Block(2,1,0,159:15)
Block(2,1,1,251:15)
Block(2,1,2,251:15)
Block(2,1,3,251:15)
Block(2,2,-7,251:7)
Block(2,2,-6,159:15)
Block(2,2,-5,251:15)
Block(2,2,-4,159:15)
Block(2,2,-3,159:15)
Block(2,2,-2,251:15)
Block(2,2,-1,251:15)
Block(2,2,0,159:15)
Block(2,2,1,251:15)
Block(2,2,2,159:15)
Block(2,2,3,251:15)
Block(2,3,-7,251:15)
Block(2,3,-6,159:15)
Block(2,3,-5,251:15)
Block(2,3,-4,251:15)
Block(2,3,-3,251:15)
Block(2,3,-2,159:15)
Block(2,3,-1,159:15)
Block(2,3,0,159:15)
Block(2,3,1,159:15)
Block(2,3,2,159:15)
Block(2,3,3,251:15)
Block(2,4,-7,251:15)
Block(2,4,-6,251:15)
Block(2,4,-5,159:15)
Block(2,4,-4,159:15)
Block(2,4,-3,251:15)
Block(2,4,-2,251:15)
Block(2,4,-1,159:15)
Block(2,4,0,251:15)
Block(2,4,1,159:15)
Block(2,4,2,251:15)
Block(2,4,3,251:15)
Block(2,5,-7,251:15)
Block(2,5,-6,159:15)
Block(2,5,-5,159:15)
Block(2,5,-4,251:15)
Block(2,5,-3,251:15)
Block(2,5,-2,251:15)
Block(2,5,-1,159:15)
Block(2,5,0,251:15)
Block(2,5,1,159:15)
Block(2,5,2,159:15)
Block(2,5,3,251:15)
Block(2,6,-7,251:15)
Block(2,6,-6,251:15)
Block(2,6,-5,159:15)
Block(2,6,-4,251:15)
Block(2,6,-3,159:15)
Block(2,6,-2,251:15)
Block(2,6,-1,159:15)
Block(2,6,0,159:15)
Block(2,6,1,251:15)
Block(2,6,2,159:15)
Block(2,6,3,251:15)
Block(2,7,-7,251:15)
Block(2,7,-6,251:15)
Block(2,7,-5,159:15)
Block(2,7,-4,251:15)
Block(2,7,-3,251:15)
Block(2,7,-2,251:15)
Block(2,7,-1,251:15)
Block(2,7,0,251:15)
Block(2,7,1,251:15)
Block(2,7,2,159:15)
Block(2,7,3,159:15)
Block(2,8,-7,251:15)
Block(2,8,-6,251:15)
Block(2,8,-5,251:15)
Block(2,8,-4,251:15)
Block(2,8,-3,159:15)
Block(2,8,-2,159:15)
Block(2,8,-1,159:15)
Block(2,8,0,251:15)
Block(2,8,1,251:15)
Block(2,8,2,251:15)
Block(2,8,3,159:15)
Block(2,9,-7,159:15)
Block(2,9,-6,159:15)
Block(2,9,-5,251:15)
Block(2,9,-4,159:15)
Block(2,9,-3,159:15)
Block(2,9,-2,159:15)
Block(2,9,-1,251:15)
Block(2,9,0,251:15)
Block(2,9,1,159:15)
Block(2,9,2,251:15)
Block(2,9,3,251:7)
Block(2,10,-7,159:15)
Block(2,10,-6,159:15)
Block(2,10,-5,251:15)
Block(2,10,-4,159:15)
Block(2,10,-3,251:15)
Block(2,10,-2,251:15)
Block(2,10,-1,251:15)
Block(2,10,0,251:15)
Block(2,10,1,251:15)
Block(2,10,2,159:15)
Block(2,10,3,251:7)
Block(2,11,-7,251:15)
Block(2,11,-6,251:15)
Block(2,11,-5,159:15)
Block(2,11,-4,159:15)
Block(2,11,-3,251:15)
Block(2,11,-2,159:15)
Block(2,11,-1,159:15)
Block(2,11,0,251:15)
Block(2,11,1,159:15)
Block(2,11,2,159:15)
Block(2,11,3,251:7)
Block(2,12,-7,251:15)
Block(2,12,-6,159:15)
Block(2,12,-5,251:15)
Block(2,12,-4,159:15)
Block(2,12,-3,251:15)
Block(2,12,-2,251:15)
Block(2,12,-1,159:15)
Block(2,12,0,251:15)
Block(2,12,1,251:15)
Block(2,12,2,159:15)
Block(2,12,3,251:7)
Block(2,13,-7,159:15)
Block(2,13,-6,159:15)
Block(2,13,-5,159:15)
Block(2,13,-4,251:15)
Block(2,13,-3,251:15)
Block(2,13,-2,159:15)
Block(2,13,-1,251:15)
Block(2,13,0,159:15)
Block(2,13,1,159:15)
Block(2,13,2,159:15)
Block(2,13,3,251:15)
Block(2,14,-7,251:7)
Block(2,14,-6,251:15)
Block(2,14,-5,251:15)
Block(2,14,-4,251:15)
Block(2,14,-3,251:15)
Block(2,14,-2,159:15)
Block(2,14,-1,159:15)
Block(2,14,0,251:15)
Block(2,14,1,159:15)
Block(2,14,2,159:15)
Block(2,14,3,251:15)
Block(2,15,-7,251:7)
Block(2,15,-6,251:15)
Block(2,15,-5,251:15)
Block(2,15,-4,251:15)
Block(2,15,-3,251:15)
Block(2,15,-2,251:15)
Block(2,15,-1,251:15)
Block(2,15,0,251:15)
Block(2,15,1,159:15)
Block(2,15,2,251:15)
Block(2,15,3,251:15)
Block(2,16,-7,251:15)
Block(2,16,-6,251:15)
Block(2,16,-5,159:15)
Block(2,16,-4,159:15)
Block(2,16,-3,251:15)
Block(2,16,-2,251:15)
Block(2,16,-1,159:15)
Block(2,16,0,159:15)
Block(2,16,1,251:15)
Block(2,16,2,251:15)
Block(2,16,3,159:15)
Block(2,17,-7,251:15)
Block(2,17,-6,159:15)
Block(2,17,-5,251:15)
Block(2,17,-4,159:15)
Block(2,17,-3,159:15)
Block(2,17,-2,251:15)
Block(2,17,-1,251:15)
Block(2,17,0,251:15)
Block(2,17,1,251:15)
Block(2,17,2,251:15)
Block(2,17,3,159:15)
Block(2,18,-7,251:15)
Block(2,18,-6,251:15)
Block(2,18,-5,159:15)
Block(2,18,-4,159:15)
Block(2,18,-3,159:15)
Block(2,18,-2,159:15)
Block(2,18,-1,2)
Block(2,18,0,2)
Block(2,18,1,251:15)
Block(2,18,2,251:15)
Block(2,18,3,159:15)
Block(3,0,-7,251:15)
Block(3,0,-6,251:15)
Block(3,0,-5,251:15)
Block(3,0,-4,159:15)
Block(3,0,-3,159:15)
Block(3,0,-2,251:15)
Block(3,0,-1,159:15)
Block(3,0,0,159:15)
Block(3,0,1,159:15)
Block(3,0,2,159:15)
Block(3,0,3,251:15)
Block(3,1,-7,251:15)
Block(3,1,-6,251:15)
Block(3,1,-5,159:15)
Block(3,1,-4,159:15)
Block(3,1,-3,159:15)
Block(3,1,-2,159:15)
Block(3,1,-1,251:15)
Block(3,1,0,251:15)
Block(3,1,1,159:15)
Block(3,1,2,159:15)
Block(3,1,3,159:15)
Block(3,2,-7,159:15)
Block(3,2,-6,159:15)
Block(3,2,-5,159:15)
Block(3,2,-4,159:15)
Block(3,2,-3,251:15)
Block(3,2,-2,159:15)
Block(3,2,-1,251:15)
Block(3,2,0,251:15)
Block(3,2,1,159:15)
Block(3,2,2,159:15)
Block(3,2,3,159:15)
Block(3,3,-7,251:15)
Block(3,3,-6,159:15)
Block(3,3,-5,251:15)
Block(3,3,-4,159:15)
Block(3,3,-3,251:15)
Block(3,3,-2,159:15)
Block(3,3,-1,251:15)
Block(3,3,0,159:15)
Block(3,3,1,251:15)
Block(3,3,2,251:15)
Block(3,3,3,159:15)
Block(3,4,-7,159:15)
Block(3,4,-6,251:15)
Block(3,4,-5,251:15)
Block(3,4,-4,159:15)
Block(3,4,-3,159:15)
Block(3,4,-2,251:15)
Block(3,4,-1,251:15)
Block(3,4,0,159:15)
Block(3,4,1,251:15)
Block(3,4,2,159:15)
Block(3,4,3,251:15)
Block(3,5,-7,251:15)
Block(3,5,-6,159:15)
Block(3,5,-5,159:15)
Block(3,5,-4,159:15)
Block(3,5,-3,159:15)
Block(3,5,-2,159:15)
Block(3,5,-1,251:15)
Block(3,5,0,251:15)
Block(3,5,1,159:15)
Block(3,5,2,159:15)
Block(3,5,3,251:15)
Block(3,6,-7,159:15)
Block(3,6,-6,251:15)
Block(3,6,-5,159:15)
Block(3,6,-4,159:15)
Block(3,6,-3,251:15)
Block(3,6,-2,251:15)
Block(3,6,-1,159:15)
Block(3,6,0,251:15)
Block(3,6,1,159:15)
Block(3,6,2,159:15)
Block(3,6,3,159:15)
Block(3,7,-7,251:15)
Block(3,7,-6,251:15)
Block(3,7,-5,159:15)
Block(3,7,-4,251:15)
Block(3,7,-3,159:15)
Block(3,7,-2,251:15)
Block(3,7,-1,251:15)
Block(3,7,0,159:15)
Block(3,7,1,159:15)
Block(3,7,2,159:15)
Block(3,7,3,159:15)
Block(3,8,-7,251:15)
Block(3,8,-6,251:15)
Block(3,8,-5,159:15)
Block(3,8,-4,251:15)
Block(3,8,-3,251:15)
Block(3,8,-2,251:15)
Block(3,8,-1,159:15)
Block(3,8,0,159:15)
Block(3,8,1,251:15)
Block(3,8,2,251:15)
Block(3,8,3,251:15)
Block(3,9,-7,251:15)
Block(3,9,-6,251:15)
Block(3,9,-5,251:15)
Block(3,9,-4,251:15)
Block(3,9,-3,159:15)
Block(3,9,-2,251:15)
Block(3,9,-1,159:15)
Block(3,9,0,159:15)
Block(3,9,1,159:15)
Block(3,9,2,251:15)
Block(3,9,3,159:15)
Block(3,10,-7,159:15)
Block(3,10,-6,159:15)
Block(3,10,-5,251:15)
Block(3,10,-4,159:15)
Block(3,10,-3,251:15)
Block(3,10,-2,251:15)
Block(3,10,-1,251:15)
Block(3,10,0,251:15)
Block(3,10,1,159:15)
Block(3,10,2,251:15)
Block(3,10,3,251:7)
Block(3,11,-7,251:15)
Block(3,11,-6,159:15)
Block(3,11,-5,251:15)
Block(3,11,-4,159:15)
Block(3,11,-3,159:15)
Block(3,11,-2,159:15)
Block(3,11,-1,251:15)
Block(3,11,0,159:15)
Block(3,11,1,251:15)
Block(3,11,2,251:15)
Block(3,11,3,251:7)
Block(3,12,-7,159:15)
Block(3,12,-6,159:15)
Block(3,12,-5,159:15)
Block(3,12,-4,251:15)
Block(3,12,-3,159:15)
Block(3,12,-2,159:15)
Block(3,12,-1,159:15)
Block(3,12,0,159:15)
Block(3,12,1,251:15)
Block(3,12,2,159:15)
Block(3,12,3,251:7)
Block(3,13,-7,159:15)
Block(3,13,-6,251:15)
Block(3,13,-5,251:15)
Block(3,13,-4,251:15)
Block(3,13,-3,159:15)
Block(3,13,-2,159:15)
Block(3,13,-1,159:15)
Block(3,13,0,251:15)
Block(3,13,1,159:15)
Block(3,13,2,159:15)
Block(3,13,3,251:15)
Block(3,14,-7,251:7)
Block(3,14,-6,159:15)
Block(3,14,-5,251:15)
Block(3,14,-4,251:15)
Block(3,14,-3,251:15)
Block(3,14,-2,251:15)
Block(3,14,-1,251:15)
Block(3,14,0,251:15)
Block(3,14,1,251:15)
Block(3,14,2,159:15)
Block(3,14,3,159:15)
Block(3,15,-7,251:7)
Block(3,15,-6,159:15)
Block(3,15,-5,159:15)
Block(3,15,-4,251:15)
Block(3,15,-3,159:15)
Block(3,15,-2,251:15)
Block(3,15,-1,251:15)
Block(3,15,0,251:15)
Block(3,15,1,159:15)
Block(3,15,2,159:15)
Block(3,15,3,251:15)
Block(3,16,-7,251:15)
Block(3,16,-6,159:15)
Block(3,16,-5,251:15)
Block(3,16,-4,251:15)
Block(3,16,-3,159:15)
Block(3,16,-2,251:15)
Block(3,16,-1,159:15)
Block(3,16,0,159:15)
Block(3,16,1,159:15)
Block(3,16,2,159:15)
Block(3,16,3,159:15)
Block(3,17,-7,251:15)
Block(3,17,-6,251:15)
Block(3,17,-5,251:15)
Block(3,17,-4,159:15)
Block(3,17,-3,251:15)
Block(3,17,-2,159:15)
Block(3,17,-1,159:15)
Block(3,17,0,159:15)
Block(3,17,1,159:15)
Block(3,17,2,159:15)
Block(3,17,3,251:15)
Block(3,18,-7,251:15)
Block(3,18,-6,251:15)
Block(3,18,-5,159:15)
Block(3,18,-4,159:15)
Block(3,18,-3,159:15)
Block(3,18,-2,159:15)
Block(3,18,-1,251:15)
Block(3,18,0,2)
Block(3,18,1,2)
Block(3,18,2,159:15)
Block(3,18,3,251:15)
Block(4,0,-7,159:15)
Block(4,0,-6,159:15)
Block(4,0,-5,159:15)
Block(4,0,-4,159:15)
Block(4,0,-3,251:15)
Block(4,0,-2,251:15)
Block(4,0,-1,251:15)
Block(4,0,0,251:15)
Block(4,0,1,251:15)
Block(4,0,2,159:15)
Block(4,0,3,159:15)
Block(4,1,-7,159:15)
Block(4,1,-6,159:15)
Block(4,1,-5,159:15)
Block(4,1,-4,159:15)
Block(4,1,-3,159:15)
Block(4,1,-2,159:15)
Block(4,1,-1,159:15)
Block(4,1,0,159:15)
Block(4,1,1,159:15)
Block(4,1,2,251:15)
Block(4,1,3,159:15)
Block(4,2,-7,159:15)
Block(4,2,-6,251:15)
Block(4,2,-5,159:15)
Block(4,2,-4,159:15)
Block(4,2,-3,251:15)
Block(4,2,-2,251:15)
Block(4,2,-1,251:15)
Block(4,2,0,251:15)
Block(4,2,1,251:15)
Block(4,2,2,251:15)
Block(4,2,3,251:15)
Block(4,3,-7,251:15)
Block(4,3,-6,159:15)
Block(4,3,-5,159:15)
Block(4,3,-4,159:15)
Block(4,3,-3,251:15)
Block(4,3,-2,251:15)
Block(4,3,-1,251:15)
Block(4,3,0,159:15)
Block(4,3,1,159:15)
Block(4,3,2,159:15)
Block(4,3,3,159:15)
Block(4,4,-7,251:15)
Block(4,4,-6,251:15)
Block(4,4,-5,159:15)
Block(4,4,-4,159:15)
Block(4,4,-3,159:15)
Block(4,4,-2,159:15)
Block(4,4,-1,251:15)
Block(4,4,0,159:15)
Block(4,4,1,159:15)
Block(4,4,2,251:15)
Block(4,4,3,159:15)
Block(4,5,-7,159:15)
Block(4,5,-6,251:15)
Block(4,5,-5,159:15)
Block(4,5,-4,251:15)
Block(4,5,-3,251:15)
Block(4,5,-2,159:15)
Block(4,5,-1,251:15)
Block(4,5,0,251:15)
Block(4,5,1,251:15)
Block(4,5,2,251:15)
Block(4,5,3,159:15)
Block(4,6,-7,251:15)
Block(4,6,-6,159:15)
Block(4,6,-5,159:15)
Block(4,6,-4,251:15)
Block(4,6,-3,159:15)
Block(4,6,-2,159:15)
Block(4,6,-1,251:15)
Block(4,6,0,159:15)
Block(4,6,1,251:15)
Block(4,6,2,251:15)
Block(4,6,3,159:15)
Block(4,7,-7,251:15)
Block(4,7,-6,159:15)
Block(4,7,-5,159:15)
Block(4,7,-4,159:15)
Block(4,7,-3,159:15)
Block(4,7,-2,159:15)
Block(4,7,-1,159:15)
Block(4,7,0,159:15)
Block(4,7,1,251:15)
Block(4,7,2,251:15)
Block(4,7,3,159:15)
Block(4,8,-7,251:15)
Block(4,8,-6,159:15)
Block(4,8,-5,159:15)
Block(4,8,-4,159:15)
Block(4,8,-3,251:15)
Block(4,8,-2,159:15)
Block(4,8,-1,159:15)
Block(4,8,0,251:15)
Block(4,8,1,159:15)
Block(4,8,2,251:15)
Block(4,8,3,251:15)
Block(4,9,-7,251:15)
Block(4,9,-6,251:15)
Block(4,9,-5,159:15)
Block(4,9,-4,251:15)
Block(4,9,-3,251:15)
Block(4,9,-2,251:15)
Block(4,9,-1,251:15)
Block(4,9,0,251:15)
Block(4,9,1,159:15)
Block(4,9,2,251:15)
Block(4,9,3,159:15)
Block(4,10,-7,251:15)
Block(4,10,-6,251:15)
Block(4,10,-5,251:15)
Block(4,10,-4,159:15)
Block(4,10,-3,251:15)
Block(4,10,-2,159:15)
Block(4,10,-1,159:15)
Block(4,10,0,159:15)
Block(4,10,1,159:15)
Block(4,10,2,251:15)
Block(4,10,3,251:15)
Block(4,11,-7,251:15)
Block(4,11,-6,251:15)
Block(4,11,-5,159:15)
Block(4,11,-4,251:15)
Block(4,11,-3,251:15)
Block(4,11,-2,159:15)
Block(4,11,-1,251:15)
Block(4,11,0,251:15)
Block(4,11,1,159:15)
Block(4,11,2,251:15)
Block(4,11,3,251:7)
Block(4,12,-7,159:15)
Block(4,12,-6,251:15)
Block(4,12,-5,251:15)
Block(4,12,-4,159:15)
Block(4,12,-3,251:15)
Block(4,12,-2,251:15)
Block(4,12,-1,159:15)
Block(4,12,0,159:15)
Block(4,12,1,251:15)
Block(4,12,2,251:15)
Block(4,12,3,251:7)
Block(4,13,-7,159:15)
Block(4,13,-6,159:15)
Block(4,13,-5,251:15)
Block(4,13,-4,159:15)
Block(4,13,-3,159:15)
Block(4,13,-2,159:15)
Block(4,13,-1,159:15)
Block(4,13,0,251:15)
Block(4,13,1,159:15)
Block(4,13,2,159:15)
Block(4,13,3,251:7)
Block(4,14,-7,251:7)
Block(4,14,-6,159:15)
Block(4,14,-5,159:15)
Block(4,14,-4,159:15)
Block(4,14,-3,159:15)
Block(4,14,-2,159:15)
Block(4,14,-1,251:15)
Block(4,14,0,251:15)
Block(4,14,1,159:15)
Block(4,14,2,159:15)
Block(4,14,3,251:15)
Block(4,15,-7,251:7)
Block(4,15,-6,251:15)
Block(4,15,-5,159:15)
Block(4,15,-4,251:15)
Block(4,15,-3,159:15)
Block(4,15,-2,159:15)
Block(4,15,-1,159:15)
Block(4,15,0,159:15)
Block(4,15,1,159:15)
Block(4,15,2,159:15)
Block(4,15,3,159:15)
Block(4,16,-7,251:15)
Block(4,16,-6,251:15)
Block(4,16,-5,251:15)
Block(4,16,-4,251:15)
Block(4,16,-3,251:15)
Block(4,16,-2,159:15)
Block(4,16,-1,159:15)
Block(4,16,0,251:15)
Block(4,16,1,159:15)
Block(4,16,2,159:15)
Block(4,16,3,251:15)
Block(4,17,-7,251:15)
Block(4,17,-6,251:15)
Block(4,17,-5,159:15)
Block(4,17,-4,159:15)
Block(4,17,-3,159:15)
Block(4,17,-2,159:15)
Block(4,17,-1,159:15)
Block(4,17,0,159:15)
Block(4,17,1,251:15)
Block(4,17,2,159:15)
Block(4,17,3,251:15)
Block(4,18,-7,251:15)
Block(4,18,-6,251:15)
Block(4,18,-5,251:15)
Block(4,18,-4,159:15)
Block(4,18,-3,159:15)
Block(4,18,-2,159:15)
Block(4,18,-1,159:15)
Block(4,18,0,2)
Block(4,18,1,159:15)
Block(4,18,2,159:15)
Block(4,18,3,251:15)
Block(5,0,-7,251:15)
Block(5,0,-6,251:15)
Block(5,0,-5,159:15)
Block(5,0,-4,159:15)
Block(5,0,-3,159:15)
Block(5,0,-2,251:15)
Block(5,0,-1,159:15)
Block(5,0,0,251:15)
Block(5,0,1,159:15)
Block(5,0,2,159:15)
Block(5,0,3,159:15)
Block(5,1,-7,159:15)
Block(5,1,-6,251:15)
Block(5,1,-5,251:15)
Block(5,1,-4,159:15)
Block(5,1,-3,251:15)
Block(5,1,-2,159:15)
Block(5,1,-1,251:15)
Block(5,1,0,251:15)
Block(5,1,1,159:15)
Block(5,1,2,251:15)
Block(5,1,3,251:15)
Block(5,2,-7,159:15)
Block(5,2,-6,251:15)
Block(5,2,-5,159:15)
Block(5,2,-4,251:15)
Block(5,2,-3,251:15)
Block(5,2,-2,251:15)
Block(5,2,-1,159:15)
Block(5,2,0,159:15)
Block(5,2,1,251:15)
Block(5,2,2,251:15)
Block(5,2,3,251:15)
Block(5,3,-7,251:15)
Block(5,3,-6,159:15)
Block(5,3,-5,159:15)
Block(5,3,-4,159:15)
Block(5,3,-3,251:15)
Block(5,3,-2,251:15)
Block(5,3,-1,251:15)
Block(5,3,0,159:15)
Block(5,3,1,159:15)
Block(5,3,2,251:15)
Block(5,3,3,159:15)
Block(5,4,-7,251:15)
Block(5,4,-6,159:15)
Block(5,4,-5,251:15)
Block(5,4,-4,159:15)
Block(5,4,-3,159:15)
Block(5,4,-2,251:15)
Block(5,4,-1,159:15)
Block(5,4,0,251:15)
Block(5,4,1,159:15)
Block(5,4,2,159:15)
Block(5,4,3,159:15)
Block(5,5,-7,251:15)
Block(5,5,-6,159:15)
Block(5,5,-5,159:15)
Block(5,5,-4,159:15)
Block(5,5,-3,251:15)
Block(5,5,-2,251:15)
Block(5,5,-1,251:15)
Block(5,5,0,159:15)
Block(5,5,1,159:15)
Block(5,5,2,251:15)
Block(5,5,3,159:15)
Block(5,6,-7,251:15)
Block(5,6,-6,251:15)
Block(5,6,-5,159:15)
Block(5,6,-4,159:15)
Block(5,6,-3,251:15)
Block(5,6,-2,251:15)
Block(5,6,-1,251:15)
Block(5,6,0,159:15)
Block(5,6,1,251:15)
Block(5,6,2,251:15)
Block(5,6,3,159:15)
Block(5,7,-7,251:15)
Block(5,7,-6,159:15)
Block(5,7,-5,251:15)
Block(5,7,-4,159:15)
Block(5,7,-3,159:15)
Block(5,7,-2,159:15)
Block(5,7,-1,159:15)
Block(5,7,0,251:15)
Block(5,7,1,251:15)
Block(5,7,2,159:15)
Block(5,7,3,159:15)
Block(5,8,-7,251:15)
Block(5,8,-6,251:15)
Block(5,8,-5,159:15)
Block(5,8,-4,159:15)
Block(5,8,-3,251:15)
Block(5,8,-2,251:15)
Block(5,8,-1,251:15)
Block(5,8,0,251:15)
Block(5,8,1,251:15)
Block(5,8,2,159:15)
Block(5,8,3,159:15)
Block(5,9,-7,251:15)
Block(5,9,-6,251:15)
Block(5,9,-5,251:15)
Block(5,9,-4,159:15)
Block(5,9,-3,159:15)
Block(5,9,-2,159:15)
Block(5,9,-1,159:15)
Block(5,9,0,251:15)
Block(5,9,1,159:15)
Block(5,9,2,251:15)
Block(5,9,3,251:15)
Block(5,10,-7,251:15)
Block(5,10,-6,159:15)
Block(5,10,-5,251:15)
Block(5,10,-4,159:15)
Block(5,10,-3,159:15)
Block(5,10,-2,251:15)
Block(5,10,-1,159:15)
Block(5,10,0,251:15)
Block(5,10,1,159:15)
Block(5,10,2,251:15)
Block(5,10,3,159:15)
Block(5,11,-7,251:15)
Block(5,11,-6,251:15)
Block(5,11,-5,159:15)
Block(5,11,-4,159:15)
Block(5,11,-3,159:15)
Block(5,11,-2,159:15)
Block(5,11,-1,159:15)
Block(5,11,0,159:15)
Block(5,11,1,159:15)
Block(5,11,2,251:15)
Block(5,11,3,251:7)
Block(5,12,-7,251:15)
Block(5,12,-6,251:15)
Block(5,12,-5,159:15)
Block(5,12,-4,159:15)
Block(5,12,-3,159:15)
Block(5,12,-2,159:15)
Block(5,12,-1,159:15)
Block(5,12,0,159:15)
Block(5,12,1,251:15)
Block(5,12,2,251:15)
Block(5,12,3,251:7)
Block(5,13,-7,159:15)
Block(5,13,-6,159:15)
Block(5,13,-5,159:15)
Block(5,13,-4,251:15)
Block(5,13,-3,251:15)
Block(5,13,-2,251:15)
Block(5,13,-1,251:15)
Block(5,13,0,251:15)
Block(5,13,1,159:15)
Block(5,13,2,159:15)
Block(5,13,3,251:7)
Block(5,14,-7,251:7)
Block(5,14,-6,251:15)
Block(5,14,-5,159:15)
Block(5,14,-4,251:15)
Block(5,14,-3,251:15)
Block(5,14,-2,251:15)
Block(5,14,-1,159:15)
Block(5,14,0,159:15)
Block(5,14,1,159:15)
Block(5,14,2,251:15)
Block(5,14,3,159:15)
Block(5,15,-7,251:7)
Block(5,15,-6,159:15)
Block(5,15,-5,159:15)
Block(5,15,-4,251:15)
Block(5,15,-3,251:15)
Block(5,15,-2,251:15)
Block(5,15,-1,159:15)
Block(5,15,0,159:15)
Block(5,15,1,251:15)
Block(5,15,2,159:15)
Block(5,15,3,159:15)
Block(5,16,-7,159:15)
Block(5,16,-6,251:15)
Block(5,16,-5,251:15)
Block(5,16,-4,251:15)
Block(5,16,-3,159:15)
Block(5,16,-2,159:15)
Block(5,16,-1,251:15)
Block(5,16,0,159:15)
Block(5,16,1,251:15)
Block(5,16,2,251:15)
Block(5,16,3,251:15)
Block(5,17,-7,251:15)
Block(5,17,-6,159:15)
Block(5,17,-5,159:15)
Block(5,17,-4,251:15)
Block(5,17,-3,159:15)
Block(5,17,-2,251:15)
Block(5,17,-1,159:15)
Block(5,17,0,159:15)
Block(5,17,1,159:15)
Block(5,17,2,251:15)
Block(5,17,3,251:15)
Block(5,18,-7,159:15)
Block(5,18,-6,159:15)
Block(5,18,-5,251:15)
Block(5,18,-4,159:15)
Block(5,18,-3,251:15)
Block(5,18,-2,2)
Block(5,18,-1,2)
Block(5,18,0,2)
Block(5,18,1,2)
Block(5,18,2,159:15)
Block(5,18,3,251:15)
Block(6,0,-7,251:15)
Block(6,0,-6,159:15)
Block(6,0,-5,159:15)
Block(6,0,-4,159:15)
Block(6,0,-3,251:15)
Block(6,0,-2,159:15)
Block(6,0,-1,159:15)
Block(6,0,0,251:15)
Block(6,0,1,251:15)
Block(6,0,2,251:15)
Block(6,0,3,251:15)
Block(6,1,-7,159:15)
Block(6,1,-6,159:15)
Block(6,1,-5,251:15)
Block(6,1,-4,251:15)
Block(6,1,-3,251:15)
Block(6,1,-2,159:15)
Block(6,1,-1,251:15)
Block(6,1,0,159:15)
Block(6,1,1,251:15)
Block(6,1,2,251:15)
Block(6,1,3,159:15)
Block(6,2,-7,159:15)
Block(6,2,-6,159:15)
Block(6,2,-5,251:15)
Block(6,2,-4,251:15)
Block(6,2,-3,251:15)
Block(6,2,-2,251:15)
Block(6,2,-1,251:15)
Block(6,2,0,251:15)
Block(6,2,1,159:15)
Block(6,2,2,159:15)
Block(6,2,3,251:15)
Block(6,3,-7,251:15)
Block(6,3,-6,251:15)
Block(6,3,-5,251:15)
Block(6,3,-4,159:15)
Block(6,3,-3,251:15)
Block(6,3,-2,251:15)
Block(6,3,-1,159:15)
Block(6,3,0,159:15)
Block(6,3,1,159:15)
Block(6,3,2,251:15)
Block(6,3,3,159:15)
Block(6,4,-7,251:15)
Block(6,4,-6,251:15)
Block(6,4,-5,159:15)
Block(6,4,-4,251:15)
Block(6,4,-3,159:15)
Block(6,4,-2,251:15)
Block(6,4,-1,159:15)
Block(6,4,0,251:15)
Block(6,4,1,251:15)
Block(6,4,2,251:15)
Block(6,4,3,159:15)
Block(6,5,-7,251:15)
Block(6,5,-6,251:15)
Block(6,5,-5,251:15)
Block(6,5,-4,159:15)
Block(6,5,-3,251:15)
Block(6,5,-2,159:15)
Block(6,5,-1,159:15)
Block(6,5,0,251:15)
Block(6,5,1,159:15)
Block(6,5,2,251:15)
Block(6,5,3,251:15)
Block(6,6,-7,251:15)
Block(6,6,-6,251:15)
Block(6,6,-5,159:15)
Block(6,6,-4,251:15)
Block(6,6,-3,251:15)
Block(6,6,-2,159:15)
Block(6,6,-1,251:15)
Block(6,6,0,159:15)
Block(6,6,1,159:15)
Block(6,6,2,251:15)
Block(6,6,3,251:15)
Block(6,7,-7,159:15)
Block(6,7,-6,159:15)
Block(6,7,-5,251:15)
Block(6,7,-4,251:15)
Block(6,7,-3,251:15)
Block(6,7,-2,159:15)
Block(6,7,-1,159:15)
Block(6,7,0,159:15)
Block(6,7,1,159:15)
Block(6,7,2,251:15)
Block(6,7,3,251:15)
Block(6,8,-7,251:15)
Block(6,8,-6,251:15)
Block(6,8,-5,159:15)
Block(6,8,-4,251:15)
Block(6,8,-3,251:15)
Block(6,8,-2,159:15)
Block(6,8,-1,251:15)
Block(6,8,0,251:15)
Block(6,8,1,159:15)
Block(6,8,2,159:15)
Block(6,8,3,159:15)
Block(6,9,-7,159:15)
Block(6,9,-6,159:15)
Block(6,9,-5,159:15)
Block(6,9,-4,251:15)
Block(6,9,-3,251:15)
Block(6,9,-2,159:15)
Block(6,9,-1,251:15)
Block(6,9,0,159:15)
Block(6,9,1,251:15)
Block(6,9,2,251:15)
Block(6,9,3,251:15)
Block(6,10,-7,159:15)
Block(6,10,-6,159:15)
Block(6,10,-5,251:15)
Block(6,10,-4,251:15)
Block(6,10,-3,251:15)
Block(6,10,-2,251:15)
Block(6,10,-1,159:15)
Block(6,10,0,251:15)
Block(6,10,1,159:15)
Block(6,10,2,251:15)
Block(6,10,3,159:15)
Block(6,11,-7,159:15)
Block(6,11,-6,159:15)
Block(6,11,-5,251:15)
Block(6,11,-4,251:15)
Block(6,11,-3,159:15)
Block(6,11,-2,251:15)
Block(6,11,-1,159:15)
Block(6,11,0,159:15)
Block(6,11,1,159:15)
Block(6,11,2,251:15)
Block(6,11,3,251:15)
Block(6,12,-7,251:15)
Block(6,12,-6,159:15)
Block(6,12,-5,159:15)
Block(6,12,-4,251:15)
Block(6,12,-3,251:15)
Block(6,12,-2,251:15)
Block(6,12,-1,159:15)
Block(6,12,0,159:15)
Block(6,12,1,251:15)
Block(6,12,2,251:15)
Block(6,12,3,251:7)
Block(6,13,-7,251:15)
Block(6,13,-6,251:15)
Block(6,13,-5,251:15)
Block(6,13,-4,251:15)
Block(6,13,-3,159:15)
Block(6,13,-2,159:15)
Block(6,13,-1,251:15)
Block(6,13,0,159:15)
Block(6,13,1,159:15)
Block(6,13,2,251:15)
Block(6,13,3,251:7)
Block(6,14,-7,251:7)
Block(6,14,-6,159:15)
Block(6,14,-5,251:15)
Block(6,14,-4,251:15)
Block(6,14,-3,159:15)
Block(6,14,-2,251:15)
Block(6,14,-1,251:15)
Block(6,14,0,159:15)
Block(6,14,1,159:15)
Block(6,14,2,251:15)
Block(6,14,3,159:15)
Block(6,15,-7,251:7)
Block(6,15,-6,251:15)
Block(6,15,-5,251:15)
Block(6,15,-4,251:15)
Block(6,15,-3,159:15)
Block(6,15,-2,251:15)
Block(6,15,-1,159:15)
Block(6,15,0,159:15)
Block(6,15,1,159:15)
Block(6,15,2,251:15)
Block(6,15,3,159:15)
Block(6,16,-7,159:15)
Block(6,16,-6,251:15)
Block(6,16,-5,251:15)
Block(6,16,-4,251:15)
Block(6,16,-3,251:15)
Block(6,16,-2,159:15)
Block(6,16,-1,159:15)
Block(6,16,0,159:15)
Block(6,16,1,251:15)
Block(6,16,2,159:15)
Block(6,16,3,251:15)
Block(6,17,-7,159:15)
Block(6,17,-6,159:15)
Block(6,17,-5,251:15)
Block(6,17,-4,159:15)
Block(6,17,-3,159:15)
Block(6,17,-2,159:15)
Block(6,17,-1,251:15)
Block(6,17,0,251:15)
Block(6,17,1,251:15)
Block(6,17,2,251:15)
Block(6,17,3,251:15)
Block(6,18,-7,159:15)
Block(6,18,-6,251:15)
Block(6,18,-5,251:15)
Block(6,18,-4,251:15)
Block(6,18,-3,2)
Block(6,18,-2,2)
Block(6,18,-1,2)
Block(6,18,0,2)
Block(6,18,1,251:15)
Block(6,18,2,251:15)
Block(6,18,3,251:15)
Block(7,0,-7,251:15)
Block(7,0,-6,251:15)
Block(7,0,-5,251:15)
Block(7,0,-4,159:15)
Block(7,0,-3,251:15)
Block(7,0,-2,159:15)
Block(7,0,-1,251:15)
Block(7,0,0,251:15)
Block(7,0,1,159:15)
Block(7,0,2,251:15)
Block(7,0,3,159:15)
Block(7,0,4,251:15)
Block(7,0,5,159:15)
Block(7,1,-7,159:15)
Block(7,1,-6,159:15)
Block(7,1,-5,251:15)
Block(7,1,-4,251:15)
Block(7,1,-3,159:15)
Block(7,1,-2,159:15)
Block(7,1,-1,251:15)
Block(7,1,0,159:15)
Block(7,1,1,251:15)
Block(7,1,2,251:15)
Block(7,1,3,251:15)
Block(7,1,4,251:15)
Block(7,1,5,159:15)
Block(7,2,-7,251:15)
Block(7,2,-6,159:15)
Block(7,2,-5,159:15)
Block(7,2,-4,159:15)
Block(7,2,-3,159:15)
Block(7,2,-2,159:15)
Block(7,2,-1,251:15)
Block(7,2,0,251:15)
Block(7,2,1,159:15)
Block(7,2,2,159:15)
Block(7,2,3,159:15)
Block(7,2,4,251:15)
Block(7,2,5,159:15)
Block(7,3,-7,159:15)
Block(7,3,-6,159:15)
Block(7,3,-5,159:15)
Block(7,3,-4,251:15)
Block(7,3,-3,251:15)
Block(7,3,-2,251:15)
Block(7,3,-1,159:15)
Block(7,3,0,159:15)
Block(7,3,1,251:15)
Block(7,3,2,251:15)
Block(7,3,3,251:15)
Block(7,3,4,251:15)
Block(7,3,5,159:15)
Block(7,4,-7,251:15)
Block(7,4,-6,159:15)
Block(7,4,-5,251:15)
Block(7,4,-4,251:15)
Block(7,4,-3,159:15)
Block(7,4,-2,251:15)
Block(7,4,-1,159:15)
Block(7,4,0,159:15)
Block(7,4,1,251:15)
Block(7,4,2,251:15)
Block(7,4,3,251:15)
Block(7,4,4,159:15)
Block(7,4,5,251:15)
Block(7,5,-7,251:15)
Block(7,5,-6,159:15)
Block(7,5,-5,159:15)
Block(7,5,-4,159:15)
Block(7,5,-3,159:15)
Block(7,5,-2,251:15)
Block(7,5,-1,251:15)
Block(7,5,0,251:15)
Block(7,5,1,159:15)
Block(7,5,2,159:15)
Block(7,5,3,159:15)
Block(7,5,4,251:15)
Block(7,5,5,159:15)
Block(7,6,-7,251:15)
Block(7,6,-6,251:15)
Block(7,6,-5,251:15)
Block(7,6,-4,159:15)
Block(7,6,-3,251:15)
Block(7,6,-2,251:15)
Block(7,6,-1,159:15)
Block(7,6,0,159:15)
Block(7,6,1,159:15)
Block(7,6,2,159:15)
Block(7,6,3,159:15)
Block(7,6,4,159:15)
Block(7,6,5,159:15)
Block(7,7,-7,159:15)
Block(7,7,-6,159:15)
Block(7,7,-5,159:15)
Block(7,7,-4,159:15)
Block(7,7,-3,251:15)
Block(7,7,-2,251:15)
Block(7,7,-1,251:15)
Block(7,7,0,159:15)
Block(7,7,1,159:15)
Block(7,7,2,251:15)
Block(7,7,3,159:15)
Block(7,7,4,159:15)
Block(7,7,5,251:15)
Block(7,8,-7,159:15)
Block(7,8,-6,251:15)
Block(7,8,-5,159:15)
Block(7,8,-4,159:15)
Block(7,8,-3,251:15)
Block(7,8,-2,159:15)
Block(7,8,-1,251:15)
Block(7,8,0,159:15)
Block(7,8,1,159:15)
Block(7,8,2,251:15)
Block(7,8,3,251:15)
Block(7,8,4,251:15)
Block(7,8,5,159:15)
Block(7,9,-7,251:15)
Block(7,9,-6,159:15)
Block(7,9,-5,159:15)
Block(7,9,-4,159:15)
Block(7,9,-3,159:15)
Block(7,9,-2,251:15)
Block(7,9,-1,251:15)
Block(7,9,0,251:15)
Block(7,9,1,251:15)
Block(7,9,2,159:15)
Block(7,9,3,251:15)
Block(7,9,4,159:15)
Block(7,9,5,251:15)
Block(7,10,-7,159:15)
Block(7,10,-6,251:15)
Block(7,10,-5,159:15)
Block(7,10,-4,251:15)
Block(7,10,-3,159:15)
Block(7,10,-2,159:15)
Block(7,10,-1,159:15)
Block(7,10,0,159:15)
Block(7,10,1,251:15)
Block(7,10,2,251:15)
Block(7,10,3,159:15)
Block(7,10,4,159:15)
Block(7,10,5,251:15)
Block(7,11,-7,159:15)
Block(7,11,-6,159:15)
Block(7,11,-5,159:15)
Block(7,11,-4,159:15)
Block(7,11,-3,251:15)
Block(7,11,-2,251:15)
Block(7,11,-1,251:15)
Block(7,11,0,251:15)
Block(7,11,1,251:15)
Block(7,11,2,159:15)
Block(7,11,3,159:15)
Block(7,11,4,159:15)
Block(7,11,5,251:15)
Block(7,12,-7,159:15)
Block(7,12,-6,159:15)
Block(7,12,-5,159:15)
Block(7,12,-4,251:15)
Block(7,12,-3,159:15)
Block(7,12,-2,251:15)
Block(7,12,-1,251:15)
Block(7,12,0,251:15)
Block(7,12,1,251:15)
Block(7,12,2,251:15)
Block(7,12,3,251:15)
Block(7,12,4,251:7)
Block(7,12,5,251:7)
Block(7,13,-7,251:15)
Block(7,13,-6,159:15)
Block(7,13,-5,251:15)
Block(7,13,-4,251:15)
Block(7,13,-3,159:15)
Block(7,13,-2,251:15)
Block(7,13,-1,159:15)
Block(7,13,0,159:15)
Block(7,13,1,251:15)
Block(7,13,2,251:15)
Block(7,13,3,159:15)
Block(7,13,4,251:7)
Block(7,13,5,251:7)
Block(7,14,-7,251:7)
Block(7,14,-6,251:15)
Block(7,14,-5,159:15)
Block(7,14,-4,159:15)
Block(7,14,-3,159:15)
Block(7,14,-2,251:15)
Block(7,14,-1,251:15)
Block(7,14,0,251:15)
Block(7,14,1,159:15)
Block(7,14,2,251:15)
Block(7,14,3,251:15)
Block(7,14,4,251:15)
Block(7,14,5,159:15)
Block(7,15,-7,251:7)
Block(7,15,-6,159:15)
Block(7,15,-5,251:15)
Block(7,15,-4,159:15)
Block(7,15,-3,159:15)
Block(7,15,-2,159:15)
Block(7,15,-1,251:15)
Block(7,15,0,251:15)
Block(7,15,1,251:15)
Block(7,15,2,251:15)
Block(7,15,3,159:15)
Block(7,15,4,251:15)
Block(7,15,5,251:15)
Block(7,16,-7,251:7)
Block(7,16,-6,159:15)
Block(7,16,-5,159:15)
Block(7,16,-4,159:15)
Block(7,16,-3,159:15)
Block(7,16,-2,251:15)
Block(7,16,-1,159:15)
Block(7,16,0,159:15)
Block(7,16,1,159:15)
Block(7,16,2,159:15)
Block(7,16,3,251:15)
Block(7,16,4,159:15)
Block(7,16,5,251:15)
Block(7,17,-7,159:15)
Block(7,17,-6,159:15)
Block(7,17,-5,159:15)
Block(7,17,-4,251:15)
Block(7,17,-3,251:15)
Block(7,17,-2,251:15)
Block(7,17,-1,159:15)
Block(7,17,0,159:15)
Block(7,17,1,159:15)
Block(7,17,2,159:15)
Block(7,17,3,159:15)
Block(7,17,4,251:15)
Block(7,17,5,251:15)
Block(7,18,-7,159:15)
Block(7,18,-6,159:15)
Block(7,18,-5,251:15)
Block(7,18,-4,2)
Block(7,18,-3,251:15)
Block(7,18,-2,159:15)
Block(7,18,-1,159:15)
Block(7,18,0,251:15)
Block(7,18,1,251:15)
Block(7,18,2,251:15)
Block(7,18,3,159:15)
Block(7,18,4,251:15)
Block(7,18,5,251:15)
Block(7,19,-3,251:15)
Block(7,19,-2,2)
Block(7,19,-1,2)
Block(7,19,0,2)
Block(7,19,1,3:1)
Block(7,19,3,159:15)
Block(7,19,4,251:15)
Block(7,19,5,159:15)
Block(7,20,3,159:15)
Block(7,20,4,159:15)
Block(7,20,5,159:15)
Block(7,21,3,159:15)
Block(7,21,4,159:15)
Block(7,21,5,251:15)
Block(7,22,3,251:15)
Block(7,22,4,251:15)
Block(7,22,5,251:15)
Block(7,23,3,251:7)
Block(7,23,4,251:7)
Block(7,23,5,251:7)
Block(7,24,3,251:7)
Block(7,24,4,251:7)
Block(7,24,5,251:7)
Block(7,25,3,251:15)
Block(7,25,4,251:7)
Block(7,25,5,251:7)
Block(7,26,3,251:15)
Block(7,26,4,159:15)
Block(7,26,5,159:15)
Block(7,27,3,159:15)
Block(7,27,4,251:15)
Block(7,27,5,159:15)


#######################################################################
# +-----------------------------------------------------------------+ #
# |                             ModData                             | #
# +-----------------------------------------------------------------+ #
#######################################################################

# Currently only available for MCW, this feature will be added to OTG+ a.s.a.p.# Use the ModData() tag to include data that other mods can use
# ModData(x,y,z,ModName,DataText)
# Example: ModData(x,y,z,MyCystomNPCMod,SpawnBobHere/WithAPotato/And50Health)
# MCW has some built in ModData commands for basic mob and block spawning.
# These are mostly just a demonstration for mod makers to show how ModData.
# can be used by other mods.
# For mob spawning in MCW use: ModData(x,y,z,TC/MCW,mob/MobType/Count/Persistent/Name)
# mob: Makes MCW recognise this as a mob spawning command.
# MobType: Lower-case, no spaces. Any vanilla mob like dragon, skeleton, wither, villager etc
# Count: The number of mobs to spawn
# Persistent (true/false): Should the mobs never de-spawn? If set to true the mob will get a
# name-tag ingame so you can recognise it.
# Name: A name-tag for the monster/npc.
# Example: ModData(0,0,0,TC/MCW,villager/1/true/Bob)
# For a complete list of possible creatures check the mc forums or the mctcp forums.
# To spawn blocks using ModData use: ModData(x,y,z,TC/MCW,block/material)
# block: Makes MCW recognise this as a block spawning command.
# material: id or text, custom blocks can be added using ModName:MaterialName.
# To send all ModData within a radius in chunks around the player to the specified mod
# use this console command: /mcw GetModData ModName Radius
# ModName: name of the mod, for MCW commands use TC/MCW 
# Radius (optional): Radius in chunks around the player.
# Mod makers can use ModData and the /mcw GetModData command to test IMC communications between MCW
# and their mod.
# Normal users can use it to spawn some mobs and blocks on command!

#######################################################################
# +-----------------------------------------------------------------+ #
# |                             Entities                            | #
# +-----------------------------------------------------------------+ #
#######################################################################

# Entity() spawns an entity instead of a block. The entity is spawned only once when the BO3 is spawned.
# Entities are persistent by default so they don't de-spawn when no player is near, they are only unloaded.
# Usage: Entity(x,y,z,mobName,groupSize,NameTagOrNBTFileName) or Entity(x,y,z,mobName,groupSize)
# Use /tc entities or /otg entities to get a list of entities that can be used as mobName, this includes entities added by other mods.
# NameTagOrNBTFileName can be either a nametag for the mob or an nbt file (such as mymobinfo.nbt or mymobinfo.txt).
# When using a text file you can use the same mob spawning parameters used with the /summon command to equip the
# entity and give it custom attributes etc. You can copy the DATA part of a summon command including surrounding
# curly braces to a .txt file, for instance for: "/summon Skeleton x y z {DATA}"

#######################################################################
# +-----------------------------------------------------------------+ #
# |                             Spawners                            | #
# +-----------------------------------------------------------------+ #
#######################################################################

# Currently only available for MCW, this feature will be added to OTG+ a.s.a.p.# Spawner(x,y,z,EntityType,count,interval,chance,max,despawnTime,velocityX,velocityY,velocityZ,yaw,pitch) tag for BO3's,
# works just like the Block() tag and is spawned when the BO3 is spawned. Spawners are invisible ingame but can be blocked
# up with a solid or liquid block (depending on if the entity being spawned can spawn in those blocks) to prevent entities
# from spawning. A spawner tries to spawn <count> number of <entityType> each <interval> seconds, with each entity having
# a spawn chance of <chance>%. The spawner can only spawn an entity if there are not more than <max> of the same EntityType
# in the surrounding chunks (3x3 chunk area centered on the spawner). If an entity is assigned a <despawnTime> in seconds
# then the entity will automatically be despawned after the specified time. Entities spawned using a Spawner will have the
# same light level requirements as they do when they normally spawn in the world, so most monsters only spawn in the dark.
# A spawner will not spawn if the spawn location is blocked by another entity, it can however spawn multiple mobs at once.
# The last 6 parameters are optional and are set to 0 by default (despawnTime,velocityX,velocityY,velocityZ,yaw,pitch), you
# only need to add as many of those parameters as you need. So for instance all of these work: "Spawner(0,0,0,Arrow,1,5,100,5)"
# "Spawner(0,0,0,Arrow,1,5,100,5, 1,0,1)" "Spawner(0,0,0,Arrow,1,5,100,5,1,0,1,180,180)"
# Use the /mcw entities or /otg entities console command (ops only) to see a list of available entityTypes.

#######################################################################
# +-----------------------------------------------------------------+ #
# |                             Particles                           | #
# +-----------------------------------------------------------------+ #
#######################################################################

# Currently only available for MCW, this feature will be added to OTG+ a.s.a.p.# Continually spawns particles in the world at the specified coordinates, interval and velocity.
# For a list of particles use /mcw particles or /otg particles.
# When no velocity is supplied a small random velocity is used.
# Particles will disappear if a solid block is placed on them for at least one second.
# Usage1: Particle(x, y , z, particleName, interval
# Usage2: Particle(x, y , z, particleName, interval, velocityX, velocityY, velocityZ)

#######################################################################
# +-----------------------------------------------------------------+ #
# |                            BO3 checks                           | #
# +-----------------------------------------------------------------+ #
#######################################################################

# This settings is disabled for MCW/OTG+.

#######################################################################
# +-----------------------------------------------------------------+ #
# |                             Branches                            | #
# +-----------------------------------------------------------------+ #
#######################################################################

# Check the otg docs, mctcp forums, the mc forums and PeeGee85 YT channel for.
# Documentation and tutorials for the branching features.
# Branch(x,y,z,isBranchEnding,branchName,rotation,chance,branchLength)
# branchName - filename of the object to spawn (without extension).
# rotation - NORTH, SOUTH, EAST or WEST.
# chance - Chance to spawn between 0 and 100

# WeightedBranch(x,y,z,isBranchEnding,branchName,rotation,chance,branchLength,[anotherBranchName,rotation,chance,branchLength[,...]],maxChanceOutOf)
# maxChanceOutOf - The chance all branches have to spawn out of, assumed to be 100 when left blank
# Example: WeightedBranch(0,0,0,true,RandomInterior1,NORTH,20,0,RandomInterior2,NORTH,20,0,RandomInterior3,NORTH,20,0,RandomInterior4,NORTH,20,0)

Branch(16,0,0,true,BasaltColumnSmall1C1R2,NORTH,100,0)
Branch(0,0,16,true,BasaltColumnSmall1C0R3,NORTH,100,0)
