

BranchFrequencyGroup: CanOverride:0

CanOverride: true

SmoothRadius: -1

OverrideChildSettings: false

ReplaceAbove:
ReplaceBelow:

MustBeInside: VillageGeneratorStructurePlaceHolder, VillageGeneratorStructuresDelay, VillageGeneratorStructuresDelay2, VillageGeneratorStructuresDelay3, VillageGeneratorStructuresDelay4, VillageGeneratorStructuresDelay5, VillageGeneratorStructuresDelay6, VillageGeneratorStructuresDelay7, VillageGeneratorStructuresDelay8, VillageGeneratorStructuresDelay9, VillageGeneratorStructuresDelay10

Block(-8,0,-7,3)
Block(-8,0,-6,3)
Block(-8,0,-5,3)
Block(-8,0,-4,3)
Block(-8,0,-3,3)
Block(-8,0,-2,3)
Block(-8,0,-1,3)
Block(-8,0,0,3)
Block(-8,0,1,3)
Block(-8,0,2,3)
Block(-8,0,3,3)
Block(-8,0,4,3)
Block(-8,0,5,3)
Block(-8,1,-7,2)
Block(-8,1,-6,2)
Block(-8,1,-5,2)
Block(-8,1,-4,2)
Block(-8,1,-3,2)
Block(-8,1,-2,2)
Block(-8,1,-1,2)
Block(-8,1,0,2)
Block(-8,1,1,2)
Block(-8,1,2,2)
Block(-8,1,3,2)
Block(-8,1,4,2)
Block(-8,1,5,2)
Block(-8,2,-7,31:1)
Block(-8,2,-6,31:1)
Block(-8,2,-5,31:1)
Block(-8,2,-4,31:1)
Block(-8,2,-1,31:1)
Block(-8,2,1,31:1)
Block(-8,2,2,37)
Block(-7,0,-7,3)
Block(-7,0,-6,3)
Block(-7,0,-5,3)
Block(-7,0,-4,3)
Block(-7,0,-3,3)
Block(-7,0,-2,3)
Block(-7,0,-1,3)
Block(-7,0,0,3)
Block(-7,0,1,3)
Block(-7,0,2,3)
Block(-7,0,3,3)
Block(-7,0,4,3)
Block(-7,0,5,3)
Block(-7,1,-7,2)
Block(-7,1,-6,2)
Block(-7,1,-5,2)
Block(-7,1,-4,2)
Block(-7,1,-3,2)
Block(-7,1,-2,3:2)
Block(-7,1,-1,2)
Block(-7,1,0,2)
Block(-7,1,1,2)
Block(-7,1,2,2)
Block(-7,1,3,2)
Block(-7,1,4,2)
Block(-7,1,5,2)
Block(-7,2,-7,31:1)
Block(-7,2,-6,31:1)
Block(-7,2,-5,31:1)
Block(-7,2,-4,38:6)
Block(-7,2,-3,31:1)
Block(-7,2,-1,31:1)
Block(-7,2,0,31:1)
Block(-7,2,1,31:1)
Block(-7,2,2,31:1)
Block(-7,2,3,31:1)
Block(-7,2,5,38)
Block(-6,0,-7,3)
Block(-6,0,-6,3)
Block(-6,0,-5,3)
Block(-6,0,-4,3)
Block(-6,0,-3,3)
Block(-6,0,-2,3)
Block(-6,0,-1,3)
Block(-6,0,0,3)
Block(-6,0,1,3)
Block(-6,0,2,3)
Block(-6,0,3,3)
Block(-6,0,4,3)
Block(-6,0,5,3)
Block(-6,1,-7,2)
Block(-6,1,-6,3:2)
Block(-6,1,-5,2)
Block(-6,1,-4,2)
Block(-6,1,-3,2)
Block(-6,1,-2,2)
Block(-6,1,-1,2)
Block(-6,1,0,2)
Block(-6,1,1,3:2)
Block(-6,1,2,2)
Block(-6,1,3,2)
Block(-6,1,4,2)
Block(-6,1,5,2)
Block(-6,2,-7,31:1)
Block(-6,2,-5,31:1)
Block(-6,2,-4,31:1)
Block(-6,2,-3,31:1)
Block(-6,2,-2,175:2)
Block(-6,2,-1,31:1)
Block(-6,2,0,38:8)
Block(-6,2,2,31:1)
Block(-6,2,3,31:1)
Block(-6,3,-2,175:8)
Block(-5,0,-7,3)
Block(-5,0,-6,3)
Block(-5,0,-5,3)
Block(-5,0,-4,3)
Block(-5,0,-3,3)
Block(-5,0,-2,3)
Block(-5,0,-1,3)
Block(-5,0,0,3)
Block(-5,0,1,3)
Block(-5,0,2,3)
Block(-5,0,3,3)
Block(-5,0,4,3)
Block(-5,0,5,3)
Block(-5,1,-7,3)
Block(-5,1,-6,2)
Block(-5,1,-5,3)
Block(-5,1,-4,2)
Block(-5,1,-3,3)
Block(-5,1,-2,2)
Block(-5,1,-1,3)
Block(-5,1,0,2)
Block(-5,1,1,3)
Block(-5,1,2,2)
Block(-5,1,3,2)
Block(-5,1,4,2)
Block(-5,1,5,2)
Block(-5,2,-7,109:4)
Block(-5,2,-6,109)
Block(-5,2,-5,98:3)
Block(-5,2,-4,109)
Block(-5,2,-3,109:4)
Block(-5,2,-2,109)
Block(-5,2,-1,98:3)
Block(-5,2,0,109)
Block(-5,2,1,98)
Block(-5,2,2,31:1)
Block(-5,2,3,31:1)
Block(-5,3,-7,162)
Block(-5,3,-6,101)
Block(-5,3,-5,101)
Block(-5,3,-4,101)
Block(-5,3,-3,162)
Block(-5,3,-2,101)
Block(-5,3,-1,101)
Block(-5,3,0,101)
Block(-5,3,1,162)
Block(-5,4,-7,98)
Block(-5,4,-6,101)
Block(-5,4,-5,101)
Block(-5,4,-4,101)
Block(-5,4,-3,98:1)
Block(-5,4,-2,101)
Block(-5,4,-1,101)
Block(-5,4,0,101)
Block(-5,4,1,98:1)
Block(-5,5,-7,139)
Block(-5,5,-6,44:5)
Block(-5,5,-5,98:3)
Block(-5,5,-4,44:5)
Block(-5,5,-3,139:1)
Block(-5,5,-2,44:5)
Block(-5,5,-1,98:3)
Block(-5,5,0,44:5)
Block(-5,5,1,139:1)
Block(-4,0,-7,3)
Block(-4,0,-6,3)
Block(-4,0,-5,3)
Block(-4,0,-4,3)
Block(-4,0,-3,3)
Block(-4,0,-2,3)
Block(-4,0,-1,3)
Block(-4,0,0,3)
Block(-4,0,1,3)
Block(-4,0,2,3)
Block(-4,0,3,3)
Block(-4,0,4,3)
Block(-4,0,5,3)
Block(-4,1,-7,3)
Block(-4,1,-6,3:2)
Block(-4,1,-5,2)
Block(-4,1,-4,3:2)
Block(-4,1,-3,3:2)
Block(-4,1,-2,3)
Block(-4,1,-1,2)
Block(-4,1,0,3:2)
Block(-4,1,1,2)
Block(-4,1,2,2)
Block(-4,1,3,3:2)
Block(-4,1,4,2)
Block(-4,1,5,2)
Block(-4,2,-7,2)
Block(-4,2,-6,175:2)
Block(-4,2,-4,175:2)
Block(-4,2,-2,2)
Block(-4,2,-1,175:2)
Block(-4,2,1,109:3)
Block(-4,2,2,31:1)
Block(-4,2,4,31:1)
Block(-4,3,-7,175:2)
Block(-4,3,-6,175:8)
Block(-4,3,-4,175:8)
Block(-4,3,-1,175:11)
Block(-4,3,1,101)
Block(-4,4,-7,175:8)
Block(-4,4,1,101)
Block(-4,5,1,44:5)
Block(-3,0,-7,3)
Block(-3,0,-6,3)
Block(-3,0,-5,3)
Block(-3,0,-4,3)
Block(-3,0,-3,3)
Block(-3,0,-2,3)
Block(-3,0,-1,3)
Block(-3,0,0,3)
Block(-3,0,1,3)
Block(-3,0,2,3)
Block(-3,0,3,3)
Block(-3,0,4,3)
Block(-3,0,5,3)
Block(-3,1,-7,2)
Block(-3,1,-6,2)
Block(-3,1,-5,88)
Block(-3,1,-4,2)
Block(-3,1,-3,3:2)
Block(-3,1,-2,2)
Block(-3,1,-1,3)
Block(-3,1,0,2)
Block(-3,1,1,3)
Block(-3,1,2,2)
Block(-3,1,3,2)
Block(-3,1,4,2)
Block(-3,1,5,2)
Block(-3,2,-7,109:1)
Block(-3,2,-6,31:1)
Block(-3,2,-5,109:5)
Block(-3,2,-3,98:1)
Block(-3,2,-2,175:3)
Block(-3,2,-1,98:3)
Block(-3,2,1,98:3)
Block(-3,2,2,31:1)
Block(-3,2,3,31:1)
Block(-3,2,4,38:8)
Block(-3,3,-7,109)
Block(-3,3,-5,98:3)
Block(-3,3,-3,139)
Block(-3,3,-2,175:11)
Block(-3,3,1,101)
Block(-3,4,-5,44:5)
Block(-3,4,-3,139:1)
Block(-3,4,1,101)
Block(-3,5,-4,139)
Block(-3,5,-3,139)
Block(-3,5,-2,139:1)
Block(-3,5,1,98:3)
Block(-3,6,-3,139)
Block(-2,0,-7,3)
Block(-2,0,-6,3)
Block(-2,0,-5,3)
Block(-2,0,-4,3)
Block(-2,0,-3,3)
Block(-2,0,-2,3)
Block(-2,0,-1,3)
Block(-2,0,0,3)
Block(-2,0,1,3)
Block(-2,0,2,3)
Block(-2,0,3,3)
Block(-2,0,4,3)
Block(-2,0,5,3)
Block(-2,1,-7,88)
Block(-2,1,-6,2)
Block(-2,1,-5,88)
Block(-2,1,-4,2)
Block(-2,1,-3,88)
Block(-2,1,-2,3:2)
Block(-2,1,-1,88)
Block(-2,1,0,3)
Block(-2,1,1,2)
Block(-2,1,2,3:2)
Block(-2,1,3,2)
Block(-2,1,4,2)
Block(-2,1,5,2)
Block(-2,2,-6,31:1)
Block(-2,2,-4,175:2)
Block(-2,2,-3,68:5,1-Sign.nbt)
Block(-2,2,-1,68:5,2-Sign.nbt)
Block(-2,2,0,2)
Block(-2,2,1,109:3)
Block(-2,2,3,31:1)
Block(-2,3,-7,68:5,3-Sign.nbt)
Block(-2,3,-5,68:5,4-Sign.nbt)
Block(-2,3,-4,175:11)
Block(-2,3,0,175:2)
Block(-2,3,1,101)
Block(-2,4,0,175:11)
Block(-2,4,1,101)
Block(-2,5,1,44:5)
Block(-1,0,-7,3)
Block(-1,0,-6,3)
Block(-1,0,-5,3)
Block(-1,0,-4,3)
Block(-1,0,-3,3)
Block(-1,0,-2,3)
Block(-1,0,-1,3)
Block(-1,0,0,3)
Block(-1,0,1,3)
Block(-1,0,2,3)
Block(-1,0,3,3)
Block(-1,0,4,3)
Block(-1,0,5,3)
Block(-1,1,-7,88)
Block(-1,1,-6,3:2)
Block(-1,1,-5,88)
Block(-1,1,-4,4)
Block(-1,1,-3,88)
Block(-1,1,-2,2)
Block(-1,1,-1,88)
Block(-1,1,0,3:2)
Block(-1,1,1,3)
Block(-1,1,2,2)
Block(-1,1,3,2)
Block(-1,1,4,2)
Block(-1,1,5,2)
Block(-1,2,-6,140,5-FlowerPot.nbt)
Block(-1,2,-4,3:2)
Block(-1,2,-3,140:4,6-FlowerPot.nbt)
Block(-1,2,-2,175:2)
Block(-1,2,1,109:7)
Block(-1,2,2,175:2)
Block(-1,2,5,31:1)
Block(-1,3,-2,175:11)
Block(-1,3,1,162)
Block(-1,3,2,175:8)
Block(-1,4,1,98)
Block(-1,5,1,139)
Block(0,0,-7,3)
Block(0,0,-6,3)
Block(0,0,-5,3)
Block(0,0,-4,3)
Block(0,0,-3,3)
Block(0,0,-2,3)
Block(0,0,-1,3)
Block(0,0,0,3)
Block(0,0,1,3)
Block(0,0,2,3)
Block(0,0,3,3)
Block(0,0,4,3)
Block(0,0,5,3)
Block(0,1,-7,2)
Block(0,1,-6,13)
Block(0,1,-5,48)
Block(0,1,-4,13)
Block(0,1,-3,48)
Block(0,1,-2,13)
Block(0,1,-1,2)
Block(0,1,0,4)
Block(0,1,1,2)
Block(0,1,2,3:2)
Block(0,1,3,3:2)
Block(0,1,4,2)
Block(0,1,5,2)
Block(0,2,-7,175:2)
Block(0,2,-4,140:5,9-FlowerPot.nbt)
Block(0,2,-1,175:3)
Block(0,2,1,109:3)
Block(0,2,4,38)
Block(0,2,5,31:1)
Block(0,3,-7,175:9)
Block(0,3,-1,175:10)
Block(0,3,1,101)
Block(0,4,1,101)
Block(0,5,1,44:5)
Block(1,0,-7,3)
Block(1,0,-6,3)
Block(1,0,-5,3)
Block(1,0,-4,3)
Block(1,0,-3,3)
Block(1,0,-2,3)
Block(1,0,-1,3)
Block(1,0,0,3)
Block(1,0,1,3)
Block(1,0,2,3)
Block(1,0,3,3)
Block(1,0,4,3)
Block(1,0,5,3)
Block(1,1,-7,1)
Block(1,1,-6,4)
Block(1,1,-5,13)
Block(1,1,-4,2)
Block(1,1,-3,1)
Block(1,1,-2,4)
Block(1,1,-1,1)
Block(1,1,0,3)
Block(1,1,1,3)
Block(1,1,2,3:2)
Block(1,1,3,2)
Block(1,1,4,2)
Block(1,1,5,2)
Block(1,2,-4,175:2)
Block(1,2,0,2)
Block(1,2,1,98:3)
Block(1,2,3,31:1)
Block(1,2,4,31:1)
Block(1,3,-4,175:10)
Block(1,3,1,101)
Block(1,4,1,101)
Block(1,5,1,98:3)
Block(2,0,-7,3)
Block(2,0,-6,3)
Block(2,0,-5,3)
Block(2,0,-4,3)
Block(2,0,-3,3)
Block(2,0,-2,3)
Block(2,0,-1,3)
Block(2,0,0,3)
Block(2,0,1,3)
Block(2,0,2,3)
Block(2,0,3,3)
Block(2,0,4,3)
Block(2,0,5,3)
Block(2,1,-7,98)
Block(2,1,-6,2)
Block(2,1,-5,88)
Block(2,1,-4,1)
Block(2,1,-3,88)
Block(2,1,-2,13)
Block(2,1,-1,2)
Block(2,1,0,13)
Block(2,1,1,2)
Block(2,1,2,2)
Block(2,1,3,2)
Block(2,1,4,2)
Block(2,1,5,2)
Block(2,2,-7,98:2)
Block(2,2,-6,175:2)
Block(2,2,-1,31:2)
Block(2,2,1,109:3)
Block(2,2,2,31:1)
Block(2,2,3,31:1)
Block(2,2,4,175:2)
Block(2,2,5,31:1)
Block(2,3,-7,140,14-FlowerPot.nbt)
Block(2,3,-6,175:8)
Block(2,3,1,101)
Block(2,3,4,175:8)
Block(2,4,1,101)
Block(2,5,1,44:5)
Block(3,0,-7,3)
Block(3,0,-6,3)
Block(3,0,-5,3)
Block(3,0,-4,3)
Block(3,0,-3,3)
Block(3,0,-2,3)
Block(3,0,-1,3)
Block(3,0,0,3)
Block(3,0,1,3)
Block(3,0,2,3)
Block(3,0,3,3)
Block(3,0,4,3)
Block(3,0,5,3)
Block(3,1,-7,98)
Block(3,1,-6,2)
Block(3,1,-5,88)
Block(3,1,-4,2)
Block(3,1,-3,88)
Block(3,1,-2,48)
Block(3,1,-1,13)
Block(3,1,0,1)
Block(3,1,1,3)
Block(3,1,2,2)
Block(3,1,3,3:2)
Block(3,1,4,2)
Block(3,1,5,2)
Block(3,2,-7,98)
Block(3,2,-6,175:2)
Block(3,2,-3,68:4,15-Sign.nbt)
Block(3,2,1,98:1)
Block(3,2,2,31:1)
Block(3,2,4,31:1)
Block(3,2,5,31:1)
Block(3,3,-7,68:4,16-Sign.nbt)
Block(3,3,-6,175:9)
Block(3,3,-5,68:4,17-Sign.nbt)
Block(3,3,1,98:2)
Block(3,4,1,98)
Block(3,5,1,109)
Block(4,0,-7,3)
Block(4,0,-6,3)
Block(4,0,-5,3)
Block(4,0,-4,3)
Block(4,0,-3,3)
Block(4,0,-2,3)
Block(4,0,-1,3)
Block(4,0,0,3)
Block(4,0,1,3)
Block(4,0,2,3)
Block(4,0,3,3)
Block(4,0,4,3)
Block(4,0,5,3)
Block(4,1,-7,3)
Block(4,1,-6,2)
Block(4,1,-5,2)
Block(4,1,-4,2)
Block(4,1,-3,3)
Block(4,1,-2,1)
Block(4,1,-1,13)
Block(4,1,0,48)
Block(4,1,1,2)
Block(4,1,2,3:2)
Block(4,1,3,2)
Block(4,1,4,2)
Block(4,1,5,2)
Block(4,2,-7,98:1)
Block(4,2,-5,109)
Block(4,2,-4,175:3)
Block(4,2,-3,98:2)
Block(4,2,-1,2)
Block(4,2,1,175:2)
Block(4,2,3,31:1)
Block(4,2,4,31:1)
Block(4,2,5,31:1)
Block(4,3,-7,98:3)
Block(4,3,-5,109:1)
Block(4,3,-4,175:11)
Block(4,3,-3,44:5)
Block(4,3,1,175:11)
Block(4,5,1,109:5)
Block(4,6,1,109)
Block(5,0,-7,3)
Block(5,0,-6,3)
Block(5,0,-5,3)
Block(5,0,-4,3)
Block(5,0,-3,3)
Block(5,0,-2,3)
Block(5,0,-1,3)
Block(5,0,0,3)
Block(5,0,1,3)
Block(5,0,2,3)
Block(5,0,3,3)
Block(5,0,4,3)
Block(5,0,5,3)
Block(5,1,-7,4)
Block(5,1,-6,1)
Block(5,1,-5,13)
Block(5,1,-4,1)
Block(5,1,-3,2)
Block(5,1,-2,13)
Block(5,1,-1,1)
Block(5,1,0,4)
Block(5,1,1,13)
Block(5,1,2,2)
Block(5,1,3,2)
Block(5,1,4,2)
Block(5,1,5,2)
Block(5,2,-3,31:2)
Block(5,2,2,38:3)
Block(5,2,3,31:1)
Block(5,2,4,31:1)
Block(5,2,5,31:1)
Block(5,6,1,98:3)
Block(6,0,-7,3)
Block(6,0,-6,3)
Block(6,0,-5,3)
Block(6,0,-4,3)
Block(6,0,-3,3)
Block(6,0,-2,3)
Block(6,0,-1,3)
Block(6,0,0,3)
Block(6,0,1,3)
Block(6,0,2,3)
Block(6,0,3,3)
Block(6,0,4,3)
Block(6,0,5,3)
Block(6,1,-7,1)
Block(6,1,-6,13)
Block(6,1,-5,2)
Block(6,1,-4,2)
Block(6,1,-3,1)
Block(6,1,-2,4)
Block(6,1,-1,48)
Block(6,1,0,13)
Block(6,1,1,2)
Block(6,1,2,2)
Block(6,1,3,2)
Block(6,1,4,2)
Block(6,1,5,2)
Block(6,2,-4,18:14)
Block(6,2,1,31:1)
Block(6,2,2,38:4)
Block(6,2,3,31:1)
Block(6,2,4,31:1)
Block(6,2,5,31:1)
Block(6,5,1,109:4)
Block(6,6,1,109:1)
Block(7,0,-7,3)
Block(7,0,-6,3)
Block(7,0,-5,3)
Block(7,0,-4,3)
Block(7,0,-3,3)
Block(7,0,-2,3)
Block(7,0,-1,3)
Block(7,0,0,3)
Block(7,0,1,3)
Block(7,0,2,3)
Block(7,0,3,3)
Block(7,0,4,3)
Block(7,0,5,3)
Block(7,1,-7,2)
Block(7,1,-6,3:2)
Block(7,1,-5,1)
Block(7,1,-4,13)
Block(7,1,-3,4)
Block(7,1,-2,3)
Block(7,1,-1,2)
Block(7,1,0,3)
Block(7,1,1,3)
Block(7,1,2,2)
Block(7,1,3,3:2)
Block(7,1,4,2)
Block(7,1,5,2)
Block(7,2,-2,2)
Block(7,2,-1,175:2)
Block(7,2,0,3:2)
Block(7,2,1,98:2)
Block(7,2,4,31:1)
Block(7,2,5,31:1)
Block(7,3,-2,175:2)
Block(7,3,-1,175:11)
Block(7,3,1,98:1)
Block(7,4,-2,175:11)
Block(7,4,1,98:2)
Block(7,5,1,109:1)

Branch(16,0,0,true,graveyardC1R1,NORTH,100,0)
