

BranchFrequencyGroup: CanOverride:0

CanOverride: true

SmoothRadius: -1

OverrideChildSettings: false

ReplaceAbove:
ReplaceBelow:

MustBeInside: VillageGeneratorStructurePlaceHolder, VillageGeneratorStructuresDelay, VillageGeneratorStructuresDelay2, VillageGeneratorStructuresDelay3, VillageGeneratorStructuresDelay4, VillageGeneratorStructuresDelay5, VillageGeneratorStructuresDelay6, VillageGeneratorStructuresDelay7, VillageGeneratorStructuresDelay8, VillageGeneratorStructuresDelay9, VillageGeneratorStructuresDelay10

Block(-8,0,-7,3)
Block(-8,0,-6,3)
Block(-8,0,-5,3)
Block(-8,0,-4,3)
Block(-8,0,-3,3)
Block(-8,0,-2,3)
Block(-8,0,-1,3)
Block(-8,0,0,3)
Block(-8,0,1,3)
Block(-8,0,2,3)
Block(-8,0,3,3)
Block(-8,0,4,3)
Block(-8,0,5,3)
Block(-8,0,6,3)
Block(-8,0,7,3)
Block(-8,0,8,3)
Block(-8,1,-7,2)
Block(-8,1,-6,2)
Block(-8,1,-5,2)
Block(-8,1,-4,3:2)
Block(-8,1,-3,2)
Block(-8,1,-2,3:2)
Block(-8,1,-1,3)
Block(-8,1,0,88)
Block(-8,1,1,88)
Block(-8,1,2,48)
Block(-8,1,3,1)
Block(-8,1,4,4)
Block(-8,1,5,88)
Block(-8,1,6,88)
Block(-8,1,7,3)
Block(-8,1,8,88)
Block(-8,2,-6,37)
Block(-8,2,-5,31:1)
Block(-8,2,-3,109:2)
Block(-8,2,-2,175:2)
Block(-8,2,-1,98:3)
Block(-8,2,0,68:3,18-Sign.nbt)
Block(-8,2,6,68:2,19-Sign.nbt)
Block(-8,2,7,98:3)
Block(-8,2,8,109:7)
Block(-8,3,-3,101)
Block(-8,3,-2,175:9)
Block(-8,3,-1,139:1)
Block(-8,3,7,44:5)
Block(-8,3,8,98:3)
Block(-8,4,-3,101)
Block(-8,4,-1,139)
Block(-8,4,8,44:5)
Block(-8,5,-3,44:5)
Block(-8,5,-1,139)
Block(-8,6,8,18:14)
Block(-8,7,7,18:6)
Block(-8,7,8,17)
Block(-8,8,8,18:14)
Block(-7,0,-7,3)
Block(-7,0,-6,3)
Block(-7,0,-5,3)
Block(-7,0,-4,3)
Block(-7,0,-3,3)
Block(-7,0,-2,3)
Block(-7,0,-1,3)
Block(-7,0,0,3)
Block(-7,0,1,3)
Block(-7,0,2,3)
Block(-7,0,3,3)
Block(-7,0,4,3)
Block(-7,0,5,3)
Block(-7,0,6,3)
Block(-7,0,7,3)
Block(-7,0,8,3)
Block(-7,1,-7,2)
Block(-7,1,-6,2)
Block(-7,1,-5,2)
Block(-7,1,-4,2)
Block(-7,1,-3,3)
Block(-7,1,-2,3:2)
Block(-7,1,-1,2)
Block(-7,1,0,2)
Block(-7,1,1,2)
Block(-7,1,2,2)
Block(-7,1,3,13)
Block(-7,1,4,1)
Block(-7,1,5,3)
Block(-7,1,6,3:2)
Block(-7,1,7,2)
Block(-7,1,8,3:2)
Block(-7,2,-6,31:1)
Block(-7,2,-5,31:1)
Block(-7,2,-4,31:1)
Block(-7,2,-3,98:3)
Block(-7,2,-1,31:1)
Block(-7,2,0,31:1)
Block(-7,2,1,175:2)
Block(-7,2,2,31:1)
Block(-7,2,4,18:6)
Block(-7,2,5,2)
Block(-7,3,-3,101)
Block(-7,3,1,175:9)
Block(-7,4,-3,101)
Block(-7,4,-1,139:1)
Block(-7,4,7,139:1)
Block(-7,5,-3,98:3)
Block(-7,6,7,18:6)
Block(-7,6,8,17)
Block(-6,0,-7,3)
Block(-6,0,-6,3)
Block(-6,0,-5,3)
Block(-6,0,-4,3)
Block(-6,0,-3,3)
Block(-6,0,-2,3)
Block(-6,0,-1,3)
Block(-6,0,0,3)
Block(-6,0,1,3)
Block(-6,0,2,3)
Block(-6,0,3,3)
Block(-6,0,4,3)
Block(-6,0,5,3)
Block(-6,0,6,3)
Block(-6,0,7,3)
Block(-6,0,8,3)
Block(-6,1,-7,2)
Block(-6,1,-6,2)
Block(-6,1,-5,3:2)
Block(-6,1,-4,3:2)
Block(-6,1,-3,2)
Block(-6,1,-2,2)
Block(-6,1,-1,3:2)
Block(-6,1,0,98)
Block(-6,1,1,98)
Block(-6,1,2,13)
Block(-6,1,3,1)
Block(-6,1,4,48)
Block(-6,1,5,88)
Block(-6,1,6,88)
Block(-6,1,7,3)
Block(-6,1,8,3)
Block(-6,2,-3,109:2)
Block(-6,2,-2,175:3)
Block(-6,2,-1,109:6)
Block(-6,2,0,98:1)
Block(-6,2,1,98:1)
Block(-6,2,6,68:2,22-Sign.nbt)
Block(-6,2,7,98:1)
Block(-6,2,8,2)
Block(-6,3,-3,101)
Block(-6,3,-2,175:9)
Block(-6,3,-1,98:3)
Block(-6,3,0,68:3,23-Sign.nbt)
Block(-6,3,7,139:1)
Block(-6,4,-3,101)
Block(-6,4,7,139:1)
Block(-6,5,-3,44:5)
Block(-6,5,7,139)
Block(-6,6,8,18:14)
Block(-6,7,7,17)
Block(-6,8,7,18:6)
Block(-5,0,-7,3)
Block(-5,0,-6,3)
Block(-5,0,-5,3)
Block(-5,0,-4,3)
Block(-5,0,-3,3)
Block(-5,0,-2,3)
Block(-5,0,-1,3)
Block(-5,0,0,3)
Block(-5,0,1,3)
Block(-5,0,2,3)
Block(-5,0,3,3)
Block(-5,0,4,3)
Block(-5,0,5,3)
Block(-5,0,6,3)
Block(-5,0,7,3)
Block(-5,0,8,3)
Block(-5,1,-7,2)
Block(-5,1,-6,2)
Block(-5,1,-5,2)
Block(-5,1,-4,3:2)
Block(-5,1,-3,3)
Block(-5,1,-2,3:2)
Block(-5,1,-1,2)
Block(-5,1,0,2)
Block(-5,1,1,2)
Block(-5,1,2,1)
Block(-5,1,3,48)
Block(-5,1,4,1)
Block(-5,1,5,3:2)
Block(-5,1,6,2)
Block(-5,1,7,17:8)
Block(-5,1,8,3:2)
Block(-5,2,-7,31:1)
Block(-5,2,-3,109:6)
Block(-5,2,-2,175:2)
Block(-5,2,0,31:2)
Block(-5,2,1,140:6,25-FlowerPot.nbt)
Block(-5,2,5,140,26-FlowerPot.nbt)
Block(-5,2,8,31:1)
Block(-5,3,-3,162)
Block(-5,3,-2,175:9)
Block(-5,4,-3,98:1)
Block(-5,4,7,139)
Block(-5,5,-3,139:1)
Block(-5,7,7,18:6)
Block(-4,0,-7,3)
Block(-4,0,-6,3)
Block(-4,0,-5,3)
Block(-4,0,-4,3)
Block(-4,0,-3,3)
Block(-4,0,-2,3)
Block(-4,0,-1,3)
Block(-4,0,0,3)
Block(-4,0,1,3)
Block(-4,0,2,3)
Block(-4,0,3,3)
Block(-4,0,4,3)
Block(-4,0,5,3)
Block(-4,0,6,3)
Block(-4,0,7,3)
Block(-4,0,8,88)
Block(-4,1,-7,2)
Block(-4,1,-6,2)
Block(-4,1,-5,2)
Block(-4,1,-4,2)
Block(-4,1,-3,2)
Block(-4,1,-2,3)
Block(-4,1,-1,3)
Block(-4,1,0,88)
Block(-4,1,1,88)
Block(-4,1,2,2)
Block(-4,1,3,13)
Block(-4,1,4,48)
Block(-4,1,5,2)
Block(-4,1,6,88)
Block(-4,1,7,3)
Block(-4,1,8,3)
Block(-4,2,-6,31:1)
Block(-4,2,-5,175:2)
Block(-4,2,-4,38:3)
Block(-4,2,-3,109:2)
Block(-4,2,-2,3:2)
Block(-4,2,-1,98:3)
Block(-4,2,0,68:3,29-Sign.nbt)
Block(-4,2,2,31:2)
Block(-4,2,5,109:6)
Block(-4,2,6,98:2)
Block(-4,2,7,98:1)
Block(-4,2,8,98)
Block(-4,3,-5,175:8)
Block(-4,3,-3,101)
Block(-4,3,-1,140:7,33-FlowerPot.nbt)
Block(-4,3,6,68:2,34-Sign.nbt)
Block(-4,3,7,98:1)
Block(-4,4,-3,101)
Block(-4,5,-3,44:5)
Block(-4,7,7,18:6)
Block(-4,7,8,17)
Block(-3,0,-7,3)
Block(-3,0,-6,3)
Block(-3,0,-5,3)
Block(-3,0,-4,3)
Block(-3,0,-3,3)
Block(-3,0,-2,3)
Block(-3,0,-1,3)
Block(-3,0,0,3)
Block(-3,0,1,3)
Block(-3,0,2,3)
Block(-3,0,3,3)
Block(-3,0,4,3)
Block(-3,0,5,3)
Block(-3,0,6,3)
Block(-3,0,7,3)
Block(-3,0,8,3)
Block(-3,1,-7,2)
Block(-3,1,-6,2)
Block(-3,1,-5,2)
Block(-3,1,-4,2)
Block(-3,1,-3,3)
Block(-3,1,-2,2)
Block(-3,1,-1,3:2)
Block(-3,1,0,3:2)
Block(-3,1,1,2)
Block(-3,1,2,13)
Block(-3,1,3,48)
Block(-3,1,4,4)
Block(-3,1,5,2)
Block(-3,1,6,3:2)
Block(-3,1,7,3:2)
Block(-3,1,8,2)
Block(-3,2,-7,38)
Block(-3,2,-5,31:1)
Block(-3,2,-4,31:1)
Block(-3,2,-3,98:3)
Block(-3,2,-2,175:3)
Block(-3,2,-1,31:1)
Block(-3,2,0,31:1)
Block(-3,2,1,31:1)
Block(-3,2,5,175:2)
Block(-3,2,6,175:2)
Block(-3,2,8,175:2)
Block(-3,3,-3,101)
Block(-3,3,-2,175:9)
Block(-3,3,5,175:10)
Block(-3,3,6,175:10)
Block(-3,3,8,175:10)
Block(-3,4,-3,101)
Block(-3,5,-3,98:3)
Block(-3,7,8,18:14)
Block(-2,0,-7,3)
Block(-2,0,-6,3)
Block(-2,0,-5,3)
Block(-2,0,-4,3)
Block(-2,0,-3,3)
Block(-2,0,-2,3)
Block(-2,0,-1,3)
Block(-2,0,0,3)
Block(-2,0,1,3)
Block(-2,0,2,3)
Block(-2,0,3,3)
Block(-2,0,4,3)
Block(-2,0,5,3)
Block(-2,0,6,3)
Block(-2,0,7,3)
Block(-2,0,8,3)
Block(-2,1,-7,2)
Block(-2,1,-6,2)
Block(-2,1,-5,3:2)
Block(-2,1,-4,2)
Block(-2,1,-3,2)
Block(-2,1,-2,3:2)
Block(-2,1,-1,3:2)
Block(-2,1,0,3:2)
Block(-2,1,1,2)
Block(-2,1,2,3:2)
Block(-2,1,3,3)
Block(-2,1,4,2)
Block(-2,1,5,2)
Block(-2,1,6,3:2)
Block(-2,1,7,2)
Block(-2,1,8,3:2)
Block(-2,2,-7,31:1)
Block(-2,2,-6,31:1)
Block(-2,2,-4,31:1)
Block(-2,2,-3,109:2)
Block(-2,2,-2,175:3)
Block(-2,2,0,175:2)
Block(-2,2,1,175:3)
Block(-2,2,3,3:2)
Block(-2,2,5,18:6)
Block(-2,2,7,175:3)
Block(-2,2,8,175:2)
Block(-2,3,-3,101)
Block(-2,3,-2,175:9)
Block(-2,3,0,175:9)
Block(-2,3,1,175:9)
Block(-2,3,3,175:2)
Block(-2,3,7,175:10)
Block(-2,3,8,175:10)
Block(-2,4,-3,101)
Block(-2,4,3,175:10)
Block(-2,5,-3,44:5)
Block(-1,0,-7,3)
Block(-1,0,-6,3)
Block(-1,0,-5,3)
Block(-1,0,-4,3)
Block(-1,0,-3,3)
Block(-1,0,-2,3)
Block(-1,0,-1,3)
Block(-1,0,0,3)
Block(-1,0,1,3)
Block(-1,0,2,3)
Block(-1,0,3,3)
Block(-1,0,4,3)
Block(-1,0,5,3)
Block(-1,0,6,3)
Block(-1,0,7,3)
Block(-1,0,8,3)
Block(-1,1,-7,2)
Block(-1,1,-6,2)
Block(-1,1,-5,2)
Block(-1,1,-4,3:2)
Block(-1,1,-3,3)
Block(-1,1,-2,2)
Block(-1,1,-1,3)
Block(-1,1,0,2)
Block(-1,1,1,3)
Block(-1,1,2,2)
Block(-1,1,3,3)
Block(-1,1,4,2)
Block(-1,1,5,3)
Block(-1,1,6,2)
Block(-1,1,7,3)
Block(-1,1,8,2)
Block(-1,2,-5,175:2)
Block(-1,2,-3,98)
Block(-1,2,-2,109:1)
Block(-1,2,-1,98:3)
Block(-1,2,0,109:1)
Block(-1,2,1,109:5)
Block(-1,2,2,109:1)
Block(-1,2,3,98:3)
Block(-1,2,4,109:1)
Block(-1,2,5,109:5)
Block(-1,2,6,109:1)
Block(-1,2,7,98:3)
Block(-1,2,8,109:1)
Block(-1,3,-5,175:8)
Block(-1,3,-3,162)
Block(-1,3,-2,101)
Block(-1,3,-1,101)
Block(-1,3,0,101)
Block(-1,3,1,162)
Block(-1,3,2,101)
Block(-1,3,3,101)
Block(-1,3,4,101)
Block(-1,3,5,162)
Block(-1,3,6,101)
Block(-1,3,7,101)
Block(-1,3,8,101)
Block(-1,4,-3,98:2)
Block(-1,4,-2,101)
Block(-1,4,-1,101)
Block(-1,4,0,101)
Block(-1,4,1,98)
Block(-1,4,2,101)
Block(-1,4,3,101)
Block(-1,4,4,101)
Block(-1,4,5,98:2)
Block(-1,4,6,101)
Block(-1,4,7,101)
Block(-1,4,8,101)
Block(-1,5,-3,139:1)
Block(-1,5,-2,44:5)
Block(-1,5,-1,98:3)
Block(-1,5,0,44:5)
Block(-1,5,1,139)
Block(-1,5,2,44:5)
Block(-1,5,3,98:3)
Block(-1,5,4,44:5)
Block(-1,5,5,139:1)
Block(-1,5,6,44:5)
Block(-1,5,7,98:3)
Block(-1,5,8,44:5)
Block(0,0,-7,3)
Block(0,0,-6,3)
Block(0,0,-5,3)
Block(0,0,-4,3)
Block(0,0,-3,3)
Block(0,0,-2,3)
Block(0,0,-1,3)
Block(0,0,0,3)
Block(0,0,1,3)
Block(0,0,2,3)
Block(0,0,3,3)
Block(0,0,4,3)
Block(0,0,5,3)
Block(0,0,6,3)
Block(0,0,7,3)
Block(0,0,8,3)
Block(0,1,-7,2)
Block(0,1,-6,2)
Block(0,1,-5,3:2)
Block(0,1,-4,2)
Block(0,1,-3,3:2)
Block(0,1,-2,2)
Block(0,1,-1,3:2)
Block(0,1,0,2)
Block(0,1,1,2)
Block(0,1,2,3:2)
Block(0,1,3,2)
Block(0,1,4,2)
Block(0,1,5,2)
Block(0,1,6,3:2)
Block(0,1,7,2)
Block(0,1,8,2)
Block(0,2,-4,31:1)
Block(0,2,0,38:8)
Block(0,2,1,38)
Block(0,2,3,175:2)
Block(0,2,4,31:1)
Block(0,2,5,31:1)
Block(0,2,7,31:1)
Block(0,2,8,31:1)
Block(0,3,3,175:8)
Block(1,0,-7,3)
Block(1,0,-6,3)
Block(1,0,-5,3)
Block(1,0,-4,3)
Block(1,0,-3,3)
Block(1,0,-2,3)
Block(1,0,-1,3)
Block(1,0,0,3)
Block(1,0,1,3)
Block(1,0,2,3)
Block(1,0,3,3)
Block(1,0,4,3)
Block(1,0,5,3)
Block(1,0,6,3)
Block(1,0,7,3)
Block(1,0,8,3)
Block(1,1,-7,2)
Block(1,1,-6,2)
Block(1,1,-5,2)
Block(1,1,-4,2)
Block(1,1,-3,3:2)
Block(1,1,-2,2)
Block(1,1,-1,2)
Block(1,1,0,3:2)
Block(1,1,1,2)
Block(1,1,2,2)
Block(1,1,3,3:2)
Block(1,1,4,2)
Block(1,1,5,2)
Block(1,1,6,2)
Block(1,1,7,2)
Block(1,1,8,3:2)
Block(1,2,-6,31:1)
Block(1,2,-5,31:1)
Block(1,2,-4,31:1)
Block(1,2,-1,31:1)
Block(1,2,1,31:1)
Block(1,2,4,31:1)
Block(1,2,5,38:4)
Block(1,2,6,31:1)
Block(1,2,7,31:1)
Block(2,0,-7,3)
Block(2,0,-6,3)
Block(2,0,-5,3)
Block(2,0,-4,3)
Block(2,0,-3,3)
Block(2,0,-2,3)
Block(2,0,-1,3)
Block(2,0,0,3)
Block(2,0,1,3)
Block(2,0,2,3)
Block(2,0,3,3)
Block(2,0,4,3)
Block(2,0,5,3)
Block(2,0,6,3)
Block(2,0,7,3)
Block(2,0,8,3)
Block(2,1,-7,2)
Block(2,1,-6,2)
Block(2,1,-5,2)
Block(2,1,-4,2)
Block(2,1,-3,2)
Block(2,1,-2,2)
Block(2,1,-1,2)
Block(2,1,0,2)
Block(2,1,1,2)
Block(2,1,2,2)
Block(2,1,3,2)
Block(2,1,4,2)
Block(2,1,5,2)
Block(2,1,6,2)
Block(2,1,7,2)
Block(2,1,8,2)
Block(2,2,-1,31:1)
Block(2,2,2,37)
Block(2,2,3,38:8)
Block(2,2,5,31:1)
Block(2,2,6,31:1)
Block(2,2,7,31:1)
Block(2,2,8,31:1)
