

BranchFrequency: 10

BranchFrequencyGroup: CanOverride:0

CanOverride: true

SmoothRadius: -1

OverrideChildSettings: false

ReplaceAbove:
ReplaceBelow:

MustBeInside: VillageGeneratorStructurePlaceHolder, VillageGeneratorStructuresDelay, VillageGeneratorStructuresDelay2, VillageGeneratorStructuresDelay3, VillageGeneratorStructuresDelay4, VillageGeneratorStructuresDelay5, VillageGeneratorStructuresDelay6, VillageGeneratorStructuresDelay7, VillageGeneratorStructuresDelay8, VillageGeneratorStructuresDelay9, VillageGeneratorStructuresDelay10

Block(-8,0,-7,3)
Block(-8,0,-6,3)
Block(-8,0,-5,3)
Block(-8,0,-4,3)
Block(-8,0,-3,3)
Block(-8,0,-2,3)
Block(-8,0,-1,3)
Block(-8,0,0,3)
Block(-8,0,1,3)
Block(-8,0,2,3)
Block(-8,0,3,3)
Block(-8,0,4,3)
Block(-8,0,5,3)
Block(-8,0,6,3)
Block(-8,0,7,3)
Block(-8,0,8,3)
Block(-8,1,-7,2)
Block(-8,1,-6,2)
Block(-8,1,-5,2)
Block(-8,1,-4,2)
Block(-8,1,-3,2)
Block(-8,1,-2,2)
Block(-8,1,-1,2)
Block(-8,1,0,2)
Block(-8,1,1,2)
Block(-8,1,2,2)
Block(-8,1,3,2)
Block(-8,1,4,2)
Block(-8,1,5,2)
Block(-8,1,6,2)
Block(-8,1,7,2)
Block(-8,1,8,2)
Block(-8,2,-6,31:1)
Block(-8,2,-5,31:1)
Block(-8,2,-4,31:1)
Block(-8,2,-3,31:1)
Block(-8,2,-2,31:1)
Block(-8,2,-1,31:1)
Block(-8,2,0,31:1)
Block(-8,2,1,31:1)
Block(-8,2,2,31:1)
Block(-8,2,3,31:1)
Block(-8,2,4,31:1)
Block(-8,2,6,31:1)
Block(-8,2,7,31:1)
Block(-8,2,8,31:1)
Block(-7,0,-7,3)
Block(-7,0,-6,3)
Block(-7,0,-5,3)
Block(-7,0,-4,3)
Block(-7,0,-3,3)
Block(-7,0,-2,3)
Block(-7,0,-1,3)
Block(-7,0,0,3)
Block(-7,0,1,3)
Block(-7,0,2,3)
Block(-7,0,3,3)
Block(-7,0,4,3)
Block(-7,0,5,3)
Block(-7,0,6,3)
Block(-7,0,7,3)
Block(-7,0,8,3)
Block(-7,1,-7,2)
Block(-7,1,-6,2)
Block(-7,1,-5,3:2)
Block(-7,1,-4,2)
Block(-7,1,-3,2)
Block(-7,1,-2,3:2)
Block(-7,1,-1,2)
Block(-7,1,0,2)
Block(-7,1,1,3:2)
Block(-7,1,2,2)
Block(-7,1,3,2)
Block(-7,1,4,2)
Block(-7,1,5,2)
Block(-7,1,6,3:2)
Block(-7,1,7,2)
Block(-7,1,8,2)
Block(-7,2,-6,31:1)
Block(-7,2,-4,31:1)
Block(-7,2,-3,31:1)
Block(-7,2,-1,38)
Block(-7,2,0,31:1)
Block(-7,2,2,31:1)
Block(-7,2,4,31:1)
Block(-7,2,5,37)
Block(-7,2,7,38:8)
Block(-7,2,8,31:1)
Block(-6,0,-7,3)
Block(-6,0,-6,3)
Block(-6,0,-5,3)
Block(-6,0,-4,3)
Block(-6,0,-3,3)
Block(-6,0,-2,3)
Block(-6,0,-1,3)
Block(-6,0,0,3)
Block(-6,0,1,3)
Block(-6,0,2,3)
Block(-6,0,3,3)
Block(-6,0,4,3)
Block(-6,0,5,3)
Block(-6,0,6,3)
Block(-6,0,7,3)
Block(-6,0,8,3)
Block(-6,1,-7,2)
Block(-6,1,-6,2)
Block(-6,1,-5,2)
Block(-6,1,-4,2)
Block(-6,1,-3,3:2)
Block(-6,1,-2,3:2)
Block(-6,1,-1,3:2)
Block(-6,1,0,2)
Block(-6,1,1,2)
Block(-6,1,2,2)
Block(-6,1,3,3:2)
Block(-6,1,4,2)
Block(-6,1,5,2)
Block(-6,1,6,2)
Block(-6,1,7,2)
Block(-6,1,8,2)
Block(-6,2,-6,31:1)
Block(-6,2,-5,31:1)
Block(-6,2,-4,31:1)
Block(-6,2,0,31:1)
Block(-6,2,1,38:4)
Block(-6,2,5,31:1)
Block(-6,2,6,175:2)
Block(-6,2,7,31:1)
Block(-6,2,8,38:8)
Block(-6,3,6,175:8)
Block(-5,0,-7,3)
Block(-5,0,-6,3)
Block(-5,0,-5,3)
Block(-5,0,-4,3)
Block(-5,0,-3,3)
Block(-5,0,-2,3)
Block(-5,0,-1,3)
Block(-5,0,0,3)
Block(-5,0,1,3)
Block(-5,0,2,3)
Block(-5,0,3,3)
Block(-5,0,4,3)
Block(-5,0,5,3)
Block(-5,0,6,3)
Block(-5,0,7,3)
Block(-5,0,8,3)
Block(-5,1,-7,2)
Block(-5,1,-6,2)
Block(-5,1,-5,2)
Block(-5,1,-4,2)
Block(-5,1,-3,3)
Block(-5,1,-2,2)
Block(-5,1,-1,3)
Block(-5,1,0,2)
Block(-5,1,1,3)
Block(-5,1,2,2)
Block(-5,1,3,3)
Block(-5,1,4,2)
Block(-5,1,5,3)
Block(-5,1,6,2)
Block(-5,1,7,3)
Block(-5,1,8,2)
Block(-5,2,-7,31:1)
Block(-5,2,-6,31:1)
Block(-5,2,-5,31:1)
Block(-5,2,-4,38)
Block(-5,2,-3,98)
Block(-5,2,-2,109)
Block(-5,2,-1,98:3)
Block(-5,2,0,109)
Block(-5,2,1,109:4)
Block(-5,2,2,109)
Block(-5,2,3,98:3)
Block(-5,2,4,109)
Block(-5,2,5,109:4)
Block(-5,2,6,109)
Block(-5,2,7,98:3)
Block(-5,2,8,109)
Block(-5,3,-3,162)
Block(-5,3,-2,101)
Block(-5,3,-1,101)
Block(-5,3,0,101)
Block(-5,3,1,162)
Block(-5,3,2,101)
Block(-5,3,3,101)
Block(-5,3,4,101)
Block(-5,3,5,162)
Block(-5,3,6,101)
Block(-5,3,7,101)
Block(-5,3,8,101)
Block(-5,4,-3,98:2)
Block(-5,4,-2,101)
Block(-5,4,-1,101)
Block(-5,4,0,101)
Block(-5,4,1,98)
Block(-5,4,2,101)
Block(-5,4,3,101)
Block(-5,4,4,101)
Block(-5,4,5,98:2)
Block(-5,4,6,101)
Block(-5,4,7,101)
Block(-5,4,8,101)
Block(-5,5,-3,139)
Block(-5,5,-2,44:5)
Block(-5,5,-1,98:3)
Block(-5,5,0,44:5)
Block(-5,5,1,139:1)
Block(-5,5,2,44:5)
Block(-5,5,3,98:3)
Block(-5,5,4,44:5)
Block(-5,5,5,139:1)
Block(-5,5,6,44:5)
Block(-5,5,7,98:3)
Block(-5,5,8,44:5)
Block(-4,0,-7,3)
Block(-4,0,-6,3)
Block(-4,0,-5,3)
Block(-4,0,-4,3)
Block(-4,0,-3,3)
Block(-4,0,-2,3)
Block(-4,0,-1,3)
Block(-4,0,0,3)
Block(-4,0,1,3)
Block(-4,0,2,3)
Block(-4,0,3,3)
Block(-4,0,4,3)
Block(-4,0,5,3)
Block(-4,0,6,3)
Block(-4,0,7,3)
Block(-4,0,8,3)
Block(-4,1,-7,2)
Block(-4,1,-6,2)
Block(-4,1,-5,3:2)
Block(-4,1,-4,2)
Block(-4,1,-3,2)
Block(-4,1,-2,2)
Block(-4,1,-1,3:2)
Block(-4,1,0,3)
Block(-4,1,1,3:2)
Block(-4,1,2,3:2)
Block(-4,1,3,2)
Block(-4,1,4,2)
Block(-4,1,5,3:2)
Block(-4,1,6,3)
Block(-4,1,7,3:2)
Block(-4,1,8,3:2)
Block(-4,2,-7,31:1)
Block(-4,2,-4,31:1)
Block(-4,2,-3,109:2)
Block(-4,2,-2,18:14)
Block(-4,2,0,2)
Block(-4,2,2,31:1)
Block(-4,2,3,18:14)
Block(-4,2,4,175:3)
Block(-4,2,5,175:2)
Block(-4,2,6,2)
Block(-4,2,7,175:2)
Block(-4,3,-3,101)
Block(-4,3,0,175:2)
Block(-4,3,4,175:9)
Block(-4,3,5,175:8)
Block(-4,3,6,31:1)
Block(-4,3,7,175:11)
Block(-4,4,-3,101)
Block(-4,4,0,175:8)
Block(-4,5,-3,44:5)
Block(-4,6,-1,44:5)
Block(-4,6,0,109:3)
Block(-4,6,1,44:5)
Block(-4,6,2,44:13)
Block(-4,6,4,44:13)
Block(-4,6,5,44:5)
Block(-4,6,6,109:2)
Block(-4,6,7,44:5)
Block(-4,7,3,44:5)
Block(-3,0,-7,3)
Block(-3,0,-6,3)
Block(-3,0,-5,3)
Block(-3,0,-4,3)
Block(-3,0,-3,3)
Block(-3,0,-2,3)
Block(-3,0,-1,3)
Block(-3,0,0,3)
Block(-3,0,1,3)
Block(-3,0,2,3)
Block(-3,0,3,3)
Block(-3,0,4,3)
Block(-3,0,5,3)
Block(-3,0,6,3)
Block(-3,0,7,3)
Block(-3,0,8,3)
Block(-3,1,-7,2)
Block(-3,1,-6,2)
Block(-3,1,-5,2)
Block(-3,1,-4,3:2)
Block(-3,1,-3,3)
Block(-3,1,-2,3:2)
Block(-3,1,-1,2)
Block(-3,1,0,3)
Block(-3,1,1,3:2)
Block(-3,1,2,3)
Block(-3,1,3,3)
Block(-3,1,4,3)
Block(-3,1,5,3:2)
Block(-3,1,6,3)
Block(-3,1,7,2)
Block(-3,1,8,2)
Block(-3,2,-6,38:5)
Block(-3,2,-5,38)
Block(-3,2,-3,98:3)
Block(-3,2,-1,175:2)
Block(-3,2,0,98:3)
Block(-3,2,1,109:4)
Block(-3,2,2,98:3)
Block(-3,2,3,109:4)
Block(-3,2,4,98:3)
Block(-3,2,5,109:4)
Block(-3,2,6,98:3)
Block(-3,2,7,175:2)
Block(-3,3,-3,101)
Block(-3,3,-1,175:9)
Block(-3,3,0,139)
Block(-3,3,1,109)
Block(-3,3,2,139)
Block(-3,3,3,109)
Block(-3,3,4,139)
Block(-3,3,5,109)
Block(-3,3,6,139)
Block(-3,3,7,175:9)
Block(-3,4,-3,101)
Block(-3,4,0,98:3)
Block(-3,4,1,139)
Block(-3,4,2,98:1)
Block(-3,4,3,139)
Block(-3,4,4,98)
Block(-3,4,5,139)
Block(-3,4,6,98:3)
Block(-3,5,-3,98:3)
Block(-3,5,0,139)
Block(-3,5,1,109:4)
Block(-3,5,2,98:2)
Block(-3,5,3,160:8)
Block(-3,5,4,98:2)
Block(-3,5,5,109:4)
Block(-3,5,6,139)
Block(-3,6,-1,109:1)
Block(-3,6,0,98)
Block(-3,6,1,162:8)
Block(-3,6,2,98)
Block(-3,6,3,160:8)
Block(-3,6,4,98)
Block(-3,6,5,162:8)
Block(-3,6,6,98)
Block(-3,6,7,109:1)
Block(-3,7,0,44:5)
Block(-3,7,1,109:3)
Block(-3,7,2,109:2)
Block(-3,7,3,162:8)
Block(-3,7,4,109:3)
Block(-3,7,5,109:2)
Block(-3,7,6,44:5)
Block(-3,8,3,44:5)
Block(-2,0,-7,3)
Block(-2,0,-6,3)
Block(-2,0,-5,3)
Block(-2,0,-4,3)
Block(-2,0,-3,3)
Block(-2,0,-2,3)
Block(-2,0,-1,3)
Block(-2,0,0,3)
Block(-2,0,1,3)
Block(-2,0,2,3)
Block(-2,0,3,3)
Block(-2,0,4,3)
Block(-2,0,5,3)
Block(-2,0,6,3)
Block(-2,0,7,3)
Block(-2,0,8,3)
Block(-2,1,-7,2)
Block(-2,1,-6,2)
Block(-2,1,-5,3:2)
Block(-2,1,-4,3:2)
Block(-2,1,-3,2)
Block(-2,1,-2,3:2)
Block(-2,1,-1,3:2)
Block(-2,1,0,3:2)
Block(-2,1,1,3)
Block(-2,1,2,3)
Block(-2,1,3,3)
Block(-2,1,4,3)
Block(-2,1,5,3)
Block(-2,1,6,3:2)
Block(-2,1,7,2)
Block(-2,1,8,3:2)
Block(-2,2,-3,109:2)
Block(-2,2,-2,175:2)
Block(-2,2,0,109:6)
Block(-2,2,1,98)
Block(-2,2,2,98)
Block(-2,2,3,98)
Block(-2,2,4,98)
Block(-2,2,5,98)
Block(-2,2,6,109:7)
Block(-2,2,8,175:2)
Block(-2,3,-3,101)
Block(-2,3,-2,175:9)
Block(-2,3,0,109:2)
Block(-2,3,1,98)
Block(-2,3,2,98)
Block(-2,3,3,98)
Block(-2,3,4,98)
Block(-2,3,5,98)
Block(-2,3,6,109:3)
Block(-2,3,8,175:9)
Block(-2,4,-3,101)
Block(-2,4,0,139)
Block(-2,4,1,98)
Block(-2,4,2,109:1)
Block(-2,4,4,109:1)
Block(-2,4,5,98)
Block(-2,4,6,139)
Block(-2,5,-3,44:5)
Block(-2,5,0,109:6)
Block(-2,5,1,139)
Block(-2,5,5,139)
Block(-2,5,6,109:7)
Block(-2,6,-1,44:5)
Block(-2,6,0,162:4)
Block(-2,6,1,98:3)
Block(-2,6,5,98:3)
Block(-2,6,6,162:4)
Block(-2,6,7,44:5)
Block(-2,7,0,109:1)
Block(-2,7,1,162)
Block(-2,7,2,162:8)
Block(-2,7,3,109:5)
Block(-2,7,4,162:8)
Block(-2,7,5,162)
Block(-2,7,6,109:1)
Block(-2,8,1,44:5)
Block(-2,8,2,109:2)
Block(-2,8,3,98:3)
Block(-2,8,4,109:3)
Block(-2,8,5,44:5)
Block(-1,0,-7,3)
Block(-1,0,-6,3)
Block(-1,0,-5,3)
Block(-1,0,-4,3)
Block(-1,0,-3,3)
Block(-1,0,-2,3)
Block(-1,0,-1,3)
Block(-1,0,0,3)
Block(-1,0,1,3)
Block(-1,0,2,3)
Block(-1,0,3,3)
Block(-1,0,4,3)
Block(-1,0,5,3)
Block(-1,0,6,3)
Block(-1,0,7,3)
Block(-1,0,8,3)
Block(-1,1,-7,2)
Block(-1,1,-6,2)
Block(-1,1,-5,2)
Block(-1,1,-4,2)
Block(-1,1,-3,3)
Block(-1,1,-2,2)
Block(-1,1,-1,2)
Block(-1,1,0,3)
Block(-1,1,1,3)
Block(-1,1,2,3)
Block(-1,1,3,3)
Block(-1,1,4,3)
Block(-1,1,5,3)
Block(-1,1,6,3)
Block(-1,1,7,3)
Block(-1,1,8,13)
Block(-1,2,-5,31:1)
Block(-1,2,-4,31:1)
Block(-1,2,-3,109:6)
Block(-1,2,-2,18:14)
Block(-1,2,-1,18:14)
Block(-1,2,0,98:3)
Block(-1,2,1,98)
Block(-1,2,2,98)
Block(-1,2,3,98)
Block(-1,2,4,98)
Block(-1,2,5,98)
Block(-1,2,6,98:1)
Block(-1,2,7,98:3)
Block(-1,3,-3,162)
Block(-1,3,0,139)
Block(-1,3,1,98:2)
Block(-1,3,2,98)
Block(-1,3,3,98)
Block(-1,3,4,98:1)
Block(-1,3,5,98)
Block(-1,3,6,98:1)
Block(-1,3,7,139)
Block(-1,4,-3,98)
Block(-1,4,0,98:1)
Block(-1,4,2,140,7-FlowerPot.nbt)
Block(-1,4,3,140:5,8-FlowerPot.nbt)
Block(-1,4,5,98:2)
Block(-1,4,6,98:2)
Block(-1,4,7,139)
Block(-1,5,-3,139:1)
Block(-1,5,0,98)
Block(-1,5,6,98)
Block(-1,5,7,109)
Block(-1,6,-1,44:13)
Block(-1,6,0,98:2)
Block(-1,6,6,109:5)
Block(-1,6,7,44:13)
Block(-1,7,0,109)
Block(-1,7,1,162:4)
Block(-1,7,5,162:4)
Block(-1,7,6,109)
Block(-1,8,1,109)
Block(-1,8,2,44:13)
Block(-1,8,3,109:5)
Block(-1,8,4,44:13)
Block(-1,8,5,109)
Block(-1,9,2,44:5)
Block(-1,9,3,109)
Block(-1,9,4,44:5)
Block(0,0,-7,3)
Block(0,0,-6,3)
Block(0,0,-5,3)
Block(0,0,-4,3)
Block(0,0,-3,3)
Block(0,0,-2,3)
Block(0,0,-1,3)
Block(0,0,0,3)
Block(0,0,1,3)
Block(0,0,2,3)
Block(0,0,3,3)
Block(0,0,4,3)
Block(0,0,5,3)
Block(0,0,6,3)
Block(0,0,7,3)
Block(0,0,8,3)
Block(0,1,-7,2)
Block(0,1,-6,2)
Block(0,1,-5,3:2)
Block(0,1,-4,2)
Block(0,1,-3,2)
Block(0,1,-2,2)
Block(0,1,-1,3:2)
Block(0,1,0,3)
Block(0,1,1,3)
Block(0,1,2,3)
Block(0,1,3,3)
Block(0,1,4,3)
Block(0,1,5,3)
Block(0,1,6,3)
Block(0,1,7,98)
Block(0,1,8,1)
Block(0,2,-7,31:1)
Block(0,2,-6,37)
Block(0,2,-4,31:1)
Block(0,2,-3,109:2)
Block(0,2,-2,175:2)
Block(0,2,-1,31:1)
Block(0,2,0,109:6)
Block(0,2,1,98)
Block(0,2,2,98)
Block(0,2,3,98)
Block(0,2,4,98)
Block(0,2,5,98)
Block(0,2,6,109:3)
Block(0,3,-3,101)
Block(0,3,-2,175:9)
Block(0,3,0,109:2)
Block(0,3,1,98)
Block(0,3,2,98)
Block(0,3,3,98)
Block(0,3,4,98)
Block(0,3,5,109:3)
Block(0,4,-3,101)
Block(0,4,0,109:6)
Block(0,4,1,54:3,10-Chest.nbt)
Block(0,4,2,44:5)
Block(0,4,3,44:5)
Block(0,4,4,68:3,11-Sign.nbt)
Block(0,5,-3,44:5)
Block(0,5,0,109:2)
Block(0,5,1,44)
Block(0,5,7,109:7)
Block(0,6,0,98:3)
Block(0,6,6,109:6)
Block(0,6,7,44:5)
Block(0,7,-1,44:5)
Block(0,7,0,162:4)
Block(0,7,1,109:7)
Block(0,7,5,109:6)
Block(0,7,6,162:4)
Block(0,7,7,44:5)
Block(0,8,0,44:5)
Block(0,8,1,98:3)
Block(0,8,2,109:7)
Block(0,8,4,109:6)
Block(0,8,5,98:3)
Block(0,8,6,44:5)
Block(0,9,2,109:2)
Block(0,9,3,95:8)
Block(0,9,4,109:3)
Block(1,0,-7,3)
Block(1,0,-6,3)
Block(1,0,-5,3)
Block(1,0,-4,3)
Block(1,0,-3,3)
Block(1,0,-2,3)
Block(1,0,-1,3)
Block(1,0,0,3)
Block(1,0,1,3)
Block(1,0,2,3)
Block(1,0,3,3)
Block(1,0,4,3)
Block(1,0,5,3)
Block(1,0,6,3)
Block(1,0,7,3)
Block(1,0,8,3)
Block(1,1,-7,2)
Block(1,1,-6,2)
Block(1,1,-5,2)
Block(1,1,-4,3:2)
Block(1,1,-3,3)
Block(1,1,-2,3:2)
Block(1,1,-1,3:2)
Block(1,1,0,3)
Block(1,1,1,3)
Block(1,1,2,3)
Block(1,1,3,3)
Block(1,1,4,3)
Block(1,1,5,3)
Block(1,1,6,3)
Block(1,1,7,3)
Block(1,1,8,48)
Block(1,2,-7,31:1)
Block(1,2,-6,31:1)
Block(1,2,-5,38)
Block(1,2,-3,98:3)
Block(1,2,-1,2)
Block(1,2,0,98:3)
Block(1,2,1,98)
Block(1,2,2,98)
Block(1,2,3,98)
Block(1,2,4,98)
Block(1,2,5,98)
Block(1,2,6,98)
Block(1,2,7,98:3)
Block(1,3,-3,101)
Block(1,3,-1,31:1)
Block(1,3,0,139)
Block(1,3,1,98)
Block(1,3,2,98:2)
Block(1,3,3,98)
Block(1,3,4,98)
Block(1,3,5,98:2)
Block(1,3,6,98:2)
Block(1,3,7,139)
Block(1,4,-3,101)
Block(1,4,0,98:2)
Block(1,4,2,140:5,12-FlowerPot.nbt)
Block(1,4,3,140,13-FlowerPot.nbt)
Block(1,4,5,109:2)
Block(1,4,6,98:1)
Block(1,4,7,139)
Block(1,5,-3,98:3)
Block(1,5,0,98:2)
Block(1,5,6,98)
Block(1,5,7,109:1)
Block(1,6,-1,44:13)
Block(1,6,0,98)
Block(1,6,6,109:4)
Block(1,6,7,44:13)
Block(1,7,0,109:1)
Block(1,7,1,162:4)
Block(1,7,5,162:4)
Block(1,7,6,109:1)
Block(1,8,1,109:1)
Block(1,8,2,44:13)
Block(1,8,3,109:4)
Block(1,8,4,44:13)
Block(1,8,5,109:1)
Block(1,9,2,44:5)
Block(1,9,3,109:1)
Block(1,9,4,44:5)
Block(2,0,-7,3)
Block(2,0,-6,3)
Block(2,0,-5,3)
Block(2,0,-4,3)
Block(2,0,-3,3)
Block(2,0,-2,3)
Block(2,0,-1,3)
Block(2,0,0,3)
Block(2,0,1,3)
Block(2,0,2,3)
Block(2,0,3,3)
Block(2,0,4,3)
Block(2,0,5,3)
Block(2,0,6,3)
Block(2,0,7,3)
Block(2,0,8,3)
Block(2,1,-7,2)
Block(2,1,-6,2)
Block(2,1,-5,2)
Block(2,1,-4,3:2)
Block(2,1,-3,2)
Block(2,1,-2,3:2)
Block(2,1,-1,2)
Block(2,1,0,3:2)
Block(2,1,1,3)
Block(2,1,2,3)
Block(2,1,3,3)
Block(2,1,4,3)
Block(2,1,5,3)
Block(2,1,6,3:2)
Block(2,1,7,3:2)
Block(2,1,8,2)
Block(2,2,-7,31:1)
Block(2,2,-6,31:1)
Block(2,2,-5,175:2)
Block(2,2,-3,109:2)
Block(2,2,-2,175:2)
Block(2,2,-1,31:1)
Block(2,2,0,109:6)
Block(2,2,1,98)
Block(2,2,2,98)
Block(2,2,3,98)
Block(2,2,4,98)
Block(2,2,5,98)
Block(2,2,6,109:7)
Block(2,2,7,31:1)
Block(2,2,8,31:1)
Block(2,3,-5,175:8)
Block(2,3,-3,101)
Block(2,3,-2,175:9)
Block(2,3,0,109:2)
Block(2,3,1,98)
Block(2,3,2,98)
Block(2,3,3,98:1)
Block(2,3,4,98)
Block(2,3,5,98)
Block(2,3,6,109:3)
Block(2,4,-3,101)
Block(2,4,0,139)
Block(2,4,1,98)
Block(2,4,2,109)
Block(2,4,4,109)
Block(2,4,5,98)
Block(2,4,6,139)
Block(2,5,-3,44:5)
Block(2,5,0,109:6)
Block(2,5,1,139)
Block(2,5,5,139)
Block(2,5,6,109:7)
Block(2,6,-1,44:5)
Block(2,6,0,162:4)
Block(2,6,1,98:3)
Block(2,6,5,98:3)
Block(2,6,6,162:4)
Block(2,6,7,44:5)
Block(2,7,0,109)
Block(2,7,1,162)
Block(2,7,2,162:8)
Block(2,7,3,109:4)
Block(2,7,4,162:8)
Block(2,7,5,162)
Block(2,7,6,109)
Block(2,8,1,44:5)
Block(2,8,2,109:2)
Block(2,8,3,98:3)
Block(2,8,4,109:3)
Block(2,8,5,44:5)
Block(3,0,-7,3)
Block(3,0,-6,3)
Block(3,0,-5,3)
Block(3,0,-4,3)
Block(3,0,-3,3)
Block(3,0,-2,3)
Block(3,0,-1,3)
Block(3,0,0,3)
Block(3,0,1,3)
Block(3,0,2,3)
Block(3,0,3,3)
Block(3,0,4,3)
Block(3,0,5,3)
Block(3,0,6,3)
Block(3,0,7,3)
Block(3,0,8,3)
Block(3,1,-7,2)
Block(3,1,-6,2)
Block(3,1,-5,2)
Block(3,1,-4,3:2)
Block(3,1,-3,3)
Block(3,1,-2,2)
Block(3,1,-1,2)
Block(3,1,0,3)
Block(3,1,1,3)
Block(3,1,2,3)
Block(3,1,3,3)
Block(3,1,4,3)
Block(3,1,5,3:2)
Block(3,1,6,3)
Block(3,1,7,2)
Block(3,1,8,3:2)
Block(3,2,-7,31:1)
Block(3,2,-6,31:1)
Block(3,2,-3,109:6)
Block(3,2,-1,175:3)
Block(3,2,0,98:3)
Block(3,2,1,109:5)
Block(3,2,2,98:3)
Block(3,2,3,109:5)
Block(3,2,4,98:3)
Block(3,2,5,109:5)
Block(3,2,6,98:3)
Block(3,2,7,175:2)
Block(3,2,8,31:1)
Block(3,3,-3,162)
Block(3,3,-1,175:9)
Block(3,3,0,139)
Block(3,3,1,109:1)
Block(3,3,2,139)
Block(3,3,3,109:1)
Block(3,3,4,139)
Block(3,3,5,109:1)
Block(3,3,6,139)
Block(3,3,7,175:8)
Block(3,4,-3,98:2)
Block(3,4,0,98:3)
Block(3,4,1,139)
Block(3,4,2,98:2)
Block(3,4,3,139)
Block(3,4,4,98)
Block(3,4,5,139)
Block(3,4,6,98:3)
Block(3,5,-3,139)
Block(3,5,0,139)
Block(3,5,1,109:5)
Block(3,5,2,98:2)
Block(3,5,3,160:8)
Block(3,5,4,98:1)
Block(3,5,5,109:5)
Block(3,5,6,139)
Block(3,6,-1,109)
Block(3,6,0,98)
Block(3,6,1,162:8)
Block(3,6,2,98)
Block(3,6,3,160:8)
Block(3,6,4,98:2)
Block(3,6,5,162:8)
Block(3,6,6,98)
Block(3,6,7,109)
Block(3,7,0,44:5)
Block(3,7,1,109:3)
Block(3,7,2,109:2)
Block(3,7,3,162:8)
Block(3,7,4,109:3)
Block(3,7,5,109:2)
Block(3,7,6,44:5)
Block(3,8,3,44:5)
Block(4,0,-7,3)
Block(4,0,-6,3)
Block(4,0,-5,3)
Block(4,0,-4,3)
Block(4,0,-3,3)
Block(4,0,-2,3)
Block(4,0,-1,3)
Block(4,0,0,3)
Block(4,0,1,3)
Block(4,0,2,3)
Block(4,0,3,3)
Block(4,0,4,3)
Block(4,0,5,3)
Block(4,0,6,3)
Block(4,0,7,3)
Block(4,0,8,3)
Block(4,1,-7,2)
Block(4,1,-6,2)
Block(4,1,-5,3:2)
Block(4,1,-4,3:2)
Block(4,1,-3,2)
Block(4,1,-2,2)
Block(4,1,-1,3)
Block(4,1,0,2)
Block(4,1,1,3)
Block(4,1,2,3:2)
Block(4,1,3,2)
Block(4,1,4,3:2)
Block(4,1,5,48)
Block(4,1,6,2)
Block(4,1,7,4)
Block(4,1,8,2)
Block(4,2,-6,31:1)
Block(4,2,-3,109:2)
Block(4,2,-2,18:14)
Block(4,2,-1,2)
Block(4,2,1,2)
Block(4,2,6,175:2)
Block(4,2,8,31:2)
Block(4,3,-3,101)
Block(4,3,-2,18:14)
Block(4,3,6,175:8)
Block(4,4,-3,101)
Block(4,5,-3,44:5)
Block(4,6,-1,44:5)
Block(4,6,0,109:3)
Block(4,6,1,44:5)
Block(4,6,2,44:13)
Block(4,6,4,44:13)
Block(4,6,5,44:5)
Block(4,6,6,109:2)
Block(4,6,7,44:5)
Block(4,7,3,44:5)
Block(5,0,-7,3)
Block(5,0,-6,3)
Block(5,0,-5,3)
Block(5,0,-4,3)
Block(5,0,-3,3)
Block(5,0,-2,3)
Block(5,0,-1,3)
Block(5,0,0,3)
Block(5,0,1,3)
Block(5,0,2,3)
Block(5,0,3,3)
Block(5,0,4,3)
Block(5,0,5,3)
Block(5,0,6,3)
Block(5,0,7,3)
Block(5,0,8,3)
Block(5,1,-7,2)
Block(5,1,-6,2)
Block(5,1,-5,2)
Block(5,1,-4,3:2)
Block(5,1,-3,3)
Block(5,1,-2,2)
Block(5,1,-1,3:2)
Block(5,1,0,2)
Block(5,1,1,2)
Block(5,1,2,4)
Block(5,1,3,4)
Block(5,1,4,13)
Block(5,1,5,3:2)
Block(5,1,6,1)
Block(5,1,7,2)
Block(5,1,8,13)
Block(5,2,-7,31:1)
Block(5,2,-6,31:1)
Block(5,2,-3,98:3)
Block(5,2,-2,18:6)
Block(5,2,0,175:2)
Block(5,2,1,31:2)
Block(5,2,4,2)
Block(5,2,5,175:2)
Block(5,3,-3,101)
Block(5,3,0,175:8)
Block(5,3,5,175:8)
Block(5,4,-3,101)
Block(5,5,-3,98:3)
Block(6,0,-7,3)
Block(6,0,-6,3)
Block(6,0,-5,3)
Block(6,0,-4,3)
Block(6,0,-3,3)
Block(6,0,-2,3)
Block(6,0,-1,3)
Block(6,0,0,2)
Block(6,0,1,2)
Block(6,0,2,3)
Block(6,0,3,3)
Block(6,0,4,3)
Block(6,0,5,3)
Block(6,0,6,3)
Block(6,0,7,3)
Block(6,0,8,3)
Block(6,1,-7,2)
Block(6,1,-6,2)
Block(6,1,-5,2)
Block(6,1,-4,3:2)
Block(6,1,-3,2)
Block(6,1,-2,3:2)
Block(6,1,-1,3:2)
Block(6,1,2,2)
Block(6,1,3,1)
Block(6,1,4,48)
Block(6,1,5,13)
Block(6,1,6,1)
Block(6,1,7,13)
Block(6,1,8,3:2)
Block(6,2,-7,31:1)
Block(6,2,-6,38)
Block(6,2,-5,31:1)
Block(6,2,-3,109:2)
Block(6,2,-1,175:2)
Block(6,2,2,175:2)
Block(6,2,8,18:14)
Block(6,3,-3,101)
Block(6,3,-1,175:9)
Block(6,3,2,175:8)
Block(6,4,-3,101)
Block(6,5,-3,44:5)
Block(7,0,-7,3)
Block(7,0,-6,3)
Block(7,0,-5,3)
Block(7,0,-4,3)
Block(7,0,-3,3)
Block(7,0,-2,3)
Block(7,0,-1,3)
Block(7,0,0,3)
Block(7,0,1,3)
Block(7,0,2,3)
Block(7,0,3,3)
Block(7,0,4,3)
Block(7,0,5,3)
Block(7,0,6,3)
Block(7,0,7,3)
Block(7,0,8,3)
Block(7,1,-7,2)
Block(7,1,-6,2)
Block(7,1,-5,2)
Block(7,1,-4,2)
Block(7,1,-3,3)
Block(7,1,-2,2)
Block(7,1,-1,2)
Block(7,1,0,2)
Block(7,1,1,2)
Block(7,1,2,1)
Block(7,1,3,13)
Block(7,1,4,1)
Block(7,1,5,1)
Block(7,1,6,2)
Block(7,1,7,3:2)
Block(7,1,8,1)
Block(7,2,-6,31:1)
Block(7,2,-5,31:1)
Block(7,2,-4,31:1)
Block(7,2,-3,109:6)
Block(7,2,-2,175:2)
Block(7,2,0,175:3)
Block(7,3,-3,162)
Block(7,3,-2,175:9)
Block(7,3,0,175:9)
Block(7,4,-3,98:1)
Block(7,4,-1,139)
Block(7,5,-3,139:1)

Branch(16,0,0,true,graveyardC1R0,NORTH,100,0)
Branch(0,0,16,true,graveyardC0R1,NORTH,100,0)
