

BranchFrequencyGroup: CanOverride:0

CanOverride: true

SmoothRadius: -1

OverrideChildSettings: false

ReplaceAbove:
ReplaceBelow:

MustBeInside: VillageGeneratorStructurePlaceHolder, VillageGeneratorStructuresDelay, VillageGeneratorStructuresDelay2, VillageGeneratorStructuresDelay3, VillageGeneratorStructuresDelay4, VillageGeneratorStructuresDelay5, VillageGeneratorStructuresDelay6, VillageGeneratorStructuresDelay7, VillageGeneratorStructuresDelay8, VillageGeneratorStructuresDelay9, VillageGeneratorStructuresDelay10

Block(-8,0,-7,2)
Block(-8,0,-6,2)
Block(-8,0,-5,2)
Block(-8,0,-4,2)
Block(-8,0,-3,2)
Block(-7,0,-7,3)
Block(-7,0,-6,3)
Block(-7,0,-5,3)
Block(-7,0,-4,3)
Block(-7,0,-3,2)
Block(-7,1,-7,5:2)
Block(-7,1,-6,5:2)
Block(-7,1,-5,5:2)
Block(-7,1,-4,5:2)
Block(-7,2,-7,5:2)
Block(-7,2,-6,5:2)
Block(-7,2,-5,5:2)
Block(-7,2,-4,5:2)
Block(-7,3,-7,5:2)
Block(-7,3,-6,5:2)
Block(-7,3,-5,5:2)
Block(-7,3,-4,5:2)
Block(-7,4,-7,5:2)
Block(-7,4,-6,5:2)
Block(-7,4,-5,5:2)
Block(-7,4,-4,5:2)
Block(-7,5,-7,5:2)
Block(-7,5,-6,5:2)
Block(-7,5,-5,5:2)
Block(-7,5,-4,5:2)
Block(-7,6,-7,5:2)
Block(-7,6,-6,5:2)
Block(-7,6,-5,5:2)
Block(-7,6,-4,5:2)
Block(-7,7,-7,35:14)
Block(-7,7,-6,35:14)
Block(-7,7,-5,35:14)
Block(-7,7,-4,35:14)
Block(-7,8,-7,5:2)
Block(-7,8,-6,5:2)
Block(-7,8,-5,5:2)
Block(-7,8,-4,5:2)
Block(-7,9,-7,5:2)
Block(-7,9,-6,5:2)
Block(-7,9,-5,5:2)
Block(-7,9,-4,5:2)
Block(-7,10,-7,5:2)
Block(-7,10,-6,5:2)
Block(-7,10,-5,5:2)
Block(-7,10,-4,5:2)
Block(-7,11,-7,5:2)
Block(-7,11,-6,5:2)
Block(-7,11,-5,5:2)
Block(-7,11,-4,5:2)
Block(-7,12,-7,35:14)
Block(-7,12,-6,35:14)
Block(-7,12,-5,35:14)
Block(-7,12,-4,126:5)
Block(-7,13,-7,5:2)
Block(-7,13,-6,5:2)
Block(-7,13,-5,164:3)
Block(-7,14,-7,5:2)
Block(-7,14,-6,164:3)
Block(-7,15,-7,164:3)
Block(-6,0,-7,3)
Block(-6,0,-6,3)
Block(-6,0,-5,2)
Block(-6,0,-4,3)
Block(-6,0,-3,2)
Block(-6,1,-7,5:2)
Block(-6,1,-6,9)
Block(-6,1,-5,9)
Block(-6,1,-4,5:2)
Block(-6,2,-4,5:2)
Block(-6,3,-4,5:2)
Block(-6,4,-4,5:2)
Block(-6,5,-7,164:2)
Block(-6,5,-4,5:2)
Block(-6,6,-6,164:2)
Block(-6,6,-4,5:2)
Block(-6,7,-5,164:2)
Block(-6,7,-4,35:14)
Block(-6,8,-4,5:2)
Block(-6,9,-4,5:2)
Block(-6,10,-4,5:2)
Block(-6,11,-4,5:2)
Block(-6,12,-4,35:14)
Block(-6,13,-5,164)
Block(-6,13,-4,164)
Block(-6,14,-6,164:3)
Block(-6,15,-7,164:3)
Block(-5,0,-7,3)
Block(-5,0,-6,2)
Block(-5,0,-5,2)
Block(-5,0,-4,3)
Block(-5,0,-3,2)
Block(-5,1,-7,5:2)
Block(-5,1,-6,9)
Block(-5,1,-5,9)
Block(-5,1,-4,5:2)
Block(-5,2,-4,5:2)
Block(-5,3,-4,5:2)
Block(-5,4,-4,5:2)
Block(-5,5,-7,164:2)
Block(-5,5,-4,5:2)
Block(-5,6,-6,164:2)
Block(-5,6,-4,5:2)
Block(-5,7,-5,164:2)
Block(-5,7,-4,35:14)
Block(-5,8,-4,5:2)
Block(-5,9,-4,5:2)
Block(-5,10,-4,5:2)
Block(-5,11,-4,5:2)
Block(-5,12,-4,35:14)
Block(-5,13,-4,5:2)
Block(-5,14,-6,164:3)
Block(-5,14,-5,164)
Block(-5,14,-4,164)
Block(-5,15,-7,164:3)
Block(-4,0,-7,3)
Block(-4,0,-6,3)
Block(-4,0,-5,3)
Block(-4,0,-4,3)
Block(-4,0,-3,2)
Block(-4,1,-7,5:2)
Block(-4,1,-6,5:2)
Block(-4,1,-5,5:2)
Block(-4,1,-4,5:2)
Block(-4,2,-4,5:2)
Block(-4,3,-4,5:2)
Block(-4,4,-4,5:2)
Block(-4,5,-4,5:2)
Block(-4,6,-4,5:2)
Block(-4,7,-7,5:5)
Block(-4,7,-6,5:5)
Block(-4,7,-5,5:5)
Block(-4,7,-4,35:14)
Block(-4,8,-4,5:2)
Block(-4,9,-4,5:2)
Block(-4,10,-4,5:2)
Block(-4,11,-4,5:2)
Block(-4,12,-4,35:14)
Block(-4,13,-4,5:2)
Block(-4,14,-4,5:2)
Block(-4,15,-7,164:3)
Block(-4,15,-6,164)
Block(-4,15,-5,164)
Block(-4,15,-4,164)
Block(-3,0,-7,2)
Block(-3,0,-6,2)
Block(-3,0,-5,2)
Block(-3,0,-4,3)
Block(-3,0,-3,2)
Block(-3,1,-4,5:2)
Block(-3,2,-4,5:2)
Block(-3,3,-4,5:2)
Block(-3,4,-4,5:2)
Block(-3,5,-4,5:2)
Block(-3,6,-4,5:2)
Block(-3,7,-7,5:5)
Block(-3,7,-6,5:5)
Block(-3,7,-5,5:5)
Block(-3,7,-4,35:14)
Block(-3,8,-4,5:2)
Block(-3,9,-4,5:2)
Block(-3,10,-4,5:2)
Block(-3,11,-4,5:2)
Block(-3,12,-4,35:14)
Block(-3,13,-4,5:2)
Block(-3,14,-4,160)
Block(-3,15,-4,5:2)
Block(-3,16,-7,126:1)
Block(-3,16,-6,126:1)
Block(-3,16,-5,126:1)
Block(-3,16,-4,126:1)
Block(-2,0,-7,2)
Block(-2,0,-6,2)
Block(-2,0,-5,2)
Block(-2,0,-4,3)
Block(-2,0,-3,2)
Block(-2,1,-4,5:2)
Block(-2,2,-4,5:2)
Block(-2,3,-4,5:2)
Block(-2,4,-4,5:2)
Block(-2,5,-4,5:2)
Block(-2,6,-5,89)
Block(-2,6,-4,5:2)
Block(-2,7,-7,5:5)
Block(-2,7,-6,5:5)
Block(-2,7,-5,5:5)
Block(-2,7,-4,35:14)
Block(-2,8,-4,5:2)
Block(-2,9,-4,5:2)
Block(-2,10,-4,5:2)
Block(-2,11,-4,5:2)
Block(-2,12,-4,35:14)
Block(-2,13,-4,5:2)
Block(-2,14,-4,5:2)
Block(-2,15,-7,164:1)
Block(-2,15,-6,164:1)
Block(-2,15,-5,164:1)
Block(-2,15,-4,164:1)
Block(-1,0,-7,2)
Block(-1,0,-6,2)
Block(-1,0,-5,2)
Block(-1,0,-4,3)
Block(-1,0,-3,2)
Block(-1,1,-4,5:2)
Block(-1,2,-4,5:2)
Block(-1,3,-4,5:2)
Block(-1,4,-4,5:2)
Block(-1,5,-4,5:2)
Block(-1,6,-4,5:2)
Block(-1,7,-7,5:5)
Block(-1,7,-6,5:5)
Block(-1,7,-5,5:5)
Block(-1,7,-4,35:14)
Block(-1,8,-4,5:2)
Block(-1,9,-4,5:2)
Block(-1,10,-4,5:2)
Block(-1,11,-4,5:2)
Block(-1,12,-4,35:14)
Block(-1,13,-4,5:2)
Block(-1,14,-6,164:1)
Block(-1,14,-5,164:1)
Block(-1,14,-4,164:1)
Block(-1,15,-7,164:3)
Block(0,0,-7,2)
Block(0,0,-6,2)
Block(0,0,-5,2)
Block(0,0,-4,3)
Block(0,0,-3,2)
Block(0,1,-4,5:2)
Block(0,2,-4,5:2)
Block(0,3,-4,5:2)
Block(0,4,-4,5:2)
Block(0,5,-4,5:2)
Block(0,6,-4,5:2)
Block(0,7,-7,5:5)
Block(0,7,-6,5:5)
Block(0,7,-5,5:5)
Block(0,7,-4,35:14)
Block(0,8,-4,5:2)
Block(0,9,-4,5:2)
Block(0,10,-4,5:2)
Block(0,11,-4,5:2)
Block(0,12,-4,35:14)
Block(0,13,-5,164:3)
Block(0,13,-4,164:1)
Block(0,14,-6,164:3)
Block(0,15,-7,164:3)
Block(1,0,-7,2)
Block(1,0,-6,2)
Block(1,0,-5,3)
Block(1,0,-4,3)
Block(1,0,-3,2)
Block(1,1,-5,5:2)
Block(1,1,-4,5:2)
Block(1,2,-5,5:2)
Block(1,2,-4,5:2)
Block(1,3,-5,5:2)
Block(1,3,-4,5:2)
Block(1,4,-5,5:2)
Block(1,4,-4,5:2)
Block(1,5,-5,5:2)
Block(1,5,-4,5:2)
Block(1,6,-6,5:2)
Block(1,6,-5,5:2)
Block(1,6,-4,5:2)
Block(1,7,-7,35:14)
Block(1,7,-6,35:14)
Block(1,7,-5,35:14)
Block(1,7,-4,35:14)
Block(1,8,-7,5:2)
Block(1,8,-6,5:2)
Block(1,8,-5,5:2)
Block(1,8,-4,5:2)
Block(1,9,-7,160)
Block(1,9,-6,5:2)
Block(1,9,-5,5:2)
Block(1,9,-4,5:2)
Block(1,10,-7,160)
Block(1,10,-6,5:2)
Block(1,10,-5,5:2)
Block(1,10,-4,5:2)
Block(1,11,-7,5:2)
Block(1,11,-6,5:2)
Block(1,11,-5,5:2)
Block(1,11,-4,5:2)
Block(1,12,-7,35:14)
Block(1,12,-6,35:14)
Block(1,12,-5,35:14)
Block(1,12,-4,126:5)
Block(1,13,-7,5:2)
Block(1,13,-6,5:2)
Block(1,13,-5,164:3)
Block(1,14,-7,5:2)
Block(1,14,-6,164:3)
Block(1,15,-7,164:3)
Block(2,0,-7,2)
Block(2,0,-6,2)
Block(2,0,-5,2)
Block(2,0,-4,2)
Block(2,0,-3,2)
Block(2,4,-5,164:5)
Block(2,5,-5,164:3)
Block(2,6,-6,164:3)
Block(2,7,-7,126:5)
Block(3,0,-7,2)
Block(3,0,-6,2)
Block(3,0,-5,2)
Block(3,0,-4,2)
Block(3,0,-3,2)
Block(3,5,-5,164:3)
Block(3,6,-6,164:3)
Block(3,7,-7,126:5)
Block(4,0,-7,2)
Block(4,0,-6,2)
Block(4,0,-5,2)
Block(4,0,-4,2)
Block(4,0,-3,2)
Block(4,5,-5,164:3)
Block(4,6,-6,164:3)
Block(4,7,-7,126:5)
Block(5,0,-7,2)
Block(5,0,-6,2)
Block(5,0,-5,2)
Block(5,0,-4,2)
Block(5,0,-3,2)
Block(5,5,-5,164:3)
Block(5,6,-6,164:3)
Block(5,7,-7,126:5)
Block(6,0,-7,2)
Block(6,0,-6,2)
Block(6,0,-5,2)
Block(6,0,-4,2)
Block(6,0,-3,2)
Block(6,5,-5,164:3)
Block(6,6,-6,164:3)
Block(6,7,-7,126:5)
Block(7,0,-7,2)
Block(7,0,-6,2)
Block(7,0,-5,2)
Block(7,0,-4,2)
Block(7,0,-3,2)
Block(7,5,-5,164:3)
Block(7,6,-6,164:3)
Block(7,7,-7,126:5)

Branch(16,0,0,true,town-center-ageC1R1,NORTH,100,0)
