

BranchFrequencyGroup: CanOverride:0

CanOverride: true

SmoothRadius: -1

OverrideChildSettings: false

ReplaceAbove:
ReplaceBelow:

MustBeInside: VillageGeneratorStructurePlaceHolder, VillageGeneratorStructuresDelay, VillageGeneratorStructuresDelay2, VillageGeneratorStructuresDelay3, VillageGeneratorStructuresDelay4, VillageGeneratorStructuresDelay5, VillageGeneratorStructuresDelay6, VillageGeneratorStructuresDelay7, VillageGeneratorStructuresDelay8, VillageGeneratorStructuresDelay9, VillageGeneratorStructuresDelay10

Block(-8,0,-7,2)
Block(-8,0,-6,2)
Block(-8,0,-5,2)
Block(-8,0,-4,2)
Block(-8,0,-3,2)
Block(-8,0,-2,2)
Block(-8,0,-1,2)
Block(-8,0,0,2)
Block(-8,0,1,2)
Block(-8,0,2,2)
Block(-8,0,3,2)
Block(-8,0,4,2)
Block(-8,0,5,2)
Block(-8,0,6,2)
Block(-8,0,7,2)
Block(-8,0,8,2)
Block(-8,1,1,85)
Block(-8,1,7,85)
Block(-8,2,1,85)
Block(-8,2,7,85)
Block(-8,3,1,85)
Block(-8,3,7,85)
Block(-8,4,1,5:5)
Block(-8,4,2,164:7)
Block(-8,4,6,164:6)
Block(-8,4,7,5:5)
Block(-8,5,1,164:2)
Block(-8,5,2,164)
Block(-8,5,3,164)
Block(-8,5,4,164)
Block(-8,5,5,164)
Block(-8,5,6,164)
Block(-8,5,7,164)
Block(-8,6,8,164:2)
Block(-7,0,-7,2)
Block(-7,0,-6,2)
Block(-7,0,-5,2)
Block(-7,0,-4,2:6)
Block(-7,0,-3,2)
Block(-7,0,-2,2)
Block(-7,0,-1,2)
Block(-7,0,0,2)
Block(-7,0,1,2)
Block(-7,0,2,2:7)
Block(-7,0,3,2:1)
Block(-7,0,4,2)
Block(-7,0,5,2)
Block(-7,0,6,2)
Block(-7,0,7,2)
Block(-7,0,8,2)
Block(-7,4,1,164:5)
Block(-7,5,1,164:2)
Block(-7,6,2,164:2)
Block(-7,6,3,164)
Block(-7,6,4,164)
Block(-7,6,5,164)
Block(-7,6,6,164)
Block(-7,6,7,164)
Block(-7,6,8,164)
Block(-6,0,-7,2)
Block(-6,0,-6,2)
Block(-6,0,-5,2)
Block(-6,0,-4,2)
Block(-6,0,-3,2:5)
Block(-6,0,-2,2)
Block(-6,0,-1,2:5)
Block(-6,0,0,2)
Block(-6,0,1,2:5)
Block(-6,0,2,2)
Block(-6,0,3,2)
Block(-6,0,4,2)
Block(-6,0,5,2)
Block(-6,0,6,2)
Block(-6,0,7,2)
Block(-6,0,8,2)
Block(-6,5,1,164:2)
Block(-6,6,2,164:2)
Block(-6,6,3,89)
Block(-6,7,3,126:5)
Block(-6,7,4,126:5)
Block(-6,7,5,126:5)
Block(-6,7,6,126:5)
Block(-6,7,7,126:5)
Block(-6,7,8,126:5)
Block(-5,0,-7,2)
Block(-5,0,-6,2)
Block(-5,0,-5,2)
Block(-5,0,-4,2)
Block(-5,0,-3,2)
Block(-5,0,-2,2)
Block(-5,0,-1,2)
Block(-5,0,0,2)
Block(-5,0,1,2)
Block(-5,0,2,2)
Block(-5,0,3,2)
Block(-5,0,4,2)
Block(-5,0,5,2)
Block(-5,0,6,2)
Block(-5,0,7,2)
Block(-5,0,8,2)
Block(-5,4,1,164:4)
Block(-5,5,1,164:2)
Block(-5,6,2,164:1)
Block(-5,6,3,164:1)
Block(-5,6,4,164:1)
Block(-5,6,5,164:1)
Block(-5,6,6,164:1)
Block(-5,6,7,164:1)
Block(-5,6,8,164:1)
Block(-4,0,-7,2)
Block(-4,0,-6,2)
Block(-4,0,-5,2)
Block(-4,0,-4,2)
Block(-4,0,-3,2)
Block(-4,0,-2,2)
Block(-4,0,-1,2)
Block(-4,0,0,2)
Block(-4,0,1,2:1)
Block(-4,0,2,2)
Block(-4,0,3,2)
Block(-4,0,4,2)
Block(-4,0,5,2)
Block(-4,0,6,2)
Block(-4,0,7,2)
Block(-4,0,8,2)
Block(-4,1,1,85)
Block(-4,1,7,85)
Block(-4,2,1,85)
Block(-4,2,7,85)
Block(-4,3,1,85)
Block(-4,3,7,85)
Block(-4,4,1,5:5)
Block(-4,4,2,164:7)
Block(-4,4,6,164:6)
Block(-4,4,7,5:5)
Block(-4,4,8,164:7)
Block(-4,5,1,164:1)
Block(-4,5,2,164:1)
Block(-4,5,3,164:1)
Block(-4,5,4,164:1)
Block(-4,5,5,164:1)
Block(-4,5,6,164:1)
Block(-4,5,7,164:1)
Block(-4,5,8,164:1)
Block(-3,0,-7,2)
Block(-3,0,-6,2)
Block(-3,0,-5,2)
Block(-3,0,-4,2)
Block(-3,0,-3,2)
Block(-3,0,-2,2)
Block(-3,0,-1,2)
Block(-3,0,0,2)
Block(-3,0,1,2)
Block(-3,0,2,2)
Block(-3,0,3,2)
Block(-3,0,4,2)
Block(-3,0,5,2)
Block(-3,0,6,2)
Block(-3,0,7,2)
Block(-3,0,8,2)
