

BranchFrequencyGroup: CanOverride:0

CanOverride: true

SmoothRadius: -1

OverrideChildSettings: false

ReplaceAbove:
ReplaceBelow:

MustBeInside: VillageGeneratorStructurePlaceHolder, VillageGeneratorStructuresDelay, VillageGeneratorStructuresDelay2, VillageGeneratorStructuresDelay3, VillageGeneratorStructuresDelay4, VillageGeneratorStructuresDelay5, VillageGeneratorStructuresDelay6, VillageGeneratorStructuresDelay7, VillageGeneratorStructuresDelay8, VillageGeneratorStructuresDelay9, VillageGeneratorStructuresDelay10

Block(-8,0,-7,2)
Block(-8,0,-6,2)
Block(-8,0,-5,2)
Block(-8,0,-4,2)
Block(-8,0,-3,2)
Block(-8,0,-2,2)
Block(-8,0,-1,2)
Block(-8,0,0,2)
Block(-8,0,1,2)
Block(-8,0,2,2)
Block(-8,0,3,2)
Block(-8,0,4,2)
Block(-7,0,-7,2)
Block(-7,0,-6,2)
Block(-7,0,-5,2)
Block(-7,0,-4,2)
Block(-7,0,-3,2)
Block(-7,0,-2,2)
Block(-7,0,-1,2)
Block(-7,0,0,2)
Block(-7,0,1,2)
Block(-7,0,2,2)
Block(-7,0,3,2)
Block(-7,0,4,2)
Block(-6,0,-7,2)
Block(-6,0,-6,2)
Block(-6,0,-5,2)
Block(-6,0,-4,2)
Block(-6,0,-3,2)
Block(-6,0,-2,2)
Block(-6,0,-1,2)
Block(-6,0,0,2)
Block(-6,0,1,2)
Block(-6,0,2,2)
Block(-6,0,3,2)
Block(-6,0,4,2)
Block(-5,0,-7,3)
Block(-5,0,-6,3)
Block(-5,0,-5,3)
Block(-5,0,-4,3)
Block(-5,0,-3,3)
Block(-5,0,-2,3)
Block(-5,0,-1,3)
Block(-5,0,0,3)
Block(-5,0,1,3)
Block(-5,0,2,2)
Block(-5,0,3,2)
Block(-5,0,4,2)
Block(-5,1,-7,155)
Block(-5,1,-6,155)
Block(-5,1,-5,155)
Block(-5,1,-4,155)
Block(-5,1,-3,155)
Block(-5,1,-2,155)
Block(-5,1,-1,155)
Block(-5,1,0,155)
Block(-5,1,1,155)
Block(-5,2,-3,85)
Block(-5,2,1,85)
Block(-5,3,-3,85)
Block(-5,3,1,85)
Block(-5,4,-3,85)
Block(-5,4,1,85)
Block(-5,5,-3,85)
Block(-5,5,1,85)
Block(-5,6,-7,35:14)
Block(-5,6,-6,35:14)
Block(-5,6,-5,35:14)
Block(-5,6,-4,35:14)
Block(-5,6,-3,35:14)
Block(-5,6,-2,35:14)
Block(-5,6,-1,35:14)
Block(-5,6,0,35:14)
Block(-5,6,1,35:14)
Block(-5,7,-7,5:5)
Block(-5,7,-6,5:5)
Block(-5,7,-5,5:5)
Block(-5,7,-4,5:5)
Block(-5,7,-3,5:5)
Block(-5,7,-2,5:5)
Block(-5,7,-1,5:5)
Block(-5,7,0,5:5)
Block(-5,7,1,5:5)
Block(-5,8,-7,5:2)
Block(-5,8,-6,5:2)
Block(-5,8,-5,5:2)
Block(-5,8,-4,5:2)
Block(-5,8,-3,125:5)
Block(-5,8,-2,5:2)
Block(-5,8,-1,5:2)
Block(-5,8,0,5:2)
Block(-5,8,1,5:2)
Block(-5,9,-7,5:2)
Block(-5,9,-6,102)
Block(-5,9,-5,5:2)
Block(-5,9,-4,5:2)
Block(-5,9,-3,125:5)
Block(-5,9,-2,5:2)
Block(-5,9,-1,102)
Block(-5,9,0,5:2)
Block(-5,9,1,5:2)
Block(-5,10,-7,5:2)
Block(-5,10,-6,5:2)
Block(-5,10,-5,5:2)
Block(-5,10,-4,5:2)
Block(-5,10,-3,125:5)
Block(-5,10,-2,5:2)
Block(-5,10,-1,5:2)
Block(-5,10,0,5:2)
Block(-5,10,1,5:2)
Block(-5,11,-7,125:5)
Block(-5,11,-6,125:5)
Block(-5,11,-5,125:5)
Block(-5,11,-4,125:5)
Block(-5,11,-3,125:5)
Block(-5,11,-2,125:5)
Block(-5,11,-1,125:5)
Block(-5,11,0,125:5)
Block(-5,11,1,125:5)
Block(-5,12,-7,125:2)
Block(-5,12,-6,125:2)
Block(-5,12,-5,125:2)
Block(-5,12,-4,136)
Block(-5,12,-3,136)
Block(-5,12,-2,125:2)
Block(-5,12,-1,125:2)
Block(-5,12,0,125:2)
Block(-5,12,1,136)
Block(-5,13,-7,136:2)
Block(-5,13,-6,125:2)
Block(-5,13,-5,136:3)
Block(-5,13,-2,136:2)
Block(-5,13,-1,125:2)
Block(-5,13,0,136:3)
Block(-5,14,-6,126:3)
Block(-5,14,-1,126:3)
Block(-4,0,-7,3)
Block(-4,0,-6,3)
Block(-4,0,-5,3)
Block(-4,0,-4,3)
Block(-4,0,-3,3)
Block(-4,0,-2,3)
Block(-4,0,-1,3)
Block(-4,0,0,3)
Block(-4,0,1,3)
Block(-4,0,2,2)
Block(-4,0,3,2)
Block(-4,0,4,2)
Block(-4,1,-7,5)
Block(-4,1,-6,5)
Block(-4,1,-5,5)
Block(-4,1,-4,5)
Block(-4,1,-3,5)
Block(-4,1,-2,5)
Block(-4,1,-1,5)
Block(-4,1,0,5)
Block(-4,1,1,155)
Block(-4,2,-7,5)
Block(-4,2,-6,5)
Block(-4,2,-5,5)
Block(-4,2,-4,5)
Block(-4,2,-3,5)
Block(-4,2,-2,5)
Block(-4,2,-1,5)
Block(-4,2,0,5)
Block(-4,3,-7,5)
Block(-4,3,-6,5)
Block(-4,3,-5,5)
Block(-4,3,-4,5)
Block(-4,3,-3,5)
Block(-4,3,-2,5)
Block(-4,3,-1,5)
Block(-4,3,0,5)
Block(-4,4,-7,5)
Block(-4,4,-6,5)
Block(-4,4,-5,5)
Block(-4,4,-4,5)
Block(-4,4,-3,5)
Block(-4,4,-2,5)
Block(-4,4,-1,5)
Block(-4,4,0,5)
Block(-4,5,-7,5)
Block(-4,5,-6,5)
Block(-4,5,-5,5)
Block(-4,5,-4,5)
Block(-4,5,-3,5)
Block(-4,5,-2,5)
Block(-4,5,-1,5)
Block(-4,5,0,5)
Block(-4,6,-7,5)
Block(-4,6,-6,5)
Block(-4,6,-5,5)
Block(-4,6,-4,5)
Block(-4,6,-3,5)
Block(-4,6,-2,5)
Block(-4,6,-1,5)
Block(-4,6,0,5)
Block(-4,6,1,125:5)
Block(-4,7,-7,54:5,3-Chest.nbt)
Block(-4,7,-6,26:9)
Block(-4,7,-5,58)
Block(-4,7,-4,54:5,4-Chest.nbt)
Block(-4,7,-3,26:9)
Block(-4,7,-2,58)
Block(-4,7,-1,26:9)
Block(-4,7,0,54:5,5-Chest.nbt)
Block(-4,7,1,5:5)
Block(-4,8,1,125:5)
Block(-4,9,1,125:5)
Block(-4,10,1,125:5)
Block(-4,11,1,125:5)
Block(-4,12,1,5:2)
Block(-4,13,-7,136:2)
Block(-4,13,-5,136:3)
Block(-4,13,-4,136)
Block(-4,13,-3,136)
Block(-4,13,-2,136:2)
Block(-4,13,0,136:3)
Block(-4,13,1,136)
Block(-4,14,-6,126:3)
Block(-4,14,-1,126:3)
Block(-3,0,-7,126:8)
Block(-3,0,-6,126:8)
Block(-3,0,-5,126:8)
Block(-3,0,-4,126:8)
Block(-3,0,-3,126:8)
Block(-3,0,-2,126:8)
Block(-3,0,-1,126:8)
Block(-3,0,0,3)
Block(-3,0,1,3)
Block(-3,0,2,2)
Block(-3,0,3,2)
Block(-3,0,4,2)
Block(-3,1,-7,164:1)
Block(-3,1,-3,107)
Block(-3,1,-1,54:2,6-Chest.nbt)
Block(-3,1,0,5)
Block(-3,1,1,155)
Block(-3,2,-1,171)
Block(-3,2,0,5)
Block(-3,3,-1,126:11)
Block(-3,3,0,5)
Block(-3,4,0,5)
Block(-3,5,-1,89)
Block(-3,5,0,5)
Block(-3,6,-7,126:8)
Block(-3,6,-6,126:8)
Block(-3,6,-5,126:8)
Block(-3,6,-4,126:8)
Block(-3,6,-3,126:8)
Block(-3,6,-2,126:8)
Block(-3,6,-1,126:8)
Block(-3,6,0,5)
Block(-3,6,1,35:14)
Block(-3,7,-6,26:1)
Block(-3,7,-3,26:1)
Block(-3,7,-1,26:1)
Block(-3,7,1,5:5)
Block(-3,8,1,5:2)
Block(-3,9,1,5:2)
Block(-3,10,1,5:2)
Block(-3,11,1,125:5)
Block(-3,12,1,5:2)
Block(-3,13,1,5:2)
Block(-3,14,-7,136)
Block(-3,14,-6,136)
Block(-3,14,-5,136)
Block(-3,14,-4,136)
Block(-3,14,-3,136)
Block(-3,14,-2,136)
Block(-3,14,-1,136)
Block(-3,14,0,136)
Block(-3,14,1,136)
Block(-2,0,-7,126:8)
Block(-2,0,-6,126:8)
Block(-2,0,-5,126:8)
Block(-2,0,-4,126:8)
Block(-2,0,-3,126:8)
Block(-2,0,-2,126:8)
Block(-2,0,-1,126:8)
Block(-2,0,0,3)
Block(-2,0,1,3)
Block(-2,0,2,2)
Block(-2,0,3,2)
Block(-2,0,4,2)
Block(-2,1,-7,85)
Block(-2,1,-6,164:2)
Block(-2,1,-3,164:6)
Block(-2,1,-1,54:2,7-Chest.nbt)
Block(-2,1,0,5)
Block(-2,1,1,155)
Block(-2,2,-7,171:7)
Block(-2,2,-1,171)
Block(-2,2,0,5)
Block(-2,3,-1,126:11)
Block(-2,3,0,5)
Block(-2,4,-1,140,8-FlowerPot.nbt)
Block(-2,4,0,5)
Block(-2,5,0,5)
Block(-2,6,-7,126:8)
Block(-2,6,-6,126:8)
Block(-2,6,-5,126:8)
Block(-2,6,-4,126:8)
Block(-2,6,-3,126:8)
Block(-2,6,-2,126:8)
Block(-2,6,-1,126:8)
Block(-2,6,0,5)
Block(-2,6,1,35:14)
Block(-2,7,1,5:5)
Block(-2,8,1,102)
Block(-2,9,1,102)
Block(-2,10,1,5:2)
Block(-2,11,-3,89)
Block(-2,11,1,125:5)
Block(-2,12,-3,85)
Block(-2,12,1,125:5)
Block(-2,13,-3,85)
Block(-2,13,1,125:5)
Block(-2,14,1,125:5)
Block(-2,15,-7,136)
Block(-2,15,-6,136)
Block(-2,15,-5,136)
Block(-2,15,-4,136)
Block(-2,15,-3,136)
Block(-2,15,-2,136)
Block(-2,15,-1,136)
Block(-2,15,0,136)
Block(-2,15,1,136)
Block(-1,0,-7,126:8)
Block(-1,0,-6,126:8)
Block(-1,0,-5,126:8)
Block(-1,0,-4,126:8)
Block(-1,0,-3,126:8)
Block(-1,0,-2,126:8)
Block(-1,0,-1,126:8)
Block(-1,0,0,3)
Block(-1,0,1,3)
Block(-1,0,2,2)
Block(-1,0,3,2)
Block(-1,0,4,2)
Block(-1,1,-7,164)
Block(-1,1,-4,164:3)
Block(-1,1,-3,164:6)
Block(-1,1,-1,61:2,9-Furnace.nbt)
Block(-1,1,0,5)
Block(-1,1,1,155)
Block(-1,2,-1,171)
Block(-1,2,0,5)
Block(-1,3,-1,126:11)
Block(-1,3,0,5)
Block(-1,4,-1,140:2,10-FlowerPot.nbt)
Block(-1,4,0,5)
Block(-1,5,0,5)
Block(-1,6,-7,126:8)
Block(-1,6,-6,126:8)
Block(-1,6,-5,126:8)
Block(-1,6,-4,126:8)
Block(-1,6,-3,126:8)
Block(-1,6,-2,126:8)
Block(-1,6,-1,126:8)
Block(-1,6,0,5)
Block(-1,6,1,35:14)
Block(-1,7,1,5:5)
Block(-1,8,1,5:2)
Block(-1,9,1,5:2)
Block(-1,10,1,5:2)
Block(-1,11,1,125:5)
Block(-1,12,1,5:2)
Block(-1,13,-3,85)
Block(-1,13,1,5:2)
Block(-1,14,-3,85)
Block(-1,14,1,5:2)
Block(-1,15,-3,85)
Block(-1,15,1,5:2)
Block(-1,16,-7,136)
Block(-1,16,-6,136)
Block(-1,16,-5,136)
Block(-1,16,-4,136)
Block(-1,16,-3,136)
Block(-1,16,-2,136)
Block(-1,16,-1,136)
Block(-1,16,0,136)
Block(-1,16,1,136)
Block(0,0,-7,126:8)
Block(0,0,-6,126:8)
Block(0,0,-5,126:8)
Block(0,0,-4,126:8)
Block(0,0,-3,126:8)
Block(0,0,-2,126:8)
Block(0,0,-1,126:8)
Block(0,0,0,3)
Block(0,0,1,3)
Block(0,0,2,2)
Block(0,0,3,2)
Block(0,0,4,2)
Block(0,1,-3,164:6)
Block(0,1,-1,61:2,11-Furnace.nbt)
Block(0,1,0,5)
Block(0,1,1,155)
Block(0,2,-1,171)
Block(0,2,0,5)
Block(0,2,1,85)
Block(0,3,-1,126:11)
Block(0,3,0,5)
Block(0,3,1,85)
Block(0,4,-1,140:2,12-FlowerPot.nbt)
Block(0,4,0,5)
Block(0,4,1,85)
Block(0,5,0,5)
Block(0,5,1,85)
Block(0,6,-7,126:8)
Block(0,6,-6,126:8)
Block(0,6,-5,126:8)
Block(0,6,-4,126:8)
Block(0,6,-3,126:8)
Block(0,6,-2,126:8)
Block(0,6,-1,126:8)
Block(0,6,0,5)
Block(0,6,1,35:14)
Block(0,7,1,5:5)
Block(0,8,1,102)
Block(0,9,1,102)
Block(0,10,1,5:2)
Block(0,11,1,125:5)
Block(0,12,1,5:2)
Block(0,13,-3,85)
Block(0,13,1,5:2)
Block(0,14,-3,85)
Block(0,14,1,5:2)
Block(0,15,-3,85)
Block(0,15,1,5:2)
Block(0,16,-7,136:1)
Block(0,16,-6,136:1)
Block(0,16,-5,136:1)
Block(0,16,-4,136:1)
Block(0,16,-3,136:1)
Block(0,16,-2,136:1)
Block(0,16,-1,136:1)
Block(0,16,0,136:1)
Block(0,16,1,136:1)
Block(1,0,-7,126:8)
Block(1,0,-6,126:8)
Block(1,0,-5,126:8)
Block(1,0,-4,126:8)
Block(1,0,-3,126:8)
Block(1,0,-2,126:8)
Block(1,0,-1,126:8)
Block(1,0,0,3)
Block(1,0,1,3)
Block(1,0,2,2)
Block(1,0,3,2)
Block(1,0,4,2)
Block(1,1,-4,164:3)
Block(1,1,-3,164:6)
Block(1,1,-1,58)
Block(1,1,0,5)
Block(1,1,1,155)
Block(1,2,-1,171)
Block(1,2,0,5)
Block(1,3,-1,126:11)
Block(1,3,0,5)
Block(1,4,-1,140,13-FlowerPot.nbt)
Block(1,4,0,5)
Block(1,5,0,5)
Block(1,6,-7,126:8)
Block(1,6,-6,126:8)
Block(1,6,-5,126:8)
Block(1,6,-4,126:8)
Block(1,6,-3,126:8)
Block(1,6,-2,126:8)
Block(1,6,-1,126:8)
Block(1,6,0,5)
Block(1,6,1,35:14)
Block(1,7,1,5:5)
Block(1,8,1,5:2)
Block(1,9,1,5:2)
Block(1,10,1,5:2)
Block(1,11,-3,89)
Block(1,11,1,125:5)
Block(1,12,-3,85)
Block(1,12,1,125:5)
Block(1,13,-3,85)
Block(1,13,1,125:5)
Block(1,14,1,125:5)
Block(1,15,-7,136:1)
Block(1,15,-6,136:1)
Block(1,15,-5,136:1)
Block(1,15,-4,136:1)
Block(1,15,-3,136:1)
Block(1,15,-2,136:1)
Block(1,15,-1,136:1)
Block(1,15,0,136:1)
Block(1,15,1,136:1)
Block(2,0,-7,126:8)
Block(2,0,-6,126:8)
Block(2,0,-5,126:8)
Block(2,0,-4,126:8)
Block(2,0,-3,126:8)
Block(2,0,-2,126:8)
Block(2,0,-1,126:8)
Block(2,0,0,3)
Block(2,0,1,3)
Block(2,0,2,2)
Block(2,0,3,2)
Block(2,0,4,2)
Block(2,1,-3,164:6)
Block(2,1,-1,58)
Block(2,1,0,5)
Block(2,1,1,155)
Block(2,2,-1,171)
Block(2,2,0,5)
Block(2,3,-1,126:11)
Block(2,3,0,5)
Block(2,4,0,5)
Block(2,5,-1,89)
Block(2,5,0,5)
Block(2,6,-7,126:8)
Block(2,6,-6,126:8)
Block(2,6,-5,126:8)
Block(2,6,-4,126:8)
Block(2,6,-3,126:8)
Block(2,6,-2,126:8)
Block(2,6,-1,126:8)
Block(2,6,0,5)
Block(2,6,1,125:5)
Block(2,7,-6,26:3)
Block(2,7,-3,26:3)
Block(2,7,-1,26:3)
Block(2,7,1,125:5)
Block(2,8,1,125:5)
Block(2,9,1,125:5)
Block(2,10,1,125:5)
Block(2,11,1,125:5)
Block(2,12,1,5:2)
Block(2,13,1,5:2)
Block(2,14,-7,136:1)
Block(2,14,-6,136:1)
Block(2,14,-5,136:1)
Block(2,14,-4,136:1)
Block(2,14,-3,136:1)
Block(2,14,-2,136:1)
Block(2,14,-1,136:1)
Block(2,14,0,136:1)
Block(2,14,1,136:1)
Block(3,0,-7,3)
Block(3,0,-6,3)
Block(3,0,-5,3)
Block(3,0,-4,3)
Block(3,0,-3,3)
Block(3,0,-2,3)
Block(3,0,-1,3)
Block(3,0,0,3)
Block(3,0,1,3)
Block(3,0,2,2)
Block(3,0,3,2)
Block(3,0,4,2)
Block(3,1,-7,5:2)
Block(3,1,-6,125:5)
Block(3,1,-5,5:2)
Block(3,1,-4,5:2)
Block(3,1,-3,5:2)
Block(3,1,-2,5:2)
Block(3,1,-1,5:2)
Block(3,1,0,5)
Block(3,1,1,155)
Block(3,2,-7,5:2)
Block(3,2,-6,125:5)
Block(3,2,-5,5:2)
Block(3,2,-4,5:2)
Block(3,2,-3,5:2)
Block(3,2,-2,5:2)
Block(3,2,-1,5:2)
Block(3,2,0,5)
Block(3,3,-7,5:2)
Block(3,3,-6,125:5)
Block(3,3,-5,5:2)
Block(3,3,-4,5:2)
Block(3,3,-3,5:2)
Block(3,3,-2,5:2)
Block(3,3,-1,5:2)
Block(3,3,0,5)
Block(3,4,-7,5:2)
Block(3,4,-6,125:5)
Block(3,4,-5,5:2)
Block(3,4,-4,5:2)
Block(3,4,-3,5:2)
Block(3,4,-2,5:2)
Block(3,4,-1,5:2)
Block(3,4,0,5)
Block(3,5,-7,5:2)
Block(3,5,-6,125:5)
Block(3,5,-5,5:2)
Block(3,5,-4,5:2)
Block(3,5,-3,5:2)
Block(3,5,-2,5:2)
Block(3,5,-1,5:2)
Block(3,5,0,5)
Block(3,6,-7,5)
Block(3,6,-6,5)
Block(3,6,-5,5)
Block(3,6,-4,5)
Block(3,6,-3,5)
Block(3,6,-2,5)
Block(3,6,-1,5)
Block(3,6,0,5)
Block(3,6,1,35:14)
Block(3,7,-7,54:4,18-Chest.nbt)
Block(3,7,-6,26:11)
Block(3,7,-5,58)
Block(3,7,-4,54:4,19-Chest.nbt)
Block(3,7,-3,26:11)
Block(3,7,-2,58)
Block(3,7,-1,26:11)
Block(3,7,0,54:4,20-Chest.nbt)
Block(3,7,1,5:5)
Block(3,8,1,5:2)
Block(3,9,1,5:2)
Block(3,10,1,5:2)
Block(3,11,1,125:5)
Block(3,12,1,5:2)
Block(3,13,-7,136:2)
Block(3,13,-5,136:1)
Block(3,13,-4,136:1)
Block(3,13,-3,136:1)
Block(3,13,-2,136:2)
Block(3,13,0,136:1)
Block(3,13,1,136:1)
Block(3,14,-6,126:3)
Block(3,14,-1,126:3)
Block(4,0,-7,2)
Block(4,0,-6,2)
Block(4,0,-5,2)
Block(4,0,-4,2)
Block(4,0,-3,2)
Block(4,0,-2,2)
Block(4,0,-1,2)
Block(4,0,0,3)
Block(4,0,1,3)
Block(4,0,2,2)
Block(4,0,3,2)
Block(4,0,4,2)
Block(4,1,0,5:1)
Block(4,1,1,155)
Block(4,2,0,5:1)
Block(4,2,1,85)
Block(4,3,0,5:1)
Block(4,3,1,85)
Block(4,4,0,5:1)
Block(4,4,1,85)
Block(4,5,-6,126:13)
Block(4,5,-3,126:13)
Block(4,5,0,5:1)
Block(4,5,1,85)
Block(4,6,-7,35:14)
Block(4,6,-6,35:14)
Block(4,6,-5,35:14)
Block(4,6,-4,35:14)
Block(4,6,-3,35:14)
Block(4,6,-2,35:14)
Block(4,6,-1,35:14)
Block(4,6,0,35:14)
Block(4,6,1,35:14)
Block(4,7,-7,125:5)
Block(4,7,-6,125:5)
Block(4,7,-5,125:5)
Block(4,7,-4,125:5)
Block(4,7,-3,125:5)
Block(4,7,-2,125:5)
Block(4,7,-1,125:5)
Block(4,7,0,125:5)
Block(4,7,1,5:5)
Block(4,8,-7,5:2)
Block(4,8,-6,5:2)
Block(4,8,-5,5:2)
Block(4,8,-4,5:2)
Block(4,8,-3,125:5)
Block(4,8,-2,5:2)
Block(4,8,-1,5:2)
Block(4,8,0,5:2)
Block(4,8,1,5:2)
Block(4,9,-7,5:2)
Block(4,9,-6,102)
Block(4,9,-5,5:2)
Block(4,9,-4,5:2)
Block(4,9,-3,125:5)
Block(4,9,-2,5:2)
Block(4,9,-1,102)
Block(4,9,0,5:2)
Block(4,9,1,5:2)
Block(4,10,-7,5:2)
Block(4,10,-6,5:2)
Block(4,10,-5,5:2)
Block(4,10,-4,5:2)
Block(4,10,-3,125:5)
Block(4,10,-2,5:2)
Block(4,10,-1,5:2)
Block(4,10,0,5:2)
Block(4,10,1,5:2)
Block(4,11,-7,125:5)
Block(4,11,-6,125:5)
Block(4,11,-5,125:5)
Block(4,11,-4,125:5)
Block(4,11,-3,125:5)
Block(4,11,-2,125:5)
Block(4,11,-1,125:5)
Block(4,11,0,125:5)
Block(4,11,1,125:5)
Block(4,12,-7,5:2)
Block(4,12,-6,5:2)
Block(4,12,-5,5:2)
Block(4,12,-4,136:1)
Block(4,12,-3,136:1)
Block(4,12,-2,5:2)
Block(4,12,-1,5:2)
Block(4,12,0,5:2)
Block(4,12,1,136:1)
Block(4,13,-7,136:2)
Block(4,13,-6,5:2)
Block(4,13,-5,136:3)
Block(4,13,-2,136:2)
Block(4,13,-1,5:2)
Block(4,13,0,136:3)
Block(4,14,-6,126:3)
Block(4,14,-1,126:3)
Block(5,0,-7,2)
Block(5,0,-6,2)
Block(5,0,-5,2)
Block(5,0,-4,2)
Block(5,0,-3,2)
Block(5,0,-2,2)
Block(5,0,-1,2)
Block(5,0,0,3)
Block(5,0,1,3)
Block(5,0,2,2)
Block(5,0,3,2)
Block(5,0,4,2)
Block(5,1,0,5:1)
Block(5,1,1,155)
Block(5,2,0,5:1)
Block(5,3,0,5:1)
Block(5,4,0,5:1)
Block(5,5,-6,126:13)
Block(5,5,-3,126:13)
Block(5,5,0,5:1)
Block(5,5,1,5:1)
Block(5,6,1,85)
Block(6,0,-7,2)
Block(6,0,-6,2)
Block(6,0,-5,2)
Block(6,0,-4,2)
Block(6,0,-3,2)
Block(6,0,-2,2)
Block(6,0,-1,2)
Block(6,0,0,3)
Block(6,0,1,3)
Block(6,0,2,2)
Block(6,0,3,2)
Block(6,0,4,2)
Block(6,1,0,5:1)
Block(6,1,1,155)
Block(6,2,0,5:1)
Block(6,3,0,5:1)
Block(6,4,0,5:1)
Block(6,5,0,5:1)
Block(6,5,1,5:1)
Block(6,6,1,85)
Block(7,0,-7,2)
Block(7,0,-6,2)
Block(7,0,-5,2)
Block(7,0,-4,2)
Block(7,0,-3,2)
Block(7,0,-2,2)
Block(7,0,-1,2)
Block(7,0,0,3)
Block(7,0,1,3)
Block(7,0,2,2)
Block(7,0,3,2)
Block(7,0,4,2)
Block(7,1,0,5:1)
Block(7,1,1,155)
Block(7,2,0,5:1)
Block(7,3,0,5:1)
Block(7,4,0,5:1)
Block(7,4,1,134:7)
Block(7,5,0,5:1)
Block(7,5,1,5:1)
Block(7,6,1,85)

Branch(16,0,0,true,barracks-age-ofC1R1,NORTH,100,0)
