

BranchFrequency: 10

BranchFrequencyGroup: CanOverride:0

CanOverride: true

SmoothRadius: -1

OverrideChildSettings: false

ReplaceAbove:
ReplaceBelow:

MustBeInside: VillageGeneratorStructurePlaceHolder, VillageGeneratorStructuresDelay, VillageGeneratorStructuresDelay2, VillageGeneratorStructuresDelay3, VillageGeneratorStructuresDelay4, VillageGeneratorStructuresDelay5, VillageGeneratorStructuresDelay6, VillageGeneratorStructuresDelay7, VillageGeneratorStructuresDelay8, VillageGeneratorStructuresDelay9, VillageGeneratorStructuresDelay10

Block(-8,0,-7,2)
Block(-8,0,-6,2)
Block(-8,0,-5,2)
Block(-8,0,-4,2)
Block(-8,0,-3,2)
Block(-8,0,-2,2)
Block(-8,0,-1,2)
Block(-8,0,0,2)
Block(-8,0,1,2)
Block(-8,0,2,2)
Block(-8,0,3,2)
Block(-8,0,4,2)
Block(-8,0,5,2)
Block(-8,0,6,2)
Block(-8,0,7,2)
Block(-8,0,8,2)
Block(-7,0,-7,2)
Block(-7,0,-6,2)
Block(-7,0,-5,2)
Block(-7,0,-4,2)
Block(-7,0,-3,2)
Block(-7,0,-2,2)
Block(-7,0,-1,2)
Block(-7,0,0,2)
Block(-7,0,1,2)
Block(-7,0,2,2)
Block(-7,0,3,2)
Block(-7,0,4,2)
Block(-7,0,5,2)
Block(-7,0,6,2)
Block(-7,0,7,2)
Block(-7,0,8,2)
Block(-6,0,-7,2)
Block(-6,0,-6,2)
Block(-6,0,-5,2)
Block(-6,0,-4,2)
Block(-6,0,-3,2)
Block(-6,0,-2,2)
Block(-6,0,-1,2)
Block(-6,0,0,2)
Block(-6,0,1,2)
Block(-6,0,2,2)
Block(-6,0,3,2)
Block(-6,0,4,2)
Block(-6,0,5,2)
Block(-6,0,6,2)
Block(-6,0,7,2)
Block(-6,0,8,2)
Block(-5,0,-7,2)
Block(-5,0,-6,2)
Block(-5,0,-5,2)
Block(-5,0,-4,3)
Block(-5,0,-3,3)
Block(-5,0,-2,3)
Block(-5,0,-1,3)
Block(-5,0,0,3)
Block(-5,0,1,3)
Block(-5,0,2,3)
Block(-5,0,3,3)
Block(-5,0,4,3)
Block(-5,0,5,3)
Block(-5,0,6,3)
Block(-5,0,7,3)
Block(-5,0,8,3)
Block(-5,1,-4,155)
Block(-5,1,-3,155)
Block(-5,1,-2,155)
Block(-5,1,-1,155)
Block(-5,1,0,155)
Block(-5,1,1,155)
Block(-5,1,2,155)
Block(-5,1,3,155)
Block(-5,1,4,155)
Block(-5,1,5,155)
Block(-5,1,6,155)
Block(-5,1,7,155)
Block(-5,1,8,155)
Block(-5,2,-4,85)
Block(-5,2,0,85)
Block(-5,2,4,85)
Block(-5,2,8,85)
Block(-5,3,-4,85)
Block(-5,3,0,85)
Block(-5,3,4,85)
Block(-5,3,8,85)
Block(-5,4,-4,85)
Block(-5,4,0,85)
Block(-5,4,4,85)
Block(-5,4,8,85)
Block(-5,5,-4,85)
Block(-5,5,0,85)
Block(-5,5,4,85)
Block(-5,5,8,85)
Block(-5,6,-4,35:14)
Block(-5,6,-3,35:14)
Block(-5,6,-2,35:14)
Block(-5,6,-1,35:14)
Block(-5,6,0,35:14)
Block(-5,6,1,35:14)
Block(-5,6,2,35:14)
Block(-5,6,3,35:14)
Block(-5,6,4,35:14)
Block(-5,6,5,35:14)
Block(-5,6,6,35:14)
Block(-5,6,7,35:14)
Block(-5,6,8,35:14)
Block(-5,7,-4,5:5)
Block(-5,7,-3,5:5)
Block(-5,7,-2,5:5)
Block(-5,7,-1,5:5)
Block(-5,7,0,5:5)
Block(-5,7,1,5:5)
Block(-5,7,2,5:5)
Block(-5,7,3,5:5)
Block(-5,7,4,5:5)
Block(-5,7,5,5:5)
Block(-5,7,6,5:5)
Block(-5,7,7,5:5)
Block(-5,7,8,5:5)
Block(-5,8,-4,5:2)
Block(-5,8,-3,5:2)
Block(-5,8,-2,5:2)
Block(-5,8,-1,5:2)
Block(-5,8,0,5:2)
Block(-5,8,1,125:5)
Block(-5,8,2,5:2)
Block(-5,8,3,5:2)
Block(-5,8,4,5:2)
Block(-5,8,5,5:2)
Block(-5,8,6,5:2)
Block(-5,8,7,125:5)
Block(-5,8,8,5:2)
Block(-5,9,-4,5:2)
Block(-5,9,-3,5:2)
Block(-5,9,-2,102)
Block(-5,9,-1,5:2)
Block(-5,9,0,5:2)
Block(-5,9,1,125:5)
Block(-5,9,2,5:2)
Block(-5,9,3,5:2)
Block(-5,9,4,102)
Block(-5,9,5,5:2)
Block(-5,9,6,5:2)
Block(-5,9,7,125:5)
Block(-5,9,8,5:2)
Block(-5,10,-4,5:2)
Block(-5,10,-3,5:2)
Block(-5,10,-2,5:2)
Block(-5,10,-1,5:2)
Block(-5,10,0,5:2)
Block(-5,10,1,125:5)
Block(-5,10,2,5:2)
Block(-5,10,3,5:2)
Block(-5,10,4,5:2)
Block(-5,10,5,5:2)
Block(-5,10,6,5:2)
Block(-5,10,7,125:5)
Block(-5,10,8,5:2)
Block(-5,11,-4,125:5)
Block(-5,11,-3,125:5)
Block(-5,11,-2,125:5)
Block(-5,11,-1,125:5)
Block(-5,11,0,125:5)
Block(-5,11,1,125:5)
Block(-5,11,2,125:5)
Block(-5,11,3,125:5)
Block(-5,11,4,125:5)
Block(-5,11,5,125:5)
Block(-5,11,6,125:5)
Block(-5,11,7,125:5)
Block(-5,11,8,125:5)
Block(-5,12,-4,136)
Block(-5,12,-3,125:2)
Block(-5,12,-2,125:2)
Block(-5,12,-1,125:2)
Block(-5,12,0,136)
Block(-5,12,1,136)
Block(-5,12,2,136)
Block(-5,12,3,125:2)
Block(-5,12,4,125:2)
Block(-5,12,5,125:2)
Block(-5,12,6,136)
Block(-5,12,7,136)
Block(-5,12,8,136)
Block(-5,13,-3,136:2)
Block(-5,13,-2,125:2)
Block(-5,13,-1,136:3)
Block(-5,13,3,136:2)
Block(-5,13,4,125:2)
Block(-5,13,5,136:3)
Block(-5,14,-2,126:3)
Block(-5,14,4,126:3)
Block(-4,0,-7,2)
Block(-4,0,-6,2)
Block(-4,0,-5,2)
Block(-4,0,-4,3)
Block(-4,0,-3,3)
Block(-4,0,-2,3)
Block(-4,0,-1,3)
Block(-4,0,0,3)
Block(-4,0,1,3)
Block(-4,0,2,3)
Block(-4,0,3,3)
Block(-4,0,4,3)
Block(-4,0,5,3)
Block(-4,0,6,3)
Block(-4,0,7,3)
Block(-4,0,8,3)
Block(-4,1,-4,155)
Block(-4,1,-3,5)
Block(-4,1,-2,5)
Block(-4,1,-1,5)
Block(-4,1,0,5)
Block(-4,1,1,5)
Block(-4,1,2,5)
Block(-4,1,3,5)
Block(-4,1,4,5)
Block(-4,1,5,5)
Block(-4,1,6,5)
Block(-4,1,7,5)
Block(-4,1,8,5)
Block(-4,2,-3,5)
Block(-4,2,-2,5)
Block(-4,2,-1,5)
Block(-4,2,0,5)
Block(-4,2,1,5)
Block(-4,2,2,5)
Block(-4,2,3,5)
Block(-4,2,4,5)
Block(-4,2,5,5)
Block(-4,2,6,5)
Block(-4,2,7,5)
Block(-4,2,8,5)
Block(-4,3,-3,5)
Block(-4,3,-2,5)
Block(-4,3,-1,5)
Block(-4,3,0,5)
Block(-4,3,1,5)
Block(-4,3,2,5)
Block(-4,3,3,5)
Block(-4,3,4,5)
Block(-4,3,5,5)
Block(-4,3,6,5)
Block(-4,3,7,5)
Block(-4,3,8,5)
Block(-4,4,-3,5)
Block(-4,4,-2,5)
Block(-4,4,-1,5)
Block(-4,4,0,5)
Block(-4,4,1,5)
Block(-4,4,2,5)
Block(-4,4,3,5)
Block(-4,4,4,5)
Block(-4,4,5,5)
Block(-4,4,6,5)
Block(-4,4,7,5)
Block(-4,4,8,5)
Block(-4,5,-3,5)
Block(-4,5,-2,5)
Block(-4,5,-1,5)
Block(-4,5,0,5)
Block(-4,5,1,5)
Block(-4,5,2,5)
Block(-4,5,3,5)
Block(-4,5,4,5)
Block(-4,5,5,5)
Block(-4,5,6,5)
Block(-4,5,7,5)
Block(-4,5,8,5)
Block(-4,6,-4,125:5)
Block(-4,6,-3,5)
Block(-4,6,-2,126)
Block(-4,6,-1,126)
Block(-4,6,0,5)
Block(-4,6,1,5)
Block(-4,6,2,5)
Block(-4,6,3,5)
Block(-4,6,4,5)
Block(-4,6,5,5)
Block(-4,6,6,5)
Block(-4,6,7,5)
Block(-4,6,8,5)
Block(-4,7,-4,5:5)
Block(-4,7,3,54:5,1-Chest.nbt)
Block(-4,7,4,26:9)
Block(-4,7,5,58)
Block(-4,7,6,54:5,2-Chest.nbt)
Block(-4,7,7,26:9)
Block(-4,7,8,58)
Block(-4,8,-4,125:5)
Block(-4,9,-4,125:5)
Block(-4,10,-4,125:5)
Block(-4,11,-4,125:5)
Block(-4,12,-4,5:2)
Block(-4,13,-4,136)
Block(-4,13,-3,136)
Block(-4,13,-1,136:3)
Block(-4,13,0,136)
Block(-4,13,1,136)
Block(-4,13,2,136)
Block(-4,13,3,136:2)
Block(-4,13,5,136:3)
Block(-4,13,6,136)
Block(-4,13,7,136)
Block(-4,13,8,136)
Block(-4,14,-2,126:3)
Block(-4,14,4,126:3)
Block(-3,0,-7,2)
Block(-3,0,-6,2)
Block(-3,0,-5,2)
Block(-3,0,-4,3)
Block(-3,0,-3,3)
Block(-3,0,-2,126:8)
Block(-3,0,-1,126:8)
Block(-3,0,0,126:8)
Block(-3,0,1,126:8)
Block(-3,0,2,126:8)
Block(-3,0,3,126:8)
Block(-3,0,4,126:8)
Block(-3,0,5,126:8)
Block(-3,0,6,126:8)
Block(-3,0,7,126:8)
Block(-3,0,8,126:8)
Block(-3,1,-4,155)
Block(-3,1,-3,5)
Block(-3,1,-2,164:1)
Block(-3,1,-1,164:1)
Block(-3,1,0,164:1)
Block(-3,1,5,164:1)
Block(-3,2,-3,5)
Block(-3,3,-3,5)
Block(-3,4,-3,5)
Block(-3,4,-2,89)
Block(-3,4,0,85)
Block(-3,5,-3,5)
Block(-3,5,-2,53:1)
Block(-3,5,-1,53:1)
Block(-3,5,0,85)
Block(-3,6,-4,35:14)
Block(-3,6,-3,5)
Block(-3,6,0,126:8)
Block(-3,6,1,126:8)
Block(-3,6,2,126:8)
Block(-3,6,3,126:8)
Block(-3,6,4,126:8)
Block(-3,6,5,126:8)
Block(-3,6,6,126:8)
Block(-3,6,7,126:8)
Block(-3,6,8,126:8)
Block(-3,7,-4,5:5)
Block(-3,7,0,85)
Block(-3,7,4,26:1)
Block(-3,7,7,26:1)
Block(-3,8,-4,5:2)
Block(-3,9,-4,5:2)
Block(-3,10,-4,5:2)
Block(-3,11,-4,125:5)
Block(-3,12,-4,5:2)
Block(-3,13,-4,5:2)
Block(-3,14,-4,136)
Block(-3,14,-3,136)
Block(-3,14,-2,136)
Block(-3,14,-1,136)
Block(-3,14,0,136)
Block(-3,14,1,136)
Block(-3,14,2,136)
Block(-3,14,3,136)
Block(-3,14,4,136)
Block(-3,14,5,136)
Block(-3,14,6,136)
Block(-3,14,7,136)
Block(-3,14,8,136)
Block(-2,0,-7,2)
Block(-2,0,-6,2)
Block(-2,0,-5,2)
Block(-2,0,-4,3)
Block(-2,0,-3,3)
Block(-2,0,-2,126:8)
Block(-2,0,-1,126:8)
Block(-2,0,0,126:8)
Block(-2,0,1,126:8)
Block(-2,0,2,126:8)
Block(-2,0,3,126:8)
Block(-2,0,4,126:8)
Block(-2,0,5,126:8)
Block(-2,0,6,126:8)
Block(-2,0,7,126:8)
Block(-2,0,8,126:8)
Block(-2,1,-4,155)
Block(-2,1,-3,5)
Block(-2,1,-2,164:3)
Block(-2,1,-1,85)
Block(-2,1,0,85)
Block(-2,1,4,164:3)
Block(-2,1,5,85)
Block(-2,1,6,164:2)
Block(-2,1,8,164:3)
Block(-2,2,-3,5)
Block(-2,2,-1,171:7)
Block(-2,2,0,171:7)
Block(-2,2,5,171:7)
Block(-2,3,-3,5)
Block(-2,4,-3,5)
Block(-2,4,-2,53:1)
Block(-2,4,-1,53:1)
Block(-2,4,0,85)
Block(-2,5,-3,5)
Block(-2,5,0,85)
Block(-2,6,-4,35:14)
Block(-2,6,-3,5)
Block(-2,6,0,126:8)
Block(-2,6,1,126:8)
Block(-2,6,2,126:8)
Block(-2,6,3,126:8)
Block(-2,6,4,126:8)
Block(-2,6,5,126:8)
Block(-2,6,6,126:8)
Block(-2,6,7,126:8)
Block(-2,6,8,126:8)
Block(-2,7,-4,5:5)
Block(-2,7,0,85)
Block(-2,8,-4,102)
Block(-2,9,-4,102)
Block(-2,10,-4,5:2)
Block(-2,11,-4,125:5)
Block(-2,11,2,89)
Block(-2,12,-4,125:5)
Block(-2,12,2,85)
Block(-2,13,-4,125:5)
Block(-2,13,2,85)
Block(-2,14,-4,125:5)
Block(-2,15,-4,136)
Block(-2,15,-3,136)
Block(-2,15,-2,136)
Block(-2,15,-1,136)
Block(-2,15,0,136)
Block(-2,15,1,136)
Block(-2,15,2,136)
Block(-2,15,3,136)
Block(-2,15,4,136)
Block(-2,15,5,136)
Block(-2,15,6,136)
Block(-2,15,7,136)
Block(-2,15,8,136)
Block(-1,0,-7,2)
Block(-1,0,-6,2)
Block(-1,0,-5,2)
Block(-1,0,-4,3)
Block(-1,0,-3,3)
Block(-1,0,-2,126:8)
Block(-1,0,-1,126:8)
Block(-1,0,0,126:8)
Block(-1,0,1,126:8)
Block(-1,0,2,126:8)
Block(-1,0,3,126:8)
Block(-1,0,4,126:8)
Block(-1,0,5,126:8)
Block(-1,0,6,126:8)
Block(-1,0,7,126:8)
Block(-1,0,8,126:8)
Block(-1,1,-4,155)
Block(-1,1,-3,5)
Block(-1,1,-2,164:3)
Block(-1,1,-1,85)
Block(-1,1,0,85)
Block(-1,1,5,164)
Block(-1,2,-3,5)
Block(-1,2,-1,171:7)
Block(-1,2,0,171:7)
Block(-1,3,-3,5)
Block(-1,3,-2,53:1)
Block(-1,3,-1,53:1)
Block(-1,3,0,85)
Block(-1,4,-3,5)
Block(-1,4,0,85)
Block(-1,5,-3,5)
Block(-1,6,-4,35:14)
Block(-1,6,-3,5)
Block(-1,6,0,126:8)
Block(-1,6,1,126:8)
Block(-1,6,2,126:8)
Block(-1,6,3,126:8)
Block(-1,6,4,126:8)
Block(-1,6,5,126:8)
Block(-1,6,6,126:8)
Block(-1,6,7,126:8)
Block(-1,6,8,126:8)
Block(-1,7,-4,5:5)
Block(-1,7,0,85)
Block(-1,8,-4,5:2)
Block(-1,9,-4,5:2)
Block(-1,10,-4,5:2)
Block(-1,11,-4,125:5)
Block(-1,12,-4,5:2)
Block(-1,13,-4,5:2)
Block(-1,13,2,85)
Block(-1,14,-4,5:2)
Block(-1,14,2,85)
Block(-1,15,-4,5:2)
Block(-1,15,2,85)
Block(-1,16,-4,136)
Block(-1,16,-3,136)
Block(-1,16,-2,136)
Block(-1,16,-1,136)
Block(-1,16,0,136)
Block(-1,16,1,136)
Block(-1,16,2,136)
Block(-1,16,3,136)
Block(-1,16,4,136)
Block(-1,16,5,136)
Block(-1,16,6,136)
Block(-1,16,7,136)
Block(-1,16,8,136)
Block(0,0,-7,2)
Block(0,0,-6,2)
Block(0,0,-5,2)
Block(0,0,-4,3)
Block(0,0,-3,3)
Block(0,0,-2,126:8)
Block(0,0,-1,126:8)
Block(0,0,0,126:8)
Block(0,0,1,126:8)
Block(0,0,2,126:8)
Block(0,0,3,126:8)
Block(0,0,4,126:8)
Block(0,0,5,126:8)
Block(0,0,6,126:8)
Block(0,0,7,126:8)
Block(0,0,8,126:8)
Block(0,1,-4,155)
Block(0,1,-3,5)
Block(0,1,0,85)
Block(0,2,-4,85)
Block(0,2,-3,5)
Block(0,2,-2,53:1)
Block(0,2,-1,53:1)
Block(0,2,0,85)
Block(0,3,-4,85)
Block(0,3,-3,5)
Block(0,3,0,85)
Block(0,4,-4,85)
Block(0,4,-3,5)
Block(0,5,-4,85)
Block(0,5,-3,5)
Block(0,6,-4,35:14)
Block(0,6,-3,5)
Block(0,6,-2,126:8)
Block(0,6,-1,126:8)
Block(0,6,0,126:8)
Block(0,6,1,126:8)
Block(0,6,2,126:8)
Block(0,6,3,126:8)
Block(0,6,4,126:8)
Block(0,6,5,126:8)
Block(0,6,6,126:8)
Block(0,6,7,126:8)
Block(0,6,8,126:8)
Block(0,7,-4,5:5)
Block(0,7,-3,85)
Block(0,7,-2,85)
Block(0,7,-1,85)
Block(0,7,0,85)
Block(0,8,-4,102)
Block(0,9,-4,102)
Block(0,10,-4,5:2)
Block(0,11,-4,125:5)
Block(0,12,-4,5:2)
Block(0,13,-4,5:2)
Block(0,13,2,85)
Block(0,14,-4,5:2)
Block(0,14,2,85)
Block(0,15,-4,5:2)
Block(0,15,2,85)
Block(0,16,-4,136:1)
Block(0,16,-3,136:1)
Block(0,16,-2,136:1)
Block(0,16,-1,136:1)
Block(0,16,0,136:1)
Block(0,16,1,136:1)
Block(0,16,2,136:1)
Block(0,16,3,136:1)
Block(0,16,4,136:1)
Block(0,16,5,136:1)
Block(0,16,6,136:1)
Block(0,16,7,136:1)
Block(0,16,8,136:1)
Block(1,0,-7,2)
Block(1,0,-6,2)
Block(1,0,-5,2)
Block(1,0,-4,3)
Block(1,0,-3,3)
Block(1,0,-2,126:8)
Block(1,0,-1,126:8)
Block(1,0,0,126:8)
Block(1,0,1,126:8)
Block(1,0,2,126:8)
Block(1,0,3,126:8)
Block(1,0,4,126:8)
Block(1,0,5,126:8)
Block(1,0,6,126:8)
Block(1,0,7,126:8)
Block(1,0,8,126:8)
Block(1,1,-4,155)
Block(1,1,-3,5)
Block(1,1,-2,126:8)
Block(1,1,-1,126:8)
Block(1,1,0,53:3)
Block(1,2,-3,5)
Block(1,3,-3,5)
Block(1,4,-3,5)
Block(1,5,-3,5)
Block(1,6,-4,35:14)
Block(1,6,-3,5)
Block(1,6,-2,126:8)
Block(1,6,-1,126:8)
Block(1,6,0,126:8)
Block(1,6,1,126:8)
Block(1,6,2,126:8)
Block(1,6,3,126:8)
Block(1,6,4,126:8)
Block(1,6,5,126:8)
Block(1,6,6,126:8)
Block(1,6,7,126:8)
Block(1,6,8,126:8)
Block(1,7,-4,5:5)
Block(1,8,-4,5:2)
Block(1,9,-4,5:2)
Block(1,10,-4,5:2)
Block(1,11,-4,125:5)
Block(1,11,2,89)
Block(1,12,-4,125:5)
Block(1,12,2,85)
Block(1,13,-4,125:5)
Block(1,13,2,85)
Block(1,14,-4,125:5)
Block(1,15,-4,136:1)
Block(1,15,-3,136:1)
Block(1,15,-2,136:1)
Block(1,15,-1,136:1)
Block(1,15,0,136:1)
Block(1,15,1,136:1)
Block(1,15,2,136:1)
Block(1,15,3,136:1)
Block(1,15,4,136:1)
Block(1,15,5,136:1)
Block(1,15,6,136:1)
Block(1,15,7,136:1)
Block(1,15,8,136:1)
Block(2,0,-7,2)
Block(2,0,-6,2)
Block(2,0,-5,2)
Block(2,0,-4,3)
Block(2,0,-3,3)
Block(2,0,-2,126:8)
Block(2,0,-1,126:8)
Block(2,0,0,126:8)
Block(2,0,1,126:8)
Block(2,0,2,126:8)
Block(2,0,3,126:8)
Block(2,0,4,126:8)
Block(2,0,5,126:8)
Block(2,0,6,126:8)
Block(2,0,7,126:8)
Block(2,0,8,126:8)
Block(2,1,-4,155)
Block(2,1,-3,5)
Block(2,1,-2,126:8)
Block(2,1,-1,126:8)
Block(2,1,0,53:3)
Block(2,2,-3,5)
Block(2,3,-3,5)
Block(2,4,-3,5)
Block(2,5,-3,5)
Block(2,5,-2,89)
Block(2,6,-4,125:5)
Block(2,6,-3,125)
Block(2,6,-2,126:8)
Block(2,6,-1,126:8)
Block(2,6,0,126:8)
Block(2,6,1,126:8)
Block(2,6,2,126:8)
Block(2,6,3,126:8)
Block(2,6,4,126:8)
Block(2,6,5,126:8)
Block(2,6,6,126:8)
Block(2,6,7,126:8)
Block(2,6,8,126:8)
Block(2,7,-4,5:5)
Block(2,7,-2,26:3)
Block(2,7,1,26:3)
Block(2,7,4,26:3)
Block(2,7,7,26:3)
Block(2,8,-4,125:5)
Block(2,9,-4,125:5)
Block(2,10,-4,125:5)
Block(2,11,-4,125:5)
Block(2,12,-4,5:2)
Block(2,13,-4,5:2)
Block(2,14,-4,136:1)
Block(2,14,-3,136:1)
Block(2,14,-2,136:1)
Block(2,14,-1,136:1)
Block(2,14,0,136:1)
Block(2,14,1,136:1)
Block(2,14,2,136:1)
Block(2,14,3,136:1)
Block(2,14,4,136:1)
Block(2,14,5,136:1)
Block(2,14,6,136:1)
Block(2,14,7,136:1)
Block(2,14,8,136:1)
Block(3,0,-7,2)
Block(3,0,-6,2)
Block(3,0,-5,2)
Block(3,0,-4,3)
Block(3,0,-3,3)
Block(3,0,-2,3)
Block(3,0,-1,3)
Block(3,0,0,3)
Block(3,0,1,3)
Block(3,0,2,3)
Block(3,0,3,3)
Block(3,0,4,3)
Block(3,0,5,3)
Block(3,0,6,2)
Block(3,0,7,2)
Block(3,0,8,2)
Block(3,1,-4,155)
Block(3,1,-3,5)
Block(3,1,-2,5:2)
Block(3,1,-1,5:2)
Block(3,1,0,5:2)
Block(3,1,1,5:2)
Block(3,1,2,5:2)
Block(3,1,3,5:2)
Block(3,1,4,125:5)
Block(3,1,5,5:2)
Block(3,2,-3,5)
Block(3,2,-2,5:2)
Block(3,2,-1,5:2)
Block(3,2,0,5:2)
Block(3,2,1,5:2)
Block(3,2,2,5:2)
Block(3,2,3,5:2)
Block(3,2,4,125:5)
Block(3,2,5,5:2)
Block(3,3,-3,5)
Block(3,3,-2,5:2)
Block(3,3,-1,5:2)
Block(3,3,0,5:2)
Block(3,3,1,5:2)
Block(3,3,2,5:2)
Block(3,3,3,5:2)
Block(3,3,4,125:5)
Block(3,3,5,5:2)
Block(3,4,-3,5)
Block(3,4,-2,5:2)
Block(3,4,-1,5:2)
Block(3,4,0,5:2)
Block(3,4,1,5:2)
Block(3,4,2,5:2)
Block(3,4,3,5:2)
Block(3,4,4,125:5)
Block(3,4,5,5:2)
Block(3,4,6,135:7)
Block(3,4,8,135:6)
Block(3,5,-3,5)
Block(3,5,-2,5:2)
Block(3,5,-1,5:2)
Block(3,5,0,5:2)
Block(3,5,1,5:2)
Block(3,5,2,5:2)
Block(3,5,3,5:2)
Block(3,5,4,125:5)
Block(3,5,5,5:2)
Block(3,5,6,5:2)
Block(3,5,7,5:2)
Block(3,5,8,5:2)
Block(3,6,-4,35:14)
Block(3,6,-3,5)
Block(3,6,-2,5)
Block(3,6,-1,5)
Block(3,6,0,5)
Block(3,6,1,5)
Block(3,6,2,5)
Block(3,6,3,5)
Block(3,6,4,5)
Block(3,6,5,5)
Block(3,6,6,5)
Block(3,6,7,5)
Block(3,6,8,5)
Block(3,7,-4,5:5)
Block(3,7,-3,54:4,14-Chest.nbt)
Block(3,7,-2,26:11)
Block(3,7,-1,58)
Block(3,7,0,54:4,15-Chest.nbt)
Block(3,7,1,26:11)
Block(3,7,2,58)
Block(3,7,3,54:4,16-Chest.nbt)
Block(3,7,4,26:11)
Block(3,7,5,58)
Block(3,7,6,54:4,17-Chest.nbt)
Block(3,7,7,26:11)
Block(3,7,8,58)
Block(3,8,-4,5:2)
Block(3,9,-4,5:2)
Block(3,10,-4,5:2)
Block(3,11,-4,125:5)
Block(3,12,-4,5:2)
Block(3,13,-4,136:1)
Block(3,13,-3,136:1)
Block(3,13,-1,136:3)
Block(3,13,0,136:1)
Block(3,13,1,136:1)
Block(3,13,2,136:1)
Block(3,13,3,136:2)
Block(3,13,5,136:3)
Block(3,13,6,136:1)
Block(3,13,7,136:1)
Block(3,13,8,136:1)
Block(3,14,-2,126:3)
Block(3,14,4,126:3)
Block(4,0,-7,2)
Block(4,0,-6,2)
Block(4,0,-5,2)
Block(4,0,-4,3)
Block(4,0,-3,3)
Block(4,0,-2,2)
Block(4,0,-1,2)
Block(4,0,0,2)
Block(4,0,1,2)
Block(4,0,2,2)
Block(4,0,3,2)
Block(4,0,4,2)
Block(4,0,5,2)
Block(4,0,6,2)
Block(4,0,7,2)
Block(4,0,8,2)
Block(4,1,-4,155)
Block(4,1,-3,5:1)
Block(4,2,-4,85)
Block(4,2,-3,5:1)
Block(4,3,-4,85)
Block(4,3,-3,5:1)
Block(4,4,-4,85)
Block(4,4,-3,5:1)
Block(4,5,-4,85)
Block(4,5,-3,5:1)
Block(4,5,1,126:13)
Block(4,5,4,126:13)
Block(4,5,7,126:13)
Block(4,6,-4,35:14)
Block(4,6,-3,35:14)
Block(4,6,-2,35:14)
Block(4,6,-1,35:14)
Block(4,6,0,35:14)
Block(4,6,1,35:14)
Block(4,6,2,35:14)
Block(4,6,3,35:14)
Block(4,6,4,35:14)
Block(4,6,5,35:14)
Block(4,6,6,35:14)
Block(4,6,7,35:14)
Block(4,6,8,35:14)
Block(4,7,-4,5:5)
Block(4,7,-3,125:5)
Block(4,7,-2,125:5)
Block(4,7,-1,125:5)
Block(4,7,0,125:5)
Block(4,7,1,125:5)
Block(4,7,2,125:5)
Block(4,7,3,125:5)
Block(4,7,4,125:5)
Block(4,7,5,125:5)
Block(4,7,6,125:5)
Block(4,7,7,125:5)
Block(4,7,8,125:5)
Block(4,8,-4,5:2)
Block(4,8,-3,5:2)
Block(4,8,-2,5:2)
Block(4,8,-1,5:2)
Block(4,8,0,5:2)
Block(4,8,1,125:5)
Block(4,8,2,5:2)
Block(4,8,3,5:2)
Block(4,8,4,5:2)
Block(4,8,5,5:2)
Block(4,8,6,5:2)
Block(4,8,7,125:5)
Block(4,8,8,5:2)
Block(4,9,-4,5:2)
Block(4,9,-3,5:2)
Block(4,9,-2,102)
Block(4,9,-1,5:2)
Block(4,9,0,5:2)
Block(4,9,1,125:5)
Block(4,9,2,5:2)
Block(4,9,3,5:2)
Block(4,9,4,102)
Block(4,9,5,5:2)
Block(4,9,6,5:2)
Block(4,9,7,125:5)
Block(4,9,8,5:2)
Block(4,10,-4,5:2)
Block(4,10,-3,5:2)
Block(4,10,-2,5:2)
Block(4,10,-1,5:2)
Block(4,10,0,5:2)
Block(4,10,1,125:5)
Block(4,10,2,5:2)
Block(4,10,3,5:2)
Block(4,10,4,5:2)
Block(4,10,5,5:2)
Block(4,10,6,5:2)
Block(4,10,7,125:5)
Block(4,10,8,5:2)
Block(4,11,-4,125:5)
Block(4,11,-3,125:5)
Block(4,11,-2,125:5)
Block(4,11,-1,125:5)
Block(4,11,0,125:5)
Block(4,11,1,125:5)
Block(4,11,2,125:5)
Block(4,11,3,125:5)
Block(4,11,4,125:5)
Block(4,11,5,125:5)
Block(4,11,6,125:5)
Block(4,11,7,125:5)
Block(4,11,8,125:5)
Block(4,12,-4,136:1)
Block(4,12,-3,5:2)
Block(4,12,-2,5:2)
Block(4,12,-1,5:2)
Block(4,12,0,136:1)
Block(4,12,1,136:1)
Block(4,12,2,136:1)
Block(4,12,3,5:2)
Block(4,12,4,5:2)
Block(4,12,5,5:2)
Block(4,12,6,136:1)
Block(4,12,7,136:1)
Block(4,12,8,136:1)
Block(4,13,-3,136:2)
Block(4,13,-2,125:2)
Block(4,13,-1,136:3)
Block(4,13,3,136:2)
Block(4,13,4,5:2)
Block(4,13,5,136:3)
Block(4,14,-2,126:3)
Block(4,14,4,126:3)
Block(5,0,-7,2)
Block(5,0,-6,2)
Block(5,0,-5,2)
Block(5,0,-4,3)
Block(5,0,-3,3)
Block(5,0,-2,2)
Block(5,0,-1,2)
Block(5,0,0,2)
Block(5,0,1,2)
Block(5,0,2,2)
Block(5,0,3,2)
Block(5,0,4,2)
Block(5,0,5,2)
Block(5,0,6,2)
Block(5,0,7,2)
Block(5,0,8,2)
Block(5,1,-4,155)
Block(5,1,-3,5:1)
Block(5,2,-3,5:1)
Block(5,3,-3,5:1)
Block(5,4,-3,5:1)
Block(5,5,-4,5:1)
Block(5,5,-3,5:1)
Block(5,5,1,126:13)
Block(5,5,4,126:13)
Block(5,5,7,126:13)
Block(5,6,-4,85)
Block(6,0,-7,2)
Block(6,0,-6,2)
Block(6,0,-5,2)
Block(6,0,-4,3)
Block(6,0,-3,3)
Block(6,0,-2,2)
Block(6,0,-1,2)
Block(6,0,0,2)
Block(6,0,1,2)
Block(6,0,2,2)
Block(6,0,3,2)
Block(6,0,4,2)
Block(6,0,5,2)
Block(6,0,6,2)
Block(6,0,7,2)
Block(6,0,8,2)
Block(6,1,-4,155)
Block(6,1,-3,5:1)
Block(6,2,-3,5:1)
Block(6,3,-3,5:1)
Block(6,4,-3,5:1)
Block(6,5,-4,5:1)
Block(6,5,-3,5:1)
Block(6,6,-4,85)
Block(7,0,-7,2)
Block(7,0,-6,2)
Block(7,0,-5,2)
Block(7,0,-4,3)
Block(7,0,-3,3)
Block(7,0,-2,2)
Block(7,0,-1,2:1)
Block(7,0,0,2:9)
Block(7,0,1,2:9)
Block(7,0,2,2)
Block(7,0,3,2)
Block(7,0,4,2)
Block(7,0,5,2)
Block(7,0,6,2)
Block(7,0,7,2)
Block(7,0,8,2)
Block(7,1,-4,155)
Block(7,1,-3,5:1)
Block(7,2,-3,5:1)
Block(7,3,-3,5:1)
Block(7,4,-4,134:6)
Block(7,4,-3,5:1)
Block(7,5,-4,5:1)
Block(7,5,-3,5:1)
Block(7,6,-4,85)

Branch(16,0,0,true,barracks-age-ofC1R0,NORTH,100,0)
Branch(0,0,16,true,barracks-age-ofC0R1,NORTH,100,0)
