

BranchFrequencyGroup: CanOverride:0

CanOverride: true

SmoothRadius: -1

OverrideChildSettings: false

ReplaceAbove:
ReplaceBelow:

MustBeInside: VillageGeneratorStructurePlaceHolder, VillageGeneratorStructuresDelay, VillageGeneratorStructuresDelay2, VillageGeneratorStructuresDelay3, VillageGeneratorStructuresDelay4, VillageGeneratorStructuresDelay5, VillageGeneratorStructuresDelay6, VillageGeneratorStructuresDelay7, VillageGeneratorStructuresDelay8, VillageGeneratorStructuresDelay9, VillageGeneratorStructuresDelay10

Block(-8,0,-7,2)
Block(-8,0,-6,2)
Block(-8,0,-5,2)
Block(-8,0,-4,3)
Block(-8,0,-3,3)
Block(-8,0,-2,2:14)
Block(-8,0,-1,2)
Block(-8,0,0,2)
Block(-8,0,1,2)
Block(-8,0,2,2)
Block(-8,0,3,2)
Block(-8,0,4,2)
Block(-8,0,5,2)
Block(-8,0,6,2)
Block(-8,0,7,2)
Block(-8,0,8,2)
Block(-8,1,-4,155)
Block(-8,1,-3,5:1)
Block(-8,1,-2,134)
Block(-8,1,-1,134)
Block(-8,2,-3,5:1)
Block(-8,3,-3,5:1)
Block(-8,4,-3,5:1)
Block(-8,5,-4,5:1)
Block(-8,5,-3,5:1)
Block(-8,6,-4,85)
Block(-7,0,-7,2)
Block(-7,0,-6,2)
Block(-7,0,-5,2)
Block(-7,0,-4,3)
Block(-7,0,-3,3)
Block(-7,0,-2,2)
Block(-7,0,-1,2)
Block(-7,0,0,2)
Block(-7,0,1,2)
Block(-7,0,2,2)
Block(-7,0,3,2)
Block(-7,0,4,2)
Block(-7,0,5,2)
Block(-7,0,6,2)
Block(-7,0,7,2)
Block(-7,0,8,2)
Block(-7,1,-4,155)
Block(-7,1,-3,5:1)
Block(-7,2,-3,5:1)
Block(-7,2,-2,134)
Block(-7,2,-1,134)
Block(-7,3,-3,5:1)
Block(-7,4,-4,134:6)
Block(-7,4,-3,5:1)
Block(-7,5,-4,5:1)
Block(-7,5,-3,5:1)
Block(-7,6,-4,85)
Block(-6,0,-7,2)
Block(-6,0,-6,2)
Block(-6,0,-5,2)
Block(-6,0,-4,3)
Block(-6,0,-3,3)
Block(-6,0,-2,2)
Block(-6,0,-1,2)
Block(-6,0,0,2)
Block(-6,0,1,2)
Block(-6,0,2,2)
Block(-6,0,3,2)
Block(-6,0,4,2)
Block(-6,0,5,2)
Block(-6,0,6,2)
Block(-6,0,7,2)
Block(-6,0,8,2)
Block(-6,1,-4,155)
Block(-6,1,-3,5:1)
Block(-6,2,-3,5:1)
Block(-6,3,-3,5:1)
Block(-6,3,-2,134)
Block(-6,3,-1,134)
Block(-6,4,-3,5:1)
Block(-6,5,-4,5:1)
Block(-6,5,-3,5:1)
Block(-6,6,-4,85)
Block(-5,0,-7,2)
Block(-5,0,-6,2)
Block(-5,0,-5,2)
Block(-5,0,-4,3)
Block(-5,0,-3,3)
Block(-5,0,-2,2)
Block(-5,0,-1,2:14)
Block(-5,0,0,2)
Block(-5,0,1,2)
Block(-5,0,2,2)
Block(-5,0,3,2)
Block(-5,0,4,2)
Block(-5,0,5,2)
Block(-5,0,6,2)
Block(-5,0,7,2)
Block(-5,0,8,2)
Block(-5,1,-4,155)
Block(-5,1,-3,5:1)
Block(-5,2,-3,5:1)
Block(-5,3,-3,5:1)
Block(-5,4,-4,134:6)
Block(-5,4,-3,5:1)
Block(-5,4,-2,134)
Block(-5,4,-1,134)
Block(-5,5,-4,5:1)
Block(-5,5,-3,5:1)
Block(-5,5,1,136)
Block(-5,5,2,136)
Block(-5,5,3,136)
Block(-5,5,4,136)
Block(-5,5,5,136)
Block(-5,5,6,136)
Block(-5,5,7,136)
Block(-5,5,8,136)
Block(-5,6,-4,85)
Block(-4,0,-7,2)
Block(-4,0,-6,2)
Block(-4,0,-5,2)
Block(-4,0,-4,3)
Block(-4,0,-3,3)
Block(-4,0,-2,2:9)
Block(-4,0,-1,2:1)
Block(-4,0,0,2)
Block(-4,0,1,3)
Block(-4,0,2,3)
Block(-4,0,3,3)
Block(-4,0,4,3)
Block(-4,0,5,2)
Block(-4,0,6,2)
Block(-4,0,7,2)
Block(-4,0,8,2)
Block(-4,1,-4,155)
Block(-4,1,-3,5:1)
Block(-4,1,1,5)
Block(-4,1,2,5)
Block(-4,1,3,5)
Block(-4,1,4,43:5)
Block(-4,2,-3,5:1)
Block(-4,2,1,5)
Block(-4,2,2,5)
Block(-4,2,3,5)
Block(-4,2,4,43:5)
Block(-4,3,-3,5:1)
Block(-4,3,1,5)
Block(-4,3,2,5)
Block(-4,3,3,5)
Block(-4,3,4,43:5)
Block(-4,4,-3,5:1)
Block(-4,4,1,5)
Block(-4,4,2,5)
Block(-4,4,3,5)
Block(-4,4,4,43:5)
Block(-4,4,5,109:7)
Block(-4,4,6,44:13)
Block(-4,4,7,44:13)
Block(-4,4,8,109:6)
Block(-4,5,-4,5:1)
Block(-4,5,-3,5:1)
Block(-4,5,-2,134)
Block(-4,5,-1,134)
Block(-4,5,1,5)
Block(-4,5,2,5)
Block(-4,5,3,5)
Block(-4,5,4,43:5)
Block(-4,5,5,43:5)
Block(-4,5,6,43:5)
Block(-4,5,7,43:5)
Block(-4,5,8,43:5)
Block(-4,6,-4,85)
Block(-4,6,1,136)
Block(-4,6,2,136)
Block(-4,6,3,136)
Block(-4,6,4,136)
Block(-4,6,5,136)
Block(-4,6,6,136)
Block(-4,6,7,136)
Block(-4,6,8,136)
Block(-3,0,-7,2)
Block(-3,0,-6,2)
Block(-3,0,-5,2)
Block(-3,0,-4,3)
Block(-3,0,-3,3)
Block(-3,0,-2,3)
Block(-3,0,-1,3)
Block(-3,0,0,3)
Block(-3,0,1,3)
Block(-3,0,2,3)
Block(-3,0,3,3)
Block(-3,0,4,3)
Block(-3,0,5,2)
Block(-3,0,6,2)
Block(-3,0,7,2)
Block(-3,0,8,2)
Block(-3,1,-4,155)
Block(-3,1,-3,5:1)
Block(-3,1,-2,5:1)
Block(-3,1,-1,5:1)
Block(-3,1,0,5:1)
Block(-3,1,1,5)
Block(-3,1,2,5)
Block(-3,1,3,5)
Block(-3,1,4,5)
Block(-3,2,-3,5:1)
Block(-3,2,-2,5:1)
Block(-3,2,-1,5:1)
Block(-3,2,0,5:1)
Block(-3,2,1,5)
Block(-3,2,2,5)
Block(-3,2,3,5)
Block(-3,2,4,5)
Block(-3,3,-3,5:1)
Block(-3,3,-2,5:1)
Block(-3,3,-1,5:1)
Block(-3,3,0,5:1)
Block(-3,3,1,5)
Block(-3,3,2,5)
Block(-3,3,3,5)
Block(-3,3,4,5)
Block(-3,4,-4,134:6)
Block(-3,4,-3,5:1)
Block(-3,4,-2,5:1)
Block(-3,4,-1,5:1)
Block(-3,4,0,5:1)
Block(-3,4,1,5)
Block(-3,4,2,5)
Block(-3,4,3,5)
Block(-3,4,4,5)
Block(-3,4,5,53:7)
Block(-3,4,6,126:8)
Block(-3,4,7,126:8)
Block(-3,4,8,53:6)
Block(-3,5,-4,5:1)
Block(-3,5,-3,5:1)
Block(-3,5,-2,5:1)
Block(-3,5,-1,5:1)
Block(-3,5,0,5:1)
Block(-3,5,1,5)
Block(-3,5,2,5)
Block(-3,5,3,5)
Block(-3,5,4,5)
Block(-3,5,5,5)
Block(-3,5,6,5)
Block(-3,5,7,5)
Block(-3,5,8,5)
Block(-3,6,-4,85)
Block(-3,6,1,5)
Block(-3,6,2,5)
Block(-3,6,3,5)
Block(-3,6,4,5)
Block(-3,6,5,5)
Block(-3,6,6,5)
Block(-3,6,7,5)
Block(-3,6,8,5)
Block(-3,7,1,136)
Block(-3,7,2,136)
Block(-3,7,3,136)
Block(-3,7,4,136)
Block(-3,7,5,136)
Block(-3,7,6,136)
Block(-3,7,7,136)
Block(-3,7,8,136)
Block(-2,0,-7,2)
Block(-2,0,-6,2)
Block(-2,0,-5,2)
Block(-2,0,-4,3)
Block(-2,0,-3,3)
Block(-2,0,-2,3)
Block(-2,0,-1,3)
Block(-2,0,0,3)
Block(-2,0,1,3)
Block(-2,0,2,3)
Block(-2,0,3,3)
Block(-2,0,4,3)
Block(-2,0,5,2)
Block(-2,0,6,2)
Block(-2,0,7,2)
Block(-2,0,8,2)
Block(-2,1,-4,155)
Block(-2,1,-3,155)
Block(-2,1,-2,155)
Block(-2,1,-1,155)
Block(-2,1,0,155)
Block(-2,1,1,5)
Block(-2,1,2,5)
Block(-2,1,3,5)
Block(-2,1,4,5)
Block(-2,2,0,106:1)
Block(-2,2,1,5)
Block(-2,2,2,5)
Block(-2,2,3,5)
Block(-2,2,4,5)
Block(-2,3,1,5)
Block(-2,3,2,5)
Block(-2,3,3,5)
Block(-2,3,4,5)
Block(-2,4,-3,134:5)
Block(-2,4,-1,134:5)
Block(-2,4,1,5)
Block(-2,4,2,5)
Block(-2,4,3,5)
Block(-2,4,4,5)
Block(-2,4,5,53:7)
Block(-2,4,6,126:8)
Block(-2,4,7,126:8)
Block(-2,4,8,53:6)
Block(-2,5,-4,5:1)
Block(-2,5,-3,5:1)
Block(-2,5,-2,5:1)
Block(-2,5,-1,5:1)
Block(-2,5,0,5:1)
Block(-2,5,1,5)
Block(-2,5,2,5)
Block(-2,5,3,5)
Block(-2,5,4,5)
Block(-2,5,5,5)
Block(-2,5,6,5)
Block(-2,5,7,5)
Block(-2,5,8,5)
Block(-2,6,-4,85)
Block(-2,6,-3,85)
Block(-2,6,-2,85)
Block(-2,6,-1,85)
Block(-2,6,0,85)
Block(-2,6,1,5)
Block(-2,6,2,5)
Block(-2,6,3,5)
Block(-2,6,4,5)
Block(-2,6,5,5)
Block(-2,6,6,5)
Block(-2,6,7,5)
Block(-2,6,8,5)
Block(-2,7,1,136:1)
Block(-2,7,2,136:1)
Block(-2,7,3,136:1)
Block(-2,7,4,136:1)
Block(-2,7,5,136:1)
Block(-2,7,6,136:1)
Block(-2,7,7,136:1)
Block(-2,7,8,136:1)
Block(-1,0,-7,2)
Block(-1,0,-6,2)
Block(-1,0,-5,2)
Block(-1,0,-4,2:9)
Block(-1,0,-3,2:1)
Block(-1,0,-2,2:9)
Block(-1,0,-1,2:9)
Block(-1,0,0,2:9)
Block(-1,0,1,2)
Block(-1,0,2,3)
Block(-1,0,3,3)
Block(-1,0,4,3)
Block(-1,0,5,2)
Block(-1,0,6,2)
Block(-1,0,7,2)
Block(-1,0,8,2)
Block(-1,1,0,106:1)
Block(-1,1,1,43:5)
Block(-1,1,2,5)
Block(-1,1,3,5)
Block(-1,1,4,43:5)
Block(-1,2,0,106:1)
Block(-1,2,1,43:5)
Block(-1,2,2,5)
Block(-1,2,3,5)
Block(-1,2,4,43:5)
Block(-1,3,1,43:5)
Block(-1,3,2,5)
Block(-1,3,3,5)
Block(-1,3,4,43:5)
Block(-1,4,1,43:5)
Block(-1,4,2,5)
Block(-1,4,3,5)
Block(-1,4,4,43:5)
Block(-1,4,5,109:7)
Block(-1,4,6,44:13)
Block(-1,4,7,44:13)
Block(-1,4,8,109:6)
Block(-1,5,1,43:5)
Block(-1,5,2,5)
Block(-1,5,3,5)
Block(-1,5,4,43:5)
Block(-1,5,5,43:5)
Block(-1,5,6,43:5)
Block(-1,5,7,43:5)
Block(-1,5,8,43:5)
Block(-1,6,1,136:1)
Block(-1,6,2,136:1)
Block(-1,6,3,136:1)
Block(-1,6,4,136:1)
Block(-1,6,5,136:1)
Block(-1,6,6,136:1)
Block(-1,6,7,136:1)
Block(-1,6,8,136:1)
Block(0,0,-7,2)
Block(0,0,-6,2)
Block(0,0,-5,2)
Block(0,0,-4,2:9)
Block(0,0,-3,2:9)
Block(0,0,-2,2:9)
Block(0,0,-1,2:9)
Block(0,0,0,2:9)
Block(0,0,1,2)
Block(0,0,2,2)
Block(0,0,3,2)
Block(0,0,4,2)
Block(0,0,5,2)
Block(0,0,6,2)
Block(0,0,7,2)
Block(0,0,8,2)
Block(0,1,1,106:2)
Block(0,2,1,106:2)
Block(0,5,1,136:1)
Block(0,5,2,136:1)
Block(0,5,3,136:1)
Block(0,5,4,136:1)
Block(0,5,5,136:1)
Block(0,5,6,136:1)
Block(0,5,7,136:1)
Block(0,5,8,136:1)
Block(1,0,-7,2)
Block(1,0,-6,2)
Block(1,0,-5,2)
Block(1,0,-4,2)
Block(1,0,-3,2)
Block(1,0,-2,2)
Block(1,0,-1,2)
Block(1,0,0,2)
Block(1,0,1,2)
Block(1,0,2,2)
Block(1,0,3,2)
Block(1,0,4,2)
Block(1,0,5,2)
Block(1,0,6,2)
Block(1,0,7,2)
Block(1,0,8,2)
Block(2,0,-7,2)
Block(2,0,-6,2)
Block(2,0,-5,2)
Block(2,0,-4,2)
Block(2,0,-3,2)
Block(2,0,-2,2)
Block(2,0,-1,2)
Block(2,0,0,2)
Block(2,0,1,2)
Block(2,0,2,2)
Block(2,0,3,2)
Block(2,0,4,2)
Block(2,0,5,2)
Block(2,0,6,2)
Block(2,0,7,2)
Block(2,0,8,2)
