

BranchFrequency: 10

BranchFrequencyGroup: CanOverride:0

CanOverride: true

SmoothRadius: -1

OverrideChildSettings: false

ReplaceAbove:
ReplaceBelow:

MustBeInside: VillageGeneratorStructurePlaceHolder, VillageGeneratorStructuresDelay, VillageGeneratorStructuresDelay2, VillageGeneratorStructuresDelay3, VillageGeneratorStructuresDelay4, VillageGeneratorStructuresDelay5, VillageGeneratorStructuresDelay6, VillageGeneratorStructuresDelay7, VillageGeneratorStructuresDelay8, VillageGeneratorStructuresDelay9, VillageGeneratorStructuresDelay10

Block(-8,0,-6,136)
Block(-8,0,-5,136)
Block(-8,0,-4,136)
Block(-8,0,-3,136)
Block(-8,0,-2,136)
Block(-8,0,-1,136:3)
Block(-7,0,-6,5:3)
Block(-7,0,-5,5:3)
Block(-7,0,-4,5:3)
Block(-7,0,-3,5:3)
Block(-7,0,-2,5:3)
Block(-7,0,-1,136:3)
Block(-7,8,-6,96:6)
Block(-6,0,-6,5:3)
Block(-6,0,-5,5:3)
Block(-6,0,-4,5:3)
Block(-6,0,-3,5:3)
Block(-6,0,-2,5:3)
Block(-6,0,-1,136:3)
Block(-6,1,-3,135)
Block(-6,1,-2,85)
Block(-6,2,-2,85)
Block(-6,7,-6,85)
Block(-6,8,-7,96:4)
Block(-6,8,-6,89)
Block(-6,8,-5,96:5)
Block(-6,9,-6,126)
Block(-5,0,-6,5:3)
Block(-5,0,-5,5:3)
Block(-5,0,-4,5:3)
Block(-5,0,-3,5:3)
Block(-5,0,-2,5:3)
Block(-5,0,-1,136:3)
Block(-5,1,-6,85)
Block(-5,1,-3,135:5)
Block(-5,1,-2,85)
Block(-5,2,-6,85)
Block(-5,2,-3,135)
Block(-5,2,-2,85)
Block(-5,3,-6,85)
Block(-5,3,-2,85)
Block(-5,4,-6,85)
Block(-5,5,-6,85)
Block(-5,6,-6,85)
Block(-5,7,-6,85)
Block(-5,8,-6,96:7)
Block(-4,0,-6,5:3)
Block(-4,0,-5,5:3)
Block(-4,0,-4,5:3)
Block(-4,0,-3,5:3)
Block(-4,0,-2,5:3)
Block(-4,0,-1,136:3)
Block(-4,2,-3,135:5)
Block(-4,2,-2,85)
Block(-4,3,-6,5:2)
Block(-4,3,-3,135)
Block(-4,3,-2,85)
Block(-4,4,-6,5:2)
Block(-4,4,-2,85)
Block(-4,5,-6,5:2)
Block(-4,5,-2,50:5)
Block(-4,6,-6,5:2)
Block(-4,7,-6,5:2)
Block(-3,0,-6,5:3)
Block(-3,0,-5,5:3)
Block(-3,0,-4,5:3)
Block(-3,0,-3,5:3)
Block(-3,0,-2,5:3)
Block(-3,0,-1,136:3)
Block(-3,3,-6,5:2)
Block(-3,3,-3,5:2)
Block(-3,3,-2,85)
Block(-3,4,-6,5:2)
Block(-3,4,-2,85)
Block(-3,4,-1,85)
Block(-3,5,-6,5:2)
Block(-3,6,-6,5:2)
Block(-3,7,-6,5:2)
Block(-3,9,-6,96:6)
Block(-2,0,-6,5:3)
Block(-2,0,-5,5:3)
Block(-2,0,-4,5:3)
Block(-2,0,-3,5:3)
Block(-2,0,-2,5:3)
Block(-2,0,-1,136:3)
Block(-2,3,-6,5:2)
Block(-2,3,-3,5:2)
Block(-2,3,-2,5:2)
Block(-2,4,-6,5:2)
Block(-2,4,-1,85)
Block(-2,5,-6,5:2)
Block(-2,6,-6,5:2)
Block(-2,7,-6,5:2)
Block(-2,8,-6,85)
Block(-2,9,-7,96:4)
Block(-2,9,-6,89)
Block(-2,9,-5,96:5)
Block(-2,10,-6,126)
Block(-1,0,-6,5:3)
Block(-1,0,-5,5:3)
Block(-1,0,-4,5:3)
Block(-1,0,-3,5:3)
Block(-1,0,-2,5:3)
Block(-1,0,-1,136:3)
Block(-1,3,-6,5:2)
Block(-1,3,-3,5:2)
Block(-1,3,-2,85)
Block(-1,4,-6,5:2)
Block(-1,4,-2,85)
Block(-1,4,-1,85)
Block(-1,5,-6,5:2)
Block(-1,6,-6,5:2)
Block(-1,7,-6,5:2)
Block(-1,9,-6,96:7)
Block(0,0,-6,5:3)
Block(0,0,-5,5:3)
Block(0,0,-4,5:3)
Block(0,0,-3,5:3)
Block(0,0,-2,5:3)
Block(0,0,-1,136:3)
Block(0,2,-3,135:4)
Block(0,2,-2,85)
Block(0,3,-6,5:2)
Block(0,3,-3,135:1)
Block(0,3,-2,85)
Block(0,4,-6,5:2)
Block(0,4,-2,85)
Block(0,5,-6,5:2)
Block(0,5,-2,50:5)
Block(0,6,-6,5:2)
Block(0,7,-6,5:2)
Block(1,0,-6,5:3)
Block(1,0,-5,5:3)
Block(1,0,-4,5:3)
Block(1,0,-3,5:3)
Block(1,0,-2,5:3)
Block(1,0,-1,136:3)
Block(1,1,-6,85)
Block(1,1,-3,135:4)
Block(1,1,-2,85)
Block(1,2,-6,85)
Block(1,2,-3,135:1)
Block(1,2,-2,85)
Block(1,3,-6,85)
Block(1,3,-2,85)
Block(1,4,-6,85)
Block(1,5,-6,85)
Block(1,6,-6,85)
Block(1,7,-6,85)
Block(1,8,-6,96:6)
Block(2,0,-6,5:3)
Block(2,0,-5,5:3)
Block(2,0,-4,5:3)
Block(2,0,-3,5:3)
Block(2,0,-2,5:3)
Block(2,0,-1,136:3)
Block(2,1,-3,135:1)
Block(2,1,-2,85)
Block(2,2,-2,85)
Block(2,7,-6,85)
Block(2,8,-7,96:4)
Block(2,8,-6,89)
Block(2,8,-5,96:5)
Block(2,9,-6,126)
Block(3,0,-6,5:3)
Block(3,0,-5,5:3)
Block(3,0,-4,5:3)
Block(3,0,-3,5:3)
Block(3,0,-2,5:3)
Block(3,0,-1,136:3)
Block(3,8,-6,96:7)
Block(4,0,-6,136:1)
Block(4,0,-5,136:1)
Block(4,0,-4,136:1)
Block(4,0,-3,136:1)
Block(4,0,-2,136:1)
Block(4,0,-1,136:1)
