

BranchFrequencyGroup: CanOverride:0

CanOverride: true

SmoothRadius: -1

OverrideChildSettings: false

ReplaceAbove:
ReplaceBelow:

MustBeInside: VillageGeneratorWaterStructurePlaceHolder, VillageGeneratorStructuresDelayWater, VillageGeneratorStructuresDelay2Water, VillageGeneratorStructuresDelay3Water, VillageGeneratorStructuresDelay4Water, VillageGeneratorStructuresDelay5Water, VillageGeneratorStructuresDelay6Water, VillageGeneratorStructuresDelay7Water, VillageGeneratorStructuresDelay8Water, VillageGeneratorStructuresDelay9Water, VillageGeneratorStructuresDelay10Water, VillageGeneratorWallBlocksWater, VillageGeneratorWallCornerBlocksWater, VillageGeneratorWallCornerBlocksOverrideWater

ReplacesBO3: VillageGeneratorWallBlocksWater, VillageGeneratorWallCornerBlocksWater, VillageGeneratorWallCornerBlocksOverrideWater

Block(-8,0,-2,134:6)
Block(-8,0,-1,5:1)
Block(-8,0,0,134:7)
Block(-8,1,-2,5:1)
Block(-8,1,-1,5:1)
Block(-8,1,0,5:1)
Block(-8,1,1,134:7)
Block(-8,2,-3,5:1)
Block(-8,2,1,5:1)
Block(-8,8,-5,35:4)
Block(-8,8,-4,35:4)
Block(-8,8,-3,35:4)
Block(-8,8,-2,35:14)
Block(-8,8,-1,35:14)
Block(-8,8,0,35:14)
Block(-8,8,1,35:4)
Block(-8,8,2,35:4)
Block(-8,8,3,35:4)
Block(-8,11,-5,35:4)
Block(-8,11,-4,35:4)
Block(-8,11,-3,35:14)
Block(-8,11,-2,35:4)
Block(-8,11,-1,35:14)
Block(-8,11,0,35:4)
Block(-8,11,1,35:14)
Block(-8,11,2,35:4)
Block(-8,11,3,35:4)
Block(-7,0,-2,134:6)
Block(-7,0,-1,5:1)
Block(-7,0,0,134:7)
Block(-7,1,-2,5:1)
Block(-7,1,-1,5:1)
Block(-7,1,0,5:1)
Block(-7,1,1,134:7)
Block(-7,2,-3,5:1)
Block(-7,2,1,5:1)
Block(-7,9,-5,35:4)
Block(-7,9,-4,35:4)
Block(-7,9,-3,35:14)
Block(-7,9,-2,35:4)
Block(-7,9,-1,35:14)
Block(-7,9,0,35:4)
Block(-7,9,1,35:14)
Block(-7,9,2,35:4)
Block(-7,9,3,35:4)
Block(-7,10,-5,35:4)
Block(-7,10,-4,35:14)
Block(-7,10,-3,35:14)
Block(-7,10,-2,35:14)
Block(-7,10,-1,35:14)
Block(-7,10,0,35:14)
Block(-7,10,1,35:14)
Block(-7,10,2,35:14)
Block(-7,10,3,35:4)
Block(-6,0,-2,134:6)
Block(-6,0,-1,5:1)
Block(-6,0,0,134:7)
Block(-6,1,-2,5:1)
Block(-6,1,-1,5:1)
Block(-6,1,0,5:1)
Block(-6,1,1,134:7)
Block(-6,2,-3,5:1)
Block(-6,2,1,5:1)
Block(-5,0,-2,134:6)
Block(-5,0,-1,5:1)
Block(-5,0,0,134:7)
Block(-5,1,-2,5:1)
Block(-5,1,-1,5:1)
Block(-5,1,0,5:1)
Block(-5,1,1,134:7)
Block(-5,2,-3,5:1)
Block(-5,2,1,5:1)
Block(-5,3,-3,126)
Block(-5,3,1,126)
Block(-4,0,-2,134:6)
Block(-4,0,-1,5:1)
Block(-4,0,0,134:7)
Block(-4,1,-2,5:1)
Block(-4,1,-1,5:1)
Block(-4,1,0,5:1)
Block(-4,1,1,134:7)
Block(-4,2,-3,5:1)
Block(-4,2,1,5:1)
Block(-4,3,-3,126)
Block(-4,3,1,126)
Block(-3,0,-2,134:6)
Block(-3,0,-1,5:1)
Block(-3,0,0,134:7)
Block(-3,1,-2,5:1)
Block(-3,1,-1,5:1)
Block(-3,1,0,5:1)
Block(-3,1,1,134:7)
Block(-3,2,-3,5:1)
Block(-3,2,1,5:1)
Block(-3,3,-3,126)
Block(-3,3,1,126)
Block(-2,0,-2,134:6)
Block(-2,0,-1,5:1)
Block(-2,0,0,134:7)
Block(-2,1,-2,5:1)
Block(-2,1,-1,5:1)
Block(-2,1,0,5:1)
Block(-2,1,1,134:7)
Block(-2,2,-3,5:1)
Block(-2,2,-2,85)
Block(-2,2,-1,126:1)
Block(-2,2,0,85)
Block(-2,2,1,5:1)
Block(-2,3,-3,126)
Block(-2,3,-2,85)
Block(-2,3,0,85)
Block(-2,3,1,126)
Block(-2,4,-2,50:5)
Block(-2,4,0,50:5)
Block(-1,0,-1,53:5)
Block(-1,1,-2,5:1)
Block(-1,1,-1,5:1)
Block(-1,1,0,5:1)
Block(-1,2,-2,5:1)
Block(-1,2,-1,5:1)
Block(-1,2,0,5:1)
Block(-1,3,-2,126)
Block(-1,3,0,126)
Block(0,1,-1,53:5)
Block(0,2,-1,5)
Block(0,3,-1,126)
Block(1,2,-1,53:5)
Block(1,3,-1,5)
Block(1,4,-1,5)
Block(1,5,-1,126)
Block(2,4,-1,126:8)
Block(2,5,-1,53:1)
