

BranchFrequency: 10

BranchFrequencyGroup: CanOverride:0

CanOverride: true

SmoothRadius: -1

OverrideChildSettings: false

ReplaceAbove:
ReplaceBelow:

MustBeInside: VillageGeneratorWaterStructurePlaceHolder, VillageGeneratorStructuresDelayWater, VillageGeneratorStructuresDelay2Water, VillageGeneratorStructuresDelay3Water, VillageGeneratorStructuresDelay4Water, VillageGeneratorStructuresDelay5Water, VillageGeneratorStructuresDelay6Water, VillageGeneratorStructuresDelay7Water, VillageGeneratorStructuresDelay8Water, VillageGeneratorStructuresDelay9Water, VillageGeneratorStructuresDelay10Water, VillageGeneratorWallBlocksWater, VillageGeneratorWallCornerBlocksWater, VillageGeneratorWallCornerBlocksOverrideWater

ReplacesBO3: VillageGeneratorWallBlocksWater, VillageGeneratorWallCornerBlocksWater, VillageGeneratorWallCornerBlocksOverrideWater

Block(-4,4,-1,53:4)
Block(-4,5,-1,53)
Block(-3,2,-1,53:4)
Block(-3,3,-1,5)
Block(-3,4,-1,5)
Block(-3,5,-1,126)
Block(-2,1,-1,53:4)
Block(-2,2,-1,5)
Block(-2,3,-1,126)
Block(-1,0,-1,53:4)
Block(-1,1,-2,5:1)
Block(-1,1,-1,5)
Block(-1,1,0,5:1)
Block(-1,2,-2,5:1)
Block(-1,2,-1,5)
Block(-1,2,0,5:1)
Block(-1,3,-2,126)
Block(-1,3,-1,5)
Block(-1,3,0,126)
Block(0,0,-2,134:6)
Block(0,0,-1,5:1)
Block(0,0,0,134:7)
Block(0,1,-2,5:1)
Block(0,1,-1,5:1)
Block(0,1,0,5:1)
Block(0,1,1,134:7)
Block(0,2,-3,5:1)
Block(0,2,1,5:1)
Block(0,3,-3,126)
Block(0,3,-2,5)
Block(0,3,-1,50:1)
Block(0,3,0,5)
Block(0,3,1,126)
Block(0,4,-1,126)
Block(1,0,-2,134:6)
Block(1,0,-1,5:1)
Block(1,0,0,134:7)
Block(1,1,-2,5:1)
Block(1,1,-1,5:1)
Block(1,1,0,5:1)
Block(1,1,1,134:7)
Block(1,2,-3,5:1)
Block(1,2,1,5:1)
Block(1,3,-3,126)
Block(1,3,-2,5)
Block(1,3,0,5)
Block(1,3,1,126)
Block(1,4,-1,126)
Block(2,0,-2,134:6)
Block(2,0,-1,5:1)
Block(2,0,0,134:7)
Block(2,1,-2,5:1)
Block(2,1,-1,5:1)
Block(2,1,0,5:1)
Block(2,1,1,134:7)
Block(2,2,-3,5:1)
Block(2,2,-2,5)
Block(2,2,0,5)
Block(2,2,1,5:1)
Block(2,3,-3,126)
Block(2,3,-2,5)
Block(2,3,0,5)
Block(2,3,1,126)
Block(2,4,-1,126)
Block(3,0,-2,134:6)
Block(3,0,-1,5:1)
Block(3,0,0,134:7)
Block(3,1,-2,5:1)
Block(3,1,-1,5:1)
Block(3,1,0,5:1)
Block(3,1,1,134:7)
Block(3,2,-3,5:1)
Block(3,2,-2,53:1)
Block(3,2,0,53:1)
Block(3,2,1,5:1)
Block(3,3,-2,53:5)
Block(3,3,0,53:5)
Block(3,4,-1,126)
Block(4,0,-2,134:6)
Block(4,0,-1,5:1)
Block(4,0,0,134:7)
Block(4,1,-2,5:1)
Block(4,1,-1,5:1)
Block(4,1,0,5:1)
Block(4,1,1,134:7)
Block(4,2,-3,5:1)
Block(4,2,-2,50:3)
Block(4,2,0,50:4)
Block(4,2,1,5:1)
Block(5,0,-2,134:6)
Block(5,0,-1,5:1)
Block(5,0,0,134:7)
Block(5,1,-2,5:1)
Block(5,1,-1,5:2)
Block(5,1,0,5:1)
Block(5,1,1,134:7)
Block(5,2,-3,5:1)
Block(5,2,1,5:1)
Block(5,13,-1,5:2)
Block(5,14,-1,85)
Block(6,0,-2,134:6)
Block(6,0,-1,5:1)
Block(6,0,0,134:7)
Block(6,1,-2,5:1)
Block(6,1,-1,5:1)
Block(6,1,0,5:1)
Block(6,1,1,134:7)
Block(6,2,-3,5:1)
Block(6,2,-1,5:2)
Block(6,2,1,5:1)
Block(6,3,-1,5:2)
Block(6,4,-1,5:2)
Block(6,5,-1,5:2)
Block(6,6,-1,5:2)
Block(6,7,-1,5:2)
Block(6,8,-1,5:2)
Block(6,9,-1,5:2)
Block(6,10,-1,5:2)
Block(6,11,-5,5:2)
Block(6,11,-4,5:2)
Block(6,11,-3,5:2)
Block(6,11,-2,5:2)
Block(6,11,-1,5:2)
Block(6,11,0,5:2)
Block(6,11,1,5:2)
Block(6,11,2,5:2)
Block(6,11,3,5:2)
Block(6,12,-1,5:2)
Block(6,13,-2,5:2)
Block(6,13,-1,5:2)
Block(6,13,0,5:2)
Block(6,14,-2,85)
Block(6,14,0,85)
Block(7,0,-2,134:6)
Block(7,0,-1,5:1)
Block(7,0,0,134:7)
Block(7,1,-2,5:1)
Block(7,1,-1,5:2)
Block(7,1,0,5:1)
Block(7,1,1,134:7)
Block(7,2,-3,5:1)
Block(7,2,1,5:1)
Block(7,4,-1,50:1)
Block(7,7,-4,35:4)
Block(7,7,-3,35:4)
Block(7,7,-2,35:4)
Block(7,7,-1,35:14)
Block(7,7,0,35:4)
Block(7,7,1,35:4)
Block(7,7,2,35:4)
Block(7,11,-5,35:4)
Block(7,11,-4,35:4)
Block(7,11,-3,35:4)
Block(7,11,-2,35:4)
Block(7,11,-1,35:4)
Block(7,11,0,35:4)
Block(7,11,1,35:4)
Block(7,11,2,35:4)
Block(7,11,3,35:4)
Block(7,12,-4,35:4)
Block(7,12,-3,35:4)
Block(7,12,-2,35:14)
Block(7,12,-1,35:14)
Block(7,12,0,35:14)
Block(7,12,1,35:4)
Block(7,12,2,35:4)
Block(7,13,-1,5:2)
Block(7,14,-1,85)

Branch(16,0,0,true,viking-ship-smallC1R0,NORTH,100,0)
