

BranchFrequencyGroup: CanOverride:0

CanOverride: true

SmoothRadius: -1

OverrideChildSettings: false

ReplaceAbove:
ReplaceBelow:

MustBeInside: VillageGeneratorStructurePlaceHolder, VillageGeneratorStructuresDelay, VillageGeneratorStructuresDelay2, VillageGeneratorStructuresDelay3, VillageGeneratorStructuresDelay4, VillageGeneratorStructuresDelay5, VillageGeneratorStructuresDelay6, VillageGeneratorStructuresDelay7, VillageGeneratorStructuresDelay8, VillageGeneratorStructuresDelay9, VillageGeneratorStructuresDelay10

Block(-8,0,-7,2)
Block(-8,0,-6,2)
Block(-8,0,-5,2)
Block(-8,0,-4,2)
Block(-8,0,-3,2)
Block(-8,0,-2,2)
Block(-8,0,-1,2)
Block(-8,0,0,2)
Block(-8,0,1,2)
Block(-8,0,2,2)
Block(-8,0,3,2)
Block(-8,0,4,2)
Block(-8,0,5,2)
Block(-8,0,6,2)
Block(-8,0,7,2)
Block(-7,0,-7,2)
Block(-7,0,-6,2)
Block(-7,0,-5,2)
Block(-7,0,-4,2)
Block(-7,0,-3,2)
Block(-7,0,-2,2)
Block(-7,0,-1,2)
Block(-7,0,0,2)
Block(-7,0,1,2)
Block(-7,0,2,2)
Block(-7,0,3,2)
Block(-7,0,4,2)
Block(-7,0,5,2)
Block(-7,0,6,2)
Block(-7,0,7,2)
Block(-6,0,-7,2)
Block(-6,0,-6,2)
Block(-6,0,-5,2)
Block(-6,0,-4,2)
Block(-6,0,-3,2)
Block(-6,0,-2,2)
Block(-6,0,-1,2)
Block(-6,0,0,2)
Block(-6,0,1,2)
Block(-6,0,2,2)
Block(-6,0,3,2)
Block(-6,0,4,2)
Block(-6,0,5,2)
Block(-6,0,6,2)
Block(-6,0,7,2)
Block(-5,0,-7,2)
Block(-5,0,-6,2)
Block(-5,0,-5,2)
Block(-5,0,-4,2)
Block(-5,0,-3,2)
Block(-5,0,-2,2)
Block(-5,0,-1,2)
Block(-5,0,0,2)
Block(-5,0,1,2)
Block(-5,0,2,2)
Block(-5,0,3,2)
Block(-5,0,4,2)
Block(-5,0,5,2)
Block(-5,0,6,2)
Block(-5,0,7,2)
Block(-4,0,-7,2)
Block(-4,0,-6,2)
Block(-4,0,-5,2)
Block(-4,0,-4,2)
Block(-4,0,-3,2)
Block(-4,0,-2,2)
Block(-4,0,-1,2)
Block(-4,0,0,2)
Block(-4,0,1,2)
Block(-4,0,2,2)
Block(-4,0,3,2)
Block(-4,0,4,2)
Block(-4,0,5,2)
Block(-4,0,6,2)
Block(-4,0,7,2)
Block(-3,0,-7,2)
Block(-3,0,-6,2)
Block(-3,0,-5,2)
Block(-3,0,-4,2)
Block(-3,0,-3,2)
Block(-3,0,-2,2)
Block(-3,0,-1,2)
Block(-3,0,0,2)
Block(-3,0,1,2)
Block(-3,0,2,2)
Block(-3,0,3,2)
Block(-3,0,4,2)
Block(-3,0,5,2)
Block(-3,0,6,2)
Block(-3,0,7,2)
Block(-2,0,-7,2)
Block(-2,0,-6,2)
Block(-2,0,-5,2)
Block(-2,0,-4,2)
Block(-2,0,-3,2)
Block(-2,0,-2,2)
Block(-2,0,-1,2)
Block(-2,0,0,2)
Block(-2,0,1,2)
Block(-2,0,2,2)
Block(-2,0,3,2)
Block(-2,0,4,2)
Block(-2,0,5,2)
Block(-2,0,6,2)
Block(-2,0,7,2)
Block(-1,0,-7,2)
Block(-1,0,-6,2)
Block(-1,0,-5,2)
Block(-1,0,-4,2)
Block(-1,0,-3,2)
Block(-1,0,-2,2)
Block(-1,0,-1,2)
Block(-1,0,0,2)
Block(-1,0,1,2)
Block(-1,0,2,2)
Block(-1,0,3,2)
Block(-1,0,4,2)
Block(-1,0,5,2)
Block(-1,0,6,2)
Block(-1,0,7,2)
Block(0,0,-7,2)
Block(0,0,-6,2)
Block(0,0,-5,2)
Block(0,0,-4,2)
Block(0,0,-3,2)
Block(0,0,-2,2)
Block(0,0,-1,2)
Block(0,0,0,2)
Block(0,0,1,2)
Block(0,0,2,2)
Block(0,0,3,2)
Block(0,0,4,2)
Block(0,0,5,2)
Block(0,0,6,2)
Block(0,0,7,2)
Block(1,0,-7,2)
Block(1,0,-6,2)
Block(1,0,-5,2)
Block(1,0,-4,2)
Block(1,0,-3,2)
Block(1,0,-2,2)
Block(1,0,-1,2)
Block(1,0,0,2)
Block(1,0,1,2)
Block(1,0,2,2)
Block(1,0,3,2)
Block(1,0,4,2)
Block(1,0,5,2)
Block(1,0,6,2)
Block(1,0,7,2)
Block(2,0,-7,2)
Block(2,0,-6,2)
Block(2,0,-5,2)
Block(2,0,-4,2)
Block(2,0,-3,2)
Block(2,0,-2,2)
Block(2,0,-1,2)
Block(2,0,0,2)
Block(2,0,1,2)
Block(2,0,2,2)
Block(2,0,3,2)
Block(2,0,4,2)
Block(2,0,5,2)
Block(2,0,6,2)
Block(2,0,7,2)
Block(3,0,-7,2)
Block(3,0,-6,2)
Block(3,0,-5,2)
Block(3,0,-4,2)
Block(3,0,-3,2)
Block(3,0,-2,2)
Block(3,0,-1,2)
Block(3,0,0,2)
Block(3,0,1,2)
Block(3,0,2,2)
Block(3,0,3,2)
Block(3,0,4,2)
Block(3,0,5,2)
Block(3,0,6,2)
Block(3,0,7,2)
Block(4,0,-7,2)
Block(4,0,-6,2)
Block(4,0,-5,2)
Block(4,0,-4,2)
Block(4,0,-3,2)
Block(4,0,-2,2)
Block(4,0,-1,2)
Block(4,0,0,2)
Block(4,0,1,2)
Block(4,0,2,2)
Block(4,0,3,2)
Block(4,0,4,2)
Block(4,0,5,2)
Block(4,0,6,2)
Block(4,0,7,2)
Block(5,0,-7,2)
Block(5,0,-6,2)
Block(5,0,-5,2)
Block(5,0,-4,2)
Block(5,0,-3,2)
Block(5,0,-2,2)
Block(5,0,-1,2)
Block(5,0,0,2)
Block(5,0,1,2)
Block(5,0,2,2)
Block(5,0,3,2)
Block(5,0,4,2)
Block(5,0,5,2)
Block(5,0,6,2)
Block(5,0,7,2)
Block(5,4,-7,136)
Block(5,4,-6,136)
Block(5,4,-5,136)
Block(5,4,-4,136)
Block(5,4,-3,136)
Block(5,4,-2,136)
Block(5,4,-1,136)
Block(5,4,0,136)
Block(5,4,1,136)
Block(5,4,2,136)
Block(5,4,3,136)
Block(5,4,4,136)
Block(6,0,-7,3)
Block(6,0,-6,3)
Block(6,0,-5,3)
Block(6,0,-4,3)
Block(6,0,-3,3)
Block(6,0,-2,3)
Block(6,0,-1,3)
Block(6,0,0,3)
Block(6,0,1,3)
Block(6,0,2,3)
Block(6,0,3,3)
Block(6,0,4,2)
Block(6,0,5,2)
Block(6,0,6,2)
Block(6,0,7,2)
Block(6,1,-7,98)
Block(6,1,-6,98)
Block(6,1,-5,98)
Block(6,1,-4,98)
Block(6,1,-3,98)
Block(6,1,-2,98)
Block(6,1,-1,98)
Block(6,1,0,98)
Block(6,1,1,98)
Block(6,1,2,98)
Block(6,1,3,98)
Block(6,1,4,85)
Block(6,2,-7,98)
Block(6,2,-6,98)
Block(6,2,-5,98)
Block(6,2,-4,98)
Block(6,2,-3,98)
Block(6,2,-2,98)
Block(6,2,-1,98)
Block(6,2,0,98)
Block(6,2,1,98)
Block(6,2,2,98)
Block(6,2,3,98)
Block(6,2,4,85)
Block(6,3,-7,98)
Block(6,3,-6,98)
Block(6,3,-5,98)
Block(6,3,-4,98)
Block(6,3,-3,98)
Block(6,3,-2,98)
Block(6,3,4,85)
Block(6,4,-7,98)
Block(6,4,-6,98)
Block(6,4,-5,98)
Block(6,4,-4,98)
Block(6,4,-3,98)
Block(6,4,-2,98)
Block(6,4,4,85)
Block(6,5,-7,136)
Block(6,5,-6,136)
Block(6,5,-5,136)
Block(6,5,-4,136)
Block(6,5,-3,136)
Block(6,5,-2,136)
Block(6,5,-1,136)
Block(6,5,0,136)
Block(6,5,1,136)
Block(6,5,2,136)
Block(6,5,3,136)
Block(6,5,4,136)
Block(7,0,-7,2)
Block(7,0,-6,2)
Block(7,0,-5,3)
Block(7,0,-4,3)
Block(7,0,-3,3)
Block(7,0,-2,3)
Block(7,0,-1,2)
Block(7,0,0,2)
Block(7,0,1,2)
Block(7,0,2,2)
Block(7,0,3,2)
Block(7,0,4,2)
Block(7,0,5,2)
Block(7,0,6,2)
Block(7,0,7,2)
Block(7,1,-5,58)
Block(7,1,-4,61:5,1-Furnace.nbt)
Block(7,1,-3,61:5,2-Furnace.nbt)
Block(7,1,-2,61:5,3-Furnace.nbt)
Block(7,1,4,126:5)
Block(7,1,5,126:5)
Block(7,1,6,126:5)
Block(7,6,-7,136)
Block(7,6,-6,136)
Block(7,6,-5,136)
Block(7,6,-4,136)
Block(7,6,-3,136)
Block(7,6,-2,136)
Block(7,6,-1,136)
Block(7,6,0,136)
Block(7,6,1,136)
Block(7,6,2,136)
Block(7,6,3,136)
Block(7,6,4,136)

Branch(16,0,0,true,blacksmith-age-ofC1R1,NORTH,100,0)
