

BranchFrequencyGroup: CanOverride:0

CanOverride: true

SmoothRadius: -1

OverrideChildSettings: false

ReplaceAbove:
ReplaceBelow:

MustBeInside: VillageGeneratorStructurePlaceHolder, VillageGeneratorStructuresDelay, VillageGeneratorStructuresDelay2, VillageGeneratorStructuresDelay3, VillageGeneratorStructuresDelay4, VillageGeneratorStructuresDelay5, VillageGeneratorStructuresDelay6, VillageGeneratorStructuresDelay7, VillageGeneratorStructuresDelay8, VillageGeneratorStructuresDelay9, VillageGeneratorStructuresDelay10

Block(-8,0,-7,2)
Block(-8,0,-6,2)
Block(-8,0,-5,2)
Block(-8,0,-4,2)
Block(-8,0,-3,2)
Block(-8,0,-2,2)
Block(-8,0,-1,3)
Block(-8,0,0,2)
Block(-8,0,1,2)
Block(-8,0,2,2)
Block(-8,0,3,2)
Block(-8,0,4,2)
Block(-8,0,5,2)
Block(-8,0,6,2)
Block(-8,0,7,3)
Block(-8,0,8,2)
Block(-8,1,-1,98)
Block(-8,1,7,98)
Block(-8,2,-1,98)
Block(-8,2,7,98)
Block(-8,3,-1,98)
Block(-8,3,7,98)
Block(-8,4,-1,98)
Block(-8,4,7,98)
Block(-8,5,-2,5:5)
Block(-8,5,-1,5:5)
Block(-8,5,0,5:5)
Block(-8,5,1,5:5)
Block(-8,5,5,5:5)
Block(-8,5,6,5:5)
Block(-8,5,7,5:5)
Block(-8,5,8,5:5)
Block(-8,6,-2,35:14)
Block(-8,6,8,35:14)
Block(-8,7,-2,5:2)
Block(-8,7,8,5:2)
Block(-8,8,-2,5:2)
Block(-8,8,8,102)
Block(-8,9,-2,5:2)
Block(-8,9,8,102)
Block(-8,10,-2,5:2)
Block(-8,10,8,102)
Block(-8,11,-3,136:2)
Block(-8,11,-2,5:5)
Block(-8,11,8,5:5)
Block(-8,12,-2,5:2)
Block(-8,12,8,5:2)
Block(-8,13,-2,136)
Block(-8,13,-1,136)
Block(-8,13,7,136:3)
Block(-8,13,8,136)
Block(-8,14,0,136:2)
Block(-8,14,6,136:3)
Block(-8,15,1,136:2)
Block(-8,15,5,136:3)
Block(-8,16,2,136:2)
Block(-8,16,4,136:3)
Block(-8,17,3,126:3)
Block(-7,0,-7,2)
Block(-7,0,-6,2)
Block(-7,0,-5,2)
Block(-7,0,-4,2)
Block(-7,0,-3,2)
Block(-7,0,-2,2)
Block(-7,0,-1,3)
Block(-7,0,0,2)
Block(-7,0,1,2)
Block(-7,0,2,2)
Block(-7,0,3,2)
Block(-7,0,4,2)
Block(-7,0,5,2)
Block(-7,0,6,2)
Block(-7,0,7,2)
Block(-7,0,8,2)
Block(-7,1,-1,98)
Block(-7,2,-1,98)
Block(-7,3,-1,98)
Block(-7,4,-1,98)
Block(-7,4,7,98)
Block(-7,5,-2,5:5)
Block(-7,5,-1,5:5)
Block(-7,5,0,5:5)
Block(-7,5,1,5:5)
Block(-7,5,5,5:5)
Block(-7,5,6,5:5)
Block(-7,5,7,5:5)
Block(-7,5,8,5:5)
Block(-7,6,-2,35:14)
Block(-7,6,8,35:14)
Block(-7,7,-2,5:2)
Block(-7,7,8,5:2)
Block(-7,8,-2,5:2)
Block(-7,8,8,102)
Block(-7,9,-2,5:2)
Block(-7,9,8,102)
Block(-7,10,-2,5:2)
Block(-7,10,8,102)
Block(-7,11,-3,136:2)
Block(-7,11,-2,5:5)
Block(-7,11,8,5:5)
Block(-7,12,-2,5:2)
Block(-7,12,8,5:2)
Block(-7,13,-2,5:2)
Block(-7,13,8,5:2)
Block(-7,14,-2,126:3)
Block(-7,14,-1,126:3)
Block(-7,14,0,136:2)
Block(-7,14,6,136:3)
Block(-7,14,7,126:3)
Block(-7,14,8,126:3)
Block(-7,15,1,136:2)
Block(-7,15,5,136:3)
Block(-7,16,2,136:2)
Block(-7,16,4,136:3)
Block(-7,17,3,126:3)
Block(-6,0,-7,2)
Block(-6,0,-6,2)
Block(-6,0,-5,2)
Block(-6,0,-4,2)
Block(-6,0,-3,2)
Block(-6,0,-2,2)
Block(-6,0,-1,3)
Block(-6,0,0,2)
Block(-6,0,1,2)
Block(-6,0,2,2)
Block(-6,0,3,2)
Block(-6,0,4,2)
Block(-6,0,5,2)
Block(-6,0,6,2)
Block(-6,0,7,2)
Block(-6,0,8,2)
Block(-6,1,-1,98)
Block(-6,2,-1,98)
Block(-6,3,-1,98)
Block(-6,4,-1,98)
Block(-6,4,7,98)
Block(-6,5,-2,5:5)
Block(-6,5,-1,5:5)
Block(-6,5,0,5:5)
Block(-6,5,1,5:5)
Block(-6,5,5,5:5)
Block(-6,5,6,5:5)
Block(-6,5,7,5:5)
Block(-6,5,8,5:5)
Block(-6,6,-2,35:14)
Block(-6,6,8,35:14)
Block(-6,7,-2,5:2)
Block(-6,7,8,5:2)
Block(-6,8,-2,5:2)
Block(-6,8,8,102)
Block(-6,9,-2,5:2)
Block(-6,9,8,102)
Block(-6,10,-2,5:2)
Block(-6,10,8,102)
Block(-6,11,-3,136:2)
Block(-6,11,-2,5:5)
Block(-6,11,8,5:5)
Block(-6,12,-2,5:2)
Block(-6,12,8,5:2)
Block(-6,13,-2,136:1)
Block(-6,13,-1,136:2)
Block(-6,13,7,136:1)
Block(-6,13,8,136:1)
Block(-6,14,0,136:2)
Block(-6,14,6,136:3)
Block(-6,15,1,136:2)
Block(-6,15,5,136:3)
Block(-6,16,2,136:2)
Block(-6,16,4,136:3)
Block(-6,17,3,126:3)
Block(-5,0,-7,2)
Block(-5,0,-6,2)
Block(-5,0,-5,2)
Block(-5,0,-4,2)
Block(-5,0,-3,2)
Block(-5,0,-2,2)
Block(-5,0,-1,3)
Block(-5,0,0,2)
Block(-5,0,1,2)
Block(-5,0,2,2)
Block(-5,0,3,2)
Block(-5,0,4,2)
Block(-5,0,5,2)
Block(-5,0,6,2)
Block(-5,0,7,3)
Block(-5,0,8,2)
Block(-5,1,-1,98)
Block(-5,1,7,98)
Block(-5,2,-1,98)
Block(-5,2,7,98)
Block(-5,3,-1,98)
Block(-5,3,7,98)
Block(-5,4,-1,98)
Block(-5,4,7,98)
Block(-5,5,-2,5:5)
Block(-5,5,-1,5:5)
Block(-5,5,0,5:5)
Block(-5,5,1,5:5)
Block(-5,5,2,5:5)
Block(-5,5,3,5:5)
Block(-5,5,4,5:5)
Block(-5,5,5,5:5)
Block(-5,5,6,5:5)
Block(-5,5,7,5:5)
Block(-5,5,8,5:5)
Block(-5,6,-2,35:14)
Block(-5,6,8,5:5)
Block(-5,7,-2,5:2)
Block(-5,7,8,5:5)
Block(-5,8,-2,5:2)
Block(-5,8,8,5:5)
Block(-5,9,-2,5:2)
Block(-5,9,8,5:5)
Block(-5,10,-2,5:2)
Block(-5,10,8,5:5)
Block(-5,11,-3,136:2)
Block(-5,11,-2,5:5)
Block(-5,11,8,5:5)
Block(-5,12,-2,136:2)
Block(-5,12,8,136:3)
Block(-5,13,-1,136:2)
Block(-5,13,7,136:3)
Block(-5,14,0,136:2)
Block(-5,14,6,136:3)
Block(-5,15,1,136:2)
Block(-5,15,5,136:3)
Block(-5,16,2,136:2)
Block(-5,16,4,136:3)
Block(-5,17,3,126:3)
Block(-4,0,-7,2)
Block(-4,0,-6,2)
Block(-4,0,-5,2)
Block(-4,0,-4,2)
Block(-4,0,-3,2)
Block(-4,0,-2,2)
Block(-4,0,-1,3)
Block(-4,0,0,3)
Block(-4,0,1,2)
Block(-4,0,2,2)
Block(-4,0,3,2)
Block(-4,0,4,2)
Block(-4,0,5,2)
Block(-4,0,6,3)
Block(-4,0,7,3)
Block(-4,0,8,2)
Block(-4,1,-1,98)
Block(-4,1,0,98)
Block(-4,1,6,98)
Block(-4,1,7,98)
Block(-4,2,-1,98)
Block(-4,2,0,98)
Block(-4,2,6,98)
Block(-4,2,7,98)
Block(-4,3,-1,98)
Block(-4,3,0,98)
Block(-4,3,6,98)
Block(-4,3,7,98)
Block(-4,4,-1,98)
Block(-4,4,0,98)
Block(-4,4,6,98)
Block(-4,4,7,98)
Block(-4,5,-2,5:5)
Block(-4,5,-1,5:5)
Block(-4,5,0,5:5)
Block(-4,5,1,5:5)
Block(-4,5,2,5:5)
Block(-4,5,3,5:5)
Block(-4,5,4,5:5)
Block(-4,5,5,5:5)
Block(-4,5,6,5:5)
Block(-4,5,7,5:5)
Block(-4,5,8,5:5)
Block(-4,6,-2,35:14)
Block(-4,6,8,35:14)
Block(-4,7,-2,5:2)
Block(-4,7,8,5:2)
Block(-4,8,-2,5:2)
Block(-4,8,8,5:2)
Block(-4,9,-2,5:2)
Block(-4,9,8,5:2)
Block(-4,10,-2,5:2)
Block(-4,10,8,5:2)
Block(-4,11,-3,136:2)
Block(-4,11,-2,5:5)
Block(-4,11,8,5:5)
Block(-4,12,-2,136:2)
Block(-4,12,8,136:3)
Block(-4,13,-1,136:2)
Block(-4,13,7,136:3)
Block(-4,14,0,136:2)
Block(-4,14,6,136:3)
Block(-4,15,1,136:2)
Block(-4,15,5,136:3)
Block(-4,16,2,136:2)
Block(-4,16,4,136:3)
Block(-4,17,3,126:3)
Block(-3,0,-7,2)
Block(-3,0,-6,2)
Block(-3,0,-5,2)
Block(-3,0,-4,2)
Block(-3,0,-3,2)
Block(-3,0,-2,2)
Block(-3,0,-1,2)
Block(-3,0,0,2)
Block(-3,0,1,2)
Block(-3,0,2,2)
Block(-3,0,3,2)
Block(-3,0,4,2)
Block(-3,0,5,2)
Block(-3,0,6,2)
Block(-3,0,7,2)
Block(-3,0,8,2)
Block(-3,5,-2,5:5)
Block(-3,5,-1,5:5)
Block(-3,5,0,5:5)
Block(-3,5,1,5:5)
Block(-3,5,2,5:5)
Block(-3,5,3,5:5)
Block(-3,5,4,5:5)
Block(-3,5,5,5:5)
Block(-3,5,6,5:5)
Block(-3,5,7,5:5)
Block(-3,5,8,5:5)
Block(-3,6,-2,5:5)
Block(-3,6,-1,35:14)
Block(-3,6,0,35:14)
Block(-3,6,1,35:14)
Block(-3,6,2,35:14)
Block(-3,6,3,35:14)
Block(-3,6,4,35:14)
Block(-3,6,5,35:14)
Block(-3,6,6,35:14)
Block(-3,6,7,35:14)
Block(-3,6,8,5:5)
Block(-3,7,-2,5:5)
Block(-3,7,-1,5:2)
Block(-3,7,0,5:2)
Block(-3,7,1,5:2)
Block(-3,7,2,5:2)
Block(-3,7,3,5:2)
Block(-3,7,4,5:2)
Block(-3,7,5,5:2)
Block(-3,7,6,5:2)
Block(-3,7,7,5:2)
Block(-3,7,8,5:5)
Block(-3,8,-2,5:5)
Block(-3,8,-1,5:2)
Block(-3,8,0,5:2)
Block(-3,8,1,5:2)
Block(-3,8,5,5:2)
Block(-3,8,6,5:2)
Block(-3,8,7,5:2)
Block(-3,8,8,5:5)
Block(-3,9,-2,5:5)
Block(-3,9,-1,5:2)
Block(-3,9,0,5:2)
Block(-3,9,1,5:2)
Block(-3,9,5,5:2)
Block(-3,9,6,5:2)
Block(-3,9,7,5:2)
Block(-3,9,8,5:5)
Block(-3,10,-2,5:5)
Block(-3,10,-1,5:2)
Block(-3,10,0,5:2)
Block(-3,10,1,5:2)
Block(-3,10,2,5:2)
Block(-3,10,3,5:2)
Block(-3,10,4,5:2)
Block(-3,10,5,5:2)
Block(-3,10,6,5:2)
Block(-3,10,7,5:2)
Block(-3,10,8,5:5)
Block(-3,11,-3,136:2)
Block(-3,11,-2,5:5)
Block(-3,11,-1,5:5)
Block(-3,11,0,5:5)
Block(-3,11,1,5:5)
Block(-3,11,2,5:5)
Block(-3,11,3,5:5)
Block(-3,11,4,5:5)
Block(-3,11,5,5:5)
Block(-3,11,6,5:5)
Block(-3,11,7,5:5)
Block(-3,11,8,5:5)
Block(-3,12,-2,136:2)
Block(-3,12,-1,5:2)
Block(-3,12,0,5:2)
Block(-3,12,1,5:2)
Block(-3,12,2,5:2)
Block(-3,12,3,5:2)
Block(-3,12,4,5:2)
Block(-3,12,5,5:2)
Block(-3,12,6,5:2)
Block(-3,12,7,5:2)
Block(-3,12,8,136:3)
Block(-3,13,-1,136:2)
Block(-3,13,0,5:2)
Block(-3,13,1,5:2)
Block(-3,13,2,5:2)
Block(-3,13,3,5:2)
Block(-3,13,4,5:2)
Block(-3,13,5,5:2)
Block(-3,13,6,5:2)
Block(-3,13,7,136:3)
Block(-3,14,0,136:2)
Block(-3,14,1,5:2)
Block(-3,14,2,5:2)
Block(-3,14,3,5:2)
Block(-3,14,4,5:2)
Block(-3,14,5,5:2)
Block(-3,14,6,136:3)
Block(-3,15,1,136:2)
Block(-3,15,2,5:2)
Block(-3,15,3,5:2)
Block(-3,15,4,5:2)
Block(-3,15,5,136:3)
Block(-3,16,2,136:2)
Block(-3,16,3,5:2)
Block(-3,16,4,136:3)
Block(-3,17,3,126:3)
Block(-2,0,-7,2)
Block(-2,0,-6,2)
Block(-2,0,-5,2)
Block(-2,0,-4,2)
Block(-2,0,-3,2)
Block(-2,0,-2,2)
Block(-2,0,-1,2)
Block(-2,0,0,2)
Block(-2,0,1,2)
Block(-2,0,2,2)
Block(-2,0,3,2)
Block(-2,0,4,2)
Block(-2,0,5,2)
Block(-2,0,6,2)
Block(-2,0,7,2)
Block(-2,0,8,2)
Block(-2,13,3,5:5)
Block(-1,0,-7,2)
Block(-1,0,-6,2)
Block(-1,0,-5,2)
Block(-1,0,-4,2)
Block(-1,0,-3,2)
Block(-1,0,-2,2)
Block(-1,0,-1,2)
Block(-1,0,0,2)
Block(-1,0,1,2)
Block(-1,0,2,2)
Block(-1,0,3,2)
Block(-1,0,4,2)
Block(-1,0,5,2)
Block(-1,0,6,2)
Block(-1,0,7,2)
Block(-1,0,8,2)
Block(-1,13,3,5:5)
Block(0,0,-7,2)
Block(0,0,-6,2)
Block(0,0,-5,2)
Block(0,0,-4,2)
Block(0,0,-3,2)
Block(0,0,-2,2)
Block(0,0,-1,2)
Block(0,0,0,2)
Block(0,0,1,2)
Block(0,0,2,2)
Block(0,0,3,2)
Block(0,0,4,2)
Block(0,0,5,2)
Block(0,0,6,2)
Block(0,0,7,2)
Block(0,0,8,2)
Block(0,6,3,85)
Block(0,7,3,85)
Block(0,8,3,85)
Block(0,9,3,85)
Block(0,10,3,85)
Block(0,11,3,85)
Block(0,12,3,85)
Block(0,13,3,5:5)
Block(1,0,-7,2)
Block(1,0,-6,2)
Block(1,0,-5,2)
Block(1,0,-4,2)
Block(1,0,-3,2)
Block(1,0,-2,2)
Block(1,0,-1,2)
Block(1,0,0,2)
Block(1,0,1,2)
Block(1,0,2,2)
Block(1,0,3,2)
Block(1,0,4,2)
Block(1,0,5,2)
Block(1,0,6,2)
Block(1,0,7,2)
Block(1,0,8,2)
Block(2,0,-7,2)
Block(2,0,-6,2)
Block(2,0,-5,2)
Block(2,0,-4,2)
Block(2,0,-3,2)
Block(2,0,-2,2)
Block(2,0,-1,2)
Block(2,0,0,2)
Block(2,0,1,2)
Block(2,0,2,2)
Block(2,0,3,2)
Block(2,0,4,2)
Block(2,0,5,2)
Block(2,0,6,2)
Block(2,0,7,2)
Block(2,0,8,2)
Block(3,0,-7,2)
Block(3,0,-6,2)
Block(3,0,-5,2)
Block(3,0,-4,2)
Block(3,0,-3,2)
Block(3,0,-2,2)
Block(3,0,-1,2)
Block(3,0,0,2)
Block(3,0,1,2)
Block(3,0,2,2)
Block(3,0,3,2)
Block(3,0,4,2)
Block(3,0,5,2)
Block(3,0,6,2)
Block(3,0,7,2)
Block(3,0,8,2)
