

BranchFrequencyGroup: CanOverride:0

CanOverride: true

SmoothRadius: -1

OverrideChildSettings: false

ReplaceAbove:
ReplaceBelow:

MustBeInside: VillageGeneratorStructurePlaceHolder, VillageGeneratorStructuresDelay, VillageGeneratorStructuresDelay2, VillageGeneratorStructuresDelay3, VillageGeneratorStructuresDelay4, VillageGeneratorStructuresDelay5, VillageGeneratorStructuresDelay6, VillageGeneratorStructuresDelay7, VillageGeneratorStructuresDelay8, VillageGeneratorStructuresDelay9, VillageGeneratorStructuresDelay10

Block(-8,0,-7,3)
Block(-8,0,-6,3)
Block(-8,0,-5,2)
Block(-8,0,-4,2)
Block(-8,0,-3,2)
Block(-8,0,-2,2)
Block(-8,0,-1,2)
Block(-8,0,0,2)
Block(-8,0,1,2)
Block(-8,0,2,2)
Block(-8,0,3,2)
Block(-8,0,4,2)
Block(-8,0,5,9:8)
Block(-8,0,6,2)
Block(-8,0,7,2)
Block(-8,1,-7,98)
Block(-8,1,-6,98)
Block(-8,1,4,126:5)
Block(-8,1,5,9)
Block(-8,1,6,126:5)
Block(-8,2,-7,98)
Block(-8,2,-6,98)
Block(-8,3,-7,98)
Block(-8,3,-6,98)
Block(-8,4,-7,98)
Block(-8,4,-6,98)
Block(-8,5,-7,98)
Block(-8,5,-6,98)
Block(-8,6,-7,98)
Block(-8,6,-6,98)
Block(-8,7,-7,98)
Block(-8,7,-6,98)
Block(-8,7,-5,136)
Block(-8,7,-4,136)
Block(-8,7,-3,136)
Block(-8,7,-2,136)
Block(-8,7,-1,136)
Block(-8,7,0,136)
Block(-8,7,1,136)
Block(-8,7,2,136)
Block(-8,7,3,136)
Block(-8,7,4,136)
Block(-8,8,-7,98)
Block(-8,8,-6,98)
Block(-8,9,-7,98)
Block(-8,9,-6,98)
Block(-8,10,-7,98)
Block(-8,10,-6,98)
Block(-8,11,-7,98)
Block(-8,11,-6,98)
Block(-8,12,-7,98)
Block(-8,12,-6,98)
Block(-8,13,-7,98)
Block(-8,13,-6,98)
Block(-8,14,-7,98)
Block(-8,14,-6,98)
Block(-7,0,-7,2)
Block(-7,0,-6,3)
Block(-7,0,-5,2)
Block(-7,0,-4,2)
Block(-7,0,-3,2)
Block(-7,0,-2,2)
Block(-7,0,-1,3)
Block(-7,0,0,2)
Block(-7,0,1,3)
Block(-7,0,2,3)
Block(-7,0,3,2)
Block(-7,0,4,2)
Block(-7,0,5,9:8)
Block(-7,0,6,2)
Block(-7,0,7,2)
Block(-7,1,-6,98)
Block(-7,1,-1,44:5)
Block(-7,1,0,44:5)
Block(-7,1,1,44:5)
Block(-7,1,2,44:5)
Block(-7,1,4,126:5)
Block(-7,1,5,9)
Block(-7,1,6,126:5)
Block(-7,2,-6,98)
Block(-7,3,-6,98)
Block(-7,3,-1,98)
Block(-7,3,0,98)
Block(-7,3,1,98)
Block(-7,3,2,98)
Block(-7,4,-6,98)
Block(-7,4,-1,98)
Block(-7,4,0,98)
Block(-7,4,1,98)
Block(-7,4,2,98)
Block(-7,5,-6,98)
Block(-7,5,-1,98)
Block(-7,5,0,98)
Block(-7,5,1,98)
Block(-7,5,2,98)
Block(-7,6,-6,98)
Block(-7,6,-1,98)
Block(-7,6,0,98)
Block(-7,6,1,98)
Block(-7,6,2,98)
Block(-7,7,-6,98)
Block(-7,7,-1,98)
Block(-7,7,0,98)
Block(-7,7,1,98)
Block(-7,7,2,98)
Block(-7,8,-6,98)
Block(-7,8,-5,136)
Block(-7,8,-4,136)
Block(-7,8,-3,136)
Block(-7,8,-2,136)
Block(-7,8,-1,98)
Block(-7,8,0,98)
Block(-7,8,1,98)
Block(-7,8,2,98)
Block(-7,8,3,136)
Block(-7,8,4,136)
Block(-7,9,-6,98)
Block(-7,9,-1,98)
Block(-7,9,0,98)
Block(-7,9,1,98)
Block(-7,9,2,98)
Block(-7,10,-6,98)
Block(-7,10,-1,98)
Block(-7,10,0,98)
Block(-7,10,1,98)
Block(-7,10,2,98)
Block(-7,11,-6,98)
Block(-7,11,-1,98)
Block(-7,11,0,98)
Block(-7,11,1,98)
Block(-7,11,2,98)
Block(-7,12,-6,98)
Block(-7,13,-6,98)
Block(-7,14,-6,98)
Block(-6,0,-7,2)
Block(-6,0,-6,3)
Block(-6,0,-5,2)
Block(-6,0,-4,2)
Block(-6,0,-3,2)
Block(-6,0,-2,2)
Block(-6,0,-1,2)
Block(-6,0,0,98)
Block(-6,0,1,98)
Block(-6,0,2,3)
Block(-6,0,3,2)
Block(-6,0,4,2)
Block(-6,0,5,9:8)
Block(-6,0,6,2)
Block(-6,0,7,2)
Block(-6,1,-6,98)
Block(-6,1,-1,44:5)
Block(-6,1,0,11)
Block(-6,1,1,11)
Block(-6,1,2,44:5)
Block(-6,1,4,126:5)
Block(-6,1,5,9)
Block(-6,1,6,126:5)
Block(-6,2,-6,98)
Block(-6,3,-6,98)
Block(-6,3,-1,98)
Block(-6,3,2,98)
Block(-6,4,-6,98)
Block(-6,4,-1,98)
Block(-6,4,2,98)
Block(-6,5,-6,98)
Block(-6,5,-1,98)
Block(-6,5,2,98)
Block(-6,6,-6,98)
Block(-6,6,-1,98)
Block(-6,6,2,98)
Block(-6,7,-6,98)
Block(-6,7,-1,98)
Block(-6,7,2,98)
Block(-6,8,-6,98)
Block(-6,8,-1,98)
Block(-6,8,2,98)
Block(-6,9,-6,98)
Block(-6,9,-5,136)
Block(-6,9,-4,136)
Block(-6,9,-3,136)
Block(-6,9,-2,136)
Block(-6,9,-1,98)
Block(-6,9,2,98)
Block(-6,9,3,136)
Block(-6,9,4,136)
Block(-6,10,-6,98)
Block(-6,10,-1,98)
Block(-6,10,2,98)
Block(-6,11,-6,98)
Block(-6,11,-1,98)
Block(-6,11,2,98)
Block(-6,12,-6,98)
Block(-6,13,-6,98)
Block(-6,14,-6,98)
Block(-5,0,-7,3)
Block(-5,0,-6,3)
Block(-5,0,-5,2)
Block(-5,0,-4,2)
Block(-5,0,-3,2)
Block(-5,0,-2,2)
Block(-5,0,-1,3)
Block(-5,0,0,98)
Block(-5,0,1,98)
Block(-5,0,2,2)
Block(-5,0,3,2)
Block(-5,0,4,2)
Block(-5,0,5,9:8)
Block(-5,0,6,2)
Block(-5,0,7,2)
Block(-5,1,-7,98)
Block(-5,1,-6,98)
Block(-5,1,-1,44:5)
Block(-5,1,0,11)
Block(-5,1,1,11)
Block(-5,1,2,44:5)
Block(-5,1,4,126:5)
Block(-5,1,5,9)
Block(-5,1,6,126:5)
Block(-5,2,-7,98)
Block(-5,2,-6,98)
Block(-5,3,-7,98)
Block(-5,3,-6,98)
Block(-5,3,-1,98)
Block(-5,3,2,98)
Block(-5,4,-7,98)
Block(-5,4,-6,98)
Block(-5,4,-1,98)
Block(-5,4,2,98)
Block(-5,5,-7,98)
Block(-5,5,-6,98)
Block(-5,5,-1,98)
Block(-5,5,2,98)
Block(-5,6,-7,98)
Block(-5,6,-6,98)
Block(-5,6,-1,98)
Block(-5,6,2,98)
Block(-5,7,-7,98)
Block(-5,7,-6,98)
Block(-5,7,-1,98)
Block(-5,7,2,98)
Block(-5,8,-7,98)
Block(-5,8,-6,98)
Block(-5,8,-1,98)
Block(-5,8,2,98)
Block(-5,9,-7,98)
Block(-5,9,-6,98)
Block(-5,9,-5,136:1)
Block(-5,9,-4,136:1)
Block(-5,9,-3,136:1)
Block(-5,9,-2,136:1)
Block(-5,9,-1,98)
Block(-5,9,2,98)
Block(-5,9,3,136:1)
Block(-5,9,4,136:1)
Block(-5,10,-7,98)
Block(-5,10,-6,98)
Block(-5,10,-1,98)
Block(-5,10,2,98)
Block(-5,11,-7,98)
Block(-5,11,-6,98)
Block(-5,11,-1,98)
Block(-5,11,2,98)
Block(-5,12,-7,98)
Block(-5,12,-6,98)
Block(-5,13,-7,98)
Block(-5,13,-6,98)
Block(-5,14,-7,98)
Block(-5,14,-6,98)
Block(-4,0,-7,2)
Block(-4,0,-6,2)
Block(-4,0,-5,2)
Block(-4,0,-4,2)
Block(-4,0,-3,2)
Block(-4,0,-2,2)
Block(-4,0,-1,3)
Block(-4,0,0,3)
Block(-4,0,1,2)
Block(-4,0,2,3)
Block(-4,0,3,2)
Block(-4,0,4,2)
Block(-4,0,5,9:8)
Block(-4,0,6,2)
Block(-4,0,7,2)
Block(-4,1,-1,44:5)
Block(-4,1,0,44:5)
Block(-4,1,1,44:5)
Block(-4,1,2,44:5)
Block(-4,1,4,126:5)
Block(-4,1,5,9)
Block(-4,1,6,126:5)
Block(-4,3,-1,98)
Block(-4,3,0,98)
Block(-4,3,1,98)
Block(-4,3,2,98)
Block(-4,4,-1,98)
Block(-4,4,0,98)
Block(-4,4,1,98)
Block(-4,4,2,98)
Block(-4,5,-1,98)
Block(-4,5,0,98)
Block(-4,5,1,98)
Block(-4,5,2,98)
Block(-4,6,-1,98)
Block(-4,6,0,98)
Block(-4,6,1,98)
Block(-4,6,2,98)
Block(-4,7,-1,98)
Block(-4,7,0,98)
Block(-4,7,1,98)
Block(-4,7,2,98)
Block(-4,8,-7,136:1)
Block(-4,8,-6,136:1)
Block(-4,8,-5,136:1)
Block(-4,8,-4,136:1)
Block(-4,8,-3,136:1)
Block(-4,8,-2,136:1)
Block(-4,8,-1,98)
Block(-4,8,0,98)
Block(-4,8,1,98)
Block(-4,8,2,98)
Block(-4,8,3,136:1)
Block(-4,8,4,136:1)
Block(-4,9,-1,98)
Block(-4,9,0,98)
Block(-4,9,1,98)
Block(-4,9,2,98)
Block(-4,10,-1,98)
Block(-4,10,0,98)
Block(-4,10,1,98)
Block(-4,10,2,98)
Block(-4,11,-1,98)
Block(-4,11,0,98)
Block(-4,11,1,98)
Block(-4,11,2,98)
Block(-3,0,-7,2)
Block(-3,0,-6,2)
Block(-3,0,-5,2)
Block(-3,0,-4,2)
Block(-3,0,-3,2)
Block(-3,0,-2,2)
Block(-3,0,-1,2)
Block(-3,0,0,2)
Block(-3,0,1,2)
Block(-3,0,2,2)
Block(-3,0,3,2)
Block(-3,0,4,2)
Block(-3,0,5,9:8)
Block(-3,0,6,2)
Block(-3,0,7,2)
Block(-3,1,-6,145:1)
Block(-3,1,4,126:5)
Block(-3,1,5,9)
Block(-3,1,6,126:5)
Block(-3,7,-7,136:1)
Block(-3,7,-6,136:1)
Block(-3,7,-5,136:1)
Block(-3,7,-4,136:1)
Block(-3,7,-3,136:1)
Block(-3,7,-2,136:1)
Block(-3,7,-1,136:1)
Block(-3,7,0,136:1)
Block(-3,7,1,136:1)
Block(-3,7,2,136:1)
Block(-3,7,3,136:1)
Block(-3,7,4,136:1)
Block(-2,0,-7,2)
Block(-2,0,-6,2)
Block(-2,0,-5,2)
Block(-2,0,-4,2)
Block(-2,0,-3,2)
Block(-2,0,-2,2)
Block(-2,0,-1,2)
Block(-2,0,0,2)
Block(-2,0,1,2)
Block(-2,0,2,2)
Block(-2,0,3,2)
Block(-2,0,4,2)
Block(-2,0,5,3)
Block(-2,0,6,2)
Block(-2,0,7,2)
Block(-2,1,4,126:5)
Block(-2,1,5,126:5)
Block(-2,1,6,126:5)
Block(-2,6,-7,136:1)
Block(-2,6,-6,136:1)
Block(-2,6,-5,136:1)
Block(-2,6,-4,136:1)
Block(-2,6,-3,136:1)
Block(-2,6,-2,136:1)
Block(-2,6,-1,136:1)
Block(-2,6,0,136:1)
Block(-2,6,1,136:1)
Block(-2,6,2,136:1)
Block(-2,6,3,136:1)
Block(-2,6,4,136:1)
Block(-1,0,-7,3)
Block(-1,0,-6,3)
Block(-1,0,-5,3)
Block(-1,0,-4,3)
Block(-1,0,-3,3)
Block(-1,0,-2,3)
Block(-1,0,-1,2)
Block(-1,0,0,2)
Block(-1,0,1,2)
Block(-1,0,2,2)
Block(-1,0,3,2)
Block(-1,0,4,2)
Block(-1,0,5,2)
Block(-1,0,6,2)
Block(-1,0,7,2)
Block(-1,1,-7,98)
Block(-1,1,-6,98)
Block(-1,1,-5,98)
Block(-1,1,-4,98)
Block(-1,1,-3,98)
Block(-1,1,-2,98)
Block(-1,1,4,85)
Block(-1,2,-7,98)
Block(-1,2,-6,98)
Block(-1,2,-5,98)
Block(-1,2,-4,102)
Block(-1,2,-3,102)
Block(-1,2,-2,98)
Block(-1,2,4,85)
Block(-1,3,-7,98)
Block(-1,3,-6,98)
Block(-1,3,-5,98)
Block(-1,3,-4,102)
Block(-1,3,-3,102)
Block(-1,3,-2,98)
Block(-1,3,4,85)
Block(-1,4,-7,98)
Block(-1,4,-6,98)
Block(-1,4,-5,98)
Block(-1,4,-4,98)
Block(-1,4,-3,98)
Block(-1,4,-2,98)
Block(-1,4,4,85)
Block(-1,5,-7,136:1)
Block(-1,5,-6,136:1)
Block(-1,5,-5,136:1)
Block(-1,5,-4,136:1)
Block(-1,5,-3,136:1)
Block(-1,5,-2,136:1)
Block(-1,5,-1,136:1)
Block(-1,5,0,136:1)
Block(-1,5,1,136:1)
Block(-1,5,2,136:1)
Block(-1,5,3,136:1)
Block(-1,5,4,136:1)
Block(0,0,-7,2)
Block(0,0,-6,2)
Block(0,0,-5,2)
Block(0,0,-4,2)
Block(0,0,-3,2)
Block(0,0,-2,2)
Block(0,0,-1,2)
Block(0,0,0,2)
Block(0,0,1,2)
Block(0,0,2,2)
Block(0,0,3,2)
Block(0,0,4,2)
Block(0,0,5,2)
Block(0,0,6,2)
Block(0,0,7,2)
Block(0,4,-7,136:1)
Block(0,4,-6,136:1)
Block(0,4,-5,136:1)
Block(0,4,-4,136:1)
Block(0,4,-3,136:1)
Block(0,4,-2,136:1)
Block(0,4,-1,136:1)
Block(0,4,0,136:1)
Block(0,4,1,136:1)
Block(0,4,2,136:1)
Block(0,4,3,136:1)
Block(0,4,4,136:1)
Block(1,0,-7,2)
Block(1,0,-6,2)
Block(1,0,-5,2)
Block(1,0,-4,2)
Block(1,0,-3,2)
Block(1,0,-2,2)
Block(1,0,-1,2)
Block(1,0,0,2)
Block(1,0,1,2)
Block(1,0,2,2)
Block(1,0,3,2)
Block(1,0,4,2)
Block(1,0,5,2)
Block(1,0,6,2)
Block(1,0,7,2)
Block(2,0,-7,2)
Block(2,0,-6,2)
Block(2,0,-5,2)
Block(2,0,-4,2)
Block(2,0,-3,2)
Block(2,0,-2,2)
Block(2,0,-1,2)
Block(2,0,0,2)
Block(2,0,1,2)
Block(2,0,2,2)
Block(2,0,3,2)
Block(2,0,4,2)
Block(2,0,5,2)
Block(2,0,6,2)
Block(2,0,7,2)
Block(3,0,-7,2)
Block(3,0,-6,2)
Block(3,0,-5,2)
Block(3,0,-4,2)
Block(3,0,-3,2)
Block(3,0,-2,2)
Block(3,0,-1,2)
Block(3,0,0,2)
Block(3,0,1,2)
Block(3,0,2,2)
Block(3,0,3,2)
Block(3,0,4,2)
Block(3,0,5,2)
Block(3,0,6,2)
Block(3,0,7,2)
Block(4,0,-7,2)
Block(4,0,-6,2)
Block(4,0,-5,2)
Block(4,0,-4,2)
Block(4,0,-3,2)
Block(4,0,-2,2)
Block(4,0,-1,2)
Block(4,0,0,2)
Block(4,0,1,2)
Block(4,0,2,2)
Block(4,0,3,2)
Block(4,0,4,2)
Block(4,0,5,2)
Block(4,0,6,2)
Block(4,0,7,2)
Block(5,0,-7,2)
Block(5,0,-6,2)
Block(5,0,-5,2)
Block(5,0,-4,2)
Block(5,0,-3,2)
Block(5,0,-2,2)
Block(5,0,-1,2)
Block(5,0,0,2)
Block(5,0,1,2)
Block(5,0,2,2)
Block(5,0,3,2)
Block(5,0,4,2)
Block(5,0,5,2)
Block(5,0,6,2)
Block(5,0,7,2)
Block(6,0,-7,2)
Block(6,0,-6,2)
Block(6,0,-5,2)
Block(6,0,-4,2)
Block(6,0,-3,2)
Block(6,0,-2,2)
Block(6,0,-1,2)
Block(6,0,0,2)
Block(6,0,1,2)
Block(6,0,2,2)
Block(6,0,3,2)
Block(6,0,4,2)
Block(6,0,5,2)
Block(6,0,6,2)
Block(6,0,7,2)
Block(7,0,-7,2)
Block(7,0,-6,2)
Block(7,0,-5,2)
Block(7,0,-4,2)
Block(7,0,-3,2)
Block(7,0,-2,2)
Block(7,0,-1,2)
Block(7,0,0,2)
Block(7,0,1,2)
Block(7,0,2,2)
Block(7,0,3,2)
Block(7,0,4,2)
Block(7,0,5,2)
Block(7,0,6,2)
Block(7,0,7,2)

Branch(16,0,0,true,blacksmith-age-ofC2R1,NORTH,100,0)
