

BranchFrequencyGroup: CanOverride:0

CanOverride: true

SmoothRadius: -1

OverrideChildSettings: false

ReplaceAbove:
ReplaceBelow:

MustBeInside: VillageGeneratorStructurePlaceHolder, VillageGeneratorStructuresDelay, VillageGeneratorStructuresDelay2, VillageGeneratorStructuresDelay3, VillageGeneratorStructuresDelay4, VillageGeneratorStructuresDelay5, VillageGeneratorStructuresDelay6, VillageGeneratorStructuresDelay7, VillageGeneratorStructuresDelay8, VillageGeneratorStructuresDelay9, VillageGeneratorStructuresDelay10

Block(-8,0,-7,2)
Block(-8,0,-6,2)
Block(-8,0,-5,2)
Block(-8,0,-4,2)
Block(-8,0,-3,2)
Block(-8,0,-2,2)
Block(-8,0,-1,3)
Block(-8,0,0,2)
Block(-8,0,1,2)
Block(-8,0,2,2)
Block(-8,0,3,2)
Block(-8,0,4,2)
Block(-8,0,5,3)
Block(-8,0,6,3)
Block(-8,0,7,3)
Block(-8,0,8,3)
Block(-8,1,-1,98)
Block(-8,1,4,85)
Block(-8,1,5,126:13)
Block(-8,1,6,126:13)
Block(-8,1,7,98)
Block(-8,1,8,98)
Block(-8,2,-1,98)
Block(-8,2,4,85)
Block(-8,2,7,98)
Block(-8,2,8,98)
Block(-8,3,-1,98)
Block(-8,3,7,98)
Block(-8,3,8,98)
Block(-8,4,-1,98)
Block(-8,4,7,98)
Block(-8,4,8,98)
Block(-8,5,-2,5:5)
Block(-8,5,-1,5:5)
Block(-8,5,0,5:5)
Block(-8,5,1,5:5)
Block(-8,5,2,5:5)
Block(-8,5,3,5:5)
Block(-8,5,4,5:5)
Block(-8,5,5,5:5)
Block(-8,5,6,5:5)
Block(-8,5,7,5:5)
Block(-8,5,8,98)
Block(-8,6,-2,35:14)
Block(-8,6,8,98)
Block(-8,7,-2,5:2)
Block(-8,7,8,98)
Block(-8,8,-2,5:2)
Block(-8,8,8,98)
Block(-8,9,-2,5:2)
Block(-8,9,8,98)
Block(-8,10,-2,5:2)
Block(-8,10,8,98)
Block(-8,11,-3,136:2)
Block(-8,11,-2,5:5)
Block(-8,11,8,98)
Block(-8,12,-2,136:2)
Block(-8,12,8,98)
Block(-8,13,-1,136:2)
Block(-8,13,7,136:3)
Block(-8,13,8,98)
Block(-8,14,0,136:2)
Block(-8,14,6,136:3)
Block(-8,14,8,98)
Block(-8,15,1,136:2)
Block(-8,15,5,136:3)
Block(-8,16,2,136:2)
Block(-8,16,4,136:3)
Block(-8,17,3,126:3)
Block(-7,0,-7,2)
Block(-7,0,-6,2)
Block(-7,0,-5,2)
Block(-7,0,-4,2)
Block(-7,0,-3,2)
Block(-7,0,-2,2)
Block(-7,0,-1,3)
Block(-7,0,0,2)
Block(-7,0,1,2)
Block(-7,0,2,2)
Block(-7,0,3,2)
Block(-7,0,4,3)
Block(-7,0,5,3)
Block(-7,0,6,3)
Block(-7,0,7,3)
Block(-7,0,8,3)
Block(-7,1,-1,98)
Block(-7,1,4,126:5)
Block(-7,1,5,126:5)
Block(-7,1,6,126:5)
Block(-7,1,7,98)
Block(-7,1,8,98)
Block(-7,2,-1,98)
Block(-7,2,7,98)
Block(-7,2,8,98)
Block(-7,3,-1,98)
Block(-7,3,7,98)
Block(-7,3,8,98)
Block(-7,4,-1,98)
Block(-7,4,7,98)
Block(-7,4,8,98)
Block(-7,5,-2,5:5)
Block(-7,5,-1,5:5)
Block(-7,5,0,5:5)
Block(-7,5,1,5:5)
Block(-7,5,5,5:5)
Block(-7,5,6,5:5)
Block(-7,5,7,5:5)
Block(-7,5,8,98)
Block(-7,6,-2,35:14)
Block(-7,6,8,98)
Block(-7,7,-2,5:2)
Block(-7,7,8,98)
Block(-7,8,-2,5:2)
Block(-7,8,8,98)
Block(-7,9,-2,5:2)
Block(-7,9,8,98)
Block(-7,10,-2,5:2)
Block(-7,10,8,98)
Block(-7,11,-3,136:2)
Block(-7,11,-2,5:5)
Block(-7,11,8,98)
Block(-7,12,-2,5:2)
Block(-7,12,8,98)
Block(-7,13,-2,136)
Block(-7,13,-1,136:2)
Block(-7,13,7,136:3)
Block(-7,13,8,98)
Block(-7,14,0,136:2)
Block(-7,14,6,136:3)
Block(-7,14,8,98)
Block(-7,15,1,136:2)
Block(-7,15,5,136:3)
Block(-7,16,2,136:2)
Block(-7,16,4,136:3)
Block(-7,17,3,126:3)
Block(-6,0,-7,2)
Block(-6,0,-6,2)
Block(-6,0,-5,2)
Block(-6,0,-4,2)
Block(-6,0,-3,2)
Block(-6,0,-2,2)
Block(-6,0,-1,3)
Block(-6,0,0,2)
Block(-6,0,1,2)
Block(-6,0,2,2)
Block(-6,0,3,2)
Block(-6,0,4,2)
Block(-6,0,5,2)
Block(-6,0,6,2)
Block(-6,0,7,3)
Block(-6,0,8,3)
Block(-6,1,-1,98)
Block(-6,1,7,98)
Block(-6,1,8,98)
Block(-6,2,-1,98)
Block(-6,2,7,98)
Block(-6,2,8,98)
Block(-6,3,-1,98)
Block(-6,3,7,98)
Block(-6,3,8,98)
Block(-6,4,-1,98)
Block(-6,4,7,98)
Block(-6,4,8,98)
Block(-6,5,-2,5:5)
Block(-6,5,-1,5:5)
Block(-6,5,0,5:5)
Block(-6,5,1,5:5)
Block(-6,5,5,5:5)
Block(-6,5,6,5:5)
Block(-6,5,7,5:5)
Block(-6,5,8,98)
Block(-6,6,-2,35:14)
Block(-6,6,8,98)
Block(-6,7,-2,5:2)
Block(-6,7,8,98)
Block(-6,8,-2,5:2)
Block(-6,8,8,98)
Block(-6,9,-2,5:2)
Block(-6,9,8,98)
Block(-6,10,-2,5:2)
Block(-6,10,8,98)
Block(-6,11,-3,136:2)
Block(-6,11,-2,5:5)
Block(-6,11,8,98)
Block(-6,12,-2,5:2)
Block(-6,12,8,98)
Block(-6,13,-2,5:2)
Block(-6,13,7,136:3)
Block(-6,13,8,98)
Block(-6,14,-2,126:3)
Block(-6,14,-1,126:3)
Block(-6,14,0,136:2)
Block(-6,14,6,136:3)
Block(-6,14,8,98)
Block(-6,15,1,136:2)
Block(-6,15,5,136:3)
Block(-6,16,2,136:2)
Block(-6,16,4,136:3)
Block(-6,17,3,126:3)
Block(-5,0,-7,2)
Block(-5,0,-6,2)
Block(-5,0,-5,2)
Block(-5,0,-4,2)
Block(-5,0,-3,2)
Block(-5,0,-2,2)
Block(-5,0,-1,3)
Block(-5,0,0,2)
Block(-5,0,1,2)
Block(-5,0,2,2)
Block(-5,0,3,2)
Block(-5,0,4,2)
Block(-5,0,5,2)
Block(-5,0,6,2)
Block(-5,0,7,3)
Block(-5,0,8,3)
Block(-5,1,-1,98)
Block(-5,1,7,98)
Block(-5,1,8,98)
Block(-5,2,-1,98)
Block(-5,2,7,98)
Block(-5,2,8,98)
Block(-5,3,-1,98)
Block(-5,3,7,98)
Block(-5,3,8,98)
Block(-5,4,-1,98)
Block(-5,4,7,98)
Block(-5,4,8,98)
Block(-5,5,-2,5:5)
Block(-5,5,-1,5:5)
Block(-5,5,0,5:5)
Block(-5,5,1,5:5)
Block(-5,5,5,5:5)
Block(-5,5,6,5:5)
Block(-5,5,7,5:5)
Block(-5,5,8,98)
Block(-5,6,-2,35:14)
Block(-5,6,8,98)
Block(-5,7,-2,5:2)
Block(-5,7,8,98)
Block(-5,8,-2,5:2)
Block(-5,8,8,98)
Block(-5,9,-2,5:2)
Block(-5,9,8,98)
Block(-5,10,-2,5:2)
Block(-5,10,8,98)
Block(-5,11,-3,136:2)
Block(-5,11,-2,5:5)
Block(-5,11,8,98)
Block(-5,12,-2,5:2)
Block(-5,12,8,98)
Block(-5,13,-2,136:1)
Block(-5,13,-1,136:2)
Block(-5,13,7,136:3)
Block(-5,13,8,98)
Block(-5,14,0,136:2)
Block(-5,14,6,136:3)
Block(-5,14,8,98)
Block(-5,15,1,136:2)
Block(-5,15,5,136:3)
Block(-5,16,2,136:2)
Block(-5,16,4,136:3)
Block(-5,17,3,126:3)
Block(-4,0,-7,2)
Block(-4,0,-6,2)
Block(-4,0,-5,2)
Block(-4,0,-4,2)
Block(-4,0,-3,2)
Block(-4,0,-2,2)
Block(-4,0,-1,3)
Block(-4,0,0,2)
Block(-4,0,1,2)
Block(-4,0,2,2)
Block(-4,0,3,2)
Block(-4,0,4,2)
Block(-4,0,5,2)
Block(-4,0,6,2)
Block(-4,0,7,3)
Block(-4,0,8,2)
Block(-4,1,-1,98)
Block(-4,1,7,98)
Block(-4,1,8,146:3,4-Chest.nbt)
Block(-4,2,-1,98)
Block(-4,2,7,98)
Block(-4,3,-1,98)
Block(-4,3,7,98)
Block(-4,4,-1,98)
Block(-4,4,7,98)
Block(-4,5,-2,5:5)
Block(-4,5,-1,5:5)
Block(-4,5,0,5:5)
Block(-4,5,1,5:5)
Block(-4,5,5,5:5)
Block(-4,5,6,5:5)
Block(-4,5,7,5:5)
Block(-4,5,8,5:5)
Block(-4,6,-2,35:14)
Block(-4,6,8,5:5)
Block(-4,7,-2,5:2)
Block(-4,7,8,5:5)
Block(-4,8,-2,5:2)
Block(-4,8,8,5:5)
Block(-4,9,-2,5:2)
Block(-4,9,8,5:5)
Block(-4,10,-2,5:2)
Block(-4,10,8,5:5)
Block(-4,11,-3,136:2)
Block(-4,11,-2,5:5)
Block(-4,11,8,5:5)
Block(-4,12,-2,136:2)
Block(-4,12,8,136:3)
Block(-4,13,-1,136:2)
Block(-4,13,7,136:3)
Block(-4,14,0,136:2)
Block(-4,14,6,136:3)
Block(-4,15,1,136:2)
Block(-4,15,5,136:3)
Block(-4,16,2,136:2)
Block(-4,16,4,136:3)
Block(-4,17,3,126:3)
Block(-3,0,-7,2)
Block(-3,0,-6,2)
Block(-3,0,-5,2)
Block(-3,0,-4,2)
Block(-3,0,-3,2)
Block(-3,0,-2,2)
Block(-3,0,-1,3)
Block(-3,0,0,2)
Block(-3,0,1,2)
Block(-3,0,2,2)
Block(-3,0,3,2)
Block(-3,0,4,2)
Block(-3,0,5,2)
Block(-3,0,6,2)
Block(-3,0,7,3)
Block(-3,0,8,2)
Block(-3,1,-1,98)
Block(-3,1,7,98)
Block(-3,1,8,146:3,5-Chest.nbt)
Block(-3,2,-1,98)
Block(-3,2,7,98)
Block(-3,3,-1,98)
Block(-3,3,7,98)
Block(-3,4,-1,98)
Block(-3,4,7,98)
Block(-3,5,-2,5:5)
Block(-3,5,-1,5:5)
Block(-3,5,0,5:5)
Block(-3,5,1,5:5)
Block(-3,5,5,5:5)
Block(-3,5,6,5:5)
Block(-3,5,7,5:5)
Block(-3,5,8,5:5)
Block(-3,6,-2,35:14)
Block(-3,6,8,35:14)
Block(-3,7,-2,5:2)
Block(-3,7,8,5:2)
Block(-3,8,-2,5:2)
Block(-3,8,8,5:2)
Block(-3,9,-2,5:2)
Block(-3,9,8,5:2)
Block(-3,10,-2,5:2)
Block(-3,10,8,5:2)
Block(-3,11,-3,136:2)
Block(-3,11,-2,5:5)
Block(-3,11,8,5:5)
Block(-3,12,-2,136:2)
Block(-3,12,8,136:3)
Block(-3,13,-1,136:2)
Block(-3,13,7,136:3)
Block(-3,14,0,136:2)
Block(-3,14,6,136:3)
Block(-3,15,1,136:2)
Block(-3,15,5,136:3)
Block(-3,16,2,136:2)
Block(-3,16,4,136:3)
Block(-3,17,3,126:3)
Block(-2,0,-7,2)
Block(-2,0,-6,2)
Block(-2,0,-5,2)
Block(-2,0,-4,2)
Block(-2,0,-3,2)
Block(-2,0,-2,2)
Block(-2,0,-1,3)
Block(-2,0,0,2)
Block(-2,0,1,2)
Block(-2,0,2,2)
Block(-2,0,3,2)
Block(-2,0,4,2)
Block(-2,0,5,2)
Block(-2,0,6,2)
Block(-2,0,7,3)
Block(-2,0,8,3)
Block(-2,1,-1,98)
Block(-2,1,7,98)
Block(-2,1,8,58)
Block(-2,2,-1,98)
Block(-2,2,7,98)
Block(-2,3,-1,98)
Block(-2,3,7,98)
Block(-2,4,-1,98)
Block(-2,4,7,98)
Block(-2,5,-2,5:5)
Block(-2,5,-1,5:5)
Block(-2,5,0,5:5)
Block(-2,5,1,5:5)
Block(-2,5,5,5:5)
Block(-2,5,6,5:5)
Block(-2,5,7,5:5)
Block(-2,5,8,5:5)
Block(-2,6,-2,35:14)
Block(-2,6,8,35:14)
Block(-2,7,-2,5:2)
Block(-2,7,8,5:2)
Block(-2,8,-2,5:2)
Block(-2,8,8,5:2)
Block(-2,9,-2,5:2)
Block(-2,9,8,5:2)
Block(-2,10,-2,5:2)
Block(-2,10,8,5:2)
Block(-2,11,-3,136:2)
Block(-2,11,-2,5:5)
Block(-2,11,8,5:5)
Block(-2,12,-2,136:2)
Block(-2,12,8,136:3)
Block(-2,13,-1,136:2)
Block(-2,13,7,136:3)
Block(-2,14,0,136:2)
Block(-2,14,6,136:3)
Block(-2,15,1,136:2)
Block(-2,15,5,136:3)
Block(-2,16,2,136:2)
Block(-2,16,4,136:3)
Block(-2,17,3,126:3)
Block(-1,0,-7,2)
Block(-1,0,-6,2)
Block(-1,0,-5,2)
Block(-1,0,-4,2)
Block(-1,0,-3,2)
Block(-1,0,-2,2)
Block(-1,0,-1,3)
Block(-1,0,0,2)
Block(-1,0,1,2)
Block(-1,0,2,2)
Block(-1,0,3,2)
Block(-1,0,4,2)
Block(-1,0,5,2)
Block(-1,0,6,2)
Block(-1,0,7,3)
Block(-1,0,8,3)
Block(-1,1,-1,98)
Block(-1,1,7,98)
Block(-1,1,8,98)
Block(-1,2,-1,98)
Block(-1,2,7,98)
Block(-1,2,8,98)
Block(-1,3,-1,98)
Block(-1,3,7,98)
Block(-1,3,8,98)
Block(-1,4,-1,98)
Block(-1,4,7,98)
Block(-1,4,8,98)
Block(-1,5,-2,5:5)
Block(-1,5,-1,5:5)
Block(-1,5,0,5:5)
Block(-1,5,1,5:5)
Block(-1,5,5,5:5)
Block(-1,5,6,5:5)
Block(-1,5,7,5:5)
Block(-1,5,8,5:5)
Block(-1,6,-2,35:14)
Block(-1,6,8,35:14)
Block(-1,7,-2,5:2)
Block(-1,7,8,5:2)
Block(-1,8,-2,5:2)
Block(-1,8,8,5:2)
Block(-1,9,-2,5:2)
Block(-1,9,8,5:2)
Block(-1,10,-2,5:2)
Block(-1,10,8,5:2)
Block(-1,11,-3,136:2)
Block(-1,11,-2,5:5)
Block(-1,11,8,5:5)
Block(-1,12,-2,136:2)
Block(-1,12,8,136:3)
Block(-1,13,-1,136:2)
Block(-1,13,7,136:3)
Block(-1,14,0,136:2)
Block(-1,14,6,136:3)
Block(-1,15,1,136:2)
Block(-1,15,5,136:3)
Block(-1,16,2,136:2)
Block(-1,16,4,136:3)
Block(-1,17,3,126:3)
Block(0,0,-7,2)
Block(0,0,-6,2)
Block(0,0,-5,2)
Block(0,0,-4,2)
Block(0,0,-3,2)
Block(0,0,-2,2)
Block(0,0,-1,3)
Block(0,0,0,2)
Block(0,0,1,2)
Block(0,0,2,2)
Block(0,0,3,2)
Block(0,0,4,2)
Block(0,0,5,2)
Block(0,0,6,2)
Block(0,0,7,3)
Block(0,0,8,2)
Block(0,1,-1,98)
Block(0,1,7,98)
Block(0,2,-1,98)
Block(0,2,7,98)
Block(0,3,-1,98)
Block(0,3,7,98)
Block(0,4,-1,98)
Block(0,4,7,98)
Block(0,5,-2,5:5)
Block(0,5,-1,5:5)
Block(0,5,0,5:5)
Block(0,5,1,5:5)
Block(0,5,5,5:5)
Block(0,5,6,5:5)
Block(0,5,7,5:5)
Block(0,5,8,5:5)
Block(0,6,-2,35:14)
Block(0,6,8,5:5)
Block(0,7,-2,5:2)
Block(0,7,8,5:5)
Block(0,8,-2,5:2)
Block(0,8,8,5:5)
Block(0,9,-2,5:2)
Block(0,9,8,5:5)
Block(0,10,-2,5:2)
Block(0,10,8,5:5)
Block(0,11,-3,136:2)
Block(0,11,-2,5:5)
Block(0,11,8,5:5)
Block(0,12,-2,136:2)
Block(0,12,8,136:3)
Block(0,13,-1,136:2)
Block(0,13,7,136:3)
Block(0,14,0,136:2)
Block(0,14,6,136:3)
Block(0,15,1,136:2)
Block(0,15,5,136:3)
Block(0,16,2,136:2)
Block(0,16,4,136:3)
Block(0,17,3,126:3)
Block(1,0,-7,2)
Block(1,0,-6,2)
Block(1,0,-5,2)
Block(1,0,-4,2)
Block(1,0,-3,2)
Block(1,0,-2,2)
Block(1,0,-1,3)
Block(1,0,0,2)
Block(1,0,1,2)
Block(1,0,2,2)
Block(1,0,3,2)
Block(1,0,4,2)
Block(1,0,5,2)
Block(1,0,6,2)
Block(1,0,7,3)
Block(1,0,8,2)
Block(1,1,-1,98)
Block(1,1,7,98)
Block(1,2,-1,98)
Block(1,2,7,98)
Block(1,3,-1,98)
Block(1,3,7,98)
Block(1,4,-1,98)
Block(1,4,7,98)
Block(1,5,-2,5:5)
Block(1,5,-1,5:5)
Block(1,5,0,5:5)
Block(1,5,1,5:5)
Block(1,5,5,5:5)
Block(1,5,6,5:5)
Block(1,5,7,5:5)
Block(1,5,8,5:5)
Block(1,6,-2,35:14)
Block(1,6,8,35:14)
Block(1,7,-2,5:2)
Block(1,7,8,5:2)
Block(1,8,-2,5:2)
Block(1,8,8,102)
Block(1,9,-2,5:2)
Block(1,9,8,102)
Block(1,10,-2,5:2)
Block(1,10,8,102)
Block(1,11,-3,136:2)
Block(1,11,-2,5:5)
Block(1,11,8,5:5)
Block(1,12,-2,5:2)
Block(1,12,8,5:2)
Block(1,13,-2,136)
Block(1,13,-1,136)
Block(1,13,7,136:3)
Block(1,13,8,136)
Block(1,14,0,136:2)
Block(1,14,6,136:3)
Block(1,15,1,136:2)
Block(1,15,5,136:3)
Block(1,16,2,136:2)
Block(1,16,4,136:3)
Block(1,17,3,126:3)
Block(2,0,-7,2)
Block(2,0,-6,2)
Block(2,0,-5,2)
Block(2,0,-4,2)
Block(2,0,-3,2)
Block(2,0,-2,2)
Block(2,0,-1,3)
Block(2,0,0,2)
Block(2,0,1,2)
Block(2,0,2,2)
Block(2,0,3,2)
Block(2,0,4,2)
Block(2,0,5,2)
Block(2,0,6,2)
Block(2,0,7,3)
Block(2,0,8,2)
Block(2,1,-1,98)
Block(2,1,7,98)
Block(2,2,-1,98)
Block(2,2,7,98)
Block(2,3,-1,98)
Block(2,3,7,98)
Block(2,4,-1,98)
Block(2,4,7,98)
Block(2,5,-2,5:5)
Block(2,5,-1,5:5)
Block(2,5,0,5:5)
Block(2,5,1,5:5)
Block(2,5,5,5:5)
Block(2,5,6,5:5)
Block(2,5,7,5:5)
Block(2,5,8,5:5)
Block(2,6,-2,35:14)
Block(2,6,8,35:14)
Block(2,7,-2,5:2)
Block(2,7,8,5:2)
Block(2,8,-2,5:2)
Block(2,8,8,102)
Block(2,9,-2,5:2)
Block(2,9,8,102)
Block(2,10,-2,5:2)
Block(2,10,8,102)
Block(2,11,-3,136:2)
Block(2,11,-2,5:5)
Block(2,11,8,5:5)
Block(2,12,-2,5:2)
Block(2,12,8,5:2)
Block(2,13,-2,5:2)
Block(2,13,8,5:2)
Block(2,14,-2,126:3)
Block(2,14,-1,126:3)
Block(2,14,0,136:2)
Block(2,14,6,136:3)
Block(2,14,7,126:3)
Block(2,14,8,126:3)
Block(2,15,1,136:2)
Block(2,15,5,136:3)
Block(2,16,2,136:2)
Block(2,16,4,136:3)
Block(2,17,3,126:3)
Block(3,0,-7,2)
Block(3,0,-6,2)
Block(3,0,-5,2)
Block(3,0,-4,2)
Block(3,0,-3,2)
Block(3,0,-2,2)
Block(3,0,-1,3)
Block(3,0,0,2)
Block(3,0,1,2)
Block(3,0,2,2)
Block(3,0,3,2)
Block(3,0,4,2)
Block(3,0,5,2)
Block(3,0,6,2)
Block(3,0,7,3)
Block(3,0,8,2)
Block(3,1,-1,98)
Block(3,1,7,98)
Block(3,2,-1,98)
Block(3,2,7,98)
Block(3,3,-1,98)
Block(3,3,7,98)
Block(3,4,-1,98)
Block(3,4,7,98)
Block(3,5,-2,5:5)
Block(3,5,-1,5:5)
Block(3,5,0,5:5)
Block(3,5,1,5:5)
Block(3,5,5,5:5)
Block(3,5,6,5:5)
Block(3,5,7,5:5)
Block(3,5,8,5:5)
Block(3,6,-2,35:14)
Block(3,6,8,35:14)
Block(3,7,-2,5:2)
Block(3,7,8,5:2)
Block(3,8,-2,5:2)
Block(3,8,8,102)
Block(3,9,-2,5:2)
Block(3,9,8,102)
Block(3,10,-2,5:2)
Block(3,10,8,102)
Block(3,11,-3,136:2)
Block(3,11,-2,5:5)
Block(3,11,8,5:5)
Block(3,12,-2,5:2)
Block(3,12,8,5:2)
Block(3,13,-2,136:1)
Block(3,13,-1,136:1)
Block(3,13,7,136:1)
Block(3,13,8,136:1)
Block(3,14,0,136:2)
Block(3,14,6,136:3)
Block(3,15,1,136:2)
Block(3,15,5,136:3)
Block(3,16,2,136:2)
Block(3,16,4,136:3)
Block(3,17,3,126:3)
Block(4,0,-7,2)
Block(4,0,-6,2)
Block(4,0,-5,2)
Block(4,0,-4,2)
Block(4,0,-3,2)
Block(4,0,-2,2)
Block(4,0,-1,3)
Block(4,0,0,2)
Block(4,0,1,2)
Block(4,0,2,2)
Block(4,0,3,2)
Block(4,0,4,2)
Block(4,0,5,2)
Block(4,0,6,2)
Block(4,0,7,3)
Block(4,0,8,2)
Block(4,1,-1,98)
Block(4,1,7,98)
Block(4,2,-1,98)
Block(4,2,7,98)
Block(4,3,-1,98)
Block(4,3,7,98)
Block(4,4,-1,98)
Block(4,4,7,98)
Block(4,5,-2,5:5)
Block(4,5,-1,5:5)
Block(4,5,0,5:5)
Block(4,5,1,5:5)
Block(4,5,5,5:5)
Block(4,5,6,5:5)
Block(4,5,7,5:5)
Block(4,5,8,5:5)
Block(4,6,-2,35:14)
Block(4,6,8,5:5)
Block(4,7,-2,5:2)
Block(4,7,8,5:5)
Block(4,8,-2,5:2)
Block(4,8,8,5:5)
Block(4,9,-2,5:2)
Block(4,9,8,5:5)
Block(4,10,-2,5:2)
Block(4,10,8,5:5)
Block(4,11,-3,136:2)
Block(4,11,-2,5:5)
Block(4,11,8,5:5)
Block(4,12,-2,136:2)
Block(4,12,8,136:3)
Block(4,13,-1,136:2)
Block(4,13,7,136:3)
Block(4,14,0,136:2)
Block(4,14,6,136:3)
Block(4,15,1,136:2)
Block(4,15,5,136:3)
Block(4,16,2,136:2)
Block(4,16,4,136:3)
Block(4,17,3,126:3)
Block(5,0,-7,2)
Block(5,0,-6,2)
Block(5,0,-5,2)
Block(5,0,-4,2)
Block(5,0,-3,2)
Block(5,0,-2,2)
Block(5,0,-1,3)
Block(5,0,0,2)
Block(5,0,1,2)
Block(5,0,2,2)
Block(5,0,3,2)
Block(5,0,4,2)
Block(5,0,5,2)
Block(5,0,6,2)
Block(5,0,7,3)
Block(5,0,8,2)
Block(5,1,-1,98)
Block(5,1,7,98)
Block(5,2,-1,98)
Block(5,2,7,102)
Block(5,3,-1,98)
Block(5,3,7,102)
Block(5,4,-1,98)
Block(5,4,7,102)
Block(5,5,-2,5:5)
Block(5,5,-1,5:5)
Block(5,5,0,5:5)
Block(5,5,1,5:5)
Block(5,5,5,5:5)
Block(5,5,6,5:5)
Block(5,5,7,5:5)
Block(5,5,8,5:5)
Block(5,6,-2,35:14)
Block(5,6,8,35:14)
Block(5,7,-2,5:2)
Block(5,7,8,5:2)
Block(5,8,-2,5:2)
Block(5,8,8,5:2)
Block(5,9,-2,5:2)
Block(5,9,8,5:2)
Block(5,10,-2,5:2)
Block(5,10,8,5:2)
Block(5,11,-3,136:2)
Block(5,11,-2,5:5)
Block(5,11,8,5:5)
Block(5,12,-2,136:2)
Block(5,12,8,136:3)
Block(5,13,-1,136:2)
Block(5,13,7,136:3)
Block(5,14,0,136:2)
Block(5,14,6,136:3)
Block(5,15,1,136:2)
Block(5,15,5,136:3)
Block(5,16,2,136:2)
Block(5,16,4,136:3)
Block(5,17,3,126:3)
Block(6,0,-7,2)
Block(6,0,-6,2)
Block(6,0,-5,2)
Block(6,0,-4,2)
Block(6,0,-3,2)
Block(6,0,-2,2)
Block(6,0,-1,3)
Block(6,0,0,2)
Block(6,0,1,2)
Block(6,0,2,2)
Block(6,0,3,2)
Block(6,0,4,2)
Block(6,0,5,2)
Block(6,0,6,2)
Block(6,0,7,3)
Block(6,0,8,2)
Block(6,1,-1,98)
Block(6,1,7,98)
Block(6,2,-1,98)
Block(6,2,7,102)
Block(6,3,-1,98)
Block(6,3,7,102)
Block(6,4,-1,98)
Block(6,4,7,102)
Block(6,5,-2,5:5)
Block(6,5,-1,5:5)
Block(6,5,0,5:5)
Block(6,5,1,5:5)
Block(6,5,5,5:5)
Block(6,5,6,5:5)
Block(6,5,7,5:5)
Block(6,5,8,5:5)
Block(6,6,-2,35:14)
Block(6,6,8,35:14)
Block(6,7,-2,5:2)
Block(6,7,8,5:2)
Block(6,8,-2,5:2)
Block(6,8,8,5:2)
Block(6,9,-2,5:2)
Block(6,9,8,5:2)
Block(6,10,-2,5:2)
Block(6,10,8,5:2)
Block(6,11,-3,136:2)
Block(6,11,-2,5:5)
Block(6,11,8,5:5)
Block(6,12,-2,136:2)
Block(6,12,8,136:3)
Block(6,13,-1,136:2)
Block(6,13,7,136:3)
Block(6,14,0,136:2)
Block(6,14,6,136:3)
Block(6,15,1,136:2)
Block(6,15,5,136:3)
Block(6,16,2,136:2)
Block(6,16,4,136:3)
Block(6,17,3,126:3)
Block(7,0,-7,2)
Block(7,0,-6,2)
Block(7,0,-5,2)
Block(7,0,-4,2)
Block(7,0,-3,2)
Block(7,0,-2,2)
Block(7,0,-1,3)
Block(7,0,0,2)
Block(7,0,1,2)
Block(7,0,2,2)
Block(7,0,3,2)
Block(7,0,4,2)
Block(7,0,5,2)
Block(7,0,6,2)
Block(7,0,7,3)
Block(7,0,8,2)
Block(7,1,-1,98)
Block(7,1,7,98)
Block(7,2,-1,98)
Block(7,2,7,102)
Block(7,3,-1,98)
Block(7,3,7,102)
Block(7,4,-1,98)
Block(7,4,7,102)
Block(7,5,-2,5:5)
Block(7,5,-1,5:5)
Block(7,5,0,5:5)
Block(7,5,1,5:5)
Block(7,5,5,5:5)
Block(7,5,6,5:5)
Block(7,5,7,5:5)
Block(7,5,8,5:5)
Block(7,6,-2,35:14)
Block(7,6,8,5:5)
Block(7,7,-2,5:2)
Block(7,7,8,5:5)
Block(7,8,-2,5:2)
Block(7,8,8,5:5)
Block(7,9,-2,5:2)
Block(7,9,8,5:5)
Block(7,10,-2,5:2)
Block(7,10,8,5:5)
Block(7,11,-3,136:2)
Block(7,11,-2,5:5)
Block(7,11,8,5:5)
Block(7,12,-2,136:2)
Block(7,12,8,136:3)
Block(7,13,-1,136:2)
Block(7,13,7,136:3)
Block(7,14,0,136:2)
Block(7,14,6,136:3)
Block(7,15,1,136:2)
Block(7,15,5,136:3)
Block(7,16,2,136:2)
Block(7,16,4,136:3)
Block(7,17,3,126:3)

Branch(16,0,0,true,blacksmith-age-ofC2R0,NORTH,100,0)
