

BranchFrequencyGroup: CanOverride:0

CanOverride: true

SmoothRadius: 15

OverrideChildSettings: false

ReplaceAbove: WATER
ReplaceBelow:

MustBeInside: VillageGeneratorStructurePlaceHolder, VillageGeneratorStructuresDelay, VillageGeneratorStructuresDelay2, VillageGeneratorStructuresDelay3, VillageGeneratorStructuresDelay4, VillageGeneratorStructuresDelay5, VillageGeneratorStructuresDelay6, VillageGeneratorStructuresDelay7, VillageGeneratorStructuresDelay8, VillageGeneratorStructuresDelay9, VillageGeneratorStructuresDelay10, VillageGeneratorWaterStructurePlaceHolder, VillageGeneratorStructuresDelayWater, VillageGeneratorStructuresDelay2Water, VillageGeneratorStructuresDelay3Water, VillageGeneratorStructuresDelay4Water, VillageGeneratorStructuresDelay5Water, VillageGeneratorStructuresDelay6Water, VillageGeneratorStructuresDelay7Water, VillageGeneratorStructuresDelay8Water, VillageGeneratorStructuresDelay9Water, VillageGeneratorStructuresDelay10Water, VillageGeneratorWallBlocksWater, VillageGeneratorWallCornerBlocksWater, VillageGeneratorWallCornerBlocksOverrideWater

ReplacesBO3: VillageGeneratorWallBlocksWater, VillageGeneratorWallCornerBlocksWater, VillageGeneratorWallCornerBlocksOverrideWater

Block(-8,0,-7,1)
Block(-8,0,-6,1)
Block(-8,0,-5,1)
Block(-8,0,-4,1)
Block(-8,0,-3,1)
Block(-8,0,-2,1)
Block(-8,0,-1,1)
Block(-8,0,0,1)
Block(-8,0,1,1)
Block(-8,0,2,1)
Block(-8,0,3,1)
Block(-8,0,4,1)
Block(-8,0,5,1)
Block(-8,0,6,1)
Block(-8,0,7,1)
Block(-8,0,8,1)
Block(-8,1,-7,9)
Block(-8,1,-6,9)
Block(-8,1,-5,9)
Block(-8,1,-4,9)
Block(-8,1,-3,9)
Block(-8,1,-2,9)
Block(-8,1,-1,9)
Block(-8,1,0,9)
Block(-8,1,1,9)
Block(-8,1,2,9)
Block(-8,1,3,9)
Block(-8,1,4,9)
Block(-8,1,5,9)
Block(-8,1,6,9)
Block(-8,1,7,9)
Block(-8,1,8,9)
Block(-8,2,-7,9)
Block(-8,2,-6,9)
Block(-8,2,-5,9)
Block(-8,2,-4,9)
Block(-8,2,-3,9)
Block(-8,2,-2,9)
Block(-8,2,-1,9)
Block(-8,2,0,9)
Block(-8,2,1,9)
Block(-8,2,2,9)
Block(-8,2,3,9)
Block(-8,2,4,9)
Block(-8,2,5,9)
Block(-8,2,6,9)
Block(-8,2,7,9)
Block(-8,2,8,9)
Block(-8,3,-7,9)
Block(-8,3,-6,9)
Block(-8,3,-5,9)
Block(-8,3,-4,9)
Block(-8,3,-3,9)
Block(-8,3,-2,9)
Block(-8,3,-1,9)
Block(-8,3,0,9)
Block(-8,3,1,9)
Block(-8,3,2,9)
Block(-8,3,3,9)
Block(-8,3,4,9)
Block(-8,3,5,9)
Block(-8,3,6,9)
Block(-8,3,7,9)
Block(-8,3,8,9)
Block(-8,4,-7,9)
Block(-8,4,-6,9)
Block(-8,4,-5,9)
Block(-8,4,-4,9)
Block(-8,4,-3,9)
Block(-8,4,-2,9)
Block(-8,4,-1,9)
Block(-8,4,0,9)
Block(-8,4,1,9)
Block(-8,4,2,9)
Block(-8,4,3,9)
Block(-8,4,4,9)
Block(-8,4,5,9)
Block(-8,4,6,9)
Block(-8,4,7,9)
Block(-8,4,8,9)
Block(-8,5,-7,9)
Block(-8,5,-6,9)
Block(-8,5,-5,9)
Block(-8,5,-4,9)
Block(-8,5,-3,9)
Block(-8,5,-2,9)
Block(-8,5,-1,9)
Block(-8,5,0,9)
Block(-8,5,1,9)
Block(-8,5,2,9)
Block(-8,5,3,9)
Block(-8,5,4,9)
Block(-8,5,5,9)
Block(-8,5,6,9)
Block(-8,5,7,9)
Block(-8,5,8,9)
Block(-8,6,-7,9)
Block(-8,6,-6,9)
Block(-8,6,-5,9)
Block(-8,6,-4,9)
Block(-8,6,-3,9)
Block(-8,6,-2,9)
Block(-8,6,-1,9)
Block(-8,6,0,9)
Block(-8,6,1,9)
Block(-8,6,2,9)
Block(-8,6,3,9)
Block(-8,6,4,9)
Block(-8,6,5,9)
Block(-8,6,6,9)
Block(-8,6,7,9)
Block(-8,6,8,9)
Block(-8,7,-7,9)
Block(-8,7,-6,9)
Block(-8,7,-5,9)
Block(-8,7,-4,9)
Block(-8,7,-3,9)
Block(-8,7,-2,9)
Block(-8,7,-1,9)
Block(-8,7,0,9)
Block(-8,7,1,9)
Block(-8,7,2,9)
Block(-8,7,3,9)
Block(-8,7,4,9)
Block(-8,7,5,9)
Block(-8,7,6,9)
Block(-8,7,7,9)
Block(-8,7,8,9)
Block(-8,8,-7,9)
Block(-8,8,-6,9)
Block(-8,8,-5,9)
Block(-8,8,-4,9)
Block(-8,8,-3,9)
Block(-8,8,-2,9)
Block(-8,8,-1,9)
Block(-8,8,0,9)
Block(-8,8,1,9)
Block(-8,8,2,9)
Block(-8,8,3,9)
Block(-8,8,4,9)
Block(-8,8,5,9)
Block(-8,8,6,9)
Block(-8,8,7,9)
Block(-8,8,8,9)
Block(-8,9,-7,9)
Block(-8,9,-6,9)
Block(-8,9,-5,9)
Block(-8,9,-4,9)
Block(-8,9,-3,9)
Block(-8,9,-2,9)
Block(-8,9,-1,9)
Block(-8,9,0,9)
Block(-8,9,1,9)
Block(-8,9,2,9)
Block(-8,9,3,9)
Block(-8,9,4,9)
Block(-8,9,5,9)
Block(-8,9,6,9)
Block(-8,9,7,9)
Block(-8,9,8,9)
Block(-8,10,-7,9)
Block(-8,10,-6,9)
Block(-8,10,-5,9)
Block(-8,10,-4,9)
Block(-8,10,-3,9)
Block(-8,10,-2,9)
Block(-8,10,-1,9)
Block(-8,10,0,9)
Block(-8,10,1,9)
Block(-8,10,2,9)
Block(-8,10,3,9)
Block(-8,10,4,9)
Block(-8,10,5,9)
Block(-8,10,6,9)
Block(-8,10,7,9)
Block(-8,10,8,9)
Block(-8,11,-7,9)
Block(-8,11,-6,9)
Block(-8,11,-5,9)
Block(-8,11,-4,9)
Block(-8,11,-3,9)
Block(-8,11,-2,9)
Block(-8,11,-1,9)
Block(-8,11,0,9)
Block(-8,11,1,9)
Block(-8,11,2,9)
Block(-8,11,3,9)
Block(-8,11,4,9)
Block(-8,11,5,9)
Block(-8,11,6,9)
Block(-8,11,7,9)
Block(-8,11,8,9)
Block(-8,12,-7,9)
Block(-8,12,-6,9)
Block(-8,12,-5,9)
Block(-8,12,-4,9)
Block(-8,12,-3,9)
Block(-8,12,-2,9)
Block(-8,12,-1,9)
Block(-8,12,0,9)
Block(-8,12,1,9)
Block(-8,12,2,9)
Block(-8,12,3,9)
Block(-8,12,4,9)
Block(-8,12,5,9)
Block(-8,12,6,9)
Block(-8,12,7,9)
Block(-8,12,8,9)
Block(-8,13,-7,9)
Block(-8,13,-6,9)
Block(-8,13,-5,9)
Block(-8,13,-4,9)
Block(-8,13,-3,9)
Block(-8,13,-2,9)
Block(-8,13,-1,9)
Block(-8,13,0,9)
Block(-8,13,1,9)
Block(-8,13,2,9)
Block(-8,13,3,9)
Block(-8,13,4,9)
Block(-8,13,5,9)
Block(-8,13,6,9)
Block(-8,13,7,9)
Block(-8,13,8,9)
Block(-8,14,5,139:1)
Block(-8,14,7,139:1)
Block(-8,15,5,126:1)
Block(-8,15,6,126:1)
Block(-8,15,7,126:1)
Block(-7,0,-7,1)
Block(-7,0,-6,1)
Block(-7,0,-5,1)
Block(-7,0,-4,1)
Block(-7,0,-3,1)
Block(-7,0,-2,1)
Block(-7,0,-1,1)
Block(-7,0,0,1)
Block(-7,0,1,1)
Block(-7,0,2,1)
Block(-7,0,3,1)
Block(-7,0,4,1)
Block(-7,0,5,1)
Block(-7,0,6,1)
Block(-7,0,7,1)
Block(-7,0,8,1)
Block(-7,1,-7,9)
Block(-7,1,-6,9)
Block(-7,1,-5,9)
Block(-7,1,-4,9)
Block(-7,1,-3,9)
Block(-7,1,-2,9)
Block(-7,1,-1,9)
Block(-7,1,0,9)
Block(-7,1,1,9)
Block(-7,1,2,9)
Block(-7,1,3,9)
Block(-7,1,4,9)
Block(-7,1,5,9)
Block(-7,1,6,9)
Block(-7,1,7,9)
Block(-7,1,8,1)
Block(-7,2,-7,9)
Block(-7,2,-6,9)
Block(-7,2,-5,9)
Block(-7,2,-4,9)
Block(-7,2,-3,9)
Block(-7,2,-2,9)
Block(-7,2,-1,9)
Block(-7,2,0,9)
Block(-7,2,1,9)
Block(-7,2,2,9)
Block(-7,2,3,9)
Block(-7,2,4,9)
Block(-7,2,5,9)
Block(-7,2,6,9)
Block(-7,2,7,9)
Block(-7,2,8,1)
Block(-7,3,-7,9)
Block(-7,3,-6,9)
Block(-7,3,-5,9)
Block(-7,3,-4,9)
Block(-7,3,-3,9)
Block(-7,3,-2,9)
Block(-7,3,-1,9)
Block(-7,3,0,9)
Block(-7,3,1,9)
Block(-7,3,2,9)
Block(-7,3,3,9)
Block(-7,3,4,9)
Block(-7,3,5,9)
Block(-7,3,6,9)
Block(-7,3,7,9)
Block(-7,3,8,1)
Block(-7,4,-7,9)
Block(-7,4,-6,9)
Block(-7,4,-5,9)
Block(-7,4,-4,9)
Block(-7,4,-3,9)
Block(-7,4,-2,9)
Block(-7,4,-1,9)
Block(-7,4,0,9)
Block(-7,4,1,9)
Block(-7,4,2,9)
Block(-7,4,3,9)
Block(-7,4,4,9)
Block(-7,4,5,9)
Block(-7,4,6,9)
Block(-7,4,7,9)
Block(-7,4,8,1)
Block(-7,5,-7,9)
Block(-7,5,-6,9)
Block(-7,5,-5,9)
Block(-7,5,-4,9)
Block(-7,5,-3,9)
Block(-7,5,-2,9)
Block(-7,5,-1,9)
Block(-7,5,0,9)
Block(-7,5,1,9)
Block(-7,5,2,9)
Block(-7,5,3,9)
Block(-7,5,4,9)
Block(-7,5,5,9)
Block(-7,5,6,9)
Block(-7,5,7,9)
Block(-7,5,8,1)
Block(-7,6,-7,9)
Block(-7,6,-6,9)
Block(-7,6,-5,9)
Block(-7,6,-4,9)
Block(-7,6,-3,9)
Block(-7,6,-2,9)
Block(-7,6,-1,9)
Block(-7,6,0,9)
Block(-7,6,1,9)
Block(-7,6,2,9)
Block(-7,6,3,9)
Block(-7,6,4,9)
Block(-7,6,5,9)
Block(-7,6,6,9)
Block(-7,6,7,9)
Block(-7,6,8,1)
Block(-7,7,-7,9)
Block(-7,7,-6,9)
Block(-7,7,-5,9)
Block(-7,7,-4,9)
Block(-7,7,-3,9)
Block(-7,7,-2,9)
Block(-7,7,-1,9)
Block(-7,7,0,9)
Block(-7,7,1,9)
Block(-7,7,2,9)
Block(-7,7,3,9)
Block(-7,7,4,9)
Block(-7,7,5,9)
Block(-7,7,6,9)
Block(-7,7,7,9)
Block(-7,7,8,1)
Block(-7,8,-7,9)
Block(-7,8,-6,9)
Block(-7,8,-5,9)
Block(-7,8,-4,9)
Block(-7,8,-3,9)
Block(-7,8,-2,9)
Block(-7,8,-1,9)
Block(-7,8,0,9)
Block(-7,8,1,9)
Block(-7,8,2,9)
Block(-7,8,3,9)
Block(-7,8,4,9)
Block(-7,8,5,9)
Block(-7,8,6,9)
Block(-7,8,7,9)
Block(-7,8,8,1)
Block(-7,9,-7,9)
Block(-7,9,-6,9)
Block(-7,9,-5,9)
Block(-7,9,-4,9)
Block(-7,9,-3,9)
Block(-7,9,-2,9)
Block(-7,9,-1,9)
Block(-7,9,0,9)
Block(-7,9,1,9)
Block(-7,9,2,9)
Block(-7,9,3,9)
Block(-7,9,4,9)
Block(-7,9,5,9)
Block(-7,9,6,9)
Block(-7,9,7,9)
Block(-7,9,8,3)
Block(-7,10,-7,9)
Block(-7,10,-6,9)
Block(-7,10,-5,9)
Block(-7,10,-4,9)
Block(-7,10,-3,9)
Block(-7,10,-2,9)
Block(-7,10,-1,9)
Block(-7,10,0,9)
Block(-7,10,1,9)
Block(-7,10,2,9)
Block(-7,10,3,9)
Block(-7,10,4,9)
Block(-7,10,5,9)
Block(-7,10,6,9)
Block(-7,10,7,9)
Block(-7,10,8,9)
Block(-7,11,-7,9)
Block(-7,11,-6,9)
Block(-7,11,-5,9)
Block(-7,11,-4,9)
Block(-7,11,-3,9)
Block(-7,11,-2,9)
Block(-7,11,-1,9)
Block(-7,11,0,9)
Block(-7,11,1,9)
Block(-7,11,2,9)
Block(-7,11,3,9)
Block(-7,11,4,9)
Block(-7,11,5,9)
Block(-7,11,6,9)
Block(-7,11,7,9)
Block(-7,11,8,9)
Block(-7,12,-7,9)
Block(-7,12,-6,9)
Block(-7,12,-5,9)
Block(-7,12,-4,9)
Block(-7,12,-3,9)
Block(-7,12,-2,9)
Block(-7,12,-1,9)
Block(-7,12,0,9)
Block(-7,12,1,9)
Block(-7,12,2,9)
Block(-7,12,3,9)
Block(-7,12,4,9)
Block(-7,12,5,9)
Block(-7,12,6,9)
Block(-7,12,7,9)
Block(-7,12,8,9)
Block(-7,13,-7,9)
Block(-7,13,-6,9)
Block(-7,13,-5,9)
Block(-7,13,-4,9)
Block(-7,13,-3,9)
Block(-7,13,-2,9)
Block(-7,13,-1,9)
Block(-7,13,0,9)
Block(-7,13,1,9)
Block(-7,13,2,9)
Block(-7,13,3,9)
Block(-7,13,4,9)
Block(-7,13,5,9)
Block(-7,13,6,9)
Block(-7,13,7,9)
Block(-7,13,8,9)
Block(-7,14,5,139:1)
Block(-7,14,7,139:1)
Block(-7,15,5,126:1)
Block(-7,15,6,126:1)
Block(-7,15,7,126:1)
Block(-6,0,-7,1)
Block(-6,0,-6,1)
Block(-6,0,-5,1)
Block(-6,0,-4,1)
Block(-6,0,-3,1)
Block(-6,0,-2,1)
Block(-6,0,-1,1)
Block(-6,0,0,1)
Block(-6,0,1,1)
Block(-6,0,2,1)
Block(-6,0,3,1)
Block(-6,0,4,1)
Block(-6,0,5,1)
Block(-6,0,6,1)
Block(-6,0,7,1)
Block(-6,0,8,1)
Block(-6,1,-7,9)
Block(-6,1,-6,9)
Block(-6,1,-5,9)
Block(-6,1,-4,9)
Block(-6,1,-3,9)
Block(-6,1,-2,17:1)
Block(-6,1,-1,9)
Block(-6,1,0,9)
Block(-6,1,1,1)
Block(-6,1,2,1)
Block(-6,1,3,1)
Block(-6,1,4,1)
Block(-6,1,5,17:1)
Block(-6,1,6,1)
Block(-6,1,7,17:1)
Block(-6,1,8,1)
Block(-6,2,-7,9)
Block(-6,2,-6,9)
Block(-6,2,-5,9)
Block(-6,2,-4,9)
Block(-6,2,-3,9)
Block(-6,2,-2,17:1)
Block(-6,2,-1,9)
Block(-6,2,0,9)
Block(-6,2,1,1)
Block(-6,2,2,1)
Block(-6,2,3,15)
Block(-6,2,4,15)
Block(-6,2,5,17:1)
Block(-6,2,6,1)
Block(-6,2,7,17:1)
Block(-6,2,8,1)
Block(-6,3,-7,9)
Block(-6,3,-6,9)
Block(-6,3,-5,9)
Block(-6,3,-4,9)
Block(-6,3,-3,9)
Block(-6,3,-2,17:1)
Block(-6,3,-1,9)
Block(-6,3,0,9)
Block(-6,3,1,1)
Block(-6,3,2,1)
Block(-6,3,3,1)
Block(-6,3,4,15)
Block(-6,3,5,17:1)
Block(-6,3,6,1)
Block(-6,3,7,17:1)
Block(-6,3,8,1)
Block(-6,4,-7,9)
Block(-6,4,-6,9)
Block(-6,4,-5,9)
Block(-6,4,-4,9)
Block(-6,4,-3,9)
Block(-6,4,-2,17:1)
Block(-6,4,-1,9)
Block(-6,4,0,9)
Block(-6,4,1,1)
Block(-6,4,2,1)
Block(-6,4,3,1)
Block(-6,4,4,1)
Block(-6,4,5,17:1)
Block(-6,4,6,16)
Block(-6,4,7,17:1)
Block(-6,4,8,1)
Block(-6,5,-7,9)
Block(-6,5,-6,9)
Block(-6,5,-5,9)
Block(-6,5,-4,9)
Block(-6,5,-3,9)
Block(-6,5,-2,17:1)
Block(-6,5,-1,9)
Block(-6,5,0,9)
Block(-6,5,1,1)
Block(-6,5,2,13)
Block(-6,5,3,13)
Block(-6,5,4,13)
Block(-6,5,5,17:1)
Block(-6,5,6,16)
Block(-6,5,7,17:1)
Block(-6,5,8,1)
Block(-6,6,-7,9)
Block(-6,6,-6,9)
Block(-6,6,-5,9)
Block(-6,6,-4,9)
Block(-6,6,-3,9)
Block(-6,6,-2,17:1)
Block(-6,6,-1,9)
Block(-6,6,0,9)
Block(-6,6,1,13)
Block(-6,6,2,13)
Block(-6,6,3,13)
Block(-6,6,4,13)
Block(-6,6,5,17:1)
Block(-6,6,6,13)
Block(-6,6,7,17:1)
Block(-6,6,8,1)
Block(-6,7,-7,9)
Block(-6,7,-6,9)
Block(-6,7,-5,9)
Block(-6,7,-4,9)
Block(-6,7,-3,9)
Block(-6,7,-2,17:1)
Block(-6,7,-1,9)
Block(-6,7,0,9)
Block(-6,7,1,13)
Block(-6,7,2,13)
Block(-6,7,3,13)
Block(-6,7,4,13)
Block(-6,7,5,17:1)
Block(-6,7,6,13)
Block(-6,7,7,17:1)
Block(-6,7,8,1)
Block(-6,8,-7,9)
Block(-6,8,-6,9)
Block(-6,8,-5,9)
Block(-6,8,-4,9)
Block(-6,8,-3,9)
Block(-6,8,-2,17:1)
Block(-6,8,-1,9)
Block(-6,8,0,9)
Block(-6,8,1,3)
Block(-6,8,2,3)
Block(-6,8,3,3)
Block(-6,8,4,3)
Block(-6,8,5,17:1)
Block(-6,8,6,15)
Block(-6,8,7,17:1)
Block(-6,8,8,1)
Block(-6,9,-7,9)
Block(-6,9,-6,9)
Block(-6,9,-5,9)
Block(-6,9,-4,9)
Block(-6,9,-3,9)
Block(-6,9,-2,17:1)
Block(-6,9,-1,9)
Block(-6,9,0,9)
Block(-6,9,1,3)
Block(-6,9,2,3)
Block(-6,9,3,3)
Block(-6,9,4,3)
Block(-6,9,5,17:1)
Block(-6,9,6,3)
Block(-6,9,7,17:1)
Block(-6,9,8,3)
Block(-6,10,-7,9)
Block(-6,10,-6,9)
Block(-6,10,-5,9)
Block(-6,10,-4,9)
Block(-6,10,-3,9)
Block(-6,10,-2,17:1)
Block(-6,10,-1,9)
Block(-6,10,0,9)
Block(-6,10,1,3)
Block(-6,10,2,3)
Block(-6,10,3,3)
Block(-6,10,4,3)
Block(-6,10,5,17:1)
Block(-6,10,6,9:8)
Block(-6,10,7,17:1)
Block(-6,10,8,9:8)
Block(-6,11,-7,9)
Block(-6,11,-6,9)
Block(-6,11,-5,9)
Block(-6,11,-4,9)
Block(-6,11,-3,9)
Block(-6,11,-2,17:1)
Block(-6,11,-1,9)
Block(-6,11,0,9)
Block(-6,11,1,9)
Block(-6,11,2,9)
Block(-6,11,3,9)
Block(-6,11,4,9)
Block(-6,11,5,17:1)
Block(-6,11,6,9:8)
Block(-6,11,7,17:1)
Block(-6,11,8,9:8)
Block(-6,12,-7,9)
Block(-6,12,-6,9)
Block(-6,12,-5,9)
Block(-6,12,-4,9)
Block(-6,12,-3,9)
Block(-6,12,-2,17:1)
Block(-6,12,-1,9)
Block(-6,12,0,9)
Block(-6,12,1,9)
Block(-6,12,2,9)
Block(-6,12,3,9)
Block(-6,12,4,9)
Block(-6,12,5,17:1)
Block(-6,12,6,9)
Block(-6,12,7,17:1)
Block(-6,12,8,9)
Block(-6,13,-7,9)
Block(-6,13,-6,9)
Block(-6,13,-5,9)
Block(-6,13,-4,9)
Block(-6,13,-3,9)
Block(-6,13,-2,17:1)
Block(-6,13,-1,9)
Block(-6,13,0,9)
Block(-6,13,1,9)
Block(-6,13,2,9)
Block(-6,13,3,9)
Block(-6,13,4,9)
Block(-6,13,5,17:1)
Block(-6,13,6,9)
Block(-6,13,7,17:1)
Block(-6,13,8,9)
Block(-6,14,-7,139:1)
Block(-6,14,-6,139:1)
Block(-6,14,-5,139:1)
Block(-6,14,-4,139:1)
Block(-6,14,-3,139:1)
Block(-6,14,-2,17:1)
Block(-6,14,-1,139:1)
Block(-6,14,0,139:1)
Block(-6,14,1,139:1)
Block(-6,14,2,139:1)
Block(-6,14,3,139:1)
Block(-6,14,4,139:1)
Block(-6,14,5,17:1)
Block(-6,14,7,17:1)
Block(-6,14,8,139:1)
Block(-6,15,-7,126:1)
Block(-6,15,-6,126:1)
Block(-6,15,-5,126:1)
Block(-6,15,-4,126:1)
Block(-6,15,-3,126:1)
Block(-6,15,-2,17:1)
Block(-6,15,-1,126:1)
Block(-6,15,0,126:1)
Block(-6,15,1,126:1)
Block(-6,15,2,126:1)
Block(-6,15,3,126:1)
Block(-6,15,4,126:1)
Block(-6,15,5,17:1)
Block(-6,15,6,126:1)
Block(-6,15,7,17:1)
Block(-6,15,8,126:1)
Block(-5,0,-7,1)
Block(-5,0,-6,1)
Block(-5,0,-5,1)
Block(-5,0,-4,1)
Block(-5,0,-3,1)
Block(-5,0,-2,1)
Block(-5,0,-1,1)
Block(-5,0,0,1)
Block(-5,0,1,1)
Block(-5,0,2,1)
Block(-5,0,3,1)
Block(-5,0,4,1)
Block(-5,0,5,1)
Block(-5,0,6,1)
Block(-5,0,7,1)
Block(-5,0,8,1)
Block(-5,1,-7,1)
Block(-5,1,-6,1)
Block(-5,1,-5,1)
Block(-5,1,-4,1)
Block(-5,1,-3,1)
Block(-5,1,-2,1)
Block(-5,1,-1,1)
Block(-5,1,0,1)
Block(-5,1,1,1)
Block(-5,1,2,1)
Block(-5,1,3,1)
Block(-5,1,4,1)
Block(-5,1,5,1)
Block(-5,1,6,1)
Block(-5,1,7,1)
Block(-5,1,8,1)
Block(-5,2,-7,1)
Block(-5,2,-6,1)
Block(-5,2,-5,1)
Block(-5,2,-4,1)
Block(-5,2,-3,1)
Block(-5,2,-2,1)
Block(-5,2,-1,1)
Block(-5,2,0,1)
Block(-5,2,1,1)
Block(-5,2,2,1)
Block(-5,2,3,1)
Block(-5,2,4,1)
Block(-5,2,5,1)
Block(-5,2,6,1)
Block(-5,2,7,1)
Block(-5,2,8,1)
Block(-5,3,-7,1)
Block(-5,3,-6,1)
Block(-5,3,-5,1)
Block(-5,3,-4,1)
Block(-5,3,-3,1)
Block(-5,3,-2,1)
Block(-5,3,-1,1)
Block(-5,3,0,1)
Block(-5,3,1,1)
Block(-5,3,2,1)
Block(-5,3,3,1)
Block(-5,3,4,1)
Block(-5,3,5,1)
Block(-5,3,6,1)
Block(-5,3,7,1)
Block(-5,3,8,1)
Block(-5,4,-7,1)
Block(-5,4,-6,1)
Block(-5,4,-5,1)
Block(-5,4,-4,1)
Block(-5,4,-3,1)
Block(-5,4,-2,1)
Block(-5,4,-1,1)
Block(-5,4,0,1)
Block(-5,4,1,1)
Block(-5,4,2,1)
Block(-5,4,3,1)
Block(-5,4,4,1)
Block(-5,4,5,1)
Block(-5,4,6,16)
Block(-5,4,7,16)
Block(-5,4,8,1)
Block(-5,5,-7,1)
Block(-5,5,-6,1)
Block(-5,5,-5,1)
Block(-5,5,-4,1)
Block(-5,5,-3,1)
Block(-5,5,-2,1)
Block(-5,5,-1,1)
Block(-5,5,0,1)
Block(-5,5,1,1)
Block(-5,5,2,1)
Block(-5,5,3,13)
Block(-5,5,4,13)
Block(-5,5,5,1)
Block(-5,5,6,16)
Block(-5,5,7,16)
Block(-5,5,8,1)
Block(-5,6,-7,1)
Block(-5,6,-6,1)
Block(-5,6,-5,1)
Block(-5,6,-4,1)
Block(-5,6,-3,1)
Block(-5,6,-2,1)
Block(-5,6,-1,1)
Block(-5,6,0,13)
Block(-5,6,1,13)
Block(-5,6,2,13)
Block(-5,6,3,13)
Block(-5,6,4,13)
Block(-5,6,5,1)
Block(-5,6,6,1)
Block(-5,6,7,1)
Block(-5,6,8,1)
Block(-5,7,-7,1)
Block(-5,7,-6,1)
Block(-5,7,-5,1)
Block(-5,7,-4,1)
Block(-5,7,-3,1)
Block(-5,7,-2,1)
Block(-5,7,-1,1)
Block(-5,7,0,13)
Block(-5,7,1,13)
Block(-5,7,2,13)
Block(-5,7,3,13)
Block(-5,7,4,13)
Block(-5,7,5,1)
Block(-5,7,6,1)
Block(-5,7,7,1)
Block(-5,7,8,1)
Block(-5,8,-7,1)
Block(-5,8,-6,1)
Block(-5,8,-5,1)
Block(-5,8,-4,1)
Block(-5,8,-3,1)
Block(-5,8,-2,1)
Block(-5,8,-1,1)
Block(-5,8,0,1)
Block(-5,8,1,1)
Block(-5,8,2,1)
Block(-5,8,3,13)
Block(-5,8,4,13)
Block(-5,8,5,1)
Block(-5,8,6,15)
Block(-5,8,7,15)
Block(-5,8,8,1)
Block(-5,9,-7,3)
Block(-5,9,-6,9:8)
Block(-5,9,-5,3)
Block(-5,9,-4,3)
Block(-5,9,-3,3)
Block(-5,9,-2,3)
Block(-5,9,-1,1)
Block(-5,9,0,1)
Block(-5,9,1,1)
Block(-5,9,2,1)
Block(-5,9,3,13)
Block(-5,9,4,13)
Block(-5,9,5,1)
Block(-5,9,6,15)
Block(-5,9,7,15)
Block(-5,9,8,1)
Block(-5,10,-7,9:8)
Block(-5,10,-6,9:8)
Block(-5,10,-5,9:8)
Block(-5,10,-4,9:8)
Block(-5,10,-3,9:8)
Block(-5,10,-2,9:8)
Block(-5,10,-1,3)
Block(-5,10,0,3)
Block(-5,10,1,3)
Block(-5,10,2,3)
Block(-5,10,3,13)
Block(-5,10,4,13)
Block(-5,10,5,1)
Block(-5,10,6,15)
Block(-5,10,7,1)
Block(-5,10,8,1)
Block(-5,11,-7,9:8)
Block(-5,11,-6,9:8)
Block(-5,11,-5,9:8)
Block(-5,11,-4,9:8)
Block(-5,11,-3,9:8)
Block(-5,11,-2,9:8)
Block(-5,11,-1,9:8)
Block(-5,11,0,9:8)
Block(-5,11,1,3)
Block(-5,11,2,3)
Block(-5,11,3,3)
Block(-5,11,4,3)
Block(-5,11,5,3)
Block(-5,11,6,3)
Block(-5,11,7,3)
Block(-5,11,8,3)
Block(-5,12,-7,9)
Block(-5,12,-6,9)
Block(-5,12,-5,9)
Block(-5,12,-4,9)
Block(-5,12,-3,9)
Block(-5,12,-2,9)
Block(-5,12,-1,9)
Block(-5,12,0,9)
Block(-5,12,1,9)
Block(-5,12,2,9)
Block(-5,12,3,9)
Block(-5,12,4,9)
Block(-5,12,5,9)
Block(-5,12,6,9)
Block(-5,12,7,9)
Block(-5,12,8,9)
Block(-5,13,-7,9)
Block(-5,13,-6,9)
Block(-5,13,-5,9)
Block(-5,13,-4,9)
Block(-5,13,-3,9)
Block(-5,13,-2,9)
Block(-5,13,-1,9)
Block(-5,13,0,9)
Block(-5,13,1,9)
Block(-5,13,2,9)
Block(-5,13,3,9)
Block(-5,13,4,9)
Block(-5,13,5,9)
Block(-5,13,6,9)
Block(-5,13,7,9)
Block(-5,13,8,9)
Block(-5,15,-7,126:1)
Block(-5,15,-6,126:1)
Block(-5,15,-5,126:1)
Block(-5,15,-4,126:1)
Block(-5,15,-3,126:1)
Block(-5,15,-2,126:1)
Block(-5,15,-1,126:1)
Block(-5,15,0,126:1)
Block(-5,15,1,126:1)
Block(-5,15,2,126:1)
Block(-5,15,3,126:1)
Block(-5,15,4,126:1)
Block(-5,15,5,126:1)
Block(-5,15,6,126:1)
Block(-5,15,7,126:1)
Block(-5,15,8,126:1)
Block(-4,0,-7,1)
Block(-4,0,-6,1)
Block(-4,0,-5,1)
Block(-4,0,-4,1)
Block(-4,0,-3,1)
Block(-4,0,-2,1)
Block(-4,0,-1,1)
Block(-4,0,0,1)
Block(-4,0,1,1)
Block(-4,0,2,1)
Block(-4,0,3,1)
Block(-4,0,4,1)
Block(-4,0,5,1)
Block(-4,0,6,1)
Block(-4,0,7,1)
Block(-4,0,8,1)
Block(-4,1,-7,1)
Block(-4,1,-6,1)
Block(-4,1,-5,1)
Block(-4,1,-4,1)
Block(-4,1,-3,1)
Block(-4,1,-2,1)
Block(-4,1,-1,1)
Block(-4,1,0,1)
Block(-4,1,1,1)
Block(-4,1,2,1)
Block(-4,1,3,1)
Block(-4,1,4,1)
Block(-4,1,5,1)
Block(-4,1,6,1)
Block(-4,1,7,1)
Block(-4,1,8,1)
Block(-4,2,-7,3)
Block(-4,2,-6,3)
Block(-4,2,-5,1)
Block(-4,2,-4,1)
Block(-4,2,-3,1)
Block(-4,2,-2,1)
Block(-4,2,-1,1)
Block(-4,2,0,1)
Block(-4,2,1,1)
Block(-4,2,2,1)
Block(-4,2,3,1)
Block(-4,2,4,1)
Block(-4,2,5,1)
Block(-4,2,6,1)
Block(-4,2,7,1)
Block(-4,2,8,1)
Block(-4,3,-7,3)
Block(-4,3,-6,3)
Block(-4,3,-5,1)
Block(-4,3,-4,1)
Block(-4,3,-3,1)
Block(-4,3,-2,1)
Block(-4,3,-1,1)
Block(-4,3,0,1)
Block(-4,3,1,1)
Block(-4,3,2,1)
Block(-4,3,3,1)
Block(-4,3,4,1)
Block(-4,3,5,1)
Block(-4,3,6,1)
Block(-4,3,7,1)
Block(-4,3,8,1)
Block(-4,4,-7,1)
Block(-4,4,-6,1)
Block(-4,4,-5,1)
Block(-4,4,-4,1)
Block(-4,4,-3,1)
Block(-4,4,-2,1)
Block(-4,4,-1,1)
Block(-4,4,0,1)
Block(-4,4,1,1)
Block(-4,4,2,1)
Block(-4,4,3,1)
Block(-4,4,4,1)
Block(-4,4,5,1)
Block(-4,4,6,16)
Block(-4,4,7,16)
Block(-4,4,8,1)
Block(-4,5,-7,1)
Block(-4,5,-6,1)
Block(-4,5,-5,1)
Block(-4,5,-4,1)
Block(-4,5,-3,1)
Block(-4,5,-2,1)
Block(-4,5,-1,1)
Block(-4,5,0,1)
Block(-4,5,1,1)
Block(-4,5,2,1)
Block(-4,5,3,1)
Block(-4,5,4,1)
Block(-4,5,5,1)
Block(-4,5,6,16)
Block(-4,5,7,16)
Block(-4,5,8,1)
Block(-4,6,-7,1)
Block(-4,6,-6,1)
Block(-4,6,-5,1)
Block(-4,6,-4,1)
Block(-4,6,-3,1)
Block(-4,6,-2,1)
Block(-4,6,-1,1)
Block(-4,6,0,13)
Block(-4,6,1,13)
Block(-4,6,2,1)
Block(-4,6,3,1)
Block(-4,6,4,1)
Block(-4,6,5,1)
Block(-4,6,6,1)
Block(-4,6,7,1)
Block(-4,6,8,1)
Block(-4,7,-7,1)
Block(-4,7,-6,1)
Block(-4,7,-5,1)
Block(-4,7,-4,1)
Block(-4,7,-3,1)
Block(-4,7,-2,1)
Block(-4,7,-1,1)
Block(-4,7,0,13)
Block(-4,7,1,13)
Block(-4,7,2,1)
Block(-4,7,3,1)
Block(-4,7,4,1)
Block(-4,7,5,1)
Block(-4,7,6,1)
Block(-4,7,7,1)
Block(-4,7,8,1)
Block(-4,8,-7,1)
Block(-4,8,-6,1)
Block(-4,8,-5,1)
Block(-4,8,-4,1)
Block(-4,8,-3,1)
Block(-4,8,-2,1)
Block(-4,8,-1,1)
Block(-4,8,0,1)
Block(-4,8,1,1)
Block(-4,8,2,1)
Block(-4,8,3,1)
Block(-4,8,4,1)
Block(-4,8,5,1)
Block(-4,8,6,1)
Block(-4,8,7,1)
Block(-4,8,8,1)
Block(-4,9,-7,1)
Block(-4,9,-6,1)
Block(-4,9,-5,1)
Block(-4,9,-4,1)
Block(-4,9,-3,1)
Block(-4,9,-2,1)
Block(-4,9,-1,1)
Block(-4,9,0,1)
Block(-4,9,1,1)
Block(-4,9,2,1)
Block(-4,9,3,1)
Block(-4,9,4,1)
Block(-4,9,5,1)
Block(-4,9,6,1)
Block(-4,9,7,1)
Block(-4,9,8,1)
Block(-4,10,-7,3)
Block(-4,10,-6,1)
Block(-4,10,-5,1)
Block(-4,10,-4,1)
Block(-4,10,-3,1)
Block(-4,10,-2,3)
Block(-4,10,-1,3)
Block(-4,10,0,1)
Block(-4,10,1,3)
Block(-4,10,2,3)
Block(-4,10,3,1)
Block(-4,10,4,1)
Block(-4,10,5,3)
Block(-4,10,6,3)
Block(-4,10,7,3)
Block(-4,10,8,3)
Block(-4,11,-7,3)
Block(-4,11,-6,3)
Block(-4,11,-5,1)
Block(-4,11,-4,1)
Block(-4,11,-3,1)
Block(-4,11,-2,3)
Block(-4,11,-1,3)
Block(-4,11,0,3)
Block(-4,11,1,3)
Block(-4,11,2,3)
Block(-4,11,3,3)
Block(-4,11,4,3)
Block(-4,11,5,3)
Block(-4,11,6,3)
Block(-4,11,7,3)
Block(-4,11,8,3)
Block(-4,12,-7,3)
Block(-4,12,-6,3)
Block(-4,12,-5,3)
Block(-4,12,-4,3)
Block(-4,12,-3,3)
Block(-4,12,-2,3)
Block(-4,12,-1,9)
Block(-4,12,0,9)
Block(-4,12,1,9)
Block(-4,12,2,9)
Block(-4,12,3,9)
Block(-4,12,4,9)
Block(-4,12,5,9)
Block(-4,12,6,9)
Block(-4,12,7,9)
Block(-4,12,8,9)
Block(-4,13,-7,9)
Block(-4,13,-6,9)
Block(-4,13,-5,9)
Block(-4,13,-4,9)
Block(-4,13,-3,9)
Block(-4,13,-2,9)
Block(-4,13,-1,9)
Block(-4,13,0,9)
Block(-4,13,1,9)
Block(-4,13,2,9)
Block(-4,13,3,9)
Block(-4,13,4,9)
Block(-4,13,5,9)
Block(-4,13,6,9)
Block(-4,13,7,9)
Block(-4,13,8,9)
Block(-4,15,-7,126:1)
Block(-4,15,-6,126:1)
Block(-4,15,-5,126:1)
Block(-4,15,-4,126:1)
Block(-4,15,-3,126:1)
Block(-4,15,-2,126:1)
Block(-4,15,-1,126:1)
Block(-4,15,0,126:1)
Block(-4,15,1,126:1)
Block(-4,15,2,126:1)
Block(-4,15,3,126:1)
Block(-4,15,4,126:1)
Block(-4,15,5,126:1)
Block(-4,15,6,126:1)
Block(-4,15,7,126:1)
Block(-4,15,8,126:1)
Block(-3,0,-7,1)
Block(-3,0,-6,1)
Block(-3,0,-5,1)
Block(-3,0,-4,1)
Block(-3,0,-3,1)
Block(-3,0,-2,1)
Block(-3,0,-1,1)
Block(-3,0,0,1)
Block(-3,0,1,1)
Block(-3,0,2,1)
Block(-3,0,3,1)
Block(-3,0,4,1)
Block(-3,0,5,1)
Block(-3,0,6,1)
Block(-3,0,7,1)
Block(-3,0,8,1)
Block(-3,1,-7,1)
Block(-3,1,-6,3)
Block(-3,1,-5,1)
Block(-3,1,-4,1)
Block(-3,1,-3,1)
Block(-3,1,-2,1)
Block(-3,1,-1,1)
Block(-3,1,0,1)
Block(-3,1,1,1)
Block(-3,1,2,1)
Block(-3,1,3,1)
Block(-3,1,4,1)
Block(-3,1,5,1)
Block(-3,1,6,1)
Block(-3,1,7,1)
Block(-3,1,8,1)
Block(-3,2,-7,3)
Block(-3,2,-6,3)
Block(-3,2,-5,3)
Block(-3,2,-4,3)
Block(-3,2,-3,1)
Block(-3,2,-2,1)
Block(-3,2,-1,1)
Block(-3,2,0,1)
Block(-3,2,1,1)
Block(-3,2,2,1)
Block(-3,2,3,1)
Block(-3,2,4,1)
Block(-3,2,5,1)
Block(-3,2,6,1)
Block(-3,2,7,1)
Block(-3,2,8,1)
Block(-3,3,-7,3)
Block(-3,3,-6,3)
Block(-3,3,-5,3)
Block(-3,3,-4,3)
Block(-3,3,-3,1)
Block(-3,3,-2,1)
Block(-3,3,-1,1)
Block(-3,3,0,1)
Block(-3,3,1,1)
Block(-3,3,2,1)
Block(-3,3,3,1)
Block(-3,3,4,1)
Block(-3,3,5,1)
Block(-3,3,6,1)
Block(-3,3,7,1)
Block(-3,3,8,1)
Block(-3,4,-7,1)
Block(-3,4,-6,3)
Block(-3,4,-5,1)
Block(-3,4,-4,1)
Block(-3,4,-3,1)
Block(-3,4,-2,1)
Block(-3,4,-1,1)
Block(-3,4,0,1)
Block(-3,4,1,1)
Block(-3,4,2,1)
Block(-3,4,3,1)
Block(-3,4,4,1)
Block(-3,4,5,1)
Block(-3,4,6,16)
Block(-3,4,7,16)
Block(-3,4,8,1)
Block(-3,5,-7,1)
Block(-3,5,-6,1)
Block(-3,5,-5,1)
Block(-3,5,-4,1)
Block(-3,5,-3,1)
Block(-3,5,-2,1)
Block(-3,5,-1,1)
Block(-3,5,0,1)
Block(-3,5,1,1)
Block(-3,5,2,1)
Block(-3,5,3,1)
Block(-3,5,4,1)
Block(-3,5,5,1)
Block(-3,5,6,16)
Block(-3,5,7,16)
Block(-3,5,8,1)
Block(-3,6,-7,1)
Block(-3,6,-6,1)
Block(-3,6,-5,1)
Block(-3,6,-4,1)
Block(-3,6,-3,1)
Block(-3,6,-2,1)
Block(-3,6,-1,1)
Block(-3,6,0,1)
Block(-3,6,1,1)
Block(-3,6,2,1)
Block(-3,6,3,1)
Block(-3,6,4,1)
Block(-3,6,5,1)
Block(-3,6,6,1)
Block(-3,6,7,1)
Block(-3,6,8,1)
Block(-3,7,-7,1)
Block(-3,7,-6,1)
Block(-3,7,-5,1)
Block(-3,7,-4,1)
Block(-3,7,-3,1)
Block(-3,7,-2,1)
Block(-3,7,-1,1)
Block(-3,7,0,1)
Block(-3,7,1,1)
Block(-3,7,2,1)
Block(-3,7,3,1)
Block(-3,7,4,1)
Block(-3,7,5,1)
Block(-3,7,6,1)
Block(-3,7,7,1)
Block(-3,7,8,1)
Block(-3,8,-7,1)
Block(-3,8,-6,1)
Block(-3,8,-5,1)
Block(-3,8,-4,1)
Block(-3,8,-3,1)
Block(-3,8,-2,1)
Block(-3,8,-1,1)
Block(-3,8,0,1)
Block(-3,8,1,1)
Block(-3,8,2,1)
Block(-3,8,3,1)
Block(-3,8,4,1)
Block(-3,8,5,1)
Block(-3,8,6,1)
Block(-3,8,7,1)
Block(-3,8,8,1)
Block(-3,9,-7,1)
Block(-3,9,-6,1)
Block(-3,9,-5,1)
Block(-3,9,-4,1)
Block(-3,9,-3,1)
Block(-3,9,-2,1)
Block(-3,9,-1,1)
Block(-3,9,0,1)
Block(-3,9,1,1)
Block(-3,9,2,1)
Block(-3,9,3,1)
Block(-3,9,4,1)
Block(-3,9,5,1)
Block(-3,9,6,1)
Block(-3,9,7,1)
Block(-3,9,8,1)
Block(-3,10,-7,3)
Block(-3,10,-6,1)
Block(-3,10,-5,1)
Block(-3,10,-4,1)
Block(-3,10,-3,1)
Block(-3,10,-2,1)
Block(-3,10,-1,1)
Block(-3,10,0,1)
Block(-3,10,1,1)
Block(-3,10,2,3)
Block(-3,10,3,1)
Block(-3,10,4,1)
Block(-3,10,5,1)
Block(-3,10,6,1)
Block(-3,10,7,1)
Block(-3,10,8,1)
Block(-3,11,-7,3)
Block(-3,11,-6,1)
Block(-3,11,-5,1)
Block(-3,11,-4,1)
Block(-3,11,-3,1)
Block(-3,11,-2,1)
Block(-3,11,-1,1)
Block(-3,11,0,1)
Block(-3,11,1,1)
Block(-3,11,2,3)
Block(-3,11,3,3)
Block(-3,11,4,3)
Block(-3,11,5,3)
Block(-3,11,6,3)
Block(-3,11,7,3)
Block(-3,11,8,3)
Block(-3,12,-7,3)
Block(-3,12,-6,3)
Block(-3,12,-5,3)
Block(-3,12,-4,3)
Block(-3,12,-3,3)
Block(-3,12,-2,3)
Block(-3,12,-1,3)
Block(-3,12,0,3)
Block(-3,12,1,3)
Block(-3,12,2,3)
Block(-3,12,3,3)
Block(-3,12,4,3)
Block(-3,12,5,3)
Block(-3,12,6,3)
Block(-3,12,7,3)
Block(-3,12,8,3)
Block(-3,13,-7,2)
Block(-3,13,-6,2)
Block(-3,13,-5,2)
Block(-3,13,-4,2)
Block(-3,13,-3,2)
Block(-3,13,-2,2)
Block(-3,13,-1,9)
Block(-3,13,0,9)
Block(-3,13,1,9)
Block(-3,13,2,9)
Block(-3,13,3,9)
Block(-3,13,4,9)
Block(-3,13,5,9)
Block(-3,13,6,9)
Block(-3,13,7,9)
Block(-3,13,8,9)
Block(-3,14,-2,2)
Block(-3,15,-7,126:1)
Block(-3,15,-6,126:1)
Block(-3,15,-5,126:1)
Block(-3,15,-4,126:1)
Block(-3,15,-3,126:1)
Block(-3,15,-1,126:1)
Block(-3,15,0,126:1)
Block(-3,15,1,126:1)
Block(-3,15,2,126:1)
Block(-3,15,3,126:1)
Block(-3,15,4,126:1)
Block(-3,15,5,126:1)
Block(-3,15,6,126:1)
Block(-3,15,7,126:1)
Block(-3,15,8,126:1)
Block(-2,0,-7,1)
Block(-2,0,-6,1)
Block(-2,0,-5,1)
Block(-2,0,-4,1)
Block(-2,0,-3,1)
Block(-2,0,-2,1)
Block(-2,0,-1,1)
Block(-2,0,0,1)
Block(-2,0,1,1)
Block(-2,0,2,1)
Block(-2,0,3,1)
Block(-2,0,4,1)
Block(-2,0,5,1)
Block(-2,0,6,1)
Block(-2,0,7,1)
Block(-2,0,8,1)
Block(-2,1,-7,1)
Block(-2,1,-6,3)
Block(-2,1,-5,3)
Block(-2,1,-4,1)
Block(-2,1,-3,1)
Block(-2,1,-2,1)
Block(-2,1,-1,1)
Block(-2,1,0,1)
Block(-2,1,1,1)
Block(-2,1,2,1)
Block(-2,1,3,1)
Block(-2,1,4,1)
Block(-2,1,5,1)
Block(-2,1,6,1)
Block(-2,1,7,1)
Block(-2,1,8,1)
Block(-2,2,-7,3)
Block(-2,2,-6,3)
Block(-2,2,-5,3)
Block(-2,2,-4,3)
Block(-2,2,-3,1)
Block(-2,2,-2,1)
Block(-2,2,-1,1)
Block(-2,2,0,1)
Block(-2,2,1,1)
Block(-2,2,2,1)
Block(-2,2,3,1)
Block(-2,2,4,1)
Block(-2,2,5,1)
Block(-2,2,6,1)
Block(-2,2,7,1)
Block(-2,2,8,1)
Block(-2,3,-7,3)
Block(-2,3,-6,3)
Block(-2,3,-5,3)
Block(-2,3,-4,3)
Block(-2,3,-3,1)
Block(-2,3,-2,1)
Block(-2,3,-1,1)
Block(-2,3,0,1)
Block(-2,3,1,1)
Block(-2,3,2,1)
Block(-2,3,3,1)
Block(-2,3,4,1)
Block(-2,3,5,1)
Block(-2,3,6,1)
Block(-2,3,7,1)
Block(-2,3,8,1)
Block(-2,4,-7,1)
Block(-2,4,-6,3)
Block(-2,4,-5,3)
Block(-2,4,-4,1)
Block(-2,4,-3,1)
Block(-2,4,-2,1)
Block(-2,4,-1,1)
Block(-2,4,0,1)
Block(-2,4,1,1)
Block(-2,4,2,1)
Block(-2,4,3,1)
Block(-2,4,4,1)
Block(-2,4,5,1)
Block(-2,4,6,1)
Block(-2,4,7,1)
Block(-2,4,8,1)
Block(-2,5,-7,1)
Block(-2,5,-6,1)
Block(-2,5,-5,1)
Block(-2,5,-4,1)
Block(-2,5,-3,1)
Block(-2,5,-2,1)
Block(-2,5,-1,1)
Block(-2,5,0,1)
Block(-2,5,1,1)
Block(-2,5,2,1)
Block(-2,5,3,1)
Block(-2,5,4,1)
Block(-2,5,5,1)
Block(-2,5,6,1)
Block(-2,5,7,1)
Block(-2,5,8,1)
Block(-2,6,-7,1)
Block(-2,6,-6,1)
Block(-2,6,-5,1)
Block(-2,6,-4,1)
Block(-2,6,-3,1)
Block(-2,6,-2,1)
Block(-2,6,-1,1)
Block(-2,6,0,1)
Block(-2,6,1,1)
Block(-2,6,2,1)
Block(-2,6,3,1)
Block(-2,6,4,1)
Block(-2,6,5,1)
Block(-2,6,6,1)
Block(-2,6,7,1)
Block(-2,6,8,1)
Block(-2,7,-7,1)
Block(-2,7,-6,1)
Block(-2,7,-5,1)
Block(-2,7,-4,1)
Block(-2,7,-3,1)
Block(-2,7,-2,1)
Block(-2,7,-1,1)
Block(-2,7,0,1)
Block(-2,7,1,1)
Block(-2,7,2,1)
Block(-2,7,3,1)
Block(-2,7,4,1)
Block(-2,7,5,1)
Block(-2,7,6,1)
Block(-2,7,7,1)
Block(-2,7,8,1)
Block(-2,8,-7,1)
Block(-2,8,-6,1)
Block(-2,8,-5,1)
Block(-2,8,-4,1)
Block(-2,8,-3,1)
Block(-2,8,-2,1)
Block(-2,8,-1,1)
Block(-2,8,0,1)
Block(-2,8,1,1)
Block(-2,8,2,1)
Block(-2,8,3,1)
Block(-2,8,4,1)
Block(-2,8,5,1)
Block(-2,8,6,1)
Block(-2,8,7,1)
Block(-2,8,8,1)
Block(-2,9,-7,1)
Block(-2,9,-6,1)
Block(-2,9,-5,1)
Block(-2,9,-4,1)
Block(-2,9,-3,1)
Block(-2,9,-2,1)
Block(-2,9,-1,1)
Block(-2,9,0,1)
Block(-2,9,1,1)
Block(-2,9,2,1)
Block(-2,9,3,1)
Block(-2,9,4,1)
Block(-2,9,5,1)
Block(-2,9,6,1)
Block(-2,9,7,1)
Block(-2,9,8,1)
Block(-2,10,-7,1)
Block(-2,10,-6,1)
Block(-2,10,-5,1)
Block(-2,10,-4,1)
Block(-2,10,-3,1)
Block(-2,10,-2,1)
Block(-2,10,-1,1)
Block(-2,10,0,1)
Block(-2,10,1,1)
Block(-2,10,2,1)
Block(-2,10,3,1)
Block(-2,10,4,1)
Block(-2,10,5,1)
Block(-2,10,6,1)
Block(-2,10,7,1)
Block(-2,10,8,3)
Block(-2,11,-7,1)
Block(-2,11,-6,1)
Block(-2,11,-5,1)
Block(-2,11,-4,1)
Block(-2,11,-3,1)
Block(-2,11,-2,1)
Block(-2,11,-1,1)
Block(-2,11,0,1)
Block(-2,11,1,1)
Block(-2,11,2,1)
Block(-2,11,3,3)
Block(-2,11,4,3)
Block(-2,11,5,3)
Block(-2,11,6,3)
Block(-2,11,7,3)
Block(-2,11,8,3)
Block(-2,12,-7,3)
Block(-2,12,-6,3)
Block(-2,12,-5,1)
Block(-2,12,-4,1)
Block(-2,12,-3,1)
Block(-2,12,-2,1)
Block(-2,12,-1,1)
Block(-2,12,0,1)
Block(-2,12,1,1)
Block(-2,12,2,3)
Block(-2,12,3,3)
Block(-2,12,4,3)
Block(-2,12,5,3)
Block(-2,12,6,3)
Block(-2,12,7,3)
Block(-2,12,8,3)
Block(-2,13,-7,3)
Block(-2,13,-6,3)
Block(-2,13,-5,3)
Block(-2,13,-4,3)
Block(-2,13,-3,3)
Block(-2,13,-2,3)
Block(-2,13,-1,3)
Block(-2,13,0,3)
Block(-2,13,1,3)
Block(-2,13,2,3)
Block(-2,13,3,3)
Block(-2,13,4,3)
Block(-2,13,5,3)
Block(-2,13,6,3)
Block(-2,13,7,3)
Block(-2,13,8,3)
Block(-2,14,-7,3)
Block(-2,14,-6,3)
Block(-2,14,-5,3)
Block(-2,14,-4,3)
Block(-2,14,-3,3)
Block(-2,14,-2,3)
Block(-2,14,-1,3)
Block(-2,14,0,3)
Block(-2,14,1,3)
Block(-2,14,2,3)
Block(-2,14,3,3)
Block(-2,14,4,3)
Block(-2,14,5,3)
Block(-2,14,6,3)
Block(-2,14,7,3)
Block(-2,14,8,3)
Block(-2,15,-7,5:1)
Block(-2,15,-6,5:1)
Block(-2,15,-5,5:1)
Block(-2,15,-4,5:1)
Block(-2,15,-3,5:1)
Block(-2,15,-2,5:1)
Block(-2,15,-1,5:1)
Block(-2,15,0,5:1)
Block(-2,15,1,5:1)
Block(-2,15,2,5:1)
Block(-2,15,3,5:1)
Block(-2,15,4,5:1)
Block(-2,15,5,5:1)
Block(-2,15,6,5:1)
Block(-2,15,7,5:1)
Block(-2,15,8,5:1)
Block(-2,16,-7,5:1)
Block(-2,16,3,5:1)
Block(-2,16,4,5:1)
Block(-2,16,5,5:1)
Block(-2,16,6,5:1)
Block(-2,16,7,5:1)
Block(-2,16,8,5:1)
Block(-2,17,-7,126)
Block(-2,17,3,126)
Block(-2,17,4,126)
Block(-2,17,5,126)
Block(-2,17,6,126)
Block(-2,17,7,126)
Block(-2,17,8,126)
Block(-2,35,-6,35:14)
Block(-1,0,-7,1)
Block(-1,0,-6,1)
Block(-1,0,-5,1)
Block(-1,0,-4,1)
Block(-1,0,-3,1)
Block(-1,0,-2,1)
Block(-1,0,-1,1)
Block(-1,0,0,1)
Block(-1,0,1,1)
Block(-1,0,2,1)
Block(-1,0,3,1)
Block(-1,0,4,1)
Block(-1,0,5,1)
Block(-1,0,6,1)
Block(-1,0,7,1)
Block(-1,0,8,1)
Block(-1,1,-7,1)
Block(-1,1,-6,3)
Block(-1,1,-5,3)
Block(-1,1,-4,3)
Block(-1,1,-3,3)
Block(-1,1,-2,1)
Block(-1,1,-1,1)
Block(-1,1,0,1)
Block(-1,1,1,1)
Block(-1,1,2,1)
Block(-1,1,3,1)
Block(-1,1,4,1)
Block(-1,1,5,1)
Block(-1,1,6,1)
Block(-1,1,7,1)
Block(-1,1,8,1)
Block(-1,2,-7,3)
Block(-1,2,-6,3)
Block(-1,2,-5,3)
Block(-1,2,-4,3)
Block(-1,2,-3,3)
Block(-1,2,-2,1)
Block(-1,2,-1,1)
Block(-1,2,0,1)
Block(-1,2,1,1)
Block(-1,2,2,1)
Block(-1,2,3,1)
Block(-1,2,4,1)
Block(-1,2,5,1)
Block(-1,2,6,1)
Block(-1,2,7,1)
Block(-1,2,8,1)
Block(-1,3,-7,3)
Block(-1,3,-6,3)
Block(-1,3,-5,3)
Block(-1,3,-4,3)
Block(-1,3,-3,3)
Block(-1,3,-2,1)
Block(-1,3,-1,1)
Block(-1,3,0,1)
Block(-1,3,1,1)
Block(-1,3,2,1)
Block(-1,3,3,1)
Block(-1,3,4,1)
Block(-1,3,5,1)
Block(-1,3,6,1)
Block(-1,3,7,1)
Block(-1,3,8,1)
Block(-1,4,-7,1)
Block(-1,4,-6,3)
Block(-1,4,-5,3)
Block(-1,4,-4,3)
Block(-1,4,-3,3)
Block(-1,4,-2,1)
Block(-1,4,-1,1)
Block(-1,4,0,1)
Block(-1,4,1,1)
Block(-1,4,2,1)
Block(-1,4,3,1)
Block(-1,4,4,1)
Block(-1,4,5,1)
Block(-1,4,6,1)
Block(-1,4,7,1)
Block(-1,4,8,1)
Block(-1,5,-7,1)
Block(-1,5,-6,1)
Block(-1,5,-5,1)
Block(-1,5,-4,1)
Block(-1,5,-3,1)
Block(-1,5,-2,1)
Block(-1,5,-1,1)
Block(-1,5,0,1)
Block(-1,5,1,1)
Block(-1,5,2,1)
Block(-1,5,3,1)
Block(-1,5,4,1)
Block(-1,5,5,1)
Block(-1,5,6,1)
Block(-1,5,7,1)
Block(-1,5,8,1)
Block(-1,6,-7,1)
Block(-1,6,-6,1)
Block(-1,6,-5,1)
Block(-1,6,-4,1)
Block(-1,6,-3,1)
Block(-1,6,-2,1)
Block(-1,6,-1,1)
Block(-1,6,0,1)
Block(-1,6,1,1)
Block(-1,6,2,1)
Block(-1,6,3,1)
Block(-1,6,4,1)
Block(-1,6,5,1)
Block(-1,6,6,1)
Block(-1,6,7,1)
Block(-1,6,8,1)
Block(-1,7,-7,1)
Block(-1,7,-6,1)
Block(-1,7,-5,1)
Block(-1,7,-4,1)
Block(-1,7,-3,1)
Block(-1,7,-2,1)
Block(-1,7,-1,1)
Block(-1,7,0,1)
Block(-1,7,1,1)
Block(-1,7,2,1)
Block(-1,7,3,1)
Block(-1,7,4,1)
Block(-1,7,5,1)
Block(-1,7,6,1)
Block(-1,7,7,1)
Block(-1,7,8,1)
Block(-1,8,-7,1)
Block(-1,8,-6,1)
Block(-1,8,-5,1)
Block(-1,8,-4,1)
Block(-1,8,-3,1)
Block(-1,8,-2,1)
Block(-1,8,-1,1)
Block(-1,8,0,1)
Block(-1,8,1,1)
Block(-1,8,2,1)
Block(-1,8,3,1)
Block(-1,8,4,1)
Block(-1,8,5,1)
Block(-1,8,6,1)
Block(-1,8,7,1)
Block(-1,8,8,1)
Block(-1,9,-7,1)
Block(-1,9,-6,1)
Block(-1,9,-5,1)
Block(-1,9,-4,1)
Block(-1,9,-3,1)
Block(-1,9,-2,1)
Block(-1,9,-1,1)
Block(-1,9,0,1)
Block(-1,9,1,1)
Block(-1,9,2,1)
Block(-1,9,3,1)
Block(-1,9,4,1)
Block(-1,9,5,1)
Block(-1,9,6,1)
Block(-1,9,7,1)
Block(-1,9,8,1)
Block(-1,10,-7,1)
Block(-1,10,-6,1)
Block(-1,10,-5,1)
Block(-1,10,-4,1)
Block(-1,10,-3,1)
Block(-1,10,-2,1)
Block(-1,10,-1,1)
Block(-1,10,0,1)
Block(-1,10,1,1)
Block(-1,10,2,1)
Block(-1,10,3,1)
Block(-1,10,4,1)
Block(-1,10,5,1)
Block(-1,10,6,1)
Block(-1,10,7,1)
Block(-1,10,8,1)
Block(-1,11,-7,1)
Block(-1,11,-6,1)
Block(-1,11,-5,1)
Block(-1,11,-4,1)
Block(-1,11,-3,1)
Block(-1,11,-2,1)
Block(-1,11,-1,1)
Block(-1,11,0,1)
Block(-1,11,1,1)
Block(-1,11,2,1)
Block(-1,11,3,1)
Block(-1,11,4,1)
Block(-1,11,5,1)
Block(-1,11,6,1)
Block(-1,11,7,1)
Block(-1,11,8,3)
Block(-1,12,-7,1)
Block(-1,12,-6,1)
Block(-1,12,-5,1)
Block(-1,12,-4,1)
Block(-1,12,-3,1)
Block(-1,12,-2,1)
Block(-1,12,-1,1)
Block(-1,12,0,1)
Block(-1,12,1,1)
Block(-1,12,2,3)
Block(-1,12,3,3)
Block(-1,12,4,3)
Block(-1,12,5,3)
Block(-1,12,6,3)
Block(-1,12,7,3)
Block(-1,12,8,3)
Block(-1,13,-7,3)
Block(-1,13,-6,3)
Block(-1,13,-5,3)
Block(-1,13,-4,3)
Block(-1,13,-3,3)
Block(-1,13,-2,3)
Block(-1,13,-1,3)
Block(-1,13,0,3)
Block(-1,13,1,3)
Block(-1,13,2,3)
Block(-1,13,3,3)
Block(-1,13,4,3)
Block(-1,13,5,3)
Block(-1,13,6,3)
Block(-1,13,7,3)
Block(-1,13,8,3)
Block(-1,14,-7,3)
Block(-1,14,-6,3)
Block(-1,14,-5,3)
Block(-1,14,-4,3)
Block(-1,14,-3,3)
Block(-1,14,-2,3)
Block(-1,14,-1,3)
Block(-1,14,0,3)
Block(-1,14,1,3)
Block(-1,14,2,3)
Block(-1,14,3,3)
Block(-1,14,4,3)
Block(-1,14,5,3)
Block(-1,14,6,3)
Block(-1,14,7,3)
Block(-1,14,8,3)
Block(-1,15,-7,3)
Block(-1,15,-6,2)
Block(-1,15,-5,2)
Block(-1,15,-4,2)
Block(-1,15,-3,2)
Block(-1,15,-2,2)
Block(-1,15,-1,3)
Block(-1,15,0,3)
Block(-1,15,1,3)
Block(-1,15,2,3)
Block(-1,15,3,3)
Block(-1,15,4,3)
Block(-1,15,5,3)
Block(-1,15,6,3)
Block(-1,15,7,3)
Block(-1,15,8,3)
Block(-1,16,-7,5)
Block(-1,16,-6,126)
Block(-1,16,-5,126)
Block(-1,16,-4,126)
Block(-1,16,-3,126)
Block(-1,16,-2,126)
Block(-1,16,-1,126)
Block(-1,16,0,126)
Block(-1,16,1,126)
Block(-1,16,2,126)
Block(-1,16,3,5)
Block(-1,16,4,5)
Block(-1,16,5,5)
Block(-1,16,6,5)
Block(-1,16,7,5)
Block(-1,16,8,5)
Block(-1,17,-7,126)
Block(-1,17,3,126)
Block(-1,35,-5,35:14)
Block(0,0,-7,1)
Block(0,0,-6,1)
Block(0,0,-5,1)
Block(0,0,-4,1)
Block(0,0,-3,1)
Block(0,0,-2,1)
Block(0,0,-1,1)
Block(0,0,0,1)
Block(0,0,1,1)
Block(0,0,2,1)
Block(0,0,3,1)
Block(0,0,4,1)
Block(0,0,5,1)
Block(0,0,6,1)
Block(0,0,7,1)
Block(0,0,8,1)
Block(0,1,-7,1)
Block(0,1,-6,1)
Block(0,1,-5,3)
Block(0,1,-4,3)
Block(0,1,-3,3)
Block(0,1,-2,1)
Block(0,1,-1,1)
Block(0,1,0,1)
Block(0,1,1,1)
Block(0,1,2,1)
Block(0,1,3,1)
Block(0,1,4,1)
Block(0,1,5,1)
Block(0,1,6,1)
Block(0,1,7,1)
Block(0,1,8,1)
Block(0,2,-7,1)
Block(0,2,-6,3)
Block(0,2,-5,3)
Block(0,2,-4,3)
Block(0,2,-3,3)
Block(0,2,-2,3)
Block(0,2,-1,1)
Block(0,2,0,1)
Block(0,2,1,1)
Block(0,2,2,1)
Block(0,2,3,1)
Block(0,2,4,1)
Block(0,2,5,1)
Block(0,2,6,1)
Block(0,2,7,1)
Block(0,2,8,1)
Block(0,3,-7,1)
Block(0,3,-6,3)
Block(0,3,-5,3)
Block(0,3,-4,3)
Block(0,3,-3,3)
Block(0,3,-2,3)
Block(0,3,-1,1)
Block(0,3,0,1)
Block(0,3,1,1)
Block(0,3,2,1)
Block(0,3,3,1)
Block(0,3,4,1)
Block(0,3,5,1)
Block(0,3,6,1)
Block(0,3,7,1)
Block(0,3,8,1)
Block(0,4,-7,1)
Block(0,4,-6,1)
Block(0,4,-5,3)
Block(0,4,-4,3)
Block(0,4,-3,3)
Block(0,4,-2,1)
Block(0,4,-1,1)
Block(0,4,0,1)
Block(0,4,1,1)
Block(0,4,2,1)
Block(0,4,3,1)
Block(0,4,4,1)
Block(0,4,5,1)
Block(0,4,6,1)
Block(0,4,7,1)
Block(0,4,8,1)
Block(0,5,-7,1)
Block(0,5,-6,1)
Block(0,5,-5,1)
Block(0,5,-4,1)
Block(0,5,-3,1)
Block(0,5,-2,1)
Block(0,5,-1,1)
Block(0,5,0,1)
Block(0,5,1,1)
Block(0,5,2,1)
Block(0,5,3,1)
Block(0,5,4,1)
Block(0,5,5,1)
Block(0,5,6,1)
Block(0,5,7,1)
Block(0,5,8,1)
Block(0,6,-7,1)
Block(0,6,-6,1)
Block(0,6,-5,1)
Block(0,6,-4,1)
Block(0,6,-3,1)
Block(0,6,-2,1)
Block(0,6,-1,1)
Block(0,6,0,1)
Block(0,6,1,1)
Block(0,6,2,1)
Block(0,6,3,1)
Block(0,6,4,1)
Block(0,6,5,1)
Block(0,6,6,1)
Block(0,6,7,1)
Block(0,6,8,1)
Block(0,7,-7,1)
Block(0,7,-6,1)
Block(0,7,-5,1)
Block(0,7,-4,1)
Block(0,7,-3,1)
Block(0,7,-2,1)
Block(0,7,-1,1)
Block(0,7,0,1)
Block(0,7,1,1)
Block(0,7,2,1)
Block(0,7,3,1)
Block(0,7,4,1)
Block(0,7,5,1)
Block(0,7,6,1)
Block(0,7,7,1)
Block(0,7,8,1)
Block(0,8,-7,1)
Block(0,8,-6,1)
Block(0,8,-5,1)
Block(0,8,-4,1)
Block(0,8,-3,1)
Block(0,8,-2,1)
Block(0,8,-1,1)
Block(0,8,0,1)
Block(0,8,1,1)
Block(0,8,2,1)
Block(0,8,3,1)
Block(0,8,4,1)
Block(0,8,5,1)
Block(0,8,6,1)
Block(0,8,7,1)
Block(0,8,8,1)
Block(0,9,-7,1)
Block(0,9,-6,1)
Block(0,9,-5,1)
Block(0,9,-4,1)
Block(0,9,-3,1)
Block(0,9,-2,1)
Block(0,9,-1,1)
Block(0,9,0,1)
Block(0,9,1,1)
Block(0,9,2,1)
Block(0,9,3,1)
Block(0,9,4,1)
Block(0,9,5,1)
Block(0,9,6,1)
Block(0,9,7,1)
Block(0,9,8,1)
Block(0,10,-7,1)
Block(0,10,-6,1)
Block(0,10,-5,1)
Block(0,10,-4,1)
Block(0,10,-3,1)
Block(0,10,-2,1)
Block(0,10,-1,1)
Block(0,10,0,1)
Block(0,10,1,1)
Block(0,10,2,1)
Block(0,10,3,1)
Block(0,10,4,1)
Block(0,10,5,1)
Block(0,10,6,1)
Block(0,10,7,1)
Block(0,10,8,1)
Block(0,11,-7,1)
Block(0,11,-6,1)
Block(0,11,-5,1)
Block(0,11,-4,1)
Block(0,11,-3,1)
Block(0,11,-2,1)
Block(0,11,-1,1)
Block(0,11,0,1)
Block(0,11,1,1)
Block(0,11,2,1)
Block(0,11,3,1)
Block(0,11,4,1)
Block(0,11,5,1)
Block(0,11,6,1)
Block(0,11,7,3)
Block(0,11,8,1)
Block(0,12,-7,1)
Block(0,12,-6,1)
Block(0,12,-5,1)
Block(0,12,-4,1)
Block(0,12,-3,1)
Block(0,12,-2,1)
Block(0,12,-1,1)
Block(0,12,0,1)
Block(0,12,1,1)
Block(0,12,2,1)
Block(0,12,3,3)
Block(0,12,4,3)
Block(0,12,5,3)
Block(0,12,6,3)
Block(0,12,7,3)
Block(0,12,8,3)
Block(0,13,-7,16)
Block(0,13,-6,3)
Block(0,13,-5,3)
Block(0,13,-4,3)
Block(0,13,-3,3)
Block(0,13,-2,3)
Block(0,13,-1,3)
Block(0,13,0,3)
Block(0,13,1,3)
Block(0,13,2,3)
Block(0,13,3,3)
Block(0,13,4,3)
Block(0,13,5,3)
Block(0,13,6,3)
Block(0,13,7,3)
Block(0,13,8,3)
Block(0,14,-7,3)
Block(0,14,-6,3)
Block(0,14,-5,3)
Block(0,14,-4,3)
Block(0,14,-3,3)
Block(0,14,-2,3)
Block(0,14,-1,3)
Block(0,14,0,3)
Block(0,14,1,3)
Block(0,14,2,3)
Block(0,14,3,3)
Block(0,14,4,3)
Block(0,14,5,3)
Block(0,14,6,3)
Block(0,14,7,3)
Block(0,14,8,3)
Block(0,15,-7,3)
Block(0,15,-6,3)
Block(0,15,-5,3)
Block(0,15,-4,3)
Block(0,15,-3,3)
Block(0,15,-2,3)
Block(0,15,-1,3)
Block(0,15,0,3)
Block(0,15,1,3)
Block(0,15,2,3)
Block(0,15,3,3)
Block(0,15,4,3)
Block(0,15,5,3)
Block(0,15,6,3)
Block(0,15,7,3)
Block(0,15,8,3)
Block(0,16,-7,5)
Block(0,16,-6,5)
Block(0,16,-5,5)
Block(0,16,-4,5)
Block(0,16,-3,5)
Block(0,16,-2,5)
Block(0,16,-1,5)
Block(0,16,0,5)
Block(0,16,1,5)
Block(0,16,2,5)
Block(0,16,3,5)
Block(0,16,4,5)
Block(0,16,5,5)
Block(0,16,6,5)
Block(0,16,7,5)
Block(0,16,8,5)
Block(0,17,8,5:2)
Block(0,30,1,35:14)
Block(0,35,-4,35:14)
Block(0,36,-4,35:14)
Block(1,0,-7,1)
Block(1,0,-6,1)
Block(1,0,-5,1)
Block(1,0,-4,1)
Block(1,0,-3,1)
Block(1,0,-2,1)
Block(1,0,-1,1)
Block(1,0,0,1)
Block(1,0,1,1)
Block(1,0,2,1)
Block(1,0,3,1)
Block(1,0,4,1)
Block(1,0,5,1)
Block(1,0,6,1)
Block(1,0,7,1)
Block(1,0,8,1)
Block(1,1,-7,1)
Block(1,1,-6,1)
Block(1,1,-5,3)
Block(1,1,-4,3)
Block(1,1,-3,3)
Block(1,1,-2,3)
Block(1,1,-1,1)
Block(1,1,0,1)
Block(1,1,1,1)
Block(1,1,2,1)
Block(1,1,3,1)
Block(1,1,4,1)
Block(1,1,5,1)
Block(1,1,6,1)
Block(1,1,7,1)
Block(1,1,8,1)
Block(1,2,-7,1)
Block(1,2,-6,1)
Block(1,2,-5,3)
Block(1,2,-4,3)
Block(1,2,-3,3)
Block(1,2,-2,3)
Block(1,2,-1,1)
Block(1,2,0,1)
Block(1,2,1,1)
Block(1,2,2,1)
Block(1,2,3,1)
Block(1,2,4,1)
Block(1,2,5,1)
Block(1,2,6,1)
Block(1,2,7,1)
Block(1,2,8,1)
Block(1,3,-7,1)
Block(1,3,-6,1)
Block(1,3,-5,3)
Block(1,3,-4,3)
Block(1,3,-3,3)
Block(1,3,-2,3)
Block(1,3,-1,1)
Block(1,3,0,1)
Block(1,3,1,1)
Block(1,3,2,1)
Block(1,3,3,1)
Block(1,3,4,1)
Block(1,3,5,1)
Block(1,3,6,1)
Block(1,3,7,1)
Block(1,3,8,1)
Block(1,4,-7,1)
Block(1,4,-6,1)
Block(1,4,-5,3)
Block(1,4,-4,3)
Block(1,4,-3,3)
Block(1,4,-2,3)
Block(1,4,-1,1)
Block(1,4,0,1)
Block(1,4,1,1)
Block(1,4,2,1)
Block(1,4,3,1)
Block(1,4,4,1)
Block(1,4,5,1)
Block(1,4,6,1)
Block(1,4,7,1)
Block(1,4,8,1)
Block(1,5,-7,1)
Block(1,5,-6,1)
Block(1,5,-5,1)
Block(1,5,-4,1)
Block(1,5,-3,1)
Block(1,5,-2,1)
Block(1,5,-1,1)
Block(1,5,0,1)
Block(1,5,1,1)
Block(1,5,2,1)
Block(1,5,3,1)
Block(1,5,4,1)
Block(1,5,5,1)
Block(1,5,6,1)
Block(1,5,7,1)
Block(1,5,8,1)
Block(1,6,-7,1)
Block(1,6,-6,1)
Block(1,6,-5,1)
Block(1,6,-4,1)
Block(1,6,-3,1)
Block(1,6,-2,1)
Block(1,6,-1,1)
Block(1,6,0,1)
Block(1,6,1,1)
Block(1,6,2,1)
Block(1,6,3,1)
Block(1,6,4,1)
Block(1,6,5,1)
Block(1,6,6,1)
Block(1,6,7,1)
Block(1,6,8,1)
Block(1,7,-7,1)
Block(1,7,-6,1)
Block(1,7,-5,1)
Block(1,7,-4,1)
Block(1,7,-3,1)
Block(1,7,-2,1)
Block(1,7,-1,1)
Block(1,7,0,1)
Block(1,7,1,1)
Block(1,7,2,1)
Block(1,7,3,1)
Block(1,7,4,1)
Block(1,7,5,1)
Block(1,7,6,1)
Block(1,7,7,1)
Block(1,7,8,1)
Block(1,8,-7,1)
Block(1,8,-6,1)
Block(1,8,-5,1)
Block(1,8,-4,1)
Block(1,8,-3,1)
Block(1,8,-2,1)
Block(1,8,-1,1)
Block(1,8,0,1)
Block(1,8,1,1)
Block(1,8,2,1)
Block(1,8,3,1)
Block(1,8,4,1)
Block(1,8,5,1)
Block(1,8,6,1)
Block(1,8,7,1)
Block(1,8,8,1)
Block(1,9,-7,1)
Block(1,9,-6,1)
Block(1,9,-5,1)
Block(1,9,-4,1)
Block(1,9,-3,1)
Block(1,9,-2,1)
Block(1,9,-1,1)
Block(1,9,0,1)
Block(1,9,1,1)
Block(1,9,2,1)
Block(1,9,3,1)
Block(1,9,4,1)
Block(1,9,5,1)
Block(1,9,6,1)
Block(1,9,7,1)
Block(1,9,8,1)
Block(1,10,-7,1)
Block(1,10,-6,1)
Block(1,10,-5,1)
Block(1,10,-4,1)
Block(1,10,-3,1)
Block(1,10,-2,1)
Block(1,10,-1,1)
Block(1,10,0,1)
Block(1,10,1,1)
Block(1,10,2,1)
Block(1,10,3,1)
Block(1,10,4,1)
Block(1,10,5,1)
Block(1,10,6,1)
Block(1,10,7,1)
Block(1,10,8,1)
Block(1,11,-7,1)
Block(1,11,-6,1)
Block(1,11,-5,1)
Block(1,11,-4,1)
Block(1,11,-3,1)
Block(1,11,-2,1)
Block(1,11,-1,1)
Block(1,11,0,1)
Block(1,11,1,1)
Block(1,11,2,1)
Block(1,11,3,1)
Block(1,11,4,1)
Block(1,11,5,1)
Block(1,11,6,1)
Block(1,11,7,3)
Block(1,11,8,1)
Block(1,12,-7,1)
Block(1,12,-6,1)
Block(1,12,-5,1)
Block(1,12,-4,1)
Block(1,12,-3,1)
Block(1,12,-2,1)
Block(1,12,-1,1)
Block(1,12,0,1)
Block(1,12,1,1)
Block(1,12,2,1)
Block(1,12,3,13)
Block(1,12,4,13)
Block(1,12,5,3)
Block(1,12,6,3)
Block(1,12,7,3)
Block(1,12,8,3)
Block(1,13,-7,3)
Block(1,13,-6,3)
Block(1,13,-5,3)
Block(1,13,-4,3)
Block(1,13,-3,3)
Block(1,13,-2,3)
Block(1,13,-1,3)
Block(1,13,0,3)
Block(1,13,1,3)
Block(1,13,2,3)
Block(1,13,3,3)
Block(1,13,4,3)
Block(1,13,5,3)
Block(1,13,6,3)
Block(1,13,7,3)
Block(1,13,8,3)
Block(1,14,-7,3)
Block(1,14,-6,3)
Block(1,14,-5,3)
Block(1,14,-4,3)
Block(1,14,-3,3)
Block(1,14,-2,3)
Block(1,14,-1,3)
Block(1,14,0,3)
Block(1,14,1,3)
Block(1,14,2,3)
Block(1,14,3,3)
Block(1,14,4,3)
Block(1,14,5,3)
Block(1,14,6,3)
Block(1,14,7,3)
Block(1,14,8,3)
Block(1,15,-7,3)
Block(1,15,-6,3)
Block(1,15,-5,3)
Block(1,15,-4,3)
Block(1,15,-3,3)
Block(1,15,-2,3)
Block(1,15,-1,3)
Block(1,15,0,3)
Block(1,15,1,3)
Block(1,15,2,3)
Block(1,15,3,3)
Block(1,15,4,3)
Block(1,15,5,3)
Block(1,15,6,3)
Block(1,15,7,3)
Block(1,15,8,3)
Block(1,16,-7,5)
Block(1,16,-6,5)
Block(1,16,-5,5)
Block(1,16,-4,5)
Block(1,16,-3,5)
Block(1,16,-2,5)
Block(1,16,-1,5)
Block(1,16,0,5)
Block(1,16,1,5)
Block(1,16,2,5)
Block(1,16,3,5)
Block(1,16,4,5)
Block(1,16,5,5)
Block(1,16,6,5)
Block(1,16,7,5)
Block(1,16,8,5)
Block(1,17,7,5:2)
Block(1,17,8,5:2)
Block(1,18,8,5:2)
Block(1,30,2,35:14)
Block(1,33,-2,108:4)
Block(1,34,-2,85)
Block(1,35,-3,35:14)
Block(1,35,-2,85)
Block(1,36,-3,35:14)
Block(1,36,-2,85)
Block(2,0,-7,1)
Block(2,0,-6,1)
Block(2,0,-5,1)
Block(2,0,-4,1)
Block(2,0,-3,1)
Block(2,0,-2,1)
Block(2,0,-1,1)
Block(2,0,0,1)
Block(2,0,1,1)
Block(2,0,2,1)
Block(2,0,3,1)
Block(2,0,4,1)
Block(2,0,5,1)
Block(2,0,6,1)
Block(2,0,7,1)
Block(2,0,8,1)
Block(2,1,-7,1)
Block(2,1,-6,1)
Block(2,1,-5,1)
Block(2,1,-4,3)
Block(2,1,-3,3)
Block(2,1,-2,3)
Block(2,1,-1,1)
Block(2,1,0,1)
Block(2,1,1,1)
Block(2,1,2,1)
Block(2,1,3,1)
Block(2,1,4,1)
Block(2,1,5,1)
Block(2,1,6,1)
Block(2,1,7,1)
Block(2,1,8,1)
Block(2,2,-7,1)
Block(2,2,-6,1)
Block(2,2,-5,1)
Block(2,2,-4,3)
Block(2,2,-3,3)
Block(2,2,-2,3)
Block(2,2,-1,3)
Block(2,2,0,1)
Block(2,2,1,1)
Block(2,2,2,1)
Block(2,2,3,1)
Block(2,2,4,1)
Block(2,2,5,1)
Block(2,2,6,1)
Block(2,2,7,1)
Block(2,2,8,1)
Block(2,3,-7,1)
Block(2,3,-6,1)
Block(2,3,-5,1)
Block(2,3,-4,3)
Block(2,3,-3,3)
Block(2,3,-2,3)
Block(2,3,-1,3)
Block(2,3,0,1)
Block(2,3,1,1)
Block(2,3,2,1)
Block(2,3,3,1)
Block(2,3,4,1)
Block(2,3,5,1)
Block(2,3,6,1)
Block(2,3,7,1)
Block(2,3,8,1)
Block(2,4,-7,1)
Block(2,4,-6,1)
Block(2,4,-5,1)
Block(2,4,-4,3)
Block(2,4,-3,3)
Block(2,4,-2,3)
Block(2,4,-1,1)
Block(2,4,0,1)
Block(2,4,1,1)
Block(2,4,2,1)
Block(2,4,3,1)
Block(2,4,4,1)
Block(2,4,5,1)
Block(2,4,6,1)
Block(2,4,7,1)
Block(2,4,8,1)
Block(2,5,-7,1)
Block(2,5,-6,1)
Block(2,5,-5,1)
Block(2,5,-4,1)
Block(2,5,-3,1)
Block(2,5,-2,1)
Block(2,5,-1,1)
Block(2,5,0,1)
Block(2,5,1,1)
Block(2,5,2,1)
Block(2,5,3,1)
Block(2,5,4,1)
Block(2,5,5,1)
Block(2,5,6,1)
Block(2,5,7,1)
Block(2,5,8,1)
Block(2,6,-7,1)
Block(2,6,-6,1)
Block(2,6,-5,1)
Block(2,6,-4,1)
Block(2,6,-3,1)
Block(2,6,-2,1)
Block(2,6,-1,1)
Block(2,6,0,1)
Block(2,6,1,1)
Block(2,6,2,1)
Block(2,6,3,1)
Block(2,6,4,1)
Block(2,6,5,1)
Block(2,6,6,1)
Block(2,6,7,1)
Block(2,6,8,1)
Block(2,7,-7,1)
Block(2,7,-6,1)
Block(2,7,-5,1)
Block(2,7,-4,1)
Block(2,7,-3,1)
Block(2,7,-2,1)
Block(2,7,-1,1)
Block(2,7,0,1)
Block(2,7,1,1)
Block(2,7,2,1)
Block(2,7,3,1)
Block(2,7,4,1)
Block(2,7,5,1)
Block(2,7,6,1)
Block(2,7,7,1)
Block(2,7,8,1)
Block(2,8,-7,1)
Block(2,8,-6,1)
Block(2,8,-5,1)
Block(2,8,-4,1)
Block(2,8,-3,1)
Block(2,8,-2,1)
Block(2,8,-1,1)
Block(2,8,0,1)
Block(2,8,1,1)
Block(2,8,2,1)
Block(2,8,3,1)
Block(2,8,4,1)
Block(2,8,5,1)
Block(2,8,6,1)
Block(2,8,7,1)
Block(2,8,8,1)
Block(2,9,-7,1)
Block(2,9,-6,1)
Block(2,9,-5,1)
Block(2,9,-4,1)
Block(2,9,-3,1)
Block(2,9,-2,1)
Block(2,9,-1,1)
Block(2,9,0,1)
Block(2,9,1,1)
Block(2,9,2,1)
Block(2,9,3,1)
Block(2,9,4,1)
Block(2,9,5,1)
Block(2,9,6,1)
Block(2,9,7,1)
Block(2,9,8,1)
Block(2,10,-7,1)
Block(2,10,-6,1)
Block(2,10,-5,1)
Block(2,10,-4,1)
Block(2,10,-3,1)
Block(2,10,-2,1)
Block(2,10,-1,1)
Block(2,10,0,1)
Block(2,10,1,1)
Block(2,10,2,1)
Block(2,10,3,1)
Block(2,10,4,1)
Block(2,10,5,1)
Block(2,10,6,1)
Block(2,10,7,1)
Block(2,10,8,1)
Block(2,11,-7,1)
Block(2,11,-6,1)
Block(2,11,-5,1)
Block(2,11,-4,1)
Block(2,11,-3,1)
Block(2,11,-2,1)
Block(2,11,-1,1)
Block(2,11,0,1)
Block(2,11,1,1)
Block(2,11,2,1)
Block(2,11,3,1)
Block(2,11,4,1)
Block(2,11,5,1)
Block(2,11,6,1)
Block(2,11,7,1)
Block(2,11,8,3)
Block(2,12,-7,1)
Block(2,12,-6,1)
Block(2,12,-5,1)
Block(2,12,-4,1)
Block(2,12,-3,1)
Block(2,12,-2,1)
Block(2,12,-1,1)
Block(2,12,0,1)
Block(2,12,1,13)
Block(2,12,2,13)
Block(2,12,3,13)
Block(2,12,4,13)
Block(2,12,5,1)
Block(2,12,6,3)
Block(2,12,7,3)
Block(2,12,8,3)
Block(2,13,-7,3)
Block(2,13,-6,3)
Block(2,13,-5,3)
Block(2,13,-4,3)
Block(2,13,-3,3)
Block(2,13,-2,3)
Block(2,13,-1,1)
Block(2,13,0,1)
Block(2,13,1,3)
Block(2,13,2,3)
Block(2,13,3,3)
Block(2,13,4,3)
Block(2,13,5,3)
Block(2,13,6,3)
Block(2,13,7,3)
Block(2,13,8,3)
Block(2,14,-7,3)
Block(2,14,-6,3)
Block(2,14,-5,3)
Block(2,14,-4,3)
Block(2,14,-3,3)
Block(2,14,-2,3)
Block(2,14,-1,3)
Block(2,14,0,3)
Block(2,14,1,3)
Block(2,14,2,3)
Block(2,14,3,3)
Block(2,14,4,3)
Block(2,14,5,3)
Block(2,14,6,3)
Block(2,14,7,3)
Block(2,14,8,3)
Block(2,15,-7,3)
Block(2,15,-6,3)
Block(2,15,-5,3)
Block(2,15,-4,3)
Block(2,15,-3,3)
Block(2,15,-2,3)
Block(2,15,-1,3)
Block(2,15,0,3)
Block(2,15,1,3)
Block(2,15,2,3)
Block(2,15,3,3)
Block(2,15,4,3)
Block(2,15,5,3)
Block(2,15,6,3)
Block(2,15,7,3)
Block(2,15,8,3)
Block(2,16,-7,5)
Block(2,16,-6,5)
Block(2,16,-5,5)
Block(2,16,-4,5)
Block(2,16,-3,5)
Block(2,16,-2,5)
Block(2,16,-1,5)
Block(2,16,0,5)
Block(2,16,1,5)
Block(2,16,2,5)
Block(2,16,3,5)
Block(2,16,4,5)
Block(2,16,5,5)
Block(2,16,6,5)
Block(2,16,7,5)
Block(2,16,8,5)
Block(2,17,-4,96:6)
Block(2,17,0,96:6)
Block(2,18,-4,96:6)
Block(2,18,0,96:6)
Block(2,19,-3,96:6)
Block(2,19,-1,96:6)
Block(2,20,-2,96:6)
Block(2,21,-7,85)
Block(2,21,-6,85)
Block(2,21,-5,85)
Block(2,21,-4,85)
Block(2,21,-2,85)
Block(2,21,0,85)
Block(2,21,1,85)
Block(2,21,2,85)
Block(2,21,3,85)
Block(2,22,-4,85)
Block(2,22,-3,85)
Block(2,22,-2,85)
Block(2,22,-1,85)
Block(2,22,0,85)
Block(2,23,-4,85)
Block(2,23,-2,85)
Block(2,23,0,85)
Block(2,24,-4,85)
Block(2,24,-2,85)
Block(2,24,0,85)
Block(2,25,-7,108:2)
Block(2,25,-6,108:7)
Block(2,25,-4,50:5)
Block(2,25,-2,85)
Block(2,25,0,50:5)
Block(2,25,2,108:6)
Block(2,25,3,108:3)
Block(2,26,-6,108:2)
Block(2,26,-5,108:7)
Block(2,26,-2,50:5)
Block(2,26,1,108:6)
Block(2,26,2,108:3)
Block(2,27,-5,108:2)
Block(2,27,-4,108:7)
Block(2,27,0,108:6)
Block(2,27,1,108:3)
Block(2,28,-4,45)
Block(2,28,0,45)
Block(2,29,-4,108:2)
Block(2,29,-3,108:7)
Block(2,29,-1,108:6)
Block(2,29,0,108:3)
Block(2,30,-3,45)
Block(2,30,-1,45)
Block(2,30,3,35:14)
Block(2,31,-3,108:2)
Block(2,31,-2,44:12)
Block(2,31,-1,108:3)
Block(2,31,3,35:14)
Block(2,32,-2,45)
Block(2,33,-2,108:1)
Block(3,0,-7,1)
Block(3,0,-6,1)
Block(3,0,-5,1)
Block(3,0,-4,1)
Block(3,0,-3,1)
Block(3,0,-2,1)
Block(3,0,-1,1)
Block(3,0,0,1)
Block(3,0,1,1)
Block(3,0,2,1)
Block(3,0,3,1)
Block(3,0,4,1)
Block(3,0,5,1)
Block(3,0,6,1)
Block(3,0,7,1)
Block(3,0,8,1)
Block(3,1,-7,1)
Block(3,1,-6,1)
Block(3,1,-5,1)
Block(3,1,-4,16)
Block(3,1,-3,16)
Block(3,1,-2,1)
Block(3,1,-1,1)
Block(3,1,0,1)
Block(3,1,1,1)
Block(3,1,2,1)
Block(3,1,3,1)
Block(3,1,4,1)
Block(3,1,5,1)
Block(3,1,6,1)
Block(3,1,7,1)
Block(3,1,8,1)
Block(3,2,-7,1)
Block(3,2,-6,1)
Block(3,2,-5,1)
Block(3,2,-4,3)
Block(3,2,-3,3)
Block(3,2,-2,3)
Block(3,2,-1,1)
Block(3,2,0,1)
Block(3,2,1,1)
Block(3,2,2,1)
Block(3,2,3,1)
Block(3,2,4,1)
Block(3,2,5,1)
Block(3,2,6,1)
Block(3,2,7,1)
Block(3,2,8,1)
Block(3,3,-7,1)
Block(3,3,-6,1)
Block(3,3,-5,1)
Block(3,3,-4,3)
Block(3,3,-3,3)
Block(3,3,-2,3)
Block(3,3,-1,1)
Block(3,3,0,1)
Block(3,3,1,1)
Block(3,3,2,1)
Block(3,3,3,1)
Block(3,3,4,1)
Block(3,3,5,1)
Block(3,3,6,1)
Block(3,3,7,1)
Block(3,3,8,1)
Block(3,4,-7,1)
Block(3,4,-6,1)
Block(3,4,-5,1)
Block(3,4,-4,1)
Block(3,4,-3,1)
Block(3,4,-2,1)
Block(3,4,-1,1)
Block(3,4,0,1)
Block(3,4,1,1)
Block(3,4,2,1)
Block(3,4,3,1)
Block(3,4,4,1)
Block(3,4,5,1)
Block(3,4,6,1)
Block(3,4,7,1)
Block(3,4,8,1)
Block(3,5,-7,1)
Block(3,5,-6,1)
Block(3,5,-5,1)
Block(3,5,-4,1)
Block(3,5,-3,1)
Block(3,5,-2,1)
Block(3,5,-1,1)
Block(3,5,0,1)
Block(3,5,1,1)
Block(3,5,2,1)
Block(3,5,3,1)
Block(3,5,4,1)
Block(3,5,5,1)
Block(3,5,6,1)
Block(3,5,7,1)
Block(3,5,8,1)
Block(3,6,-7,1)
Block(3,6,-6,1)
Block(3,6,-5,1)
Block(3,6,-4,1)
Block(3,6,-3,1)
Block(3,6,-2,1)
Block(3,6,-1,1)
Block(3,6,0,1)
Block(3,6,1,1)
Block(3,6,2,1)
Block(3,6,3,1)
Block(3,6,4,1)
Block(3,6,5,1)
Block(3,6,6,1)
Block(3,6,7,1)
Block(3,6,8,1)
Block(3,7,-7,1)
Block(3,7,-6,1)
Block(3,7,-5,1)
Block(3,7,-4,1)
Block(3,7,-3,1)
Block(3,7,-2,1)
Block(3,7,-1,1)
Block(3,7,0,1)
Block(3,7,1,1)
Block(3,7,2,1)
Block(3,7,3,1)
Block(3,7,4,1)
Block(3,7,5,1)
Block(3,7,6,1)
Block(3,7,7,1)
Block(3,7,8,1)
Block(3,8,-7,1)
Block(3,8,-6,1)
Block(3,8,-5,1)
Block(3,8,-4,1)
Block(3,8,-3,1)
Block(3,8,-2,1)
Block(3,8,-1,1)
Block(3,8,0,1)
Block(3,8,1,1)
Block(3,8,2,1)
Block(3,8,3,1)
Block(3,8,4,1)
Block(3,8,5,1)
Block(3,8,6,1)
Block(3,8,7,1)
Block(3,8,8,1)
Block(3,9,-7,1)
Block(3,9,-6,1)
Block(3,9,-5,1)
Block(3,9,-4,1)
Block(3,9,-3,1)
Block(3,9,-2,1)
Block(3,9,-1,1)
Block(3,9,0,1)
Block(3,9,1,1)
Block(3,9,2,1)
Block(3,9,3,1)
Block(3,9,4,1)
Block(3,9,5,1)
Block(3,9,6,1)
Block(3,9,7,1)
Block(3,9,8,1)
Block(3,10,-7,1)
Block(3,10,-6,1)
Block(3,10,-5,1)
Block(3,10,-4,1)
Block(3,10,-3,1)
Block(3,10,-2,1)
Block(3,10,-1,1)
Block(3,10,0,1)
Block(3,10,1,1)
Block(3,10,2,1)
Block(3,10,3,1)
Block(3,10,4,1)
Block(3,10,5,1)
Block(3,10,6,1)
Block(3,10,7,1)
Block(3,10,8,1)
Block(3,11,-7,1)
Block(3,11,-6,1)
Block(3,11,-5,1)
Block(3,11,-4,1)
Block(3,11,-3,1)
Block(3,11,-2,1)
Block(3,11,-1,1)
Block(3,11,0,1)
Block(3,11,1,1)
Block(3,11,2,13)
Block(3,11,3,13)
Block(3,11,4,1)
Block(3,11,5,1)
Block(3,11,6,1)
Block(3,11,7,1)
Block(3,11,8,1)
Block(3,12,-7,1)
Block(3,12,-6,1)
Block(3,12,-5,1)
Block(3,12,-4,1)
Block(3,12,-3,1)
Block(3,12,-2,1)
Block(3,12,-1,1)
Block(3,12,0,1)
Block(3,12,1,1)
Block(3,12,2,13)
Block(3,12,3,13)
Block(3,12,4,13)
Block(3,12,5,1)
Block(3,12,6,3)
Block(3,12,7,3)
Block(3,12,8,3)
Block(3,13,-7,3)
Block(3,13,-6,3)
Block(3,13,-5,3)
Block(3,13,-4,3)
Block(3,13,-3,3)
Block(3,13,-2,3)
Block(3,13,-1,1)
Block(3,13,0,1)
Block(3,13,1,13)
Block(3,13,2,3)
Block(3,13,3,3)
Block(3,13,4,3)
Block(3,13,5,3)
Block(3,13,6,3)
Block(3,13,7,3)
Block(3,13,8,3)
Block(3,14,-7,3)
Block(3,14,-6,3)
Block(3,14,-5,3)
Block(3,14,-4,3)
Block(3,14,-3,3)
Block(3,14,-2,3)
Block(3,14,-1,3)
Block(3,14,0,3)
Block(3,14,1,3)
Block(3,14,2,3)
Block(3,14,3,3)
Block(3,14,4,3)
Block(3,14,5,3)
Block(3,14,6,3)
Block(3,14,7,3)
Block(3,14,8,3)
Block(3,15,-7,3)
Block(3,15,-6,3)
Block(3,15,-5,3)
Block(3,15,-4,3)
Block(3,15,-3,3)
Block(3,15,-2,3)
Block(3,15,-1,3)
Block(3,15,0,3)
Block(3,15,1,3)
Block(3,15,2,3)
Block(3,15,3,3)
Block(3,15,4,3)
Block(3,15,5,3)
Block(3,15,6,3)
Block(3,15,7,3)
Block(3,15,8,3)
Block(3,16,-7,5)
Block(3,16,-6,17)
Block(3,16,-5,5)
Block(3,16,-4,5)
Block(3,16,-3,5)
Block(3,16,-2,5)
Block(3,16,-1,5)
Block(3,16,0,5)
Block(3,16,1,5)
Block(3,16,2,17)
Block(3,16,3,5)
Block(3,16,4,5)
Block(3,16,5,5)
Block(3,16,6,5)
Block(3,16,7,5)
Block(3,16,8,5)
Block(3,17,-7,54:2,1-Chest.nbt)
Block(3,17,-6,17)
Block(3,17,-5,35)
Block(3,17,-4,5:2)
Block(3,17,-3,96:5)
Block(3,17,-1,96:4)
Block(3,17,0,5:2)
Block(3,17,1,35)
Block(3,17,2,17)
Block(3,17,8,86:2)
Block(3,18,-6,17)
Block(3,18,-5,35)
Block(3,18,-4,5:2)
Block(3,18,-3,96:5)
Block(3,18,-1,96:4)
Block(3,18,0,5:2)
Block(3,18,1,35)
Block(3,18,2,17)
Block(3,19,-6,17)
Block(3,19,-5,35)
Block(3,19,-4,35)
Block(3,19,-3,5:2)
Block(3,19,-1,5:2)
Block(3,19,0,35)
Block(3,19,1,35)
Block(3,19,2,17)
Block(3,20,-6,17)
Block(3,20,-5,35)
Block(3,20,-4,102)
Block(3,20,-3,35)
Block(3,20,-2,5:2)
Block(3,20,-1,35)
Block(3,20,0,102)
Block(3,20,1,35)
Block(3,20,2,17)
Block(3,21,-7,85)
Block(3,21,-6,17)
Block(3,21,-5,35)
Block(3,21,-4,35)
Block(3,21,-3,35)
Block(3,21,-2,35)
Block(3,21,-1,35)
Block(3,21,0,35)
Block(3,21,1,35)
Block(3,21,2,17)
Block(3,21,3,85)
Block(3,22,-6,17)
Block(3,22,-5,35)
Block(3,22,-4,35)
Block(3,22,-3,35)
Block(3,22,-2,35)
Block(3,22,-1,35)
Block(3,22,0,35)
Block(3,22,1,35)
Block(3,22,2,17)
Block(3,23,-6,17)
Block(3,23,-5,102)
Block(3,23,-4,35)
Block(3,23,-3,102)
Block(3,23,-2,35)
Block(3,23,-1,102)
Block(3,23,0,35)
Block(3,23,1,102)
Block(3,23,2,17)
Block(3,24,-6,17)
Block(3,24,-5,102)
Block(3,24,-4,35)
Block(3,24,-3,102)
Block(3,24,-2,35)
Block(3,24,-1,102)
Block(3,24,0,35)
Block(3,24,1,102)
Block(3,24,2,17)
Block(3,25,-7,108:2)
Block(3,25,-6,17)
Block(3,25,-5,35)
Block(3,25,-4,35)
Block(3,25,-3,35)
Block(3,25,-2,35)
Block(3,25,-1,35)
Block(3,25,0,35)
Block(3,25,1,35)
Block(3,25,2,17)
Block(3,25,3,108:3)
Block(3,26,-6,108:2)
Block(3,26,-5,17)
Block(3,26,-4,35)
Block(3,26,-3,102)
Block(3,26,-2,35)
Block(3,26,-1,102)
Block(3,26,0,35)
Block(3,26,1,17)
Block(3,26,2,108:3)
Block(3,27,-5,108:2)
Block(3,27,-4,17)
Block(3,27,-3,35)
Block(3,27,-2,35)
Block(3,27,-1,35)
Block(3,27,0,17)
Block(3,27,1,108:3)
Block(3,28,-4,45)
Block(3,28,-3,17)
Block(3,28,-2,35)
Block(3,28,-1,17)
Block(3,28,0,45)
Block(3,28,5,108:4)
Block(3,29,-4,108:2)
Block(3,29,-3,17)
Block(3,29,-2,35)
Block(3,29,-1,17)
Block(3,29,0,108:3)
Block(3,29,5,85)
Block(3,30,-3,45)
Block(3,30,-2,17)
Block(3,30,-1,45)
Block(3,30,4,35:14)
Block(3,30,5,85)
Block(3,31,-3,108:2)
Block(3,31,-2,17)
Block(3,31,-1,108:3)
Block(3,31,4,35:14)
Block(3,31,5,85)
Block(3,32,-2,45)
Block(3,33,-2,44:4)
Block(4,0,-7,1)
Block(4,0,-6,1)
Block(4,0,-5,1)
Block(4,0,-4,1)
Block(4,0,-3,1)
Block(4,0,-2,1)
Block(4,0,-1,1)
Block(4,0,0,1)
Block(4,0,1,1)
Block(4,0,2,1)
Block(4,0,3,1)
Block(4,0,4,1)
Block(4,0,5,1)
Block(4,0,6,1)
Block(4,0,7,1)
Block(4,0,8,1)
Block(4,1,-7,1)
Block(4,1,-6,1)
Block(4,1,-5,1)
Block(4,1,-4,16)
Block(4,1,-3,16)
Block(4,1,-2,1)
Block(4,1,-1,1)
Block(4,1,0,1)
Block(4,1,1,1)
Block(4,1,2,1)
Block(4,1,3,1)
Block(4,1,4,1)
Block(4,1,5,1)
Block(4,1,6,1)
Block(4,1,7,1)
Block(4,1,8,1)
Block(4,2,-7,1)
Block(4,2,-6,1)
Block(4,2,-5,16)
Block(4,2,-4,16)
Block(4,2,-3,16)
Block(4,2,-2,1)
Block(4,2,-1,1)
Block(4,2,0,1)
Block(4,2,1,1)
Block(4,2,2,1)
Block(4,2,3,1)
Block(4,2,4,1)
Block(4,2,5,1)
Block(4,2,6,1)
Block(4,2,7,1)
Block(4,2,8,1)
Block(4,3,-7,1)
Block(4,3,-6,1)
Block(4,3,-5,1)
Block(4,3,-4,16)
Block(4,3,-3,16)
Block(4,3,-2,1)
Block(4,3,-1,1)
Block(4,3,0,1)
Block(4,3,1,1)
Block(4,3,2,1)
Block(4,3,3,1)
Block(4,3,4,1)
Block(4,3,5,1)
Block(4,3,6,1)
Block(4,3,7,1)
Block(4,3,8,1)
Block(4,4,-7,1)
Block(4,4,-6,1)
Block(4,4,-5,1)
Block(4,4,-4,1)
Block(4,4,-3,1)
Block(4,4,-2,1)
Block(4,4,-1,1)
Block(4,4,0,1)
Block(4,4,1,1)
Block(4,4,2,1)
Block(4,4,3,1)
Block(4,4,4,1)
Block(4,4,5,1)
Block(4,4,6,1)
Block(4,4,7,1)
Block(4,4,8,1)
Block(4,5,-7,1)
Block(4,5,-6,1)
Block(4,5,-5,1)
Block(4,5,-4,1)
Block(4,5,-3,1)
Block(4,5,-2,1)
Block(4,5,-1,1)
Block(4,5,0,1)
Block(4,5,1,1)
Block(4,5,2,1)
Block(4,5,3,1)
Block(4,5,4,1)
Block(4,5,5,1)
Block(4,5,6,1)
Block(4,5,7,1)
Block(4,5,8,1)
Block(4,6,-7,1)
Block(4,6,-6,1)
Block(4,6,-5,1)
Block(4,6,-4,1)
Block(4,6,-3,1)
Block(4,6,-2,1)
Block(4,6,-1,1)
Block(4,6,0,1)
Block(4,6,1,1)
Block(4,6,2,1)
Block(4,6,3,1)
Block(4,6,4,1)
Block(4,6,5,1)
Block(4,6,6,1)
Block(4,6,7,1)
Block(4,6,8,1)
Block(4,7,-7,1)
Block(4,7,-6,1)
Block(4,7,-5,1)
Block(4,7,-4,1)
Block(4,7,-3,1)
Block(4,7,-2,1)
Block(4,7,-1,1)
Block(4,7,0,1)
Block(4,7,1,1)
Block(4,7,2,1)
Block(4,7,3,1)
Block(4,7,4,1)
Block(4,7,5,1)
Block(4,7,6,1)
Block(4,7,7,1)
Block(4,7,8,1)
Block(4,8,-7,1)
Block(4,8,-6,1)
Block(4,8,-5,1)
Block(4,8,-4,1)
Block(4,8,-3,1)
Block(4,8,-2,1)
Block(4,8,-1,1)
Block(4,8,0,1)
Block(4,8,1,1)
Block(4,8,2,1)
Block(4,8,3,1)
Block(4,8,4,1)
Block(4,8,5,1)
Block(4,8,6,1)
Block(4,8,7,1)
Block(4,8,8,1)
Block(4,9,-7,1)
Block(4,9,-6,1)
Block(4,9,-5,1)
Block(4,9,-4,1)
Block(4,9,-3,1)
Block(4,9,-2,1)
Block(4,9,-1,1)
Block(4,9,0,1)
Block(4,9,1,1)
Block(4,9,2,1)
Block(4,9,3,1)
Block(4,9,4,1)
Block(4,9,5,1)
Block(4,9,6,1)
Block(4,9,7,1)
Block(4,9,8,1)
Block(4,10,-7,1)
Block(4,10,-6,1)
Block(4,10,-5,1)
Block(4,10,-4,1)
Block(4,10,-3,1)
Block(4,10,-2,1)
Block(4,10,-1,1)
Block(4,10,0,1)
Block(4,10,1,1)
Block(4,10,2,1)
Block(4,10,3,1)
Block(4,10,4,1)
Block(4,10,5,1)
Block(4,10,6,1)
Block(4,10,7,1)
Block(4,10,8,1)
Block(4,11,-7,1)
Block(4,11,-6,1)
Block(4,11,-5,1)
Block(4,11,-4,1)
Block(4,11,-3,1)
Block(4,11,-2,1)
Block(4,11,-1,1)
Block(4,11,0,1)
Block(4,11,1,13)
Block(4,11,2,13)
Block(4,11,3,13)
Block(4,11,4,1)
Block(4,11,5,1)
Block(4,11,6,1)
Block(4,11,7,1)
Block(4,11,8,3)
Block(4,12,-7,1)
Block(4,12,-6,1)
Block(4,12,-5,1)
Block(4,12,-4,1)
Block(4,12,-3,1)
Block(4,12,-2,1)
Block(4,12,-1,1)
Block(4,12,0,13)
Block(4,12,1,13)
Block(4,12,2,13)
Block(4,12,3,13)
Block(4,12,4,13)
Block(4,12,5,1)
Block(4,12,6,1)
Block(4,12,7,3)
Block(4,12,8,3)
Block(4,13,-7,3)
Block(4,13,-6,3)
Block(4,13,-5,3)
Block(4,13,-4,3)
Block(4,13,-3,3)
Block(4,13,-2,3)
Block(4,13,-1,3)
Block(4,13,0,13)
Block(4,13,1,13)
Block(4,13,2,13)
Block(4,13,3,3)
Block(4,13,4,3)
Block(4,13,5,3)
Block(4,13,6,3)
Block(4,13,7,3)
Block(4,13,8,3)
Block(4,14,-7,3)
Block(4,14,-6,3)
Block(4,14,-5,3)
Block(4,14,-4,3)
Block(4,14,-3,3)
Block(4,14,-2,3)
Block(4,14,-1,3)
Block(4,14,0,3)
Block(4,14,1,13)
Block(4,14,2,3)
Block(4,14,3,3)
Block(4,14,4,3)
Block(4,14,5,3)
Block(4,14,6,3)
Block(4,14,7,3)
Block(4,14,8,3)
Block(4,15,-7,3)
Block(4,15,-6,3)
Block(4,15,-5,3)
Block(4,15,-4,3)
Block(4,15,-3,3)
Block(4,15,-2,3)
Block(4,15,-1,3)
Block(4,15,0,3)
Block(4,15,1,3)
Block(4,15,2,3)
Block(4,15,3,3)
Block(4,15,4,3)
Block(4,15,5,3)
Block(4,15,6,3)
Block(4,15,7,3)
Block(4,15,8,3)
Block(4,16,-7,5)
Block(4,16,-6,5)
Block(4,16,-5,5)
Block(4,16,-4,5)
Block(4,16,-3,5)
Block(4,16,-2,5)
Block(4,16,-1,5)
Block(4,16,0,5)
Block(4,16,1,5)
Block(4,16,2,5)
Block(4,16,3,5)
Block(4,16,4,5)
Block(4,16,5,5)
Block(4,16,6,5)
Block(4,16,7,5)
Block(4,16,8,5)
Block(4,17,-7,54:2,2-Chest.nbt)
Block(4,17,-6,5:2)
Block(4,17,-4,96:7)
Block(4,17,0,96:7)
Block(4,17,2,5:2)
Block(4,18,-6,5:2)
Block(4,18,-4,96:15)
Block(4,18,0,96:7)
Block(4,18,2,5:2)
Block(4,19,-6,5:2)
Block(4,19,-3,96:7)
Block(4,19,-1,96:7)
Block(4,19,2,5:2)
Block(4,20,-6,35)
Block(4,20,-2,96:7)
Block(4,20,2,35)
Block(4,21,-7,85)
Block(4,21,-6,35)
Block(4,21,-5,126:9)
Block(4,21,-4,126:9)
Block(4,21,-3,126:9)
Block(4,21,-2,126:9)
Block(4,21,-1,126:9)
Block(4,21,0,126:9)
Block(4,21,1,126:9)
Block(4,21,2,35)
Block(4,21,3,85)
Block(4,21,4,85)
Block(4,21,5,85)
Block(4,21,6,85)
Block(4,21,7,85)
Block(4,21,8,108:6)
Block(4,22,-7,108:6)
Block(4,22,-6,35)
Block(4,22,2,35)
Block(4,22,3,108:7)
Block(4,22,7,108:6)
Block(4,22,8,108:3)
Block(4,23,-7,45)
Block(4,23,-6,35)
Block(4,23,2,35)
Block(4,23,3,45)
Block(4,23,7,45)
Block(4,24,-7,45)
Block(4,24,-6,35)
Block(4,24,2,35)
Block(4,24,3,45)
Block(4,24,4,108:7)
Block(4,24,6,108:6)
Block(4,24,7,108:3)
Block(4,25,-7,108:2)
Block(4,25,-6,35)
Block(4,25,3,108:3)
Block(4,25,4,45)
Block(4,25,6,45)
Block(4,26,-6,108:2)
Block(4,26,2,108:3)
Block(4,26,4,108:2)
Block(4,26,5,44:12)
Block(4,26,6,108:3)
Block(4,27,-5,108:2)
Block(4,27,1,108:3)
Block(4,27,5,45)
Block(4,28,-4,45)
Block(4,28,0,45)
Block(4,28,5,108:1)
Block(4,29,-4,108:2)
Block(4,29,0,108:3)
Block(4,30,-3,45)
Block(4,30,-2,17)
Block(4,30,-1,45)
Block(4,31,-3,108:2)
Block(4,31,-2,17)
Block(4,31,-1,108:3)
Block(4,32,-2,45)
Block(4,33,-2,44:4)
Block(5,0,-7,1)
Block(5,0,-6,1)
Block(5,0,-5,1)
Block(5,0,-4,1)
Block(5,0,-3,1)
Block(5,0,-2,1)
Block(5,0,-1,1)
Block(5,0,0,1)
Block(5,0,1,1)
Block(5,0,2,1)
Block(5,0,3,1)
Block(5,0,4,1)
Block(5,0,5,1)
Block(5,0,6,1)
Block(5,0,7,1)
Block(5,0,8,1)
Block(5,1,-7,1)
Block(5,1,-6,1)
Block(5,1,-5,1)
Block(5,1,-4,1)
Block(5,1,-3,1)
Block(5,1,-2,1)
Block(5,1,-1,1)
Block(5,1,0,1)
Block(5,1,1,1)
Block(5,1,2,1)
Block(5,1,3,1)
Block(5,1,4,1)
Block(5,1,5,1)
Block(5,1,6,1)
Block(5,1,7,1)
Block(5,1,8,1)
Block(5,2,-7,1)
Block(5,2,-6,1)
Block(5,2,-5,16)
Block(5,2,-4,16)
Block(5,2,-3,16)
Block(5,2,-2,1)
Block(5,2,-1,1)
Block(5,2,0,1)
Block(5,2,1,1)
Block(5,2,2,1)
Block(5,2,3,1)
Block(5,2,4,1)
Block(5,2,5,1)
Block(5,2,6,1)
Block(5,2,7,1)
Block(5,2,8,1)
Block(5,3,-7,1)
Block(5,3,-6,1)
Block(5,3,-5,16)
Block(5,3,-4,16)
Block(5,3,-3,1)
Block(5,3,-2,1)
Block(5,3,-1,1)
Block(5,3,0,1)
Block(5,3,1,1)
Block(5,3,2,1)
Block(5,3,3,1)
Block(5,3,4,1)
Block(5,3,5,1)
Block(5,3,6,1)
Block(5,3,7,1)
Block(5,3,8,1)
Block(5,4,-7,1)
Block(5,4,-6,1)
Block(5,4,-5,1)
Block(5,4,-4,1)
Block(5,4,-3,1)
Block(5,4,-2,1)
Block(5,4,-1,1)
Block(5,4,0,1)
Block(5,4,1,1)
Block(5,4,2,1)
Block(5,4,3,1)
Block(5,4,4,1)
Block(5,4,5,1)
Block(5,4,6,1)
Block(5,4,7,1)
Block(5,4,8,1)
Block(5,5,-7,1)
Block(5,5,-6,1)
Block(5,5,-5,1)
Block(5,5,-4,1)
Block(5,5,-3,1)
Block(5,5,-2,1)
Block(5,5,-1,1)
Block(5,5,0,1)
Block(5,5,1,1)
Block(5,5,2,1)
Block(5,5,3,1)
Block(5,5,4,1)
Block(5,5,5,1)
Block(5,5,6,1)
Block(5,5,7,1)
Block(5,5,8,1)
Block(5,6,-7,1)
Block(5,6,-6,1)
Block(5,6,-5,1)
Block(5,6,-4,1)
Block(5,6,-3,1)
Block(5,6,-2,1)
Block(5,6,-1,1)
Block(5,6,0,1)
Block(5,6,1,1)
Block(5,6,2,1)
Block(5,6,3,1)
Block(5,6,4,1)
Block(5,6,5,1)
Block(5,6,6,1)
Block(5,6,7,1)
Block(5,6,8,1)
Block(5,7,-7,1)
Block(5,7,-6,1)
Block(5,7,-5,1)
Block(5,7,-4,1)
Block(5,7,-3,1)
Block(5,7,-2,1)
Block(5,7,-1,1)
Block(5,7,0,1)
Block(5,7,1,1)
Block(5,7,2,1)
Block(5,7,3,1)
Block(5,7,4,1)
Block(5,7,5,1)
Block(5,7,6,1)
Block(5,7,7,1)
Block(5,7,8,1)
Block(5,8,-7,1)
Block(5,8,-6,1)
Block(5,8,-5,1)
Block(5,8,-4,1)
Block(5,8,-3,1)
Block(5,8,-2,1)
Block(5,8,-1,1)
Block(5,8,0,1)
Block(5,8,1,1)
Block(5,8,2,1)
Block(5,8,3,1)
Block(5,8,4,1)
Block(5,8,5,1)
Block(5,8,6,1)
Block(5,8,7,1)
Block(5,8,8,1)
Block(5,9,-7,1)
Block(5,9,-6,1)
Block(5,9,-5,1)
Block(5,9,-4,1)
Block(5,9,-3,1)
Block(5,9,-2,1)
Block(5,9,-1,1)
Block(5,9,0,1)
Block(5,9,1,1)
Block(5,9,2,1)
Block(5,9,3,1)
Block(5,9,4,1)
Block(5,9,5,1)
Block(5,9,6,1)
Block(5,9,7,1)
Block(5,9,8,1)
Block(5,10,-7,1)
Block(5,10,-6,1)
Block(5,10,-5,1)
Block(5,10,-4,1)
Block(5,10,-3,1)
Block(5,10,-2,1)
Block(5,10,-1,1)
Block(5,10,0,1)
Block(5,10,1,1)
Block(5,10,2,1)
Block(5,10,3,1)
Block(5,10,4,1)
Block(5,10,5,1)
Block(5,10,6,1)
Block(5,10,7,1)
Block(5,10,8,1)
Block(5,11,-7,1)
Block(5,11,-6,1)
Block(5,11,-5,1)
Block(5,11,-4,1)
Block(5,11,-3,1)
Block(5,11,-2,1)
Block(5,11,-1,1)
Block(5,11,0,1)
Block(5,11,1,13)
Block(5,11,2,13)
Block(5,11,3,1)
Block(5,11,4,1)
Block(5,11,5,1)
Block(5,11,6,1)
Block(5,11,7,1)
Block(5,11,8,1)
Block(5,12,-7,1)
Block(5,12,-6,1)
Block(5,12,-5,1)
Block(5,12,-4,1)
Block(5,12,-3,1)
Block(5,12,-2,1)
Block(5,12,-1,1)
Block(5,12,0,13)
Block(5,12,1,13)
Block(5,12,2,13)
Block(5,12,3,13)
Block(5,12,4,13)
Block(5,12,5,1)
Block(5,12,6,1)
Block(5,12,7,3)
Block(5,12,8,3)
Block(5,13,-7,3)
Block(5,13,-6,3)
Block(5,13,-5,3)
Block(5,13,-4,3)
Block(5,13,-3,3)
Block(5,13,-2,3)
Block(5,13,-1,1)
Block(5,13,0,13)
Block(5,13,1,13)
Block(5,13,2,13)
Block(5,13,3,13)
Block(5,13,4,3)
Block(5,13,5,3)
Block(5,13,6,3)
Block(5,13,7,3)
Block(5,13,8,3)
Block(5,14,-7,3)
Block(5,14,-6,3)
Block(5,14,-5,3)
Block(5,14,-4,3)
Block(5,14,-3,3)
Block(5,14,-2,3)
Block(5,14,-1,3)
Block(5,14,0,3)
Block(5,14,1,3)
Block(5,14,2,3)
Block(5,14,3,3)
Block(5,14,4,3)
Block(5,14,5,3)
Block(5,14,6,3)
Block(5,14,7,3)
Block(5,14,8,3)
Block(5,15,-7,3)
Block(5,15,-6,3)
Block(5,15,-5,3)
Block(5,15,-4,3)
Block(5,15,-3,3)
Block(5,15,-2,3)
Block(5,15,-1,3)
Block(5,15,0,3)
Block(5,15,1,3)
Block(5,15,2,3)
Block(5,15,3,3)
Block(5,15,4,3)
Block(5,15,5,3)
Block(5,15,6,3)
Block(5,15,7,3)
Block(5,15,8,3)
Block(5,16,-7,5:2)
Block(5,16,-6,17)
Block(5,16,-5,5)
Block(5,16,-4,5)
Block(5,16,-3,5)
Block(5,16,-2,5)
Block(5,16,-1,5)
Block(5,16,0,5)
Block(5,16,1,5)
Block(5,16,2,17)
Block(5,16,3,5:2)
Block(5,16,4,5)
Block(5,16,5,5:2)
Block(5,16,6,5:2)
Block(5,16,7,5)
Block(5,16,8,5)
Block(5,17,-7,5:2)
Block(5,17,-6,17)
Block(5,17,2,17)
Block(5,17,3,5:2)
Block(5,17,4,64)
Block(5,17,5,5:2)
Block(5,17,6,5:2)
Block(5,17,7,5:2)
Block(5,17,8,17)
Block(5,18,-7,5:2)
Block(5,18,-6,17)
Block(5,18,2,17)
Block(5,18,3,5:2)
Block(5,18,4,64:8)
Block(5,18,5,5:2)
Block(5,18,6,102)
Block(5,18,7,5:2)
Block(5,18,8,17)
Block(5,19,-7,5:2)
Block(5,19,-6,17)
Block(5,19,2,17)
Block(5,19,3,5:2)
Block(5,19,4,5:2)
Block(5,19,5,5:2)
Block(5,19,6,5:2)
Block(5,19,7,5:2)
Block(5,19,8,17)
Block(5,20,-7,35:8)
Block(5,20,-6,17)
Block(5,20,2,17)
Block(5,20,3,35:8)
Block(5,20,4,102)
Block(5,20,5,35:8)
Block(5,20,6,102)
Block(5,20,7,35:8)
Block(5,20,8,17)
Block(5,21,-7,35:8)
Block(5,21,-6,17)
Block(5,21,-5,126:9)
Block(5,21,-4,126:9)
Block(5,21,-3,126:9)
Block(5,21,-2,126:9)
Block(5,21,-1,126:9)
Block(5,21,0,126:9)
Block(5,21,1,126:9)
Block(5,21,2,17)
Block(5,21,3,35:8)
Block(5,21,4,35:8)
Block(5,21,5,35:8)
Block(5,21,6,35:8)
Block(5,21,7,35:8)
Block(5,21,8,17)
Block(5,22,-7,17)
Block(5,22,-6,17)
Block(5,22,2,17)
Block(5,22,3,17)
Block(5,22,4,35:8)
Block(5,22,5,102)
Block(5,22,6,35:8)
Block(5,22,7,17)
Block(5,22,8,108:3)
Block(5,23,-7,45)
Block(5,23,-6,17)
Block(5,23,2,17)
Block(5,23,3,45)
Block(5,23,4,17)
Block(5,23,5,35:8)
Block(5,23,6,17)
Block(5,23,7,45)
Block(5,24,-7,45)
Block(5,24,-6,17)
Block(5,24,2,17)
Block(5,24,3,108:2)
Block(5,24,4,17)
Block(5,24,5,35:8)
Block(5,24,6,17)
Block(5,24,7,108:3)
Block(5,25,-7,108:2)
Block(5,25,-6,17)
Block(5,25,2,17)
Block(5,25,3,108:3)
Block(5,25,4,45)
Block(5,25,5,17)
Block(5,25,6,45)
Block(5,26,-6,108:2)
Block(5,26,2,108:3)
Block(5,26,4,108:2)
Block(5,26,5,17)
Block(5,26,6,108:3)
Block(5,27,-5,108:2)
Block(5,27,1,108:3)
Block(5,27,5,45)
Block(5,28,-4,45)
Block(5,28,0,45)
Block(5,28,5,44:4)
Block(5,29,-4,108:2)
Block(5,29,0,108:3)
Block(5,30,-3,45)
Block(5,30,-2,17)
Block(5,30,-1,45)
Block(5,31,-3,108:2)
Block(5,31,-2,17)
Block(5,31,-1,108:3)
Block(5,32,-2,45)
Block(5,33,-2,44:4)
Block(6,0,-7,1)
Block(6,0,-6,1)
Block(6,0,-5,1)
Block(6,0,-4,1)
Block(6,0,-3,1)
Block(6,0,-2,1)
Block(6,0,-1,1)
Block(6,0,0,1)
Block(6,0,1,1)
Block(6,0,2,1)
Block(6,0,3,1)
Block(6,0,4,1)
Block(6,0,5,1)
Block(6,0,6,1)
Block(6,0,7,1)
Block(6,0,8,1)
Block(6,1,-7,1)
Block(6,1,-6,1)
Block(6,1,-5,1)
Block(6,1,-4,1)
Block(6,1,-3,1)
Block(6,1,-2,1)
Block(6,1,-1,1)
Block(6,1,0,1)
Block(6,1,1,1)
Block(6,1,2,1)
Block(6,1,3,1)
Block(6,1,4,1)
Block(6,1,5,1)
Block(6,1,6,1)
Block(6,1,7,1)
Block(6,1,8,1)
Block(6,2,-7,1)
Block(6,2,-6,1)
Block(6,2,-5,1)
Block(6,2,-4,1)
Block(6,2,-3,1)
Block(6,2,-2,1)
Block(6,2,-1,1)
Block(6,2,0,1)
Block(6,2,1,1)
Block(6,2,2,1)
Block(6,2,3,1)
Block(6,2,4,1)
Block(6,2,5,1)
Block(6,2,6,1)
Block(6,2,7,1)
Block(6,2,8,1)
Block(6,3,-7,1)
Block(6,3,-6,1)
Block(6,3,-5,1)
Block(6,3,-4,1)
Block(6,3,-3,1)
Block(6,3,-2,1)
Block(6,3,-1,1)
Block(6,3,0,1)
Block(6,3,1,1)
Block(6,3,2,1)
Block(6,3,3,1)
Block(6,3,4,1)
Block(6,3,5,1)
Block(6,3,6,1)
Block(6,3,7,1)
Block(6,3,8,1)
Block(6,4,-7,1)
Block(6,4,-6,1)
Block(6,4,-5,1)
Block(6,4,-4,1)
Block(6,4,-3,1)
Block(6,4,-2,1)
Block(6,4,-1,1)
Block(6,4,0,1)
Block(6,4,1,1)
Block(6,4,2,1)
Block(6,4,3,1)
Block(6,4,4,1)
Block(6,4,5,1)
Block(6,4,6,1)
Block(6,4,7,1)
Block(6,4,8,1)
Block(6,5,-7,1)
Block(6,5,-6,1)
Block(6,5,-5,1)
Block(6,5,-4,1)
Block(6,5,-3,1)
Block(6,5,-2,1)
Block(6,5,-1,1)
Block(6,5,0,1)
Block(6,5,1,1)
Block(6,5,2,1)
Block(6,5,3,1)
Block(6,5,4,1)
Block(6,5,5,1)
Block(6,5,6,1)
Block(6,5,7,1)
Block(6,5,8,1)
Block(6,6,-7,1)
Block(6,6,-6,1)
Block(6,6,-5,1)
Block(6,6,-4,1)
Block(6,6,-3,1)
Block(6,6,-2,1)
Block(6,6,-1,1)
Block(6,6,0,1)
Block(6,6,1,1)
Block(6,6,2,1)
Block(6,6,3,1)
Block(6,6,4,1)
Block(6,6,5,1)
Block(6,6,6,1)
Block(6,6,7,1)
Block(6,6,8,1)
Block(6,7,-7,1)
Block(6,7,-6,1)
Block(6,7,-5,1)
Block(6,7,-4,1)
Block(6,7,-3,1)
Block(6,7,-2,1)
Block(6,7,-1,1)
Block(6,7,0,1)
Block(6,7,1,1)
Block(6,7,2,1)
Block(6,7,3,1)
Block(6,7,4,1)
Block(6,7,5,1)
Block(6,7,6,1)
Block(6,7,7,1)
Block(6,7,8,1)
Block(6,8,-7,1)
Block(6,8,-6,1)
Block(6,8,-5,1)
Block(6,8,-4,1)
Block(6,8,-3,1)
Block(6,8,-2,1)
Block(6,8,-1,1)
Block(6,8,0,1)
Block(6,8,1,1)
Block(6,8,2,1)
Block(6,8,3,1)
Block(6,8,4,1)
Block(6,8,5,1)
Block(6,8,6,1)
Block(6,8,7,1)
Block(6,8,8,1)
Block(6,9,-7,1)
Block(6,9,-6,1)
Block(6,9,-5,1)
Block(6,9,-4,1)
Block(6,9,-3,1)
Block(6,9,-2,1)
Block(6,9,-1,1)
Block(6,9,0,1)
Block(6,9,1,1)
Block(6,9,2,1)
Block(6,9,3,1)
Block(6,9,4,1)
Block(6,9,5,1)
Block(6,9,6,1)
Block(6,9,7,1)
Block(6,9,8,1)
Block(6,10,-7,1)
Block(6,10,-6,1)
Block(6,10,-5,1)
Block(6,10,-4,1)
Block(6,10,-3,1)
Block(6,10,-2,1)
Block(6,10,-1,1)
Block(6,10,0,1)
Block(6,10,1,1)
Block(6,10,2,1)
Block(6,10,3,1)
Block(6,10,4,1)
Block(6,10,5,1)
Block(6,10,6,1)
Block(6,10,7,1)
Block(6,10,8,1)
Block(6,11,-7,1)
Block(6,11,-6,1)
Block(6,11,-5,1)
Block(6,11,-4,1)
Block(6,11,-3,1)
Block(6,11,-2,1)
Block(6,11,-1,1)
Block(6,11,0,1)
Block(6,11,1,13)
Block(6,11,2,1)
Block(6,11,3,1)
Block(6,11,4,1)
Block(6,11,5,1)
Block(6,11,6,1)
Block(6,11,7,1)
Block(6,11,8,1)
Block(6,12,-7,1)
Block(6,12,-6,1)
Block(6,12,-5,1)
Block(6,12,-4,1)
Block(6,12,-3,1)
Block(6,12,-2,1)
Block(6,12,-1,1)
Block(6,12,0,13)
Block(6,12,1,13)
Block(6,12,2,13)
Block(6,12,3,13)
Block(6,12,4,1)
Block(6,12,5,1)
Block(6,12,6,1)
Block(6,12,7,3)
Block(6,12,8,1)
Block(6,13,-7,3)
Block(6,13,-6,3)
Block(6,13,-5,3)
Block(6,13,-4,3)
Block(6,13,-3,3)
Block(6,13,-2,3)
Block(6,13,-1,1)
Block(6,13,0,13)
Block(6,13,1,13)
Block(6,13,2,13)
Block(6,13,3,13)
Block(6,13,4,1)
Block(6,13,5,3)
Block(6,13,6,3)
Block(6,13,7,3)
Block(6,13,8,3)
Block(6,14,-7,3)
Block(6,14,-6,3)
Block(6,14,-5,3)
Block(6,14,-4,3)
Block(6,14,-3,3)
Block(6,14,-2,3)
Block(6,14,-1,3)
Block(6,14,0,3)
Block(6,14,1,3)
Block(6,14,2,3)
Block(6,14,3,3)
Block(6,14,4,3)
Block(6,14,5,3)
Block(6,14,6,3)
Block(6,14,7,3)
Block(6,14,8,3)
Block(6,15,-7,3)
Block(6,15,-6,3)
Block(6,15,-5,3)
Block(6,15,-4,3)
Block(6,15,-3,3)
Block(6,15,-2,3)
Block(6,15,-1,3)
Block(6,15,0,3)
Block(6,15,1,3)
Block(6,15,2,3)
Block(6,15,3,3)
Block(6,15,4,3)
Block(6,15,5,3)
Block(6,15,6,3)
Block(6,15,7,3)
Block(6,15,8,3)
Block(6,16,-7,5)
Block(6,16,-6,5)
Block(6,16,-5,5)
Block(6,16,-4,5)
Block(6,16,-3,5)
Block(6,16,-2,5)
Block(6,16,-1,5)
Block(6,16,0,5)
Block(6,16,1,5)
Block(6,16,2,5)
Block(6,16,3,5)
Block(6,16,4,5)
Block(6,16,5,5)
Block(6,16,6,5)
Block(6,16,7,5)
Block(6,16,8,5)
Block(6,17,-6,5:2)
Block(6,17,2,5:2)
Block(6,17,7,24:2)
Block(6,17,8,5:2)
Block(6,18,-6,5:2)
Block(6,18,2,5:2)
Block(6,18,8,5:2)
Block(6,19,-6,5:2)
Block(6,19,2,5:2)
Block(6,19,8,5:2)
Block(6,20,-6,5:2)
Block(6,20,2,5:2)
Block(6,20,8,35:8)
Block(6,21,-7,126:9)
Block(6,21,-6,125:1)
Block(6,21,-5,126:9)
Block(6,21,-4,126:9)
Block(6,21,-3,126:9)
Block(6,21,-2,126:9)
Block(6,21,-1,126:9)
Block(6,21,0,126:9)
Block(6,21,1,126:9)
Block(6,21,2,125:1)
Block(6,21,3,126:9)
Block(6,21,4,126:9)
Block(6,21,5,126:9)
Block(6,21,6,126:9)
Block(6,21,7,126:9)
Block(6,21,8,125:1)
Block(6,22,-7,64:3)
Block(6,22,3,64:1)
Block(6,22,8,108:3)
Block(6,23,-7,64:8)
Block(6,23,3,64:8)
Block(6,23,7,45)
Block(6,24,-7,45)
Block(6,24,3,108:2)
Block(6,24,7,108:3)
Block(6,25,-7,108:2)
Block(6,25,3,108:3)
Block(6,25,4,45)
Block(6,25,6,45)
Block(6,26,-6,108:2)
Block(6,26,2,108:3)
Block(6,26,4,108:2)
Block(6,26,6,108:3)
Block(6,27,-5,108:2)
Block(6,27,1,108:3)
Block(6,27,5,45)
Block(6,28,-4,45)
Block(6,28,0,45)
Block(6,28,5,44:4)
Block(6,29,-4,108:2)
Block(6,29,0,108:3)
Block(6,30,-3,45)
Block(6,30,-2,17)
Block(6,30,-1,45)
Block(6,31,-3,108:2)
Block(6,31,-2,17)
Block(6,31,-1,108:3)
Block(6,32,-2,45)
Block(6,33,-2,44:4)
Block(7,0,-7,1)
Block(7,0,-6,1)
Block(7,0,-5,1)
Block(7,0,-4,1)
Block(7,0,-3,1)
Block(7,0,-2,1)
Block(7,0,-1,1)
Block(7,0,0,1)
Block(7,0,1,1)
Block(7,0,2,1)
Block(7,0,3,1)
Block(7,0,4,1)
Block(7,0,5,1)
Block(7,0,6,1)
Block(7,0,7,1)
Block(7,0,8,1)
Block(7,1,-7,1)
Block(7,1,-6,1)
Block(7,1,-5,1)
Block(7,1,-4,1)
Block(7,1,-3,1)
Block(7,1,-2,1)
Block(7,1,-1,1)
Block(7,1,0,1)
Block(7,1,1,1)
Block(7,1,2,1)
Block(7,1,3,1)
Block(7,1,4,1)
Block(7,1,5,1)
Block(7,1,6,1)
Block(7,1,7,1)
Block(7,1,8,1)
Block(7,2,-7,1)
Block(7,2,-6,1)
Block(7,2,-5,1)
Block(7,2,-4,1)
Block(7,2,-3,1)
Block(7,2,-2,1)
Block(7,2,-1,1)
Block(7,2,0,1)
Block(7,2,1,1)
Block(7,2,2,1)
Block(7,2,3,1)
Block(7,2,4,1)
Block(7,2,5,1)
Block(7,2,6,1)
Block(7,2,7,1)
Block(7,2,8,1)
Block(7,3,-7,1)
Block(7,3,-6,1)
Block(7,3,-5,1)
Block(7,3,-4,1)
Block(7,3,-3,1)
Block(7,3,-2,1)
Block(7,3,-1,1)
Block(7,3,0,1)
Block(7,3,1,1)
Block(7,3,2,1)
Block(7,3,3,1)
Block(7,3,4,1)
Block(7,3,5,1)
Block(7,3,6,1)
Block(7,3,7,1)
Block(7,3,8,1)
Block(7,4,-7,1)
Block(7,4,-6,1)
Block(7,4,-5,1)
Block(7,4,-4,1)
Block(7,4,-3,1)
Block(7,4,-2,1)
Block(7,4,-1,1)
Block(7,4,0,1)
Block(7,4,1,1)
Block(7,4,2,1)
Block(7,4,3,1)
Block(7,4,4,1)
Block(7,4,5,1)
Block(7,4,6,1)
Block(7,4,7,1)
Block(7,4,8,1)
Block(7,5,-7,1)
Block(7,5,-6,1)
Block(7,5,-5,1)
Block(7,5,-4,1)
Block(7,5,-3,1)
Block(7,5,-2,1)
Block(7,5,-1,1)
Block(7,5,0,1)
Block(7,5,1,1)
Block(7,5,2,1)
Block(7,5,3,1)
Block(7,5,4,1)
Block(7,5,5,1)
Block(7,5,6,1)
Block(7,5,7,1)
Block(7,5,8,1)
Block(7,6,-7,1)
Block(7,6,-6,1)
Block(7,6,-5,1)
Block(7,6,-4,1)
Block(7,6,-3,1)
Block(7,6,-2,1)
Block(7,6,-1,1)
Block(7,6,0,16)
Block(7,6,1,1)
Block(7,6,2,1)
Block(7,6,3,1)
Block(7,6,4,1)
Block(7,6,5,1)
Block(7,6,6,1)
Block(7,6,7,1)
Block(7,6,8,1)
Block(7,7,-7,1)
Block(7,7,-6,1)
Block(7,7,-5,1)
Block(7,7,-4,1)
Block(7,7,-3,1)
Block(7,7,-2,1)
Block(7,7,-1,1)
Block(7,7,0,16)
Block(7,7,1,1)
Block(7,7,2,1)
Block(7,7,3,1)
Block(7,7,4,1)
Block(7,7,5,1)
Block(7,7,6,1)
Block(7,7,7,1)
Block(7,7,8,1)
Block(7,8,-7,1)
Block(7,8,-6,1)
Block(7,8,-5,1)
Block(7,8,-4,1)
Block(7,8,-3,1)
Block(7,8,-2,1)
Block(7,8,-1,1)
Block(7,8,0,1)
Block(7,8,1,1)
Block(7,8,2,1)
Block(7,8,3,1)
Block(7,8,4,1)
Block(7,8,5,1)
Block(7,8,6,1)
Block(7,8,7,1)
Block(7,8,8,1)
Block(7,9,-7,1)
Block(7,9,-6,1)
Block(7,9,-5,1)
Block(7,9,-4,1)
Block(7,9,-3,1)
Block(7,9,-2,1)
Block(7,9,-1,1)
Block(7,9,0,1)
Block(7,9,1,1)
Block(7,9,2,1)
Block(7,9,3,1)
Block(7,9,4,1)
Block(7,9,5,1)
Block(7,9,6,1)
Block(7,9,7,1)
Block(7,9,8,1)
Block(7,10,-7,1)
Block(7,10,-6,1)
Block(7,10,-5,1)
Block(7,10,-4,1)
Block(7,10,-3,1)
Block(7,10,-2,1)
Block(7,10,-1,1)
Block(7,10,0,1)
Block(7,10,1,1)
Block(7,10,2,1)
Block(7,10,3,1)
Block(7,10,4,1)
Block(7,10,5,1)
Block(7,10,6,1)
Block(7,10,7,1)
Block(7,10,8,1)
Block(7,11,-7,1)
Block(7,11,-6,1)
Block(7,11,-5,1)
Block(7,11,-4,1)
Block(7,11,-3,1)
Block(7,11,-2,1)
Block(7,11,-1,1)
Block(7,11,0,1)
Block(7,11,1,1)
Block(7,11,2,1)
Block(7,11,3,1)
Block(7,11,4,1)
Block(7,11,5,1)
Block(7,11,6,1)
Block(7,11,7,1)
Block(7,11,8,1)
Block(7,12,-7,1)
Block(7,12,-6,1)
Block(7,12,-5,1)
Block(7,12,-4,1)
Block(7,12,-3,1)
Block(7,12,-2,1)
Block(7,12,-1,1)
Block(7,12,0,13)
Block(7,12,1,13)
Block(7,12,2,13)
Block(7,12,3,1)
Block(7,12,4,1)
Block(7,12,5,1)
Block(7,12,6,1)
Block(7,12,7,1)
Block(7,12,8,3)
Block(7,13,-7,3)
Block(7,13,-6,3)
Block(7,13,-5,3)
Block(7,13,-4,3)
Block(7,13,-3,3)
Block(7,13,-2,3)
Block(7,13,-1,1)
Block(7,13,0,13)
Block(7,13,1,13)
Block(7,13,2,13)
Block(7,13,3,1)
Block(7,13,4,1)
Block(7,13,5,1)
Block(7,13,6,3)
Block(7,13,7,3)
Block(7,13,8,3)
Block(7,14,-7,3)
Block(7,14,-6,3)
Block(7,14,-5,3)
Block(7,14,-4,3)
Block(7,14,-3,3)
Block(7,14,-2,3)
Block(7,14,-1,3)
Block(7,14,0,3)
Block(7,14,1,3)
Block(7,14,2,3)
Block(7,14,3,3)
Block(7,14,4,3)
Block(7,14,5,3)
Block(7,14,6,3)
Block(7,14,7,3)
Block(7,14,8,3)
Block(7,15,-7,3)
Block(7,15,-6,3)
Block(7,15,-5,3)
Block(7,15,-4,3)
Block(7,15,-3,3)
Block(7,15,-2,3)
Block(7,15,-1,3)
Block(7,15,0,3)
Block(7,15,1,3)
Block(7,15,2,3)
Block(7,15,3,3)
Block(7,15,4,3)
Block(7,15,5,3)
Block(7,15,6,3)
Block(7,15,7,3)
Block(7,15,8,3)
Block(7,16,-7,5)
Block(7,16,-6,5)
Block(7,16,-5,5)
Block(7,16,-4,5)
Block(7,16,-3,5)
Block(7,16,-2,5)
Block(7,16,-1,5)
Block(7,16,0,5)
Block(7,16,1,5)
Block(7,16,2,5)
Block(7,16,3,5)
Block(7,16,4,5)
Block(7,16,5,5)
Block(7,16,6,5)
Block(7,16,7,5)
Block(7,16,8,5)
Block(7,17,-7,24:2)
Block(7,17,-6,5:2)
Block(7,17,2,5:2)
Block(7,17,6,24:2)
Block(7,17,7,24:2)
Block(7,17,8,5:2)
Block(7,18,-6,5:2)
Block(7,18,2,5:2)
Block(7,18,7,24:2)
Block(7,18,8,5:2)
Block(7,19,-6,5:2)
Block(7,19,2,5:2)
Block(7,19,8,5:2)
Block(7,20,-6,5:2)
Block(7,20,2,5:2)
Block(7,20,8,102)
Block(7,21,-7,126:9)
Block(7,21,-6,125:1)
Block(7,21,-5,126:9)
Block(7,21,-4,126:9)
Block(7,21,-3,126:9)
Block(7,21,-2,126:9)
Block(7,21,-1,126:9)
Block(7,21,0,126:9)
Block(7,21,1,126:9)
Block(7,21,2,125:1)
Block(7,21,3,126:9)
Block(7,21,4,126:9)
Block(7,21,5,126:9)
Block(7,21,6,126:9)
Block(7,21,7,126:9)
Block(7,21,8,125:1)
Block(7,22,-7,45)
Block(7,22,3,45)
Block(7,22,8,108:3)
Block(7,23,-7,45)
Block(7,23,3,45)
Block(7,23,7,45)
Block(7,24,-7,45)
Block(7,24,3,108:2)
Block(7,24,7,108:3)
Block(7,25,-7,108:2)
Block(7,25,3,108:3)
Block(7,25,4,45)
Block(7,25,6,45)
Block(7,26,-6,108:2)
Block(7,26,2,108:3)
Block(7,26,4,108:2)
Block(7,26,6,108:3)
Block(7,27,-5,108:2)
Block(7,27,1,108:3)
Block(7,27,5,45)
Block(7,28,-4,45)
Block(7,28,0,45)
Block(7,28,5,44:4)
Block(7,29,-4,108:2)
Block(7,29,0,108:3)
Block(7,30,-3,45)
Block(7,30,-2,17)
Block(7,30,-1,45)
Block(7,31,-3,108:2)
Block(7,31,-2,17)
Block(7,31,-1,108:3)
Block(7,32,-2,45)
Block(7,33,-2,44:4)

Branch(16,0,0,true,kontorWaterStartC2R1,NORTH,100,0)
