

BranchFrequency: 10

BranchFrequencyGroup: CanOverride:0

CanOverride: true

SmoothRadius: -1

OverrideChildSettings: false

ReplaceAbove:
ReplaceBelow:

MustBeInside: VillageGeneratorStructurePlaceHolder, VillageGeneratorStructuresDelay, VillageGeneratorStructuresDelay2, VillageGeneratorStructuresDelay3, VillageGeneratorStructuresDelay4, VillageGeneratorStructuresDelay5, VillageGeneratorStructuresDelay6, VillageGeneratorStructuresDelay7, VillageGeneratorStructuresDelay8, VillageGeneratorStructuresDelay9, VillageGeneratorStructuresDelay10

Block(-8,0,-7,2)
Block(-8,0,-6,2)
Block(-8,0,-5,2)
Block(-8,0,-4,2)
Block(-8,0,-3,2)
Block(-8,0,-2,2)
Block(-8,0,-1,2)
Block(-8,1,-6,31:1)
Block(-8,7,-3,17:5)
Block(-7,0,-7,3)
Block(-7,0,-6,2)
Block(-7,0,-5,2)
Block(-7,0,-4,2)
Block(-7,0,-3,2)
Block(-7,0,-2,2)
Block(-7,0,-1,3)
Block(-7,1,-7,5:5)
Block(-7,1,-6,113)
Block(-7,1,-5,113)
Block(-7,1,-4,113)
Block(-7,1,-3,113)
Block(-7,1,-2,113)
Block(-7,1,-1,5:5)
Block(-7,2,-7,5:5)
Block(-7,2,-6,113)
Block(-7,2,-5,113)
Block(-7,2,-4,113)
Block(-7,2,-3,113)
Block(-7,2,-2,113)
Block(-7,2,-1,5:5)
Block(-7,3,-7,5:5)
Block(-7,3,-6,164:4)
Block(-7,3,-5,164:4)
Block(-7,3,-4,164:4)
Block(-7,3,-3,164:4)
Block(-7,3,-2,164:4)
Block(-7,3,-1,5:5)
Block(-7,4,-3,17:1)
Block(-7,5,-4,68:2,1-Sign.nbt)
Block(-7,5,-3,17:1)
Block(-7,6,-4,68:2,2-Sign.nbt)
Block(-7,6,-3,17:1)
Block(-7,7,-3,17:5)
Block(-6,0,-7,2)
Block(-6,0,-6,2)
Block(-6,0,-5,2)
Block(-6,0,-4,2)
Block(-6,0,-3,2)
Block(-6,0,-2,2)
Block(-6,0,-1,2)
Block(-6,1,-6,113)
Block(-6,1,-1,113)
Block(-6,2,-6,113)
Block(-6,2,-1,113)
Block(-6,3,-7,164:4)
Block(-6,3,-6,164:6)
Block(-6,3,-5,126:13)
Block(-6,3,-4,126:13)
Block(-6,3,-3,126:13)
Block(-6,3,-2,126:13)
Block(-6,3,-1,164:7)
Block(-6,7,-3,17:5)
Block(-5,0,-7,2)
Block(-5,0,-6,2)
Block(-5,0,-5,2)
Block(-5,0,-4,2)
Block(-5,0,-3,2)
Block(-5,0,-2,2)
Block(-5,0,-1,2)
Block(-5,1,-6,113)
Block(-5,1,-1,113)
Block(-5,2,-7,164:4)
Block(-5,2,-6,113)
Block(-5,2,-1,113)
Block(-5,3,-7,126:5)
Block(-5,3,-6,164:6)
Block(-5,3,-5,126:13)
Block(-5,3,-4,126:13)
Block(-5,3,-3,96:8)
Block(-5,3,-2,125:5)
Block(-5,3,-1,164:7)
Block(-5,4,-2,69:6)
Block(-5,7,-3,17:5)
Block(-4,0,-7,2)
Block(-4,0,-6,2)
Block(-4,0,-5,2)
Block(-4,0,-4,2)
Block(-4,0,-3,2)
Block(-4,0,-2,2)
Block(-4,0,-1,2)
Block(-4,1,-7,164:4)
Block(-4,1,-6,113)
Block(-4,1,-3,31:1)
Block(-4,1,-1,113)
Block(-4,2,-7,125:5)
Block(-4,2,-6,113)
Block(-4,2,-1,113)
Block(-4,3,-6,164:6)
Block(-4,3,-5,126:13)
Block(-4,3,-4,126:13)
Block(-4,3,-3,126:13)
Block(-4,3,-2,126:13)
Block(-4,3,-1,164:7)
Block(-4,7,-3,17:5)
Block(-3,0,-7,2)
Block(-3,0,-6,2)
Block(-3,0,-5,2)
Block(-3,0,-4,2)
Block(-3,0,-3,2)
Block(-3,0,-2,2)
Block(-3,0,-1,3)
Block(-3,1,-7,125:5)
Block(-3,1,-6,113)
Block(-3,1,-4,31:1)
Block(-3,1,-1,5:5)
Block(-3,2,-7,126:5)
Block(-3,2,-6,113)
Block(-3,2,-1,5:5)
Block(-3,3,-6,164:6)
Block(-3,3,-5,126:13)
Block(-3,3,-4,126:13)
Block(-3,3,-3,126:13)
Block(-3,3,-2,126:13)
Block(-3,3,-1,125:5)
Block(-3,7,-3,17:5)
Block(-2,0,-7,2)
Block(-2,0,-6,2)
Block(-2,0,-5,2)
Block(-2,0,-4,2)
Block(-2,0,-3,2)
Block(-2,0,-2,2)
Block(-2,0,-1,2)
Block(-2,1,-7,125:5)
Block(-2,1,-6,113)
Block(-2,1,-5,31:1)
Block(-2,1,-4,37)
Block(-2,1,-3,31:1)
Block(-2,2,-6,113)
Block(-2,3,-6,164:6)
Block(-2,3,-5,126:13)
Block(-2,3,-4,126:13)
Block(-2,3,-3,96:8)
Block(-2,3,-2,125:5)
Block(-2,3,-1,126:13)
Block(-2,4,-2,69:6)
Block(-2,7,-3,17:5)
Block(-1,0,-7,2)
Block(-1,0,-6,3)
Block(-1,0,-5,2)
Block(-1,0,-4,2)
Block(-1,0,-3,2)
Block(-1,0,-2,2)
Block(-1,0,-1,2)
Block(-1,1,-7,126:5)
Block(-1,1,-6,5:5)
Block(-1,1,-4,31:1)
Block(-1,1,-3,31:1)
Block(-1,2,-6,5:5)
Block(-1,3,-6,125:5)
Block(-1,3,-5,126:13)
Block(-1,3,-4,126:13)
Block(-1,3,-3,126:13)
Block(-1,3,-2,126:13)
Block(-1,3,-1,126:13)
Block(-1,7,-3,17:5)
Block(0,0,-7,2)
Block(0,0,-6,2)
Block(0,0,-5,2)
Block(0,0,-4,2)
Block(0,0,-3,2)
Block(0,0,-2,2)
Block(0,0,-1,2)
Block(0,1,-7,31:1)
Block(0,1,-6,113)
Block(0,1,-5,31:1)
Block(0,1,-4,31:1)
Block(0,1,-3,31:1)
Block(0,2,-6,113)
Block(0,3,-6,164:6)
Block(0,3,-5,126:13)
Block(0,3,-4,126:13)
Block(0,3,-3,126:13)
Block(0,3,-2,126:13)
Block(0,3,-1,126:13)
Block(0,7,-3,17:5)
Block(1,0,-7,2)
Block(1,0,-6,2)
Block(1,0,-5,2)
Block(1,0,-4,2)
Block(1,0,-3,2)
Block(1,0,-2,2)
Block(1,0,-1,2)
Block(1,1,-6,113)
Block(1,1,-5,31:1)
Block(1,1,-4,38)
Block(1,1,-3,31:1)
Block(1,1,-2,31:1)
Block(1,2,-6,113)
Block(1,3,-6,164:6)
Block(1,3,-5,126:13)
Block(1,3,-4,126:13)
Block(1,3,-3,96:8)
Block(1,3,-2,125:5)
Block(1,3,-1,126:13)
Block(1,4,-2,69:6)
Block(1,7,-3,17:5)
Block(2,0,-7,2)
Block(2,0,-6,2)
Block(2,0,-5,2)
Block(2,0,-4,2)
Block(2,0,-3,2)
Block(2,0,-2,2)
Block(2,0,-1,2)
Block(2,1,-6,113)
Block(2,1,-5,31:1)
Block(2,1,-4,31:1)
Block(2,1,-3,31:1)
Block(2,1,-2,31:1)
Block(2,2,-6,113)
Block(2,3,-6,164:6)
Block(2,3,-5,126:13)
Block(2,3,-4,126:13)
Block(2,3,-3,126:13)
Block(2,3,-2,126:13)
Block(2,3,-1,126:13)
Block(2,7,-3,17:5)
Block(3,0,-7,2)
Block(3,0,-6,3)
Block(3,0,-5,2)
Block(3,0,-4,2)
Block(3,0,-3,2)
Block(3,0,-2,2)
Block(3,0,-1,3)
Block(3,1,-7,31:1)
Block(3,1,-6,5:5)
Block(3,1,-5,113)
Block(3,1,-4,113)
Block(3,1,-3,113)
Block(3,1,-2,113)
Block(3,1,-1,5:5)
Block(3,2,-6,5:5)
Block(3,2,-5,113)
Block(3,2,-4,113)
Block(3,2,-3,113)
Block(3,2,-2,113)
Block(3,2,-1,5:5)
Block(3,3,-6,5:5)
Block(3,3,-5,164:5)
Block(3,3,-4,164:5)
Block(3,3,-3,164:5)
Block(3,3,-2,164:5)
Block(3,3,-1,5:5)
Block(3,4,-3,17:1)
Block(3,5,-3,17:1)
Block(3,6,-3,17:1)
Block(3,7,-3,17:5)
Block(4,0,-7,2)
Block(4,0,-6,2)
Block(4,0,-5,2)
Block(4,0,-4,2)
Block(4,0,-3,2)
Block(4,0,-2,2)
Block(4,0,-1,2)
Block(4,1,-5,31:1)
Block(4,1,-3,31:1)
Block(4,1,-2,31:1)
Block(4,7,-3,17:5)
